<robot name = "robot">
    <link name="Torso">
        <inertial>
            <origin xyz="0 0 1.2264357241832475" rpy="0 0 0"/>
            <mass value="1" />
            <inertia ixx="100" ixy="0" ixz="0" iyy="100" iyz="0" izz="100" />
        </inertial>
        <visual>
            <origin xyz="0 0 1.2264357241832475" rpy="0 0 0"/>
            <geometry>
                <box size="1.1710732864148785 2.7981389850949325 2.452871448366495" />
            </geometry>
            <material name="Green">
                <color rgba="0 180.0 0.0 1.0"/>
            </material>
        </visual>
        <collision>
            <origin xyz="0 0 1.2264357241832475" rpy="0 0 0"/>
            <geometry>
                <box size="1.1710732864148785 2.7981389850949325 2.452871448366495" />
            </geometry>
        </collision>
    </link>
    <link name="Leg1">
        <inertial>
            <origin xyz="1.2528237917054026 0 0" rpy="0 0 0"/>
            <mass value="1" />
            <inertia ixx="100" ixy="0" ixz="0" iyy="100" iyz="0" izz="100" />
        </inertial>
        <visual>
            <origin xyz="1.2528237917054026 0 0" rpy="0 0 0"/>
            <geometry>
                <box size="2.505647583410805 2.615328289448195 2.986469708938383" />
            </geometry>
            <material name="Green">
                <color rgba="0 180.0 0.0 1.0"/>
            </material>
        </visual>
        <collision>
            <origin xyz="1.2528237917054026 0 0" rpy="0 0 0"/>
            <geometry>
                <box size="2.505647583410805 2.615328289448195 2.986469708938383" />
            </geometry>
        </collision>
    </link>
    <link name="Leg2">
        <inertial>
            <origin xyz="0 0 0.617595699570374" rpy="0 0 0"/>
            <mass value="1" />
            <inertia ixx="100" ixy="0" ixz="0" iyy="100" iyz="0" izz="100" />
        </inertial>
        <visual>
            <origin xyz="0 0 0.617595699570374" rpy="0 0 0"/>
            <geometry>
                <box size="1.0989500199689841 2.400991992372904 1.235191399140748" />
            </geometry>
            <material name="Green">
                <color rgba="0 180.0 0.0 1.0"/>
            </material>
        </visual>
        <collision>
            <origin xyz="0 0 0.617595699570374" rpy="0 0 0"/>
            <geometry>
                <box size="1.0989500199689841 2.400991992372904 1.235191399140748" />
            </geometry>
        </collision>
    </link>
    <link name="Leg3">
        <inertial>
            <origin xyz="0 0 0.9745612239549359" rpy="0 0 0"/>
            <mass value="1" />
            <inertia ixx="100" ixy="0" ixz="0" iyy="100" iyz="0" izz="100" />
        </inertial>
        <visual>
            <origin xyz="0 0 0.9745612239549359" rpy="0 0 0"/>
            <geometry>
                <box size="2.4956224061533665 1.688908964950188 1.9491224479098719" />
            </geometry>
            <material name="Green">
                <color rgba="0 180.0 0.0 1.0"/>
            </material>
        </visual>
        <collision>
            <origin xyz="0 0 0.9745612239549359" rpy="0 0 0"/>
            <geometry>
                <box size="2.4956224061533665 1.688908964950188 1.9491224479098719" />
            </geometry>
        </collision>
    </link>
    <link name="Leg4">
        <inertial>
            <origin xyz="1.4781276739168216 0 0" rpy="0 0 0"/>
            <mass value="1" />
            <inertia ixx="100" ixy="0" ixz="0" iyy="100" iyz="0" izz="100" />
        </inertial>
        <visual>
            <origin xyz="1.4781276739168216 0 0" rpy="0 0 0"/>
            <geometry>
                <box size="2.9562553478336433 2.1652239789183625 1.559914648286002" />
            </geometry>
            <material name="Blue">
                <color rgba="0 1.0 1.0 1.0"/>
            </material>
        </visual>
        <collision>
            <origin xyz="1.4781276739168216 0 0" rpy="0 0 0"/>
            <geometry>
                <box size="2.9562553478336433 2.1652239789183625 1.559914648286002" />
            </geometry>
        </collision>
    </link>
    <link name="Leg5">
        <inertial>
            <origin xyz="0 1.3272224150453988 0" rpy="0 0 0"/>
            <mass value="1" />
            <inertia ixx="100" ixy="0" ixz="0" iyy="100" iyz="0" izz="100" />
        </inertial>
        <visual>
            <origin xyz="0 1.3272224150453988 0" rpy="0 0 0"/>
            <geometry>
                <box size="1.6364739213048525 2.6544448300907977 1.1176554863009953" />
            </geometry>
            <material name="Green">
                <color rgba="0 180.0 0.0 1.0"/>
            </material>
        </visual>
        <collision>
            <origin xyz="0 1.3272224150453988 0" rpy="0 0 0"/>
            <geometry>
                <box size="1.6364739213048525 2.6544448300907977 1.1176554863009953" />
            </geometry>
        </collision>
    </link>
    <link name="Leg6">
        <inertial>
            <origin xyz="0 0.8774247074718547 0" rpy="0 0 0"/>
            <mass value="1" />
            <inertia ixx="100" ixy="0" ixz="0" iyy="100" iyz="0" izz="100" />
        </inertial>
        <visual>
            <origin xyz="0 0.8774247074718547 0" rpy="0 0 0"/>
            <geometry>
                <box size="2.1640015594656554 1.7548494149437095 2.40584374093641" />
            </geometry>
            <material name="Blue">
                <color rgba="0 1.0 1.0 1.0"/>
            </material>
        </visual>
        <collision>
            <origin xyz="0 0.8774247074718547 0" rpy="0 0 0"/>
            <geometry>
                <box size="2.1640015594656554 1.7548494149437095 2.40584374093641" />
            </geometry>
        </collision>
    </link>
    <link name="Leg7">
        <inertial>
            <origin xyz="0 1.1271094822408847 0" rpy="0 0 0"/>
            <mass value="1" />
            <inertia ixx="100" ixy="0" ixz="0" iyy="100" iyz="0" izz="100" />
        </inertial>
        <visual>
            <origin xyz="0 1.1271094822408847 0" rpy="0 0 0"/>
            <geometry>
                <box size="1.3050166996102919 2.2542189644817694 1.8949384772704847" />
            </geometry>
            <material name="Blue">
                <color rgba="0 1.0 1.0 1.0"/>
            </material>
        </visual>
        <collision>
            <origin xyz="0 1.1271094822408847 0" rpy="0 0 0"/>
            <geometry>
                <box size="1.3050166996102919 2.2542189644817694 1.8949384772704847" />
            </geometry>
        </collision>
    </link>
    <link name="Leg8">
        <inertial>
            <origin xyz="0 0.6260236983288261 0" rpy="0 0 0"/>
            <mass value="1" />
            <inertia ixx="100" ixy="0" ixz="0" iyy="100" iyz="0" izz="100" />
        </inertial>
        <visual>
            <origin xyz="0 0.6260236983288261 0" rpy="0 0 0"/>
            <geometry>
                <box size="2.6182224122027287 1.2520473966576522 1.0094069909017978" />
            </geometry>
            <material name="Blue">
                <color rgba="0 1.0 1.0 1.0"/>
            </material>
        </visual>
        <collision>
            <origin xyz="0 0.6260236983288261 0" rpy="0 0 0"/>
            <geometry>
                <box size="2.6182224122027287 1.2520473966576522 1.0094069909017978" />
            </geometry>
        </collision>
    </link>
    <link name="Leg9">
        <inertial>
            <origin xyz="0 0.5648342049219819 0" rpy="0 0 0"/>
            <mass value="1" />
            <inertia ixx="100" ixy="0" ixz="0" iyy="100" iyz="0" izz="100" />
        </inertial>
        <visual>
            <origin xyz="0 0.5648342049219819 0" rpy="0 0 0"/>
            <geometry>
                <box size="2.752637438869809 1.1296684098439638 1.0930698846423939" />
            </geometry>
            <material name="Green">
                <color rgba="0 180.0 0.0 1.0"/>
            </material>
        </visual>
        <collision>
            <origin xyz="0 0.5648342049219819 0" rpy="0 0 0"/>
            <geometry>
                <box size="2.752637438869809 1.1296684098439638 1.0930698846423939" />
            </geometry>
        </collision>
    </link>
    <link name="Leg10">
        <inertial>
            <origin xyz="1.4960903468729754 0 0" rpy="0 0 0"/>
            <mass value="1" />
            <inertia ixx="100" ixy="0" ixz="0" iyy="100" iyz="0" izz="100" />
        </inertial>
        <visual>
            <origin xyz="1.4960903468729754 0 0" rpy="0 0 0"/>
            <geometry>
                <box size="2.9921806937459507 1.708471981071319 1.9331547135864586" />
            </geometry>
            <material name="Blue">
                <color rgba="0 1.0 1.0 1.0"/>
            </material>
        </visual>
        <collision>
            <origin xyz="1.4960903468729754 0 0" rpy="0 0 0"/>
            <geometry>
                <box size="2.9921806937459507 1.708471981071319 1.9331547135864586" />
            </geometry>
        </collision>
    </link>
    <link name="Leg11">
        <inertial>
            <origin xyz="0 0.9806984449604416 0" rpy="0 0 0"/>
            <mass value="1" />
            <inertia ixx="100" ixy="0" ixz="0" iyy="100" iyz="0" izz="100" />
        </inertial>
        <visual>
            <origin xyz="0 0.9806984449604416 0" rpy="0 0 0"/>
            <geometry>
                <box size="2.187451246751583 1.9613968899208831 1.1443338389012057" />
            </geometry>
            <material name="Green">
                <color rgba="0 180.0 0.0 1.0"/>
            </material>
        </visual>
        <collision>
            <origin xyz="0 0.9806984449604416 0" rpy="0 0 0"/>
            <geometry>
                <box size="2.187451246751583 1.9613968899208831 1.1443338389012057" />
            </geometry>
        </collision>
    </link>
    <link name="Leg12">
        <inertial>
            <origin xyz="1.3590584531020737 0 0" rpy="0 0 0"/>
            <mass value="1" />
            <inertia ixx="100" ixy="0" ixz="0" iyy="100" iyz="0" izz="100" />
        </inertial>
        <visual>
            <origin xyz="1.3590584531020737 0 0" rpy="0 0 0"/>
            <geometry>
                <box size="2.7181169062041475 1.2063550422741187 2.682462490927041" />
            </geometry>
            <material name="Blue">
                <color rgba="0 1.0 1.0 1.0"/>
            </material>
        </visual>
        <collision>
            <origin xyz="1.3590584531020737 0 0" rpy="0 0 0"/>
            <geometry>
                <box size="2.7181169062041475 1.2063550422741187 2.682462490927041" />
            </geometry>
        </collision>
    </link>
    <link name="Leg13">
        <inertial>
            <origin xyz="0 0.8423469697846463 0" rpy="0 0 0"/>
            <mass value="1" />
            <inertia ixx="100" ixy="0" ixz="0" iyy="100" iyz="0" izz="100" />
        </inertial>
        <visual>
            <origin xyz="0 0.8423469697846463 0" rpy="0 0 0"/>
            <geometry>
                <box size="2.879732412660652 1.6846939395692926 2.945375755106344" />
            </geometry>
            <material name="Blue">
                <color rgba="0 1.0 1.0 1.0"/>
            </material>
        </visual>
        <collision>
            <origin xyz="0 0.8423469697846463 0" rpy="0 0 0"/>
            <geometry>
                <box size="2.879732412660652 1.6846939395692926 2.945375755106344" />
            </geometry>
        </collision>
    </link>
    <link name="Leg14">
        <inertial>
            <origin xyz="0 0 0.9417053909617261" rpy="0 0 0"/>
            <mass value="1" />
            <inertia ixx="100" ixy="0" ixz="0" iyy="100" iyz="0" izz="100" />
        </inertial>
        <visual>
            <origin xyz="0 0 0.9417053909617261" rpy="0 0 0"/>
            <geometry>
                <box size="1.9466655449500576 2.272384794855693 1.8834107819234522" />
            </geometry>
            <material name="Green">
                <color rgba="0 180.0 0.0 1.0"/>
            </material>
        </visual>
        <collision>
            <origin xyz="0 0 0.9417053909617261" rpy="0 0 0"/>
            <geometry>
                <box size="1.9466655449500576 2.272384794855693 1.8834107819234522" />
            </geometry>
        </collision>
    </link>
    <link name="Leg15">
        <inertial>
            <origin xyz="0.7847113447654052 0 0" rpy="0 0 0"/>
            <mass value="1" />
            <inertia ixx="100" ixy="0" ixz="0" iyy="100" iyz="0" izz="100" />
        </inertial>
        <visual>
            <origin xyz="0.7847113447654052 0 0" rpy="0 0 0"/>
            <geometry>
                <box size="1.5694226895308103 2.1187347843955546 1.3244818883713871" />
            </geometry>
            <material name="Blue">
                <color rgba="0 1.0 1.0 1.0"/>
            </material>
        </visual>
        <collision>
            <origin xyz="0.7847113447654052 0 0" rpy="0 0 0"/>
            <geometry>
                <box size="1.5694226895308103 2.1187347843955546 1.3244818883713871" />
            </geometry>
        </collision>
    </link>
    <link name="Leg16">
        <inertial>
            <origin xyz="0 0.7174480014396847 0" rpy="0 0 0"/>
            <mass value="1" />
            <inertia ixx="100" ixy="0" ixz="0" iyy="100" iyz="0" izz="100" />
        </inertial>
        <visual>
            <origin xyz="0 0.7174480014396847 0" rpy="0 0 0"/>
            <geometry>
                <box size="2.8274436030188452 1.4348960028793694 1.4556162390449245" />
            </geometry>
            <material name="Green">
                <color rgba="0 180.0 0.0 1.0"/>
            </material>
        </visual>
        <collision>
            <origin xyz="0 0.7174480014396847 0" rpy="0 0 0"/>
            <geometry>
                <box size="2.8274436030188452 1.4348960028793694 1.4556162390449245" />
            </geometry>
        </collision>
    </link>
    <link name="Leg17">
        <inertial>
            <origin xyz="0.770953919572936 0 0" rpy="0 0 0"/>
            <mass value="1" />
            <inertia ixx="100" ixy="0" ixz="0" iyy="100" iyz="0" izz="100" />
        </inertial>
        <visual>
            <origin xyz="0.770953919572936 0 0" rpy="0 0 0"/>
            <geometry>
                <box size="1.541907839145872 2.2848916000183612 1.747980619822723" />
            </geometry>
            <material name="Blue">
                <color rgba="0 1.0 1.0 1.0"/>
            </material>
        </visual>
        <collision>
            <origin xyz="0.770953919572936 0 0" rpy="0 0 0"/>
            <geometry>
                <box size="1.541907839145872 2.2848916000183612 1.747980619822723" />
            </geometry>
        </collision>
    </link>
    <link name="Leg18">
        <inertial>
            <origin xyz="0.5195602981091392 0 0" rpy="0 0 0"/>
            <mass value="1" />
            <inertia ixx="100" ixy="0" ixz="0" iyy="100" iyz="0" izz="100" />
        </inertial>
        <visual>
            <origin xyz="0.5195602981091392 0 0" rpy="0 0 0"/>
            <geometry>
                <box size="1.0391205962182783 1.338707909185827 2.509142789852415" />
            </geometry>
            <material name="Blue">
                <color rgba="0 1.0 1.0 1.0"/>
            </material>
        </visual>
        <collision>
            <origin xyz="0.5195602981091392 0 0" rpy="0 0 0"/>
            <geometry>
                <box size="1.0391205962182783 1.338707909185827 2.509142789852415" />
            </geometry>
        </collision>
    </link>
    <link name="Leg19">
        <inertial>
            <origin xyz="1.1350926924392213 0 0" rpy="0 0 0"/>
            <mass value="1" />
            <inertia ixx="100" ixy="0" ixz="0" iyy="100" iyz="0" izz="100" />
        </inertial>
        <visual>
            <origin xyz="1.1350926924392213 0 0" rpy="0 0 0"/>
            <geometry>
                <box size="2.2701853848784426 1.6960704690425592 1.0336208019038498" />
            </geometry>
            <material name="Blue">
                <color rgba="0 1.0 1.0 1.0"/>
            </material>
        </visual>
        <collision>
            <origin xyz="1.1350926924392213 0 0" rpy="0 0 0"/>
            <geometry>
                <box size="2.2701853848784426 1.6960704690425592 1.0336208019038498" />
            </geometry>
        </collision>
    </link>
    <link name="Leg20">
        <inertial>
            <origin xyz="0 0.572242306977152 0" rpy="0 0 0"/>
            <mass value="1" />
            <inertia ixx="100" ixy="0" ixz="0" iyy="100" iyz="0" izz="100" />
        </inertial>
        <visual>
            <origin xyz="0 0.572242306977152 0" rpy="0 0 0"/>
            <geometry>
                <box size="2.5787151482946573 1.144484613954304 2.448746567357147" />
            </geometry>
            <material name="Green">
                <color rgba="0 180.0 0.0 1.0"/>
            </material>
        </visual>
        <collision>
            <origin xyz="0 0.572242306977152 0" rpy="0 0 0"/>
            <geometry>
                <box size="2.5787151482946573 1.144484613954304 2.448746567357147" />
            </geometry>
        </collision>
    </link>
    <link name="Leg21">
        <inertial>
            <origin xyz="1.360092705929309 0 0" rpy="0 0 0"/>
            <mass value="1" />
            <inertia ixx="100" ixy="0" ixz="0" iyy="100" iyz="0" izz="100" />
        </inertial>
        <visual>
            <origin xyz="1.360092705929309 0 0" rpy="0 0 0"/>
            <geometry>
                <box size="2.720185411858618 1.1793350293148737 2.812674584185355" />
            </geometry>
            <material name="Green">
                <color rgba="0 180.0 0.0 1.0"/>
            </material>
        </visual>
        <collision>
            <origin xyz="1.360092705929309 0 0" rpy="0 0 0"/>
            <geometry>
                <box size="2.720185411858618 1.1793350293148737 2.812674584185355" />
            </geometry>
        </collision>
    </link>
    <link name="Leg22">
        <inertial>
            <origin xyz="0.9974919102317396 0 0" rpy="0 0 0"/>
            <mass value="1" />
            <inertia ixx="100" ixy="0" ixz="0" iyy="100" iyz="0" izz="100" />
        </inertial>
        <visual>
            <origin xyz="0.9974919102317396 0 0" rpy="0 0 0"/>
            <geometry>
                <box size="1.994983820463479 1.8145681563545595 2.9464317084125495" />
            </geometry>
            <material name="Green">
                <color rgba="0 180.0 0.0 1.0"/>
            </material>
        </visual>
        <collision>
            <origin xyz="0.9974919102317396 0 0" rpy="0 0 0"/>
            <geometry>
                <box size="1.994983820463479 1.8145681563545595 2.9464317084125495" />
            </geometry>
        </collision>
    </link>
    <link name="Leg23">
        <inertial>
            <origin xyz="0 1.4037675471800715 0" rpy="0 0 0"/>
            <mass value="1" />
            <inertia ixx="100" ixy="0" ixz="0" iyy="100" iyz="0" izz="100" />
        </inertial>
        <visual>
            <origin xyz="0 1.4037675471800715 0" rpy="0 0 0"/>
            <geometry>
                <box size="1.727253867321171 2.807535094360143 2.503367983355081" />
            </geometry>
            <material name="Green">
                <color rgba="0 180.0 0.0 1.0"/>
            </material>
        </visual>
        <collision>
            <origin xyz="0 1.4037675471800715 0" rpy="0 0 0"/>
            <geometry>
                <box size="1.727253867321171 2.807535094360143 2.503367983355081" />
            </geometry>
        </collision>
    </link>
    <link name="Leg24">
        <inertial>
            <origin xyz="0 0 0.7305388374364445" rpy="0 0 0"/>
            <mass value="1" />
            <inertia ixx="100" ixy="0" ixz="0" iyy="100" iyz="0" izz="100" />
        </inertial>
        <visual>
            <origin xyz="0 0 0.7305388374364445" rpy="0 0 0"/>
            <geometry>
                <box size="2.683404368837806 1.2494724352686712 1.461077674872889" />
            </geometry>
            <material name="Green">
                <color rgba="0 180.0 0.0 1.0"/>
            </material>
        </visual>
        <collision>
            <origin xyz="0 0 0.7305388374364445" rpy="0 0 0"/>
            <geometry>
                <box size="2.683404368837806 1.2494724352686712 1.461077674872889" />
            </geometry>
        </collision>
    </link>
    <link name="Leg25">
        <inertial>
            <origin xyz="0.9709967029471795 0 0" rpy="0 0 0"/>
            <mass value="1" />
            <inertia ixx="100" ixy="0" ixz="0" iyy="100" iyz="0" izz="100" />
        </inertial>
        <visual>
            <origin xyz="0.9709967029471795 0 0" rpy="0 0 0"/>
            <geometry>
                <box size="1.941993405894359 2.9790122439209883 2.3164460355235588" />
            </geometry>
            <material name="Blue">
                <color rgba="0 1.0 1.0 1.0"/>
            </material>
        </visual>
        <collision>
            <origin xyz="0.9709967029471795 0 0" rpy="0 0 0"/>
            <geometry>
                <box size="1.941993405894359 2.9790122439209883 2.3164460355235588" />
            </geometry>
        </collision>
    </link>
    <link name="Leg26">
        <inertial>
            <origin xyz="1.2752481826758078 0 0" rpy="0 0 0"/>
            <mass value="1" />
            <inertia ixx="100" ixy="0" ixz="0" iyy="100" iyz="0" izz="100" />
        </inertial>
        <visual>
            <origin xyz="1.2752481826758078 0 0" rpy="0 0 0"/>
            <geometry>
                <box size="2.5504963653516155 1.032550302057611 2.067872840619165" />
            </geometry>
            <material name="Blue">
                <color rgba="0 1.0 1.0 1.0"/>
            </material>
        </visual>
        <collision>
            <origin xyz="1.2752481826758078 0 0" rpy="0 0 0"/>
            <geometry>
                <box size="2.5504963653516155 1.032550302057611 2.067872840619165" />
            </geometry>
        </collision>
    </link>
    <link name="Leg27">
        <inertial>
            <origin xyz="0 0 0.6012258823507967" rpy="0 0 0"/>
            <mass value="1" />
            <inertia ixx="100" ixy="0" ixz="0" iyy="100" iyz="0" izz="100" />
        </inertial>
        <visual>
            <origin xyz="0 0 0.6012258823507967" rpy="0 0 0"/>
            <geometry>
                <box size="2.043486829112126 1.322128598533842 1.2024517647015933" />
            </geometry>
            <material name="Blue">
                <color rgba="0 1.0 1.0 1.0"/>
            </material>
        </visual>
        <collision>
            <origin xyz="0 0 0.6012258823507967" rpy="0 0 0"/>
            <geometry>
                <box size="2.043486829112126 1.322128598533842 1.2024517647015933" />
            </geometry>
        </collision>
    </link>
    <link name="Leg28">
        <inertial>
            <origin xyz="0 0.6426287759784373 0" rpy="0 0 0"/>
            <mass value="1" />
            <inertia ixx="100" ixy="0" ixz="0" iyy="100" iyz="0" izz="100" />
        </inertial>
        <visual>
            <origin xyz="0 0.6426287759784373 0" rpy="0 0 0"/>
            <geometry>
                <box size="2.5082543884801103 1.2852575519568745 1.9927531618355638" />
            </geometry>
            <material name="Green">
                <color rgba="0 180.0 0.0 1.0"/>
            </material>
        </visual>
        <collision>
            <origin xyz="0 0.6426287759784373 0" rpy="0 0 0"/>
            <geometry>
                <box size="2.5082543884801103 1.2852575519568745 1.9927531618355638" />
            </geometry>
        </collision>
    </link>
    <joint name="Torso_Leg1" type="revolute">
       <parent link="Torso"/>
       <child  link="Leg1"/>
       <origin rpy="0 0 0" xyz="0.5855366432074393 0 1.2264357241832475" />
     <axis xyz="1 0 0"/>
       <limit effort="0.0" lower="-3.14159" upper="3.14159" velocity="0.0"/>
    </joint>
    <joint name="Leg1_Leg2" type="revolute">
       <parent link="Leg1"/>
       <child  link="Leg2"/>
       <origin rpy="0 0 0" xyz="0 0 1.235191399140748" />
     <axis xyz="1 0 0"/>
       <limit effort="0.0" lower="-3.14159" upper="3.14159" velocity="0.0"/>
    </joint>
    <joint name="Torso_Leg3" type="revolute">
       <parent link="Torso"/>
       <child  link="Leg3"/>
       <origin rpy="0 0 0" xyz="1.2528237917054026 0 1.4932348544691916" />
     <axis xyz="1 0 0"/>
       <limit effort="0.0" lower="-3.14159" upper="3.14159" velocity="0.0"/>
    </joint>
    <joint name="Leg1_Leg4" type="revolute">
       <parent link="Leg1"/>
       <child  link="Leg4"/>
       <origin rpy="0 0 0" xyz="0.5494750099844921 0 1.235191399140748" />
     <axis xyz="1 0 0"/>
       <limit effort="0.0" lower="-3.14159" upper="3.14159" velocity="0.0"/>
    </joint>
    <joint name="Leg1_Leg5" type="revolute">
       <parent link="Leg1"/>
       <child  link="Leg5"/>
       <origin rpy="0 0 0" xyz="0.5494750099844921 1.200495996186452 1.235191399140748" />
     <axis xyz="1 0 0"/>
       <limit effort="0.0" lower="-3.14159" upper="3.14159" velocity="0.0"/>
    </joint>
    <joint name="Leg4_Leg6" type="revolute">
       <parent link="Leg4"/>
       <child  link="Leg6"/>
       <origin rpy="0 0 0" xyz="0 2.6544448300907977 0" />
     <axis xyz="1 0 0"/>
       <limit effort="0.0" lower="-3.14159" upper="3.14159" velocity="0.0"/>
    </joint>
    <joint name="Leg3_Leg7" type="revolute">
       <parent link="Leg3"/>
       <child  link="Leg7"/>
       <origin rpy="0 0 0" xyz="1.4781276739168216 1.0826119894591812 0" />
     <axis xyz="1 0 0"/>
       <limit effort="0.0" lower="-3.14159" upper="3.14159" velocity="0.0"/>
    </joint>
    <joint name="Leg6_Leg8" type="revolute">
       <parent link="Leg6"/>
       <child  link="Leg8"/>
       <origin rpy="0 0 0" xyz="0 2.2542189644817694 0" />
     <axis xyz="1 0 0"/>
       <limit effort="0.0" lower="-3.14159" upper="3.14159" velocity="0.0"/>
    </joint>
    <joint name="Leg5_Leg9" type="revolute">
       <parent link="Leg5"/>
       <child  link="Leg9"/>
       <origin rpy="0 0 0" xyz="0 1.7548494149437095 0" />
     <axis xyz="1 0 0"/>
       <limit effort="0.0" lower="-3.14159" upper="3.14159" velocity="0.0"/>
    </joint>
    <joint name="Leg8_Leg10" type="revolute">
       <parent link="Leg8"/>
       <child  link="Leg10"/>
       <origin rpy="0 0 0" xyz="1.3763187194349045 0.5648342049219819 0" />
     <axis xyz="1 0 0"/>
       <limit effort="0.0" lower="-3.14159" upper="3.14159" velocity="0.0"/>
    </joint>
    <joint name="Leg7_Leg11" type="revolute">
       <parent link="Leg7"/>
       <child  link="Leg11"/>
       <origin rpy="0 0 0" xyz="0 1.2520473966576522 0" />
     <axis xyz="1 0 0"/>
       <limit effort="0.0" lower="-3.14159" upper="3.14159" velocity="0.0"/>
    </joint>
    <joint name="Leg6_Leg12" type="revolute">
       <parent link="Leg6"/>
       <child  link="Leg12"/>
       <origin rpy="0 0 0" xyz="0.6525083498051459 2.2542189644817694 0" />
     <axis xyz="1 0 0"/>
       <limit effort="0.0" lower="-3.14159" upper="3.14159" velocity="0.0"/>
    </joint>
    <joint name="Leg8_Leg13" type="revolute">
       <parent link="Leg8"/>
       <child  link="Leg13"/>
       <origin rpy="0 0 0" xyz="1.3763187194349045 1.1296684098439638 0" />
     <axis xyz="1 0 0"/>
       <limit effort="0.0" lower="-3.14159" upper="3.14159" velocity="0.0"/>
    </joint>
    <joint name="Leg11_Leg14" type="revolute">
       <parent link="Leg11"/>
       <child  link="Leg14"/>
       <origin rpy="0 0 0" xyz="1.3590584531020737 0 1.3412312454635205" />
     <axis xyz="1 0 0"/>
       <limit effort="0.0" lower="-3.14159" upper="3.14159" velocity="0.0"/>
    </joint>
    <joint name="Leg14_Leg15" type="revolute">
       <parent link="Leg14"/>
       <child  link="Leg15"/>
       <origin rpy="0 0 0" xyz="1.5694226895308103 0 0" />
     <axis xyz="1 0 0"/>
       <limit effort="0.0" lower="-3.14159" upper="3.14159" velocity="0.0"/>
    </joint>
    <joint name="Leg11_Leg16" type="revolute">
       <parent link="Leg11"/>
       <child  link="Leg16"/>
       <origin rpy="0 0 0" xyz="1.3590584531020737 0.6031775211370594 1.3412312454635205" />
     <axis xyz="1 0 0"/>
       <limit effort="0.0" lower="-3.14159" upper="3.14159" velocity="0.0"/>
    </joint>
    <joint name="Leg12_Leg17" type="revolute">
       <parent link="Leg12"/>
       <child  link="Leg17"/>
       <origin rpy="0 0 0" xyz="1.439866206330326 0.8423469697846463 0" />
     <axis xyz="1 0 0"/>
       <limit effort="0.0" lower="-3.14159" upper="3.14159" velocity="0.0"/>
    </joint>
    <joint name="Leg3_Leg18" type="revolute">
       <parent link="Leg3"/>
       <child  link="Leg18"/>
       <origin rpy="0 0 0" xyz="2.9562553478336433 1.0826119894591812 0" />
     <axis xyz="1 0 0"/>
       <limit effort="0.0" lower="-3.14159" upper="3.14159" velocity="0.0"/>
    </joint>
    <joint name="Leg7_Leg19" type="revolute">
       <parent link="Leg7"/>
       <child  link="Leg19"/>
       <origin rpy="0 0 0" xyz="1.3091112061013643 1.2520473966576522 0" />
     <axis xyz="1 0 0"/>
       <limit effort="0.0" lower="-3.14159" upper="3.14159" velocity="0.0"/>
    </joint>
    <joint name="Leg2_Leg20" type="revolute">
       <parent link="Leg2"/>
       <child  link="Leg20"/>
       <origin rpy="0 0 0" xyz="0 0.844454482475094 0.9745612239549359" />
     <axis xyz="1 0 0"/>
       <limit effort="0.0" lower="-3.14159" upper="3.14159" velocity="0.0"/>
    </joint>
    <joint name="Leg10_Leg21" type="revolute">
       <parent link="Leg10"/>
       <child  link="Leg21"/>
       <origin rpy="0 0 0" xyz="1.0937256233757915 0.9806984449604416 0" />
     <axis xyz="1 0 0"/>
       <limit effort="0.0" lower="-3.14159" upper="3.14159" velocity="0.0"/>
    </joint>
    <joint name="Leg21_Leg22" type="revolute">
       <parent link="Leg21"/>
       <child  link="Leg22"/>
       <origin rpy="0 0 0" xyz="1.994983820463479 0 0" />
     <axis xyz="1 0 0"/>
       <limit effort="0.0" lower="-3.14159" upper="3.14159" velocity="0.0"/>
    </joint>
    <joint name="Leg14_Leg23" type="revolute">
       <parent link="Leg14"/>
       <child  link="Leg23"/>
       <origin rpy="0 0 0" xyz="1.5694226895308103 1.0593673921977773 0" />
     <axis xyz="1 0 0"/>
       <limit effort="0.0" lower="-3.14159" upper="3.14159" velocity="0.0"/>
    </joint>
    <joint name="Leg16_Leg24" type="revolute">
       <parent link="Leg16"/>
       <child  link="Leg24"/>
       <origin rpy="0 0 0" xyz="0.770953919572936 0 0.8739903099113615" />
     <axis xyz="1 0 0"/>
       <limit effort="0.0" lower="-3.14159" upper="3.14159" velocity="0.0"/>
    </joint>
    <joint name="Leg4_Leg25" type="revolute">
       <parent link="Leg4"/>
       <child  link="Leg25"/>
       <origin rpy="0 0 0" xyz="0.8182369606524262 2.6544448300907977 0" />
     <axis xyz="1 0 0"/>
       <limit effort="0.0" lower="-3.14159" upper="3.14159" velocity="0.0"/>
    </joint>
    <joint name="Leg25_Leg26" type="revolute">
       <parent link="Leg25"/>
       <child  link="Leg26"/>
       <origin rpy="0 0 0" xyz="2.5504963653516155 0 0" />
     <axis xyz="1 0 0"/>
       <limit effort="0.0" lower="-3.14159" upper="3.14159" velocity="0.0"/>
    </joint>
    <joint name="Leg10_Leg27" type="revolute">
       <parent link="Leg10"/>
       <child  link="Leg27"/>
       <origin rpy="0 0 0" xyz="1.0937256233757915 0.9806984449604416 0.5721669194506028" />
     <axis xyz="1 0 0"/>
       <limit effort="0.0" lower="-3.14159" upper="3.14159" velocity="0.0"/>
    </joint>
    <joint name="Leg25_Leg28" type="revolute">
       <parent link="Leg25"/>
       <child  link="Leg28"/>
       <origin rpy="0 0 0" xyz="2.5504963653516155 0.5162751510288055 0" />
     <axis xyz="1 0 0"/>
       <limit effort="0.0" lower="-3.14159" upper="3.14159" velocity="0.0"/>
    </joint>
</robot>