<robot name = "robot">
    <link name="Torso">
        <inertial>
            <origin xyz="0 0 0.8264118977065092" rpy="0 0 0"/>
            <mass value="1" />
            <inertia ixx="100" ixy="0" ixz="0" iyy="100" iyz="0" izz="100" />
        </inertial>
        <visual>
            <origin xyz="0 0 0.8264118977065092" rpy="0 0 0"/>
            <geometry>
                <box size="2.3556466779158907 1.7217240051611795 1.6528237954130185" />
            </geometry>
            <material name="Green">
                <color rgba="0 180.0 0.0 1.0"/>
            </material>
        </visual>
        <collision>
            <origin xyz="0 0 0.8264118977065092" rpy="0 0 0"/>
            <geometry>
                <box size="2.3556466779158907 1.7217240051611795 1.6528237954130185" />
            </geometry>
        </collision>
    </link>
    <link name="Leg1">
        <inertial>
            <origin xyz="0 1.0355704140702764 0" rpy="0 0 0"/>
            <mass value="1" />
            <inertia ixx="100" ixy="0" ixz="0" iyy="100" iyz="0" izz="100" />
        </inertial>
        <visual>
            <origin xyz="0 1.0355704140702764 0" rpy="0 0 0"/>
            <geometry>
                <box size="1.3674729122871347 2.071140828140553 1.0024905275018932" />
            </geometry>
            <material name="Green">
                <color rgba="0 180.0 0.0 1.0"/>
            </material>
        </visual>
        <collision>
            <origin xyz="0 1.0355704140702764 0" rpy="0 0 0"/>
            <geometry>
                <box size="1.3674729122871347 2.071140828140553 1.0024905275018932" />
            </geometry>
        </collision>
    </link>
    <link name="Leg2">
        <inertial>
            <origin xyz="1.0010923766383746 0 0" rpy="0 0 0"/>
            <mass value="1" />
            <inertia ixx="100" ixy="0" ixz="0" iyy="100" iyz="0" izz="100" />
        </inertial>
        <visual>
            <origin xyz="1.0010923766383746 0 0" rpy="0 0 0"/>
            <geometry>
                <box size="2.002184753276749 1.6170465831619862 2.949547668178715" />
            </geometry>
            <material name="Blue">
                <color rgba="0 1.0 1.0 1.0"/>
            </material>
        </visual>
        <collision>
            <origin xyz="1.0010923766383746 0 0" rpy="0 0 0"/>
            <geometry>
                <box size="2.002184753276749 1.6170465831619862 2.949547668178715" />
            </geometry>
        </collision>
    </link>
    <link name="Leg3">
        <inertial>
            <origin xyz="0 1.4576556398666631 0" rpy="0 0 0"/>
            <mass value="1" />
            <inertia ixx="100" ixy="0" ixz="0" iyy="100" iyz="0" izz="100" />
        </inertial>
        <visual>
            <origin xyz="0 1.4576556398666631 0" rpy="0 0 0"/>
            <geometry>
                <box size="2.147529217002774 2.9153112797333263 2.92769937362357" />
            </geometry>
            <material name="Green">
                <color rgba="0 180.0 0.0 1.0"/>
            </material>
        </visual>
        <collision>
            <origin xyz="0 1.4576556398666631 0" rpy="0 0 0"/>
            <geometry>
                <box size="2.147529217002774 2.9153112797333263 2.92769937362357" />
            </geometry>
        </collision>
    </link>
    <link name="Leg4">
        <inertial>
            <origin xyz="1.1772576571146907 0 0" rpy="0 0 0"/>
            <mass value="1" />
            <inertia ixx="100" ixy="0" ixz="0" iyy="100" iyz="0" izz="100" />
        </inertial>
        <visual>
            <origin xyz="1.1772576571146907 0 0" rpy="0 0 0"/>
            <geometry>
                <box size="2.3545153142293813 1.073314949855537 1.4789996838699861" />
            </geometry>
            <material name="Green">
                <color rgba="0 180.0 0.0 1.0"/>
            </material>
        </visual>
        <collision>
            <origin xyz="1.1772576571146907 0 0" rpy="0 0 0"/>
            <geometry>
                <box size="2.3545153142293813 1.073314949855537 1.4789996838699861" />
            </geometry>
        </collision>
    </link>
    <link name="Leg5">
        <inertial>
            <origin xyz="0 0.9776834850446041 0" rpy="0 0 0"/>
            <mass value="1" />
            <inertia ixx="100" ixy="0" ixz="0" iyy="100" iyz="0" izz="100" />
        </inertial>
        <visual>
            <origin xyz="0 0.9776834850446041 0" rpy="0 0 0"/>
            <geometry>
                <box size="1.8101772892997061 1.9553669700892082 2.614253464768678" />
            </geometry>
            <material name="Green">
                <color rgba="0 180.0 0.0 1.0"/>
            </material>
        </visual>
        <collision>
            <origin xyz="0 0.9776834850446041 0" rpy="0 0 0"/>
            <geometry>
                <box size="1.8101772892997061 1.9553669700892082 2.614253464768678" />
            </geometry>
        </collision>
    </link>
    <link name="Leg6">
        <inertial>
            <origin xyz="0 0 0.9426052099211432" rpy="0 0 0"/>
            <mass value="1" />
            <inertia ixx="100" ixy="0" ixz="0" iyy="100" iyz="0" izz="100" />
        </inertial>
        <visual>
            <origin xyz="0 0 0.9426052099211432" rpy="0 0 0"/>
            <geometry>
                <box size="1.1873760880352595 1.4459426876963195 1.8852104198422863" />
            </geometry>
            <material name="Green">
                <color rgba="0 180.0 0.0 1.0"/>
            </material>
        </visual>
        <collision>
            <origin xyz="0 0 0.9426052099211432" rpy="0 0 0"/>
            <geometry>
                <box size="1.1873760880352595 1.4459426876963195 1.8852104198422863" />
            </geometry>
        </collision>
    </link>
    <link name="Leg7">
        <inertial>
            <origin xyz="0 0 0.7219979642001039" rpy="0 0 0"/>
            <mass value="1" />
            <inertia ixx="100" ixy="0" ixz="0" iyy="100" iyz="0" izz="100" />
        </inertial>
        <visual>
            <origin xyz="0 0 0.7219979642001039" rpy="0 0 0"/>
            <geometry>
                <box size="1.9374016963099414 2.3801600732161665 1.4439959284002077" />
            </geometry>
            <material name="Blue">
                <color rgba="0 1.0 1.0 1.0"/>
            </material>
        </visual>
        <collision>
            <origin xyz="0 0 0.7219979642001039" rpy="0 0 0"/>
            <geometry>
                <box size="1.9374016963099414 2.3801600732161665 1.4439959284002077" />
            </geometry>
        </collision>
    </link>
    <link name="Leg8">
        <inertial>
            <origin xyz="0 0 0.8915740360465892" rpy="0 0 0"/>
            <mass value="1" />
            <inertia ixx="100" ixy="0" ixz="0" iyy="100" iyz="0" izz="100" />
        </inertial>
        <visual>
            <origin xyz="0 0 0.8915740360465892" rpy="0 0 0"/>
            <geometry>
                <box size="1.0882864038654916 1.282520358945237 1.7831480720931785" />
            </geometry>
            <material name="Green">
                <color rgba="0 180.0 0.0 1.0"/>
            </material>
        </visual>
        <collision>
            <origin xyz="0 0 0.8915740360465892" rpy="0 0 0"/>
            <geometry>
                <box size="1.0882864038654916 1.282520358945237 1.7831480720931785" />
            </geometry>
        </collision>
    </link>
    <link name="Leg9">
        <inertial>
            <origin xyz="0 0 1.1572046359010124" rpy="0 0 0"/>
            <mass value="1" />
            <inertia ixx="100" ixy="0" ixz="0" iyy="100" iyz="0" izz="100" />
        </inertial>
        <visual>
            <origin xyz="0 0 1.1572046359010124" rpy="0 0 0"/>
            <geometry>
                <box size="1.9604357543269013 2.6652459330616685 2.314409271802025" />
            </geometry>
            <material name="Blue">
                <color rgba="0 1.0 1.0 1.0"/>
            </material>
        </visual>
        <collision>
            <origin xyz="0 0 1.1572046359010124" rpy="0 0 0"/>
            <geometry>
                <box size="1.9604357543269013 2.6652459330616685 2.314409271802025" />
            </geometry>
        </collision>
    </link>
    <link name="Leg10">
        <inertial>
            <origin xyz="0 0 1.1541709715577304" rpy="0 0 0"/>
            <mass value="1" />
            <inertia ixx="100" ixy="0" ixz="0" iyy="100" iyz="0" izz="100" />
        </inertial>
        <visual>
            <origin xyz="0 0 1.1541709715577304" rpy="0 0 0"/>
            <geometry>
                <box size="1.0541719126564908 1.2139772668376145 2.308341943115461" />
            </geometry>
            <material name="Blue">
                <color rgba="0 1.0 1.0 1.0"/>
            </material>
        </visual>
        <collision>
            <origin xyz="0 0 1.1541709715577304" rpy="0 0 0"/>
            <geometry>
                <box size="1.0541719126564908 1.2139772668376145 2.308341943115461" />
            </geometry>
        </collision>
    </link>
    <link name="Leg11">
        <inertial>
            <origin xyz="0 0 0.9993074321796833" rpy="0 0 0"/>
            <mass value="1" />
            <inertia ixx="100" ixy="0" ixz="0" iyy="100" iyz="0" izz="100" />
        </inertial>
        <visual>
            <origin xyz="0 0 0.9993074321796833" rpy="0 0 0"/>
            <geometry>
                <box size="2.1675553119476296 2.3015438135803366 1.9986148643593666" />
            </geometry>
            <material name="Green">
                <color rgba="0 180.0 0.0 1.0"/>
            </material>
        </visual>
        <collision>
            <origin xyz="0 0 0.9993074321796833" rpy="0 0 0"/>
            <geometry>
                <box size="2.1675553119476296 2.3015438135803366 1.9986148643593666" />
            </geometry>
        </collision>
    </link>
    <link name="Leg12">
        <inertial>
            <origin xyz="0 0.5850588579995287 0" rpy="0 0 0"/>
            <mass value="1" />
            <inertia ixx="100" ixy="0" ixz="0" iyy="100" iyz="0" izz="100" />
        </inertial>
        <visual>
            <origin xyz="0 0.5850588579995287 0" rpy="0 0 0"/>
            <geometry>
                <box size="2.0023788433773677 1.1701177159990575 2.711538262134371" />
            </geometry>
            <material name="Green">
                <color rgba="0 180.0 0.0 1.0"/>
            </material>
        </visual>
        <collision>
            <origin xyz="0 0.5850588579995287 0" rpy="0 0 0"/>
            <geometry>
                <box size="2.0023788433773677 1.1701177159990575 2.711538262134371" />
            </geometry>
        </collision>
    </link>
    <link name="Leg13">
        <inertial>
            <origin xyz="0.5298194718421131 0 0" rpy="0 0 0"/>
            <mass value="1" />
            <inertia ixx="100" ixy="0" ixz="0" iyy="100" iyz="0" izz="100" />
        </inertial>
        <visual>
            <origin xyz="0.5298194718421131 0 0" rpy="0 0 0"/>
            <geometry>
                <box size="1.0596389436842262 1.4992538021072896 1.1176401942178427" />
            </geometry>
            <material name="Green">
                <color rgba="0 180.0 0.0 1.0"/>
            </material>
        </visual>
        <collision>
            <origin xyz="0.5298194718421131 0 0" rpy="0 0 0"/>
            <geometry>
                <box size="1.0596389436842262 1.4992538021072896 1.1176401942178427" />
            </geometry>
        </collision>
    </link>
    <link name="Leg14">
        <inertial>
            <origin xyz="0.5157621614029525 0 0" rpy="0 0 0"/>
            <mass value="1" />
            <inertia ixx="100" ixy="0" ixz="0" iyy="100" iyz="0" izz="100" />
        </inertial>
        <visual>
            <origin xyz="0.5157621614029525 0 0" rpy="0 0 0"/>
            <geometry>
                <box size="1.031524322805905 2.657053888387666 1.8039194449656497" />
            </geometry>
            <material name="Green">
                <color rgba="0 180.0 0.0 1.0"/>
            </material>
        </visual>
        <collision>
            <origin xyz="0.5157621614029525 0 0" rpy="0 0 0"/>
            <geometry>
                <box size="1.031524322805905 2.657053888387666 1.8039194449656497" />
            </geometry>
        </collision>
    </link>
    <link name="Leg15">
        <inertial>
            <origin xyz="0.6968902811643473 0 0" rpy="0 0 0"/>
            <mass value="1" />
            <inertia ixx="100" ixy="0" ixz="0" iyy="100" iyz="0" izz="100" />
        </inertial>
        <visual>
            <origin xyz="0.6968902811643473 0 0" rpy="0 0 0"/>
            <geometry>
                <box size="1.3937805623286945 2.0567428183060774 1.9229661880103353" />
            </geometry>
            <material name="Blue">
                <color rgba="0 1.0 1.0 1.0"/>
            </material>
        </visual>
        <collision>
            <origin xyz="0.6968902811643473 0 0" rpy="0 0 0"/>
            <geometry>
                <box size="1.3937805623286945 2.0567428183060774 1.9229661880103353" />
            </geometry>
        </collision>
    </link>
    <link name="Leg16">
        <inertial>
            <origin xyz="0 0 0.545685015656323" rpy="0 0 0"/>
            <mass value="1" />
            <inertia ixx="100" ixy="0" ixz="0" iyy="100" iyz="0" izz="100" />
        </inertial>
        <visual>
            <origin xyz="0 0 0.545685015656323" rpy="0 0 0"/>
            <geometry>
                <box size="1.5983614405729558 2.4209569895606524 1.091370031312646" />
            </geometry>
            <material name="Green">
                <color rgba="0 180.0 0.0 1.0"/>
            </material>
        </visual>
        <collision>
            <origin xyz="0 0 0.545685015656323" rpy="0 0 0"/>
            <geometry>
                <box size="1.5983614405729558 2.4209569895606524 1.091370031312646" />
            </geometry>
        </collision>
    </link>
    <link name="Leg17">
        <inertial>
            <origin xyz="0 1.291404009835206 0" rpy="0 0 0"/>
            <mass value="1" />
            <inertia ixx="100" ixy="0" ixz="0" iyy="100" iyz="0" izz="100" />
        </inertial>
        <visual>
            <origin xyz="0 1.291404009835206 0" rpy="0 0 0"/>
            <geometry>
                <box size="2.325067117048043 2.582808019670412 1.1497514218663323" />
            </geometry>
            <material name="Blue">
                <color rgba="0 1.0 1.0 1.0"/>
            </material>
        </visual>
        <collision>
            <origin xyz="0 1.291404009835206 0" rpy="0 0 0"/>
            <geometry>
                <box size="2.325067117048043 2.582808019670412 1.1497514218663323" />
            </geometry>
        </collision>
    </link>
    <link name="Leg18">
        <inertial>
            <origin xyz="1.2624265003180044 0 0" rpy="0 0 0"/>
            <mass value="1" />
            <inertia ixx="100" ixy="0" ixz="0" iyy="100" iyz="0" izz="100" />
        </inertial>
        <visual>
            <origin xyz="1.2624265003180044 0 0" rpy="0 0 0"/>
            <geometry>
                <box size="2.524853000636009 2.6649179290592775 2.4409174802543934" />
            </geometry>
            <material name="Blue">
                <color rgba="0 1.0 1.0 1.0"/>
            </material>
        </visual>
        <collision>
            <origin xyz="1.2624265003180044 0 0" rpy="0 0 0"/>
            <geometry>
                <box size="2.524853000636009 2.6649179290592775 2.4409174802543934" />
            </geometry>
        </collision>
    </link>
    <link name="Leg19">
        <inertial>
            <origin xyz="0 0.7478654335831264 0" rpy="0 0 0"/>
            <mass value="1" />
            <inertia ixx="100" ixy="0" ixz="0" iyy="100" iyz="0" izz="100" />
        </inertial>
        <visual>
            <origin xyz="0 0.7478654335831264 0" rpy="0 0 0"/>
            <geometry>
                <box size="2.6584271104919246 1.4957308671662528 2.120876194595934" />
            </geometry>
            <material name="Green">
                <color rgba="0 180.0 0.0 1.0"/>
            </material>
        </visual>
        <collision>
            <origin xyz="0 0.7478654335831264 0" rpy="0 0 0"/>
            <geometry>
                <box size="2.6584271104919246 1.4957308671662528 2.120876194595934" />
            </geometry>
        </collision>
    </link>
    <link name="Leg20">
        <inertial>
            <origin xyz="1.3366521427918117 0 0" rpy="0 0 0"/>
            <mass value="1" />
            <inertia ixx="100" ixy="0" ixz="0" iyy="100" iyz="0" izz="100" />
        </inertial>
        <visual>
            <origin xyz="1.3366521427918117 0 0" rpy="0 0 0"/>
            <geometry>
                <box size="2.6733042855836233 2.2015133512166734 1.453894101556484" />
            </geometry>
            <material name="Blue">
                <color rgba="0 1.0 1.0 1.0"/>
            </material>
        </visual>
        <collision>
            <origin xyz="1.3366521427918117 0 0" rpy="0 0 0"/>
            <geometry>
                <box size="2.6733042855836233 2.2015133512166734 1.453894101556484" />
            </geometry>
        </collision>
    </link>
    <link name="Leg21">
        <inertial>
            <origin xyz="0 1.3364502816003196 0" rpy="0 0 0"/>
            <mass value="1" />
            <inertia ixx="100" ixy="0" ixz="0" iyy="100" iyz="0" izz="100" />
        </inertial>
        <visual>
            <origin xyz="0 1.3364502816003196 0" rpy="0 0 0"/>
            <geometry>
                <box size="2.3764207931215915 2.6729005632006393 2.612983380537108" />
            </geometry>
            <material name="Blue">
                <color rgba="0 1.0 1.0 1.0"/>
            </material>
        </visual>
        <collision>
            <origin xyz="0 1.3364502816003196 0" rpy="0 0 0"/>
            <geometry>
                <box size="2.3764207931215915 2.6729005632006393 2.612983380537108" />
            </geometry>
        </collision>
    </link>
    <link name="Leg22">
        <inertial>
            <origin xyz="0.9931566861697945 0 0" rpy="0 0 0"/>
            <mass value="1" />
            <inertia ixx="100" ixy="0" ixz="0" iyy="100" iyz="0" izz="100" />
        </inertial>
        <visual>
            <origin xyz="0.9931566861697945 0 0" rpy="0 0 0"/>
            <geometry>
                <box size="1.986313372339589 2.7137174521207665 1.9881960019804628" />
            </geometry>
            <material name="Blue">
                <color rgba="0 1.0 1.0 1.0"/>
            </material>
        </visual>
        <collision>
            <origin xyz="0.9931566861697945 0 0" rpy="0 0 0"/>
            <geometry>
                <box size="1.986313372339589 2.7137174521207665 1.9881960019804628" />
            </geometry>
        </collision>
    </link>
    <link name="Leg23">
        <inertial>
            <origin xyz="0 0 0.8540444659622856" rpy="0 0 0"/>
            <mass value="1" />
            <inertia ixx="100" ixy="0" ixz="0" iyy="100" iyz="0" izz="100" />
        </inertial>
        <visual>
            <origin xyz="0 0 0.8540444659622856" rpy="0 0 0"/>
            <geometry>
                <box size="2.5406411985808637 2.605412891512501 1.7080889319245711" />
            </geometry>
            <material name="Green">
                <color rgba="0 180.0 0.0 1.0"/>
            </material>
        </visual>
        <collision>
            <origin xyz="0 0 0.8540444659622856" rpy="0 0 0"/>
            <geometry>
                <box size="2.5406411985808637 2.605412891512501 1.7080889319245711" />
            </geometry>
        </collision>
    </link>
    <link name="Leg24">
        <inertial>
            <origin xyz="0 0 1.4172125032407634" rpy="0 0 0"/>
            <mass value="1" />
            <inertia ixx="100" ixy="0" ixz="0" iyy="100" iyz="0" izz="100" />
        </inertial>
        <visual>
            <origin xyz="0 0 1.4172125032407634" rpy="0 0 0"/>
            <geometry>
                <box size="1.635879961894799 2.504530509441621 2.834425006481527" />
            </geometry>
            <material name="Green">
                <color rgba="0 180.0 0.0 1.0"/>
            </material>
        </visual>
        <collision>
            <origin xyz="0 0 1.4172125032407634" rpy="0 0 0"/>
            <geometry>
                <box size="1.635879961894799 2.504530509441621 2.834425006481527" />
            </geometry>
        </collision>
    </link>
    <link name="Leg25">
        <inertial>
            <origin xyz="0.6263150355486828 0 0" rpy="0 0 0"/>
            <mass value="1" />
            <inertia ixx="100" ixy="0" ixz="0" iyy="100" iyz="0" izz="100" />
        </inertial>
        <visual>
            <origin xyz="0.6263150355486828 0 0" rpy="0 0 0"/>
            <geometry>
                <box size="1.2526300710973657 1.3992808468538027 2.6091991308563207" />
            </geometry>
            <material name="Green">
                <color rgba="0 180.0 0.0 1.0"/>
            </material>
        </visual>
        <collision>
            <origin xyz="0.6263150355486828 0 0" rpy="0 0 0"/>
            <geometry>
                <box size="1.2526300710973657 1.3992808468538027 2.6091991308563207" />
            </geometry>
        </collision>
    </link>
    <joint name="Torso_Leg1" type="revolute">
       <parent link="Torso"/>
       <child  link="Leg1"/>
       <origin rpy="0 0 0" xyz="0 0.8608620025805898 0.8264118977065092" />
     <axis xyz="1 0 0"/>
       <limit effort="0.0" lower="-3.14159" upper="3.14159" velocity="0.0"/>
    </joint>
    <joint name="Torso_Leg2" type="revolute">
       <parent link="Torso"/>
       <child  link="Leg2"/>
       <origin rpy="0 0 0" xyz="0.6837364561435674 1.0355704140702764 0" />
     <axis xyz="1 0 0"/>
       <limit effort="0.0" lower="-3.14159" upper="3.14159" velocity="0.0"/>
    </joint>
    <joint name="Leg1_Leg3" type="revolute">
       <parent link="Leg1"/>
       <child  link="Leg3"/>
       <origin rpy="0 0 0" xyz="1.0010923766383746 0.8085232915809931 0" />
     <axis xyz="1 0 0"/>
       <limit effort="0.0" lower="-3.14159" upper="3.14159" velocity="0.0"/>
    </joint>
    <joint name="Leg3_Leg4" type="revolute">
       <parent link="Leg3"/>
       <child  link="Leg4"/>
       <origin rpy="0 0 0" xyz="2.3545153142293813 0 0" />
     <axis xyz="1 0 0"/>
       <limit effort="0.0" lower="-3.14159" upper="3.14159" velocity="0.0"/>
    </joint>
    <joint name="Leg3_Leg5" type="revolute">
       <parent link="Leg3"/>
       <child  link="Leg5"/>
       <origin rpy="0 0 0" xyz="2.3545153142293813 0.5366574749277685 0" />
     <axis xyz="1 0 0"/>
       <limit effort="0.0" lower="-3.14159" upper="3.14159" velocity="0.0"/>
    </joint>
    <joint name="Torso_Leg6" type="revolute">
       <parent link="Torso"/>
       <child  link="Leg6"/>
       <origin rpy="0 0 0" xyz="0.6837364561435674 1.0355704140702764 0.5012452637509466" />
     <axis xyz="1 0 0"/>
       <limit effort="0.0" lower="-3.14159" upper="3.14159" velocity="0.0"/>
    </joint>
    <joint name="Leg5_Leg7" type="revolute">
       <parent link="Leg5"/>
       <child  link="Leg7"/>
       <origin rpy="0 0 0" xyz="0 0 1.8852104198422863" />
     <axis xyz="1 0 0"/>
       <limit effort="0.0" lower="-3.14159" upper="3.14159" velocity="0.0"/>
    </joint>
    <joint name="Leg6_Leg8" type="revolute">
       <parent link="Leg6"/>
       <child  link="Leg8"/>
       <origin rpy="0 0 0" xyz="0 0 1.4439959284002077" />
     <axis xyz="1 0 0"/>
       <limit effort="0.0" lower="-3.14159" upper="3.14159" velocity="0.0"/>
    </joint>
    <joint name="Leg2_Leg9" type="revolute">
       <parent link="Leg2"/>
       <child  link="Leg9"/>
       <origin rpy="0 0 0" xyz="0 1.4576556398666631 1.463849686811785" />
     <axis xyz="1 0 0"/>
       <limit effort="0.0" lower="-3.14159" upper="3.14159" velocity="0.0"/>
    </joint>
    <joint name="Leg3_Leg10" type="revolute">
       <parent link="Leg3"/>
       <child  link="Leg10"/>
       <origin rpy="0 0 0" xyz="2.3545153142293813 0.5366574749277685 0.7394998419349931" />
     <axis xyz="1 0 0"/>
       <limit effort="0.0" lower="-3.14159" upper="3.14159" velocity="0.0"/>
    </joint>
    <joint name="Leg10_Leg11" type="revolute">
       <parent link="Leg10"/>
       <child  link="Leg11"/>
       <origin rpy="0 0 0" xyz="0 0 1.9986148643593666" />
     <axis xyz="1 0 0"/>
       <limit effort="0.0" lower="-3.14159" upper="3.14159" velocity="0.0"/>
    </joint>
    <joint name="Leg10_Leg12" type="revolute">
       <parent link="Leg10"/>
       <child  link="Leg12"/>
       <origin rpy="0 0 0" xyz="0 1.1507719067901683 1.9986148643593666" />
     <axis xyz="1 0 0"/>
       <limit effort="0.0" lower="-3.14159" upper="3.14159" velocity="0.0"/>
    </joint>
    <joint name="Leg11_Leg13" type="revolute">
       <parent link="Leg11"/>
       <child  link="Leg13"/>
       <origin rpy="0 0 0" xyz="1.0011894216886839 0.5850588579995287 0" />
     <axis xyz="1 0 0"/>
       <limit effort="0.0" lower="-3.14159" upper="3.14159" velocity="0.0"/>
    </joint>
    <joint name="Leg1_Leg14" type="revolute">
       <parent link="Leg1"/>
       <child  link="Leg14"/>
       <origin rpy="0 0 0" xyz="2.002184753276749 0.8085232915809931 0" />
     <axis xyz="1 0 0"/>
       <limit effort="0.0" lower="-3.14159" upper="3.14159" velocity="0.0"/>
    </joint>
    <joint name="Leg7_Leg15" type="revolute">
       <parent link="Leg7"/>
       <child  link="Leg15"/>
       <origin rpy="0 0 0" xyz="0.5441432019327458 0 0.8915740360465892" />
     <axis xyz="1 0 0"/>
       <limit effort="0.0" lower="-3.14159" upper="3.14159" velocity="0.0"/>
    </joint>
    <joint name="Leg14_Leg16" type="revolute">
       <parent link="Leg14"/>
       <child  link="Leg16"/>
       <origin rpy="0 0 0" xyz="0.6968902811643473 0 0.9614830940051676" />
     <axis xyz="1 0 0"/>
       <limit effort="0.0" lower="-3.14159" upper="3.14159" velocity="0.0"/>
    </joint>
    <joint name="Leg5_Leg17" type="revolute">
       <parent link="Leg5"/>
       <child  link="Leg17"/>
       <origin rpy="0 0 0" xyz="0 0.7229713438481598 1.8852104198422863" />
     <axis xyz="1 0 0"/>
       <limit effort="0.0" lower="-3.14159" upper="3.14159" velocity="0.0"/>
    </joint>
    <joint name="Leg15_Leg18" type="revolute">
       <parent link="Leg15"/>
       <child  link="Leg18"/>
       <origin rpy="0 0 0" xyz="0.7991807202864779 0 0.545685015656323" />
     <axis xyz="1 0 0"/>
       <limit effort="0.0" lower="-3.14159" upper="3.14159" velocity="0.0"/>
    </joint>
    <joint name="Leg18_Leg19" type="revolute">
       <parent link="Leg18"/>
       <child  link="Leg19"/>
       <origin rpy="0 0 0" xyz="0 1.4957308671662528 0" />
     <axis xyz="1 0 0"/>
       <limit effort="0.0" lower="-3.14159" upper="3.14159" velocity="0.0"/>
    </joint>
    <joint name="Leg6_Leg20" type="revolute">
       <parent link="Leg6"/>
       <child  link="Leg20"/>
       <origin rpy="0 0 0" xyz="0.9687008481549707 0 1.4439959284002077" />
     <axis xyz="1 0 0"/>
       <limit effort="0.0" lower="-3.14159" upper="3.14159" velocity="0.0"/>
    </joint>
    <joint name="Leg4_Leg21" type="revolute">
       <parent link="Leg4"/>
       <child  link="Leg21"/>
       <origin rpy="0 0 0" xyz="0 1.9553669700892082 0" />
     <axis xyz="1 0 0"/>
       <limit effort="0.0" lower="-3.14159" upper="3.14159" velocity="0.0"/>
    </joint>
    <joint name="Leg2_Leg22" type="revolute">
       <parent link="Leg2"/>
       <child  link="Leg22"/>
       <origin rpy="0 0 0" xyz="1.073764608501387 1.4576556398666631 1.463849686811785" />
     <axis xyz="1 0 0"/>
       <limit effort="0.0" lower="-3.14159" upper="3.14159" velocity="0.0"/>
    </joint>
    <joint name="Leg22_Leg23" type="revolute">
       <parent link="Leg22"/>
       <child  link="Leg23"/>
       <origin rpy="0 0 0" xyz="0 0 1.7080889319245711" />
     <axis xyz="1 0 0"/>
       <limit effort="0.0" lower="-3.14159" upper="3.14159" velocity="0.0"/>
    </joint>
    <joint name="Leg20_Leg24" type="revolute">
       <parent link="Leg20"/>
       <child  link="Leg24"/>
       <origin rpy="0 0 0" xyz="0 1.3364502816003196 1.306491690268554" />
     <axis xyz="1 0 0"/>
       <limit effort="0.0" lower="-3.14159" upper="3.14159" velocity="0.0"/>
    </joint>
    <joint name="Leg20_Leg25" type="revolute">
       <parent link="Leg20"/>
       <child  link="Leg25"/>
       <origin rpy="0 0 0" xyz="1.1882103965607957 1.3364502816003196 1.306491690268554" />
     <axis xyz="1 0 0"/>
       <limit effort="0.0" lower="-3.14159" upper="3.14159" velocity="0.0"/>
    </joint>
</robot>