<robot name = "robot">
    <link name="Torso">
        <inertial>
            <origin xyz="0 0 1.4224213099966068" rpy="0 0 0"/>
            <mass value="1" />
            <inertia ixx="100" ixy="0" ixz="0" iyy="100" iyz="0" izz="100" />
        </inertial>
        <visual>
            <origin xyz="0 0 1.4224213099966068" rpy="0 0 0"/>
            <geometry>
                <box size="2.8263497340117842 1.1838128823948033 2.8448426199932135" />
            </geometry>
            <material name="Green">
                <color rgba="0 180.0 0.0 1.0"/>
            </material>
        </visual>
        <collision>
            <origin xyz="0 0 1.4224213099966068" rpy="0 0 0"/>
            <geometry>
                <box size="2.8263497340117842 1.1838128823948033 2.8448426199932135" />
            </geometry>
        </collision>
    </link>
    <link name="Leg1">
        <inertial>
            <origin xyz="0 0 1.2702841860993481" rpy="0 0 0"/>
            <mass value="1" />
            <inertia ixx="100" ixy="0" ixz="0" iyy="100" iyz="0" izz="100" />
        </inertial>
        <visual>
            <origin xyz="0 0 1.2702841860993481" rpy="0 0 0"/>
            <geometry>
                <box size="1.758564487744752 1.4383588320131275 2.5405683721986962" />
            </geometry>
            <material name="Green">
                <color rgba="0 180.0 0.0 1.0"/>
            </material>
        </visual>
        <collision>
            <origin xyz="0 0 1.2702841860993481" rpy="0 0 0"/>
            <geometry>
                <box size="1.758564487744752 1.4383588320131275 2.5405683721986962" />
            </geometry>
        </collision>
    </link>
    <link name="Leg2">
        <inertial>
            <origin xyz="0 1.2358803569625645 0" rpy="0 0 0"/>
            <mass value="1" />
            <inertia ixx="100" ixy="0" ixz="0" iyy="100" iyz="0" izz="100" />
        </inertial>
        <visual>
            <origin xyz="0 1.2358803569625645 0" rpy="0 0 0"/>
            <geometry>
                <box size="1.3315093810614012 2.471760713925129 1.8865451462018668" />
            </geometry>
            <material name="Green">
                <color rgba="0 180.0 0.0 1.0"/>
            </material>
        </visual>
        <collision>
            <origin xyz="0 1.2358803569625645 0" rpy="0 0 0"/>
            <geometry>
                <box size="1.3315093810614012 2.471760713925129 1.8865451462018668" />
            </geometry>
        </collision>
    </link>
    <link name="Leg3">
        <inertial>
            <origin xyz="0 0 0.6580237207362585" rpy="0 0 0"/>
            <mass value="1" />
            <inertia ixx="100" ixy="0" ixz="0" iyy="100" iyz="0" izz="100" />
        </inertial>
        <visual>
            <origin xyz="0 0 0.6580237207362585" rpy="0 0 0"/>
            <geometry>
                <box size="1.3065562718944117 1.606686146388864 1.316047441472517" />
            </geometry>
            <material name="Green">
                <color rgba="0 180.0 0.0 1.0"/>
            </material>
        </visual>
        <collision>
            <origin xyz="0 0 0.6580237207362585" rpy="0 0 0"/>
            <geometry>
                <box size="1.3065562718944117 1.606686146388864 1.316047441472517" />
            </geometry>
        </collision>
    </link>
    <link name="Leg4">
        <inertial>
            <origin xyz="0.9250433281861815 0 0" rpy="0 0 0"/>
            <mass value="1" />
            <inertia ixx="100" ixy="0" ixz="0" iyy="100" iyz="0" izz="100" />
        </inertial>
        <visual>
            <origin xyz="0.9250433281861815 0 0" rpy="0 0 0"/>
            <geometry>
                <box size="1.850086656372363 1.3797443895710824 2.532222311652383" />
            </geometry>
            <material name="Green">
                <color rgba="0 180.0 0.0 1.0"/>
            </material>
        </visual>
        <collision>
            <origin xyz="0.9250433281861815 0 0" rpy="0 0 0"/>
            <geometry>
                <box size="1.850086656372363 1.3797443895710824 2.532222311652383" />
            </geometry>
        </collision>
    </link>
    <link name="Leg5">
        <inertial>
            <origin xyz="1.3769248833832552 0 0" rpy="0 0 0"/>
            <mass value="1" />
            <inertia ixx="100" ixy="0" ixz="0" iyy="100" iyz="0" izz="100" />
        </inertial>
        <visual>
            <origin xyz="1.3769248833832552 0 0" rpy="0 0 0"/>
            <geometry>
                <box size="2.7538497667665105 1.2545523027925336 1.7295775187760158" />
            </geometry>
            <material name="Blue">
                <color rgba="0 1.0 1.0 1.0"/>
            </material>
        </visual>
        <collision>
            <origin xyz="1.3769248833832552 0 0" rpy="0 0 0"/>
            <geometry>
                <box size="2.7538497667665105 1.2545523027925336 1.7295775187760158" />
            </geometry>
        </collision>
    </link>
    <link name="Leg6">
        <inertial>
            <origin xyz="0.7537466280079373 0 0" rpy="0 0 0"/>
            <mass value="1" />
            <inertia ixx="100" ixy="0" ixz="0" iyy="100" iyz="0" izz="100" />
        </inertial>
        <visual>
            <origin xyz="0.7537466280079373 0 0" rpy="0 0 0"/>
            <geometry>
                <box size="1.5074932560158747 2.9056428185294347 2.2828591756631984" />
            </geometry>
            <material name="Green">
                <color rgba="0 180.0 0.0 1.0"/>
            </material>
        </visual>
        <collision>
            <origin xyz="0.7537466280079373 0 0" rpy="0 0 0"/>
            <geometry>
                <box size="1.5074932560158747 2.9056428185294347 2.2828591756631984" />
            </geometry>
        </collision>
    </link>
    <link name="Leg7">
        <inertial>
            <origin xyz="0 0 1.1801580974668722" rpy="0 0 0"/>
            <mass value="1" />
            <inertia ixx="100" ixy="0" ixz="0" iyy="100" iyz="0" izz="100" />
        </inertial>
        <visual>
            <origin xyz="0 0 1.1801580974668722" rpy="0 0 0"/>
            <geometry>
                <box size="1.0985687532036559 1.3281778110991136 2.3603161949337443" />
            </geometry>
            <material name="Green">
                <color rgba="0 180.0 0.0 1.0"/>
            </material>
        </visual>
        <collision>
            <origin xyz="0 0 1.1801580974668722" rpy="0 0 0"/>
            <geometry>
                <box size="1.0985687532036559 1.3281778110991136 2.3603161949337443" />
            </geometry>
        </collision>
    </link>
    <link name="Leg8">
        <inertial>
            <origin xyz="0 0 0.8783757160890605" rpy="0 0 0"/>
            <mass value="1" />
            <inertia ixx="100" ixy="0" ixz="0" iyy="100" iyz="0" izz="100" />
        </inertial>
        <visual>
            <origin xyz="0 0 0.8783757160890605" rpy="0 0 0"/>
            <geometry>
                <box size="1.649267754289903 2.9265120370119897 1.756751432178121" />
            </geometry>
            <material name="Green">
                <color rgba="0 180.0 0.0 1.0"/>
            </material>
        </visual>
        <collision>
            <origin xyz="0 0 0.8783757160890605" rpy="0 0 0"/>
            <geometry>
                <box size="1.649267754289903 2.9265120370119897 1.756751432178121" />
            </geometry>
        </collision>
    </link>
    <link name="Leg9">
        <inertial>
            <origin xyz="0 1.3662184708930973 0" rpy="0 0 0"/>
            <mass value="1" />
            <inertia ixx="100" ixy="0" ixz="0" iyy="100" iyz="0" izz="100" />
        </inertial>
        <visual>
            <origin xyz="0 1.3662184708930973 0" rpy="0 0 0"/>
            <geometry>
                <box size="2.5190126128387096 2.7324369417861947 2.2495466673782616" />
            </geometry>
            <material name="Green">
                <color rgba="0 180.0 0.0 1.0"/>
            </material>
        </visual>
        <collision>
            <origin xyz="0 1.3662184708930973 0" rpy="0 0 0"/>
            <geometry>
                <box size="2.5190126128387096 2.7324369417861947 2.2495466673782616" />
            </geometry>
        </collision>
    </link>
    <link name="Leg10">
        <inertial>
            <origin xyz="0 0 1.2440215373149384" rpy="0 0 0"/>
            <mass value="1" />
            <inertia ixx="100" ixy="0" ixz="0" iyy="100" iyz="0" izz="100" />
        </inertial>
        <visual>
            <origin xyz="0 0 1.2440215373149384" rpy="0 0 0"/>
            <geometry>
                <box size="2.7693516387847508 1.6340465885897868 2.4880430746298767" />
            </geometry>
            <material name="Green">
                <color rgba="0 180.0 0.0 1.0"/>
            </material>
        </visual>
        <collision>
            <origin xyz="0 0 1.2440215373149384" rpy="0 0 0"/>
            <geometry>
                <box size="2.7693516387847508 1.6340465885897868 2.4880430746298767" />
            </geometry>
        </collision>
    </link>
    <link name="Leg11">
        <inertial>
            <origin xyz="0 0 0.5397191091371917" rpy="0 0 0"/>
            <mass value="1" />
            <inertia ixx="100" ixy="0" ixz="0" iyy="100" iyz="0" izz="100" />
        </inertial>
        <visual>
            <origin xyz="0 0 0.5397191091371917" rpy="0 0 0"/>
            <geometry>
                <box size="1.1978813603703191 2.422098190443272 1.0794382182743834" />
            </geometry>
            <material name="Green">
                <color rgba="0 180.0 0.0 1.0"/>
            </material>
        </visual>
        <collision>
            <origin xyz="0 0 0.5397191091371917" rpy="0 0 0"/>
            <geometry>
                <box size="1.1978813603703191 2.422098190443272 1.0794382182743834" />
            </geometry>
        </collision>
    </link>
    <link name="Leg12">
        <inertial>
            <origin xyz="0.67198163135695 0 0" rpy="0 0 0"/>
            <mass value="1" />
            <inertia ixx="100" ixy="0" ixz="0" iyy="100" iyz="0" izz="100" />
        </inertial>
        <visual>
            <origin xyz="0.67198163135695 0 0" rpy="0 0 0"/>
            <geometry>
                <box size="1.3439632627139 1.8393156042372873 2.218011137758207" />
            </geometry>
            <material name="Green">
                <color rgba="0 180.0 0.0 1.0"/>
            </material>
        </visual>
        <collision>
            <origin xyz="0.67198163135695 0 0" rpy="0 0 0"/>
            <geometry>
                <box size="1.3439632627139 1.8393156042372873 2.218011137758207" />
            </geometry>
        </collision>
    </link>
    <link name="Leg13">
        <inertial>
            <origin xyz="1.0433481527197683 0 0" rpy="0 0 0"/>
            <mass value="1" />
            <inertia ixx="100" ixy="0" ixz="0" iyy="100" iyz="0" izz="100" />
        </inertial>
        <visual>
            <origin xyz="1.0433481527197683 0 0" rpy="0 0 0"/>
            <geometry>
                <box size="2.0866963054395367 2.11535430210429 1.6495826321218874" />
            </geometry>
            <material name="Blue">
                <color rgba="0 1.0 1.0 1.0"/>
            </material>
        </visual>
        <collision>
            <origin xyz="1.0433481527197683 0 0" rpy="0 0 0"/>
            <geometry>
                <box size="2.0866963054395367 2.11535430210429 1.6495826321218874" />
            </geometry>
        </collision>
    </link>
    <link name="Leg14">
        <inertial>
            <origin xyz="0 0 1.4601749489539788" rpy="0 0 0"/>
            <mass value="1" />
            <inertia ixx="100" ixy="0" ixz="0" iyy="100" iyz="0" izz="100" />
        </inertial>
        <visual>
            <origin xyz="0 0 1.4601749489539788" rpy="0 0 0"/>
            <geometry>
                <box size="1.770872625370731 2.5229784044738146 2.9203498979079576" />
            </geometry>
            <material name="Green">
                <color rgba="0 180.0 0.0 1.0"/>
            </material>
        </visual>
        <collision>
            <origin xyz="0 0 1.4601749489539788" rpy="0 0 0"/>
            <geometry>
                <box size="1.770872625370731 2.5229784044738146 2.9203498979079576" />
            </geometry>
        </collision>
    </link>
    <link name="Leg15">
        <inertial>
            <origin xyz="0 0 0.6690036890430949" rpy="0 0 0"/>
            <mass value="1" />
            <inertia ixx="100" ixy="0" ixz="0" iyy="100" iyz="0" izz="100" />
        </inertial>
        <visual>
            <origin xyz="0 0 0.6690036890430949" rpy="0 0 0"/>
            <geometry>
                <box size="1.2171540751952357 2.6858675594883668 1.3380073780861899" />
            </geometry>
            <material name="Blue">
                <color rgba="0 1.0 1.0 1.0"/>
            </material>
        </visual>
        <collision>
            <origin xyz="0 0 0.6690036890430949" rpy="0 0 0"/>
            <geometry>
                <box size="1.2171540751952357 2.6858675594883668 1.3380073780861899" />
            </geometry>
        </collision>
    </link>
    <link name="Leg16">
        <inertial>
            <origin xyz="0 1.19593057993462 0" rpy="0 0 0"/>
            <mass value="1" />
            <inertia ixx="100" ixy="0" ixz="0" iyy="100" iyz="0" izz="100" />
        </inertial>
        <visual>
            <origin xyz="0 1.19593057993462 0" rpy="0 0 0"/>
            <geometry>
                <box size="2.77039000386383 2.39186115986924 2.4211123370786156" />
            </geometry>
            <material name="Blue">
                <color rgba="0 1.0 1.0 1.0"/>
            </material>
        </visual>
        <collision>
            <origin xyz="0 1.19593057993462 0" rpy="0 0 0"/>
            <geometry>
                <box size="2.77039000386383 2.39186115986924 2.4211123370786156" />
            </geometry>
        </collision>
    </link>
    <link name="Leg17">
        <inertial>
            <origin xyz="0 0.8311335755597584 0" rpy="0 0 0"/>
            <mass value="1" />
            <inertia ixx="100" ixy="0" ixz="0" iyy="100" iyz="0" izz="100" />
        </inertial>
        <visual>
            <origin xyz="0 0.8311335755597584 0" rpy="0 0 0"/>
            <geometry>
                <box size="2.226363988410889 1.6622671511195168 2.5330704189360125" />
            </geometry>
            <material name="Blue">
                <color rgba="0 1.0 1.0 1.0"/>
            </material>
        </visual>
        <collision>
            <origin xyz="0 0.8311335755597584 0" rpy="0 0 0"/>
            <geometry>
                <box size="2.226363988410889 1.6622671511195168 2.5330704189360125" />
            </geometry>
        </collision>
    </link>
    <link name="Leg18">
        <inertial>
            <origin xyz="0.8451263679510863 0 0" rpy="0 0 0"/>
            <mass value="1" />
            <inertia ixx="100" ixy="0" ixz="0" iyy="100" iyz="0" izz="100" />
        </inertial>
        <visual>
            <origin xyz="0.8451263679510863 0 0" rpy="0 0 0"/>
            <geometry>
                <box size="1.6902527359021726 2.852496630404242 2.0456780588393704" />
            </geometry>
            <material name="Green">
                <color rgba="0 180.0 0.0 1.0"/>
            </material>
        </visual>
        <collision>
            <origin xyz="0.8451263679510863 0 0" rpy="0 0 0"/>
            <geometry>
                <box size="1.6902527359021726 2.852496630404242 2.0456780588393704" />
            </geometry>
        </collision>
    </link>
    <link name="Leg19">
        <inertial>
            <origin xyz="0 0 1.207801329754579" rpy="0 0 0"/>
            <mass value="1" />
            <inertia ixx="100" ixy="0" ixz="0" iyy="100" iyz="0" izz="100" />
        </inertial>
        <visual>
            <origin xyz="0 0 1.207801329754579" rpy="0 0 0"/>
            <geometry>
                <box size="1.774388951040833 1.5809974758193803 2.415602659509158" />
            </geometry>
            <material name="Green">
                <color rgba="0 180.0 0.0 1.0"/>
            </material>
        </visual>
        <collision>
            <origin xyz="0 0 1.207801329754579" rpy="0 0 0"/>
            <geometry>
                <box size="1.774388951040833 1.5809974758193803 2.415602659509158" />
            </geometry>
        </collision>
    </link>
    <link name="Leg20">
        <inertial>
            <origin xyz="0.7408348207819103 0 0" rpy="0 0 0"/>
            <mass value="1" />
            <inertia ixx="100" ixy="0" ixz="0" iyy="100" iyz="0" izz="100" />
        </inertial>
        <visual>
            <origin xyz="0.7408348207819103 0 0" rpy="0 0 0"/>
            <geometry>
                <box size="1.4816696415638206 2.1251297224307604 1.1081745251565789" />
            </geometry>
            <material name="Blue">
                <color rgba="0 1.0 1.0 1.0"/>
            </material>
        </visual>
        <collision>
            <origin xyz="0.7408348207819103 0 0" rpy="0 0 0"/>
            <geometry>
                <box size="1.4816696415638206 2.1251297224307604 1.1081745251565789" />
            </geometry>
        </collision>
    </link>
    <link name="Leg21">
        <inertial>
            <origin xyz="1.0819426761122073 0 0" rpy="0 0 0"/>
            <mass value="1" />
            <inertia ixx="100" ixy="0" ixz="0" iyy="100" iyz="0" izz="100" />
        </inertial>
        <visual>
            <origin xyz="1.0819426761122073 0 0" rpy="0 0 0"/>
            <geometry>
                <box size="2.1638853522244146 1.1696985604657133 1.597202058014318" />
            </geometry>
            <material name="Blue">
                <color rgba="0 1.0 1.0 1.0"/>
            </material>
        </visual>
        <collision>
            <origin xyz="1.0819426761122073 0 0" rpy="0 0 0"/>
            <geometry>
                <box size="2.1638853522244146 1.1696985604657133 1.597202058014318" />
            </geometry>
        </collision>
    </link>
    <link name="Leg22">
        <inertial>
            <origin xyz="0 0.7464277425052889 0" rpy="0 0 0"/>
            <mass value="1" />
            <inertia ixx="100" ixy="0" ixz="0" iyy="100" iyz="0" izz="100" />
        </inertial>
        <visual>
            <origin xyz="0 0.7464277425052889 0" rpy="0 0 0"/>
            <geometry>
                <box size="2.2050817621447307 1.4928554850105777 2.6820305593014147" />
            </geometry>
            <material name="Green">
                <color rgba="0 180.0 0.0 1.0"/>
            </material>
        </visual>
        <collision>
            <origin xyz="0 0.7464277425052889 0" rpy="0 0 0"/>
            <geometry>
                <box size="2.2050817621447307 1.4928554850105777 2.6820305593014147" />
            </geometry>
        </collision>
    </link>
    <link name="Leg23">
        <inertial>
            <origin xyz="0 0 0.6197352335248077" rpy="0 0 0"/>
            <mass value="1" />
            <inertia ixx="100" ixy="0" ixz="0" iyy="100" iyz="0" izz="100" />
        </inertial>
        <visual>
            <origin xyz="0 0 0.6197352335248077" rpy="0 0 0"/>
            <geometry>
                <box size="2.533695733497521 2.181523043272372 1.2394704670496155" />
            </geometry>
            <material name="Blue">
                <color rgba="0 1.0 1.0 1.0"/>
            </material>
        </visual>
        <collision>
            <origin xyz="0 0 0.6197352335248077" rpy="0 0 0"/>
            <geometry>
                <box size="2.533695733497521 2.181523043272372 1.2394704670496155" />
            </geometry>
        </collision>
    </link>
    <link name="Leg24">
        <inertial>
            <origin xyz="1.125439701647628 0 0" rpy="0 0 0"/>
            <mass value="1" />
            <inertia ixx="100" ixy="0" ixz="0" iyy="100" iyz="0" izz="100" />
        </inertial>
        <visual>
            <origin xyz="1.125439701647628 0 0" rpy="0 0 0"/>
            <geometry>
                <box size="2.250879403295256 1.6581883665223986 1.40151645077507" />
            </geometry>
            <material name="Green">
                <color rgba="0 180.0 0.0 1.0"/>
            </material>
        </visual>
        <collision>
            <origin xyz="1.125439701647628 0 0" rpy="0 0 0"/>
            <geometry>
                <box size="2.250879403295256 1.6581883665223986 1.40151645077507" />
            </geometry>
        </collision>
    </link>
    <link name="Leg25">
        <inertial>
            <origin xyz="1.4059375932447593 0 0" rpy="0 0 0"/>
            <mass value="1" />
            <inertia ixx="100" ixy="0" ixz="0" iyy="100" iyz="0" izz="100" />
        </inertial>
        <visual>
            <origin xyz="1.4059375932447593 0 0" rpy="0 0 0"/>
            <geometry>
                <box size="2.8118751864895186 1.9075882073884538 1.815087599061498" />
            </geometry>
            <material name="Blue">
                <color rgba="0 1.0 1.0 1.0"/>
            </material>
        </visual>
        <collision>
            <origin xyz="1.4059375932447593 0 0" rpy="0 0 0"/>
            <geometry>
                <box size="2.8118751864895186 1.9075882073884538 1.815087599061498" />
            </geometry>
        </collision>
    </link>
    <link name="Leg26">
        <inertial>
            <origin xyz="0 0 1.3354189698637822" rpy="0 0 0"/>
            <mass value="1" />
            <inertia ixx="100" ixy="0" ixz="0" iyy="100" iyz="0" izz="100" />
        </inertial>
        <visual>
            <origin xyz="0 0 1.3354189698637822" rpy="0 0 0"/>
            <geometry>
                <box size="2.5125940061832157 1.9197506926757288 2.6708379397275643" />
            </geometry>
            <material name="Blue">
                <color rgba="0 1.0 1.0 1.0"/>
            </material>
        </visual>
        <collision>
            <origin xyz="0 0 1.3354189698637822" rpy="0 0 0"/>
            <geometry>
                <box size="2.5125940061832157 1.9197506926757288 2.6708379397275643" />
            </geometry>
        </collision>
    </link>
    <joint name="Torso_Leg1" type="revolute">
       <parent link="Torso"/>
       <child  link="Leg1"/>
       <origin rpy="0 0 0" xyz="0 0 2.8448426199932135" />
     <axis xyz="1 0 0"/>
       <limit effort="0.0" lower="-3.14159" upper="3.14159" velocity="0.0"/>
    </joint>
    <joint name="Torso_Leg2" type="revolute">
       <parent link="Torso"/>
       <child  link="Leg2"/>
       <origin rpy="0 0 0" xyz="0 0.7191794160065638 1.2702841860993481" />
     <axis xyz="1 0 0"/>
       <limit effort="0.0" lower="-3.14159" upper="3.14159" velocity="0.0"/>
    </joint>
    <joint name="Leg2_Leg3" type="revolute">
       <parent link="Leg2"/>
       <child  link="Leg3"/>
       <origin rpy="0 0 0" xyz="0 0 1.316047441472517" />
     <axis xyz="1 0 0"/>
       <limit effort="0.0" lower="-3.14159" upper="3.14159" velocity="0.0"/>
    </joint>
    <joint name="Leg2_Leg4" type="revolute">
       <parent link="Leg2"/>
       <child  link="Leg4"/>
       <origin rpy="0 0 0" xyz="0.6532781359472059 0 1.316047441472517" />
     <axis xyz="1 0 0"/>
       <limit effort="0.0" lower="-3.14159" upper="3.14159" velocity="0.0"/>
    </joint>
    <joint name="Leg3_Leg5" type="revolute">
       <parent link="Leg3"/>
       <child  link="Leg5"/>
       <origin rpy="0 0 0" xyz="1.850086656372363 0 0" />
     <axis xyz="1 0 0"/>
       <limit effort="0.0" lower="-3.14159" upper="3.14159" velocity="0.0"/>
    </joint>
    <joint name="Leg5_Leg6" type="revolute">
       <parent link="Leg5"/>
       <child  link="Leg6"/>
       <origin rpy="0 0 0" xyz="1.5074932560158747 0 0" />
     <axis xyz="1 0 0"/>
       <limit effort="0.0" lower="-3.14159" upper="3.14159" velocity="0.0"/>
    </joint>
    <joint name="Leg1_Leg7" type="revolute">
       <parent link="Leg1"/>
       <child  link="Leg7"/>
       <origin rpy="0 0 0" xyz="0 1.2358803569625645 0.9432725731009334" />
     <axis xyz="1 0 0"/>
       <limit effort="0.0" lower="-3.14159" upper="3.14159" velocity="0.0"/>
    </joint>
    <joint name="Leg6_Leg8" type="revolute">
       <parent link="Leg6"/>
       <child  link="Leg8"/>
       <origin rpy="0 0 0" xyz="0 0 2.3603161949337443" />
     <axis xyz="1 0 0"/>
       <limit effort="0.0" lower="-3.14159" upper="3.14159" velocity="0.0"/>
    </joint>
    <joint name="Leg4_Leg9" type="revolute">
       <parent link="Leg4"/>
       <child  link="Leg9"/>
       <origin rpy="0 0 0" xyz="1.3769248833832552 0.6272761513962668 0" />
     <axis xyz="1 0 0"/>
       <limit effort="0.0" lower="-3.14159" upper="3.14159" velocity="0.0"/>
    </joint>
    <joint name="Leg4_Leg10" type="revolute">
       <parent link="Leg4"/>
       <child  link="Leg10"/>
       <origin rpy="0 0 0" xyz="1.3769248833832552 0.6272761513962668 0.8647887593880079" />
     <axis xyz="1 0 0"/>
       <limit effort="0.0" lower="-3.14159" upper="3.14159" velocity="0.0"/>
    </joint>
    <joint name="Leg8_Leg11" type="revolute">
       <parent link="Leg8"/>
       <child  link="Leg11"/>
       <origin rpy="0 0 0" xyz="0 1.3662184708930973 1.1247733336891308" />
     <axis xyz="1 0 0"/>
       <limit effort="0.0" lower="-3.14159" upper="3.14159" velocity="0.0"/>
    </joint>
    <joint name="Leg7_Leg12" type="revolute">
       <parent link="Leg7"/>
       <child  link="Leg12"/>
       <origin rpy="0 0 0" xyz="0.8246338771449515 0 0.8783757160890605" />
     <axis xyz="1 0 0"/>
       <limit effort="0.0" lower="-3.14159" upper="3.14159" velocity="0.0"/>
    </joint>
    <joint name="Leg9_Leg13" type="revolute">
       <parent link="Leg9"/>
       <child  link="Leg13"/>
       <origin rpy="0 0 0" xyz="1.3846758193923754 0 1.2440215373149384" />
     <axis xyz="1 0 0"/>
       <limit effort="0.0" lower="-3.14159" upper="3.14159" velocity="0.0"/>
    </joint>
    <joint name="Leg9_Leg14" type="revolute">
       <parent link="Leg9"/>
       <child  link="Leg14"/>
       <origin rpy="0 0 0" xyz="1.3846758193923754 0 2.4880430746298767" />
     <axis xyz="1 0 0"/>
       <limit effort="0.0" lower="-3.14159" upper="3.14159" velocity="0.0"/>
    </joint>
    <joint name="Leg7_Leg15" type="revolute">
       <parent link="Leg7"/>
       <child  link="Leg15"/>
       <origin rpy="0 0 0" xyz="0.8246338771449515 0 1.756751432178121" />
     <axis xyz="1 0 0"/>
       <limit effort="0.0" lower="-3.14159" upper="3.14159" velocity="0.0"/>
    </joint>
    <joint name="Leg14_Leg16" type="revolute">
       <parent link="Leg14"/>
       <child  link="Leg16"/>
       <origin rpy="0 0 0" xyz="0 1.3429337797441834 0.6690036890430949" />
     <axis xyz="1 0 0"/>
       <limit effort="0.0" lower="-3.14159" upper="3.14159" velocity="0.0"/>
    </joint>
    <joint name="Leg1_Leg17" type="revolute">
       <parent link="Leg1"/>
       <child  link="Leg17"/>
       <origin rpy="0 0 0" xyz="0 2.471760713925129 0.9432725731009334" />
     <axis xyz="1 0 0"/>
       <limit effort="0.0" lower="-3.14159" upper="3.14159" velocity="0.0"/>
    </joint>
    <joint name="Leg16_Leg18" type="revolute">
       <parent link="Leg16"/>
       <child  link="Leg18"/>
       <origin rpy="0 0 0" xyz="1.1131819942054444 0.8311335755597584 0" />
     <axis xyz="1 0 0"/>
       <limit effort="0.0" lower="-3.14159" upper="3.14159" velocity="0.0"/>
    </joint>
    <joint name="Leg11_Leg19" type="revolute">
       <parent link="Leg11"/>
       <child  link="Leg19"/>
       <origin rpy="0 0 0" xyz="0.67198163135695 0 1.1090055688791034" />
     <axis xyz="1 0 0"/>
       <limit effort="0.0" lower="-3.14159" upper="3.14159" velocity="0.0"/>
    </joint>
    <joint name="Torso_Leg20" type="revolute">
       <parent link="Torso"/>
       <child  link="Leg20"/>
       <origin rpy="0 0 0" xyz="0.879282243872376 0.7191794160065638 1.2702841860993481" />
     <axis xyz="1 0 0"/>
       <limit effort="0.0" lower="-3.14159" upper="3.14159" velocity="0.0"/>
    </joint>
    <joint name="Leg6_Leg21" type="revolute">
       <parent link="Leg6"/>
       <child  link="Leg21"/>
       <origin rpy="0 0 0" xyz="0.5492843766018279 0 2.3603161949337443" />
     <axis xyz="1 0 0"/>
       <limit effort="0.0" lower="-3.14159" upper="3.14159" velocity="0.0"/>
    </joint>
    <joint name="Leg19_Leg22" type="revolute">
       <parent link="Leg19"/>
       <child  link="Leg22"/>
       <origin rpy="0 0 0" xyz="0.7408348207819103 1.0625648612153802 0" />
     <axis xyz="1 0 0"/>
       <limit effort="0.0" lower="-3.14159" upper="3.14159" velocity="0.0"/>
    </joint>
    <joint name="Leg12_Leg23" type="revolute">
       <parent link="Leg12"/>
       <child  link="Leg23"/>
       <origin rpy="0 0 0" xyz="1.0433481527197683 0 0.8247913160609437" />
     <axis xyz="1 0 0"/>
       <limit effort="0.0" lower="-3.14159" upper="3.14159" velocity="0.0"/>
    </joint>
    <joint name="Leg13_Leg24" type="revolute">
       <parent link="Leg13"/>
       <child  link="Leg24"/>
       <origin rpy="0 0 0" xyz="0.8854363126853655 0 1.4601749489539788" />
     <axis xyz="1 0 0"/>
       <limit effort="0.0" lower="-3.14159" upper="3.14159" velocity="0.0"/>
    </joint>
    <joint name="Leg12_Leg25" type="revolute">
       <parent link="Leg12"/>
       <child  link="Leg25"/>
       <origin rpy="0 0 0" xyz="2.0866963054395367 0 0.8247913160609437" />
     <axis xyz="1 0 0"/>
       <limit effort="0.0" lower="-3.14159" upper="3.14159" velocity="0.0"/>
    </joint>
    <joint name="Leg16_Leg26" type="revolute">
       <parent link="Leg16"/>
       <child  link="Leg26"/>
       <origin rpy="0 0 0" xyz="1.1131819942054444 0.8311335755597584 1.2665352094680062" />
     <axis xyz="1 0 0"/>
       <limit effort="0.0" lower="-3.14159" upper="3.14159" velocity="0.0"/>
    </joint>
</robot>