<robot name = "robot">
    <link name="Torso">
        <inertial>
            <origin xyz="0 0 0.9194197193579617" rpy="0 0 0"/>
            <mass value="1" />
            <inertia ixx="100" ixy="0" ixz="0" iyy="100" iyz="0" izz="100" />
        </inertial>
        <visual>
            <origin xyz="0 0 0.9194197193579617" rpy="0 0 0"/>
            <geometry>
                <box size="1.803353801617032 1.5061113650535447 1.8388394387159235" />
            </geometry>
            <material name="Green">
                <color rgba="0 180.0 0.0 1.0"/>
            </material>
        </visual>
        <collision>
            <origin xyz="0 0 0.9194197193579617" rpy="0 0 0"/>
            <geometry>
                <box size="1.803353801617032 1.5061113650535447 1.8388394387159235" />
            </geometry>
        </collision>
    </link>
    <link name="Leg1">
        <inertial>
            <origin xyz="0 0 0.7273512186532775" rpy="0 0 0"/>
            <mass value="1" />
            <inertia ixx="100" ixy="0" ixz="0" iyy="100" iyz="0" izz="100" />
        </inertial>
        <visual>
            <origin xyz="0 0 0.7273512186532775" rpy="0 0 0"/>
            <geometry>
                <box size="1.2541933839540325 1.9747456638021659 1.454702437306555" />
            </geometry>
            <material name="Blue">
                <color rgba="0 1.0 1.0 1.0"/>
            </material>
        </visual>
        <collision>
            <origin xyz="0 0 0.7273512186532775" rpy="0 0 0"/>
            <geometry>
                <box size="1.2541933839540325 1.9747456638021659 1.454702437306555" />
            </geometry>
        </collision>
    </link>
    <link name="Leg2">
        <inertial>
            <origin xyz="0 1.4790488175313186 0" rpy="0 0 0"/>
            <mass value="1" />
            <inertia ixx="100" ixy="0" ixz="0" iyy="100" iyz="0" izz="100" />
        </inertial>
        <visual>
            <origin xyz="0 1.4790488175313186 0" rpy="0 0 0"/>
            <geometry>
                <box size="2.7446053343073706 2.958097635062637 1.411408563958673" />
            </geometry>
            <material name="Blue">
                <color rgba="0 1.0 1.0 1.0"/>
            </material>
        </visual>
        <collision>
            <origin xyz="0 1.4790488175313186 0" rpy="0 0 0"/>
            <geometry>
                <box size="2.7446053343073706 2.958097635062637 1.411408563958673" />
            </geometry>
        </collision>
    </link>
    <link name="Leg3">
        <inertial>
            <origin xyz="0 0.6895121140597394 0" rpy="0 0 0"/>
            <mass value="1" />
            <inertia ixx="100" ixy="0" ixz="0" iyy="100" iyz="0" izz="100" />
        </inertial>
        <visual>
            <origin xyz="0 0.6895121140597394 0" rpy="0 0 0"/>
            <geometry>
                <box size="1.1186363796287366 1.379024228119479 2.118593508161125" />
            </geometry>
            <material name="Green">
                <color rgba="0 180.0 0.0 1.0"/>
            </material>
        </visual>
        <collision>
            <origin xyz="0 0.6895121140597394 0" rpy="0 0 0"/>
            <geometry>
                <box size="1.1186363796287366 1.379024228119479 2.118593508161125" />
            </geometry>
        </collision>
    </link>
    <link name="Leg4">
        <inertial>
            <origin xyz="0.5746073849050424 0 0" rpy="0 0 0"/>
            <mass value="1" />
            <inertia ixx="100" ixy="0" ixz="0" iyy="100" iyz="0" izz="100" />
        </inertial>
        <visual>
            <origin xyz="0.5746073849050424 0 0" rpy="0 0 0"/>
            <geometry>
                <box size="1.1492147698100847 1.5074843603834032 1.3568567202531832" />
            </geometry>
            <material name="Blue">
                <color rgba="0 1.0 1.0 1.0"/>
            </material>
        </visual>
        <collision>
            <origin xyz="0.5746073849050424 0 0" rpy="0 0 0"/>
            <geometry>
                <box size="1.1492147698100847 1.5074843603834032 1.3568567202531832" />
            </geometry>
        </collision>
    </link>
    <link name="Leg5">
        <inertial>
            <origin xyz="0 0.7053649867975386 0" rpy="0 0 0"/>
            <mass value="1" />
            <inertia ixx="100" ixy="0" ixz="0" iyy="100" iyz="0" izz="100" />
        </inertial>
        <visual>
            <origin xyz="0 0.7053649867975386 0" rpy="0 0 0"/>
            <geometry>
                <box size="2.988843295184336 1.4107299735950771 2.3543732860120277" />
            </geometry>
            <material name="Blue">
                <color rgba="0 1.0 1.0 1.0"/>
            </material>
        </visual>
        <collision>
            <origin xyz="0 0.7053649867975386 0" rpy="0 0 0"/>
            <geometry>
                <box size="2.988843295184336 1.4107299735950771 2.3543732860120277" />
            </geometry>
        </collision>
    </link>
    <link name="Leg6">
        <inertial>
            <origin xyz="0 0 1.1215309505723279" rpy="0 0 0"/>
            <mass value="1" />
            <inertia ixx="100" ixy="0" ixz="0" iyy="100" iyz="0" izz="100" />
        </inertial>
        <visual>
            <origin xyz="0 0 1.1215309505723279" rpy="0 0 0"/>
            <geometry>
                <box size="2.322847814506286 2.674234774708088 2.2430619011446558" />
            </geometry>
            <material name="Green">
                <color rgba="0 180.0 0.0 1.0"/>
            </material>
        </visual>
        <collision>
            <origin xyz="0 0 1.1215309505723279" rpy="0 0 0"/>
            <geometry>
                <box size="2.322847814506286 2.674234774708088 2.2430619011446558" />
            </geometry>
        </collision>
    </link>
    <link name="Leg7">
        <inertial>
            <origin xyz="0 0 0.9098323239480111" rpy="0 0 0"/>
            <mass value="1" />
            <inertia ixx="100" ixy="0" ixz="0" iyy="100" iyz="0" izz="100" />
        </inertial>
        <visual>
            <origin xyz="0 0 0.9098323239480111" rpy="0 0 0"/>
            <geometry>
                <box size="1.846132192511218 2.3557388562489097 1.8196646478960221" />
            </geometry>
            <material name="Green">
                <color rgba="0 180.0 0.0 1.0"/>
            </material>
        </visual>
        <collision>
            <origin xyz="0 0 0.9098323239480111" rpy="0 0 0"/>
            <geometry>
                <box size="1.846132192511218 2.3557388562489097 1.8196646478960221" />
            </geometry>
        </collision>
    </link>
    <link name="Leg8">
        <inertial>
            <origin xyz="1.4841836672453579 0 0" rpy="0 0 0"/>
            <mass value="1" />
            <inertia ixx="100" ixy="0" ixz="0" iyy="100" iyz="0" izz="100" />
        </inertial>
        <visual>
            <origin xyz="1.4841836672453579 0 0" rpy="0 0 0"/>
            <geometry>
                <box size="2.9683673344907158 1.7496407886198142 2.653032975229875" />
            </geometry>
            <material name="Blue">
                <color rgba="0 1.0 1.0 1.0"/>
            </material>
        </visual>
        <collision>
            <origin xyz="1.4841836672453579 0 0" rpy="0 0 0"/>
            <geometry>
                <box size="2.9683673344907158 1.7496407886198142 2.653032975229875" />
            </geometry>
        </collision>
    </link>
    <link name="Leg9">
        <inertial>
            <origin xyz="0 0 1.0349757328326732" rpy="0 0 0"/>
            <mass value="1" />
            <inertia ixx="100" ixy="0" ixz="0" iyy="100" iyz="0" izz="100" />
        </inertial>
        <visual>
            <origin xyz="0 0 1.0349757328326732" rpy="0 0 0"/>
            <geometry>
                <box size="2.502518283921659 1.6945757428393375 2.0699514656653464" />
            </geometry>
            <material name="Green">
                <color rgba="0 180.0 0.0 1.0"/>
            </material>
        </visual>
        <collision>
            <origin xyz="0 0 1.0349757328326732" rpy="0 0 0"/>
            <geometry>
                <box size="2.502518283921659 1.6945757428393375 2.0699514656653464" />
            </geometry>
        </collision>
    </link>
    <link name="Leg10">
        <inertial>
            <origin xyz="1.4170948956150866 0 0" rpy="0 0 0"/>
            <mass value="1" />
            <inertia ixx="100" ixy="0" ixz="0" iyy="100" iyz="0" izz="100" />
        </inertial>
        <visual>
            <origin xyz="1.4170948956150866 0 0" rpy="0 0 0"/>
            <geometry>
                <box size="2.8341897912301732 2.2652379814139625 1.3965805181044233" />
            </geometry>
            <material name="Blue">
                <color rgba="0 1.0 1.0 1.0"/>
            </material>
        </visual>
        <collision>
            <origin xyz="1.4170948956150866 0 0" rpy="0 0 0"/>
            <geometry>
                <box size="2.8341897912301732 2.2652379814139625 1.3965805181044233" />
            </geometry>
        </collision>
    </link>
    <link name="Leg11">
        <inertial>
            <origin xyz="0 0.7085321192479337 0" rpy="0 0 0"/>
            <mass value="1" />
            <inertia ixx="100" ixy="0" ixz="0" iyy="100" iyz="0" izz="100" />
        </inertial>
        <visual>
            <origin xyz="0 0.7085321192479337 0" rpy="0 0 0"/>
            <geometry>
                <box size="2.8839688410363147 1.4170642384958674 2.441359535887406" />
            </geometry>
            <material name="Green">
                <color rgba="0 180.0 0.0 1.0"/>
            </material>
        </visual>
        <collision>
            <origin xyz="0 0.7085321192479337 0" rpy="0 0 0"/>
            <geometry>
                <box size="2.8839688410363147 1.4170642384958674 2.441359535887406" />
            </geometry>
        </collision>
    </link>
    <link name="Leg12">
        <inertial>
            <origin xyz="0 0 1.0686196011519733" rpy="0 0 0"/>
            <mass value="1" />
            <inertia ixx="100" ixy="0" ixz="0" iyy="100" iyz="0" izz="100" />
        </inertial>
        <visual>
            <origin xyz="0 0 1.0686196011519733" rpy="0 0 0"/>
            <geometry>
                <box size="1.0996014234223843 1.914297153199835 2.1372392023039466" />
            </geometry>
            <material name="Blue">
                <color rgba="0 1.0 1.0 1.0"/>
            </material>
        </visual>
        <collision>
            <origin xyz="0 0 1.0686196011519733" rpy="0 0 0"/>
            <geometry>
                <box size="1.0996014234223843 1.914297153199835 2.1372392023039466" />
            </geometry>
        </collision>
    </link>
    <link name="Leg13">
        <inertial>
            <origin xyz="0 1.2396007793607229 0" rpy="0 0 0"/>
            <mass value="1" />
            <inertia ixx="100" ixy="0" ixz="0" iyy="100" iyz="0" izz="100" />
        </inertial>
        <visual>
            <origin xyz="0 1.2396007793607229 0" rpy="0 0 0"/>
            <geometry>
                <box size="2.6905040096361805 2.4792015587214458 1.0637640647594155" />
            </geometry>
            <material name="Green">
                <color rgba="0 180.0 0.0 1.0"/>
            </material>
        </visual>
        <collision>
            <origin xyz="0 1.2396007793607229 0" rpy="0 0 0"/>
            <geometry>
                <box size="2.6905040096361805 2.4792015587214458 1.0637640647594155" />
            </geometry>
        </collision>
    </link>
    <link name="Leg14">
        <inertial>
            <origin xyz="0.6730035162170953 0 0" rpy="0 0 0"/>
            <mass value="1" />
            <inertia ixx="100" ixy="0" ixz="0" iyy="100" iyz="0" izz="100" />
        </inertial>
        <visual>
            <origin xyz="0.6730035162170953 0 0" rpy="0 0 0"/>
            <geometry>
                <box size="1.3460070324341906 1.6068208132807287 1.6503939334984588" />
            </geometry>
            <material name="Green">
                <color rgba="0 180.0 0.0 1.0"/>
            </material>
        </visual>
        <collision>
            <origin xyz="0.6730035162170953 0 0" rpy="0 0 0"/>
            <geometry>
                <box size="1.3460070324341906 1.6068208132807287 1.6503939334984588" />
            </geometry>
        </collision>
    </link>
    <link name="Leg15">
        <inertial>
            <origin xyz="1.2688084270296818 0 0" rpy="0 0 0"/>
            <mass value="1" />
            <inertia ixx="100" ixy="0" ixz="0" iyy="100" iyz="0" izz="100" />
        </inertial>
        <visual>
            <origin xyz="1.2688084270296818 0 0" rpy="0 0 0"/>
            <geometry>
                <box size="2.5376168540593635 1.622667171058231 1.5559217408157286" />
            </geometry>
            <material name="Blue">
                <color rgba="0 1.0 1.0 1.0"/>
            </material>
        </visual>
        <collision>
            <origin xyz="1.2688084270296818 0 0" rpy="0 0 0"/>
            <geometry>
                <box size="2.5376168540593635 1.622667171058231 1.5559217408157286" />
            </geometry>
        </collision>
    </link>
    <link name="Leg16">
        <inertial>
            <origin xyz="0 0.5887041739717976 0" rpy="0 0 0"/>
            <mass value="1" />
            <inertia ixx="100" ixy="0" ixz="0" iyy="100" iyz="0" izz="100" />
        </inertial>
        <visual>
            <origin xyz="0 0.5887041739717976 0" rpy="0 0 0"/>
            <geometry>
                <box size="2.483406321651455 1.1774083479435953 1.5749539247383073" />
            </geometry>
            <material name="Green">
                <color rgba="0 180.0 0.0 1.0"/>
            </material>
        </visual>
        <collision>
            <origin xyz="0 0.5887041739717976 0" rpy="0 0 0"/>
            <geometry>
                <box size="2.483406321651455 1.1774083479435953 1.5749539247383073" />
            </geometry>
        </collision>
    </link>
    <link name="Leg17">
        <inertial>
            <origin xyz="1.4713860404531207 0 0" rpy="0 0 0"/>
            <mass value="1" />
            <inertia ixx="100" ixy="0" ixz="0" iyy="100" iyz="0" izz="100" />
        </inertial>
        <visual>
            <origin xyz="1.4713860404531207 0 0" rpy="0 0 0"/>
            <geometry>
                <box size="2.9427720809062414 1.0663075162367515 2.8503787348417085" />
            </geometry>
            <material name="Blue">
                <color rgba="0 1.0 1.0 1.0"/>
            </material>
        </visual>
        <collision>
            <origin xyz="1.4713860404531207 0 0" rpy="0 0 0"/>
            <geometry>
                <box size="2.9427720809062414 1.0663075162367515 2.8503787348417085" />
            </geometry>
        </collision>
    </link>
    <link name="Leg18">
        <inertial>
            <origin xyz="0.7025871427756599 0 0" rpy="0 0 0"/>
            <mass value="1" />
            <inertia ixx="100" ixy="0" ixz="0" iyy="100" iyz="0" izz="100" />
        </inertial>
        <visual>
            <origin xyz="0.7025871427756599 0 0" rpy="0 0 0"/>
            <geometry>
                <box size="1.4051742855513198 2.0963933800906442 2.169004186009127" />
            </geometry>
            <material name="Blue">
                <color rgba="0 1.0 1.0 1.0"/>
            </material>
        </visual>
        <collision>
            <origin xyz="0.7025871427756599 0 0" rpy="0 0 0"/>
            <geometry>
                <box size="1.4051742855513198 2.0963933800906442 2.169004186009127" />
            </geometry>
        </collision>
    </link>
    <link name="Leg19">
        <inertial>
            <origin xyz="0 0 0.977186336724779" rpy="0 0 0"/>
            <mass value="1" />
            <inertia ixx="100" ixy="0" ixz="0" iyy="100" iyz="0" izz="100" />
        </inertial>
        <visual>
            <origin xyz="0 0 0.977186336724779" rpy="0 0 0"/>
            <geometry>
                <box size="2.0866786455612756 2.828080870439827 1.954372673449558" />
            </geometry>
            <material name="Blue">
                <color rgba="0 1.0 1.0 1.0"/>
            </material>
        </visual>
        <collision>
            <origin xyz="0 0 0.977186336724779" rpy="0 0 0"/>
            <geometry>
                <box size="2.0866786455612756 2.828080870439827 1.954372673449558" />
            </geometry>
        </collision>
    </link>
    <link name="Leg20">
        <inertial>
            <origin xyz="0 0 1.135706290810992" rpy="0 0 0"/>
            <mass value="1" />
            <inertia ixx="100" ixy="0" ixz="0" iyy="100" iyz="0" izz="100" />
        </inertial>
        <visual>
            <origin xyz="0 0 1.135706290810992" rpy="0 0 0"/>
            <geometry>
                <box size="1.3951400505371339 1.7171508312274735 2.271412581621984" />
            </geometry>
            <material name="Blue">
                <color rgba="0 1.0 1.0 1.0"/>
            </material>
        </visual>
        <collision>
            <origin xyz="0 0 1.135706290810992" rpy="0 0 0"/>
            <geometry>
                <box size="1.3951400505371339 1.7171508312274735 2.271412581621984" />
            </geometry>
        </collision>
    </link>
    <link name="Leg21">
        <inertial>
            <origin xyz="0 0 1.0154150029402045" rpy="0 0 0"/>
            <mass value="1" />
            <inertia ixx="100" ixy="0" ixz="0" iyy="100" iyz="0" izz="100" />
        </inertial>
        <visual>
            <origin xyz="0 0 1.0154150029402045" rpy="0 0 0"/>
            <geometry>
                <box size="1.4108260413434057 1.7214218354820512 2.030830005880409" />
            </geometry>
            <material name="Green">
                <color rgba="0 180.0 0.0 1.0"/>
            </material>
        </visual>
        <collision>
            <origin xyz="0 0 1.0154150029402045" rpy="0 0 0"/>
            <geometry>
                <box size="1.4108260413434057 1.7214218354820512 2.030830005880409" />
            </geometry>
        </collision>
    </link>
    <link name="Leg22">
        <inertial>
            <origin xyz="0 0.925860141730401 0" rpy="0 0 0"/>
            <mass value="1" />
            <inertia ixx="100" ixy="0" ixz="0" iyy="100" iyz="0" izz="100" />
        </inertial>
        <visual>
            <origin xyz="0 0.925860141730401 0" rpy="0 0 0"/>
            <geometry>
                <box size="1.4365730450808045 1.851720283460802 2.4967682301984135" />
            </geometry>
            <material name="Blue">
                <color rgba="0 1.0 1.0 1.0"/>
            </material>
        </visual>
        <collision>
            <origin xyz="0 0.925860141730401 0" rpy="0 0 0"/>
            <geometry>
                <box size="1.4365730450808045 1.851720283460802 2.4967682301984135" />
            </geometry>
        </collision>
    </link>
    <link name="Leg23">
        <inertial>
            <origin xyz="0 0.6774939004763049 0" rpy="0 0 0"/>
            <mass value="1" />
            <inertia ixx="100" ixy="0" ixz="0" iyy="100" iyz="0" izz="100" />
        </inertial>
        <visual>
            <origin xyz="0 0.6774939004763049 0" rpy="0 0 0"/>
            <geometry>
                <box size="1.1665596173106687 1.3549878009526097 2.1121658009399273" />
            </geometry>
            <material name="Blue">
                <color rgba="0 1.0 1.0 1.0"/>
            </material>
        </visual>
        <collision>
            <origin xyz="0 0.6774939004763049 0" rpy="0 0 0"/>
            <geometry>
                <box size="1.1665596173106687 1.3549878009526097 2.1121658009399273" />
            </geometry>
        </collision>
    </link>
    <link name="Leg24">
        <inertial>
            <origin xyz="0.748282168387571 0 0" rpy="0 0 0"/>
            <mass value="1" />
            <inertia ixx="100" ixy="0" ixz="0" iyy="100" iyz="0" izz="100" />
        </inertial>
        <visual>
            <origin xyz="0.748282168387571 0 0" rpy="0 0 0"/>
            <geometry>
                <box size="1.496564336775142 1.9686767962738212 1.4595220759800427" />
            </geometry>
            <material name="Blue">
                <color rgba="0 1.0 1.0 1.0"/>
            </material>
        </visual>
        <collision>
            <origin xyz="0.748282168387571 0 0" rpy="0 0 0"/>
            <geometry>
                <box size="1.496564336775142 1.9686767962738212 1.4595220759800427" />
            </geometry>
        </collision>
    </link>
    <link name="Leg25">
        <inertial>
            <origin xyz="0.7120184133140549 0 0" rpy="0 0 0"/>
            <mass value="1" />
            <inertia ixx="100" ixy="0" ixz="0" iyy="100" iyz="0" izz="100" />
        </inertial>
        <visual>
            <origin xyz="0.7120184133140549 0 0" rpy="0 0 0"/>
            <geometry>
                <box size="1.4240368266281098 1.594594319820969 1.1084906725637549" />
            </geometry>
            <material name="Blue">
                <color rgba="0 1.0 1.0 1.0"/>
            </material>
        </visual>
        <collision>
            <origin xyz="0.7120184133140549 0 0" rpy="0 0 0"/>
            <geometry>
                <box size="1.4240368266281098 1.594594319820969 1.1084906725637549" />
            </geometry>
        </collision>
    </link>
    <link name="Leg26">
        <inertial>
            <origin xyz="1.4342543763562574 0 0" rpy="0 0 0"/>
            <mass value="1" />
            <inertia ixx="100" ixy="0" ixz="0" iyy="100" iyz="0" izz="100" />
        </inertial>
        <visual>
            <origin xyz="1.4342543763562574 0 0" rpy="0 0 0"/>
            <geometry>
                <box size="2.868508752712515 1.0897409234261093 2.1134918826604494" />
            </geometry>
            <material name="Green">
                <color rgba="0 180.0 0.0 1.0"/>
            </material>
        </visual>
        <collision>
            <origin xyz="1.4342543763562574 0 0" rpy="0 0 0"/>
            <geometry>
                <box size="2.868508752712515 1.0897409234261093 2.1134918826604494" />
            </geometry>
        </collision>
    </link>
    <joint name="Torso_Leg1" type="revolute">
       <parent link="Torso"/>
       <child  link="Leg1"/>
       <origin rpy="0 0 0" xyz="0 0 1.8388394387159235" />
     <axis xyz="1 0 0"/>
       <limit effort="0.0" lower="-3.14159" upper="3.14159" velocity="0.0"/>
    </joint>
    <joint name="Torso_Leg2" type="revolute">
       <parent link="Torso"/>
       <child  link="Leg2"/>
       <origin rpy="0 0 0" xyz="0 0.9873728319010829 0.7273512186532775" />
     <axis xyz="1 0 0"/>
       <limit effort="0.0" lower="-3.14159" upper="3.14159" velocity="0.0"/>
    </joint>
    <joint name="Leg2_Leg3" type="revolute">
       <parent link="Leg2"/>
       <child  link="Leg3"/>
       <origin rpy="0 0 0" xyz="0 1.379024228119479 0" />
     <axis xyz="1 0 0"/>
       <limit effort="0.0" lower="-3.14159" upper="3.14159" velocity="0.0"/>
    </joint>
    <joint name="Leg2_Leg4" type="revolute">
       <parent link="Leg2"/>
       <child  link="Leg4"/>
       <origin rpy="0 0 0" xyz="0.5593181898143683 1.379024228119479 0" />
     <axis xyz="1 0 0"/>
       <limit effort="0.0" lower="-3.14159" upper="3.14159" velocity="0.0"/>
    </joint>
    <joint name="Leg3_Leg5" type="revolute">
       <parent link="Leg3"/>
       <child  link="Leg5"/>
       <origin rpy="0 0 0" xyz="0.5746073849050424 0.7537421801917016 0" />
     <axis xyz="1 0 0"/>
       <limit effort="0.0" lower="-3.14159" upper="3.14159" velocity="0.0"/>
    </joint>
    <joint name="Leg1_Leg6" type="revolute">
       <parent link="Leg1"/>
       <child  link="Leg6"/>
       <origin rpy="0 0 0" xyz="0 1.4790488175313186 0.7057042819793365" />
     <axis xyz="1 0 0"/>
       <limit effort="0.0" lower="-3.14159" upper="3.14159" velocity="0.0"/>
    </joint>
    <joint name="Leg4_Leg7" type="revolute">
       <parent link="Leg4"/>
       <child  link="Leg7"/>
       <origin rpy="0 0 0" xyz="0 0.7053649867975386 1.1771866430060138" />
     <axis xyz="1 0 0"/>
       <limit effort="0.0" lower="-3.14159" upper="3.14159" velocity="0.0"/>
    </joint>
    <joint name="Leg1_Leg8" type="revolute">
       <parent link="Leg1"/>
       <child  link="Leg8"/>
       <origin rpy="0 0 0" xyz="1.3723026671536853 1.4790488175313186 0.7057042819793365" />
     <axis xyz="1 0 0"/>
       <limit effort="0.0" lower="-3.14159" upper="3.14159" velocity="0.0"/>
    </joint>
    <joint name="Leg7_Leg9" type="revolute">
       <parent link="Leg7"/>
       <child  link="Leg9"/>
       <origin rpy="0 0 0" xyz="1.4841836672453579 0 1.3265164876149376" />
     <axis xyz="1 0 0"/>
       <limit effort="0.0" lower="-3.14159" upper="3.14159" velocity="0.0"/>
    </joint>
    <joint name="Leg6_Leg10" type="revolute">
       <parent link="Leg6"/>
       <child  link="Leg10"/>
       <origin rpy="0 0 0" xyz="0.923066096255609 0 0.9098323239480111" />
     <axis xyz="1 0 0"/>
       <limit effort="0.0" lower="-3.14159" upper="3.14159" velocity="0.0"/>
    </joint>
    <joint name="Leg9_Leg11" type="revolute">
       <parent link="Leg9"/>
       <child  link="Leg11"/>
       <origin rpy="0 0 0" xyz="1.4170948956150866 1.1326189907069812 0" />
     <axis xyz="1 0 0"/>
       <limit effort="0.0" lower="-3.14159" upper="3.14159" velocity="0.0"/>
    </joint>
    <joint name="Leg2_Leg12" type="revolute">
       <parent link="Leg2"/>
       <child  link="Leg12"/>
       <origin rpy="0 0 0" xyz="0.5593181898143683 1.379024228119479 1.0592967540805625" />
     <axis xyz="1 0 0"/>
       <limit effort="0.0" lower="-3.14159" upper="3.14159" velocity="0.0"/>
    </joint>
    <joint name="Leg12_Leg13" type="revolute">
       <parent link="Leg12"/>
       <child  link="Leg13"/>
       <origin rpy="0 0 0" xyz="0 2.4792015587214458 0" />
     <axis xyz="1 0 0"/>
       <limit effort="0.0" lower="-3.14159" upper="3.14159" velocity="0.0"/>
    </joint>
    <joint name="Leg5_Leg14" type="revolute">
       <parent link="Leg5"/>
       <child  link="Leg14"/>
       <origin rpy="0 0 0" xyz="1.161423907253143 0 1.1215309505723279" />
     <axis xyz="1 0 0"/>
       <limit effort="0.0" lower="-3.14159" upper="3.14159" velocity="0.0"/>
    </joint>
    <joint name="Leg11_Leg15" type="revolute">
       <parent link="Leg11"/>
       <child  link="Leg15"/>
       <origin rpy="0 0 0" xyz="0.5498007117111922 0 1.0686196011519733" />
     <axis xyz="1 0 0"/>
       <limit effort="0.0" lower="-3.14159" upper="3.14159" velocity="0.0"/>
    </joint>
    <joint name="Leg11_Leg16" type="revolute">
       <parent link="Leg11"/>
       <child  link="Leg16"/>
       <origin rpy="0 0 0" xyz="0.5498007117111922 0.9571485765999175 1.0686196011519733" />
     <axis xyz="1 0 0"/>
       <limit effort="0.0" lower="-3.14159" upper="3.14159" velocity="0.0"/>
    </joint>
    <joint name="Leg10_Leg17" type="revolute">
       <parent link="Leg10"/>
       <child  link="Leg17"/>
       <origin rpy="0 0 0" xyz="1.4419844205181573 0.7085321192479337 0" />
     <axis xyz="1 0 0"/>
       <limit effort="0.0" lower="-3.14159" upper="3.14159" velocity="0.0"/>
    </joint>
    <joint name="Leg7_Leg18" type="revolute">
       <parent link="Leg7"/>
       <child  link="Leg18"/>
       <origin rpy="0 0 0" xyz="2.9683673344907158 0 1.3265164876149376" />
     <axis xyz="1 0 0"/>
       <limit effort="0.0" lower="-3.14159" upper="3.14159" velocity="0.0"/>
    </joint>
    <joint name="Leg5_Leg19" type="revolute">
       <parent link="Leg5"/>
       <child  link="Leg19"/>
       <origin rpy="0 0 0" xyz="1.161423907253143 0 2.2430619011446558" />
     <axis xyz="1 0 0"/>
       <limit effort="0.0" lower="-3.14159" upper="3.14159" velocity="0.0"/>
    </joint>
    <joint name="Leg17_Leg20" type="revolute">
       <parent link="Leg17"/>
       <child  link="Leg20"/>
       <origin rpy="0 0 0" xyz="0.7025871427756599 0 1.0845020930045635" />
     <axis xyz="1 0 0"/>
       <limit effort="0.0" lower="-3.14159" upper="3.14159" velocity="0.0"/>
    </joint>
    <joint name="Leg12_Leg21" type="revolute">
       <parent link="Leg12"/>
       <child  link="Leg21"/>
       <origin rpy="0 0 0" xyz="0 2.4792015587214458 0.5318820323797078" />
     <axis xyz="1 0 0"/>
       <limit effort="0.0" lower="-3.14159" upper="3.14159" velocity="0.0"/>
    </joint>
    <joint name="Leg13_Leg22" type="revolute">
       <parent link="Leg13"/>
       <child  link="Leg22"/>
       <origin rpy="0 0 0" xyz="0.6730035162170953 0.8034104066403643 0" />
     <axis xyz="1 0 0"/>
       <limit effort="0.0" lower="-3.14159" upper="3.14159" velocity="0.0"/>
    </joint>
    <joint name="Leg18_Leg23" type="revolute">
       <parent link="Leg18"/>
       <child  link="Leg23"/>
       <origin rpy="0 0 0" xyz="0 1.4140404352199134 0.977186336724779" />
     <axis xyz="1 0 0"/>
       <limit effort="0.0" lower="-3.14159" upper="3.14159" velocity="0.0"/>
    </joint>
    <joint name="Leg12_Leg24" type="revolute">
       <parent link="Leg12"/>
       <child  link="Leg24"/>
       <origin rpy="0 0 0" xyz="1.3452520048180903 2.4792015587214458 0.5318820323797078" />
     <axis xyz="1 0 0"/>
       <limit effort="0.0" lower="-3.14159" upper="3.14159" velocity="0.0"/>
    </joint>
    <joint name="Leg16_Leg25" type="revolute">
       <parent link="Leg16"/>
       <child  link="Leg25"/>
       <origin rpy="0 0 0" xyz="2.9427720809062414 0 0" />
     <axis xyz="1 0 0"/>
       <limit effort="0.0" lower="-3.14159" upper="3.14159" velocity="0.0"/>
    </joint>
    <joint name="Leg13_Leg26" type="revolute">
       <parent link="Leg13"/>
       <child  link="Leg26"/>
       <origin rpy="0 0 0" xyz="1.3460070324341906 0.8034104066403643 0" />
     <axis xyz="1 0 0"/>
       <limit effort="0.0" lower="-3.14159" upper="3.14159" velocity="0.0"/>
    </joint>
</robot>