<robot name = "robot">
    <link name="Torso">
        <inertial>
            <origin xyz="0 0 1.738040960982616" rpy="0 0 0"/>
            <mass value="1" />
            <inertia ixx="100" ixy="0" ixz="0" iyy="100" iyz="0" izz="100" />
        </inertial>
        <visual>
            <origin xyz="0 0 1.738040960982616" rpy="0 0 0"/>
            <geometry>
                <box size="2.9485524501111096 1.8321073345085694 1.738040960982616" />
            </geometry>
            <material name="Green">
                <color rgba="0 180.0 0.0 1.0"/>
            </material>
        </visual>
        <collision>
            <origin xyz="0 0 1.738040960982616" rpy="0 0 0"/>
            <geometry>
                <box size="2.9485524501111096 1.8321073345085694 1.738040960982616" />
            </geometry>
        </collision>
    </link>
    <link name="Leg1">
        <inertial>
            <origin xyz="1.1362863323251386 0 1.4806508977874908" rpy="0 0 0"/>
            <mass value="1" />
            <inertia ixx="100" ixy="0" ixz="0" iyy="100" iyz="0" izz="100" />
        </inertial>
        <visual>
            <origin xyz="1.1362863323251386 0 1.4806508977874908" rpy="0 0 0"/>
            <geometry>
                <box size="2.2725726646502773 2.80959485805969 2.9613017955749816" />
            </geometry>
            <material name="Blue">
                <color rgba="0 1.0 1.0 1.0"/>
            </material>
        </visual>
        <collision>
            <origin xyz="1.1362863323251386 0 1.4806508977874908" rpy="0 0 0"/>
            <geometry>
                <box size="2.2725726646502773 2.80959485805969 2.9613017955749816" />
            </geometry>
        </collision>
    </link>
    <link name="Leg2">
        <inertial>
            <origin xyz="0 0 2.7793518695983295" rpy="0 0 0"/>
            <mass value="1" />
            <inertia ixx="100" ixy="0" ixz="0" iyy="100" iyz="0" izz="100" />
        </inertial>
        <visual>
            <origin xyz="0 0 2.7793518695983295" rpy="0 0 0"/>
            <geometry>
                <box size="2.8368152790634182 1.2848731272826404 2.7793518695983295" />
            </geometry>
            <material name="Blue">
                <color rgba="0 1.0 1.0 1.0"/>
            </material>
        </visual>
        <collision>
            <origin xyz="0 0 2.7793518695983295" rpy="0 0 0"/>
            <geometry>
                <box size="2.8368152790634182 1.2848731272826404 2.7793518695983295" />
            </geometry>
        </collision>
    </link>
    <link name="Leg3">
        <inertial>
            <origin xyz="2.7705923331791302 0 0.8342051081360868" rpy="0 0 0"/>
            <mass value="1" />
            <inertia ixx="100" ixy="0" ixz="0" iyy="100" iyz="0" izz="100" />
        </inertial>
        <visual>
            <origin xyz="2.7705923331791302 0 0.8342051081360868" rpy="0 0 0"/>
            <geometry>
                <box size="2.7705923331791302 2.3842239988516556 1.6684102162721737" />
            </geometry>
            <material name="Blue">
                <color rgba="0 1.0 1.0 1.0"/>
            </material>
        </visual>
        <collision>
            <origin xyz="2.7705923331791302 0 0.8342051081360868" rpy="0 0 0"/>
            <geometry>
                <box size="2.7705923331791302 2.3842239988516556 1.6684102162721737" />
            </geometry>
        </collision>
    </link>
    <link name="Leg4">
        <inertial>
            <origin xyz="0 1.4536159695814557 2.1704651420906633" rpy="0 0 0"/>
            <mass value="1" />
            <inertia ixx="100" ixy="0" ixz="0" iyy="100" iyz="0" izz="100" />
        </inertial>
        <visual>
            <origin xyz="0 1.4536159695814557 2.1704651420906633" rpy="0 0 0"/>
            <geometry>
                <box size="2.5907682555791203 2.9072319391629113 2.1704651420906633" />
            </geometry>
            <material name="Blue">
                <color rgba="0 1.0 1.0 1.0"/>
            </material>
        </visual>
        <collision>
            <origin xyz="0 1.4536159695814557 2.1704651420906633" rpy="0 0 0"/>
            <geometry>
                <box size="2.5907682555791203 2.9072319391629113 2.1704651420906633" />
            </geometry>
        </collision>
    </link>
    <link name="Leg5">
        <inertial>
            <origin xyz="2.60758108502823 0 1.1130931437094294" rpy="0 0 0"/>
            <mass value="1" />
            <inertia ixx="100" ixy="0" ixz="0" iyy="100" iyz="0" izz="100" />
        </inertial>
        <visual>
            <origin xyz="2.60758108502823 0 1.1130931437094294" rpy="0 0 0"/>
            <geometry>
                <box size="2.60758108502823 2.702008991185248 2.2261862874188587" />
            </geometry>
            <material name="Blue">
                <color rgba="0 1.0 1.0 1.0"/>
            </material>
        </visual>
        <collision>
            <origin xyz="2.60758108502823 0 1.1130931437094294" rpy="0 0 0"/>
            <geometry>
                <box size="2.60758108502823 2.702008991185248 2.2261862874188587" />
            </geometry>
        </collision>
    </link>
    <link name="Leg6">
        <inertial>
            <origin xyz="0 0 1.756824288680455" rpy="0 0 0"/>
            <mass value="1" />
            <inertia ixx="100" ixy="0" ixz="0" iyy="100" iyz="0" izz="100" />
        </inertial>
        <visual>
            <origin xyz="0 0 1.756824288680455" rpy="0 0 0"/>
            <geometry>
                <box size="2.1371938533780086 2.8606161428582704 1.756824288680455" />
            </geometry>
            <material name="Blue">
                <color rgba="0 1.0 1.0 1.0"/>
            </material>
        </visual>
        <collision>
            <origin xyz="0 0 1.756824288680455" rpy="0 0 0"/>
            <geometry>
                <box size="2.1371938533780086 2.8606161428582704 1.756824288680455" />
            </geometry>
        </collision>
    </link>
    <link name="Leg7">
        <inertial>
            <origin xyz="0 1.1576860171763288 1.209855996430278" rpy="0 0 0"/>
            <mass value="1" />
            <inertia ixx="100" ixy="0" ixz="0" iyy="100" iyz="0" izz="100" />
        </inertial>
        <visual>
            <origin xyz="0 1.1576860171763288 1.209855996430278" rpy="0 0 0"/>
            <geometry>
                <box size="2.6278353852388756 1.1576860171763288 2.419711992860556" />
            </geometry>
            <material name="Blue">
                <color rgba="0 1.0 1.0 1.0"/>
            </material>
        </visual>
        <collision>
            <origin xyz="0 1.1576860171763288 1.209855996430278" rpy="0 0 0"/>
            <geometry>
                <box size="2.6278353852388756 1.1576860171763288 2.419711992860556" />
            </geometry>
        </collision>
    </link>
    <link name="Leg8">
        <inertial>
            <origin xyz="0 1.3577225116466227 1.6668612813478714" rpy="0 0 0"/>
            <mass value="1" />
            <inertia ixx="100" ixy="0" ixz="0" iyy="100" iyz="0" izz="100" />
        </inertial>
        <visual>
            <origin xyz="0 1.3577225116466227 1.6668612813478714" rpy="0 0 0"/>
            <geometry>
                <box size="2.725042888838595 2.7154450232932454 1.6668612813478714" />
            </geometry>
            <material name="Blue">
                <color rgba="0 1.0 1.0 1.0"/>
            </material>
        </visual>
        <collision>
            <origin xyz="0 1.3577225116466227 1.6668612813478714" rpy="0 0 0"/>
            <geometry>
                <box size="2.725042888838595 2.7154450232932454 1.6668612813478714" />
            </geometry>
        </collision>
    </link>
    <link name="Leg9">
        <inertial>
            <origin xyz="0.9726823714927305 0 1.853766506456975" rpy="0 0 0"/>
            <mass value="1" />
            <inertia ixx="100" ixy="0" ixz="0" iyy="100" iyz="0" izz="100" />
        </inertial>
        <visual>
            <origin xyz="0.9726823714927305 0 1.853766506456975" rpy="0 0 0"/>
            <geometry>
                <box size="1.945364742985461 1.048379802916603 1.853766506456975" />
            </geometry>
            <material name="Blue">
                <color rgba="0 1.0 1.0 1.0"/>
            </material>
        </visual>
        <collision>
            <origin xyz="0.9726823714927305 0 1.853766506456975" rpy="0 0 0"/>
            <geometry>
                <box size="1.945364742985461 1.048379802916603 1.853766506456975" />
            </geometry>
        </collision>
    </link>
    <link name="Leg10">
        <inertial>
            <origin xyz="1.3454720597109344 0.6681513319814988 0" rpy="0 0 0"/>
            <mass value="1" />
            <inertia ixx="100" ixy="0" ixz="0" iyy="100" iyz="0" izz="100" />
        </inertial>
        <visual>
            <origin xyz="1.3454720597109344 0.6681513319814988 0" rpy="0 0 0"/>
            <geometry>
                <box size="2.690944119421869 1.3363026639629976 1.2450072010112685" />
            </geometry>
            <material name="Blue">
                <color rgba="0 1.0 1.0 1.0"/>
            </material>
        </visual>
        <collision>
            <origin xyz="1.3454720597109344 0.6681513319814988 0" rpy="0 0 0"/>
            <geometry>
                <box size="2.690944119421869 1.3363026639629976 1.2450072010112685" />
            </geometry>
        </collision>
    </link>
    <link name="Leg11">
        <inertial>
            <origin xyz="0 0.6475338012288447 0" rpy="0 0 0"/>
            <mass value="1" />
            <inertia ixx="100" ixy="0" ixz="0" iyy="100" iyz="0" izz="100" />
        </inertial>
        <visual>
            <origin xyz="0 0.6475338012288447 0" rpy="0 0 0"/>
            <geometry>
                <box size="1.6388971352540813 1.2950676024576895 2.6779782717713077" />
            </geometry>
            <material name="Blue">
                <color rgba="0 1.0 1.0 1.0"/>
            </material>
        </visual>
        <collision>
            <origin xyz="0 0.6475338012288447 0" rpy="0 0 0"/>
            <geometry>
                <box size="1.6388971352540813 1.2950676024576895 2.6779782717713077" />
            </geometry>
        </collision>
    </link>
    <link name="Leg12">
        <inertial>
            <origin xyz="0 0 0.7414274213864133" rpy="0 0 0"/>
            <mass value="1" />
            <inertia ixx="100" ixy="0" ixz="0" iyy="100" iyz="0" izz="100" />
        </inertial>
        <visual>
            <origin xyz="0 0 0.7414274213864133" rpy="0 0 0"/>
            <geometry>
                <box size="1.826574264505155 2.6675484619879724 1.4828548427728265" />
            </geometry>
            <material name="Blue">
                <color rgba="0 1.0 1.0 1.0"/>
            </material>
        </visual>
        <collision>
            <origin xyz="0 0 0.7414274213864133" rpy="0 0 0"/>
            <geometry>
                <box size="1.826574264505155 2.6675484619879724 1.4828548427728265" />
            </geometry>
        </collision>
    </link>
    <link name="Leg13">
        <inertial>
            <origin xyz="0.7574355087845152 0 0.6103453619889836" rpy="0 0 0"/>
            <mass value="1" />
            <inertia ixx="100" ixy="0" ixz="0" iyy="100" iyz="0" izz="100" />
        </inertial>
        <visual>
            <origin xyz="0.7574355087845152 0 0.6103453619889836" rpy="0 0 0"/>
            <geometry>
                <box size="1.5148710175690303 1.4083139917842051 1.2206907239779672" />
            </geometry>
            <material name="Blue">
                <color rgba="0 1.0 1.0 1.0"/>
            </material>
        </visual>
        <collision>
            <origin xyz="0.7574355087845152 0 0.6103453619889836" rpy="0 0 0"/>
            <geometry>
                <box size="1.5148710175690303 1.4083139917842051 1.2206907239779672" />
            </geometry>
        </collision>
    </link>
    <link name="Leg14">
        <inertial>
            <origin xyz="0.5338893920057555 0 0.8796644266345417" rpy="0 0 0"/>
            <mass value="1" />
            <inertia ixx="100" ixy="0" ixz="0" iyy="100" iyz="0" izz="100" />
        </inertial>
        <visual>
            <origin xyz="0.5338893920057555 0 0.8796644266345417" rpy="0 0 0"/>
            <geometry>
                <box size="1.067778784011511 1.4559459632928795 1.7593288532690834" />
            </geometry>
            <material name="Blue">
                <color rgba="0 1.0 1.0 1.0"/>
            </material>
        </visual>
        <collision>
            <origin xyz="0.5338893920057555 0 0.8796644266345417" rpy="0 0 0"/>
            <geometry>
                <box size="1.067778784011511 1.4559459632928795 1.7593288532690834" />
            </geometry>
        </collision>
    </link>
    <link name="Leg15">
        <inertial>
            <origin xyz="1.3693019238663062 0 1.1663307390376842" rpy="0 0 0"/>
            <mass value="1" />
            <inertia ixx="100" ixy="0" ixz="0" iyy="100" iyz="0" izz="100" />
        </inertial>
        <visual>
            <origin xyz="1.3693019238663062 0 1.1663307390376842" rpy="0 0 0"/>
            <geometry>
                <box size="2.7386038477326125 2.3334079051721788 2.3326614780753685" />
            </geometry>
            <material name="Blue">
                <color rgba="0 1.0 1.0 1.0"/>
            </material>
        </visual>
        <collision>
            <origin xyz="1.3693019238663062 0 1.1663307390376842" rpy="0 0 0"/>
            <geometry>
                <box size="2.7386038477326125 2.3334079051721788 2.3326614780753685" />
            </geometry>
        </collision>
    </link>
    <link name="Leg16">
        <inertial>
            <origin xyz="1.4631259696151735 0 0.6024963755806582" rpy="0 0 0"/>
            <mass value="1" />
            <inertia ixx="100" ixy="0" ixz="0" iyy="100" iyz="0" izz="100" />
        </inertial>
        <visual>
            <origin xyz="1.4631259696151735 0 0.6024963755806582" rpy="0 0 0"/>
            <geometry>
                <box size="2.926251939230347 2.9921120180099066 1.2049927511613163" />
            </geometry>
            <material name="Blue">
                <color rgba="0 1.0 1.0 1.0"/>
            </material>
        </visual>
        <collision>
            <origin xyz="1.4631259696151735 0 0.6024963755806582" rpy="0 0 0"/>
            <geometry>
                <box size="2.926251939230347 2.9921120180099066 1.2049927511613163" />
            </geometry>
        </collision>
    </link>
    <link name="Leg17">
        <inertial>
            <origin xyz="0 0 1.4958616702178866" rpy="0 0 0"/>
            <mass value="1" />
            <inertia ixx="100" ixy="0" ixz="0" iyy="100" iyz="0" izz="100" />
        </inertial>
        <visual>
            <origin xyz="0 0 1.4958616702178866" rpy="0 0 0"/>
            <geometry>
                <box size="1.629748290708438 2.507254395362974 2.9917233404357733" />
            </geometry>
            <material name="Blue">
                <color rgba="0 1.0 1.0 1.0"/>
            </material>
        </visual>
        <collision>
            <origin xyz="0 0 1.4958616702178866" rpy="0 0 0"/>
            <geometry>
                <box size="1.629748290708438 2.507254395362974 2.9917233404357733" />
            </geometry>
        </collision>
    </link>
    <link name="Leg18">
        <inertial>
            <origin xyz="0 0 0.855471935196358" rpy="0 0 0"/>
            <mass value="1" />
            <inertia ixx="100" ixy="0" ixz="0" iyy="100" iyz="0" izz="100" />
        </inertial>
        <visual>
            <origin xyz="0 0 0.855471935196358" rpy="0 0 0"/>
            <geometry>
                <box size="1.1598577811762902 2.8721280439745236 1.710943870392716" />
            </geometry>
            <material name="Blue">
                <color rgba="0 1.0 1.0 1.0"/>
            </material>
        </visual>
        <collision>
            <origin xyz="0 0 0.855471935196358" rpy="0 0 0"/>
            <geometry>
                <box size="1.1598577811762902 2.8721280439745236 1.710943870392716" />
            </geometry>
        </collision>
    </link>
    <link name="Leg19">
        <inertial>
            <origin xyz="1.0264228274265723 0 0.992049807871442" rpy="0 0 0"/>
            <mass value="1" />
            <inertia ixx="100" ixy="0" ixz="0" iyy="100" iyz="0" izz="100" />
        </inertial>
        <visual>
            <origin xyz="1.0264228274265723 0 0.992049807871442" rpy="0 0 0"/>
            <geometry>
                <box size="2.0528456548531446 1.7048444322094591 1.984099615742884" />
            </geometry>
            <material name="Blue">
                <color rgba="0 1.0 1.0 1.0"/>
            </material>
        </visual>
        <collision>
            <origin xyz="1.0264228274265723 0 0.992049807871442" rpy="0 0 0"/>
            <geometry>
                <box size="2.0528456548531446 1.7048444322094591 1.984099615742884" />
            </geometry>
        </collision>
    </link>
    <link name="Leg20">
        <inertial>
            <origin xyz="0 2.3024320036570574 0" rpy="0 0 0"/>
            <mass value="1" />
            <inertia ixx="100" ixy="0" ixz="0" iyy="100" iyz="0" izz="100" />
        </inertial>
        <visual>
            <origin xyz="0 2.3024320036570574 0" rpy="0 0 0"/>
            <geometry>
                <box size="1.5827787296604543 2.3024320036570574 1.559811253367961" />
            </geometry>
            <material name="Blue">
                <color rgba="0 1.0 1.0 1.0"/>
            </material>
        </visual>
        <collision>
            <origin xyz="0 2.3024320036570574 0" rpy="0 0 0"/>
            <geometry>
                <box size="1.5827787296604543 2.3024320036570574 1.559811253367961" />
            </geometry>
        </collision>
    </link>
    <link name="Leg21">
        <inertial>
            <origin xyz="0 0 0.9966910042111913" rpy="0 0 0"/>
            <mass value="1" />
            <inertia ixx="100" ixy="0" ixz="0" iyy="100" iyz="0" izz="100" />
        </inertial>
        <visual>
            <origin xyz="0 0 0.9966910042111913" rpy="0 0 0"/>
            <geometry>
                <box size="2.5527104131378584 2.8965785299819053 1.9933820084223826" />
            </geometry>
            <material name="Blue">
                <color rgba="0 1.0 1.0 1.0"/>
            </material>
        </visual>
        <collision>
            <origin xyz="0 0 0.9966910042111913" rpy="0 0 0"/>
            <geometry>
                <box size="2.5527104131378584 2.8965785299819053 1.9933820084223826" />
            </geometry>
        </collision>
    </link>
    <link name="Leg22">
        <inertial>
            <origin xyz="0.8846652204237068 0 1.2836393546111777" rpy="0 0 0"/>
            <mass value="1" />
            <inertia ixx="100" ixy="0" ixz="0" iyy="100" iyz="0" izz="100" />
        </inertial>
        <visual>
            <origin xyz="0.8846652204237068 0 1.2836393546111777" rpy="0 0 0"/>
            <geometry>
                <box size="1.7693304408474135 1.860767273636157 2.5672787092223555" />
            </geometry>
            <material name="Blue">
                <color rgba="0 1.0 1.0 1.0"/>
            </material>
        </visual>
        <collision>
            <origin xyz="0.8846652204237068 0 1.2836393546111777" rpy="0 0 0"/>
            <geometry>
                <box size="1.7693304408474135 1.860767273636157 2.5672787092223555" />
            </geometry>
        </collision>
    </link>
    <link name="Leg23">
        <inertial>
            <origin xyz="0 0 1.3946073037436424" rpy="0 0 0"/>
            <mass value="1" />
            <inertia ixx="100" ixy="0" ixz="0" iyy="100" iyz="0" izz="100" />
        </inertial>
        <visual>
            <origin xyz="0 0 1.3946073037436424" rpy="0 0 0"/>
            <geometry>
                <box size="1.8453594714102028 1.36819584402497 2.789214607487285" />
            </geometry>
            <material name="Blue">
                <color rgba="0 1.0 1.0 1.0"/>
            </material>
        </visual>
        <collision>
            <origin xyz="0 0 1.3946073037436424" rpy="0 0 0"/>
            <geometry>
                <box size="1.8453594714102028 1.36819584402497 2.789214607487285" />
            </geometry>
        </collision>
    </link>
    <link name="Leg24">
        <inertial>
            <origin xyz="1.2628433668389611 0 0" rpy="0 0 0"/>
            <mass value="1" />
            <inertia ixx="100" ixy="0" ixz="0" iyy="100" iyz="0" izz="100" />
        </inertial>
        <visual>
            <origin xyz="1.2628433668389611 0 0" rpy="0 0 0"/>
            <geometry>
                <box size="2.5256867336779223 2.1540689603994077 1.0309089250456147" />
            </geometry>
            <material name="Blue">
                <color rgba="0 1.0 1.0 1.0"/>
            </material>
        </visual>
        <collision>
            <origin xyz="1.2628433668389611 0 0" rpy="0 0 0"/>
            <geometry>
                <box size="2.5256867336779223 2.1540689603994077 1.0309089250456147" />
            </geometry>
        </collision>
    </link>
    <link name="Leg25">
        <inertial>
            <origin xyz="0 0.760025708643589 0" rpy="0 0 0"/>
            <mass value="1" />
            <inertia ixx="100" ixy="0" ixz="0" iyy="100" iyz="0" izz="100" />
        </inertial>
        <visual>
            <origin xyz="0 0.760025708643589 0" rpy="0 0 0"/>
            <geometry>
                <box size="2.243457119898632 1.520051417287178 2.056856574271171" />
            </geometry>
            <material name="Green">
                <color rgba="0 180.0 100.0 1.0"/>
            </material>
        </visual>
        <collision>
            <origin xyz="0 0.760025708643589 0" rpy="0 0 0"/>
            <geometry>
                <box size="2.243457119898632 1.520051417287178 2.056856574271171" />
            </geometry>
        </collision>
    </link>
    <joint name="Torso_Leg1" type="revolute">
       <parent link="Torso"/>
       <child  link="Leg1"/>
       <origin rpy="0 0 0" xyz="0 0 1.738040960982616" />
     <axis xyz="1 0 0"/>
       <limit effort="0.0" lower="-3.14159" upper="3.14159" velocity="0.0"/>
    </joint>
    <joint name="Leg1_Leg2" type="revolute">
       <parent link="Leg1"/>
       <child  link="Leg2"/>
       <origin rpy="0 0 0" xyz="0 0 2.7793518695983295" />
     <axis xyz="1 0 0"/>
       <limit effort="0.0" lower="-3.14159" upper="3.14159" velocity="0.0"/>
    </joint>
    <joint name="Leg2_Leg3" type="revolute">
       <parent link="Leg2"/>
       <child  link="Leg3"/>
       <origin rpy="0 0 0" xyz="2.7705923331791302 0 0.8342051081360868" />
     <axis xyz="1 0 0"/>
       <limit effort="0.0" lower="-3.14159" upper="3.14159" velocity="0.0"/>
    </joint>
    <joint name="Leg3_Leg4" type="revolute">
       <parent link="Leg3"/>
       <child  link="Leg4"/>
       <origin rpy="0 0 0" xyz="0 1.4536159695814557 2.1704651420906633" />
     <axis xyz="1 0 0"/>
       <limit effort="0.0" lower="-3.14159" upper="3.14159" velocity="0.0"/>
    </joint>
    <joint name="Torso_Leg5" type="revolute">
       <parent link="Torso"/>
       <child  link="Leg5"/>
       <origin rpy="0 0 0" xyz="1.1362863323251386 0 1.4806508977874908" />
     <axis xyz="1 0 0"/>
       <limit effort="0.0" lower="-3.14159" upper="3.14159" velocity="0.0"/>
    </joint>
    <joint name="Leg4_Leg6" type="revolute">
       <parent link="Leg4"/>
       <child  link="Leg6"/>
       <origin rpy="0 0 0" xyz="2.60758108502823 0 1.1130931437094294" />
     <axis xyz="1 0 0"/>
       <limit effort="0.0" lower="-3.14159" upper="3.14159" velocity="0.0"/>
    </joint>
    <joint name="Leg3_Leg7" type="revolute">
       <parent link="Leg3"/>
       <child  link="Leg7"/>
       <origin rpy="0 0 0" xyz="0 1.4536159695814557 2.1704651420906633" />
     <axis xyz="1 0 0"/>
       <limit effort="0.0" lower="-3.14159" upper="3.14159" velocity="0.0"/>
    </joint>
    <joint name="Leg7_Leg8" type="revolute">
       <parent link="Leg7"/>
       <child  link="Leg8"/>
       <origin rpy="0 0 0" xyz="0 1.3577225116466227 1.6668612813478714" />
     <axis xyz="1 0 0"/>
       <limit effort="0.0" lower="-3.14159" upper="3.14159" velocity="0.0"/>
    </joint>
    <joint name="Leg5_Leg9" type="revolute">
       <parent link="Leg5"/>
       <child  link="Leg9"/>
       <origin rpy="0 0 0" xyz="0 0 1.756824288680455" />
     <axis xyz="1 0 0"/>
       <limit effort="0.0" lower="-3.14159" upper="3.14159" velocity="0.0"/>
    </joint>
    <joint name="Leg6_Leg10" type="revolute">
       <parent link="Leg6"/>
       <child  link="Leg10"/>
       <origin rpy="0 0 0" xyz="0 1.1576860171763288 1.209855996430278" />
     <axis xyz="1 0 0"/>
       <limit effort="0.0" lower="-3.14159" upper="3.14159" velocity="0.0"/>
    </joint>
    <joint name="Leg7_Leg11" type="revolute">
       <parent link="Leg7"/>
       <child  link="Leg11"/>
       <origin rpy="0 0 0" xyz="0 1.3577225116466227 1.6668612813478714" />
     <axis xyz="1 0 0"/>
       <limit effort="0.0" lower="-3.14159" upper="3.14159" velocity="0.0"/>
    </joint>
    <joint name="Leg8_Leg12" type="revolute">
       <parent link="Leg8"/>
       <child  link="Leg12"/>
       <origin rpy="0 0 0" xyz="0.9726823714927305 0 1.853766506456975" />
     <axis xyz="1 0 0"/>
       <limit effort="0.0" lower="-3.14159" upper="3.14159" velocity="0.0"/>
    </joint>
    <joint name="Leg8_Leg13" type="revolute">
       <parent link="Leg8"/>
       <child  link="Leg13"/>
       <origin rpy="0 0 0" xyz="0.9726823714927305 0 1.853766506456975" />
     <axis xyz="1 0 0"/>
       <limit effort="0.0" lower="-3.14159" upper="3.14159" velocity="0.0"/>
    </joint>
    <joint name="Leg12_Leg14" type="revolute">
       <parent link="Leg12"/>
       <child  link="Leg14"/>
       <origin rpy="0 0 0" xyz="0.7574355087845152 0 0.6103453619889836" />
     <axis xyz="1 0 0"/>
       <limit effort="0.0" lower="-3.14159" upper="3.14159" velocity="0.0"/>
    </joint>
    <joint name="Leg13_Leg15" type="revolute">
       <parent link="Leg13"/>
       <child  link="Leg15"/>
       <origin rpy="0 0 0" xyz="0.5338893920057555 0 0.8796644266345417" />
     <axis xyz="1 0 0"/>
       <limit effort="0.0" lower="-3.14159" upper="3.14159" velocity="0.0"/>
    </joint>
    <joint name="Leg2_Leg16" type="revolute">
       <parent link="Leg2"/>
       <child  link="Leg16"/>
       <origin rpy="0 0 0" xyz="2.7705923331791302 0 0.8342051081360868" />
     <axis xyz="1 0 0"/>
       <limit effort="0.0" lower="-3.14159" upper="3.14159" velocity="0.0"/>
    </joint>
    <joint name="Leg6_Leg17" type="revolute">
       <parent link="Leg6"/>
       <child  link="Leg17"/>
       <origin rpy="0 0 0" xyz="0 1.1576860171763288 1.209855996430278" />
     <axis xyz="1 0 0"/>
       <limit effort="0.0" lower="-3.14159" upper="3.14159" velocity="0.0"/>
    </joint>
    <joint name="Leg14_Leg18" type="revolute">
       <parent link="Leg14"/>
       <child  link="Leg18"/>
       <origin rpy="0 0 0" xyz="1.3693019238663062 0 1.1663307390376842" />
     <axis xyz="1 0 0"/>
       <limit effort="0.0" lower="-3.14159" upper="3.14159" velocity="0.0"/>
    </joint>
    <joint name="Leg15_Leg19" type="revolute">
       <parent link="Leg15"/>
       <child  link="Leg19"/>
       <origin rpy="0 0 0" xyz="1.4631259696151735 0 0.6024963755806582" />
     <axis xyz="1 0 0"/>
       <limit effort="0.0" lower="-3.14159" upper="3.14159" velocity="0.0"/>
    </joint>
    <joint name="Leg19_Leg20" type="revolute">
       <parent link="Leg19"/>
       <child  link="Leg20"/>
       <origin rpy="0 0 0" xyz="0 2.3024320036570574 0" />
     <axis xyz="1 0 0"/>
       <limit effort="0.0" lower="-3.14159" upper="3.14159" velocity="0.0"/>
    </joint>
    <joint name="Leg18_Leg21" type="revolute">
       <parent link="Leg18"/>
       <child  link="Leg21"/>
       <origin rpy="0 0 0" xyz="1.0264228274265723 0 0.992049807871442" />
     <axis xyz="1 0 0"/>
       <limit effort="0.0" lower="-3.14159" upper="3.14159" velocity="0.0"/>
    </joint>
    <joint name="Leg4_Leg22" type="revolute">
       <parent link="Leg4"/>
       <child  link="Leg22"/>
       <origin rpy="0 0 0" xyz="2.60758108502823 0 1.1130931437094294" />
     <axis xyz="1 0 0"/>
       <limit effort="0.0" lower="-3.14159" upper="3.14159" velocity="0.0"/>
    </joint>
    <joint name="Leg21_Leg23" type="revolute">
       <parent link="Leg21"/>
       <child  link="Leg23"/>
       <origin rpy="0 0 0" xyz="0.8846652204237068 0 1.2836393546111777" />
     <axis xyz="1 0 0"/>
       <limit effort="0.0" lower="-3.14159" upper="3.14159" velocity="0.0"/>
    </joint>
    <joint name="Leg9_Leg24" type="revolute">
       <parent link="Leg9"/>
       <child  link="Leg24"/>
       <origin rpy="0 0 0" xyz="1.3454720597109344 0.6681513319814988 0" />
     <axis xyz="1 0 0"/>
       <limit effort="0.0" lower="-3.14159" upper="3.14159" velocity="0.0"/>
    </joint>
    <joint name="Leg24_Leg25" type="revolute">
       <parent link="Leg24"/>
       <child  link="Leg24"/>
       <origin rpy="0 0 0" xyz="1.2628433668389611 1.0770344801997038 0" />
     <axis xyz="1 0 0"/>
       <limit effort="0.0" lower="-3.14159" upper="3.14159" velocity="0.0"/>
    </joint>
</robot>