<robot name = "robot">
    <link name="Torso">
        <inertial>
            <origin xyz="0 0 0.633183512609525" rpy="0 0 0"/>
            <mass value="1" />
            <inertia ixx="100" ixy="0" ixz="0" iyy="100" iyz="0" izz="100" />
        </inertial>
        <visual>
            <origin xyz="0 0 0.633183512609525" rpy="0 0 0"/>
            <geometry>
                <box size="2.5361753815915384 2.9758213061928194 1.26636702521905" />
            </geometry>
            <material name="Green">
                <color rgba="0 180.0 0.0 1.0"/>
            </material>
        </visual>
        <collision>
            <origin xyz="0 0 0.633183512609525" rpy="0 0 0"/>
            <geometry>
                <box size="2.5361753815915384 2.9758213061928194 1.26636702521905" />
            </geometry>
        </collision>
    </link>
    <link name="Leg1">
        <inertial>
            <origin xyz="1.4542993297221267 0 0" rpy="0 0 0"/>
            <mass value="1" />
            <inertia ixx="100" ixy="0" ixz="0" iyy="100" iyz="0" izz="100" />
        </inertial>
        <visual>
            <origin xyz="1.4542993297221267 0 0" rpy="0 0 0"/>
            <geometry>
                <box size="2.9085986594442534 2.0745490358267045 2.991502075835143" />
            </geometry>
            <material name="Blue">
                <color rgba="0 1.0 1.0 1.0"/>
            </material>
        </visual>
        <collision>
            <origin xyz="1.4542993297221267 0 0" rpy="0 0 0"/>
            <geometry>
                <box size="2.9085986594442534 2.0745490358267045 2.991502075835143" />
            </geometry>
        </collision>
    </link>
    <link name="Leg2">
        <inertial>
            <origin xyz="0.7263364266175947 0 0" rpy="0 0 0"/>
            <mass value="1" />
            <inertia ixx="100" ixy="0" ixz="0" iyy="100" iyz="0" izz="100" />
        </inertial>
        <visual>
            <origin xyz="0.7263364266175947 0 0" rpy="0 0 0"/>
            <geometry>
                <box size="1.4526728532351894 2.0550003511843347 2.0976552958388126" />
            </geometry>
            <material name="Blue">
                <color rgba="0 1.0 1.0 1.0"/>
            </material>
        </visual>
        <collision>
            <origin xyz="0.7263364266175947 0 0" rpy="0 0 0"/>
            <geometry>
                <box size="1.4526728532351894 2.0550003511843347 2.0976552958388126" />
            </geometry>
        </collision>
    </link>
    <link name="Leg3">
        <inertial>
            <origin xyz="0 0.6457823081613503 0" rpy="0 0 0"/>
            <mass value="1" />
            <inertia ixx="100" ixy="0" ixz="0" iyy="100" iyz="0" izz="100" />
        </inertial>
        <visual>
            <origin xyz="0 0.6457823081613503 0" rpy="0 0 0"/>
            <geometry>
                <box size="1.9598853782070467 1.2915646163227006 2.637148216311803" />
            </geometry>
            <material name="Blue">
                <color rgba="0 1.0 1.0 1.0"/>
            </material>
        </visual>
        <collision>
            <origin xyz="0 0.6457823081613503 0" rpy="0 0 0"/>
            <geometry>
                <box size="1.9598853782070467 1.2915646163227006 2.637148216311803" />
            </geometry>
        </collision>
    </link>
    <link name="Leg4">
        <inertial>
            <origin xyz="1.141399429407528 0 0" rpy="0 0 0"/>
            <mass value="1" />
            <inertia ixx="100" ixy="0" ixz="0" iyy="100" iyz="0" izz="100" />
        </inertial>
        <visual>
            <origin xyz="1.141399429407528 0 0" rpy="0 0 0"/>
            <geometry>
                <box size="2.282798858815056 1.6391020111585535 1.1123545267734967" />
            </geometry>
            <material name="Blue">
                <color rgba="0 1.0 1.0 1.0"/>
            </material>
        </visual>
        <collision>
            <origin xyz="1.141399429407528 0 0" rpy="0 0 0"/>
            <geometry>
                <box size="2.282798858815056 1.6391020111585535 1.1123545267734967" />
            </geometry>
        </collision>
    </link>
    <link name="Leg5">
        <inertial>
            <origin xyz="0 0 1.0662363732802052" rpy="0 0 0"/>
            <mass value="1" />
            <inertia ixx="100" ixy="0" ixz="0" iyy="100" iyz="0" izz="100" />
        </inertial>
        <visual>
            <origin xyz="0 0 1.0662363732802052" rpy="0 0 0"/>
            <geometry>
                <box size="1.6508891513009791 2.7440205005817555 2.1324727465604103" />
            </geometry>
            <material name="Green">
                <color rgba="0 180.0 0.0 1.0"/>
            </material>
        </visual>
        <collision>
            <origin xyz="0 0 1.0662363732802052" rpy="0 0 0"/>
            <geometry>
                <box size="1.6508891513009791 2.7440205005817555 2.1324727465604103" />
            </geometry>
        </collision>
    </link>
    <link name="Leg6">
        <inertial>
            <origin xyz="0.7367377975250022 0 0" rpy="0 0 0"/>
            <mass value="1" />
            <inertia ixx="100" ixy="0" ixz="0" iyy="100" iyz="0" izz="100" />
        </inertial>
        <visual>
            <origin xyz="0.7367377975250022 0 0" rpy="0 0 0"/>
            <geometry>
                <box size="1.4734755950500045 1.5794479989945192 2.596540759461263" />
            </geometry>
            <material name="Blue">
                <color rgba="0 1.0 1.0 1.0"/>
            </material>
        </visual>
        <collision>
            <origin xyz="0.7367377975250022 0 0" rpy="0 0 0"/>
            <geometry>
                <box size="1.4734755950500045 1.5794479989945192 2.596540759461263" />
            </geometry>
        </collision>
    </link>
    <link name="Leg7">
        <inertial>
            <origin xyz="0 1.4727209953839222 0" rpy="0 0 0"/>
            <mass value="1" />
            <inertia ixx="100" ixy="0" ixz="0" iyy="100" iyz="0" izz="100" />
        </inertial>
        <visual>
            <origin xyz="0 1.4727209953839222 0" rpy="0 0 0"/>
            <geometry>
                <box size="2.8233393371521487 2.9454419907678444 1.4100489018021898" />
            </geometry>
            <material name="Blue">
                <color rgba="0 1.0 1.0 1.0"/>
            </material>
        </visual>
        <collision>
            <origin xyz="0 1.4727209953839222 0" rpy="0 0 0"/>
            <geometry>
                <box size="2.8233393371521487 2.9454419907678444 1.4100489018021898" />
            </geometry>
        </collision>
    </link>
    <link name="Leg8">
        <inertial>
            <origin xyz="0 0 0.9197734102396036" rpy="0 0 0"/>
            <mass value="1" />
            <inertia ixx="100" ixy="0" ixz="0" iyy="100" iyz="0" izz="100" />
        </inertial>
        <visual>
            <origin xyz="0 0 0.9197734102396036" rpy="0 0 0"/>
            <geometry>
                <box size="1.4323738606764458 2.6446308885062715 1.8395468204792071" />
            </geometry>
            <material name="Green">
                <color rgba="0 180.0 0.0 1.0"/>
            </material>
        </visual>
        <collision>
            <origin xyz="0 0 0.9197734102396036" rpy="0 0 0"/>
            <geometry>
                <box size="1.4323738606764458 2.6446308885062715 1.8395468204792071" />
            </geometry>
        </collision>
    </link>
    <link name="Leg9">
        <inertial>
            <origin xyz="1.0708171451752095 0 0" rpy="0 0 0"/>
            <mass value="1" />
            <inertia ixx="100" ixy="0" ixz="0" iyy="100" iyz="0" izz="100" />
        </inertial>
        <visual>
            <origin xyz="1.0708171451752095 0 0" rpy="0 0 0"/>
            <geometry>
                <box size="2.141634290350419 1.063791566667162 2.2630506242175015" />
            </geometry>
            <material name="Blue">
                <color rgba="0 1.0 1.0 1.0"/>
            </material>
        </visual>
        <collision>
            <origin xyz="1.0708171451752095 0 0" rpy="0 0 0"/>
            <geometry>
                <box size="2.141634290350419 1.063791566667162 2.2630506242175015" />
            </geometry>
        </collision>
    </link>
    <link name="Leg10">
        <inertial>
            <origin xyz="0.8883361227784164 0 0" rpy="0 0 0"/>
            <mass value="1" />
            <inertia ixx="100" ixy="0" ixz="0" iyy="100" iyz="0" izz="100" />
        </inertial>
        <visual>
            <origin xyz="0.8883361227784164 0 0" rpy="0 0 0"/>
            <geometry>
                <box size="1.776672245556833 2.4975111533489573 1.0806087081581268" />
            </geometry>
            <material name="Blue">
                <color rgba="0 1.0 1.0 1.0"/>
            </material>
        </visual>
        <collision>
            <origin xyz="0.8883361227784164 0 0" rpy="0 0 0"/>
            <geometry>
                <box size="1.776672245556833 2.4975111533489573 1.0806087081581268" />
            </geometry>
        </collision>
    </link>
    <link name="Leg11">
        <inertial>
            <origin xyz="0.7610973309392361 0 0" rpy="0 0 0"/>
            <mass value="1" />
            <inertia ixx="100" ixy="0" ixz="0" iyy="100" iyz="0" izz="100" />
        </inertial>
        <visual>
            <origin xyz="0.7610973309392361 0 0" rpy="0 0 0"/>
            <geometry>
                <box size="1.5221946618784723 1.1490462542341509 2.6342975390376515" />
            </geometry>
            <material name="Green">
                <color rgba="0 180.0 0.0 1.0"/>
            </material>
        </visual>
        <collision>
            <origin xyz="0.7610973309392361 0 0" rpy="0 0 0"/>
            <geometry>
                <box size="1.5221946618784723 1.1490462542341509 2.6342975390376515" />
            </geometry>
        </collision>
    </link>
    <link name="Leg12">
        <inertial>
            <origin xyz="0 1.2392164211230434 0" rpy="0 0 0"/>
            <mass value="1" />
            <inertia ixx="100" ixy="0" ixz="0" iyy="100" iyz="0" izz="100" />
        </inertial>
        <visual>
            <origin xyz="0 1.2392164211230434 0" rpy="0 0 0"/>
            <geometry>
                <box size="1.0046848180601409 2.478432842246087 1.0317935756098107" />
            </geometry>
            <material name="Green">
                <color rgba="0 180.0 0.0 1.0"/>
            </material>
        </visual>
        <collision>
            <origin xyz="0 1.2392164211230434 0" rpy="0 0 0"/>
            <geometry>
                <box size="1.0046848180601409 2.478432842246087 1.0317935756098107" />
            </geometry>
        </collision>
    </link>
    <link name="Leg13">
        <inertial>
            <origin xyz="0 1.3294515705331738 0" rpy="0 0 0"/>
            <mass value="1" />
            <inertia ixx="100" ixy="0" ixz="0" iyy="100" iyz="0" izz="100" />
        </inertial>
        <visual>
            <origin xyz="0 1.3294515705331738 0" rpy="0 0 0"/>
            <geometry>
                <box size="2.6456156179966275 2.6589031410663475 2.9785322735572852" />
            </geometry>
            <material name="Green">
                <color rgba="0 180.0 0.0 1.0"/>
            </material>
        </visual>
        <collision>
            <origin xyz="0 1.3294515705331738 0" rpy="0 0 0"/>
            <geometry>
                <box size="2.6456156179966275 2.6589031410663475 2.9785322735572852" />
            </geometry>
        </collision>
    </link>
    <link name="Leg14">
        <inertial>
            <origin xyz="0 1.1484310937913311 0" rpy="0 0 0"/>
            <mass value="1" />
            <inertia ixx="100" ixy="0" ixz="0" iyy="100" iyz="0" izz="100" />
        </inertial>
        <visual>
            <origin xyz="0 1.1484310937913311 0" rpy="0 0 0"/>
            <geometry>
                <box size="1.056752777992986 2.2968621875826623 1.268017773547264" />
            </geometry>
            <material name="Blue">
                <color rgba="0 1.0 1.0 1.0"/>
            </material>
        </visual>
        <collision>
            <origin xyz="0 1.1484310937913311 0" rpy="0 0 0"/>
            <geometry>
                <box size="1.056752777992986 2.2968621875826623 1.268017773547264" />
            </geometry>
        </collision>
    </link>
    <link name="Leg15">
        <inertial>
            <origin xyz="0 0 0.671025306750767" rpy="0 0 0"/>
            <mass value="1" />
            <inertia ixx="100" ixy="0" ixz="0" iyy="100" iyz="0" izz="100" />
        </inertial>
        <visual>
            <origin xyz="0 0 0.671025306750767" rpy="0 0 0"/>
            <geometry>
                <box size="2.907777752896985 1.6803694191664034 1.342050613501534" />
            </geometry>
            <material name="Green">
                <color rgba="0 180.0 0.0 1.0"/>
            </material>
        </visual>
        <collision>
            <origin xyz="0 0 0.671025306750767" rpy="0 0 0"/>
            <geometry>
                <box size="2.907777752896985 1.6803694191664034 1.342050613501534" />
            </geometry>
        </collision>
    </link>
    <link name="Leg16">
        <inertial>
            <origin xyz="1.3292691267297765 0 0" rpy="0 0 0"/>
            <mass value="1" />
            <inertia ixx="100" ixy="0" ixz="0" iyy="100" iyz="0" izz="100" />
        </inertial>
        <visual>
            <origin xyz="1.3292691267297765 0 0" rpy="0 0 0"/>
            <geometry>
                <box size="2.658538253459553 2.1040927913800553 2.2027004871702047" />
            </geometry>
            <material name="Blue">
                <color rgba="0 1.0 1.0 1.0"/>
            </material>
        </visual>
        <collision>
            <origin xyz="1.3292691267297765 0 0" rpy="0 0 0"/>
            <geometry>
                <box size="2.658538253459553 2.1040927913800553 2.2027004871702047" />
            </geometry>
        </collision>
    </link>
    <link name="Leg17">
        <inertial>
            <origin xyz="1.2558317549683338 0 0" rpy="0 0 0"/>
            <mass value="1" />
            <inertia ixx="100" ixy="0" ixz="0" iyy="100" iyz="0" izz="100" />
        </inertial>
        <visual>
            <origin xyz="1.2558317549683338 0 0" rpy="0 0 0"/>
            <geometry>
                <box size="2.5116635099366675 2.405196683448851 1.7719455715124497" />
            </geometry>
            <material name="Blue">
                <color rgba="0 1.0 1.0 1.0"/>
            </material>
        </visual>
        <collision>
            <origin xyz="1.2558317549683338 0 0" rpy="0 0 0"/>
            <geometry>
                <box size="2.5116635099366675 2.405196683448851 1.7719455715124497" />
            </geometry>
        </collision>
    </link>
    <link name="Leg18">
        <inertial>
            <origin xyz="0.7946979275530281 0 0" rpy="0 0 0"/>
            <mass value="1" />
            <inertia ixx="100" ixy="0" ixz="0" iyy="100" iyz="0" izz="100" />
        </inertial>
        <visual>
            <origin xyz="0.7946979275530281 0 0" rpy="0 0 0"/>
            <geometry>
                <box size="1.5893958551060563 1.2059471867716933 2.1318978692991055" />
            </geometry>
            <material name="Blue">
                <color rgba="0 1.0 1.0 1.0"/>
            </material>
        </visual>
        <collision>
            <origin xyz="0.7946979275530281 0 0" rpy="0 0 0"/>
            <geometry>
                <box size="1.5893958551060563 1.2059471867716933 2.1318978692991055" />
            </geometry>
        </collision>
    </link>
    <link name="Leg19">
        <inertial>
            <origin xyz="0 1.382496571904785 0" rpy="0 0 0"/>
            <mass value="1" />
            <inertia ixx="100" ixy="0" ixz="0" iyy="100" iyz="0" izz="100" />
        </inertial>
        <visual>
            <origin xyz="0 1.382496571904785 0" rpy="0 0 0"/>
            <geometry>
                <box size="2.494662388659081 2.76499314380957 1.3730188325190769" />
            </geometry>
            <material name="Green">
                <color rgba="0 180.0 0.0 1.0"/>
            </material>
        </visual>
        <collision>
            <origin xyz="0 1.382496571904785 0" rpy="0 0 0"/>
            <geometry>
                <box size="2.494662388659081 2.76499314380957 1.3730188325190769" />
            </geometry>
        </collision>
    </link>
    <link name="Leg20">
        <inertial>
            <origin xyz="0 0 1.453813656773566" rpy="0 0 0"/>
            <mass value="1" />
            <inertia ixx="100" ixy="0" ixz="0" iyy="100" iyz="0" izz="100" />
        </inertial>
        <visual>
            <origin xyz="0 0 1.453813656773566" rpy="0 0 0"/>
            <geometry>
                <box size="2.908835578843448 2.351640930855532 2.907627313547132" />
            </geometry>
            <material name="Blue">
                <color rgba="0 1.0 1.0 1.0"/>
            </material>
        </visual>
        <collision>
            <origin xyz="0 0 1.453813656773566" rpy="0 0 0"/>
            <geometry>
                <box size="2.908835578843448 2.351640930855532 2.907627313547132" />
            </geometry>
        </collision>
    </link>
    <link name="Leg21">
        <inertial>
            <origin xyz="0 0.7652212056949133 0" rpy="0 0 0"/>
            <mass value="1" />
            <inertia ixx="100" ixy="0" ixz="0" iyy="100" iyz="0" izz="100" />
        </inertial>
        <visual>
            <origin xyz="0 0.7652212056949133 0" rpy="0 0 0"/>
            <geometry>
                <box size="2.9045531086421503 1.5304424113898265 2.0636841396887804" />
            </geometry>
            <material name="Green">
                <color rgba="0 180.0 0.0 1.0"/>
            </material>
        </visual>
        <collision>
            <origin xyz="0 0.7652212056949133 0" rpy="0 0 0"/>
            <geometry>
                <box size="2.9045531086421503 1.5304424113898265 2.0636841396887804" />
            </geometry>
        </collision>
    </link>
    <link name="Leg22">
        <inertial>
            <origin xyz="0 0.9044474748258137 0" rpy="0 0 0"/>
            <mass value="1" />
            <inertia ixx="100" ixy="0" ixz="0" iyy="100" iyz="0" izz="100" />
        </inertial>
        <visual>
            <origin xyz="0 0.9044474748258137 0" rpy="0 0 0"/>
            <geometry>
                <box size="1.6214328792991977 1.8088949496516273 2.0545909805362372" />
            </geometry>
            <material name="Green">
                <color rgba="0 180.0 0.0 1.0"/>
            </material>
        </visual>
        <collision>
            <origin xyz="0 0.9044474748258137 0" rpy="0 0 0"/>
            <geometry>
                <box size="1.6214328792991977 1.8088949496516273 2.0545909805362372" />
            </geometry>
        </collision>
    </link>
    <link name="Leg23">
        <inertial>
            <origin xyz="0 0.5138926693246716 0" rpy="0 0 0"/>
            <mass value="1" />
            <inertia ixx="100" ixy="0" ixz="0" iyy="100" iyz="0" izz="100" />
        </inertial>
        <visual>
            <origin xyz="0 0.5138926693246716 0" rpy="0 0 0"/>
            <geometry>
                <box size="2.2585478681707585 1.0277853386493432 1.229518203378688" />
            </geometry>
            <material name="Green">
                <color rgba="0 180.0 0.0 1.0"/>
            </material>
        </visual>
        <collision>
            <origin xyz="0 0.5138926693246716 0" rpy="0 0 0"/>
            <geometry>
                <box size="2.2585478681707585 1.0277853386493432 1.229518203378688" />
            </geometry>
        </collision>
    </link>
    <link name="Leg24">
        <inertial>
            <origin xyz="0 0 0.6956586266933609" rpy="0 0 0"/>
            <mass value="1" />
            <inertia ixx="100" ixy="0" ixz="0" iyy="100" iyz="0" izz="100" />
        </inertial>
        <visual>
            <origin xyz="0 0 0.6956586266933609" rpy="0 0 0"/>
            <geometry>
                <box size="2.611131234089811 1.6195803392887567 1.3913172533867217" />
            </geometry>
            <material name="Green">
                <color rgba="0 180.0 0.0 1.0"/>
            </material>
        </visual>
        <collision>
            <origin xyz="0 0 0.6956586266933609" rpy="0 0 0"/>
            <geometry>
                <box size="2.611131234089811 1.6195803392887567 1.3913172533867217" />
            </geometry>
        </collision>
    </link>
    <link name="Leg25">
        <inertial>
            <origin xyz="0 0.7335114608077611 0" rpy="0 0 0"/>
            <mass value="1" />
            <inertia ixx="100" ixy="0" ixz="0" iyy="100" iyz="0" izz="100" />
        </inertial>
        <visual>
            <origin xyz="0 0.7335114608077611 0" rpy="0 0 0"/>
            <geometry>
                <box size="2.5004198428563273 1.4670229216155222 1.9703337125173686" />
            </geometry>
            <material name="Green">
                <color rgba="0 180.0 0.0 1.0"/>
            </material>
        </visual>
        <collision>
            <origin xyz="0 0.7335114608077611 0" rpy="0 0 0"/>
            <geometry>
                <box size="2.5004198428563273 1.4670229216155222 1.9703337125173686" />
            </geometry>
        </collision>
    </link>
    <link name="Leg26">
        <inertial>
            <origin xyz="0 0 1.159966579818406" rpy="0 0 0"/>
            <mass value="1" />
            <inertia ixx="100" ixy="0" ixz="0" iyy="100" iyz="0" izz="100" />
        </inertial>
        <visual>
            <origin xyz="0 0 1.159966579818406" rpy="0 0 0"/>
            <geometry>
                <box size="1.4196930866358988 1.393332827286731 2.319933159636812" />
            </geometry>
            <material name="Blue">
                <color rgba="0 1.0 1.0 1.0"/>
            </material>
        </visual>
        <collision>
            <origin xyz="0 0 1.159966579818406" rpy="0 0 0"/>
            <geometry>
                <box size="1.4196930866358988 1.393332827286731 2.319933159636812" />
            </geometry>
        </collision>
    </link>
    <link name="Leg27">
        <inertial>
            <origin xyz="0.9502119194452687 0 0" rpy="0 0 0"/>
            <mass value="1" />
            <inertia ixx="100" ixy="0" ixz="0" iyy="100" iyz="0" izz="100" />
        </inertial>
        <visual>
            <origin xyz="0.9502119194452687 0 0" rpy="0 0 0"/>
            <geometry>
                <box size="1.9004238388905375 1.3612491329223355 1.0771881089556286" />
            </geometry>
            <material name="Green">
                <color rgba="0 180.0 0.0 1.0"/>
            </material>
        </visual>
        <collision>
            <origin xyz="0.9502119194452687 0 0" rpy="0 0 0"/>
            <geometry>
                <box size="1.9004238388905375 1.3612491329223355 1.0771881089556286" />
            </geometry>
        </collision>
    </link>
    <joint name="Torso_Leg1" type="revolute">
       <parent link="Torso"/>
       <child  link="Leg1"/>
       <origin rpy="0 0 0" xyz="1.2680876907957692 0 0.633183512609525" />
     <axis xyz="1 0 0"/>
       <limit effort="0.0" lower="-3.14159" upper="3.14159" velocity="0.0"/>
    </joint>
    <joint name="Leg1_Leg2" type="revolute">
       <parent link="Leg1"/>
       <child  link="Leg2"/>
       <origin rpy="0 0 0" xyz="1.4526728532351894 0 0" />
     <axis xyz="1 0 0"/>
       <limit effort="0.0" lower="-3.14159" upper="3.14159" velocity="0.0"/>
    </joint>
    <joint name="Leg2_Leg3" type="revolute">
       <parent link="Leg2"/>
       <child  link="Leg3"/>
       <origin rpy="0 0 0" xyz="0 1.2915646163227006 0" />
     <axis xyz="1 0 0"/>
       <limit effort="0.0" lower="-3.14159" upper="3.14159" velocity="0.0"/>
    </joint>
    <joint name="Leg2_Leg4" type="revolute">
       <parent link="Leg2"/>
       <child  link="Leg4"/>
       <origin rpy="0 0 0" xyz="0.9799426891035233 1.2915646163227006 0" />
     <axis xyz="1 0 0"/>
       <limit effort="0.0" lower="-3.14159" upper="3.14159" velocity="0.0"/>
    </joint>
    <joint name="Leg4_Leg5" type="revolute">
       <parent link="Leg4"/>
       <child  link="Leg5"/>
       <origin rpy="0 0 0" xyz="0 0 2.1324727465604103" />
     <axis xyz="1 0 0"/>
       <limit effort="0.0" lower="-3.14159" upper="3.14159" velocity="0.0"/>
    </joint>
    <joint name="Leg4_Leg6" type="revolute">
       <parent link="Leg4"/>
       <child  link="Leg6"/>
       <origin rpy="0 0 0" xyz="0.8254445756504896 0 2.1324727465604103" />
     <axis xyz="1 0 0"/>
       <limit effort="0.0" lower="-3.14159" upper="3.14159" velocity="0.0"/>
    </joint>
    <joint name="Leg4_Leg7" type="revolute">
       <parent link="Leg4"/>
       <child  link="Leg7"/>
       <origin rpy="0 0 0" xyz="0.8254445756504896 1.3720102502908778 2.1324727465604103" />
     <axis xyz="1 0 0"/>
       <limit effort="0.0" lower="-3.14159" upper="3.14159" velocity="0.0"/>
    </joint>
    <joint name="Leg7_Leg8" type="revolute">
       <parent link="Leg7"/>
       <child  link="Leg8"/>
       <origin rpy="0 0 0" xyz="0 0 1.8395468204792071" />
     <axis xyz="1 0 0"/>
       <limit effort="0.0" lower="-3.14159" upper="3.14159" velocity="0.0"/>
    </joint>
    <joint name="Leg3_Leg9" type="revolute">
       <parent link="Leg3"/>
       <child  link="Leg9"/>
       <origin rpy="0 0 0" xyz="2.282798858815056 0 0" />
     <axis xyz="1 0 0"/>
       <limit effort="0.0" lower="-3.14159" upper="3.14159" velocity="0.0"/>
    </joint>
    <joint name="Leg7_Leg10" type="revolute">
       <parent link="Leg7"/>
       <child  link="Leg10"/>
       <origin rpy="0 0 0" xyz="0.7161869303382229 0 1.8395468204792071" />
     <axis xyz="1 0 0"/>
       <limit effort="0.0" lower="-3.14159" upper="3.14159" velocity="0.0"/>
    </joint>
    <joint name="Leg9_Leg11" type="revolute">
       <parent link="Leg9"/>
       <child  link="Leg11"/>
       <origin rpy="0 0 0" xyz="1.776672245556833 0 0" />
     <axis xyz="1 0 0"/>
       <limit effort="0.0" lower="-3.14159" upper="3.14159" velocity="0.0"/>
    </joint>
    <joint name="Leg10_Leg12" type="revolute">
       <parent link="Leg10"/>
       <child  link="Leg12"/>
       <origin rpy="0 0 0" xyz="0.7610973309392361 0.5745231271170754 0" />
     <axis xyz="1 0 0"/>
       <limit effort="0.0" lower="-3.14159" upper="3.14159" velocity="0.0"/>
    </joint>
    <joint name="Leg11_Leg13" type="revolute">
       <parent link="Leg11"/>
       <child  link="Leg13"/>
       <origin rpy="0 0 0" xyz="0 2.478432842246087 0" />
     <axis xyz="1 0 0"/>
       <limit effort="0.0" lower="-3.14159" upper="3.14159" velocity="0.0"/>
    </joint>
    <joint name="Leg12_Leg14" type="revolute">
       <parent link="Leg12"/>
       <child  link="Leg14"/>
       <origin rpy="0 0 0" xyz="0 2.6589031410663475 0" />
     <axis xyz="1 0 0"/>
       <limit effort="0.0" lower="-3.14159" upper="3.14159" velocity="0.0"/>
    </joint>
    <joint name="Torso_Leg15" type="revolute">
       <parent link="Torso"/>
       <child  link="Leg15"/>
       <origin rpy="0 0 0" xyz="1.4542993297221267 0 1.4957510379175716" />
     <axis xyz="1 0 0"/>
       <limit effort="0.0" lower="-3.14159" upper="3.14159" velocity="0.0"/>
    </joint>
    <joint name="Leg8_Leg16" type="revolute">
       <parent link="Leg8"/>
       <child  link="Leg16"/>
       <origin rpy="0 0 0" xyz="2.141634290350419 0 0" />
     <axis xyz="1 0 0"/>
       <limit effort="0.0" lower="-3.14159" upper="3.14159" velocity="0.0"/>
    </joint>
    <joint name="Leg12_Leg17" type="revolute">
       <parent link="Leg12"/>
       <child  link="Leg17"/>
       <origin rpy="0 0 0" xyz="1.3228078089983137 2.6589031410663475 0" />
     <axis xyz="1 0 0"/>
       <limit effort="0.0" lower="-3.14159" upper="3.14159" velocity="0.0"/>
    </joint>
    <joint name="Leg13_Leg18" type="revolute">
       <parent link="Leg13"/>
       <child  link="Leg18"/>
       <origin rpy="0 0 0" xyz="0.528376388996493 1.1484310937913311 0" />
     <axis xyz="1 0 0"/>
       <limit effort="0.0" lower="-3.14159" upper="3.14159" velocity="0.0"/>
    </joint>
    <joint name="Leg14_Leg19" type="revolute">
       <parent link="Leg14"/>
       <child  link="Leg19"/>
       <origin rpy="0 0 0" xyz="0 0.8401847095832017 0.671025306750767" />
     <axis xyz="1 0 0"/>
       <limit effort="0.0" lower="-3.14159" upper="3.14159" velocity="0.0"/>
    </joint>
    <joint name="Leg17_Leg20" type="revolute">
       <parent link="Leg17"/>
       <child  link="Leg20"/>
       <origin rpy="0 0 0" xyz="0.7946979275530281 0 1.0659489346495528" />
     <axis xyz="1 0 0"/>
       <limit effort="0.0" lower="-3.14159" upper="3.14159" velocity="0.0"/>
    </joint>
    <joint name="Torso_Leg21" type="revolute">
       <parent link="Torso"/>
       <child  link="Leg21"/>
       <origin rpy="0 0 0" xyz="1.4542993297221267 1.0372745179133522 1.4957510379175716" />
     <axis xyz="1 0 0"/>
       <limit effort="0.0" lower="-3.14159" upper="3.14159" velocity="0.0"/>
    </joint>
    <joint name="Leg5_Leg22" type="revolute">
       <parent link="Leg5"/>
       <child  link="Leg22"/>
       <origin rpy="0 0 0" xyz="0.7367377975250022 0.7897239994972596 0" />
     <axis xyz="1 0 0"/>
       <limit effort="0.0" lower="-3.14159" upper="3.14159" velocity="0.0"/>
    </joint>
    <joint name="Leg15_Leg23" type="revolute">
       <parent link="Leg15"/>
       <child  link="Leg23"/>
       <origin rpy="0 0 0" xyz="1.3292691267297765 1.0520463956900277 0" />
     <axis xyz="1 0 0"/>
       <limit effort="0.0" lower="-3.14159" upper="3.14159" velocity="0.0"/>
    </joint>
    <joint name="Leg14_Leg24" type="revolute">
       <parent link="Leg14"/>
       <child  link="Leg24"/>
       <origin rpy="0 0 0" xyz="0 0.8401847095832017 1.342050613501534" />
     <axis xyz="1 0 0"/>
       <limit effort="0.0" lower="-3.14159" upper="3.14159" velocity="0.0"/>
    </joint>
    <joint name="Leg3_Leg25" type="revolute">
       <parent link="Leg3"/>
       <child  link="Leg25"/>
       <origin rpy="0 0 0" xyz="2.282798858815056 0.8195510055792767 0" />
     <axis xyz="1 0 0"/>
       <limit effort="0.0" lower="-3.14159" upper="3.14159" velocity="0.0"/>
    </joint>
    <joint name="Leg21_Leg26" type="revolute">
       <parent link="Leg21"/>
       <child  link="Leg26"/>
       <origin rpy="0 0 0" xyz="0 0.9044474748258137 1.0272954902681186" />
     <axis xyz="1 0 0"/>
       <limit effort="0.0" lower="-3.14159" upper="3.14159" velocity="0.0"/>
    </joint>
    <joint name="Leg19_Leg27" type="revolute">
       <parent link="Leg19"/>
       <child  link="Leg27"/>
       <origin rpy="0 0 0" xyz="1.454417789421724 0 1.453813656773566" />
     <axis xyz="1 0 0"/>
       <limit effort="0.0" lower="-3.14159" upper="3.14159" velocity="0.0"/>
    </joint>
</robot>