<robot name = "robot">
    <link name="Torso">
        <inertial>
            <origin xyz="0 0 1.0778602682256935" rpy="0 0 0"/>
            <mass value="1" />
            <inertia ixx="100" ixy="0" ixz="0" iyy="100" iyz="0" izz="100" />
        </inertial>
        <visual>
            <origin xyz="0 0 1.0778602682256935" rpy="0 0 0"/>
            <geometry>
                <box size="2.258299675269501 2.8880518051460076 2.155720536451387" />
            </geometry>
            <material name="Green">
                <color rgba="0 180.0 0.0 1.0"/>
            </material>
        </visual>
        <collision>
            <origin xyz="0 0 1.0778602682256935" rpy="0 0 0"/>
            <geometry>
                <box size="2.258299675269501 2.8880518051460076 2.155720536451387" />
            </geometry>
        </collision>
    </link>
    <link name="Leg1">
        <inertial>
            <origin xyz="0 0 1.2018407935339792" rpy="0 0 0"/>
            <mass value="1" />
            <inertia ixx="100" ixy="0" ixz="0" iyy="100" iyz="0" izz="100" />
        </inertial>
        <visual>
            <origin xyz="0 0 1.2018407935339792" rpy="0 0 0"/>
            <geometry>
                <box size="2.6978430400273474 2.9199398083752968 2.4036815870679584" />
            </geometry>
            <material name="Blue">
                <color rgba="0 1.0 1.0 1.0"/>
            </material>
        </visual>
        <collision>
            <origin xyz="0 0 1.2018407935339792" rpy="0 0 0"/>
            <geometry>
                <box size="2.6978430400273474 2.9199398083752968 2.4036815870679584" />
            </geometry>
        </collision>
    </link>
    <link name="Leg2">
        <inertial>
            <origin xyz="0 1.0741779297693694 0" rpy="0 0 0"/>
            <mass value="1" />
            <inertia ixx="100" ixy="0" ixz="0" iyy="100" iyz="0" izz="100" />
        </inertial>
        <visual>
            <origin xyz="0 1.0741779297693694 0" rpy="0 0 0"/>
            <geometry>
                <box size="2.4875726967008096 2.148355859538739 2.591132746186798" />
            </geometry>
            <material name="Green">
                <color rgba="0 180.0 0.0 1.0"/>
            </material>
        </visual>
        <collision>
            <origin xyz="0 1.0741779297693694 0" rpy="0 0 0"/>
            <geometry>
                <box size="2.4875726967008096 2.148355859538739 2.591132746186798" />
            </geometry>
        </collision>
    </link>
    <link name="Leg3">
        <inertial>
            <origin xyz="0 0 1.4679399629554708" rpy="0 0 0"/>
            <mass value="1" />
            <inertia ixx="100" ixy="0" ixz="0" iyy="100" iyz="0" izz="100" />
        </inertial>
        <visual>
            <origin xyz="0 0 1.4679399629554708" rpy="0 0 0"/>
            <geometry>
                <box size="1.6699658596466462 1.4808519876182173 2.9358799259109416" />
            </geometry>
            <material name="Blue">
                <color rgba="0 1.0 1.0 1.0"/>
            </material>
        </visual>
        <collision>
            <origin xyz="0 0 1.4679399629554708" rpy="0 0 0"/>
            <geometry>
                <box size="1.6699658596466462 1.4808519876182173 2.9358799259109416" />
            </geometry>
        </collision>
    </link>
    <link name="Leg4">
        <inertial>
            <origin xyz="0 1.2836259589346102 0" rpy="0 0 0"/>
            <mass value="1" />
            <inertia ixx="100" ixy="0" ixz="0" iyy="100" iyz="0" izz="100" />
        </inertial>
        <visual>
            <origin xyz="0 1.2836259589346102 0" rpy="0 0 0"/>
            <geometry>
                <box size="2.492581245698239 2.5672519178692204 2.344154577909718" />
            </geometry>
            <material name="Blue">
                <color rgba="0 1.0 1.0 1.0"/>
            </material>
        </visual>
        <collision>
            <origin xyz="0 1.2836259589346102 0" rpy="0 0 0"/>
            <geometry>
                <box size="2.492581245698239 2.5672519178692204 2.344154577909718" />
            </geometry>
        </collision>
    </link>
    <link name="Leg5">
        <inertial>
            <origin xyz="0 0 1.108199504609771" rpy="0 0 0"/>
            <mass value="1" />
            <inertia ixx="100" ixy="0" ixz="0" iyy="100" iyz="0" izz="100" />
        </inertial>
        <visual>
            <origin xyz="0 0 1.108199504609771" rpy="0 0 0"/>
            <geometry>
                <box size="1.2398793300637534 1.6087239990845774 2.216399009219542" />
            </geometry>
            <material name="Green">
                <color rgba="0 180.0 0.0 1.0"/>
            </material>
        </visual>
        <collision>
            <origin xyz="0 0 1.108199504609771" rpy="0 0 0"/>
            <geometry>
                <box size="1.2398793300637534 1.6087239990845774 2.216399009219542" />
            </geometry>
        </collision>
    </link>
    <link name="Leg6">
        <inertial>
            <origin xyz="0 1.0583516591742699 0" rpy="0 0 0"/>
            <mass value="1" />
            <inertia ixx="100" ixy="0" ixz="0" iyy="100" iyz="0" izz="100" />
        </inertial>
        <visual>
            <origin xyz="0 1.0583516591742699 0" rpy="0 0 0"/>
            <geometry>
                <box size="2.478050577815447 2.1167033183485398 1.7252321351815723" />
            </geometry>
            <material name="Green">
                <color rgba="0 180.0 0.0 1.0"/>
            </material>
        </visual>
        <collision>
            <origin xyz="0 1.0583516591742699 0" rpy="0 0 0"/>
            <geometry>
                <box size="2.478050577815447 2.1167033183485398 1.7252321351815723" />
            </geometry>
        </collision>
    </link>
    <link name="Leg7">
        <inertial>
            <origin xyz="1.2448595467282257 0 0" rpy="0 0 0"/>
            <mass value="1" />
            <inertia ixx="100" ixy="0" ixz="0" iyy="100" iyz="0" izz="100" />
        </inertial>
        <visual>
            <origin xyz="1.2448595467282257 0 0" rpy="0 0 0"/>
            <geometry>
                <box size="2.4897190934564515 2.188192054280268 2.220425255387064" />
            </geometry>
            <material name="Blue">
                <color rgba="0 1.0 1.0 1.0"/>
            </material>
        </visual>
        <collision>
            <origin xyz="1.2448595467282257 0 0" rpy="0 0 0"/>
            <geometry>
                <box size="2.4897190934564515 2.188192054280268 2.220425255387064" />
            </geometry>
        </collision>
    </link>
    <link name="Leg8">
        <inertial>
            <origin xyz="0.7234792264059904 0 0" rpy="0 0 0"/>
            <mass value="1" />
            <inertia ixx="100" ixy="0" ixz="0" iyy="100" iyz="0" izz="100" />
        </inertial>
        <visual>
            <origin xyz="0.7234792264059904 0 0" rpy="0 0 0"/>
            <geometry>
                <box size="1.4469584528119808 2.4936919712879817 1.1633349467212106" />
            </geometry>
            <material name="Blue">
                <color rgba="0 1.0 1.0 1.0"/>
            </material>
        </visual>
        <collision>
            <origin xyz="0.7234792264059904 0 0" rpy="0 0 0"/>
            <geometry>
                <box size="1.4469584528119808 2.4936919712879817 1.1633349467212106" />
            </geometry>
        </collision>
    </link>
    <link name="Leg9">
        <inertial>
            <origin xyz="0 0.7952082918455342 0" rpy="0 0 0"/>
            <mass value="1" />
            <inertia ixx="100" ixy="0" ixz="0" iyy="100" iyz="0" izz="100" />
        </inertial>
        <visual>
            <origin xyz="0 0.7952082918455342 0" rpy="0 0 0"/>
            <geometry>
                <box size="2.16351510017638 1.5904165836910684 2.3211814562766286" />
            </geometry>
            <material name="Blue">
                <color rgba="0 1.0 1.0 1.0"/>
            </material>
        </visual>
        <collision>
            <origin xyz="0 0.7952082918455342 0" rpy="0 0 0"/>
            <geometry>
                <box size="2.16351510017638 1.5904165836910684 2.3211814562766286" />
            </geometry>
        </collision>
    </link>
    <link name="Leg10">
        <inertial>
            <origin xyz="0.5538049959947937 0 0" rpy="0 0 0"/>
            <mass value="1" />
            <inertia ixx="100" ixy="0" ixz="0" iyy="100" iyz="0" izz="100" />
        </inertial>
        <visual>
            <origin xyz="0.5538049959947937 0 0" rpy="0 0 0"/>
            <geometry>
                <box size="1.1076099919895874 2.7649659978643397 1.8778183416542775" />
            </geometry>
            <material name="Blue">
                <color rgba="0 1.0 1.0 1.0"/>
            </material>
        </visual>
        <collision>
            <origin xyz="0.5538049959947937 0 0" rpy="0 0 0"/>
            <geometry>
                <box size="1.1076099919895874 2.7649659978643397 1.8778183416542775" />
            </geometry>
        </collision>
    </link>
    <link name="Leg11">
        <inertial>
            <origin xyz="0.7428420088797256 0 0" rpy="0 0 0"/>
            <mass value="1" />
            <inertia ixx="100" ixy="0" ixz="0" iyy="100" iyz="0" izz="100" />
        </inertial>
        <visual>
            <origin xyz="0.7428420088797256 0 0" rpy="0 0 0"/>
            <geometry>
                <box size="1.4856840177594512 1.7208921371734685 2.799966833968714" />
            </geometry>
            <material name="Green">
                <color rgba="0 180.0 0.0 1.0"/>
            </material>
        </visual>
        <collision>
            <origin xyz="0.7428420088797256 0 0" rpy="0 0 0"/>
            <geometry>
                <box size="1.4856840177594512 1.7208921371734685 2.799966833968714" />
            </geometry>
        </collision>
    </link>
    <link name="Leg12">
        <inertial>
            <origin xyz="0 1.4919598320306373 0" rpy="0 0 0"/>
            <mass value="1" />
            <inertia ixx="100" ixy="0" ixz="0" iyy="100" iyz="0" izz="100" />
        </inertial>
        <visual>
            <origin xyz="0 1.4919598320306373 0" rpy="0 0 0"/>
            <geometry>
                <box size="2.926326488059569 2.9839196640612746 1.2443891150363282" />
            </geometry>
            <material name="Blue">
                <color rgba="0 1.0 1.0 1.0"/>
            </material>
        </visual>
        <collision>
            <origin xyz="0 1.4919598320306373 0" rpy="0 0 0"/>
            <geometry>
                <box size="2.926326488059569 2.9839196640612746 1.2443891150363282" />
            </geometry>
        </collision>
    </link>
    <link name="Leg13">
        <inertial>
            <origin xyz="0 0.64202708957877 0" rpy="0 0 0"/>
            <mass value="1" />
            <inertia ixx="100" ixy="0" ixz="0" iyy="100" iyz="0" izz="100" />
        </inertial>
        <visual>
            <origin xyz="0 0.64202708957877 0" rpy="0 0 0"/>
            <geometry>
                <box size="1.076686411144199 1.28405417915754 2.009689071551671" />
            </geometry>
            <material name="Blue">
                <color rgba="0 1.0 1.0 1.0"/>
            </material>
        </visual>
        <collision>
            <origin xyz="0 0.64202708957877 0" rpy="0 0 0"/>
            <geometry>
                <box size="1.076686411144199 1.28405417915754 2.009689071551671" />
            </geometry>
        </collision>
    </link>
    <link name="Leg14">
        <inertial>
            <origin xyz="1.2642675726819332 0 0" rpy="0 0 0"/>
            <mass value="1" />
            <inertia ixx="100" ixy="0" ixz="0" iyy="100" iyz="0" izz="100" />
        </inertial>
        <visual>
            <origin xyz="1.2642675726819332 0 0" rpy="0 0 0"/>
            <geometry>
                <box size="2.5285351453638665 2.0267029725607673 2.4030484339223435" />
            </geometry>
            <material name="Blue">
                <color rgba="0 1.0 1.0 1.0"/>
            </material>
        </visual>
        <collision>
            <origin xyz="1.2642675726819332 0 0" rpy="0 0 0"/>
            <geometry>
                <box size="2.5285351453638665 2.0267029725607673 2.4030484339223435" />
            </geometry>
        </collision>
    </link>
    <link name="Leg15">
        <inertial>
            <origin xyz="0 1.286938043332261 0" rpy="0 0 0"/>
            <mass value="1" />
            <inertia ixx="100" ixy="0" ixz="0" iyy="100" iyz="0" izz="100" />
        </inertial>
        <visual>
            <origin xyz="0 1.286938043332261 0" rpy="0 0 0"/>
            <geometry>
                <box size="1.147421360175693 2.573876086664522 2.6685015881878744" />
            </geometry>
            <material name="Green">
                <color rgba="0 180.0 0.0 1.0"/>
            </material>
        </visual>
        <collision>
            <origin xyz="0 1.286938043332261 0" rpy="0 0 0"/>
            <geometry>
                <box size="1.147421360175693 2.573876086664522 2.6685015881878744" />
            </geometry>
        </collision>
    </link>
    <link name="Leg16">
        <inertial>
            <origin xyz="0 1.4283589407173034 0" rpy="0 0 0"/>
            <mass value="1" />
            <inertia ixx="100" ixy="0" ixz="0" iyy="100" iyz="0" izz="100" />
        </inertial>
        <visual>
            <origin xyz="0 1.4283589407173034 0" rpy="0 0 0"/>
            <geometry>
                <box size="2.7944419007237817 2.856717881434607 2.8857361812014215" />
            </geometry>
            <material name="Blue">
                <color rgba="0 1.0 1.0 1.0"/>
            </material>
        </visual>
        <collision>
            <origin xyz="0 1.4283589407173034 0" rpy="0 0 0"/>
            <geometry>
                <box size="2.7944419007237817 2.856717881434607 2.8857361812014215" />
            </geometry>
        </collision>
    </link>
    <link name="Leg17">
        <inertial>
            <origin xyz="0 0 1.3311322988160348" rpy="0 0 0"/>
            <mass value="1" />
            <inertia ixx="100" ixy="0" ixz="0" iyy="100" iyz="0" izz="100" />
        </inertial>
        <visual>
            <origin xyz="0 0 1.3311322988160348" rpy="0 0 0"/>
            <geometry>
                <box size="2.369258275831225 1.5158422091600838 2.6622645976320696" />
            </geometry>
            <material name="Green">
                <color rgba="0 180.0 0.0 1.0"/>
            </material>
        </visual>
        <collision>
            <origin xyz="0 0 1.3311322988160348" rpy="0 0 0"/>
            <geometry>
                <box size="2.369258275831225 1.5158422091600838 2.6622645976320696" />
            </geometry>
        </collision>
    </link>
    <link name="Leg18">
        <inertial>
            <origin xyz="0 0 1.1476859670704032" rpy="0 0 0"/>
            <mass value="1" />
            <inertia ixx="100" ixy="0" ixz="0" iyy="100" iyz="0" izz="100" />
        </inertial>
        <visual>
            <origin xyz="0 0 1.1476859670704032" rpy="0 0 0"/>
            <geometry>
                <box size="1.0998838296048425 1.2676546528711128 2.2953719341408063" />
            </geometry>
            <material name="Green">
                <color rgba="0 180.0 0.0 1.0"/>
            </material>
        </visual>
        <collision>
            <origin xyz="0 0 1.1476859670704032" rpy="0 0 0"/>
            <geometry>
                <box size="1.0998838296048425 1.2676546528711128 2.2953719341408063" />
            </geometry>
        </collision>
    </link>
    <link name="Leg19">
        <inertial>
            <origin xyz="0 0 1.2355440579872106" rpy="0 0 0"/>
            <mass value="1" />
            <inertia ixx="100" ixy="0" ixz="0" iyy="100" iyz="0" izz="100" />
        </inertial>
        <visual>
            <origin xyz="0 0 1.2355440579872106" rpy="0 0 0"/>
            <geometry>
                <box size="2.961787691869416 1.0694438348744786 2.471088115974421" />
            </geometry>
            <material name="Green">
                <color rgba="0 180.0 0.0 1.0"/>
            </material>
        </visual>
        <collision>
            <origin xyz="0 0 1.2355440579872106" rpy="0 0 0"/>
            <geometry>
                <box size="2.961787691869416 1.0694438348744786 2.471088115974421" />
            </geometry>
        </collision>
    </link>
    <link name="Leg20">
        <inertial>
            <origin xyz="1.4633261842003455 0 0" rpy="0 0 0"/>
            <mass value="1" />
            <inertia ixx="100" ixy="0" ixz="0" iyy="100" iyz="0" izz="100" />
        </inertial>
        <visual>
            <origin xyz="1.4633261842003455 0 0" rpy="0 0 0"/>
            <geometry>
                <box size="2.926652368400691 2.0529486933264773 2.13340961645834" />
            </geometry>
            <material name="Blue">
                <color rgba="0 1.0 1.0 1.0"/>
            </material>
        </visual>
        <collision>
            <origin xyz="1.4633261842003455 0 0" rpy="0 0 0"/>
            <geometry>
                <box size="2.926652368400691 2.0529486933264773 2.13340961645834" />
            </geometry>
        </collision>
    </link>
    <link name="Leg21">
        <inertial>
            <origin xyz="0 1.0069135244930951 0" rpy="0 0 0"/>
            <mass value="1" />
            <inertia ixx="100" ixy="0" ixz="0" iyy="100" iyz="0" izz="100" />
        </inertial>
        <visual>
            <origin xyz="0 1.0069135244930951 0" rpy="0 0 0"/>
            <geometry>
                <box size="2.7768043616504445 2.0138270489861902 2.9765502083334656" />
            </geometry>
            <material name="Green">
                <color rgba="0 180.0 0.0 1.0"/>
            </material>
        </visual>
        <collision>
            <origin xyz="0 1.0069135244930951 0" rpy="0 0 0"/>
            <geometry>
                <box size="2.7768043616504445 2.0138270489861902 2.9765502083334656" />
            </geometry>
        </collision>
    </link>
    <link name="Leg22">
        <inertial>
            <origin xyz="0 0 1.055656012438009" rpy="0 0 0"/>
            <mass value="1" />
            <inertia ixx="100" ixy="0" ixz="0" iyy="100" iyz="0" izz="100" />
        </inertial>
        <visual>
            <origin xyz="0 0 1.055656012438009" rpy="0 0 0"/>
            <geometry>
                <box size="1.0080098994838371 2.4085557568970746 2.111312024876018" />
            </geometry>
            <material name="Blue">
                <color rgba="0 1.0 1.0 1.0"/>
            </material>
        </visual>
        <collision>
            <origin xyz="0 0 1.055656012438009" rpy="0 0 0"/>
            <geometry>
                <box size="1.0080098994838371 2.4085557568970746 2.111312024876018" />
            </geometry>
        </collision>
    </link>
    <link name="Leg23">
        <inertial>
            <origin xyz="0 0.763870571080828 0" rpy="0 0 0"/>
            <mass value="1" />
            <inertia ixx="100" ixy="0" ixz="0" iyy="100" iyz="0" izz="100" />
        </inertial>
        <visual>
            <origin xyz="0 0.763870571080828 0" rpy="0 0 0"/>
            <geometry>
                <box size="2.705795181125957 1.527741142161656 2.096366340898277" />
            </geometry>
            <material name="Blue">
                <color rgba="0 1.0 1.0 1.0"/>
            </material>
        </visual>
        <collision>
            <origin xyz="0 0.763870571080828 0" rpy="0 0 0"/>
            <geometry>
                <box size="2.705795181125957 1.527741142161656 2.096366340898277" />
            </geometry>
        </collision>
    </link>
    <link name="Leg24">
        <inertial>
            <origin xyz="0 0 1.2724054893086723" rpy="0 0 0"/>
            <mass value="1" />
            <inertia ixx="100" ixy="0" ixz="0" iyy="100" iyz="0" izz="100" />
        </inertial>
        <visual>
            <origin xyz="0 0 1.2724054893086723" rpy="0 0 0"/>
            <geometry>
                <box size="1.1205196137612297 1.1099250208946692 2.5448109786173445" />
            </geometry>
            <material name="Green">
                <color rgba="0 180.0 0.0 1.0"/>
            </material>
        </visual>
        <collision>
            <origin xyz="0 0 1.2724054893086723" rpy="0 0 0"/>
            <geometry>
                <box size="1.1205196137612297 1.1099250208946692 2.5448109786173445" />
            </geometry>
        </collision>
    </link>
    <link name="Leg25">
        <inertial>
            <origin xyz="0 0 0.8207834055056425" rpy="0 0 0"/>
            <mass value="1" />
            <inertia ixx="100" ixy="0" ixz="0" iyy="100" iyz="0" izz="100" />
        </inertial>
        <visual>
            <origin xyz="0 0 0.8207834055056425" rpy="0 0 0"/>
            <geometry>
                <box size="1.2306561024629896 1.2944100305399648 1.641566811011285" />
            </geometry>
            <material name="Blue">
                <color rgba="0 1.0 1.0 1.0"/>
            </material>
        </visual>
        <collision>
            <origin xyz="0 0 0.8207834055056425" rpy="0 0 0"/>
            <geometry>
                <box size="1.2306561024629896 1.2944100305399648 1.641566811011285" />
            </geometry>
        </collision>
    </link>
    <joint name="Torso_Leg1" type="revolute">
       <parent link="Torso"/>
       <child  link="Leg1"/>
       <origin rpy="0 0 0" xyz="0 0 2.155720536451387" />
     <axis xyz="1 0 0"/>
       <limit effort="0.0" lower="-3.14159" upper="3.14159" velocity="0.0"/>
    </joint>
    <joint name="Leg1_Leg2" type="revolute">
       <parent link="Leg1"/>
       <child  link="Leg2"/>
       <origin rpy="0 0 0" xyz="0 2.148355859538739 0" />
     <axis xyz="1 0 0"/>
       <limit effort="0.0" lower="-3.14159" upper="3.14159" velocity="0.0"/>
    </joint>
    <joint name="Leg1_Leg3" type="revolute">
       <parent link="Leg1"/>
       <child  link="Leg3"/>
       <origin rpy="0 0 0" xyz="0 2.148355859538739 1.295566373093399" />
     <axis xyz="1 0 0"/>
       <limit effort="0.0" lower="-3.14159" upper="3.14159" velocity="0.0"/>
    </joint>
    <joint name="Leg2_Leg4" type="revolute">
       <parent link="Leg2"/>
       <child  link="Leg4"/>
       <origin rpy="0 0 0" xyz="0 0.7404259938091087 1.4679399629554708" />
     <axis xyz="1 0 0"/>
       <limit effort="0.0" lower="-3.14159" upper="3.14159" velocity="0.0"/>
    </joint>
    <joint name="Leg4_Leg5" type="revolute">
       <parent link="Leg4"/>
       <child  link="Leg5"/>
       <origin rpy="0 0 0" xyz="0 0 2.216399009219542" />
     <axis xyz="1 0 0"/>
       <limit effort="0.0" lower="-3.14159" upper="3.14159" velocity="0.0"/>
    </joint>
    <joint name="Leg3_Leg6" type="revolute">
       <parent link="Leg3"/>
       <child  link="Leg6"/>
       <origin rpy="0 0 0" xyz="0 2.5672519178692204 0" />
     <axis xyz="1 0 0"/>
       <limit effort="0.0" lower="-3.14159" upper="3.14159" velocity="0.0"/>
    </joint>
    <joint name="Leg2_Leg7" type="revolute">
       <parent link="Leg2"/>
       <child  link="Leg7"/>
       <origin rpy="0 0 0" xyz="0.8349829298233231 0.7404259938091087 1.4679399629554708" />
     <axis xyz="1 0 0"/>
       <limit effort="0.0" lower="-3.14159" upper="3.14159" velocity="0.0"/>
    </joint>
    <joint name="Leg7_Leg8" type="revolute">
       <parent link="Leg7"/>
       <child  link="Leg8"/>
       <origin rpy="0 0 0" xyz="1.4469584528119808 0 0" />
     <axis xyz="1 0 0"/>
       <limit effort="0.0" lower="-3.14159" upper="3.14159" velocity="0.0"/>
    </joint>
    <joint name="Leg7_Leg9" type="revolute">
       <parent link="Leg7"/>
       <child  link="Leg9"/>
       <origin rpy="0 0 0" xyz="1.4469584528119808 1.2468459856439909 0" />
     <axis xyz="1 0 0"/>
       <limit effort="0.0" lower="-3.14159" upper="3.14159" velocity="0.0"/>
    </joint>
    <joint name="Leg5_Leg10" type="revolute">
       <parent link="Leg5"/>
       <child  link="Leg10"/>
       <origin rpy="0 0 0" xyz="1.2390252889077236 1.0583516591742699 0" />
     <axis xyz="1 0 0"/>
       <limit effort="0.0" lower="-3.14159" upper="3.14159" velocity="0.0"/>
    </joint>
    <joint name="Leg8_Leg11" type="revolute">
       <parent link="Leg8"/>
       <child  link="Leg11"/>
       <origin rpy="0 0 0" xyz="1.08175755008819 0.7952082918455342 0" />
     <axis xyz="1 0 0"/>
       <limit effort="0.0" lower="-3.14159" upper="3.14159" velocity="0.0"/>
    </joint>
    <joint name="Leg9_Leg12" type="revolute">
       <parent link="Leg9"/>
       <child  link="Leg12"/>
       <origin rpy="0 0 0" xyz="0.5538049959947937 1.3824829989321699 0" />
     <axis xyz="1 0 0"/>
       <limit effort="0.0" lower="-3.14159" upper="3.14159" velocity="0.0"/>
    </joint>
    <joint name="Leg5_Leg13" type="revolute">
       <parent link="Leg5"/>
       <child  link="Leg13"/>
       <origin rpy="0 0 0" xyz="1.2390252889077236 2.1167033183485398 0" />
     <axis xyz="1 0 0"/>
       <limit effort="0.0" lower="-3.14159" upper="3.14159" velocity="0.0"/>
    </joint>
    <joint name="Leg4_Leg14" type="revolute">
       <parent link="Leg4"/>
       <child  link="Leg14"/>
       <origin rpy="0 0 0" xyz="0.6199396650318767 0 2.216399009219542" />
     <axis xyz="1 0 0"/>
       <limit effort="0.0" lower="-3.14159" upper="3.14159" velocity="0.0"/>
    </joint>
    <joint name="Leg11_Leg15" type="revolute">
       <parent link="Leg11"/>
       <child  link="Leg15"/>
       <origin rpy="0 0 0" xyz="0 2.9839196640612746 0" />
     <axis xyz="1 0 0"/>
       <limit effort="0.0" lower="-3.14159" upper="3.14159" velocity="0.0"/>
    </joint>
    <joint name="Leg8_Leg16" type="revolute">
       <parent link="Leg8"/>
       <child  link="Leg16"/>
       <origin rpy="0 0 0" xyz="1.08175755008819 1.5904165836910684 0" />
     <axis xyz="1 0 0"/>
       <limit effort="0.0" lower="-3.14159" upper="3.14159" velocity="0.0"/>
    </joint>
    <joint name="Leg14_Leg17" type="revolute">
       <parent link="Leg14"/>
       <child  link="Leg17"/>
       <origin rpy="0 0 0" xyz="0 1.286938043332261 1.3342507940939372" />
     <axis xyz="1 0 0"/>
       <limit effort="0.0" lower="-3.14159" upper="3.14159" velocity="0.0"/>
    </joint>
    <joint name="Leg5_Leg18" type="revolute">
       <parent link="Leg5"/>
       <child  link="Leg18"/>
       <origin rpy="0 0 0" xyz="1.2390252889077236 2.1167033183485398 0.8626160675907861" />
     <axis xyz="1 0 0"/>
       <limit effort="0.0" lower="-3.14159" upper="3.14159" velocity="0.0"/>
    </joint>
    <joint name="Leg8_Leg19" type="revolute">
       <parent link="Leg8"/>
       <child  link="Leg19"/>
       <origin rpy="0 0 0" xyz="1.08175755008819 1.5904165836910684 1.1605907281383143" />
     <axis xyz="1 0 0"/>
       <limit effort="0.0" lower="-3.14159" upper="3.14159" velocity="0.0"/>
    </joint>
    <joint name="Leg12_Leg20" type="revolute">
       <parent link="Leg12"/>
       <child  link="Leg20"/>
       <origin rpy="0 0 0" xyz="0.5383432055720995 0.64202708957877 0" />
     <axis xyz="1 0 0"/>
       <limit effort="0.0" lower="-3.14159" upper="3.14159" velocity="0.0"/>
    </joint>
    <joint name="Leg12_Leg21" type="revolute">
       <parent link="Leg12"/>
       <child  link="Leg21"/>
       <origin rpy="0 0 0" xyz="0.5383432055720995 1.28405417915754 0" />
     <axis xyz="1 0 0"/>
       <limit effort="0.0" lower="-3.14159" upper="3.14159" velocity="0.0"/>
    </joint>
    <joint name="Leg11_Leg22" type="revolute">
       <parent link="Leg11"/>
       <child  link="Leg22"/>
       <origin rpy="0 0 0" xyz="0 2.9839196640612746 0.6221945575181641" />
     <axis xyz="1 0 0"/>
       <limit effort="0.0" lower="-3.14159" upper="3.14159" velocity="0.0"/>
    </joint>
    <joint name="Leg13_Leg23" type="revolute">
       <parent link="Leg13"/>
       <child  link="Leg23"/>
       <origin rpy="0 0 0" xyz="1.2642675726819332 1.0133514862803836 0" />
     <axis xyz="1 0 0"/>
       <limit effort="0.0" lower="-3.14159" upper="3.14159" velocity="0.0"/>
    </joint>
    <joint name="Leg9_Leg24" type="revolute">
       <parent link="Leg9"/>
       <child  link="Leg24"/>
       <origin rpy="0 0 0" xyz="0.5538049959947937 1.3824829989321699 0.9389091708271388" />
     <axis xyz="1 0 0"/>
       <limit effort="0.0" lower="-3.14159" upper="3.14159" velocity="0.0"/>
    </joint>
    <joint name="Leg7_Leg25" type="revolute">
       <parent link="Leg7"/>
       <child  link="Leg25"/>
       <origin rpy="0 0 0" xyz="1.4469584528119808 1.2468459856439909 0.5816674733606053" />
     <axis xyz="1 0 0"/>
       <limit effort="0.0" lower="-3.14159" upper="3.14159" velocity="0.0"/>
    </joint>
</robot>