<robot name = "robot">
    <link name="Torso">
        <inertial>
            <origin xyz="0 0 1.4596849440678774" rpy="0 0 0"/>
            <mass value="1" />
            <inertia ixx="100" ixy="0" ixz="0" iyy="100" iyz="0" izz="100" />
        </inertial>
        <visual>
            <origin xyz="0 0 1.4596849440678774" rpy="0 0 0"/>
            <geometry>
                <box size="2.6493225262362503 2.0976908355485397 2.919369888135755" />
            </geometry>
            <material name="Green">
                <color rgba="0 180.0 0.0 1.0"/>
            </material>
        </visual>
        <collision>
            <origin xyz="0 0 1.4596849440678774" rpy="0 0 0"/>
            <geometry>
                <box size="2.6493225262362503 2.0976908355485397 2.919369888135755" />
            </geometry>
        </collision>
    </link>
    <link name="Leg1">
        <inertial>
            <origin xyz="1.2891277663289837 0 0" rpy="0 0 0"/>
            <mass value="1" />
            <inertia ixx="100" ixy="0" ixz="0" iyy="100" iyz="0" izz="100" />
        </inertial>
        <visual>
            <origin xyz="1.2891277663289837 0 0" rpy="0 0 0"/>
            <geometry>
                <box size="2.5782555326579675 1.7302962328980063 1.7178092857996874" />
            </geometry>
            <material name="Blue">
                <color rgba="0 1.0 1.0 1.0"/>
            </material>
        </visual>
        <collision>
            <origin xyz="1.2891277663289837 0 0" rpy="0 0 0"/>
            <geometry>
                <box size="2.5782555326579675 1.7302962328980063 1.7178092857996874" />
            </geometry>
        </collision>
    </link>
    <link name="Leg2">
        <inertial>
            <origin xyz="0 1.1369647146766906 0" rpy="0 0 0"/>
            <mass value="1" />
            <inertia ixx="100" ixy="0" ixz="0" iyy="100" iyz="0" izz="100" />
        </inertial>
        <visual>
            <origin xyz="0 1.1369647146766906 0" rpy="0 0 0"/>
            <geometry>
                <box size="1.9976225805969061 2.273929429353381 1.9120405492854187" />
            </geometry>
            <material name="Green">
                <color rgba="0 180.0 0.0 1.0"/>
            </material>
        </visual>
        <collision>
            <origin xyz="0 1.1369647146766906 0" rpy="0 0 0"/>
            <geometry>
                <box size="1.9976225805969061 2.273929429353381 1.9120405492854187" />
            </geometry>
        </collision>
    </link>
    <link name="Leg3">
        <inertial>
            <origin xyz="0 0 1.1179578104270975" rpy="0 0 0"/>
            <mass value="1" />
            <inertia ixx="100" ixy="0" ixz="0" iyy="100" iyz="0" izz="100" />
        </inertial>
        <visual>
            <origin xyz="0 0 1.1179578104270975" rpy="0 0 0"/>
            <geometry>
                <box size="1.7968514811071665 2.8056747658261147 2.235915620854195" />
            </geometry>
            <material name="Blue">
                <color rgba="0 1.0 1.0 1.0"/>
            </material>
        </visual>
        <collision>
            <origin xyz="0 0 1.1179578104270975" rpy="0 0 0"/>
            <geometry>
                <box size="1.7968514811071665 2.8056747658261147 2.235915620854195" />
            </geometry>
        </collision>
    </link>
    <link name="Leg4">
        <inertial>
            <origin xyz="0.7224764231741319 0 0" rpy="0 0 0"/>
            <mass value="1" />
            <inertia ixx="100" ixy="0" ixz="0" iyy="100" iyz="0" izz="100" />
        </inertial>
        <visual>
            <origin xyz="0.7224764231741319 0 0" rpy="0 0 0"/>
            <geometry>
                <box size="1.4449528463482637 2.8451779245374578 2.472681623571498" />
            </geometry>
            <material name="Blue">
                <color rgba="0 1.0 1.0 1.0"/>
            </material>
        </visual>
        <collision>
            <origin xyz="0.7224764231741319 0 0" rpy="0 0 0"/>
            <geometry>
                <box size="1.4449528463482637 2.8451779245374578 2.472681623571498" />
            </geometry>
        </collision>
    </link>
    <link name="Leg5">
        <inertial>
            <origin xyz="0 1.1799552667599014 0" rpy="0 0 0"/>
            <mass value="1" />
            <inertia ixx="100" ixy="0" ixz="0" iyy="100" iyz="0" izz="100" />
        </inertial>
        <visual>
            <origin xyz="0 1.1799552667599014 0" rpy="0 0 0"/>
            <geometry>
                <box size="1.8714508610956395 2.3599105335198027 2.04702349512772" />
            </geometry>
            <material name="Green">
                <color rgba="0 180.0 0.0 1.0"/>
            </material>
        </visual>
        <collision>
            <origin xyz="0 1.1799552667599014 0" rpy="0 0 0"/>
            <geometry>
                <box size="1.8714508610956395 2.3599105335198027 2.04702349512772" />
            </geometry>
        </collision>
    </link>
    <link name="Leg6">
        <inertial>
            <origin xyz="0.8528409230985952 0 0" rpy="0 0 0"/>
            <mass value="1" />
            <inertia ixx="100" ixy="0" ixz="0" iyy="100" iyz="0" izz="100" />
        </inertial>
        <visual>
            <origin xyz="0.8528409230985952 0 0" rpy="0 0 0"/>
            <geometry>
                <box size="1.7056818461971903 2.731675174504982 1.1968995420972106" />
            </geometry>
            <material name="Blue">
                <color rgba="0 1.0 1.0 1.0"/>
            </material>
        </visual>
        <collision>
            <origin xyz="0.8528409230985952 0 0" rpy="0 0 0"/>
            <geometry>
                <box size="1.7056818461971903 2.731675174504982 1.1968995420972106" />
            </geometry>
        </collision>
    </link>
    <link name="Leg7">
        <inertial>
            <origin xyz="0 0 1.2381411905562103" rpy="0 0 0"/>
            <mass value="1" />
            <inertia ixx="100" ixy="0" ixz="0" iyy="100" iyz="0" izz="100" />
        </inertial>
        <visual>
            <origin xyz="0 0 1.2381411905562103" rpy="0 0 0"/>
            <geometry>
                <box size="2.591426945721718 2.707484377284037 2.4762823811124206" />
            </geometry>
            <material name="Blue">
                <color rgba="0 1.0 1.0 1.0"/>
            </material>
        </visual>
        <collision>
            <origin xyz="0 0 1.2381411905562103" rpy="0 0 0"/>
            <geometry>
                <box size="2.591426945721718 2.707484377284037 2.4762823811124206" />
            </geometry>
        </collision>
    </link>
    <link name="Leg8">
        <inertial>
            <origin xyz="0 0.8238839038223894 0" rpy="0 0 0"/>
            <mass value="1" />
            <inertia ixx="100" ixy="0" ixz="0" iyy="100" iyz="0" izz="100" />
        </inertial>
        <visual>
            <origin xyz="0 0.8238839038223894 0" rpy="0 0 0"/>
            <geometry>
                <box size="1.5498126861774375 1.6477678076447788 2.0440630016009056" />
            </geometry>
            <material name="Green">
                <color rgba="0 180.0 0.0 1.0"/>
            </material>
        </visual>
        <collision>
            <origin xyz="0 0.8238839038223894 0" rpy="0 0 0"/>
            <geometry>
                <box size="1.5498126861774375 1.6477678076447788 2.0440630016009056" />
            </geometry>
        </collision>
    </link>
    <link name="Leg9">
        <inertial>
            <origin xyz="0 1.4188283824592522 0" rpy="0 0 0"/>
            <mass value="1" />
            <inertia ixx="100" ixy="0" ixz="0" iyy="100" iyz="0" izz="100" />
        </inertial>
        <visual>
            <origin xyz="0 1.4188283824592522 0" rpy="0 0 0"/>
            <geometry>
                <box size="2.463391369270489 2.8376567649185045 2.8770989017305464" />
            </geometry>
            <material name="Green">
                <color rgba="0 180.0 0.0 1.0"/>
            </material>
        </visual>
        <collision>
            <origin xyz="0 1.4188283824592522 0" rpy="0 0 0"/>
            <geometry>
                <box size="2.463391369270489 2.8376567649185045 2.8770989017305464" />
            </geometry>
        </collision>
    </link>
    <link name="Leg10">
        <inertial>
            <origin xyz="0 0 0.5625268884330911" rpy="0 0 0"/>
            <mass value="1" />
            <inertia ixx="100" ixy="0" ixz="0" iyy="100" iyz="0" izz="100" />
        </inertial>
        <visual>
            <origin xyz="0 0 0.5625268884330911" rpy="0 0 0"/>
            <geometry>
                <box size="2.1501635305131543 1.1305599183521466 1.1250537768661821" />
            </geometry>
            <material name="Blue">
                <color rgba="0 1.0 1.0 1.0"/>
            </material>
        </visual>
        <collision>
            <origin xyz="0 0 0.5625268884330911" rpy="0 0 0"/>
            <geometry>
                <box size="2.1501635305131543 1.1305599183521466 1.1250537768661821" />
            </geometry>
        </collision>
    </link>
    <link name="Leg11">
        <inertial>
            <origin xyz="0 0 1.0521438141024197" rpy="0 0 0"/>
            <mass value="1" />
            <inertia ixx="100" ixy="0" ixz="0" iyy="100" iyz="0" izz="100" />
        </inertial>
        <visual>
            <origin xyz="0 0 1.0521438141024197" rpy="0 0 0"/>
            <geometry>
                <box size="2.8813720093437665 1.6091593477924455 2.1042876282048395" />
            </geometry>
            <material name="Green">
                <color rgba="0 180.0 0.0 1.0"/>
            </material>
        </visual>
        <collision>
            <origin xyz="0 0 1.0521438141024197" rpy="0 0 0"/>
            <geometry>
                <box size="2.8813720093437665 1.6091593477924455 2.1042876282048395" />
            </geometry>
        </collision>
    </link>
    <link name="Leg12">
        <inertial>
            <origin xyz="1.3991103427546372 0 0" rpy="0 0 0"/>
            <mass value="1" />
            <inertia ixx="100" ixy="0" ixz="0" iyy="100" iyz="0" izz="100" />
        </inertial>
        <visual>
            <origin xyz="1.3991103427546372 0 0" rpy="0 0 0"/>
            <geometry>
                <box size="2.7982206855092744 2.78906801832083 2.5736362180251398" />
            </geometry>
            <material name="Green">
                <color rgba="0 180.0 0.0 1.0"/>
            </material>
        </visual>
        <collision>
            <origin xyz="1.3991103427546372 0 0" rpy="0 0 0"/>
            <geometry>
                <box size="2.7982206855092744 2.78906801832083 2.5736362180251398" />
            </geometry>
        </collision>
    </link>
    <link name="Leg13">
        <inertial>
            <origin xyz="0 0 0.8895765616611399" rpy="0 0 0"/>
            <mass value="1" />
            <inertia ixx="100" ixy="0" ixz="0" iyy="100" iyz="0" izz="100" />
        </inertial>
        <visual>
            <origin xyz="0 0 0.8895765616611399" rpy="0 0 0"/>
            <geometry>
                <box size="1.770622611768359 1.6307026543405752 1.7791531233222797" />
            </geometry>
            <material name="Green">
                <color rgba="0 180.0 0.0 1.0"/>
            </material>
        </visual>
        <collision>
            <origin xyz="0 0 0.8895765616611399" rpy="0 0 0"/>
            <geometry>
                <box size="1.770622611768359 1.6307026543405752 1.7791531233222797" />
            </geometry>
        </collision>
    </link>
    <link name="Leg14">
        <inertial>
            <origin xyz="0 0 0.9172589026645096" rpy="0 0 0"/>
            <mass value="1" />
            <inertia ixx="100" ixy="0" ixz="0" iyy="100" iyz="0" izz="100" />
        </inertial>
        <visual>
            <origin xyz="0 0 0.9172589026645096" rpy="0 0 0"/>
            <geometry>
                <box size="1.9743970347229853 1.5522097077527186 1.8345178053290192" />
            </geometry>
            <material name="Green">
                <color rgba="0 180.0 0.0 1.0"/>
            </material>
        </visual>
        <collision>
            <origin xyz="0 0 0.9172589026645096" rpy="0 0 0"/>
            <geometry>
                <box size="1.9743970347229853 1.5522097077527186 1.8345178053290192" />
            </geometry>
        </collision>
    </link>
    <link name="Leg15">
        <inertial>
            <origin xyz="0 0.5479494102984733 0" rpy="0 0 0"/>
            <mass value="1" />
            <inertia ixx="100" ixy="0" ixz="0" iyy="100" iyz="0" izz="100" />
        </inertial>
        <visual>
            <origin xyz="0 0.5479494102984733 0" rpy="0 0 0"/>
            <geometry>
                <box size="2.1963681342458052 1.0958988205969467 2.9867140346304204" />
            </geometry>
            <material name="Green">
                <color rgba="0 180.0 0.0 1.0"/>
            </material>
        </visual>
        <collision>
            <origin xyz="0 0.5479494102984733 0" rpy="0 0 0"/>
            <geometry>
                <box size="2.1963681342458052 1.0958988205969467 2.9867140346304204" />
            </geometry>
        </collision>
    </link>
    <link name="Leg16">
        <inertial>
            <origin xyz="0.8819274803132154 0 0" rpy="0 0 0"/>
            <mass value="1" />
            <inertia ixx="100" ixy="0" ixz="0" iyy="100" iyz="0" izz="100" />
        </inertial>
        <visual>
            <origin xyz="0.8819274803132154 0 0" rpy="0 0 0"/>
            <geometry>
                <box size="1.7638549606264309 1.225904907084225 1.709165533926786" />
            </geometry>
            <material name="Blue">
                <color rgba="0 1.0 1.0 1.0"/>
            </material>
        </visual>
        <collision>
            <origin xyz="0.8819274803132154 0 0" rpy="0 0 0"/>
            <geometry>
                <box size="1.7638549606264309 1.225904907084225 1.709165533926786" />
            </geometry>
        </collision>
    </link>
    <link name="Leg17">
        <inertial>
            <origin xyz="0 1.3631502993017448 0" rpy="0 0 0"/>
            <mass value="1" />
            <inertia ixx="100" ixy="0" ixz="0" iyy="100" iyz="0" izz="100" />
        </inertial>
        <visual>
            <origin xyz="0 1.3631502993017448 0" rpy="0 0 0"/>
            <geometry>
                <box size="2.4559464256949726 2.7263005986034896 2.34457324553295" />
            </geometry>
            <material name="Green">
                <color rgba="0 180.0 0.0 1.0"/>
            </material>
        </visual>
        <collision>
            <origin xyz="0 1.3631502993017448 0" rpy="0 0 0"/>
            <geometry>
                <box size="2.4559464256949726 2.7263005986034896 2.34457324553295" />
            </geometry>
        </collision>
    </link>
    <link name="Leg18">
        <inertial>
            <origin xyz="0 0 1.447766968161479" rpy="0 0 0"/>
            <mass value="1" />
            <inertia ixx="100" ixy="0" ixz="0" iyy="100" iyz="0" izz="100" />
        </inertial>
        <visual>
            <origin xyz="0 0 1.447766968161479" rpy="0 0 0"/>
            <geometry>
                <box size="2.5118466669846606 1.3786534102985135 2.895533936322958" />
            </geometry>
            <material name="Green">
                <color rgba="0 180.0 0.0 1.0"/>
            </material>
        </visual>
        <collision>
            <origin xyz="0 0 1.447766968161479" rpy="0 0 0"/>
            <geometry>
                <box size="2.5118466669846606 1.3786534102985135 2.895533936322958" />
            </geometry>
        </collision>
    </link>
    <link name="Leg19">
        <inertial>
            <origin xyz="0 0 1.0031196620419902" rpy="0 0 0"/>
            <mass value="1" />
            <inertia ixx="100" ixy="0" ixz="0" iyy="100" iyz="0" izz="100" />
        </inertial>
        <visual>
            <origin xyz="0 0 1.0031196620419902" rpy="0 0 0"/>
            <geometry>
                <box size="1.212034451463299 2.947124495954082 2.0062393240839804" />
            </geometry>
            <material name="Blue">
                <color rgba="0 1.0 1.0 1.0"/>
            </material>
        </visual>
        <collision>
            <origin xyz="0 0 1.0031196620419902" rpy="0 0 0"/>
            <geometry>
                <box size="1.212034451463299 2.947124495954082 2.0062393240839804" />
            </geometry>
        </collision>
    </link>
    <link name="Leg20">
        <inertial>
            <origin xyz="1.498830202184118 0 0" rpy="0 0 0"/>
            <mass value="1" />
            <inertia ixx="100" ixy="0" ixz="0" iyy="100" iyz="0" izz="100" />
        </inertial>
        <visual>
            <origin xyz="1.498830202184118 0 0" rpy="0 0 0"/>
            <geometry>
                <box size="2.997660404368236 2.774147508440863 1.510359846521964" />
            </geometry>
            <material name="Blue">
                <color rgba="0 1.0 1.0 1.0"/>
            </material>
        </visual>
        <collision>
            <origin xyz="1.498830202184118 0 0" rpy="0 0 0"/>
            <geometry>
                <box size="2.997660404368236 2.774147508440863 1.510359846521964" />
            </geometry>
        </collision>
    </link>
    <link name="Leg21">
        <inertial>
            <origin xyz="0 0 1.2752191664777266" rpy="0 0 0"/>
            <mass value="1" />
            <inertia ixx="100" ixy="0" ixz="0" iyy="100" iyz="0" izz="100" />
        </inertial>
        <visual>
            <origin xyz="0 0 1.2752191664777266" rpy="0 0 0"/>
            <geometry>
                <box size="2.6088014099973167 2.254890214580022 2.550438332955453" />
            </geometry>
            <material name="Blue">
                <color rgba="0 1.0 1.0 1.0"/>
            </material>
        </visual>
        <collision>
            <origin xyz="0 0 1.2752191664777266" rpy="0 0 0"/>
            <geometry>
                <box size="2.6088014099973167 2.254890214580022 2.550438332955453" />
            </geometry>
        </collision>
    </link>
    <link name="Leg22">
        <inertial>
            <origin xyz="0 0 0.856175506059848" rpy="0 0 0"/>
            <mass value="1" />
            <inertia ixx="100" ixy="0" ixz="0" iyy="100" iyz="0" izz="100" />
        </inertial>
        <visual>
            <origin xyz="0 0 0.856175506059848" rpy="0 0 0"/>
            <geometry>
                <box size="2.1465530612622805 1.6589241157437122 1.712351012119696" />
            </geometry>
            <material name="Blue">
                <color rgba="0 1.0 1.0 1.0"/>
            </material>
        </visual>
        <collision>
            <origin xyz="0 0 0.856175506059848" rpy="0 0 0"/>
            <geometry>
                <box size="2.1465530612622805 1.6589241157437122 1.712351012119696" />
            </geometry>
        </collision>
    </link>
    <link name="Leg23">
        <inertial>
            <origin xyz="0 1.2788269014479963 0" rpy="0 0 0"/>
            <mass value="1" />
            <inertia ixx="100" ixy="0" ixz="0" iyy="100" iyz="0" izz="100" />
        </inertial>
        <visual>
            <origin xyz="0 1.2788269014479963 0" rpy="0 0 0"/>
            <geometry>
                <box size="1.968653172735629 2.5576538028959925 1.7684384346451" />
            </geometry>
            <material name="Green">
                <color rgba="0 180.0 0.0 1.0"/>
            </material>
        </visual>
        <collision>
            <origin xyz="0 1.2788269014479963 0" rpy="0 0 0"/>
            <geometry>
                <box size="1.968653172735629 2.5576538028959925 1.7684384346451" />
            </geometry>
        </collision>
    </link>
    <link name="Leg24">
        <inertial>
            <origin xyz="0 1.4456090072684606 0" rpy="0 0 0"/>
            <mass value="1" />
            <inertia ixx="100" ixy="0" ixz="0" iyy="100" iyz="0" izz="100" />
        </inertial>
        <visual>
            <origin xyz="0 1.4456090072684606 0" rpy="0 0 0"/>
            <geometry>
                <box size="1.3043275518864943 2.8912180145369213 1.2116893095686185" />
            </geometry>
            <material name="Green">
                <color rgba="0 180.0 0.0 1.0"/>
            </material>
        </visual>
        <collision>
            <origin xyz="0 1.4456090072684606 0" rpy="0 0 0"/>
            <geometry>
                <box size="1.3043275518864943 2.8912180145369213 1.2116893095686185" />
            </geometry>
        </collision>
    </link>
    <link name="Leg25">
        <inertial>
            <origin xyz="0 1.2025686534961089 0" rpy="0 0 0"/>
            <mass value="1" />
            <inertia ixx="100" ixy="0" ixz="0" iyy="100" iyz="0" izz="100" />
        </inertial>
        <visual>
            <origin xyz="0 1.2025686534961089 0" rpy="0 0 0"/>
            <geometry>
                <box size="1.9219051392318969 2.4051373069922177 1.2518046205904034" />
            </geometry>
            <material name="Green">
                <color rgba="0 180.0 0.0 1.0"/>
            </material>
        </visual>
        <collision>
            <origin xyz="0 1.2025686534961089 0" rpy="0 0 0"/>
            <geometry>
                <box size="1.9219051392318969 2.4051373069922177 1.2518046205904034" />
            </geometry>
        </collision>
    </link>
    <link name="Leg26">
        <inertial>
            <origin xyz="0.5687726276581688 0 0" rpy="0 0 0"/>
            <mass value="1" />
            <inertia ixx="100" ixy="0" ixz="0" iyy="100" iyz="0" izz="100" />
        </inertial>
        <visual>
            <origin xyz="0.5687726276581688 0 0" rpy="0 0 0"/>
            <geometry>
                <box size="1.1375452553163377 1.5868223479330672 1.4304098340530742" />
            </geometry>
            <material name="Green">
                <color rgba="0 180.0 0.0 1.0"/>
            </material>
        </visual>
        <collision>
            <origin xyz="0.5687726276581688 0 0" rpy="0 0 0"/>
            <geometry>
                <box size="1.1375452553163377 1.5868223479330672 1.4304098340530742" />
            </geometry>
        </collision>
    </link>
    <link name="Leg27">
        <inertial>
            <origin xyz="0 0.5210385779404119 0" rpy="0 0 0"/>
            <mass value="1" />
            <inertia ixx="100" ixy="0" ixz="0" iyy="100" iyz="0" izz="100" />
        </inertial>
        <visual>
            <origin xyz="0 0.5210385779404119 0" rpy="0 0 0"/>
            <geometry>
                <box size="2.811394767530083 1.0420771558808237 1.372182635446955" />
            </geometry>
            <material name="Green">
                <color rgba="0 180.0 0.0 1.0"/>
            </material>
        </visual>
        <collision>
            <origin xyz="0 0.5210385779404119 0" rpy="0 0 0"/>
            <geometry>
                <box size="2.811394767530083 1.0420771558808237 1.372182635446955" />
            </geometry>
        </collision>
    </link>
    <joint name="Torso_Leg1" type="revolute">
       <parent link="Torso"/>
       <child  link="Leg1"/>
       <origin rpy="0 0 0" xyz="1.3246612631181252 0 1.4596849440678774" />
     <axis xyz="1 0 0"/>
       <limit effort="0.0" lower="-3.14159" upper="3.14159" velocity="0.0"/>
    </joint>
    <joint name="Leg1_Leg2" type="revolute">
       <parent link="Leg1"/>
       <child  link="Leg2"/>
       <origin rpy="0 0 0" xyz="0 2.273929429353381 0" />
     <axis xyz="1 0 0"/>
       <limit effort="0.0" lower="-3.14159" upper="3.14159" velocity="0.0"/>
    </joint>
    <joint name="Leg1_Leg3" type="revolute">
       <parent link="Leg1"/>
       <child  link="Leg3"/>
       <origin rpy="0 0 0" xyz="0 2.273929429353381 0.9560202746427093" />
     <axis xyz="1 0 0"/>
       <limit effort="0.0" lower="-3.14159" upper="3.14159" velocity="0.0"/>
    </joint>
    <joint name="Leg1_Leg4" type="revolute">
       <parent link="Leg1"/>
       <child  link="Leg4"/>
       <origin rpy="0 0 0" xyz="0.9988112902984531 2.273929429353381 0.9560202746427093" />
     <axis xyz="1 0 0"/>
       <limit effort="0.0" lower="-3.14159" upper="3.14159" velocity="0.0"/>
    </joint>
    <joint name="Leg2_Leg5" type="revolute">
       <parent link="Leg2"/>
       <child  link="Leg5"/>
       <origin rpy="0 0 0" xyz="0 1.4028373829130574 1.1179578104270975" />
     <axis xyz="1 0 0"/>
       <limit effort="0.0" lower="-3.14159" upper="3.14159" velocity="0.0"/>
    </joint>
    <joint name="Leg2_Leg6" type="revolute">
       <parent link="Leg2"/>
       <child  link="Leg6"/>
       <origin rpy="0 0 0" xyz="0.8984257405535833 1.4028373829130574 1.1179578104270975" />
     <axis xyz="1 0 0"/>
       <limit effort="0.0" lower="-3.14159" upper="3.14159" velocity="0.0"/>
    </joint>
    <joint name="Leg2_Leg7" type="revolute">
       <parent link="Leg2"/>
       <child  link="Leg7"/>
       <origin rpy="0 0 0" xyz="0.8984257405535833 1.4028373829130574 2.235915620854195" />
     <axis xyz="1 0 0"/>
       <limit effort="0.0" lower="-3.14159" upper="3.14159" velocity="0.0"/>
    </joint>
    <joint name="Leg3_Leg8" type="revolute">
       <parent link="Leg3"/>
       <child  link="Leg8"/>
       <origin rpy="0 0 0" xyz="0.7224764231741319 1.4225889622687289 0" />
     <axis xyz="1 0 0"/>
       <limit effort="0.0" lower="-3.14159" upper="3.14159" velocity="0.0"/>
    </joint>
    <joint name="Leg6_Leg9" type="revolute">
       <parent link="Leg6"/>
       <child  link="Leg9"/>
       <origin rpy="0 0 0" xyz="0 1.3537421886420185 1.2381411905562103" />
     <axis xyz="1 0 0"/>
       <limit effort="0.0" lower="-3.14159" upper="3.14159" velocity="0.0"/>
    </joint>
    <joint name="Leg8_Leg10" type="revolute">
       <parent link="Leg8"/>
       <child  link="Leg10"/>
       <origin rpy="0 0 0" xyz="0 1.4188283824592522 1.4385494508652732" />
     <axis xyz="1 0 0"/>
       <limit effort="0.0" lower="-3.14159" upper="3.14159" velocity="0.0"/>
    </joint>
    <joint name="Leg4_Leg11" type="revolute">
       <parent link="Leg4"/>
       <child  link="Leg11"/>
       <origin rpy="0 0 0" xyz="0 1.1799552667599014 1.02351174756386" />
     <axis xyz="1 0 0"/>
       <limit effort="0.0" lower="-3.14159" upper="3.14159" velocity="0.0"/>
    </joint>
    <joint name="Leg6_Leg12" type="revolute">
       <parent link="Leg6"/>
       <child  link="Leg12"/>
       <origin rpy="0 0 0" xyz="1.295713472860859 1.3537421886420185 1.2381411905562103" />
     <axis xyz="1 0 0"/>
       <limit effort="0.0" lower="-3.14159" upper="3.14159" velocity="0.0"/>
    </joint>
    <joint name="Leg11_Leg13" type="revolute">
       <parent link="Leg11"/>
       <child  link="Leg13"/>
       <origin rpy="0 0 0" xyz="1.3991103427546372 0 1.2868181090125699" />
     <axis xyz="1 0 0"/>
       <limit effort="0.0" lower="-3.14159" upper="3.14159" velocity="0.0"/>
    </joint>
    <joint name="Torso_Leg14" type="revolute">
       <parent link="Torso"/>
       <child  link="Leg14"/>
       <origin rpy="0 0 0" xyz="1.2891277663289837 0 0.8589046428998437" />
     <axis xyz="1 0 0"/>
       <limit effort="0.0" lower="-3.14159" upper="3.14159" velocity="0.0"/>
    </joint>
    <joint name="Leg10_Leg15" type="revolute">
       <parent link="Leg10"/>
       <child  link="Leg15"/>
       <origin rpy="0 0 0" xyz="0 0.8045796738962228 1.0521438141024197" />
     <axis xyz="1 0 0"/>
       <limit effort="0.0" lower="-3.14159" upper="3.14159" velocity="0.0"/>
    </joint>
    <joint name="Leg15_Leg16" type="revolute">
       <parent link="Leg15"/>
       <child  link="Leg16"/>
       <origin rpy="0 0 0" xyz="1.7638549606264309 0 0" />
     <axis xyz="1 0 0"/>
       <limit effort="0.0" lower="-3.14159" upper="3.14159" velocity="0.0"/>
    </joint>
    <joint name="Leg9_Leg17" type="revolute">
       <parent link="Leg9"/>
       <child  link="Leg17"/>
       <origin rpy="0 0 0" xyz="0 0.5652799591760733 0.5625268884330911" />
     <axis xyz="1 0 0"/>
       <limit effort="0.0" lower="-3.14159" upper="3.14159" velocity="0.0"/>
    </joint>
    <joint name="Leg17_Leg18" type="revolute">
       <parent link="Leg17"/>
       <child  link="Leg18"/>
       <origin rpy="0 0 0" xyz="0 0 2.895533936322958" />
     <axis xyz="1 0 0"/>
       <limit effort="0.0" lower="-3.14159" upper="3.14159" velocity="0.0"/>
    </joint>
    <joint name="Leg12_Leg19" type="revolute">
       <parent link="Leg12"/>
       <child  link="Leg19"/>
       <origin rpy="0 0 0" xyz="0 0 1.7791531233222797" />
     <axis xyz="1 0 0"/>
       <limit effort="0.0" lower="-3.14159" upper="3.14159" velocity="0.0"/>
    </joint>
    <joint name="Leg5_Leg20" type="revolute">
       <parent link="Leg5"/>
       <child  link="Leg20"/>
       <origin rpy="0 0 0" xyz="1.7056818461971903 0 0" />
     <axis xyz="1 0 0"/>
       <limit effort="0.0" lower="-3.14159" upper="3.14159" velocity="0.0"/>
    </joint>
    <joint name="Leg16_Leg21" type="revolute">
       <parent link="Leg16"/>
       <child  link="Leg21"/>
       <origin rpy="0 0 0" xyz="0 1.3631502993017448 1.172286622766475" />
     <axis xyz="1 0 0"/>
       <limit effort="0.0" lower="-3.14159" upper="3.14159" velocity="0.0"/>
    </joint>
    <joint name="Leg5_Leg22" type="revolute">
       <parent link="Leg5"/>
       <child  link="Leg22"/>
       <origin rpy="0 0 0" xyz="1.7056818461971903 0 0.5984497710486053" />
     <axis xyz="1 0 0"/>
       <limit effort="0.0" lower="-3.14159" upper="3.14159" velocity="0.0"/>
    </joint>
    <joint name="Leg4_Leg23" type="revolute">
       <parent link="Leg4"/>
       <child  link="Leg23"/>
       <origin rpy="0 0 0" xyz="0 2.3599105335198027 1.02351174756386" />
     <axis xyz="1 0 0"/>
       <limit effort="0.0" lower="-3.14159" upper="3.14159" velocity="0.0"/>
    </joint>
    <joint name="Leg18_Leg24" type="revolute">
       <parent link="Leg18"/>
       <child  link="Leg24"/>
       <origin rpy="0 0 0" xyz="0 1.473562247977041 1.0031196620419902" />
     <axis xyz="1 0 0"/>
       <limit effort="0.0" lower="-3.14159" upper="3.14159" velocity="0.0"/>
    </joint>
    <joint name="Leg5_Leg25" type="revolute">
       <parent link="Leg5"/>
       <child  link="Leg25"/>
       <origin rpy="0 0 0" xyz="1.7056818461971903 1.365837587252491 0.5984497710486053" />
     <axis xyz="1 0 0"/>
       <limit effort="0.0" lower="-3.14159" upper="3.14159" velocity="0.0"/>
    </joint>
    <joint name="Leg21_Leg26" type="revolute">
       <parent link="Leg21"/>
       <child  link="Leg26"/>
       <origin rpy="0 0 0" xyz="1.0732765306311403 0 0.856175506059848" />
     <axis xyz="1 0 0"/>
       <limit effort="0.0" lower="-3.14159" upper="3.14159" velocity="0.0"/>
    </joint>
    <joint name="Leg23_Leg27" type="revolute">
       <parent link="Leg23"/>
       <child  link="Leg27"/>
       <origin rpy="0 0 0" xyz="0 2.8912180145369213 0" />
     <axis xyz="1 0 0"/>
       <limit effort="0.0" lower="-3.14159" upper="3.14159" velocity="0.0"/>
    </joint>
</robot>