<robot name = "robot">
    <link name="Torso">
        <inertial>
            <origin xyz="0 0 0.5574642566516018" rpy="0 0 0"/>
            <mass value="1" />
            <inertia ixx="100" ixy="0" ixz="0" iyy="100" iyz="0" izz="100" />
        </inertial>
        <visual>
            <origin xyz="0 0 0.5574642566516018" rpy="0 0 0"/>
            <geometry>
                <box size="1.3214671580403383 1.402529817295939 1.1149285133032036" />
            </geometry>
            <material name="Green">
                <color rgba="0 180.0 0.0 1.0"/>
            </material>
        </visual>
        <collision>
            <origin xyz="0 0 0.5574642566516018" rpy="0 0 0"/>
            <geometry>
                <box size="1.3214671580403383 1.402529817295939 1.1149285133032036" />
            </geometry>
        </collision>
    </link>
    <link name="Leg1">
        <inertial>
            <origin xyz="0 0 0.5374968231104444" rpy="0 0 0"/>
            <mass value="1" />
            <inertia ixx="100" ixy="0" ixz="0" iyy="100" iyz="0" izz="100" />
        </inertial>
        <visual>
            <origin xyz="0 0 0.5374968231104444" rpy="0 0 0"/>
            <geometry>
                <box size="1.210914458905869 1.1839784015211552 1.0749936462208889" />
            </geometry>
            <material name="Blue">
                <color rgba="0 1.0 1.0 1.0"/>
            </material>
        </visual>
        <collision>
            <origin xyz="0 0 0.5374968231104444" rpy="0 0 0"/>
            <geometry>
                <box size="1.210914458905869 1.1839784015211552 1.0749936462208889" />
            </geometry>
        </collision>
    </link>
    <link name="Leg2">
        <inertial>
            <origin xyz="1.1164891507541956 0 0" rpy="0 0 0"/>
            <mass value="1" />
            <inertia ixx="100" ixy="0" ixz="0" iyy="100" iyz="0" izz="100" />
        </inertial>
        <visual>
            <origin xyz="1.1164891507541956 0 0" rpy="0 0 0"/>
            <geometry>
                <box size="2.2329783015083913 1.8122034728541485 2.2417343676129295" />
            </geometry>
            <material name="Blue">
                <color rgba="0 1.0 1.0 1.0"/>
            </material>
        </visual>
        <collision>
            <origin xyz="1.1164891507541956 0 0" rpy="0 0 0"/>
            <geometry>
                <box size="2.2329783015083913 1.8122034728541485 2.2417343676129295" />
            </geometry>
        </collision>
    </link>
    <link name="Leg3">
        <inertial>
            <origin xyz="0.8967300440880208 0 0" rpy="0 0 0"/>
            <mass value="1" />
            <inertia ixx="100" ixy="0" ixz="0" iyy="100" iyz="0" izz="100" />
        </inertial>
        <visual>
            <origin xyz="0.8967300440880208 0 0" rpy="0 0 0"/>
            <geometry>
                <box size="1.7934600881760416 1.1559023082253372 1.2477182451589097" />
            </geometry>
            <material name="Green">
                <color rgba="0 180.0 0.0 1.0"/>
            </material>
        </visual>
        <collision>
            <origin xyz="0.8967300440880208 0 0" rpy="0 0 0"/>
            <geometry>
                <box size="1.7934600881760416 1.1559023082253372 1.2477182451589097" />
            </geometry>
        </collision>
    </link>
    <link name="Leg4">
        <inertial>
            <origin xyz="1.113296829197913 0 0" rpy="0 0 0"/>
            <mass value="1" />
            <inertia ixx="100" ixy="0" ixz="0" iyy="100" iyz="0" izz="100" />
        </inertial>
        <visual>
            <origin xyz="1.113296829197913 0 0" rpy="0 0 0"/>
            <geometry>
                <box size="2.226593658395826 2.0910336765663198 2.3954294408013457" />
            </geometry>
            <material name="Green">
                <color rgba="0 180.0 0.0 1.0"/>
            </material>
        </visual>
        <collision>
            <origin xyz="1.113296829197913 0 0" rpy="0 0 0"/>
            <geometry>
                <box size="2.226593658395826 2.0910336765663198 2.3954294408013457" />
            </geometry>
        </collision>
    </link>
    <link name="Leg5">
        <inertial>
            <origin xyz="1.1118658205146772 0 0" rpy="0 0 0"/>
            <mass value="1" />
            <inertia ixx="100" ixy="0" ixz="0" iyy="100" iyz="0" izz="100" />
        </inertial>
        <visual>
            <origin xyz="1.1118658205146772 0 0" rpy="0 0 0"/>
            <geometry>
                <box size="2.2237316410293544 2.0435804353689844 1.9680678870018498" />
            </geometry>
            <material name="Green">
                <color rgba="0 180.0 0.0 1.0"/>
            </material>
        </visual>
        <collision>
            <origin xyz="1.1118658205146772 0 0" rpy="0 0 0"/>
            <geometry>
                <box size="2.2237316410293544 2.0435804353689844 1.9680678870018498" />
            </geometry>
        </collision>
    </link>
    <link name="Leg6">
        <inertial>
            <origin xyz="0.6427724212316683 0 0" rpy="0 0 0"/>
            <mass value="1" />
            <inertia ixx="100" ixy="0" ixz="0" iyy="100" iyz="0" izz="100" />
        </inertial>
        <visual>
            <origin xyz="0.6427724212316683 0 0" rpy="0 0 0"/>
            <geometry>
                <box size="1.2855448424633367 2.8853283047668308 2.1491663170082784" />
            </geometry>
            <material name="Green">
                <color rgba="0 180.0 0.0 1.0"/>
            </material>
        </visual>
        <collision>
            <origin xyz="0.6427724212316683 0 0" rpy="0 0 0"/>
            <geometry>
                <box size="1.2855448424633367 2.8853283047668308 2.1491663170082784" />
            </geometry>
        </collision>
    </link>
    <link name="Leg7">
        <inertial>
            <origin xyz="0 1.1900928089132898 0" rpy="0 0 0"/>
            <mass value="1" />
            <inertia ixx="100" ixy="0" ixz="0" iyy="100" iyz="0" izz="100" />
        </inertial>
        <visual>
            <origin xyz="0 1.1900928089132898 0" rpy="0 0 0"/>
            <geometry>
                <box size="1.0653011675633945 2.3801856178265797 2.413547393666906" />
            </geometry>
            <material name="Green">
                <color rgba="0 180.0 0.0 1.0"/>
            </material>
        </visual>
        <collision>
            <origin xyz="0 1.1900928089132898 0" rpy="0 0 0"/>
            <geometry>
                <box size="1.0653011675633945 2.3801856178265797 2.413547393666906" />
            </geometry>
        </collision>
    </link>
    <link name="Leg8">
        <inertial>
            <origin xyz="0 1.4614127232064025 0" rpy="0 0 0"/>
            <mass value="1" />
            <inertia ixx="100" ixy="0" ixz="0" iyy="100" iyz="0" izz="100" />
        </inertial>
        <visual>
            <origin xyz="0 1.4614127232064025 0" rpy="0 0 0"/>
            <geometry>
                <box size="1.2752953385806225 2.922825446412805 2.330059135254598" />
            </geometry>
            <material name="Blue">
                <color rgba="0 1.0 1.0 1.0"/>
            </material>
        </visual>
        <collision>
            <origin xyz="0 1.4614127232064025 0" rpy="0 0 0"/>
            <geometry>
                <box size="1.2752953385806225 2.922825446412805 2.330059135254598" />
            </geometry>
        </collision>
    </link>
    <link name="Leg9">
        <inertial>
            <origin xyz="0 0 0.9130229908229164" rpy="0 0 0"/>
            <mass value="1" />
            <inertia ixx="100" ixy="0" ixz="0" iyy="100" iyz="0" izz="100" />
        </inertial>
        <visual>
            <origin xyz="0 0 0.9130229908229164" rpy="0 0 0"/>
            <geometry>
                <box size="1.6115815038637622 1.551485650822912 1.8260459816458328" />
            </geometry>
            <material name="Green">
                <color rgba="0 180.0 0.0 1.0"/>
            </material>
        </visual>
        <collision>
            <origin xyz="0 0 0.9130229908229164" rpy="0 0 0"/>
            <geometry>
                <box size="1.6115815038637622 1.551485650822912 1.8260459816458328" />
            </geometry>
        </collision>
    </link>
    <link name="Leg10">
        <inertial>
            <origin xyz="0 1.2510734739121863 0" rpy="0 0 0"/>
            <mass value="1" />
            <inertia ixx="100" ixy="0" ixz="0" iyy="100" iyz="0" izz="100" />
        </inertial>
        <visual>
            <origin xyz="0 1.2510734739121863 0" rpy="0 0 0"/>
            <geometry>
                <box size="1.0913290263010023 2.5021469478243725 2.986020954307825" />
            </geometry>
            <material name="Blue">
                <color rgba="0 1.0 1.0 1.0"/>
            </material>
        </visual>
        <collision>
            <origin xyz="0 1.2510734739121863 0" rpy="0 0 0"/>
            <geometry>
                <box size="1.0913290263010023 2.5021469478243725 2.986020954307825" />
            </geometry>
        </collision>
    </link>
    <link name="Leg11">
        <inertial>
            <origin xyz="0 0.5090930572979016 0" rpy="0 0 0"/>
            <mass value="1" />
            <inertia ixx="100" ixy="0" ixz="0" iyy="100" iyz="0" izz="100" />
        </inertial>
        <visual>
            <origin xyz="0 0.5090930572979016 0" rpy="0 0 0"/>
            <geometry>
                <box size="2.124002134884012 1.018186114595803 1.3193513267115862" />
            </geometry>
            <material name="Blue">
                <color rgba="0 1.0 1.0 1.0"/>
            </material>
        </visual>
        <collision>
            <origin xyz="0 0.5090930572979016 0" rpy="0 0 0"/>
            <geometry>
                <box size="2.124002134884012 1.018186114595803 1.3193513267115862" />
            </geometry>
        </collision>
    </link>
    <link name="Leg12">
        <inertial>
            <origin xyz="1.2072459421242727 0 0" rpy="0 0 0"/>
            <mass value="1" />
            <inertia ixx="100" ixy="0" ixz="0" iyy="100" iyz="0" izz="100" />
        </inertial>
        <visual>
            <origin xyz="1.2072459421242727 0 0" rpy="0 0 0"/>
            <geometry>
                <box size="2.4144918842485454 2.9335210836940346 1.3781169187948674" />
            </geometry>
            <material name="Green">
                <color rgba="0 180.0 0.0 1.0"/>
            </material>
        </visual>
        <collision>
            <origin xyz="1.2072459421242727 0 0" rpy="0 0 0"/>
            <geometry>
                <box size="2.4144918842485454 2.9335210836940346 1.3781169187948674" />
            </geometry>
        </collision>
    </link>
    <link name="Leg13">
        <inertial>
            <origin xyz="1.3841418192852974 0 0" rpy="0 0 0"/>
            <mass value="1" />
            <inertia ixx="100" ixy="0" ixz="0" iyy="100" iyz="0" izz="100" />
        </inertial>
        <visual>
            <origin xyz="1.3841418192852974 0 0" rpy="0 0 0"/>
            <geometry>
                <box size="2.768283638570595 2.292447693486184 2.850102978233497" />
            </geometry>
            <material name="Blue">
                <color rgba="0 1.0 1.0 1.0"/>
            </material>
        </visual>
        <collision>
            <origin xyz="1.3841418192852974 0 0" rpy="0 0 0"/>
            <geometry>
                <box size="2.768283638570595 2.292447693486184 2.850102978233497" />
            </geometry>
        </collision>
    </link>
    <link name="Leg14">
        <inertial>
            <origin xyz="0.609123914790453 0 0" rpy="0 0 0"/>
            <mass value="1" />
            <inertia ixx="100" ixy="0" ixz="0" iyy="100" iyz="0" izz="100" />
        </inertial>
        <visual>
            <origin xyz="0.609123914790453 0 0" rpy="0 0 0"/>
            <geometry>
                <box size="1.218247829580906 2.015393608021535 1.0482686303834736" />
            </geometry>
            <material name="Blue">
                <color rgba="0 1.0 1.0 1.0"/>
            </material>
        </visual>
        <collision>
            <origin xyz="0.609123914790453 0 0" rpy="0 0 0"/>
            <geometry>
                <box size="1.218247829580906 2.015393608021535 1.0482686303834736" />
            </geometry>
        </collision>
    </link>
    <link name="Leg15">
        <inertial>
            <origin xyz="0.9024136737236895 0 0" rpy="0 0 0"/>
            <mass value="1" />
            <inertia ixx="100" ixy="0" ixz="0" iyy="100" iyz="0" izz="100" />
        </inertial>
        <visual>
            <origin xyz="0.9024136737236895 0 0" rpy="0 0 0"/>
            <geometry>
                <box size="1.804827347447379 1.576486094360866 2.6153503360395254" />
            </geometry>
            <material name="Green">
                <color rgba="0 180.0 0.0 1.0"/>
            </material>
        </visual>
        <collision>
            <origin xyz="0.9024136737236895 0 0" rpy="0 0 0"/>
            <geometry>
                <box size="1.804827347447379 1.576486094360866 2.6153503360395254" />
            </geometry>
        </collision>
    </link>
    <link name="Leg16">
        <inertial>
            <origin xyz="0 0 0.9436601448520873" rpy="0 0 0"/>
            <mass value="1" />
            <inertia ixx="100" ixy="0" ixz="0" iyy="100" iyz="0" izz="100" />
        </inertial>
        <visual>
            <origin xyz="0 0 0.9436601448520873" rpy="0 0 0"/>
            <geometry>
                <box size="1.3045424248225774 1.708926718766007 1.8873202897041745" />
            </geometry>
            <material name="Green">
                <color rgba="0 180.0 0.0 1.0"/>
            </material>
        </visual>
        <collision>
            <origin xyz="0 0 0.9436601448520873" rpy="0 0 0"/>
            <geometry>
                <box size="1.3045424248225774 1.708926718766007 1.8873202897041745" />
            </geometry>
        </collision>
    </link>
    <link name="Leg17">
        <inertial>
            <origin xyz="0.6982407740297224 0 0" rpy="0 0 0"/>
            <mass value="1" />
            <inertia ixx="100" ixy="0" ixz="0" iyy="100" iyz="0" izz="100" />
        </inertial>
        <visual>
            <origin xyz="0.6982407740297224 0 0" rpy="0 0 0"/>
            <geometry>
                <box size="1.3964815480594448 1.9902610741589242 1.2409715326817026" />
            </geometry>
            <material name="Blue">
                <color rgba="0 1.0 1.0 1.0"/>
            </material>
        </visual>
        <collision>
            <origin xyz="0.6982407740297224 0 0" rpy="0 0 0"/>
            <geometry>
                <box size="1.3964815480594448 1.9902610741589242 1.2409715326817026" />
            </geometry>
        </collision>
    </link>
    <link name="Leg18">
        <inertial>
            <origin xyz="0.6590110742018265 0 0" rpy="0 0 0"/>
            <mass value="1" />
            <inertia ixx="100" ixy="0" ixz="0" iyy="100" iyz="0" izz="100" />
        </inertial>
        <visual>
            <origin xyz="0.6590110742018265 0 0" rpy="0 0 0"/>
            <geometry>
                <box size="1.318022148403653 2.383548693565116 2.0335076246705865" />
            </geometry>
            <material name="Blue">
                <color rgba="0 1.0 1.0 1.0"/>
            </material>
        </visual>
        <collision>
            <origin xyz="0.6590110742018265 0 0" rpy="0 0 0"/>
            <geometry>
                <box size="1.318022148403653 2.383548693565116 2.0335076246705865" />
            </geometry>
        </collision>
    </link>
    <link name="Leg19">
        <inertial>
            <origin xyz="0 0 1.17173569591869" rpy="0 0 0"/>
            <mass value="1" />
            <inertia ixx="100" ixy="0" ixz="0" iyy="100" iyz="0" izz="100" />
        </inertial>
        <visual>
            <origin xyz="0 0 1.17173569591869" rpy="0 0 0"/>
            <geometry>
                <box size="2.7395760483229097 1.4200366874306127 2.34347139183738" />
            </geometry>
            <material name="Green">
                <color rgba="0 180.0 0.0 1.0"/>
            </material>
        </visual>
        <collision>
            <origin xyz="0 0 1.17173569591869" rpy="0 0 0"/>
            <geometry>
                <box size="2.7395760483229097 1.4200366874306127 2.34347139183738" />
            </geometry>
        </collision>
    </link>
    <link name="Leg20">
        <inertial>
            <origin xyz="0 0.7309137920998303 0" rpy="0 0 0"/>
            <mass value="1" />
            <inertia ixx="100" ixy="0" ixz="0" iyy="100" iyz="0" izz="100" />
        </inertial>
        <visual>
            <origin xyz="0 0.7309137920998303 0" rpy="0 0 0"/>
            <geometry>
                <box size="1.1419484361252978 1.4618275841996606 2.7978750648933794" />
            </geometry>
            <material name="Green">
                <color rgba="0 180.0 0.0 1.0"/>
            </material>
        </visual>
        <collision>
            <origin xyz="0 0.7309137920998303 0" rpy="0 0 0"/>
            <geometry>
                <box size="1.1419484361252978 1.4618275841996606 2.7978750648933794" />
            </geometry>
        </collision>
    </link>
    <link name="Leg21">
        <inertial>
            <origin xyz="0 0.7074643202800318 0" rpy="0 0 0"/>
            <mass value="1" />
            <inertia ixx="100" ixy="0" ixz="0" iyy="100" iyz="0" izz="100" />
        </inertial>
        <visual>
            <origin xyz="0 0.7074643202800318 0" rpy="0 0 0"/>
            <geometry>
                <box size="2.9209162042062644 1.4149286405600636 2.174351225484976" />
            </geometry>
            <material name="Blue">
                <color rgba="0 1.0 1.0 1.0"/>
            </material>
        </visual>
        <collision>
            <origin xyz="0 0.7074643202800318 0" rpy="0 0 0"/>
            <geometry>
                <box size="2.9209162042062644 1.4149286405600636 2.174351225484976" />
            </geometry>
        </collision>
    </link>
    <link name="Leg22">
        <inertial>
            <origin xyz="0 0.526428096164254 0" rpy="0 0 0"/>
            <mass value="1" />
            <inertia ixx="100" ixy="0" ixz="0" iyy="100" iyz="0" izz="100" />
        </inertial>
        <visual>
            <origin xyz="0 0.526428096164254 0" rpy="0 0 0"/>
            <geometry>
                <box size="1.349023519187103 1.052856192328508 2.141872591000026" />
            </geometry>
            <material name="Blue">
                <color rgba="0 1.0 1.0 1.0"/>
            </material>
        </visual>
        <collision>
            <origin xyz="0 0.526428096164254 0" rpy="0 0 0"/>
            <geometry>
                <box size="1.349023519187103 1.052856192328508 2.141872591000026" />
            </geometry>
        </collision>
    </link>
    <link name="Leg23">
        <inertial>
            <origin xyz="0 0.8115265736739202 0" rpy="0 0 0"/>
            <mass value="1" />
            <inertia ixx="100" ixy="0" ixz="0" iyy="100" iyz="0" izz="100" />
        </inertial>
        <visual>
            <origin xyz="0 0.8115265736739202 0" rpy="0 0 0"/>
            <geometry>
                <box size="1.036561247504808 1.6230531473478405 1.5223772419336696" />
            </geometry>
            <material name="Blue">
                <color rgba="0 1.0 1.0 1.0"/>
            </material>
        </visual>
        <collision>
            <origin xyz="0 0.8115265736739202 0" rpy="0 0 0"/>
            <geometry>
                <box size="1.036561247504808 1.6230531473478405 1.5223772419336696" />
            </geometry>
        </collision>
    </link>
    <link name="Leg24">
        <inertial>
            <origin xyz="1.4712534795616117 0 0" rpy="0 0 0"/>
            <mass value="1" />
            <inertia ixx="100" ixy="0" ixz="0" iyy="100" iyz="0" izz="100" />
        </inertial>
        <visual>
            <origin xyz="1.4712534795616117 0 0" rpy="0 0 0"/>
            <geometry>
                <box size="2.9425069591232234 2.1292258646813504 1.523204881854839" />
            </geometry>
            <material name="Green">
                <color rgba="0 180.0 0.0 1.0"/>
            </material>
        </visual>
        <collision>
            <origin xyz="1.4712534795616117 0 0" rpy="0 0 0"/>
            <geometry>
                <box size="2.9425069591232234 2.1292258646813504 1.523204881854839" />
            </geometry>
        </collision>
    </link>
    <link name="Leg25">
        <inertial>
            <origin xyz="0 0 1.2109597524715163" rpy="0 0 0"/>
            <mass value="1" />
            <inertia ixx="100" ixy="0" ixz="0" iyy="100" iyz="0" izz="100" />
        </inertial>
        <visual>
            <origin xyz="0 0 1.2109597524715163" rpy="0 0 0"/>
            <geometry>
                <box size="1.9535041400484587 2.146598194492052 2.4219195049430327" />
            </geometry>
            <material name="Green">
                <color rgba="0 180.0 0.0 1.0"/>
            </material>
        </visual>
        <collision>
            <origin xyz="0 0 1.2109597524715163" rpy="0 0 0"/>
            <geometry>
                <box size="1.9535041400484587 2.146598194492052 2.4219195049430327" />
            </geometry>
        </collision>
    </link>
    <link name="Leg26">
        <inertial>
            <origin xyz="0 1.214100496407401 0" rpy="0 0 0"/>
            <mass value="1" />
            <inertia ixx="100" ixy="0" ixz="0" iyy="100" iyz="0" izz="100" />
        </inertial>
        <visual>
            <origin xyz="0 1.214100496407401 0" rpy="0 0 0"/>
            <geometry>
                <box size="1.9939625328315576 2.428200992814802 1.6447071480516118" />
            </geometry>
            <material name="Green">
                <color rgba="0 180.0 0.0 1.0"/>
            </material>
        </visual>
        <collision>
            <origin xyz="0 1.214100496407401 0" rpy="0 0 0"/>
            <geometry>
                <box size="1.9939625328315576 2.428200992814802 1.6447071480516118" />
            </geometry>
        </collision>
    </link>
    <joint name="Torso_Leg1" type="revolute">
       <parent link="Torso"/>
       <child  link="Leg1"/>
       <origin rpy="0 0 0" xyz="0 0 1.1149285133032036" />
     <axis xyz="1 0 0"/>
       <limit effort="0.0" lower="-3.14159" upper="3.14159" velocity="0.0"/>
    </joint>
    <joint name="Torso_Leg2" type="revolute">
       <parent link="Torso"/>
       <child  link="Leg2"/>
       <origin rpy="0 0 0" xyz="0.6054572294529345 0 0.5374968231104444" />
     <axis xyz="1 0 0"/>
       <limit effort="0.0" lower="-3.14159" upper="3.14159" velocity="0.0"/>
    </joint>
    <joint name="Leg1_Leg3" type="revolute">
       <parent link="Leg1"/>
       <child  link="Leg3"/>
       <origin rpy="0 0 0" xyz="2.2329783015083913 0 0" />
     <axis xyz="1 0 0"/>
       <limit effort="0.0" lower="-3.14159" upper="3.14159" velocity="0.0"/>
    </joint>
    <joint name="Leg3_Leg4" type="revolute">
       <parent link="Leg3"/>
       <child  link="Leg4"/>
       <origin rpy="0 0 0" xyz="2.226593658395826 0 0" />
     <axis xyz="1 0 0"/>
       <limit effort="0.0" lower="-3.14159" upper="3.14159" velocity="0.0"/>
    </joint>
    <joint name="Leg2_Leg5" type="revolute">
       <parent link="Leg2"/>
       <child  link="Leg5"/>
       <origin rpy="0 0 0" xyz="1.7934600881760416 0 0" />
     <axis xyz="1 0 0"/>
       <limit effort="0.0" lower="-3.14159" upper="3.14159" velocity="0.0"/>
    </joint>
    <joint name="Leg5_Leg6" type="revolute">
       <parent link="Leg5"/>
       <child  link="Leg6"/>
       <origin rpy="0 0 0" xyz="1.2855448424633367 0 0" />
     <axis xyz="1 0 0"/>
       <limit effort="0.0" lower="-3.14159" upper="3.14159" velocity="0.0"/>
    </joint>
    <joint name="Leg5_Leg7" type="revolute">
       <parent link="Leg5"/>
       <child  link="Leg7"/>
       <origin rpy="0 0 0" xyz="1.2855448424633367 1.4426641523834154 0" />
     <axis xyz="1 0 0"/>
       <limit effort="0.0" lower="-3.14159" upper="3.14159" velocity="0.0"/>
    </joint>
    <joint name="Leg7_Leg8" type="revolute">
       <parent link="Leg7"/>
       <child  link="Leg8"/>
       <origin rpy="0 0 0" xyz="0 2.922825446412805 0" />
     <axis xyz="1 0 0"/>
       <limit effort="0.0" lower="-3.14159" upper="3.14159" velocity="0.0"/>
    </joint>
    <joint name="Leg5_Leg9" type="revolute">
       <parent link="Leg5"/>
       <child  link="Leg9"/>
       <origin rpy="0 0 0" xyz="1.2855448424633367 1.4426641523834154 1.0745831585041392" />
     <axis xyz="1 0 0"/>
       <limit effort="0.0" lower="-3.14159" upper="3.14159" velocity="0.0"/>
    </joint>
    <joint name="Leg8_Leg10" type="revolute">
       <parent link="Leg8"/>
       <child  link="Leg10"/>
       <origin rpy="0 0 0" xyz="0 0.775742825411456 0.9130229908229164" />
     <axis xyz="1 0 0"/>
       <limit effort="0.0" lower="-3.14159" upper="3.14159" velocity="0.0"/>
    </joint>
    <joint name="Leg9_Leg11" type="revolute">
       <parent link="Leg9"/>
       <child  link="Leg11"/>
       <origin rpy="0 0 0" xyz="0 2.5021469478243725 0" />
     <axis xyz="1 0 0"/>
       <limit effort="0.0" lower="-3.14159" upper="3.14159" velocity="0.0"/>
    </joint>
    <joint name="Leg8_Leg12" type="revolute">
       <parent link="Leg8"/>
       <child  link="Leg12"/>
       <origin rpy="0 0 0" xyz="0.8057907519318811 0.775742825411456 0.9130229908229164" />
     <axis xyz="1 0 0"/>
       <limit effort="0.0" lower="-3.14159" upper="3.14159" velocity="0.0"/>
    </joint>
    <joint name="Leg12_Leg13" type="revolute">
       <parent link="Leg12"/>
       <child  link="Leg13"/>
       <origin rpy="0 0 0" xyz="2.768283638570595 0 0" />
     <axis xyz="1 0 0"/>
       <limit effort="0.0" lower="-3.14159" upper="3.14159" velocity="0.0"/>
    </joint>
    <joint name="Leg13_Leg14" type="revolute">
       <parent link="Leg13"/>
       <child  link="Leg14"/>
       <origin rpy="0 0 0" xyz="1.218247829580906 0 0" />
     <axis xyz="1 0 0"/>
       <limit effort="0.0" lower="-3.14159" upper="3.14159" velocity="0.0"/>
    </joint>
    <joint name="Leg14_Leg15" type="revolute">
       <parent link="Leg14"/>
       <child  link="Leg15"/>
       <origin rpy="0 0 0" xyz="1.804827347447379 0 0" />
     <axis xyz="1 0 0"/>
       <limit effort="0.0" lower="-3.14159" upper="3.14159" velocity="0.0"/>
    </joint>
    <joint name="Leg15_Leg16" type="revolute">
       <parent link="Leg15"/>
       <child  link="Leg16"/>
       <origin rpy="0 0 0" xyz="0 0 1.8873202897041745" />
     <axis xyz="1 0 0"/>
       <limit effort="0.0" lower="-3.14159" upper="3.14159" velocity="0.0"/>
    </joint>
    <joint name="Leg6_Leg17" type="revolute">
       <parent link="Leg6"/>
       <child  link="Leg17"/>
       <origin rpy="0 0 0" xyz="0.5326505837816973 1.1900928089132898 0" />
     <axis xyz="1 0 0"/>
       <limit effort="0.0" lower="-3.14159" upper="3.14159" velocity="0.0"/>
    </joint>
    <joint name="Leg16_Leg18" type="revolute">
       <parent link="Leg16"/>
       <child  link="Leg18"/>
       <origin rpy="0 0 0" xyz="1.3964815480594448 0 0" />
     <axis xyz="1 0 0"/>
       <limit effort="0.0" lower="-3.14159" upper="3.14159" velocity="0.0"/>
    </joint>
    <joint name="Leg7_Leg19" type="revolute">
       <parent link="Leg7"/>
       <child  link="Leg19"/>
       <origin rpy="0 0 0" xyz="0 2.922825446412805 1.165029567627299" />
     <axis xyz="1 0 0"/>
       <limit effort="0.0" lower="-3.14159" upper="3.14159" velocity="0.0"/>
    </joint>
    <joint name="Leg18_Leg20" type="revolute">
       <parent link="Leg18"/>
       <child  link="Leg20"/>
       <origin rpy="0 0 0" xyz="0 0.7100183437153064 1.17173569591869" />
     <axis xyz="1 0 0"/>
       <limit effort="0.0" lower="-3.14159" upper="3.14159" velocity="0.0"/>
    </joint>
    <joint name="Leg1_Leg21" type="revolute">
       <parent link="Leg1"/>
       <child  link="Leg21"/>
       <origin rpy="0 0 0" xyz="2.2329783015083913 0.9061017364270743 0" />
     <axis xyz="1 0 0"/>
       <limit effort="0.0" lower="-3.14159" upper="3.14159" velocity="0.0"/>
    </joint>
    <joint name="Leg3_Leg22" type="revolute">
       <parent link="Leg3"/>
       <child  link="Leg22"/>
       <origin rpy="0 0 0" xyz="2.226593658395826 1.0455168382831599 0" />
     <axis xyz="1 0 0"/>
       <limit effort="0.0" lower="-3.14159" upper="3.14159" velocity="0.0"/>
    </joint>
    <joint name="Leg15_Leg23" type="revolute">
       <parent link="Leg15"/>
       <child  link="Leg23"/>
       <origin rpy="0 0 0" xyz="0 0.8544633593830036 1.8873202897041745" />
     <axis xyz="1 0 0"/>
       <limit effort="0.0" lower="-3.14159" upper="3.14159" velocity="0.0"/>
    </joint>
    <joint name="Leg9_Leg24" type="revolute">
       <parent link="Leg9"/>
       <child  link="Leg24"/>
       <origin rpy="0 0 0" xyz="0.5456645131505011 2.5021469478243725 0" />
     <axis xyz="1 0 0"/>
       <limit effort="0.0" lower="-3.14159" upper="3.14159" velocity="0.0"/>
    </joint>
    <joint name="Leg14_Leg25" type="revolute">
       <parent link="Leg14"/>
       <child  link="Leg25"/>
       <origin rpy="0 0 0" xyz="1.804827347447379 0 1.3076751680197627" />
     <axis xyz="1 0 0"/>
       <limit effort="0.0" lower="-3.14159" upper="3.14159" velocity="0.0"/>
    </joint>
    <joint name="Leg17_Leg26" type="revolute">
       <parent link="Leg17"/>
       <child  link="Leg26"/>
       <origin rpy="0 0 0" xyz="0.6590110742018265 1.191774346782558 0" />
     <axis xyz="1 0 0"/>
       <limit effort="0.0" lower="-3.14159" upper="3.14159" velocity="0.0"/>
    </joint>
</robot>