<robot name = "robot">
    <link name="Torso">
        <inertial>
            <origin xyz="0 0 0.5314653456970405" rpy="0 0 0"/>
            <mass value="1" />
            <inertia ixx="100" ixy="0" ixz="0" iyy="100" iyz="0" izz="100" />
        </inertial>
        <visual>
            <origin xyz="0 0 0.5314653456970405" rpy="0 0 0"/>
            <geometry>
                <box size="1.9652668868563665 1.7890910820840635 1.062930691394081" />
            </geometry>
            <material name="Green">
                <color rgba="0 180.0 0.0 1.0"/>
            </material>
        </visual>
        <collision>
            <origin xyz="0 0 0.5314653456970405" rpy="0 0 0"/>
            <geometry>
                <box size="1.9652668868563665 1.7890910820840635 1.062930691394081" />
            </geometry>
        </collision>
    </link>
    <link name="Leg1">
        <inertial>
            <origin xyz="0 0 0.8849719207587254" rpy="0 0 0"/>
            <mass value="1" />
            <inertia ixx="100" ixy="0" ixz="0" iyy="100" iyz="0" izz="100" />
        </inertial>
        <visual>
            <origin xyz="0 0 0.8849719207587254" rpy="0 0 0"/>
            <geometry>
                <box size="1.6506041009296235 2.7640416220415363 1.7699438415174509" />
            </geometry>
            <material name="Blue">
                <color rgba="0 1.0 1.0 1.0"/>
            </material>
        </visual>
        <collision>
            <origin xyz="0 0 0.8849719207587254" rpy="0 0 0"/>
            <geometry>
                <box size="1.6506041009296235 2.7640416220415363 1.7699438415174509" />
            </geometry>
        </collision>
    </link>
    <link name="Leg2">
        <inertial>
            <origin xyz="0 0 0.932046869488523" rpy="0 0 0"/>
            <mass value="1" />
            <inertia ixx="100" ixy="0" ixz="0" iyy="100" iyz="0" izz="100" />
        </inertial>
        <visual>
            <origin xyz="0 0 0.932046869488523" rpy="0 0 0"/>
            <geometry>
                <box size="1.9659471948301406 2.9548785920834724 1.864093738977046" />
            </geometry>
            <material name="Blue">
                <color rgba="0 1.0 1.0 1.0"/>
            </material>
        </visual>
        <collision>
            <origin xyz="0 0 0.932046869488523" rpy="0 0 0"/>
            <geometry>
                <box size="1.9659471948301406 2.9548785920834724 1.864093738977046" />
            </geometry>
        </collision>
    </link>
    <link name="Leg3">
        <inertial>
            <origin xyz="1.0918771629335469 0 0" rpy="0 0 0"/>
            <mass value="1" />
            <inertia ixx="100" ixy="0" ixz="0" iyy="100" iyz="0" izz="100" />
        </inertial>
        <visual>
            <origin xyz="1.0918771629335469 0 0" rpy="0 0 0"/>
            <geometry>
                <box size="2.1837543258670937 1.8225240028527463 1.8153402357804507" />
            </geometry>
            <material name="Green">
                <color rgba="0 180.0 0.0 1.0"/>
            </material>
        </visual>
        <collision>
            <origin xyz="1.0918771629335469 0 0" rpy="0 0 0"/>
            <geometry>
                <box size="2.1837543258670937 1.8225240028527463 1.8153402357804507" />
            </geometry>
        </collision>
    </link>
    <link name="Leg4">
        <inertial>
            <origin xyz="0 0 1.3182088624523227" rpy="0 0 0"/>
            <mass value="1" />
            <inertia ixx="100" ixy="0" ixz="0" iyy="100" iyz="0" izz="100" />
        </inertial>
        <visual>
            <origin xyz="0 0 1.3182088624523227" rpy="0 0 0"/>
            <geometry>
                <box size="2.581802033051379 2.4821985109891824 2.6364177249046454" />
            </geometry>
            <material name="Green">
                <color rgba="0 180.0 0.0 1.0"/>
            </material>
        </visual>
        <collision>
            <origin xyz="0 0 1.3182088624523227" rpy="0 0 0"/>
            <geometry>
                <box size="2.581802033051379 2.4821985109891824 2.6364177249046454" />
            </geometry>
        </collision>
    </link>
    <link name="Leg5">
        <inertial>
            <origin xyz="0 1.0026539843721478 0" rpy="0 0 0"/>
            <mass value="1" />
            <inertia ixx="100" ixy="0" ixz="0" iyy="100" iyz="0" izz="100" />
        </inertial>
        <visual>
            <origin xyz="0 1.0026539843721478 0" rpy="0 0 0"/>
            <geometry>
                <box size="2.6883183141769287 2.0053079687442956 2.2006260163808644" />
            </geometry>
            <material name="Green">
                <color rgba="0 180.0 0.0 1.0"/>
            </material>
        </visual>
        <collision>
            <origin xyz="0 1.0026539843721478 0" rpy="0 0 0"/>
            <geometry>
                <box size="2.6883183141769287 2.0053079687442956 2.2006260163808644" />
            </geometry>
        </collision>
    </link>
    <link name="Leg6">
        <inertial>
            <origin xyz="0 1.3749315913171658 0" rpy="0 0 0"/>
            <mass value="1" />
            <inertia ixx="100" ixy="0" ixz="0" iyy="100" iyz="0" izz="100" />
        </inertial>
        <visual>
            <origin xyz="0 1.3749315913171658 0" rpy="0 0 0"/>
            <geometry>
                <box size="1.229011412354486 2.7498631826343316 2.0627104684471913" />
            </geometry>
            <material name="Green">
                <color rgba="0 180.0 0.0 1.0"/>
            </material>
        </visual>
        <collision>
            <origin xyz="0 1.3749315913171658 0" rpy="0 0 0"/>
            <geometry>
                <box size="1.229011412354486 2.7498631826343316 2.0627104684471913" />
            </geometry>
        </collision>
    </link>
    <link name="Leg7">
        <inertial>
            <origin xyz="0.9624531671465587 0 0" rpy="0 0 0"/>
            <mass value="1" />
            <inertia ixx="100" ixy="0" ixz="0" iyy="100" iyz="0" izz="100" />
        </inertial>
        <visual>
            <origin xyz="0.9624531671465587 0 0" rpy="0 0 0"/>
            <geometry>
                <box size="1.9249063342931174 1.8767812480637023 1.6906790881915252" />
            </geometry>
            <material name="Blue">
                <color rgba="0 1.0 1.0 1.0"/>
            </material>
        </visual>
        <collision>
            <origin xyz="0.9624531671465587 0 0" rpy="0 0 0"/>
            <geometry>
                <box size="1.9249063342931174 1.8767812480637023 1.6906790881915252" />
            </geometry>
        </collision>
    </link>
    <link name="Leg8">
        <inertial>
            <origin xyz="1.4342836436011328 0 0" rpy="0 0 0"/>
            <mass value="1" />
            <inertia ixx="100" ixy="0" ixz="0" iyy="100" iyz="0" izz="100" />
        </inertial>
        <visual>
            <origin xyz="1.4342836436011328 0 0" rpy="0 0 0"/>
            <geometry>
                <box size="2.8685672872022656 1.0759667993138926 1.0044006267309549" />
            </geometry>
            <material name="Green">
                <color rgba="0 180.0 0.0 1.0"/>
            </material>
        </visual>
        <collision>
            <origin xyz="1.4342836436011328 0 0" rpy="0 0 0"/>
            <geometry>
                <box size="2.8685672872022656 1.0759667993138926 1.0044006267309549" />
            </geometry>
        </collision>
    </link>
    <link name="Leg9">
        <inertial>
            <origin xyz="0 0 1.3998460814221285" rpy="0 0 0"/>
            <mass value="1" />
            <inertia ixx="100" ixy="0" ixz="0" iyy="100" iyz="0" izz="100" />
        </inertial>
        <visual>
            <origin xyz="0 0 1.3998460814221285" rpy="0 0 0"/>
            <geometry>
                <box size="2.7867955379914537 2.846316783851565 2.799692162844257" />
            </geometry>
            <material name="Green">
                <color rgba="0 180.0 0.0 1.0"/>
            </material>
        </visual>
        <collision>
            <origin xyz="0 0 1.3998460814221285" rpy="0 0 0"/>
            <geometry>
                <box size="2.7867955379914537 2.846316783851565 2.799692162844257" />
            </geometry>
        </collision>
    </link>
    <link name="Leg10">
        <inertial>
            <origin xyz="0 0.6502064669093438 0" rpy="0 0 0"/>
            <mass value="1" />
            <inertia ixx="100" ixy="0" ixz="0" iyy="100" iyz="0" izz="100" />
        </inertial>
        <visual>
            <origin xyz="0 0.6502064669093438 0" rpy="0 0 0"/>
            <geometry>
                <box size="1.7226838454014646 1.3004129338186876 1.6746134330324425" />
            </geometry>
            <material name="Blue">
                <color rgba="0 1.0 1.0 1.0"/>
            </material>
        </visual>
        <collision>
            <origin xyz="0 0.6502064669093438 0" rpy="0 0 0"/>
            <geometry>
                <box size="1.7226838454014646 1.3004129338186876 1.6746134330324425" />
            </geometry>
        </collision>
    </link>
    <link name="Leg11">
        <inertial>
            <origin xyz="0 1.2805255467288856 0" rpy="0 0 0"/>
            <mass value="1" />
            <inertia ixx="100" ixy="0" ixz="0" iyy="100" iyz="0" izz="100" />
        </inertial>
        <visual>
            <origin xyz="0 1.2805255467288856 0" rpy="0 0 0"/>
            <geometry>
                <box size="2.978915012567996 2.5610510934577713 2.3537719924709544" />
            </geometry>
            <material name="Green">
                <color rgba="0 180.0 0.0 1.0"/>
            </material>
        </visual>
        <collision>
            <origin xyz="0 1.2805255467288856 0" rpy="0 0 0"/>
            <geometry>
                <box size="2.978915012567996 2.5610510934577713 2.3537719924709544" />
            </geometry>
        </collision>
    </link>
    <link name="Leg12">
        <inertial>
            <origin xyz="0 0.9679758281666841 0" rpy="0 0 0"/>
            <mass value="1" />
            <inertia ixx="100" ixy="0" ixz="0" iyy="100" iyz="0" izz="100" />
        </inertial>
        <visual>
            <origin xyz="0 0.9679758281666841 0" rpy="0 0 0"/>
            <geometry>
                <box size="1.7069143150423278 1.9359516563333683 1.215242068154942" />
            </geometry>
            <material name="Blue">
                <color rgba="0 1.0 1.0 1.0"/>
            </material>
        </visual>
        <collision>
            <origin xyz="0 0.9679758281666841 0" rpy="0 0 0"/>
            <geometry>
                <box size="1.7069143150423278 1.9359516563333683 1.215242068154942" />
            </geometry>
        </collision>
    </link>
    <link name="Leg13">
        <inertial>
            <origin xyz="0 0.7508083935917504 0" rpy="0 0 0"/>
            <mass value="1" />
            <inertia ixx="100" ixy="0" ixz="0" iyy="100" iyz="0" izz="100" />
        </inertial>
        <visual>
            <origin xyz="0 0.7508083935917504 0" rpy="0 0 0"/>
            <geometry>
                <box size="1.4438170453940848 1.501616787183501 2.822401889372698" />
            </geometry>
            <material name="Blue">
                <color rgba="0 1.0 1.0 1.0"/>
            </material>
        </visual>
        <collision>
            <origin xyz="0 0.7508083935917504 0" rpy="0 0 0"/>
            <geometry>
                <box size="1.4438170453940848 1.501616787183501 2.822401889372698" />
            </geometry>
        </collision>
    </link>
    <link name="Leg14">
        <inertial>
            <origin xyz="0 1.3650267280723338 0" rpy="0 0 0"/>
            <mass value="1" />
            <inertia ixx="100" ixy="0" ixz="0" iyy="100" iyz="0" izz="100" />
        </inertial>
        <visual>
            <origin xyz="0 1.3650267280723338 0" rpy="0 0 0"/>
            <geometry>
                <box size="1.363350674573625 2.7300534561446677 1.8397597094661666" />
            </geometry>
            <material name="Green">
                <color rgba="0 180.0 0.0 1.0"/>
            </material>
        </visual>
        <collision>
            <origin xyz="0 1.3650267280723338 0" rpy="0 0 0"/>
            <geometry>
                <box size="1.363350674573625 2.7300534561446677 1.8397597094661666" />
            </geometry>
        </collision>
    </link>
    <link name="Leg15">
        <inertial>
            <origin xyz="0 0 0.9058587236382679" rpy="0 0 0"/>
            <mass value="1" />
            <inertia ixx="100" ixy="0" ixz="0" iyy="100" iyz="0" izz="100" />
        </inertial>
        <visual>
            <origin xyz="0 0 0.9058587236382679" rpy="0 0 0"/>
            <geometry>
                <box size="1.607252857700094 2.0800468743467713 1.8117174472765358" />
            </geometry>
            <material name="Blue">
                <color rgba="0 1.0 1.0 1.0"/>
            </material>
        </visual>
        <collision>
            <origin xyz="0 0 0.9058587236382679" rpy="0 0 0"/>
            <geometry>
                <box size="1.607252857700094 2.0800468743467713 1.8117174472765358" />
            </geometry>
        </collision>
    </link>
    <link name="Leg16">
        <inertial>
            <origin xyz="1.1622966756454032 0 0" rpy="0 0 0"/>
            <mass value="1" />
            <inertia ixx="100" ixy="0" ixz="0" iyy="100" iyz="0" izz="100" />
        </inertial>
        <visual>
            <origin xyz="1.1622966756454032 0 0" rpy="0 0 0"/>
            <geometry>
                <box size="2.3245933512908064 1.9461362150748338 2.16780099206933" />
            </geometry>
            <material name="Blue">
                <color rgba="0 1.0 1.0 1.0"/>
            </material>
        </visual>
        <collision>
            <origin xyz="1.1622966756454032 0 0" rpy="0 0 0"/>
            <geometry>
                <box size="2.3245933512908064 1.9461362150748338 2.16780099206933" />
            </geometry>
        </collision>
    </link>
    <link name="Leg17">
        <inertial>
            <origin xyz="1.2705874249076938 0 0" rpy="0 0 0"/>
            <mass value="1" />
            <inertia ixx="100" ixy="0" ixz="0" iyy="100" iyz="0" izz="100" />
        </inertial>
        <visual>
            <origin xyz="1.2705874249076938 0 0" rpy="0 0 0"/>
            <geometry>
                <box size="2.5411748498153877 1.0997918816709376 2.657080332258184" />
            </geometry>
            <material name="Blue">
                <color rgba="0 1.0 1.0 1.0"/>
            </material>
        </visual>
        <collision>
            <origin xyz="1.2705874249076938 0 0" rpy="0 0 0"/>
            <geometry>
                <box size="2.5411748498153877 1.0997918816709376 2.657080332258184" />
            </geometry>
        </collision>
    </link>
    <link name="Leg18">
        <inertial>
            <origin xyz="1.2888951396784571 0 0" rpy="0 0 0"/>
            <mass value="1" />
            <inertia ixx="100" ixy="0" ixz="0" iyy="100" iyz="0" izz="100" />
        </inertial>
        <visual>
            <origin xyz="1.2888951396784571 0 0" rpy="0 0 0"/>
            <geometry>
                <box size="2.5777902793569143 2.418980918746721 1.2439293512350915" />
            </geometry>
            <material name="Green">
                <color rgba="0 180.0 0.0 1.0"/>
            </material>
        </visual>
        <collision>
            <origin xyz="1.2888951396784571 0 0" rpy="0 0 0"/>
            <geometry>
                <box size="2.5777902793569143 2.418980918746721 1.2439293512350915" />
            </geometry>
        </collision>
    </link>
    <link name="Leg19">
        <inertial>
            <origin xyz="0 0.6341011851303442 0" rpy="0 0 0"/>
            <mass value="1" />
            <inertia ixx="100" ixy="0" ixz="0" iyy="100" iyz="0" izz="100" />
        </inertial>
        <visual>
            <origin xyz="0 0.6341011851303442 0" rpy="0 0 0"/>
            <geometry>
                <box size="2.1497626000350545 1.2682023702606884 1.6583990951999914" />
            </geometry>
            <material name="Blue">
                <color rgba="0 1.0 1.0 1.0"/>
            </material>
        </visual>
        <collision>
            <origin xyz="0 0.6341011851303442 0" rpy="0 0 0"/>
            <geometry>
                <box size="2.1497626000350545 1.2682023702606884 1.6583990951999914" />
            </geometry>
        </collision>
    </link>
    <link name="Leg20">
        <inertial>
            <origin xyz="0 0 0.9795318997112531" rpy="0 0 0"/>
            <mass value="1" />
            <inertia ixx="100" ixy="0" ixz="0" iyy="100" iyz="0" izz="100" />
        </inertial>
        <visual>
            <origin xyz="0 0 0.9795318997112531" rpy="0 0 0"/>
            <geometry>
                <box size="1.125262480624077 2.87107454511813 1.9590637994225062" />
            </geometry>
            <material name="Green">
                <color rgba="0 180.0 0.0 1.0"/>
            </material>
        </visual>
        <collision>
            <origin xyz="0 0 0.9795318997112531" rpy="0 0 0"/>
            <geometry>
                <box size="1.125262480624077 2.87107454511813 1.9590637994225062" />
            </geometry>
        </collision>
    </link>
    <link name="Leg21">
        <inertial>
            <origin xyz="0.7700050064910782 0 0" rpy="0 0 0"/>
            <mass value="1" />
            <inertia ixx="100" ixy="0" ixz="0" iyy="100" iyz="0" izz="100" />
        </inertial>
        <visual>
            <origin xyz="0.7700050064910782 0 0" rpy="0 0 0"/>
            <geometry>
                <box size="1.5400100129821563 2.5073360093452797 2.738198463038302" />
            </geometry>
            <material name="Blue">
                <color rgba="0 1.0 1.0 1.0"/>
            </material>
        </visual>
        <collision>
            <origin xyz="0.7700050064910782 0 0" rpy="0 0 0"/>
            <geometry>
                <box size="1.5400100129821563 2.5073360093452797 2.738198463038302" />
            </geometry>
        </collision>
    </link>
    <link name="Leg22">
        <inertial>
            <origin xyz="0 0.6570287182058812 0" rpy="0 0 0"/>
            <mass value="1" />
            <inertia ixx="100" ixy="0" ixz="0" iyy="100" iyz="0" izz="100" />
        </inertial>
        <visual>
            <origin xyz="0 0.6570287182058812 0" rpy="0 0 0"/>
            <geometry>
                <box size="1.9451963373912102 1.3140574364117623 2.254628868662633" />
            </geometry>
            <material name="Green">
                <color rgba="0 180.0 0.0 1.0"/>
            </material>
        </visual>
        <collision>
            <origin xyz="0 0.6570287182058812 0" rpy="0 0 0"/>
            <geometry>
                <box size="1.9451963373912102 1.3140574364117623 2.254628868662633" />
            </geometry>
        </collision>
    </link>
    <link name="Leg23">
        <inertial>
            <origin xyz="0 1.3532873544249515 0" rpy="0 0 0"/>
            <mass value="1" />
            <inertia ixx="100" ixy="0" ixz="0" iyy="100" iyz="0" izz="100" />
        </inertial>
        <visual>
            <origin xyz="0 1.3532873544249515 0" rpy="0 0 0"/>
            <geometry>
                <box size="2.8914950449161494 2.706574708849903 2.7006339363594343" />
            </geometry>
            <material name="Green">
                <color rgba="0 180.0 0.0 1.0"/>
            </material>
        </visual>
        <collision>
            <origin xyz="0 1.3532873544249515 0" rpy="0 0 0"/>
            <geometry>
                <box size="2.8914950449161494 2.706574708849903 2.7006339363594343" />
            </geometry>
        </collision>
    </link>
    <link name="Leg24">
        <inertial>
            <origin xyz="0 0 0.589386823762958" rpy="0 0 0"/>
            <mass value="1" />
            <inertia ixx="100" ixy="0" ixz="0" iyy="100" iyz="0" izz="100" />
        </inertial>
        <visual>
            <origin xyz="0 0 0.589386823762958" rpy="0 0 0"/>
            <geometry>
                <box size="2.2256197156259656 2.167524269370869 1.178773647525916" />
            </geometry>
            <material name="Blue">
                <color rgba="0 1.0 1.0 1.0"/>
            </material>
        </visual>
        <collision>
            <origin xyz="0 0 0.589386823762958" rpy="0 0 0"/>
            <geometry>
                <box size="2.2256197156259656 2.167524269370869 1.178773647525916" />
            </geometry>
        </collision>
    </link>
    <link name="Leg25">
        <inertial>
            <origin xyz="0 0 0.5370989214160301" rpy="0 0 0"/>
            <mass value="1" />
            <inertia ixx="100" ixy="0" ixz="0" iyy="100" iyz="0" izz="100" />
        </inertial>
        <visual>
            <origin xyz="0 0 0.5370989214160301" rpy="0 0 0"/>
            <geometry>
                <box size="2.4007825095499618 2.6177830935386286 1.0741978428320602" />
            </geometry>
            <material name="Green">
                <color rgba="0 180.0 0.0 1.0"/>
            </material>
        </visual>
        <collision>
            <origin xyz="0 0 0.5370989214160301" rpy="0 0 0"/>
            <geometry>
                <box size="2.4007825095499618 2.6177830935386286 1.0741978428320602" />
            </geometry>
        </collision>
    </link>
    <joint name="Torso_Leg1" type="revolute">
       <parent link="Torso"/>
       <child  link="Leg1"/>
       <origin rpy="0 0 0" xyz="0 0 1.062930691394081" />
     <axis xyz="1 0 0"/>
       <limit effort="0.0" lower="-3.14159" upper="3.14159" velocity="0.0"/>
    </joint>
    <joint name="Leg1_Leg2" type="revolute">
       <parent link="Leg1"/>
       <child  link="Leg2"/>
       <origin rpy="0 0 0" xyz="0 0 1.864093738977046" />
     <axis xyz="1 0 0"/>
       <limit effort="0.0" lower="-3.14159" upper="3.14159" velocity="0.0"/>
    </joint>
    <joint name="Torso_Leg3" type="revolute">
       <parent link="Torso"/>
       <child  link="Leg3"/>
       <origin rpy="0 0 0" xyz="0.8253020504648118 0 0.8849719207587254" />
     <axis xyz="1 0 0"/>
       <limit effort="0.0" lower="-3.14159" upper="3.14159" velocity="0.0"/>
    </joint>
    <joint name="Leg3_Leg4" type="revolute">
       <parent link="Leg3"/>
       <child  link="Leg4"/>
       <origin rpy="0 0 0" xyz="0 0 2.6364177249046454" />
     <axis xyz="1 0 0"/>
       <limit effort="0.0" lower="-3.14159" upper="3.14159" velocity="0.0"/>
    </joint>
    <joint name="Leg2_Leg5" type="revolute">
       <parent link="Leg2"/>
       <child  link="Leg5"/>
       <origin rpy="0 0 0" xyz="1.0918771629335469 0.9112620014263731 0" />
     <axis xyz="1 0 0"/>
       <limit effort="0.0" lower="-3.14159" upper="3.14159" velocity="0.0"/>
    </joint>
    <joint name="Leg5_Leg6" type="revolute">
       <parent link="Leg5"/>
       <child  link="Leg6"/>
       <origin rpy="0 0 0" xyz="0 2.7498631826343316 0" />
     <axis xyz="1 0 0"/>
       <limit effort="0.0" lower="-3.14159" upper="3.14159" velocity="0.0"/>
    </joint>
    <joint name="Leg4_Leg7" type="revolute">
       <parent link="Leg4"/>
       <child  link="Leg7"/>
       <origin rpy="0 0 0" xyz="1.3441591570884643 1.0026539843721478 0" />
     <axis xyz="1 0 0"/>
       <limit effort="0.0" lower="-3.14159" upper="3.14159" velocity="0.0"/>
    </joint>
    <joint name="Leg5_Leg8" type="revolute">
       <parent link="Leg5"/>
       <child  link="Leg8"/>
       <origin rpy="0 0 0" xyz="0.614505706177243 2.7498631826343316 0" />
     <axis xyz="1 0 0"/>
       <limit effort="0.0" lower="-3.14159" upper="3.14159" velocity="0.0"/>
    </joint>
    <joint name="Leg4_Leg9" type="revolute">
       <parent link="Leg4"/>
       <child  link="Leg9"/>
       <origin rpy="0 0 0" xyz="1.3441591570884643 1.0026539843721478 1.1003130081904322" />
     <axis xyz="1 0 0"/>
       <limit effort="0.0" lower="-3.14159" upper="3.14159" velocity="0.0"/>
    </joint>
    <joint name="Leg1_Leg10" type="revolute">
       <parent link="Leg1"/>
       <child  link="Leg10"/>
       <origin rpy="0 0 0" xyz="0 1.4774392960417362 1.864093738977046" />
     <axis xyz="1 0 0"/>
       <limit effort="0.0" lower="-3.14159" upper="3.14159" velocity="0.0"/>
    </joint>
    <joint name="Leg8_Leg11" type="revolute">
       <parent link="Leg8"/>
       <child  link="Leg11"/>
       <origin rpy="0 0 0" xyz="0 1.4231583919257824 1.3998460814221285" />
     <axis xyz="1 0 0"/>
       <limit effort="0.0" lower="-3.14159" upper="3.14159" velocity="0.0"/>
    </joint>
    <joint name="Leg6_Leg12" type="revolute">
       <parent link="Leg6"/>
       <child  link="Leg12"/>
       <origin rpy="0 0 0" xyz="0.9624531671465587 0.9383906240318511 0" />
     <axis xyz="1 0 0"/>
       <limit effort="0.0" lower="-3.14159" upper="3.14159" velocity="0.0"/>
    </joint>
    <joint name="Leg3_Leg13" type="revolute">
       <parent link="Leg3"/>
       <child  link="Leg13"/>
       <origin rpy="0 0 0" xyz="0 1.2410992554945912 2.6364177249046454" />
     <axis xyz="1 0 0"/>
       <limit effort="0.0" lower="-3.14159" upper="3.14159" velocity="0.0"/>
    </joint>
    <joint name="Leg4_Leg14" type="revolute">
       <parent link="Leg4"/>
       <child  link="Leg14"/>
       <origin rpy="0 0 0" xyz="1.3441591570884643 2.0053079687442956 1.1003130081904322" />
     <axis xyz="1 0 0"/>
       <limit effort="0.0" lower="-3.14159" upper="3.14159" velocity="0.0"/>
    </joint>
    <joint name="Leg13_Leg15" type="revolute">
       <parent link="Leg13"/>
       <child  link="Leg15"/>
       <origin rpy="0 0 0" xyz="0 1.3650267280723338 0.9198798547330833" />
     <axis xyz="1 0 0"/>
       <limit effort="0.0" lower="-3.14159" upper="3.14159" velocity="0.0"/>
    </joint>
    <joint name="Leg12_Leg16" type="revolute">
       <parent link="Leg12"/>
       <child  link="Leg16"/>
       <origin rpy="0 0 0" xyz="0.7219085226970424 0.7508083935917504 0" />
     <axis xyz="1 0 0"/>
       <limit effort="0.0" lower="-3.14159" upper="3.14159" velocity="0.0"/>
    </joint>
    <joint name="Leg3_Leg17" type="revolute">
       <parent link="Leg3"/>
       <child  link="Leg17"/>
       <origin rpy="0 0 0" xyz="1.2909010165256896 1.2410992554945912 2.6364177249046454" />
     <axis xyz="1 0 0"/>
       <limit effort="0.0" lower="-3.14159" upper="3.14159" velocity="0.0"/>
    </joint>
    <joint name="Leg9_Leg18" type="revolute">
       <parent link="Leg9"/>
       <child  link="Leg18"/>
       <origin rpy="0 0 0" xyz="0.8613419227007323 0.6502064669093438 0" />
     <axis xyz="1 0 0"/>
       <limit effort="0.0" lower="-3.14159" upper="3.14159" velocity="0.0"/>
    </joint>
    <joint name="Leg13_Leg19" type="revolute">
       <parent link="Leg13"/>
       <child  link="Leg19"/>
       <origin rpy="0 0 0" xyz="0 2.7300534561446677 0.9198798547330833" />
     <axis xyz="1 0 0"/>
       <limit effort="0.0" lower="-3.14159" upper="3.14159" velocity="0.0"/>
    </joint>
    <joint name="Leg11_Leg20" type="revolute">
       <parent link="Leg11"/>
       <child  link="Leg20"/>
       <origin rpy="0 0 0" xyz="0 0.9679758281666841 0.607621034077471" />
     <axis xyz="1 0 0"/>
       <limit effort="0.0" lower="-3.14159" upper="3.14159" velocity="0.0"/>
    </joint>
    <joint name="Leg8_Leg21" type="revolute">
       <parent link="Leg8"/>
       <child  link="Leg21"/>
       <origin rpy="0 0 0" xyz="1.3933977689957269 1.4231583919257824 1.3998460814221285" />
     <axis xyz="1 0 0"/>
       <limit effort="0.0" lower="-3.14159" upper="3.14159" velocity="0.0"/>
    </joint>
    <joint name="Leg9_Leg22" type="revolute">
       <parent link="Leg9"/>
       <child  link="Leg22"/>
       <origin rpy="0 0 0" xyz="0.8613419227007323 1.3004129338186876 0" />
     <axis xyz="1 0 0"/>
       <limit effort="0.0" lower="-3.14159" upper="3.14159" velocity="0.0"/>
    </joint>
    <joint name="Leg14_Leg23" type="revolute">
       <parent link="Leg14"/>
       <child  link="Leg23"/>
       <origin rpy="0 0 0" xyz="0 1.0400234371733856 0.9058587236382679" />
     <axis xyz="1 0 0"/>
       <limit effort="0.0" lower="-3.14159" upper="3.14159" velocity="0.0"/>
    </joint>
    <joint name="Leg14_Leg24" type="revolute">
       <parent link="Leg14"/>
       <child  link="Leg24"/>
       <origin rpy="0 0 0" xyz="0 1.0400234371733856 1.8117174472765358" />
     <axis xyz="1 0 0"/>
       <limit effort="0.0" lower="-3.14159" upper="3.14159" velocity="0.0"/>
    </joint>
    <joint name="Leg9_Leg25" type="revolute">
       <parent link="Leg9"/>
       <child  link="Leg25"/>
       <origin rpy="0 0 0" xyz="0.8613419227007323 1.3004129338186876 0.8373067165162212" />
     <axis xyz="1 0 0"/>
       <limit effort="0.0" lower="-3.14159" upper="3.14159" velocity="0.0"/>
    </joint>
</robot>