<robot name = "robot">
    <link name="Torso">
        <inertial>
            <origin xyz="0 0 2.354929103049636" rpy="0 0 0"/>
            <mass value="1" />
            <inertia ixx="100" ixy="0" ixz="0" iyy="100" iyz="0" izz="100" />
        </inertial>
        <visual>
            <origin xyz="0 0 2.354929103049636" rpy="0 0 0"/>
            <geometry>
                <box size="2.4180911685827864 1.736718927202977 2.354929103049636" />
            </geometry>
            <material name="Green">
                <color rgba="0 180.0 0.0 1.0"/>
            </material>
        </visual>
        <collision>
            <origin xyz="0 0 2.354929103049636" rpy="0 0 0"/>
            <geometry>
                <box size="2.4180911685827864 1.736718927202977 2.354929103049636" />
            </geometry>
        </collision>
    </link>
    <link name="Leg1">
        <inertial>
            <origin xyz="0.5470353881818245 1.2397681843396675 1.3346069032550227" rpy="0 0 0"/>
            <mass value="1" />
            <inertia ixx="100" ixy="0" ixz="0" iyy="100" iyz="0" izz="100" />
        </inertial>
        <visual>
            <origin xyz="0.5470353881818245 1.2397681843396675 1.3346069032550227" rpy="0 0 0"/>
            <geometry>
                <box size="1.094070776363649 2.479536368679335 2.6692138065100455" />
            </geometry>
            <material name="Blue">
                <color rgba="0 1.0 1.0 1.0"/>
            </material>
        </visual>
        <collision>
            <origin xyz="0.5470353881818245 1.2397681843396675 1.3346069032550227" rpy="0 0 0"/>
            <geometry>
                <box size="1.094070776363649 2.479536368679335 2.6692138065100455" />
            </geometry>
        </collision>
    </link>
    <link name="Leg2">
        <inertial>
            <origin xyz="0 1.42305997755363 2.7648523270579393" rpy="0 0 0"/>
            <mass value="1" />
            <inertia ixx="100" ixy="0" ixz="0" iyy="100" iyz="0" izz="100" />
        </inertial>
        <visual>
            <origin xyz="0 1.42305997755363 2.7648523270579393" rpy="0 0 0"/>
            <geometry>
                <box size="2.3337633032052945 2.84611995510726 2.7648523270579393" />
            </geometry>
            <material name="Blue">
                <color rgba="0 1.0 1.0 1.0"/>
            </material>
        </visual>
        <collision>
            <origin xyz="0 1.42305997755363 2.7648523270579393" rpy="0 0 0"/>
            <geometry>
                <box size="2.3337633032052945 2.84611995510726 2.7648523270579393" />
            </geometry>
        </collision>
    </link>
    <link name="Leg3">
        <inertial>
            <origin xyz="0.8936808910185349 1.404710110518075 2.3633119622009113" rpy="0 0 0"/>
            <mass value="1" />
            <inertia ixx="100" ixy="0" ixz="0" iyy="100" iyz="0" izz="100" />
        </inertial>
        <visual>
            <origin xyz="0.8936808910185349 1.404710110518075 2.3633119622009113" rpy="0 0 0"/>
            <geometry>
                <box size="1.7873617820370697 2.80942022103615 2.3633119622009113" />
            </geometry>
            <material name="Blue">
                <color rgba="0 1.0 1.0 1.0"/>
            </material>
        </visual>
        <collision>
            <origin xyz="0.8936808910185349 1.404710110518075 2.3633119622009113" rpy="0 0 0"/>
            <geometry>
                <box size="1.7873617820370697 2.80942022103615 2.3633119622009113" />
            </geometry>
        </collision>
    </link>
    <link name="Leg4">
        <inertial>
            <origin xyz="0 1.9299253223046957 0" rpy="0 0 0"/>
            <mass value="1" />
            <inertia ixx="100" ixy="0" ixz="0" iyy="100" iyz="0" izz="100" />
        </inertial>
        <visual>
            <origin xyz="0 1.9299253223046957 0" rpy="0 0 0"/>
            <geometry>
                <box size="2.3782413246223397 1.9299253223046957 1.5408172263273283" />
            </geometry>
            <material name="Blue">
                <color rgba="0 1.0 1.0 1.0"/>
            </material>
        </visual>
        <collision>
            <origin xyz="0 1.9299253223046957 0" rpy="0 0 0"/>
            <geometry>
                <box size="2.3782413246223397 1.9299253223046957 1.5408172263273283" />
            </geometry>
        </collision>
    </link>
    <link name="Leg5">
        <inertial>
            <origin xyz="0 2.74257915015386 1.1699060148896816" rpy="0 0 0"/>
            <mass value="1" />
            <inertia ixx="100" ixy="0" ixz="0" iyy="100" iyz="0" izz="100" />
        </inertial>
        <visual>
            <origin xyz="0 2.74257915015386 1.1699060148896816" rpy="0 0 0"/>
            <geometry>
                <box size="1.6449085917141588 2.74257915015386 2.339812029779363" />
            </geometry>
            <material name="Blue">
                <color rgba="0 1.0 1.0 1.0"/>
            </material>
        </visual>
        <collision>
            <origin xyz="0 2.74257915015386 1.1699060148896816" rpy="0 0 0"/>
            <geometry>
                <box size="1.6449085917141588 2.74257915015386 2.339812029779363" />
            </geometry>
        </collision>
    </link>
    <link name="Leg6">
        <inertial>
            <origin xyz="1.4737324142230315 0 0" rpy="0 0 0"/>
            <mass value="1" />
            <inertia ixx="100" ixy="0" ixz="0" iyy="100" iyz="0" izz="100" />
        </inertial>
        <visual>
            <origin xyz="1.4737324142230315 0 0" rpy="0 0 0"/>
            <geometry>
                <box size="2.947464828446063 1.8770786046437198 2.5244337097281213" />
            </geometry>
            <material name="Blue">
                <color rgba="0 1.0 1.0 1.0"/>
            </material>
        </visual>
        <collision>
            <origin xyz="1.4737324142230315 0 0" rpy="0 0 0"/>
            <geometry>
                <box size="2.947464828446063 1.8770786046437198 2.5244337097281213" />
            </geometry>
        </collision>
    </link>
    <link name="Leg7">
        <inertial>
            <origin xyz="0.9355377330775843 1.1800125298494843 2.8103180751635373" rpy="0 0 0"/>
            <mass value="1" />
            <inertia ixx="100" ixy="0" ixz="0" iyy="100" iyz="0" izz="100" />
        </inertial>
        <visual>
            <origin xyz="0.9355377330775843 1.1800125298494843 2.8103180751635373" rpy="0 0 0"/>
            <geometry>
                <box size="1.8710754661551685 2.3600250596989687 2.8103180751635373" />
            </geometry>
            <material name="Blue">
                <color rgba="0 1.0 1.0 1.0"/>
            </material>
        </visual>
        <collision>
            <origin xyz="0.9355377330775843 1.1800125298494843 2.8103180751635373" rpy="0 0 0"/>
            <geometry>
                <box size="1.8710754661551685 2.3600250596989687 2.8103180751635373" />
            </geometry>
        </collision>
    </link>
    <link name="Leg8">
        <inertial>
            <origin xyz="0 0 1.3682016709518958" rpy="0 0 0"/>
            <mass value="1" />
            <inertia ixx="100" ixy="0" ixz="0" iyy="100" iyz="0" izz="100" />
        </inertial>
        <visual>
            <origin xyz="0 0 1.3682016709518958" rpy="0 0 0"/>
            <geometry>
                <box size="2.0360222826847414 2.5054329497843257 1.3682016709518958" />
            </geometry>
            <material name="Blue">
                <color rgba="0 1.0 1.0 1.0"/>
            </material>
        </visual>
        <collision>
            <origin xyz="0 0 1.3682016709518958" rpy="0 0 0"/>
            <geometry>
                <box size="2.0360222826847414 2.5054329497843257 1.3682016709518958" />
            </geometry>
        </collision>
    </link>
    <link name="Leg9">
        <inertial>
            <origin xyz="0 1.3233535655769564 0" rpy="0 0 0"/>
            <mass value="1" />
            <inertia ixx="100" ixy="0" ixz="0" iyy="100" iyz="0" izz="100" />
        </inertial>
        <visual>
            <origin xyz="0 1.3233535655769564 0" rpy="0 0 0"/>
            <geometry>
                <box size="1.0280474499438341 2.6467071311539128 2.1209907971854403" />
            </geometry>
            <material name="Blue">
                <color rgba="0 1.0 1.0 1.0"/>
            </material>
        </visual>
        <collision>
            <origin xyz="0 1.3233535655769564 0" rpy="0 0 0"/>
            <geometry>
                <box size="1.0280474499438341 2.6467071311539128 2.1209907971854403" />
            </geometry>
        </collision>
    </link>
    <link name="Leg10">
        <inertial>
            <origin xyz="0 1.2458062572659898 0" rpy="0 0 0"/>
            <mass value="1" />
            <inertia ixx="100" ixy="0" ixz="0" iyy="100" iyz="0" izz="100" />
        </inertial>
        <visual>
            <origin xyz="0 1.2458062572659898 0" rpy="0 0 0"/>
            <geometry>
                <box size="2.1352161906112412 2.4916125145319796 1.736036778356963" />
            </geometry>
            <material name="Blue">
                <color rgba="0 1.0 1.0 1.0"/>
            </material>
        </visual>
        <collision>
            <origin xyz="0 1.2458062572659898 0" rpy="0 0 0"/>
            <geometry>
                <box size="2.1352161906112412 2.4916125145319796 1.736036778356963" />
            </geometry>
        </collision>
    </link>
    <link name="Leg11">
        <inertial>
            <origin xyz="0 1.383456670057143 2.508002406073521" rpy="0 0 0"/>
            <mass value="1" />
            <inertia ixx="100" ixy="0" ixz="0" iyy="100" iyz="0" izz="100" />
        </inertial>
        <visual>
            <origin xyz="0 1.383456670057143 2.508002406073521" rpy="0 0 0"/>
            <geometry>
                <box size="1.4106741293848173 2.766913340114286 2.508002406073521" />
            </geometry>
            <material name="Blue">
                <color rgba="0 1.0 1.0 1.0"/>
            </material>
        </visual>
        <collision>
            <origin xyz="0 1.383456670057143 2.508002406073521" rpy="0 0 0"/>
            <geometry>
                <box size="1.4106741293848173 2.766913340114286 2.508002406073521" />
            </geometry>
        </collision>
    </link>
    <link name="Leg12">
        <inertial>
            <origin xyz="1.1740421039416027 0 0" rpy="0 0 0"/>
            <mass value="1" />
            <inertia ixx="100" ixy="0" ixz="0" iyy="100" iyz="0" izz="100" />
        </inertial>
        <visual>
            <origin xyz="1.1740421039416027 0 0" rpy="0 0 0"/>
            <geometry>
                <box size="2.3480842078832054 2.345252394941956 2.1981802780226847" />
            </geometry>
            <material name="Blue">
                <color rgba="0 1.0 1.0 1.0"/>
            </material>
        </visual>
        <collision>
            <origin xyz="1.1740421039416027 0 0" rpy="0 0 0"/>
            <geometry>
                <box size="2.3480842078832054 2.345252394941956 2.1981802780226847" />
            </geometry>
        </collision>
    </link>
    <link name="Leg13">
        <inertial>
            <origin xyz="0 0.55776179682145 0" rpy="0 0 0"/>
            <mass value="1" />
            <inertia ixx="100" ixy="0" ixz="0" iyy="100" iyz="0" izz="100" />
        </inertial>
        <visual>
            <origin xyz="0 0.55776179682145 0" rpy="0 0 0"/>
            <geometry>
                <box size="2.1641203468263277 1.1155235936429 1.30191654421457" />
            </geometry>
            <material name="Blue">
                <color rgba="0 1.0 1.0 1.0"/>
            </material>
        </visual>
        <collision>
            <origin xyz="0 0.55776179682145 0" rpy="0 0 0"/>
            <geometry>
                <box size="2.1641203468263277 1.1155235936429 1.30191654421457" />
            </geometry>
        </collision>
    </link>
    <link name="Leg14">
        <inertial>
            <origin xyz="1.2279413473814629 1.7356514676967307 1.3974374572628627" rpy="0 0 0"/>
            <mass value="1" />
            <inertia ixx="100" ixy="0" ixz="0" iyy="100" iyz="0" izz="100" />
        </inertial>
        <visual>
            <origin xyz="1.2279413473814629 1.7356514676967307 1.3974374572628627" rpy="0 0 0"/>
            <geometry>
                <box size="2.4558826947629258 1.7356514676967307 2.7948749145257255" />
            </geometry>
            <material name="Blue">
                <color rgba="0 1.0 1.0 1.0"/>
            </material>
        </visual>
        <collision>
            <origin xyz="1.2279413473814629 1.7356514676967307 1.3974374572628627" rpy="0 0 0"/>
            <geometry>
                <box size="2.4558826947629258 1.7356514676967307 2.7948749145257255" />
            </geometry>
        </collision>
    </link>
    <link name="Leg15">
        <inertial>
            <origin xyz="0 0 1.226200116525412" rpy="0 0 0"/>
            <mass value="1" />
            <inertia ixx="100" ixy="0" ixz="0" iyy="100" iyz="0" izz="100" />
        </inertial>
        <visual>
            <origin xyz="0 0 1.226200116525412" rpy="0 0 0"/>
            <geometry>
                <box size="2.673660726489616 1.054831904604444 1.226200116525412" />
            </geometry>
            <material name="Blue">
                <color rgba="0 1.0 1.0 1.0"/>
            </material>
        </visual>
        <collision>
            <origin xyz="0 0 1.226200116525412" rpy="0 0 0"/>
            <geometry>
                <box size="2.673660726489616 1.054831904604444 1.226200116525412" />
            </geometry>
        </collision>
    </link>
    <link name="Leg16">
        <inertial>
            <origin xyz="0 0.5054386416416916 0" rpy="0 0 0"/>
            <mass value="1" />
            <inertia ixx="100" ixy="0" ixz="0" iyy="100" iyz="0" izz="100" />
        </inertial>
        <visual>
            <origin xyz="0 0.5054386416416916 0" rpy="0 0 0"/>
            <geometry>
                <box size="2.173168235292628 1.0108772832833832 2.384516592548229" />
            </geometry>
            <material name="Blue">
                <color rgba="0 1.0 1.0 1.0"/>
            </material>
        </visual>
        <collision>
            <origin xyz="0 0.5054386416416916 0" rpy="0 0 0"/>
            <geometry>
                <box size="2.173168235292628 1.0108772832833832 2.384516592548229" />
            </geometry>
        </collision>
    </link>
    <link name="Leg17">
        <inertial>
            <origin xyz="1.3133292585298513 0.9133991481680089 0" rpy="0 0 0"/>
            <mass value="1" />
            <inertia ixx="100" ixy="0" ixz="0" iyy="100" iyz="0" izz="100" />
        </inertial>
        <visual>
            <origin xyz="1.3133292585298513 0.9133991481680089 0" rpy="0 0 0"/>
            <geometry>
                <box size="2.6266585170597025 1.8267982963360179 1.5853493341795541" />
            </geometry>
            <material name="Blue">
                <color rgba="0 1.0 1.0 1.0"/>
            </material>
        </visual>
        <collision>
            <origin xyz="1.3133292585298513 0.9133991481680089 0" rpy="0 0 0"/>
            <geometry>
                <box size="2.6266585170597025 1.8267982963360179 1.5853493341795541" />
            </geometry>
        </collision>
    </link>
    <link name="Leg18">
        <inertial>
            <origin xyz="1.080650708073664 0 0" rpy="0 0 0"/>
            <mass value="1" />
            <inertia ixx="100" ixy="0" ixz="0" iyy="100" iyz="0" izz="100" />
        </inertial>
        <visual>
            <origin xyz="1.080650708073664 0 0" rpy="0 0 0"/>
            <geometry>
                <box size="1.080650708073664 1.818325220220429 2.0129431271013973" />
            </geometry>
            <material name="Blue">
                <color rgba="0 1.0 1.0 1.0"/>
            </material>
        </visual>
        <collision>
            <origin xyz="1.080650708073664 0 0" rpy="0 0 0"/>
            <geometry>
                <box size="1.080650708073664 1.818325220220429 2.0129431271013973" />
            </geometry>
        </collision>
    </link>
    <link name="Leg19">
        <inertial>
            <origin xyz="1.173431520203858 0 1.417747143395338" rpy="0 0 0"/>
            <mass value="1" />
            <inertia ixx="100" ixy="0" ixz="0" iyy="100" iyz="0" izz="100" />
        </inertial>
        <visual>
            <origin xyz="1.173431520203858 0 1.417747143395338" rpy="0 0 0"/>
            <geometry>
                <box size="2.346863040407716 1.6391452833357472 2.835494286790676" />
            </geometry>
            <material name="Blue">
                <color rgba="0 1.0 1.0 1.0"/>
            </material>
        </visual>
        <collision>
            <origin xyz="1.173431520203858 0 1.417747143395338" rpy="0 0 0"/>
            <geometry>
                <box size="2.346863040407716 1.6391452833357472 2.835494286790676" />
            </geometry>
        </collision>
    </link>
    <link name="Leg20">
        <inertial>
            <origin xyz="0 0 0.7526027914064071" rpy="0 0 0"/>
            <mass value="1" />
            <inertia ixx="100" ixy="0" ixz="0" iyy="100" iyz="0" izz="100" />
        </inertial>
        <visual>
            <origin xyz="0 0 0.7526027914064071" rpy="0 0 0"/>
            <geometry>
                <box size="1.4617508155076395 2.9535648988449177 1.5052055828128141" />
            </geometry>
            <material name="Blue">
                <color rgba="0 1.0 1.0 1.0"/>
            </material>
        </visual>
        <collision>
            <origin xyz="0 0 0.7526027914064071" rpy="0 0 0"/>
            <geometry>
                <box size="1.4617508155076395 2.9535648988449177 1.5052055828128141" />
            </geometry>
        </collision>
    </link>
    <link name="Leg21">
        <inertial>
            <origin xyz="0.6702071792386656 0 0" rpy="0 0 0"/>
            <mass value="1" />
            <inertia ixx="100" ixy="0" ixz="0" iyy="100" iyz="0" izz="100" />
        </inertial>
        <visual>
            <origin xyz="0.6702071792386656 0 0" rpy="0 0 0"/>
            <geometry>
                <box size="1.3404143584773311 1.3967193956075834 2.4104792230893173" />
            </geometry>
            <material name="Blue">
                <color rgba="0 1.0 1.0 1.0"/>
            </material>
        </visual>
        <collision>
            <origin xyz="0.6702071792386656 0 0" rpy="0 0 0"/>
            <geometry>
                <box size="1.3404143584773311 1.3967193956075834 2.4104792230893173" />
            </geometry>
        </collision>
    </link>
    <link name="Leg22">
        <inertial>
            <origin xyz="0 0 1.4936325449416181" rpy="0 0 0"/>
            <mass value="1" />
            <inertia ixx="100" ixy="0" ixz="0" iyy="100" iyz="0" izz="100" />
        </inertial>
        <visual>
            <origin xyz="0 0 1.4936325449416181" rpy="0 0 0"/>
            <geometry>
                <box size="1.64864465597001 2.7955327322215497 1.4936325449416181" />
            </geometry>
            <material name="Blue">
                <color rgba="0 1.0 1.0 1.0"/>
            </material>
        </visual>
        <collision>
            <origin xyz="0 0 1.4936325449416181" rpy="0 0 0"/>
            <geometry>
                <box size="1.64864465597001 2.7955327322215497 1.4936325449416181" />
            </geometry>
        </collision>
    </link>
    <link name="Leg23">
        <inertial>
            <origin xyz="0 0 0.7396554269955203" rpy="0 0 0"/>
            <mass value="1" />
            <inertia ixx="100" ixy="0" ixz="0" iyy="100" iyz="0" izz="100" />
        </inertial>
        <visual>
            <origin xyz="0 0 0.7396554269955203" rpy="0 0 0"/>
            <geometry>
                <box size="2.986622863069018 1.2707762422860736 1.4793108539910407" />
            </geometry>
            <material name="Blue">
                <color rgba="0 1.0 1.0 1.0"/>
            </material>
        </visual>
        <collision>
            <origin xyz="0 0 0.7396554269955203" rpy="0 0 0"/>
            <geometry>
                <box size="2.986622863069018 1.2707762422860736 1.4793108539910407" />
            </geometry>
        </collision>
    </link>
    <link name="Leg24">
        <inertial>
            <origin xyz="1.4558572903772378 0 0" rpy="0 0 0"/>
            <mass value="1" />
            <inertia ixx="100" ixy="0" ixz="0" iyy="100" iyz="0" izz="100" />
        </inertial>
        <visual>
            <origin xyz="1.4558572903772378 0 0" rpy="0 0 0"/>
            <geometry>
                <box size="2.9117145807544755 2.877245395003838 1.3964987413428436" />
            </geometry>
            <material name="Blue">
                <color rgba="0 1.0 1.0 1.0"/>
            </material>
        </visual>
        <collision>
            <origin xyz="1.4558572903772378 0 0" rpy="0 0 0"/>
            <geometry>
                <box size="2.9117145807544755 2.877245395003838 1.3964987413428436" />
            </geometry>
        </collision>
    </link>
    <link name="Leg25">
        <inertial>
            <origin xyz="0 0 1.3168636343944484" rpy="0 0 0"/>
            <mass value="1" />
            <inertia ixx="100" ixy="0" ixz="0" iyy="100" iyz="0" izz="100" />
        </inertial>
        <visual>
            <origin xyz="0 0 1.3168636343944484" rpy="0 0 0"/>
            <geometry>
                <box size="2.1487435906184116 1.2769034631374436 2.633727268788897" />
            </geometry>
            <material name="Blue">
                <color rgba="0 1.0 1.0 1.0"/>
            </material>
        </visual>
        <collision>
            <origin xyz="0 0 1.3168636343944484" rpy="0 0 0"/>
            <geometry>
                <box size="2.1487435906184116 1.2769034631374436 2.633727268788897" />
            </geometry>
        </collision>
    </link>
    <link name="Leg26">
        <inertial>
            <origin xyz="0 0 0.6667180004349589" rpy="0 0 0"/>
            <mass value="1" />
            <inertia ixx="100" ixy="0" ixz="0" iyy="100" iyz="0" izz="100" />
        </inertial>
        <visual>
            <origin xyz="0 0 0.6667180004349589" rpy="0 0 0"/>
            <geometry>
                <box size="1.7637473397607402 1.8032192848820767 1.3334360008699178" />
            </geometry>
            <material name="Green">
                <color rgba="0 180.0 100.0 1.0"/>
            </material>
        </visual>
        <collision>
            <origin xyz="0 0 0.6667180004349589" rpy="0 0 0"/>
            <geometry>
                <box size="1.7637473397607402 1.8032192848820767 1.3334360008699178" />
            </geometry>
        </collision>
    </link>
    <joint name="Torso_Leg1" type="revolute">
       <parent link="Torso"/>
       <child  link="Leg1"/>
       <origin rpy="0 0 0" xyz="0 0 2.354929103049636" />
     <axis xyz="1 0 0"/>
       <limit effort="0.0" lower="-3.14159" upper="3.14159" velocity="0.0"/>
    </joint>
    <joint name="Leg1_Leg2" type="revolute">
       <parent link="Leg1"/>
       <child  link="Leg2"/>
       <origin rpy="0 0 0" xyz="0 1.42305997755363 2.7648523270579393" />
     <axis xyz="1 0 0"/>
       <limit effort="0.0" lower="-3.14159" upper="3.14159" velocity="0.0"/>
    </joint>
    <joint name="Leg2_Leg3" type="revolute">
       <parent link="Leg2"/>
       <child  link="Leg3"/>
       <origin rpy="0 0 0" xyz="0.8936808910185349 1.404710110518075 2.3633119622009113" />
     <axis xyz="1 0 0"/>
       <limit effort="0.0" lower="-3.14159" upper="3.14159" velocity="0.0"/>
    </joint>
    <joint name="Torso_Leg4" type="revolute">
       <parent link="Torso"/>
       <child  link="Leg4"/>
       <origin rpy="0 0 0" xyz="0.5470353881818245 1.2397681843396675 1.3346069032550227" />
     <axis xyz="1 0 0"/>
       <limit effort="0.0" lower="-3.14159" upper="3.14159" velocity="0.0"/>
    </joint>
    <joint name="Leg4_Leg5" type="revolute">
       <parent link="Leg4"/>
       <child  link="Leg5"/>
       <origin rpy="0 0 0" xyz="0 2.74257915015386 1.1699060148896816" />
     <axis xyz="1 0 0"/>
       <limit effort="0.0" lower="-3.14159" upper="3.14159" velocity="0.0"/>
    </joint>
    <joint name="Leg2_Leg6" type="revolute">
       <parent link="Leg2"/>
       <child  link="Leg6"/>
       <origin rpy="0 0 0" xyz="0.8936808910185349 1.404710110518075 2.3633119622009113" />
     <axis xyz="1 0 0"/>
       <limit effort="0.0" lower="-3.14159" upper="3.14159" velocity="0.0"/>
    </joint>
    <joint name="Leg4_Leg7" type="revolute">
       <parent link="Leg4"/>
       <child  link="Leg7"/>
       <origin rpy="0 0 0" xyz="0 2.74257915015386 1.1699060148896816" />
     <axis xyz="1 0 0"/>
       <limit effort="0.0" lower="-3.14159" upper="3.14159" velocity="0.0"/>
    </joint>
    <joint name="Leg7_Leg8" type="revolute">
       <parent link="Leg7"/>
       <child  link="Leg8"/>
       <origin rpy="0 0 0" xyz="0 0 1.3682016709518958" />
     <axis xyz="1 0 0"/>
       <limit effort="0.0" lower="-3.14159" upper="3.14159" velocity="0.0"/>
    </joint>
    <joint name="Leg2_Leg9" type="revolute">
       <parent link="Leg2"/>
       <child  link="Leg9"/>
       <origin rpy="0 0 0" xyz="0.8936808910185349 1.404710110518075 2.3633119622009113" />
     <axis xyz="1 0 0"/>
       <limit effort="0.0" lower="-3.14159" upper="3.14159" velocity="0.0"/>
    </joint>
    <joint name="Leg6_Leg10" type="revolute">
       <parent link="Leg6"/>
       <child  link="Leg10"/>
       <origin rpy="0 0 0" xyz="0.9355377330775843 1.1800125298494843 2.8103180751635373" />
     <axis xyz="1 0 0"/>
       <limit effort="0.0" lower="-3.14159" upper="3.14159" velocity="0.0"/>
    </joint>
    <joint name="Leg10_Leg11" type="revolute">
       <parent link="Leg10"/>
       <child  link="Leg11"/>
       <origin rpy="0 0 0" xyz="0 1.383456670057143 2.508002406073521" />
     <axis xyz="1 0 0"/>
       <limit effort="0.0" lower="-3.14159" upper="3.14159" velocity="0.0"/>
    </joint>
    <joint name="Leg6_Leg12" type="revolute">
       <parent link="Leg6"/>
       <child  link="Leg12"/>
       <origin rpy="0 0 0" xyz="0.9355377330775843 1.1800125298494843 2.8103180751635373" />
     <axis xyz="1 0 0"/>
       <limit effort="0.0" lower="-3.14159" upper="3.14159" velocity="0.0"/>
    </joint>
    <joint name="Leg3_Leg13" type="revolute">
       <parent link="Leg3"/>
       <child  link="Leg13"/>
       <origin rpy="0 0 0" xyz="0 1.9299253223046957 0" />
     <axis xyz="1 0 0"/>
       <limit effort="0.0" lower="-3.14159" upper="3.14159" velocity="0.0"/>
    </joint>
    <joint name="Leg1_Leg14" type="revolute">
       <parent link="Leg1"/>
       <child  link="Leg14"/>
       <origin rpy="0 0 0" xyz="0 1.42305997755363 2.7648523270579393" />
     <axis xyz="1 0 0"/>
       <limit effort="0.0" lower="-3.14159" upper="3.14159" velocity="0.0"/>
    </joint>
    <joint name="Leg6_Leg15" type="revolute">
       <parent link="Leg6"/>
       <child  link="Leg15"/>
       <origin rpy="0 0 0" xyz="0.9355377330775843 1.1800125298494843 2.8103180751635373" />
     <axis xyz="1 0 0"/>
       <limit effort="0.0" lower="-3.14159" upper="3.14159" velocity="0.0"/>
    </joint>
    <joint name="Leg10_Leg16" type="revolute">
       <parent link="Leg10"/>
       <child  link="Leg16"/>
       <origin rpy="0 0 0" xyz="0 1.383456670057143 2.508002406073521" />
     <axis xyz="1 0 0"/>
       <limit effort="0.0" lower="-3.14159" upper="3.14159" velocity="0.0"/>
    </joint>
    <joint name="Leg13_Leg17" type="revolute">
       <parent link="Leg13"/>
       <child  link="Leg17"/>
       <origin rpy="0 0 0" xyz="1.2279413473814629 1.7356514676967307 1.3974374572628627" />
     <axis xyz="1 0 0"/>
       <limit effort="0.0" lower="-3.14159" upper="3.14159" velocity="0.0"/>
    </joint>
    <joint name="Torso_Leg18" type="revolute">
       <parent link="Torso"/>
       <child  link="Leg18"/>
       <origin rpy="0 0 0" xyz="0.5470353881818245 1.2397681843396675 1.3346069032550227" />
     <axis xyz="1 0 0"/>
       <limit effort="0.0" lower="-3.14159" upper="3.14159" velocity="0.0"/>
    </joint>
    <joint name="Leg16_Leg19" type="revolute">
       <parent link="Leg16"/>
       <child  link="Leg19"/>
       <origin rpy="0 0 0" xyz="1.3133292585298513 0.9133991481680089 0" />
     <axis xyz="1 0 0"/>
       <limit effort="0.0" lower="-3.14159" upper="3.14159" velocity="0.0"/>
    </joint>
    <joint name="Leg14_Leg20" type="revolute">
       <parent link="Leg14"/>
       <child  link="Leg20"/>
       <origin rpy="0 0 0" xyz="0 0 1.226200116525412" />
     <axis xyz="1 0 0"/>
       <limit effort="0.0" lower="-3.14159" upper="3.14159" velocity="0.0"/>
    </joint>
    <joint name="Leg13_Leg21" type="revolute">
       <parent link="Leg13"/>
       <child  link="Leg21"/>
       <origin rpy="0 0 0" xyz="1.2279413473814629 1.7356514676967307 1.3974374572628627" />
     <axis xyz="1 0 0"/>
       <limit effort="0.0" lower="-3.14159" upper="3.14159" velocity="0.0"/>
    </joint>
    <joint name="Leg21_Leg22" type="revolute">
       <parent link="Leg21"/>
       <child  link="Leg22"/>
       <origin rpy="0 0 0" xyz="0 0 1.4936325449416181" />
     <axis xyz="1 0 0"/>
       <limit effort="0.0" lower="-3.14159" upper="3.14159" velocity="0.0"/>
    </joint>
    <joint name="Leg18_Leg23" type="revolute">
       <parent link="Leg18"/>
       <child  link="Leg23"/>
       <origin rpy="0 0 0" xyz="1.173431520203858 0 1.417747143395338" />
     <axis xyz="1 0 0"/>
       <limit effort="0.0" lower="-3.14159" upper="3.14159" velocity="0.0"/>
    </joint>
    <joint name="Leg17_Leg24" type="revolute">
       <parent link="Leg17"/>
       <child  link="Leg24"/>
       <origin rpy="0 0 0" xyz="1.080650708073664 0 0" />
     <axis xyz="1 0 0"/>
       <limit effort="0.0" lower="-3.14159" upper="3.14159" velocity="0.0"/>
    </joint>
    <joint name="Leg13_Leg25" type="revolute">
       <parent link="Leg13"/>
       <child  link="Leg25"/>
       <origin rpy="0 0 0" xyz="1.2279413473814629 1.7356514676967307 1.3974374572628627" />
     <axis xyz="1 0 0"/>
       <limit effort="0.0" lower="-3.14159" upper="3.14159" velocity="0.0"/>
    </joint>
    <joint name="Leg25_Leg26" type="revolute">
       <parent link="Leg25"/>
       <child  link="Leg25"/>
       <origin rpy="0 0 0" xyz="0 0 2.633727268788897" />
     <axis xyz="1 0 0"/>
       <limit effort="0.0" lower="-3.14159" upper="3.14159" velocity="0.0"/>
    </joint>
</robot>