<robot name = "robot">
    <link name="Torso">
        <inertial>
            <origin xyz="0 0 0.9455191927723858" rpy="0 0 0"/>
            <mass value="1" />
            <inertia ixx="100" ixy="0" ixz="0" iyy="100" iyz="0" izz="100" />
        </inertial>
        <visual>
            <origin xyz="0 0 0.9455191927723858" rpy="0 0 0"/>
            <geometry>
                <box size="1.7816769183900194 1.4952728714486623 1.8910383855447717" />
            </geometry>
            <material name="Green">
                <color rgba="0 180.0 0.0 1.0"/>
            </material>
        </visual>
        <collision>
            <origin xyz="0 0 0.9455191927723858" rpy="0 0 0"/>
            <geometry>
                <box size="1.7816769183900194 1.4952728714486623 1.8910383855447717" />
            </geometry>
        </collision>
    </link>
    <link name="Leg1">
        <inertial>
            <origin xyz="0.7820599986524065 0 0" rpy="0 0 0"/>
            <mass value="1" />
            <inertia ixx="100" ixy="0" ixz="0" iyy="100" iyz="0" izz="100" />
        </inertial>
        <visual>
            <origin xyz="0.7820599986524065 0 0" rpy="0 0 0"/>
            <geometry>
                <box size="1.564119997304813 2.861239936523422 1.4039055632275197" />
            </geometry>
            <material name="Green">
                <color rgba="0 180.0 0.0 1.0"/>
            </material>
        </visual>
        <collision>
            <origin xyz="0.7820599986524065 0 0" rpy="0 0 0"/>
            <geometry>
                <box size="1.564119997304813 2.861239936523422 1.4039055632275197" />
            </geometry>
        </collision>
    </link>
    <link name="Leg2">
        <inertial>
            <origin xyz="0 0.9911290128983686 0" rpy="0 0 0"/>
            <mass value="1" />
            <inertia ixx="100" ixy="0" ixz="0" iyy="100" iyz="0" izz="100" />
        </inertial>
        <visual>
            <origin xyz="0 0.9911290128983686 0" rpy="0 0 0"/>
            <geometry>
                <box size="1.2273328968461525 1.9822580257967373 1.6511486544495555" />
            </geometry>
            <material name="Blue">
                <color rgba="0 1.0 1.0 1.0"/>
            </material>
        </visual>
        <collision>
            <origin xyz="0 0.9911290128983686 0" rpy="0 0 0"/>
            <geometry>
                <box size="1.2273328968461525 1.9822580257967373 1.6511486544495555" />
            </geometry>
        </collision>
    </link>
    <link name="Leg3">
        <inertial>
            <origin xyz="1.0787365330321712 0 0" rpy="0 0 0"/>
            <mass value="1" />
            <inertia ixx="100" ixy="0" ixz="0" iyy="100" iyz="0" izz="100" />
        </inertial>
        <visual>
            <origin xyz="1.0787365330321712 0 0" rpy="0 0 0"/>
            <geometry>
                <box size="2.1574730660643424 1.3742154731081495 2.2650734301773308" />
            </geometry>
            <material name="Green">
                <color rgba="0 180.0 0.0 1.0"/>
            </material>
        </visual>
        <collision>
            <origin xyz="1.0787365330321712 0 0" rpy="0 0 0"/>
            <geometry>
                <box size="2.1574730660643424 1.3742154731081495 2.2650734301773308" />
            </geometry>
        </collision>
    </link>
    <link name="Leg4">
        <inertial>
            <origin xyz="1.417954460587291 0 0" rpy="0 0 0"/>
            <mass value="1" />
            <inertia ixx="100" ixy="0" ixz="0" iyy="100" iyz="0" izz="100" />
        </inertial>
        <visual>
            <origin xyz="1.417954460587291 0 0" rpy="0 0 0"/>
            <geometry>
                <box size="2.835908921174582 1.1472178782685067 1.2213541289131091" />
            </geometry>
            <material name="Green">
                <color rgba="0 180.0 0.0 1.0"/>
            </material>
        </visual>
        <collision>
            <origin xyz="1.417954460587291 0 0" rpy="0 0 0"/>
            <geometry>
                <box size="2.835908921174582 1.1472178782685067 1.2213541289131091" />
            </geometry>
        </collision>
    </link>
    <link name="Leg5">
        <inertial>
            <origin xyz="0 0 0.8453329140890927" rpy="0 0 0"/>
            <mass value="1" />
            <inertia ixx="100" ixy="0" ixz="0" iyy="100" iyz="0" izz="100" />
        </inertial>
        <visual>
            <origin xyz="0 0 0.8453329140890927" rpy="0 0 0"/>
            <geometry>
                <box size="1.5182724066178643 1.606287941360229 1.6906658281781854" />
            </geometry>
            <material name="Blue">
                <color rgba="0 1.0 1.0 1.0"/>
            </material>
        </visual>
        <collision>
            <origin xyz="0 0 0.8453329140890927" rpy="0 0 0"/>
            <geometry>
                <box size="1.5182724066178643 1.606287941360229 1.6906658281781854" />
            </geometry>
        </collision>
    </link>
    <link name="Leg6">
        <inertial>
            <origin xyz="1.112662369781555 0 0" rpy="0 0 0"/>
            <mass value="1" />
            <inertia ixx="100" ixy="0" ixz="0" iyy="100" iyz="0" izz="100" />
        </inertial>
        <visual>
            <origin xyz="1.112662369781555 0 0" rpy="0 0 0"/>
            <geometry>
                <box size="2.22532473956311 1.3693174148099565 1.2467733442370015" />
            </geometry>
            <material name="Green">
                <color rgba="0 180.0 0.0 1.0"/>
            </material>
        </visual>
        <collision>
            <origin xyz="1.112662369781555 0 0" rpy="0 0 0"/>
            <geometry>
                <box size="2.22532473956311 1.3693174148099565 1.2467733442370015" />
            </geometry>
        </collision>
    </link>
    <link name="Leg7">
        <inertial>
            <origin xyz="0 0.6279650244886849 0" rpy="0 0 0"/>
            <mass value="1" />
            <inertia ixx="100" ixy="0" ixz="0" iyy="100" iyz="0" izz="100" />
        </inertial>
        <visual>
            <origin xyz="0 0.6279650244886849 0" rpy="0 0 0"/>
            <geometry>
                <box size="1.9103289908929955 1.2559300489773697 1.7827257923705324" />
            </geometry>
            <material name="Green">
                <color rgba="0 180.0 0.0 1.0"/>
            </material>
        </visual>
        <collision>
            <origin xyz="0 0.6279650244886849 0" rpy="0 0 0"/>
            <geometry>
                <box size="1.9103289908929955 1.2559300489773697 1.7827257923705324" />
            </geometry>
        </collision>
    </link>
    <link name="Leg8">
        <inertial>
            <origin xyz="1.4625840919465265 0 0" rpy="0 0 0"/>
            <mass value="1" />
            <inertia ixx="100" ixy="0" ixz="0" iyy="100" iyz="0" izz="100" />
        </inertial>
        <visual>
            <origin xyz="1.4625840919465265 0 0" rpy="0 0 0"/>
            <geometry>
                <box size="2.925168183893053 1.4751715492842514 2.4466791350632464" />
            </geometry>
            <material name="Green">
                <color rgba="0 180.0 0.0 1.0"/>
            </material>
        </visual>
        <collision>
            <origin xyz="1.4625840919465265 0 0" rpy="0 0 0"/>
            <geometry>
                <box size="2.925168183893053 1.4751715492842514 2.4466791350632464" />
            </geometry>
        </collision>
    </link>
    <link name="Leg9">
        <inertial>
            <origin xyz="0 0.8574867600952124 0" rpy="0 0 0"/>
            <mass value="1" />
            <inertia ixx="100" ixy="0" ixz="0" iyy="100" iyz="0" izz="100" />
        </inertial>
        <visual>
            <origin xyz="0 0.8574867600952124 0" rpy="0 0 0"/>
            <geometry>
                <box size="2.847590197045459 1.7149735201904248 1.073399292358921" />
            </geometry>
            <material name="Green">
                <color rgba="0 180.0 0.0 1.0"/>
            </material>
        </visual>
        <collision>
            <origin xyz="0 0.8574867600952124 0" rpy="0 0 0"/>
            <geometry>
                <box size="2.847590197045459 1.7149735201904248 1.073399292358921" />
            </geometry>
        </collision>
    </link>
    <link name="Leg10">
        <inertial>
            <origin xyz="0 1.1729911152463668 0" rpy="0 0 0"/>
            <mass value="1" />
            <inertia ixx="100" ixy="0" ixz="0" iyy="100" iyz="0" izz="100" />
        </inertial>
        <visual>
            <origin xyz="0 1.1729911152463668 0" rpy="0 0 0"/>
            <geometry>
                <box size="1.3515051477882591 2.3459822304927336 2.425751428192503" />
            </geometry>
            <material name="Blue">
                <color rgba="0 1.0 1.0 1.0"/>
            </material>
        </visual>
        <collision>
            <origin xyz="0 1.1729911152463668 0" rpy="0 0 0"/>
            <geometry>
                <box size="1.3515051477882591 2.3459822304927336 2.425751428192503" />
            </geometry>
        </collision>
    </link>
    <link name="Leg11">
        <inertial>
            <origin xyz="0.7567509862563436 0 0" rpy="0 0 0"/>
            <mass value="1" />
            <inertia ixx="100" ixy="0" ixz="0" iyy="100" iyz="0" izz="100" />
        </inertial>
        <visual>
            <origin xyz="0.7567509862563436 0 0" rpy="0 0 0"/>
            <geometry>
                <box size="1.5135019725126873 2.9425991262289664 2.475238214792852" />
            </geometry>
            <material name="Green">
                <color rgba="0 180.0 0.0 1.0"/>
            </material>
        </visual>
        <collision>
            <origin xyz="0.7567509862563436 0 0" rpy="0 0 0"/>
            <geometry>
                <box size="1.5135019725126873 2.9425991262289664 2.475238214792852" />
            </geometry>
        </collision>
    </link>
    <link name="Leg12">
        <inertial>
            <origin xyz="0 0 0.9202445707135173" rpy="0 0 0"/>
            <mass value="1" />
            <inertia ixx="100" ixy="0" ixz="0" iyy="100" iyz="0" izz="100" />
        </inertial>
        <visual>
            <origin xyz="0 0 0.9202445707135173" rpy="0 0 0"/>
            <geometry>
                <box size="1.6769940611972716 1.5305725871231248 1.8404891414270346" />
            </geometry>
            <material name="Green">
                <color rgba="0 180.0 0.0 1.0"/>
            </material>
        </visual>
        <collision>
            <origin xyz="0 0 0.9202445707135173" rpy="0 0 0"/>
            <geometry>
                <box size="1.6769940611972716 1.5305725871231248 1.8404891414270346" />
            </geometry>
        </collision>
    </link>
    <link name="Leg13">
        <inertial>
            <origin xyz="0.825584208877321 0 0" rpy="0 0 0"/>
            <mass value="1" />
            <inertia ixx="100" ixy="0" ixz="0" iyy="100" iyz="0" izz="100" />
        </inertial>
        <visual>
            <origin xyz="0.825584208877321 0 0" rpy="0 0 0"/>
            <geometry>
                <box size="1.651168417754642 2.066284252738402 1.9966443093651314" />
            </geometry>
            <material name="Blue">
                <color rgba="0 1.0 1.0 1.0"/>
            </material>
        </visual>
        <collision>
            <origin xyz="0.825584208877321 0 0" rpy="0 0 0"/>
            <geometry>
                <box size="1.651168417754642 2.066284252738402 1.9966443093651314" />
            </geometry>
        </collision>
    </link>
    <link name="Leg14">
        <inertial>
            <origin xyz="0 0.96270360978357 0" rpy="0 0 0"/>
            <mass value="1" />
            <inertia ixx="100" ixy="0" ixz="0" iyy="100" iyz="0" izz="100" />
        </inertial>
        <visual>
            <origin xyz="0 0.96270360978357 0" rpy="0 0 0"/>
            <geometry>
                <box size="1.930330259598692 1.92540721956714 1.2413582958153528" />
            </geometry>
            <material name="Blue">
                <color rgba="0 1.0 1.0 1.0"/>
            </material>
        </visual>
        <collision>
            <origin xyz="0 0.96270360978357 0" rpy="0 0 0"/>
            <geometry>
                <box size="1.930330259598692 1.92540721956714 1.2413582958153528" />
            </geometry>
        </collision>
    </link>
    <link name="Leg15">
        <inertial>
            <origin xyz="0 0 0.5744264934443986" rpy="0 0 0"/>
            <mass value="1" />
            <inertia ixx="100" ixy="0" ixz="0" iyy="100" iyz="0" izz="100" />
        </inertial>
        <visual>
            <origin xyz="0 0 0.5744264934443986" rpy="0 0 0"/>
            <geometry>
                <box size="1.4791346816984303 1.4562685595168947 1.1488529868887971" />
            </geometry>
            <material name="Blue">
                <color rgba="0 1.0 1.0 1.0"/>
            </material>
        </visual>
        <collision>
            <origin xyz="0 0 0.5744264934443986" rpy="0 0 0"/>
            <geometry>
                <box size="1.4791346816984303 1.4562685595168947 1.1488529868887971" />
            </geometry>
        </collision>
    </link>
    <link name="Leg16">
        <inertial>
            <origin xyz="0 1.045173668479139 0" rpy="0 0 0"/>
            <mass value="1" />
            <inertia ixx="100" ixy="0" ixz="0" iyy="100" iyz="0" izz="100" />
        </inertial>
        <visual>
            <origin xyz="0 1.045173668479139 0" rpy="0 0 0"/>
            <geometry>
                <box size="1.1442854330052445 2.090347336958278 1.6212953664815353" />
            </geometry>
            <material name="Blue">
                <color rgba="0 1.0 1.0 1.0"/>
            </material>
        </visual>
        <collision>
            <origin xyz="0 1.045173668479139 0" rpy="0 0 0"/>
            <geometry>
                <box size="1.1442854330052445 2.090347336958278 1.6212953664815353" />
            </geometry>
        </collision>
    </link>
    <link name="Leg17">
        <inertial>
            <origin xyz="0 0 0.5326503313005622" rpy="0 0 0"/>
            <mass value="1" />
            <inertia ixx="100" ixy="0" ixz="0" iyy="100" iyz="0" izz="100" />
        </inertial>
        <visual>
            <origin xyz="0 0 0.5326503313005622" rpy="0 0 0"/>
            <geometry>
                <box size="1.6051640905473086 1.2786560740906696 1.0653006626011243" />
            </geometry>
            <material name="Green">
                <color rgba="0 180.0 0.0 1.0"/>
            </material>
        </visual>
        <collision>
            <origin xyz="0 0 0.5326503313005622" rpy="0 0 0"/>
            <geometry>
                <box size="1.6051640905473086 1.2786560740906696 1.0653006626011243" />
            </geometry>
        </collision>
    </link>
    <link name="Leg18">
        <inertial>
            <origin xyz="0 0.9993496623676406 0" rpy="0 0 0"/>
            <mass value="1" />
            <inertia ixx="100" ixy="0" ixz="0" iyy="100" iyz="0" izz="100" />
        </inertial>
        <visual>
            <origin xyz="0 0.9993496623676406 0" rpy="0 0 0"/>
            <geometry>
                <box size="1.0260757397061666 1.9986993247352811 2.839258480506831" />
            </geometry>
            <material name="Green">
                <color rgba="0 180.0 0.0 1.0"/>
            </material>
        </visual>
        <collision>
            <origin xyz="0 0.9993496623676406 0" rpy="0 0 0"/>
            <geometry>
                <box size="1.0260757397061666 1.9986993247352811 2.839258480506831" />
            </geometry>
        </collision>
    </link>
    <link name="Leg19">
        <inertial>
            <origin xyz="0.9618629699320891 0 0" rpy="0 0 0"/>
            <mass value="1" />
            <inertia ixx="100" ixy="0" ixz="0" iyy="100" iyz="0" izz="100" />
        </inertial>
        <visual>
            <origin xyz="0.9618629699320891 0 0" rpy="0 0 0"/>
            <geometry>
                <box size="1.9237259398641782 1.652647923429632 2.9610138751562274" />
            </geometry>
            <material name="Green">
                <color rgba="0 180.0 0.0 1.0"/>
            </material>
        </visual>
        <collision>
            <origin xyz="0.9618629699320891 0 0" rpy="0 0 0"/>
            <geometry>
                <box size="1.9237259398641782 1.652647923429632 2.9610138751562274" />
            </geometry>
        </collision>
    </link>
    <link name="Leg20">
        <inertial>
            <origin xyz="1.4999976661165695 0 0" rpy="0 0 0"/>
            <mass value="1" />
            <inertia ixx="100" ixy="0" ixz="0" iyy="100" iyz="0" izz="100" />
        </inertial>
        <visual>
            <origin xyz="1.4999976661165695 0 0" rpy="0 0 0"/>
            <geometry>
                <box size="2.999995332233139 2.956244376993315 1.560152801056713" />
            </geometry>
            <material name="Green">
                <color rgba="0 180.0 0.0 1.0"/>
            </material>
        </visual>
        <collision>
            <origin xyz="1.4999976661165695 0 0" rpy="0 0 0"/>
            <geometry>
                <box size="2.999995332233139 2.956244376993315 1.560152801056713" />
            </geometry>
        </collision>
    </link>
    <link name="Leg21">
        <inertial>
            <origin xyz="0 0 0.7433490440519698" rpy="0 0 0"/>
            <mass value="1" />
            <inertia ixx="100" ixy="0" ixz="0" iyy="100" iyz="0" izz="100" />
        </inertial>
        <visual>
            <origin xyz="0 0 0.7433490440519698" rpy="0 0 0"/>
            <geometry>
                <box size="1.1375351954341442 1.527971961992396 1.4866980881039396" />
            </geometry>
            <material name="Green">
                <color rgba="0 180.0 0.0 1.0"/>
            </material>
        </visual>
        <collision>
            <origin xyz="0 0 0.7433490440519698" rpy="0 0 0"/>
            <geometry>
                <box size="1.1375351954341442 1.527971961992396 1.4866980881039396" />
            </geometry>
        </collision>
    </link>
    <link name="Leg22">
        <inertial>
            <origin xyz="0 0 0.6158913336301858" rpy="0 0 0"/>
            <mass value="1" />
            <inertia ixx="100" ixy="0" ixz="0" iyy="100" iyz="0" izz="100" />
        </inertial>
        <visual>
            <origin xyz="0 0 0.6158913336301858" rpy="0 0 0"/>
            <geometry>
                <box size="1.575245515538183 2.897745793311204 1.2317826672603716" />
            </geometry>
            <material name="Green">
                <color rgba="0 180.0 0.0 1.0"/>
            </material>
        </visual>
        <collision>
            <origin xyz="0 0 0.6158913336301858" rpy="0 0 0"/>
            <geometry>
                <box size="1.575245515538183 2.897745793311204 1.2317826672603716" />
            </geometry>
        </collision>
    </link>
    <link name="Leg23">
        <inertial>
            <origin xyz="1.2919123577830245 0 0" rpy="0 0 0"/>
            <mass value="1" />
            <inertia ixx="100" ixy="0" ixz="0" iyy="100" iyz="0" izz="100" />
        </inertial>
        <visual>
            <origin xyz="1.2919123577830245 0 0" rpy="0 0 0"/>
            <geometry>
                <box size="2.583824715566049 1.217461882011271 1.8524887489898954" />
            </geometry>
            <material name="Green">
                <color rgba="0 180.0 0.0 1.0"/>
            </material>
        </visual>
        <collision>
            <origin xyz="1.2919123577830245 0 0" rpy="0 0 0"/>
            <geometry>
                <box size="2.583824715566049 1.217461882011271 1.8524887489898954" />
            </geometry>
        </collision>
    </link>
    <link name="Leg24">
        <inertial>
            <origin xyz="0 0 1.4444145967140325" rpy="0 0 0"/>
            <mass value="1" />
            <inertia ixx="100" ixy="0" ixz="0" iyy="100" iyz="0" izz="100" />
        </inertial>
        <visual>
            <origin xyz="0 0 1.4444145967140325" rpy="0 0 0"/>
            <geometry>
                <box size="1.556029163643832 2.6227031282812314 2.888829193428065" />
            </geometry>
            <material name="Blue">
                <color rgba="0 1.0 1.0 1.0"/>
            </material>
        </visual>
        <collision>
            <origin xyz="0 0 1.4444145967140325" rpy="0 0 0"/>
            <geometry>
                <box size="1.556029163643832 2.6227031282812314 2.888829193428065" />
            </geometry>
        </collision>
    </link>
    <link name="Leg25">
        <inertial>
            <origin xyz="0 1.3481016409587618 0" rpy="0 0 0"/>
            <mass value="1" />
            <inertia ixx="100" ixy="0" ixz="0" iyy="100" iyz="0" izz="100" />
        </inertial>
        <visual>
            <origin xyz="0 1.3481016409587618 0" rpy="0 0 0"/>
            <geometry>
                <box size="2.5282522756828403 2.6962032819175237 2.9567553365345844" />
            </geometry>
            <material name="Green">
                <color rgba="0 180.0 0.0 1.0"/>
            </material>
        </visual>
        <collision>
            <origin xyz="0 1.3481016409587618 0" rpy="0 0 0"/>
            <geometry>
                <box size="2.5282522756828403 2.6962032819175237 2.9567553365345844" />
            </geometry>
        </collision>
    </link>
    <link name="Leg26">
        <inertial>
            <origin xyz="0 1.0063958641292428 0" rpy="0 0 0"/>
            <mass value="1" />
            <inertia ixx="100" ixy="0" ixz="0" iyy="100" iyz="0" izz="100" />
        </inertial>
        <visual>
            <origin xyz="0 1.0063958641292428 0" rpy="0 0 0"/>
            <geometry>
                <box size="2.336674003361674 2.0127917282584855 2.573556467829073" />
            </geometry>
            <material name="Green">
                <color rgba="0 180.0 0.0 1.0"/>
            </material>
        </visual>
        <collision>
            <origin xyz="0 1.0063958641292428 0" rpy="0 0 0"/>
            <geometry>
                <box size="2.336674003361674 2.0127917282584855 2.573556467829073" />
            </geometry>
        </collision>
    </link>
    <joint name="Torso_Leg1" type="revolute">
       <parent link="Torso"/>
       <child  link="Leg1"/>
       <origin rpy="0 0 0" xyz="0.8908384591950097 0 0.9455191927723858" />
     <axis xyz="1 0 0"/>
       <limit effort="0.0" lower="-3.14159" upper="3.14159" velocity="0.0"/>
    </joint>
    <joint name="Leg1_Leg2" type="revolute">
       <parent link="Leg1"/>
       <child  link="Leg2"/>
       <origin rpy="0 0 0" xyz="0 1.9822580257967373 0" />
     <axis xyz="1 0 0"/>
       <limit effort="0.0" lower="-3.14159" upper="3.14159" velocity="0.0"/>
    </joint>
    <joint name="Leg1_Leg3" type="revolute">
       <parent link="Leg1"/>
       <child  link="Leg3"/>
       <origin rpy="0 0 0" xyz="0.6136664484230763 1.9822580257967373 0" />
     <axis xyz="1 0 0"/>
       <limit effort="0.0" lower="-3.14159" upper="3.14159" velocity="0.0"/>
    </joint>
    <joint name="Leg2_Leg4" type="revolute">
       <parent link="Leg2"/>
       <child  link="Leg4"/>
       <origin rpy="0 0 0" xyz="2.1574730660643424 0 0" />
     <axis xyz="1 0 0"/>
       <limit effort="0.0" lower="-3.14159" upper="3.14159" velocity="0.0"/>
    </joint>
    <joint name="Leg1_Leg5" type="revolute">
       <parent link="Leg1"/>
       <child  link="Leg5"/>
       <origin rpy="0 0 0" xyz="0.6136664484230763 1.9822580257967373 0.8255743272247777" />
     <axis xyz="1 0 0"/>
       <limit effort="0.0" lower="-3.14159" upper="3.14159" velocity="0.0"/>
    </joint>
    <joint name="Leg4_Leg6" type="revolute">
       <parent link="Leg4"/>
       <child  link="Leg6"/>
       <origin rpy="0 0 0" xyz="0.7591362033089322 0 0.8453329140890927" />
     <axis xyz="1 0 0"/>
       <limit effort="0.0" lower="-3.14159" upper="3.14159" velocity="0.0"/>
    </joint>
    <joint name="Leg3_Leg7" type="revolute">
       <parent link="Leg3"/>
       <child  link="Leg7"/>
       <origin rpy="0 0 0" xyz="1.417954460587291 0.5736089391342534 0" />
     <axis xyz="1 0 0"/>
       <limit effort="0.0" lower="-3.14159" upper="3.14159" velocity="0.0"/>
    </joint>
    <joint name="Leg3_Leg8" type="revolute">
       <parent link="Leg3"/>
       <child  link="Leg8"/>
       <origin rpy="0 0 0" xyz="2.835908921174582 0.5736089391342534 0" />
     <axis xyz="1 0 0"/>
       <limit effort="0.0" lower="-3.14159" upper="3.14159" velocity="0.0"/>
    </joint>
    <joint name="Leg8_Leg9" type="revolute">
       <parent link="Leg8"/>
       <child  link="Leg9"/>
       <origin rpy="0 0 0" xyz="0 1.7149735201904248 0" />
     <axis xyz="1 0 0"/>
       <limit effort="0.0" lower="-3.14159" upper="3.14159" velocity="0.0"/>
    </joint>
    <joint name="Leg7_Leg10" type="revolute">
       <parent link="Leg7"/>
       <child  link="Leg10"/>
       <origin rpy="0 0 0" xyz="1.4625840919465265 0.7375857746421257 0" />
     <axis xyz="1 0 0"/>
       <limit effort="0.0" lower="-3.14159" upper="3.14159" velocity="0.0"/>
    </joint>
    <joint name="Leg10_Leg11" type="revolute">
       <parent link="Leg10"/>
       <child  link="Leg11"/>
       <origin rpy="0 0 0" xyz="1.5135019725126873 0 0" />
     <axis xyz="1 0 0"/>
       <limit effort="0.0" lower="-3.14159" upper="3.14159" velocity="0.0"/>
    </joint>
    <joint name="Leg5_Leg12" type="revolute">
       <parent link="Leg5"/>
       <child  link="Leg12"/>
       <origin rpy="0 0 0" xyz="1.112662369781555 0 0.6233866721185007" />
     <axis xyz="1 0 0"/>
       <limit effort="0.0" lower="-3.14159" upper="3.14159" velocity="0.0"/>
    </joint>
    <joint name="Leg8_Leg13" type="revolute">
       <parent link="Leg8"/>
       <child  link="Leg13"/>
       <origin rpy="0 0 0" xyz="1.4237950985227295 1.7149735201904248 0" />
     <axis xyz="1 0 0"/>
       <limit effort="0.0" lower="-3.14159" upper="3.14159" velocity="0.0"/>
    </joint>
    <joint name="Leg13_Leg14" type="revolute">
       <parent link="Leg13"/>
       <child  link="Leg14"/>
       <origin rpy="0 0 0" xyz="0 1.92540721956714 0" />
     <axis xyz="1 0 0"/>
       <limit effort="0.0" lower="-3.14159" upper="3.14159" velocity="0.0"/>
    </joint>
    <joint name="Leg8_Leg15" type="revolute">
       <parent link="Leg8"/>
       <child  link="Leg15"/>
       <origin rpy="0 0 0" xyz="1.4237950985227295 1.7149735201904248 0.5366996461794605" />
     <axis xyz="1 0 0"/>
       <limit effort="0.0" lower="-3.14159" upper="3.14159" velocity="0.0"/>
    </joint>
    <joint name="Leg2_Leg16" type="revolute">
       <parent link="Leg2"/>
       <child  link="Leg16"/>
       <origin rpy="0 0 0" xyz="2.1574730660643424 0.6871077365540748 0" />
     <axis xyz="1 0 0"/>
       <limit effort="0.0" lower="-3.14159" upper="3.14159" velocity="0.0"/>
    </joint>
    <joint name="Leg7_Leg17" type="revolute">
       <parent link="Leg7"/>
       <child  link="Leg17"/>
       <origin rpy="0 0 0" xyz="1.4625840919465265 0.7375857746421257 1.2233395675316232" />
     <axis xyz="1 0 0"/>
       <limit effort="0.0" lower="-3.14159" upper="3.14159" velocity="0.0"/>
    </joint>
    <joint name="Torso_Leg18" type="revolute">
       <parent link="Torso"/>
       <child  link="Leg18"/>
       <origin rpy="0 0 0" xyz="0.7820599986524065 1.430619968261711 0" />
     <axis xyz="1 0 0"/>
       <limit effort="0.0" lower="-3.14159" upper="3.14159" velocity="0.0"/>
    </joint>
    <joint name="Leg11_Leg19" type="revolute">
       <parent link="Leg11"/>
       <child  link="Leg19"/>
       <origin rpy="0 0 0" xyz="0.8384970305986358 0 0.9202445707135173" />
     <axis xyz="1 0 0"/>
       <limit effort="0.0" lower="-3.14159" upper="3.14159" velocity="0.0"/>
    </joint>
    <joint name="Leg15_Leg20" type="revolute">
       <parent link="Leg15"/>
       <child  link="Leg20"/>
       <origin rpy="0 0 0" xyz="0.5721427165026223 1.045173668479139 0" />
     <axis xyz="1 0 0"/>
       <limit effort="0.0" lower="-3.14159" upper="3.14159" velocity="0.0"/>
    </joint>
    <joint name="Leg17_Leg21" type="revolute">
       <parent link="Leg17"/>
       <child  link="Leg21"/>
       <origin rpy="0 0 0" xyz="0 0.9993496623676406 1.4196292402534154" />
     <axis xyz="1 0 0"/>
       <limit effort="0.0" lower="-3.14159" upper="3.14159" velocity="0.0"/>
    </joint>
    <joint name="Torso_Leg22" type="revolute">
       <parent link="Torso"/>
       <child  link="Leg22"/>
       <origin rpy="0 0 0" xyz="0.7820599986524065 1.430619968261711 0.7019527816137598" />
     <axis xyz="1 0 0"/>
       <limit effort="0.0" lower="-3.14159" upper="3.14159" velocity="0.0"/>
    </joint>
    <joint name="Leg22_Leg23" type="revolute">
       <parent link="Leg22"/>
       <child  link="Leg23"/>
       <origin rpy="0 0 0" xyz="2.583824715566049 0 0" />
     <axis xyz="1 0 0"/>
       <limit effort="0.0" lower="-3.14159" upper="3.14159" velocity="0.0"/>
    </joint>
    <joint name="Leg22_Leg24" type="revolute">
       <parent link="Leg22"/>
       <child  link="Leg24"/>
       <origin rpy="0 0 0" xyz="2.583824715566049 0 0.9262443744949477" />
     <axis xyz="1 0 0"/>
       <limit effort="0.0" lower="-3.14159" upper="3.14159" velocity="0.0"/>
    </joint>
    <joint name="Leg6_Leg25" type="revolute">
       <parent link="Leg6"/>
       <child  link="Leg25"/>
       <origin rpy="0 0 0" xyz="0 1.2559300489773697 0" />
     <axis xyz="1 0 0"/>
       <limit effort="0.0" lower="-3.14159" upper="3.14159" velocity="0.0"/>
    </joint>
    <joint name="Leg23_Leg26" type="revolute">
       <parent link="Leg23"/>
       <child  link="Leg26"/>
       <origin rpy="0 0 0" xyz="0 1.3113515641406157 1.4444145967140325" />
     <axis xyz="1 0 0"/>
       <limit effort="0.0" lower="-3.14159" upper="3.14159" velocity="0.0"/>
    </joint>
</robot>