<robot name = "robot">
    <link name="Torso">
        <inertial>
            <origin xyz="0 0 1.4707517215475194" rpy="0 0 0"/>
            <mass value="1" />
            <inertia ixx="100" ixy="0" ixz="0" iyy="100" iyz="0" izz="100" />
        </inertial>
        <visual>
            <origin xyz="0 0 1.4707517215475194" rpy="0 0 0"/>
            <geometry>
                <box size="1.0803420075748853 1.7088980513565672 2.941503443095039" />
            </geometry>
            <material name="Green">
                <color rgba="0 180.0 0.0 1.0"/>
            </material>
        </visual>
        <collision>
            <origin xyz="0 0 1.4707517215475194" rpy="0 0 0"/>
            <geometry>
                <box size="1.0803420075748853 1.7088980513565672 2.941503443095039" />
            </geometry>
        </collision>
    </link>
    <link name="Leg1">
        <inertial>
            <origin xyz="0 1.167667288297383 0" rpy="0 0 0"/>
            <mass value="1" />
            <inertia ixx="100" ixy="0" ixz="0" iyy="100" iyz="0" izz="100" />
        </inertial>
        <visual>
            <origin xyz="0 1.167667288297383 0" rpy="0 0 0"/>
            <geometry>
                <box size="2.007942785201248 2.335334576594766 2.54022415015" />
            </geometry>
            <material name="Blue">
                <color rgba="0 1.0 1.0 1.0"/>
            </material>
        </visual>
        <collision>
            <origin xyz="0 1.167667288297383 0" rpy="0 0 0"/>
            <geometry>
                <box size="2.007942785201248 2.335334576594766 2.54022415015" />
            </geometry>
        </collision>
    </link>
    <link name="Leg2">
        <inertial>
            <origin xyz="0.7419508000492251 0 0" rpy="0 0 0"/>
            <mass value="1" />
            <inertia ixx="100" ixy="0" ixz="0" iyy="100" iyz="0" izz="100" />
        </inertial>
        <visual>
            <origin xyz="0.7419508000492251 0 0" rpy="0 0 0"/>
            <geometry>
                <box size="1.4839016000984502 2.2364151633076395 2.8413629369181166" />
            </geometry>
            <material name="Green">
                <color rgba="0 180.0 0.0 1.0"/>
            </material>
        </visual>
        <collision>
            <origin xyz="0.7419508000492251 0 0" rpy="0 0 0"/>
            <geometry>
                <box size="1.4839016000984502 2.2364151633076395 2.8413629369181166" />
            </geometry>
        </collision>
    </link>
    <link name="Leg3">
        <inertial>
            <origin xyz="0 0.8465670598373046 0" rpy="0 0 0"/>
            <mass value="1" />
            <inertia ixx="100" ixy="0" ixz="0" iyy="100" iyz="0" izz="100" />
        </inertial>
        <visual>
            <origin xyz="0 0.8465670598373046 0" rpy="0 0 0"/>
            <geometry>
                <box size="1.7899796410210347 1.6931341196746093 2.0461215096927807" />
            </geometry>
            <material name="Green">
                <color rgba="0 180.0 0.0 1.0"/>
            </material>
        </visual>
        <collision>
            <origin xyz="0 0.8465670598373046 0" rpy="0 0 0"/>
            <geometry>
                <box size="1.7899796410210347 1.6931341196746093 2.0461215096927807" />
            </geometry>
        </collision>
    </link>
    <link name="Leg4">
        <inertial>
            <origin xyz="1.1344549943767663 0 0" rpy="0 0 0"/>
            <mass value="1" />
            <inertia ixx="100" ixy="0" ixz="0" iyy="100" iyz="0" izz="100" />
        </inertial>
        <visual>
            <origin xyz="1.1344549943767663 0 0" rpy="0 0 0"/>
            <geometry>
                <box size="2.2689099887535327 2.172144265559244 1.1917914038347204" />
            </geometry>
            <material name="Green">
                <color rgba="0 180.0 0.0 1.0"/>
            </material>
        </visual>
        <collision>
            <origin xyz="1.1344549943767663 0 0" rpy="0 0 0"/>
            <geometry>
                <box size="2.2689099887535327 2.172144265559244 1.1917914038347204" />
            </geometry>
        </collision>
    </link>
    <link name="Leg5">
        <inertial>
            <origin xyz="1.0650831369966178 0 0" rpy="0 0 0"/>
            <mass value="1" />
            <inertia ixx="100" ixy="0" ixz="0" iyy="100" iyz="0" izz="100" />
        </inertial>
        <visual>
            <origin xyz="1.0650831369966178 0 0" rpy="0 0 0"/>
            <geometry>
                <box size="2.1301662739932357 1.0748324462051502 1.8866289363688717" />
            </geometry>
            <material name="Green">
                <color rgba="0 180.0 0.0 1.0"/>
            </material>
        </visual>
        <collision>
            <origin xyz="1.0650831369966178 0 0" rpy="0 0 0"/>
            <geometry>
                <box size="2.1301662739932357 1.0748324462051502 1.8866289363688717" />
            </geometry>
        </collision>
    </link>
    <link name="Leg6">
        <inertial>
            <origin xyz="0 0.5444240090586369 0" rpy="0 0 0"/>
            <mass value="1" />
            <inertia ixx="100" ixy="0" ixz="0" iyy="100" iyz="0" izz="100" />
        </inertial>
        <visual>
            <origin xyz="0 0.5444240090586369 0" rpy="0 0 0"/>
            <geometry>
                <box size="1.139599037494228 1.0888480181172737 2.6701690829518485" />
            </geometry>
            <material name="Green">
                <color rgba="0 180.0 0.0 1.0"/>
            </material>
        </visual>
        <collision>
            <origin xyz="0 0.5444240090586369 0" rpy="0 0 0"/>
            <geometry>
                <box size="1.139599037494228 1.0888480181172737 2.6701690829518485" />
            </geometry>
        </collision>
    </link>
    <link name="Leg7">
        <inertial>
            <origin xyz="0 0.7689396236359033 0" rpy="0 0 0"/>
            <mass value="1" />
            <inertia ixx="100" ixy="0" ixz="0" iyy="100" iyz="0" izz="100" />
        </inertial>
        <visual>
            <origin xyz="0 0.7689396236359033 0" rpy="0 0 0"/>
            <geometry>
                <box size="1.995491791119449 1.5378792472718066 2.377943039098258" />
            </geometry>
            <material name="Green">
                <color rgba="0 180.0 0.0 1.0"/>
            </material>
        </visual>
        <collision>
            <origin xyz="0 0.7689396236359033 0" rpy="0 0 0"/>
            <geometry>
                <box size="1.995491791119449 1.5378792472718066 2.377943039098258" />
            </geometry>
        </collision>
    </link>
    <link name="Leg8">
        <inertial>
            <origin xyz="0.5378776975790011 0 0" rpy="0 0 0"/>
            <mass value="1" />
            <inertia ixx="100" ixy="0" ixz="0" iyy="100" iyz="0" izz="100" />
        </inertial>
        <visual>
            <origin xyz="0.5378776975790011 0 0" rpy="0 0 0"/>
            <geometry>
                <box size="1.0757553951580021 1.2621413359552125 2.5068399592794752" />
            </geometry>
            <material name="Blue">
                <color rgba="0 1.0 1.0 1.0"/>
            </material>
        </visual>
        <collision>
            <origin xyz="0.5378776975790011 0 0" rpy="0 0 0"/>
            <geometry>
                <box size="1.0757553951580021 1.2621413359552125 2.5068399592794752" />
            </geometry>
        </collision>
    </link>
    <link name="Leg9">
        <inertial>
            <origin xyz="0 0.5171411012698587 0" rpy="0 0 0"/>
            <mass value="1" />
            <inertia ixx="100" ixy="0" ixz="0" iyy="100" iyz="0" izz="100" />
        </inertial>
        <visual>
            <origin xyz="0 0.5171411012698587 0" rpy="0 0 0"/>
            <geometry>
                <box size="1.1893838653027409 1.0342822025397174 1.8620106394781784" />
            </geometry>
            <material name="Green">
                <color rgba="0 180.0 0.0 1.0"/>
            </material>
        </visual>
        <collision>
            <origin xyz="0 0.5171411012698587 0" rpy="0 0 0"/>
            <geometry>
                <box size="1.1893838653027409 1.0342822025397174 1.8620106394781784" />
            </geometry>
        </collision>
    </link>
    <link name="Leg10">
        <inertial>
            <origin xyz="0 1.4547005216916151 0" rpy="0 0 0"/>
            <mass value="1" />
            <inertia ixx="100" ixy="0" ixz="0" iyy="100" iyz="0" izz="100" />
        </inertial>
        <visual>
            <origin xyz="0 1.4547005216916151 0" rpy="0 0 0"/>
            <geometry>
                <box size="1.667307719903398 2.9094010433832302 1.0927625790050446" />
            </geometry>
            <material name="Blue">
                <color rgba="0 1.0 1.0 1.0"/>
            </material>
        </visual>
        <collision>
            <origin xyz="0 1.4547005216916151 0" rpy="0 0 0"/>
            <geometry>
                <box size="1.667307719903398 2.9094010433832302 1.0927625790050446" />
            </geometry>
        </collision>
    </link>
    <link name="Leg11">
        <inertial>
            <origin xyz="0 1.0744855958174608 0" rpy="0 0 0"/>
            <mass value="1" />
            <inertia ixx="100" ixy="0" ixz="0" iyy="100" iyz="0" izz="100" />
        </inertial>
        <visual>
            <origin xyz="0 1.0744855958174608 0" rpy="0 0 0"/>
            <geometry>
                <box size="2.6361681619174204 2.1489711916349217 2.8680965101963185" />
            </geometry>
            <material name="Blue">
                <color rgba="0 1.0 1.0 1.0"/>
            </material>
        </visual>
        <collision>
            <origin xyz="0 1.0744855958174608 0" rpy="0 0 0"/>
            <geometry>
                <box size="2.6361681619174204 2.1489711916349217 2.8680965101963185" />
            </geometry>
        </collision>
    </link>
    <link name="Leg12">
        <inertial>
            <origin xyz="0.6403152112384422 0 0" rpy="0 0 0"/>
            <mass value="1" />
            <inertia ixx="100" ixy="0" ixz="0" iyy="100" iyz="0" izz="100" />
        </inertial>
        <visual>
            <origin xyz="0.6403152112384422 0 0" rpy="0 0 0"/>
            <geometry>
                <box size="1.2806304224768843 1.8158021722184363 2.1589203974329494" />
            </geometry>
            <material name="Green">
                <color rgba="0 180.0 0.0 1.0"/>
            </material>
        </visual>
        <collision>
            <origin xyz="0.6403152112384422 0 0" rpy="0 0 0"/>
            <geometry>
                <box size="1.2806304224768843 1.8158021722184363 2.1589203974329494" />
            </geometry>
        </collision>
    </link>
    <link name="Leg13">
        <inertial>
            <origin xyz="0 0 1.4967421212098633" rpy="0 0 0"/>
            <mass value="1" />
            <inertia ixx="100" ixy="0" ixz="0" iyy="100" iyz="0" izz="100" />
        </inertial>
        <visual>
            <origin xyz="0 0 1.4967421212098633" rpy="0 0 0"/>
            <geometry>
                <box size="2.118834043901437 2.5774275258342767 2.9934842424197265" />
            </geometry>
            <material name="Green">
                <color rgba="0 180.0 0.0 1.0"/>
            </material>
        </visual>
        <collision>
            <origin xyz="0 0 1.4967421212098633" rpy="0 0 0"/>
            <geometry>
                <box size="2.118834043901437 2.5774275258342767 2.9934842424197265" />
            </geometry>
        </collision>
    </link>
    <link name="Leg14">
        <inertial>
            <origin xyz="0 0 0.9471708849923112" rpy="0 0 0"/>
            <mass value="1" />
            <inertia ixx="100" ixy="0" ixz="0" iyy="100" iyz="0" izz="100" />
        </inertial>
        <visual>
            <origin xyz="0 0 0.9471708849923112" rpy="0 0 0"/>
            <geometry>
                <box size="1.8792202896004666 1.4243190467413673 1.8943417699846223" />
            </geometry>
            <material name="Green">
                <color rgba="0 180.0 0.0 1.0"/>
            </material>
        </visual>
        <collision>
            <origin xyz="0 0 0.9471708849923112" rpy="0 0 0"/>
            <geometry>
                <box size="1.8792202896004666 1.4243190467413673 1.8943417699846223" />
            </geometry>
        </collision>
    </link>
    <link name="Leg15">
        <inertial>
            <origin xyz="0 0 0.7665952566846074" rpy="0 0 0"/>
            <mass value="1" />
            <inertia ixx="100" ixy="0" ixz="0" iyy="100" iyz="0" izz="100" />
        </inertial>
        <visual>
            <origin xyz="0 0 0.7665952566846074" rpy="0 0 0"/>
            <geometry>
                <box size="1.2525632294174138 2.9541380601021734 1.5331905133692147" />
            </geometry>
            <material name="Green">
                <color rgba="0 180.0 0.0 1.0"/>
            </material>
        </visual>
        <collision>
            <origin xyz="0 0 0.7665952566846074" rpy="0 0 0"/>
            <geometry>
                <box size="1.2525632294174138 2.9541380601021734 1.5331905133692147" />
            </geometry>
        </collision>
    </link>
    <link name="Leg16">
        <inertial>
            <origin xyz="0 1.2025104018229267 0" rpy="0 0 0"/>
            <mass value="1" />
            <inertia ixx="100" ixy="0" ixz="0" iyy="100" iyz="0" izz="100" />
        </inertial>
        <visual>
            <origin xyz="0 1.2025104018229267 0" rpy="0 0 0"/>
            <geometry>
                <box size="1.8591652050405898 2.4050208036458534 2.8496169352815417" />
            </geometry>
            <material name="Blue">
                <color rgba="0 1.0 1.0 1.0"/>
            </material>
        </visual>
        <collision>
            <origin xyz="0 1.2025104018229267 0" rpy="0 0 0"/>
            <geometry>
                <box size="1.8591652050405898 2.4050208036458534 2.8496169352815417" />
            </geometry>
        </collision>
    </link>
    <link name="Leg17">
        <inertial>
            <origin xyz="0 0 1.0488344163101533" rpy="0 0 0"/>
            <mass value="1" />
            <inertia ixx="100" ixy="0" ixz="0" iyy="100" iyz="0" izz="100" />
        </inertial>
        <visual>
            <origin xyz="0 0 1.0488344163101533" rpy="0 0 0"/>
            <geometry>
                <box size="2.5328882904912224 2.6545965963126097 2.0976688326203066" />
            </geometry>
            <material name="Blue">
                <color rgba="0 1.0 1.0 1.0"/>
            </material>
        </visual>
        <collision>
            <origin xyz="0 0 1.0488344163101533" rpy="0 0 0"/>
            <geometry>
                <box size="2.5328882904912224 2.6545965963126097 2.0976688326203066" />
            </geometry>
        </collision>
    </link>
    <link name="Leg18">
        <inertial>
            <origin xyz="0 0.5521920936239877 0" rpy="0 0 0"/>
            <mass value="1" />
            <inertia ixx="100" ixy="0" ixz="0" iyy="100" iyz="0" izz="100" />
        </inertial>
        <visual>
            <origin xyz="0 0.5521920936239877 0" rpy="0 0 0"/>
            <geometry>
                <box size="2.0459081767950353 1.1043841872479754 2.333098311673879" />
            </geometry>
            <material name="Green">
                <color rgba="0 180.0 0.0 1.0"/>
            </material>
        </visual>
        <collision>
            <origin xyz="0 0.5521920936239877 0" rpy="0 0 0"/>
            <geometry>
                <box size="2.0459081767950353 1.1043841872479754 2.333098311673879" />
            </geometry>
        </collision>
    </link>
    <link name="Leg19">
        <inertial>
            <origin xyz="0 0 1.2688716985717174" rpy="0 0 0"/>
            <mass value="1" />
            <inertia ixx="100" ixy="0" ixz="0" iyy="100" iyz="0" izz="100" />
        </inertial>
        <visual>
            <origin xyz="0 0 1.2688716985717174" rpy="0 0 0"/>
            <geometry>
                <box size="1.9855277094193722 1.0184260412799389 2.537743397143435" />
            </geometry>
            <material name="Blue">
                <color rgba="0 1.0 1.0 1.0"/>
            </material>
        </visual>
        <collision>
            <origin xyz="0 0 1.2688716985717174" rpy="0 0 0"/>
            <geometry>
                <box size="1.9855277094193722 1.0184260412799389 2.537743397143435" />
            </geometry>
        </collision>
    </link>
    <link name="Leg20">
        <inertial>
            <origin xyz="0 1.1119769872723442 0" rpy="0 0 0"/>
            <mass value="1" />
            <inertia ixx="100" ixy="0" ixz="0" iyy="100" iyz="0" izz="100" />
        </inertial>
        <visual>
            <origin xyz="0 1.1119769872723442 0" rpy="0 0 0"/>
            <geometry>
                <box size="1.629181083263967 2.2239539745446884 2.9982590746269855" />
            </geometry>
            <material name="Green">
                <color rgba="0 180.0 0.0 1.0"/>
            </material>
        </visual>
        <collision>
            <origin xyz="0 1.1119769872723442 0" rpy="0 0 0"/>
            <geometry>
                <box size="1.629181083263967 2.2239539745446884 2.9982590746269855" />
            </geometry>
        </collision>
    </link>
    <link name="Leg21">
        <inertial>
            <origin xyz="0 0 0.9930185272113818" rpy="0 0 0"/>
            <mass value="1" />
            <inertia ixx="100" ixy="0" ixz="0" iyy="100" iyz="0" izz="100" />
        </inertial>
        <visual>
            <origin xyz="0 0 0.9930185272113818" rpy="0 0 0"/>
            <geometry>
                <box size="1.661535824293932 1.972645621498385 1.9860370544227637" />
            </geometry>
            <material name="Blue">
                <color rgba="0 1.0 1.0 1.0"/>
            </material>
        </visual>
        <collision>
            <origin xyz="0 0 0.9930185272113818" rpy="0 0 0"/>
            <geometry>
                <box size="1.661535824293932 1.972645621498385 1.9860370544227637" />
            </geometry>
        </collision>
    </link>
    <link name="Leg22">
        <inertial>
            <origin xyz="1.2532605643501944 0 0" rpy="0 0 0"/>
            <mass value="1" />
            <inertia ixx="100" ixy="0" ixz="0" iyy="100" iyz="0" izz="100" />
        </inertial>
        <visual>
            <origin xyz="1.2532605643501944 0 0" rpy="0 0 0"/>
            <geometry>
                <box size="2.506521128700389 1.3325659977548023 2.434111104286978" />
            </geometry>
            <material name="Blue">
                <color rgba="0 1.0 1.0 1.0"/>
            </material>
        </visual>
        <collision>
            <origin xyz="1.2532605643501944 0 0" rpy="0 0 0"/>
            <geometry>
                <box size="2.506521128700389 1.3325659977548023 2.434111104286978" />
            </geometry>
        </collision>
    </link>
    <link name="Leg23">
        <inertial>
            <origin xyz="0.8489443086928092 0 0" rpy="0 0 0"/>
            <mass value="1" />
            <inertia ixx="100" ixy="0" ixz="0" iyy="100" iyz="0" izz="100" />
        </inertial>
        <visual>
            <origin xyz="0.8489443086928092 0 0" rpy="0 0 0"/>
            <geometry>
                <box size="1.6978886173856185 2.796789476207406 1.421041384248599" />
            </geometry>
            <material name="Green">
                <color rgba="0 180.0 0.0 1.0"/>
            </material>
        </visual>
        <collision>
            <origin xyz="0.8489443086928092 0 0" rpy="0 0 0"/>
            <geometry>
                <box size="1.6978886173856185 2.796789476207406 1.421041384248599" />
            </geometry>
        </collision>
    </link>
    <link name="Leg24">
        <inertial>
            <origin xyz="0 0.5525381622702579 0" rpy="0 0 0"/>
            <mass value="1" />
            <inertia ixx="100" ixy="0" ixz="0" iyy="100" iyz="0" izz="100" />
        </inertial>
        <visual>
            <origin xyz="0 0.5525381622702579 0" rpy="0 0 0"/>
            <geometry>
                <box size="1.6854705895107651 1.1050763245405157 2.7464614748924046" />
            </geometry>
            <material name="Blue">
                <color rgba="0 1.0 1.0 1.0"/>
            </material>
        </visual>
        <collision>
            <origin xyz="0 0.5525381622702579 0" rpy="0 0 0"/>
            <geometry>
                <box size="1.6854705895107651 1.1050763245405157 2.7464614748924046" />
            </geometry>
        </collision>
    </link>
    <joint name="Torso_Leg1" type="revolute">
       <parent link="Torso"/>
       <child  link="Leg1"/>
       <origin rpy="0 0 0" xyz="0 0.8544490256782836 1.4707517215475194" />
     <axis xyz="1 0 0"/>
       <limit effort="0.0" lower="-3.14159" upper="3.14159" velocity="0.0"/>
    </joint>
    <joint name="Torso_Leg2" type="revolute">
       <parent link="Torso"/>
       <child  link="Leg2"/>
       <origin rpy="0 0 0" xyz="1.003971392600624 1.167667288297383 0" />
     <axis xyz="1 0 0"/>
       <limit effort="0.0" lower="-3.14159" upper="3.14159" velocity="0.0"/>
    </joint>
    <joint name="Leg1_Leg3" type="revolute">
       <parent link="Leg1"/>
       <child  link="Leg3"/>
       <origin rpy="0 0 0" xyz="0.7419508000492251 1.1182075816538197 0" />
     <axis xyz="1 0 0"/>
       <limit effort="0.0" lower="-3.14159" upper="3.14159" velocity="0.0"/>
    </joint>
    <joint name="Leg3_Leg4" type="revolute">
       <parent link="Leg3"/>
       <child  link="Leg4"/>
       <origin rpy="0 0 0" xyz="2.2689099887535327 0 0" />
     <axis xyz="1 0 0"/>
       <limit effort="0.0" lower="-3.14159" upper="3.14159" velocity="0.0"/>
    </joint>
    <joint name="Leg2_Leg5" type="revolute">
       <parent link="Leg2"/>
       <child  link="Leg5"/>
       <origin rpy="0 0 0" xyz="0.8949898205105173 0.8465670598373046 0" />
     <axis xyz="1 0 0"/>
       <limit effort="0.0" lower="-3.14159" upper="3.14159" velocity="0.0"/>
    </joint>
    <joint name="Leg2_Leg6" type="revolute">
       <parent link="Leg2"/>
       <child  link="Leg6"/>
       <origin rpy="0 0 0" xyz="0.8949898205105173 1.6931341196746093 0" />
     <axis xyz="1 0 0"/>
       <limit effort="0.0" lower="-3.14159" upper="3.14159" velocity="0.0"/>
    </joint>
    <joint name="Leg4_Leg7" type="revolute">
       <parent link="Leg4"/>
       <child  link="Leg7"/>
       <origin rpy="0 0 0" xyz="1.0650831369966178 0.5374162231025751 0" />
     <axis xyz="1 0 0"/>
       <limit effort="0.0" lower="-3.14159" upper="3.14159" velocity="0.0"/>
    </joint>
    <joint name="Leg5_Leg8" type="revolute">
       <parent link="Leg5"/>
       <child  link="Leg8"/>
       <origin rpy="0 0 0" xyz="0.569799518747114 0.5444240090586369 0" />
     <axis xyz="1 0 0"/>
       <limit effort="0.0" lower="-3.14159" upper="3.14159" velocity="0.0"/>
    </joint>
    <joint name="Leg8_Leg9" type="revolute">
       <parent link="Leg8"/>
       <child  link="Leg9"/>
       <origin rpy="0 0 0" xyz="0 1.0342822025397174 0" />
     <axis xyz="1 0 0"/>
       <limit effort="0.0" lower="-3.14159" upper="3.14159" velocity="0.0"/>
    </joint>
    <joint name="Leg5_Leg10" type="revolute">
       <parent link="Leg5"/>
       <child  link="Leg10"/>
       <origin rpy="0 0 0" xyz="0.569799518747114 1.0888480181172737 0" />
     <axis xyz="1 0 0"/>
       <limit effort="0.0" lower="-3.14159" upper="3.14159" velocity="0.0"/>
    </joint>
    <joint name="Leg6_Leg11" type="revolute">
       <parent link="Leg6"/>
       <child  link="Leg11"/>
       <origin rpy="0 0 0" xyz="0 1.5378792472718066 0" />
     <axis xyz="1 0 0"/>
       <limit effort="0.0" lower="-3.14159" upper="3.14159" velocity="0.0"/>
    </joint>
    <joint name="Leg4_Leg12" type="revolute">
       <parent link="Leg4"/>
       <child  link="Leg12"/>
       <origin rpy="0 0 0" xyz="2.1301662739932357 0.5374162231025751 0" />
     <axis xyz="1 0 0"/>
       <limit effort="0.0" lower="-3.14159" upper="3.14159" velocity="0.0"/>
    </joint>
    <joint name="Leg11_Leg13" type="revolute">
       <parent link="Leg11"/>
       <child  link="Leg13"/>
       <origin rpy="0 0 0" xyz="0.6403152112384422 0 1.0794601987164747" />
     <axis xyz="1 0 0"/>
       <limit effort="0.0" lower="-3.14159" upper="3.14159" velocity="0.0"/>
    </joint>
    <joint name="Leg9_Leg14" type="revolute">
       <parent link="Leg9"/>
       <child  link="Leg14"/>
       <origin rpy="0 0 0" xyz="0 1.4547005216916151 0.5463812895025223" />
     <axis xyz="1 0 0"/>
       <limit effort="0.0" lower="-3.14159" upper="3.14159" velocity="0.0"/>
    </joint>
    <joint name="Leg12_Leg15" type="revolute">
       <parent link="Leg12"/>
       <child  link="Leg15"/>
       <origin rpy="0 0 0" xyz="0 0 2.9934842424197265" />
     <axis xyz="1 0 0"/>
       <limit effort="0.0" lower="-3.14159" upper="3.14159" velocity="0.0"/>
    </joint>
    <joint name="Leg10_Leg16" type="revolute">
       <parent link="Leg10"/>
       <child  link="Leg16"/>
       <origin rpy="0 0 0" xyz="0 2.1489711916349217 0" />
     <axis xyz="1 0 0"/>
       <limit effort="0.0" lower="-3.14159" upper="3.14159" velocity="0.0"/>
    </joint>
    <joint name="Leg8_Leg17" type="revolute">
       <parent link="Leg8"/>
       <child  link="Leg17"/>
       <origin rpy="0 0 0" xyz="0 1.0342822025397174 0.9310053197390892" />
     <axis xyz="1 0 0"/>
       <limit effort="0.0" lower="-3.14159" upper="3.14159" velocity="0.0"/>
    </joint>
    <joint name="Leg7_Leg18" type="revolute">
       <parent link="Leg7"/>
       <child  link="Leg18"/>
       <origin rpy="0 0 0" xyz="0.5378776975790011 0.6310706679776062 0" />
     <axis xyz="1 0 0"/>
       <limit effort="0.0" lower="-3.14159" upper="3.14159" velocity="0.0"/>
    </joint>
    <joint name="Leg4_Leg19" type="revolute">
       <parent link="Leg4"/>
       <child  link="Leg19"/>
       <origin rpy="0 0 0" xyz="2.1301662739932357 0.5374162231025751 0.9433144681844359" />
     <axis xyz="1 0 0"/>
       <limit effort="0.0" lower="-3.14159" upper="3.14159" velocity="0.0"/>
    </joint>
    <joint name="Leg9_Leg20" type="revolute">
       <parent link="Leg9"/>
       <child  link="Leg20"/>
       <origin rpy="0 0 0" xyz="0 2.9094010433832302 0.5463812895025223" />
     <axis xyz="1 0 0"/>
       <limit effort="0.0" lower="-3.14159" upper="3.14159" velocity="0.0"/>
    </joint>
    <joint name="Leg17_Leg21" type="revolute">
       <parent link="Leg17"/>
       <child  link="Leg21"/>
       <origin rpy="0 0 0" xyz="0 0.5521920936239877 1.1665491558369394" />
     <axis xyz="1 0 0"/>
       <limit effort="0.0" lower="-3.14159" upper="3.14159" velocity="0.0"/>
    </joint>
    <joint name="Leg6_Leg22" type="revolute">
       <parent link="Leg6"/>
       <child  link="Leg22"/>
       <origin rpy="0 0 0" xyz="0.9977458955597245 1.5378792472718066 0" />
     <axis xyz="1 0 0"/>
       <limit effort="0.0" lower="-3.14159" upper="3.14159" velocity="0.0"/>
    </joint>
    <joint name="Leg7_Leg23" type="revolute">
       <parent link="Leg7"/>
       <child  link="Leg23"/>
       <origin rpy="0 0 0" xyz="1.0757553951580021 0.6310706679776062 0" />
     <axis xyz="1 0 0"/>
       <limit effort="0.0" lower="-3.14159" upper="3.14159" velocity="0.0"/>
    </joint>
    <joint name="Leg23_Leg24" type="revolute">
       <parent link="Leg23"/>
       <child  link="Leg24"/>
       <origin rpy="0 0 0" xyz="0 1.1050763245405157 0" />
     <axis xyz="1 0 0"/>
       <limit effort="0.0" lower="-3.14159" upper="3.14159" velocity="0.0"/>
    </joint>
</robot>