<robot name = "robot">
    <link name="Torso">
        <inertial>
            <origin xyz="0 0 0.7478067185982379" rpy="0 0 0"/>
            <mass value="1" />
            <inertia ixx="100" ixy="0" ixz="0" iyy="100" iyz="0" izz="100" />
        </inertial>
        <visual>
            <origin xyz="0 0 0.7478067185982379" rpy="0 0 0"/>
            <geometry>
                <box size="2.5963556149210487 2.9501828751578962 1.4956134371964758" />
            </geometry>
            <material name="Green">
                <color rgba="0 180.0 0.0 1.0"/>
            </material>
        </visual>
        <collision>
            <origin xyz="0 0 0.7478067185982379" rpy="0 0 0"/>
            <geometry>
                <box size="2.5963556149210487 2.9501828751578962 1.4956134371964758" />
            </geometry>
        </collision>
    </link>
    <link name="Leg1">
        <inertial>
            <origin xyz="0 0 1.0952576191140848" rpy="0 0 0"/>
            <mass value="1" />
            <inertia ixx="100" ixy="0" ixz="0" iyy="100" iyz="0" izz="100" />
        </inertial>
        <visual>
            <origin xyz="0 0 1.0952576191140848" rpy="0 0 0"/>
            <geometry>
                <box size="2.744970901028616 1.0108450713850559 2.1905152382281696" />
            </geometry>
            <material name="Green">
                <color rgba="0 180.0 0.0 1.0"/>
            </material>
        </visual>
        <collision>
            <origin xyz="0 0 1.0952576191140848" rpy="0 0 0"/>
            <geometry>
                <box size="2.744970901028616 1.0108450713850559 2.1905152382281696" />
            </geometry>
        </collision>
    </link>
    <link name="Leg2">
        <inertial>
            <origin xyz="0 1.1837699632541145 0" rpy="0 0 0"/>
            <mass value="1" />
            <inertia ixx="100" ixy="0" ixz="0" iyy="100" iyz="0" izz="100" />
        </inertial>
        <visual>
            <origin xyz="0 1.1837699632541145 0" rpy="0 0 0"/>
            <geometry>
                <box size="2.748854138058764 2.367539926508229 1.4780469139595558" />
            </geometry>
            <material name="Blue">
                <color rgba="0 1.0 1.0 1.0"/>
            </material>
        </visual>
        <collision>
            <origin xyz="0 1.1837699632541145 0" rpy="0 0 0"/>
            <geometry>
                <box size="2.748854138058764 2.367539926508229 1.4780469139595558" />
            </geometry>
        </collision>
    </link>
    <link name="Leg3">
        <inertial>
            <origin xyz="0 0 1.2302892959119305" rpy="0 0 0"/>
            <mass value="1" />
            <inertia ixx="100" ixy="0" ixz="0" iyy="100" iyz="0" izz="100" />
        </inertial>
        <visual>
            <origin xyz="0 0 1.2302892959119305" rpy="0 0 0"/>
            <geometry>
                <box size="1.500499222136105 2.9358041107244723 2.460578591823861" />
            </geometry>
            <material name="Blue">
                <color rgba="0 1.0 1.0 1.0"/>
            </material>
        </visual>
        <collision>
            <origin xyz="0 0 1.2302892959119305" rpy="0 0 0"/>
            <geometry>
                <box size="1.500499222136105 2.9358041107244723 2.460578591823861" />
            </geometry>
        </collision>
    </link>
    <link name="Leg4">
        <inertial>
            <origin xyz="1.2521679036976416 0 0" rpy="0 0 0"/>
            <mass value="1" />
            <inertia ixx="100" ixy="0" ixz="0" iyy="100" iyz="0" izz="100" />
        </inertial>
        <visual>
            <origin xyz="1.2521679036976416 0 0" rpy="0 0 0"/>
            <geometry>
                <box size="2.5043358073952833 2.51762748086941 2.8998653581685447" />
            </geometry>
            <material name="Green">
                <color rgba="0 180.0 0.0 1.0"/>
            </material>
        </visual>
        <collision>
            <origin xyz="1.2521679036976416 0 0" rpy="0 0 0"/>
            <geometry>
                <box size="2.5043358073952833 2.51762748086941 2.8998653581685447" />
            </geometry>
        </collision>
    </link>
    <link name="Leg5">
        <inertial>
            <origin xyz="0 1.2560281195101357 0" rpy="0 0 0"/>
            <mass value="1" />
            <inertia ixx="100" ixy="0" ixz="0" iyy="100" iyz="0" izz="100" />
        </inertial>
        <visual>
            <origin xyz="0 1.2560281195101357 0" rpy="0 0 0"/>
            <geometry>
                <box size="1.3543038851558433 2.5120562390202714 1.9497755852881429" />
            </geometry>
            <material name="Blue">
                <color rgba="0 1.0 1.0 1.0"/>
            </material>
        </visual>
        <collision>
            <origin xyz="0 1.2560281195101357 0" rpy="0 0 0"/>
            <geometry>
                <box size="1.3543038851558433 2.5120562390202714 1.9497755852881429" />
            </geometry>
        </collision>
    </link>
    <link name="Leg6">
        <inertial>
            <origin xyz="0 1.0910163630324665 0" rpy="0 0 0"/>
            <mass value="1" />
            <inertia ixx="100" ixy="0" ixz="0" iyy="100" iyz="0" izz="100" />
        </inertial>
        <visual>
            <origin xyz="0 1.0910163630324665 0" rpy="0 0 0"/>
            <geometry>
                <box size="1.164906630836192 2.182032726064933 1.490674539322551" />
            </geometry>
            <material name="Green">
                <color rgba="0 180.0 0.0 1.0"/>
            </material>
        </visual>
        <collision>
            <origin xyz="0 1.0910163630324665 0" rpy="0 0 0"/>
            <geometry>
                <box size="1.164906630836192 2.182032726064933 1.490674539322551" />
            </geometry>
        </collision>
    </link>
    <link name="Leg7">
        <inertial>
            <origin xyz="0 0 1.0925528665932134" rpy="0 0 0"/>
            <mass value="1" />
            <inertia ixx="100" ixy="0" ixz="0" iyy="100" iyz="0" izz="100" />
        </inertial>
        <visual>
            <origin xyz="0 0 1.0925528665932134" rpy="0 0 0"/>
            <geometry>
                <box size="2.270488029653138 2.0592349583983767 2.1851057331864268" />
            </geometry>
            <material name="Blue">
                <color rgba="0 1.0 1.0 1.0"/>
            </material>
        </visual>
        <collision>
            <origin xyz="0 0 1.0925528665932134" rpy="0 0 0"/>
            <geometry>
                <box size="2.270488029653138 2.0592349583983767 2.1851057331864268" />
            </geometry>
        </collision>
    </link>
    <link name="Leg8">
        <inertial>
            <origin xyz="0 0.5841163129267968 0" rpy="0 0 0"/>
            <mass value="1" />
            <inertia ixx="100" ixy="0" ixz="0" iyy="100" iyz="0" izz="100" />
        </inertial>
        <visual>
            <origin xyz="0 0.5841163129267968 0" rpy="0 0 0"/>
            <geometry>
                <box size="2.731963481327007 1.1682326258535936 1.3275942712073228" />
            </geometry>
            <material name="Green">
                <color rgba="0 180.0 0.0 1.0"/>
            </material>
        </visual>
        <collision>
            <origin xyz="0 0.5841163129267968 0" rpy="0 0 0"/>
            <geometry>
                <box size="2.731963481327007 1.1682326258535936 1.3275942712073228" />
            </geometry>
        </collision>
    </link>
    <link name="Leg9">
        <inertial>
            <origin xyz="0 0 1.4883722266905848" rpy="0 0 0"/>
            <mass value="1" />
            <inertia ixx="100" ixy="0" ixz="0" iyy="100" iyz="0" izz="100" />
        </inertial>
        <visual>
            <origin xyz="0 0 1.4883722266905848" rpy="0 0 0"/>
            <geometry>
                <box size="1.1371544016288648 1.3486279349573003 2.9767444533811696" />
            </geometry>
            <material name="Blue">
                <color rgba="0 1.0 1.0 1.0"/>
            </material>
        </visual>
        <collision>
            <origin xyz="0 0 1.4883722266905848" rpy="0 0 0"/>
            <geometry>
                <box size="1.1371544016288648 1.3486279349573003 2.9767444533811696" />
            </geometry>
        </collision>
    </link>
    <link name="Leg10">
        <inertial>
            <origin xyz="0 1.0081150439832487 0" rpy="0 0 0"/>
            <mass value="1" />
            <inertia ixx="100" ixy="0" ixz="0" iyy="100" iyz="0" izz="100" />
        </inertial>
        <visual>
            <origin xyz="0 1.0081150439832487 0" rpy="0 0 0"/>
            <geometry>
                <box size="1.7260198309765173 2.0162300879664974 2.238332081348366" />
            </geometry>
            <material name="Blue">
                <color rgba="0 1.0 1.0 1.0"/>
            </material>
        </visual>
        <collision>
            <origin xyz="0 1.0081150439832487 0" rpy="0 0 0"/>
            <geometry>
                <box size="1.7260198309765173 2.0162300879664974 2.238332081348366" />
            </geometry>
        </collision>
    </link>
    <link name="Leg11">
        <inertial>
            <origin xyz="0 1.3099232267682956 0" rpy="0 0 0"/>
            <mass value="1" />
            <inertia ixx="100" ixy="0" ixz="0" iyy="100" iyz="0" izz="100" />
        </inertial>
        <visual>
            <origin xyz="0 1.3099232267682956 0" rpy="0 0 0"/>
            <geometry>
                <box size="2.0152335631089606 2.6198464535365913 1.473189136248174" />
            </geometry>
            <material name="Green">
                <color rgba="0 180.0 0.0 1.0"/>
            </material>
        </visual>
        <collision>
            <origin xyz="0 1.3099232267682956 0" rpy="0 0 0"/>
            <geometry>
                <box size="2.0152335631089606 2.6198464535365913 1.473189136248174" />
            </geometry>
        </collision>
    </link>
    <link name="Leg12">
        <inertial>
            <origin xyz="1.1168918462150064 0 0" rpy="0 0 0"/>
            <mass value="1" />
            <inertia ixx="100" ixy="0" ixz="0" iyy="100" iyz="0" izz="100" />
        </inertial>
        <visual>
            <origin xyz="1.1168918462150064 0 0" rpy="0 0 0"/>
            <geometry>
                <box size="2.2337836924300127 2.9426607630766117 2.3235677169030096" />
            </geometry>
            <material name="Green">
                <color rgba="0 180.0 0.0 1.0"/>
            </material>
        </visual>
        <collision>
            <origin xyz="1.1168918462150064 0 0" rpy="0 0 0"/>
            <geometry>
                <box size="2.2337836924300127 2.9426607630766117 2.3235677169030096" />
            </geometry>
        </collision>
    </link>
    <link name="Leg13">
        <inertial>
            <origin xyz="0 0.7049874962560343 0" rpy="0 0 0"/>
            <mass value="1" />
            <inertia ixx="100" ixy="0" ixz="0" iyy="100" iyz="0" izz="100" />
        </inertial>
        <visual>
            <origin xyz="0 0.7049874962560343 0" rpy="0 0 0"/>
            <geometry>
                <box size="2.5844103149143813 1.4099749925120686 1.5475960205339645" />
            </geometry>
            <material name="Blue">
                <color rgba="0 1.0 1.0 1.0"/>
            </material>
        </visual>
        <collision>
            <origin xyz="0 0.7049874962560343 0" rpy="0 0 0"/>
            <geometry>
                <box size="2.5844103149143813 1.4099749925120686 1.5475960205339645" />
            </geometry>
        </collision>
    </link>
    <link name="Leg14">
        <inertial>
            <origin xyz="0 0.9297338732938035 0" rpy="0 0 0"/>
            <mass value="1" />
            <inertia ixx="100" ixy="0" ixz="0" iyy="100" iyz="0" izz="100" />
        </inertial>
        <visual>
            <origin xyz="0 0.9297338732938035 0" rpy="0 0 0"/>
            <geometry>
                <box size="2.529967419681844 1.859467746587607 1.2959681691753866" />
            </geometry>
            <material name="Green">
                <color rgba="0 180.0 0.0 1.0"/>
            </material>
        </visual>
        <collision>
            <origin xyz="0 0.9297338732938035 0" rpy="0 0 0"/>
            <geometry>
                <box size="2.529967419681844 1.859467746587607 1.2959681691753866" />
            </geometry>
        </collision>
    </link>
    <link name="Leg15">
        <inertial>
            <origin xyz="1.3332893260960974 0 0" rpy="0 0 0"/>
            <mass value="1" />
            <inertia ixx="100" ixy="0" ixz="0" iyy="100" iyz="0" izz="100" />
        </inertial>
        <visual>
            <origin xyz="1.3332893260960974 0 0" rpy="0 0 0"/>
            <geometry>
                <box size="2.666578652192195 1.6738503448870765 1.140209894245829" />
            </geometry>
            <material name="Green">
                <color rgba="0 180.0 0.0 1.0"/>
            </material>
        </visual>
        <collision>
            <origin xyz="1.3332893260960974 0 0" rpy="0 0 0"/>
            <geometry>
                <box size="2.666578652192195 1.6738503448870765 1.140209894245829" />
            </geometry>
        </collision>
    </link>
    <link name="Leg16">
        <inertial>
            <origin xyz="0.8490837144455877 0 0" rpy="0 0 0"/>
            <mass value="1" />
            <inertia ixx="100" ixy="0" ixz="0" iyy="100" iyz="0" izz="100" />
        </inertial>
        <visual>
            <origin xyz="0.8490837144455877 0 0" rpy="0 0 0"/>
            <geometry>
                <box size="1.6981674288911754 1.1226881274429972 2.082421638571514" />
            </geometry>
            <material name="Blue">
                <color rgba="0 1.0 1.0 1.0"/>
            </material>
        </visual>
        <collision>
            <origin xyz="0.8490837144455877 0 0" rpy="0 0 0"/>
            <geometry>
                <box size="1.6981674288911754 1.1226881274429972 2.082421638571514" />
            </geometry>
        </collision>
    </link>
    <link name="Leg17">
        <inertial>
            <origin xyz="1.1607672159255635 0 0" rpy="0 0 0"/>
            <mass value="1" />
            <inertia ixx="100" ixy="0" ixz="0" iyy="100" iyz="0" izz="100" />
        </inertial>
        <visual>
            <origin xyz="1.1607672159255635 0 0" rpy="0 0 0"/>
            <geometry>
                <box size="2.321534431851127 2.838064414480147 2.4629608783193007" />
            </geometry>
            <material name="Blue">
                <color rgba="0 1.0 1.0 1.0"/>
            </material>
        </visual>
        <collision>
            <origin xyz="1.1607672159255635 0 0" rpy="0 0 0"/>
            <geometry>
                <box size="2.321534431851127 2.838064414480147 2.4629608783193007" />
            </geometry>
        </collision>
    </link>
    <link name="Leg18">
        <inertial>
            <origin xyz="0 0 0.8618839857747643" rpy="0 0 0"/>
            <mass value="1" />
            <inertia ixx="100" ixy="0" ixz="0" iyy="100" iyz="0" izz="100" />
        </inertial>
        <visual>
            <origin xyz="0 0 0.8618839857747643" rpy="0 0 0"/>
            <geometry>
                <box size="1.9487350422263947 2.3005436607414973 1.7237679715495287" />
            </geometry>
            <material name="Blue">
                <color rgba="0 1.0 1.0 1.0"/>
            </material>
        </visual>
        <collision>
            <origin xyz="0 0 0.8618839857747643" rpy="0 0 0"/>
            <geometry>
                <box size="1.9487350422263947 2.3005436607414973 1.7237679715495287" />
            </geometry>
        </collision>
    </link>
    <link name="Leg19">
        <inertial>
            <origin xyz="0 0.6870946818178192 0" rpy="0 0 0"/>
            <mass value="1" />
            <inertia ixx="100" ixy="0" ixz="0" iyy="100" iyz="0" izz="100" />
        </inertial>
        <visual>
            <origin xyz="0 0.6870946818178192 0" rpy="0 0 0"/>
            <geometry>
                <box size="2.7007957424936846 1.3741893636356384 1.5996244228824976" />
            </geometry>
            <material name="Green">
                <color rgba="0 180.0 0.0 1.0"/>
            </material>
        </visual>
        <collision>
            <origin xyz="0 0.6870946818178192 0" rpy="0 0 0"/>
            <geometry>
                <box size="2.7007957424936846 1.3741893636356384 1.5996244228824976" />
            </geometry>
        </collision>
    </link>
    <link name="Leg20">
        <inertial>
            <origin xyz="0.671605106899928 0 0" rpy="0 0 0"/>
            <mass value="1" />
            <inertia ixx="100" ixy="0" ixz="0" iyy="100" iyz="0" izz="100" />
        </inertial>
        <visual>
            <origin xyz="0.671605106899928 0 0" rpy="0 0 0"/>
            <geometry>
                <box size="1.343210213799856 2.107789566524287 1.430247829947132" />
            </geometry>
            <material name="Green">
                <color rgba="0 180.0 0.0 1.0"/>
            </material>
        </visual>
        <collision>
            <origin xyz="0.671605106899928 0 0" rpy="0 0 0"/>
            <geometry>
                <box size="1.343210213799856 2.107789566524287 1.430247829947132" />
            </geometry>
        </collision>
    </link>
    <link name="Leg21">
        <inertial>
            <origin xyz="0.5092178289146674 0 0" rpy="0 0 0"/>
            <mass value="1" />
            <inertia ixx="100" ixy="0" ixz="0" iyy="100" iyz="0" izz="100" />
        </inertial>
        <visual>
            <origin xyz="0.5092178289146674 0 0" rpy="0 0 0"/>
            <geometry>
                <box size="1.0184356578293348 1.1917551016799879 1.746096361440699" />
            </geometry>
            <material name="Blue">
                <color rgba="0 1.0 1.0 1.0"/>
            </material>
        </visual>
        <collision>
            <origin xyz="0.5092178289146674 0 0" rpy="0 0 0"/>
            <geometry>
                <box size="1.0184356578293348 1.1917551016799879 1.746096361440699" />
            </geometry>
        </collision>
    </link>
    <link name="Leg22">
        <inertial>
            <origin xyz="1.2393512059887999 0 0" rpy="0 0 0"/>
            <mass value="1" />
            <inertia ixx="100" ixy="0" ixz="0" iyy="100" iyz="0" izz="100" />
        </inertial>
        <visual>
            <origin xyz="1.2393512059887999 0 0" rpy="0 0 0"/>
            <geometry>
                <box size="2.4787024119775998 1.6705701029246958 2.767412711229044" />
            </geometry>
            <material name="Blue">
                <color rgba="0 1.0 1.0 1.0"/>
            </material>
        </visual>
        <collision>
            <origin xyz="1.2393512059887999 0 0" rpy="0 0 0"/>
            <geometry>
                <box size="2.4787024119775998 1.6705701029246958 2.767412711229044" />
            </geometry>
        </collision>
    </link>
    <link name="Leg23">
        <inertial>
            <origin xyz="0 0.9184200381994382 0" rpy="0 0 0"/>
            <mass value="1" />
            <inertia ixx="100" ixy="0" ixz="0" iyy="100" iyz="0" izz="100" />
        </inertial>
        <visual>
            <origin xyz="0 0.9184200381994382 0" rpy="0 0 0"/>
            <geometry>
                <box size="1.547029232778526 1.8368400763988764 2.361355889756676" />
            </geometry>
            <material name="Blue">
                <color rgba="0 1.0 1.0 1.0"/>
            </material>
        </visual>
        <collision>
            <origin xyz="0 0.9184200381994382 0" rpy="0 0 0"/>
            <geometry>
                <box size="1.547029232778526 1.8368400763988764 2.361355889756676" />
            </geometry>
        </collision>
    </link>
    <link name="Leg24">
        <inertial>
            <origin xyz="0 0 0.7526607246634022" rpy="0 0 0"/>
            <mass value="1" />
            <inertia ixx="100" ixy="0" ixz="0" iyy="100" iyz="0" izz="100" />
        </inertial>
        <visual>
            <origin xyz="0 0 0.7526607246634022" rpy="0 0 0"/>
            <geometry>
                <box size="2.927437403968038 1.6895037788312794 1.5053214493268043" />
            </geometry>
            <material name="Blue">
                <color rgba="0 1.0 1.0 1.0"/>
            </material>
        </visual>
        <collision>
            <origin xyz="0 0 0.7526607246634022" rpy="0 0 0"/>
            <geometry>
                <box size="2.927437403968038 1.6895037788312794 1.5053214493268043" />
            </geometry>
        </collision>
    </link>
    <link name="Leg25">
        <inertial>
            <origin xyz="0.8748469844254357 0 0" rpy="0 0 0"/>
            <mass value="1" />
            <inertia ixx="100" ixy="0" ixz="0" iyy="100" iyz="0" izz="100" />
        </inertial>
        <visual>
            <origin xyz="0.8748469844254357 0 0" rpy="0 0 0"/>
            <geometry>
                <box size="1.7496939688508715 1.809213394133585 1.0834188409418994" />
            </geometry>
            <material name="Green">
                <color rgba="0 180.0 0.0 1.0"/>
            </material>
        </visual>
        <collision>
            <origin xyz="0.8748469844254357 0 0" rpy="0 0 0"/>
            <geometry>
                <box size="1.7496939688508715 1.809213394133585 1.0834188409418994" />
            </geometry>
        </collision>
    </link>
    <link name="Leg26">
        <inertial>
            <origin xyz="0 0 1.1440083164744788" rpy="0 0 0"/>
            <mass value="1" />
            <inertia ixx="100" ixy="0" ixz="0" iyy="100" iyz="0" izz="100" />
        </inertial>
        <visual>
            <origin xyz="0 0 1.1440083164744788" rpy="0 0 0"/>
            <geometry>
                <box size="2.021314662096814 1.5355245385994536 2.2880166329489575" />
            </geometry>
            <material name="Blue">
                <color rgba="0 1.0 1.0 1.0"/>
            </material>
        </visual>
        <collision>
            <origin xyz="0 0 1.1440083164744788" rpy="0 0 0"/>
            <geometry>
                <box size="2.021314662096814 1.5355245385994536 2.2880166329489575" />
            </geometry>
        </collision>
    </link>
    <joint name="Torso_Leg1" type="revolute">
       <parent link="Torso"/>
       <child  link="Leg1"/>
       <origin rpy="0 0 0" xyz="0 0 1.4956134371964758" />
     <axis xyz="1 0 0"/>
       <limit effort="0.0" lower="-3.14159" upper="3.14159" velocity="0.0"/>
    </joint>
    <joint name="Leg1_Leg2" type="revolute">
       <parent link="Leg1"/>
       <child  link="Leg2"/>
       <origin rpy="0 0 0" xyz="0 2.367539926508229 0" />
     <axis xyz="1 0 0"/>
       <limit effort="0.0" lower="-3.14159" upper="3.14159" velocity="0.0"/>
    </joint>
    <joint name="Leg1_Leg3" type="revolute">
       <parent link="Leg1"/>
       <child  link="Leg3"/>
       <origin rpy="0 0 0" xyz="0 2.367539926508229 0.7390234569797779" />
     <axis xyz="1 0 0"/>
       <limit effort="0.0" lower="-3.14159" upper="3.14159" velocity="0.0"/>
    </joint>
    <joint name="Leg1_Leg4" type="revolute">
       <parent link="Leg1"/>
       <child  link="Leg4"/>
       <origin rpy="0 0 0" xyz="1.374427069029382 2.367539926508229 0.7390234569797779" />
     <axis xyz="1 0 0"/>
       <limit effort="0.0" lower="-3.14159" upper="3.14159" velocity="0.0"/>
    </joint>
    <joint name="Leg2_Leg5" type="revolute">
       <parent link="Leg2"/>
       <child  link="Leg5"/>
       <origin rpy="0 0 0" xyz="0 1.4679020553622362 1.2302892959119305" />
     <axis xyz="1 0 0"/>
       <limit effort="0.0" lower="-3.14159" upper="3.14159" velocity="0.0"/>
    </joint>
    <joint name="Leg5_Leg6" type="revolute">
       <parent link="Leg5"/>
       <child  link="Leg6"/>
       <origin rpy="0 0 0" xyz="0 2.182032726064933 0" />
     <axis xyz="1 0 0"/>
       <limit effort="0.0" lower="-3.14159" upper="3.14159" velocity="0.0"/>
    </joint>
    <joint name="Leg2_Leg7" type="revolute">
       <parent link="Leg2"/>
       <child  link="Leg7"/>
       <origin rpy="0 0 0" xyz="0 1.4679020553622362 2.460578591823861" />
     <axis xyz="1 0 0"/>
       <limit effort="0.0" lower="-3.14159" upper="3.14159" velocity="0.0"/>
    </joint>
    <joint name="Leg4_Leg8" type="revolute">
       <parent link="Leg4"/>
       <child  link="Leg8"/>
       <origin rpy="0 0 0" xyz="0 2.5120562390202714 0" />
     <axis xyz="1 0 0"/>
       <limit effort="0.0" lower="-3.14159" upper="3.14159" velocity="0.0"/>
    </joint>
    <joint name="Leg7_Leg9" type="revolute">
       <parent link="Leg7"/>
       <child  link="Leg9"/>
       <origin rpy="0 0 0" xyz="0 0.5841163129267968 0.6637971356036614" />
     <axis xyz="1 0 0"/>
       <limit effort="0.0" lower="-3.14159" upper="3.14159" velocity="0.0"/>
    </joint>
    <joint name="Torso_Leg10" type="revolute">
       <parent link="Torso"/>
       <child  link="Leg10"/>
       <origin rpy="0 0 0" xyz="0 0.5054225356925279 1.0952576191140848" />
     <axis xyz="1 0 0"/>
       <limit effort="0.0" lower="-3.14159" upper="3.14159" velocity="0.0"/>
    </joint>
    <joint name="Leg6_Leg11" type="revolute">
       <parent link="Leg6"/>
       <child  link="Leg11"/>
       <origin rpy="0 0 0" xyz="0 1.0296174791991883 1.0925528665932134" />
     <axis xyz="1 0 0"/>
       <limit effort="0.0" lower="-3.14159" upper="3.14159" velocity="0.0"/>
    </joint>
    <joint name="Leg7_Leg12" type="revolute">
       <parent link="Leg7"/>
       <child  link="Leg12"/>
       <origin rpy="0 0 0" xyz="1.3659817406635035 0.5841163129267968 0.6637971356036614" />
     <axis xyz="1 0 0"/>
       <limit effort="0.0" lower="-3.14159" upper="3.14159" velocity="0.0"/>
    </joint>
    <joint name="Leg8_Leg13" type="revolute">
       <parent link="Leg8"/>
       <child  link="Leg13"/>
       <origin rpy="0 0 0" xyz="0 0.6743139674786501 1.4883722266905848" />
     <axis xyz="1 0 0"/>
       <limit effort="0.0" lower="-3.14159" upper="3.14159" velocity="0.0"/>
    </joint>
    <joint name="Leg3_Leg14" type="revolute">
       <parent link="Leg3"/>
       <child  link="Leg14"/>
       <origin rpy="0 0 0" xyz="1.2521679036976416 1.258813740434705 0" />
     <axis xyz="1 0 0"/>
       <limit effort="0.0" lower="-3.14159" upper="3.14159" velocity="0.0"/>
    </joint>
    <joint name="Leg4_Leg15" type="revolute">
       <parent link="Leg4"/>
       <child  link="Leg15"/>
       <origin rpy="0 0 0" xyz="0.6771519425779217 2.5120562390202714 0" />
     <axis xyz="1 0 0"/>
       <limit effort="0.0" lower="-3.14159" upper="3.14159" velocity="0.0"/>
    </joint>
    <joint name="Leg15_Leg16" type="revolute">
       <parent link="Leg15"/>
       <child  link="Leg16"/>
       <origin rpy="0 0 0" xyz="1.6981674288911754 0 0" />
     <axis xyz="1 0 0"/>
       <limit effort="0.0" lower="-3.14159" upper="3.14159" velocity="0.0"/>
    </joint>
    <joint name="Leg10_Leg17" type="revolute">
       <parent link="Leg10"/>
       <child  link="Leg17"/>
       <origin rpy="0 0 0" xyz="1.0076167815544803 1.3099232267682956 0" />
     <axis xyz="1 0 0"/>
       <limit effort="0.0" lower="-3.14159" upper="3.14159" velocity="0.0"/>
    </joint>
    <joint name="Leg11_Leg18" type="revolute">
       <parent link="Leg11"/>
       <child  link="Leg18"/>
       <origin rpy="0 0 0" xyz="1.1168918462150064 0 1.1617838584515048" />
     <axis xyz="1 0 0"/>
       <limit effort="0.0" lower="-3.14159" upper="3.14159" velocity="0.0"/>
    </joint>
    <joint name="Leg18_Leg19" type="revolute">
       <parent link="Leg18"/>
       <child  link="Leg19"/>
       <origin rpy="0 0 0" xyz="0 1.3741893636356384 0" />
     <axis xyz="1 0 0"/>
       <limit effort="0.0" lower="-3.14159" upper="3.14159" velocity="0.0"/>
    </joint>
    <joint name="Leg17_Leg20" type="revolute">
       <parent link="Leg17"/>
       <child  link="Leg20"/>
       <origin rpy="0 0 0" xyz="0.9743675211131974 0 0.8618839857747643" />
     <axis xyz="1 0 0"/>
       <limit effort="0.0" lower="-3.14159" upper="3.14159" velocity="0.0"/>
    </joint>
    <joint name="Leg13_Leg21" type="revolute">
       <parent link="Leg13"/>
       <child  link="Leg21"/>
       <origin rpy="0 0 0" xyz="1.264983709840922 0.9297338732938035 0" />
     <axis xyz="1 0 0"/>
       <limit effort="0.0" lower="-3.14159" upper="3.14159" velocity="0.0"/>
    </joint>
    <joint name="Leg18_Leg22" type="revolute">
       <parent link="Leg18"/>
       <child  link="Leg22"/>
       <origin rpy="0 0 0" xyz="1.3503978712468423 1.3741893636356384 0" />
     <axis xyz="1 0 0"/>
       <limit effort="0.0" lower="-3.14159" upper="3.14159" velocity="0.0"/>
    </joint>
    <joint name="Leg11_Leg23" type="revolute">
       <parent link="Leg11"/>
       <child  link="Leg23"/>
       <origin rpy="0 0 0" xyz="1.1168918462150064 1.4713303815383059 1.1617838584515048" />
     <axis xyz="1 0 0"/>
       <limit effort="0.0" lower="-3.14159" upper="3.14159" velocity="0.0"/>
    </joint>
    <joint name="Leg15_Leg24" type="revolute">
       <parent link="Leg15"/>
       <child  link="Leg24"/>
       <origin rpy="0 0 0" xyz="1.6981674288911754 0 1.041210819285757" />
     <axis xyz="1 0 0"/>
       <limit effort="0.0" lower="-3.14159" upper="3.14159" velocity="0.0"/>
    </joint>
    <joint name="Leg9_Leg25" type="revolute">
       <parent link="Leg9"/>
       <child  link="Leg25"/>
       <origin rpy="0 0 0" xyz="0.8630099154882587 1.0081150439832487 0" />
     <axis xyz="1 0 0"/>
       <limit effort="0.0" lower="-3.14159" upper="3.14159" velocity="0.0"/>
    </joint>
    <joint name="Leg17_Leg26" type="revolute">
       <parent link="Leg17"/>
       <child  link="Leg26"/>
       <origin rpy="0 0 0" xyz="0.9743675211131974 0 1.7237679715495287" />
     <axis xyz="1 0 0"/>
       <limit effort="0.0" lower="-3.14159" upper="3.14159" velocity="0.0"/>
    </joint>
</robot>