<robot name = "robot">
    <link name="Torso">
        <inertial>
            <origin xyz="0 0 0.6777291796234532" rpy="0 0 0"/>
            <mass value="1" />
            <inertia ixx="100" ixy="0" ixz="0" iyy="100" iyz="0" izz="100" />
        </inertial>
        <visual>
            <origin xyz="0 0 0.6777291796234532" rpy="0 0 0"/>
            <geometry>
                <box size="2.5783258108036193 2.672520906117353 1.3554583592469065" />
            </geometry>
            <material name="Green">
                <color rgba="0 180.0 0.0 1.0"/>
            </material>
        </visual>
        <collision>
            <origin xyz="0 0 0.6777291796234532" rpy="0 0 0"/>
            <geometry>
                <box size="2.5783258108036193 2.672520906117353 1.3554583592469065" />
            </geometry>
        </collision>
    </link>
    <link name="Leg1">
        <inertial>
            <origin xyz="0 0 0.7641941049828446" rpy="0 0 0"/>
            <mass value="1" />
            <inertia ixx="100" ixy="0" ixz="0" iyy="100" iyz="0" izz="100" />
        </inertial>
        <visual>
            <origin xyz="0 0 0.7641941049828446" rpy="0 0 0"/>
            <geometry>
                <box size="2.7286000684378027 2.1458695655307207 1.5283882099656891" />
            </geometry>
            <material name="Blue">
                <color rgba="0 1.0 1.0 1.0"/>
            </material>
        </visual>
        <collision>
            <origin xyz="0 0 0.7641941049828446" rpy="0 0 0"/>
            <geometry>
                <box size="2.7286000684378027 2.1458695655307207 1.5283882099656891" />
            </geometry>
        </collision>
    </link>
    <link name="Leg2">
        <inertial>
            <origin xyz="0 0.835759817316801 0" rpy="0 0 0"/>
            <mass value="1" />
            <inertia ixx="100" ixy="0" ixz="0" iyy="100" iyz="0" izz="100" />
        </inertial>
        <visual>
            <origin xyz="0 0.835759817316801 0" rpy="0 0 0"/>
            <geometry>
                <box size="2.0586869698427446 1.671519634633602 2.7295688846450927" />
            </geometry>
            <material name="Green">
                <color rgba="0 180.0 0.0 1.0"/>
            </material>
        </visual>
        <collision>
            <origin xyz="0 0.835759817316801 0" rpy="0 0 0"/>
            <geometry>
                <box size="2.0586869698427446 1.671519634633602 2.7295688846450927" />
            </geometry>
        </collision>
    </link>
    <link name="Leg3">
        <inertial>
            <origin xyz="0.5896354346999386 0 0" rpy="0 0 0"/>
            <mass value="1" />
            <inertia ixx="100" ixy="0" ixz="0" iyy="100" iyz="0" izz="100" />
        </inertial>
        <visual>
            <origin xyz="0.5896354346999386 0 0" rpy="0 0 0"/>
            <geometry>
                <box size="1.1792708693998772 2.5965161505202317 1.938858941620084" />
            </geometry>
            <material name="Blue">
                <color rgba="0 1.0 1.0 1.0"/>
            </material>
        </visual>
        <collision>
            <origin xyz="0.5896354346999386 0 0" rpy="0 0 0"/>
            <geometry>
                <box size="1.1792708693998772 2.5965161505202317 1.938858941620084" />
            </geometry>
        </collision>
    </link>
    <link name="Leg4">
        <inertial>
            <origin xyz="0 0.9748468266679117 0" rpy="0 0 0"/>
            <mass value="1" />
            <inertia ixx="100" ixy="0" ixz="0" iyy="100" iyz="0" izz="100" />
        </inertial>
        <visual>
            <origin xyz="0 0.9748468266679117 0" rpy="0 0 0"/>
            <geometry>
                <box size="2.647294171886793 1.9496936533358233 1.382114698344486" />
            </geometry>
            <material name="Blue">
                <color rgba="0 1.0 1.0 1.0"/>
            </material>
        </visual>
        <collision>
            <origin xyz="0 0.9748468266679117 0" rpy="0 0 0"/>
            <geometry>
                <box size="2.647294171886793 1.9496936533358233 1.382114698344486" />
            </geometry>
        </collision>
    </link>
    <link name="Leg5">
        <inertial>
            <origin xyz="0.8916634957820915 0 0" rpy="0 0 0"/>
            <mass value="1" />
            <inertia ixx="100" ixy="0" ixz="0" iyy="100" iyz="0" izz="100" />
        </inertial>
        <visual>
            <origin xyz="0.8916634957820915 0 0" rpy="0 0 0"/>
            <geometry>
                <box size="1.783326991564183 2.5813360920467074 1.8016277494733728" />
            </geometry>
            <material name="Blue">
                <color rgba="0 1.0 1.0 1.0"/>
            </material>
        </visual>
        <collision>
            <origin xyz="0.8916634957820915 0 0" rpy="0 0 0"/>
            <geometry>
                <box size="1.783326991564183 2.5813360920467074 1.8016277494733728" />
            </geometry>
        </collision>
    </link>
    <link name="Leg6">
        <inertial>
            <origin xyz="0 0.6914780007364282 0" rpy="0 0 0"/>
            <mass value="1" />
            <inertia ixx="100" ixy="0" ixz="0" iyy="100" iyz="0" izz="100" />
        </inertial>
        <visual>
            <origin xyz="0 0.6914780007364282 0" rpy="0 0 0"/>
            <geometry>
                <box size="1.2423325015587734 1.3829560014728564 1.8791101755140478" />
            </geometry>
            <material name="Green">
                <color rgba="0 180.0 0.0 1.0"/>
            </material>
        </visual>
        <collision>
            <origin xyz="0 0.6914780007364282 0" rpy="0 0 0"/>
            <geometry>
                <box size="1.2423325015587734 1.3829560014728564 1.8791101755140478" />
            </geometry>
        </collision>
    </link>
    <link name="Leg7">
        <inertial>
            <origin xyz="0 0 0.5122395939707568" rpy="0 0 0"/>
            <mass value="1" />
            <inertia ixx="100" ixy="0" ixz="0" iyy="100" iyz="0" izz="100" />
        </inertial>
        <visual>
            <origin xyz="0 0 0.5122395939707568" rpy="0 0 0"/>
            <geometry>
                <box size="1.9674980870907806 2.6108283090035718 1.0244791879415136" />
            </geometry>
            <material name="Green">
                <color rgba="0 180.0 0.0 1.0"/>
            </material>
        </visual>
        <collision>
            <origin xyz="0 0 0.5122395939707568" rpy="0 0 0"/>
            <geometry>
                <box size="1.9674980870907806 2.6108283090035718 1.0244791879415136" />
            </geometry>
        </collision>
    </link>
    <link name="Leg8">
        <inertial>
            <origin xyz="0 0 0.9165985830873669" rpy="0 0 0"/>
            <mass value="1" />
            <inertia ixx="100" ixy="0" ixz="0" iyy="100" iyz="0" izz="100" />
        </inertial>
        <visual>
            <origin xyz="0 0 0.9165985830873669" rpy="0 0 0"/>
            <geometry>
                <box size="2.4320766284524833 2.9812375041212595 1.8331971661747337" />
            </geometry>
            <material name="Blue">
                <color rgba="0 1.0 1.0 1.0"/>
            </material>
        </visual>
        <collision>
            <origin xyz="0 0 0.9165985830873669" rpy="0 0 0"/>
            <geometry>
                <box size="2.4320766284524833 2.9812375041212595 1.8331971661747337" />
            </geometry>
        </collision>
    </link>
    <link name="Leg9">
        <inertial>
            <origin xyz="0 0 0.932592101261566" rpy="0 0 0"/>
            <mass value="1" />
            <inertia ixx="100" ixy="0" ixz="0" iyy="100" iyz="0" izz="100" />
        </inertial>
        <visual>
            <origin xyz="0 0 0.932592101261566" rpy="0 0 0"/>
            <geometry>
                <box size="1.515412980685856 1.857680455843271 1.865184202523132" />
            </geometry>
            <material name="Green">
                <color rgba="0 180.0 0.0 1.0"/>
            </material>
        </visual>
        <collision>
            <origin xyz="0 0 0.932592101261566" rpy="0 0 0"/>
            <geometry>
                <box size="1.515412980685856 1.857680455843271 1.865184202523132" />
            </geometry>
        </collision>
    </link>
    <link name="Leg10">
        <inertial>
            <origin xyz="0 0 0.5709188400599715" rpy="0 0 0"/>
            <mass value="1" />
            <inertia ixx="100" ixy="0" ixz="0" iyy="100" iyz="0" izz="100" />
        </inertial>
        <visual>
            <origin xyz="0 0 0.5709188400599715" rpy="0 0 0"/>
            <geometry>
                <box size="1.2719954489654461 2.7202443072884765 1.141837680119943" />
            </geometry>
            <material name="Green">
                <color rgba="0 180.0 0.0 1.0"/>
            </material>
        </visual>
        <collision>
            <origin xyz="0 0 0.5709188400599715" rpy="0 0 0"/>
            <geometry>
                <box size="1.2719954489654461 2.7202443072884765 1.141837680119943" />
            </geometry>
        </collision>
    </link>
    <link name="Leg11">
        <inertial>
            <origin xyz="0 0 1.002999715357132" rpy="0 0 0"/>
            <mass value="1" />
            <inertia ixx="100" ixy="0" ixz="0" iyy="100" iyz="0" izz="100" />
        </inertial>
        <visual>
            <origin xyz="0 0 1.002999715357132" rpy="0 0 0"/>
            <geometry>
                <box size="1.9484061884709285 2.36510359926214 2.005999430714264" />
            </geometry>
            <material name="Green">
                <color rgba="0 180.0 0.0 1.0"/>
            </material>
        </visual>
        <collision>
            <origin xyz="0 0 1.002999715357132" rpy="0 0 0"/>
            <geometry>
                <box size="1.9484061884709285 2.36510359926214 2.005999430714264" />
            </geometry>
        </collision>
    </link>
    <link name="Leg12">
        <inertial>
            <origin xyz="1.3758082022276645 0 0" rpy="0 0 0"/>
            <mass value="1" />
            <inertia ixx="100" ixy="0" ixz="0" iyy="100" iyz="0" izz="100" />
        </inertial>
        <visual>
            <origin xyz="1.3758082022276645 0 0" rpy="0 0 0"/>
            <geometry>
                <box size="2.751616404455329 2.163742808009486 1.771121154080975" />
            </geometry>
            <material name="Green">
                <color rgba="0 180.0 0.0 1.0"/>
            </material>
        </visual>
        <collision>
            <origin xyz="1.3758082022276645 0 0" rpy="0 0 0"/>
            <geometry>
                <box size="2.751616404455329 2.163742808009486 1.771121154080975" />
            </geometry>
        </collision>
    </link>
    <link name="Leg13">
        <inertial>
            <origin xyz="0.6828515636331991 0 0" rpy="0 0 0"/>
            <mass value="1" />
            <inertia ixx="100" ixy="0" ixz="0" iyy="100" iyz="0" izz="100" />
        </inertial>
        <visual>
            <origin xyz="0.6828515636331991 0 0" rpy="0 0 0"/>
            <geometry>
                <box size="1.3657031272663982 1.330841185012408 1.7816448968384864" />
            </geometry>
            <material name="Green">
                <color rgba="0 180.0 0.0 1.0"/>
            </material>
        </visual>
        <collision>
            <origin xyz="0.6828515636331991 0 0" rpy="0 0 0"/>
            <geometry>
                <box size="1.3657031272663982 1.330841185012408 1.7816448968384864" />
            </geometry>
        </collision>
    </link>
    <link name="Leg14">
        <inertial>
            <origin xyz="0.8937449642628718 0 0" rpy="0 0 0"/>
            <mass value="1" />
            <inertia ixx="100" ixy="0" ixz="0" iyy="100" iyz="0" izz="100" />
        </inertial>
        <visual>
            <origin xyz="0.8937449642628718 0 0" rpy="0 0 0"/>
            <geometry>
                <box size="1.7874899285257435 1.314024408714387 1.7094416182358503" />
            </geometry>
            <material name="Blue">
                <color rgba="0 1.0 1.0 1.0"/>
            </material>
        </visual>
        <collision>
            <origin xyz="0.8937449642628718 0 0" rpy="0 0 0"/>
            <geometry>
                <box size="1.7874899285257435 1.314024408714387 1.7094416182358503" />
            </geometry>
        </collision>
    </link>
    <link name="Leg15">
        <inertial>
            <origin xyz="0 0 1.1893018363586165" rpy="0 0 0"/>
            <mass value="1" />
            <inertia ixx="100" ixy="0" ixz="0" iyy="100" iyz="0" izz="100" />
        </inertial>
        <visual>
            <origin xyz="0 0 1.1893018363586165" rpy="0 0 0"/>
            <geometry>
                <box size="2.2425838958170763 1.5880349423149147 2.378603672717233" />
            </geometry>
            <material name="Blue">
                <color rgba="0 1.0 1.0 1.0"/>
            </material>
        </visual>
        <collision>
            <origin xyz="0 0 1.1893018363586165" rpy="0 0 0"/>
            <geometry>
                <box size="2.2425838958170763 1.5880349423149147 2.378603672717233" />
            </geometry>
        </collision>
    </link>
    <link name="Leg16">
        <inertial>
            <origin xyz="0 0 1.0978069693726398" rpy="0 0 0"/>
            <mass value="1" />
            <inertia ixx="100" ixy="0" ixz="0" iyy="100" iyz="0" izz="100" />
        </inertial>
        <visual>
            <origin xyz="0 0 1.0978069693726398" rpy="0 0 0"/>
            <geometry>
                <box size="2.9508880807193574 2.2632263242334907 2.1956139387452795" />
            </geometry>
            <material name="Green">
                <color rgba="0 180.0 0.0 1.0"/>
            </material>
        </visual>
        <collision>
            <origin xyz="0 0 1.0978069693726398" rpy="0 0 0"/>
            <geometry>
                <box size="2.9508880807193574 2.2632263242334907 2.1956139387452795" />
            </geometry>
        </collision>
    </link>
    <link name="Leg17">
        <inertial>
            <origin xyz="0.9804231469060994 0 0" rpy="0 0 0"/>
            <mass value="1" />
            <inertia ixx="100" ixy="0" ixz="0" iyy="100" iyz="0" izz="100" />
        </inertial>
        <visual>
            <origin xyz="0.9804231469060994 0 0" rpy="0 0 0"/>
            <geometry>
                <box size="1.9608462938121989 2.288798543884657 2.4460135101429508" />
            </geometry>
            <material name="Green">
                <color rgba="0 180.0 0.0 1.0"/>
            </material>
        </visual>
        <collision>
            <origin xyz="0.9804231469060994 0 0" rpy="0 0 0"/>
            <geometry>
                <box size="1.9608462938121989 2.288798543884657 2.4460135101429508" />
            </geometry>
        </collision>
    </link>
    <link name="Leg18">
        <inertial>
            <origin xyz="0 0 1.15123595969308" rpy="0 0 0"/>
            <mass value="1" />
            <inertia ixx="100" ixy="0" ixz="0" iyy="100" iyz="0" izz="100" />
        </inertial>
        <visual>
            <origin xyz="0 0 1.15123595969308" rpy="0 0 0"/>
            <geometry>
                <box size="1.8962316858455717 1.3141115427411585 2.30247191938616" />
            </geometry>
            <material name="Blue">
                <color rgba="0 1.0 1.0 1.0"/>
            </material>
        </visual>
        <collision>
            <origin xyz="0 0 1.15123595969308" rpy="0 0 0"/>
            <geometry>
                <box size="1.8962316858455717 1.3141115427411585 2.30247191938616" />
            </geometry>
        </collision>
    </link>
    <link name="Leg19">
        <inertial>
            <origin xyz="1.146785970799489 0 0" rpy="0 0 0"/>
            <mass value="1" />
            <inertia ixx="100" ixy="0" ixz="0" iyy="100" iyz="0" izz="100" />
        </inertial>
        <visual>
            <origin xyz="1.146785970799489 0 0" rpy="0 0 0"/>
            <geometry>
                <box size="2.293571941598978 2.3646471038484513 2.09031846373139" />
            </geometry>
            <material name="Green">
                <color rgba="0 180.0 0.0 1.0"/>
            </material>
        </visual>
        <collision>
            <origin xyz="1.146785970799489 0 0" rpy="0 0 0"/>
            <geometry>
                <box size="2.293571941598978 2.3646471038484513 2.09031846373139" />
            </geometry>
        </collision>
    </link>
    <link name="Leg20">
        <inertial>
            <origin xyz="1.1970646951581838 0 0" rpy="0 0 0"/>
            <mass value="1" />
            <inertia ixx="100" ixy="0" ixz="0" iyy="100" iyz="0" izz="100" />
        </inertial>
        <visual>
            <origin xyz="1.1970646951581838 0 0" rpy="0 0 0"/>
            <geometry>
                <box size="2.3941293903163676 2.4165670575536415 1.8459240160512078" />
            </geometry>
            <material name="Green">
                <color rgba="0 180.0 0.0 1.0"/>
            </material>
        </visual>
        <collision>
            <origin xyz="1.1970646951581838 0 0" rpy="0 0 0"/>
            <geometry>
                <box size="2.3941293903163676 2.4165670575536415 1.8459240160512078" />
            </geometry>
        </collision>
    </link>
    <link name="Leg21">
        <inertial>
            <origin xyz="0.6939021049209702 0 0" rpy="0 0 0"/>
            <mass value="1" />
            <inertia ixx="100" ixy="0" ixz="0" iyy="100" iyz="0" izz="100" />
        </inertial>
        <visual>
            <origin xyz="0.6939021049209702 0 0" rpy="0 0 0"/>
            <geometry>
                <box size="1.3878042098419403 1.706242315681645 1.5006513331508673" />
            </geometry>
            <material name="Green">
                <color rgba="0 180.0 0.0 1.0"/>
            </material>
        </visual>
        <collision>
            <origin xyz="0.6939021049209702 0 0" rpy="0 0 0"/>
            <geometry>
                <box size="1.3878042098419403 1.706242315681645 1.5006513331508673" />
            </geometry>
        </collision>
    </link>
    <link name="Leg22">
        <inertial>
            <origin xyz="0 0 0.5384546356978461" rpy="0 0 0"/>
            <mass value="1" />
            <inertia ixx="100" ixy="0" ixz="0" iyy="100" iyz="0" izz="100" />
        </inertial>
        <visual>
            <origin xyz="0 0 0.5384546356978461" rpy="0 0 0"/>
            <geometry>
                <box size="1.2192740123125578 1.0379385218121588 1.0769092713956923" />
            </geometry>
            <material name="Green">
                <color rgba="0 180.0 0.0 1.0"/>
            </material>
        </visual>
        <collision>
            <origin xyz="0 0 0.5384546356978461" rpy="0 0 0"/>
            <geometry>
                <box size="1.2192740123125578 1.0379385218121588 1.0769092713956923" />
            </geometry>
        </collision>
    </link>
    <link name="Leg23">
        <inertial>
            <origin xyz="0 0 0.8523695408913261" rpy="0 0 0"/>
            <mass value="1" />
            <inertia ixx="100" ixy="0" ixz="0" iyy="100" iyz="0" izz="100" />
        </inertial>
        <visual>
            <origin xyz="0 0 0.8523695408913261" rpy="0 0 0"/>
            <geometry>
                <box size="1.734242518935004 1.6583851738769617 1.7047390817826522" />
            </geometry>
            <material name="Blue">
                <color rgba="0 1.0 1.0 1.0"/>
            </material>
        </visual>
        <collision>
            <origin xyz="0 0 0.8523695408913261" rpy="0 0 0"/>
            <geometry>
                <box size="1.734242518935004 1.6583851738769617 1.7047390817826522" />
            </geometry>
        </collision>
    </link>
    <link name="Leg24">
        <inertial>
            <origin xyz="0 0 0.8719240866730712" rpy="0 0 0"/>
            <mass value="1" />
            <inertia ixx="100" ixy="0" ixz="0" iyy="100" iyz="0" izz="100" />
        </inertial>
        <visual>
            <origin xyz="0 0 0.8719240866730712" rpy="0 0 0"/>
            <geometry>
                <box size="2.409201422299979 1.6717612376949842 1.7438481733461424" />
            </geometry>
            <material name="Green">
                <color rgba="0 180.0 0.0 1.0"/>
            </material>
        </visual>
        <collision>
            <origin xyz="0 0 0.8719240866730712" rpy="0 0 0"/>
            <geometry>
                <box size="2.409201422299979 1.6717612376949842 1.7438481733461424" />
            </geometry>
        </collision>
    </link>
    <joint name="Torso_Leg1" type="revolute">
       <parent link="Torso"/>
       <child  link="Leg1"/>
       <origin rpy="0 0 0" xyz="0 0 1.3554583592469065" />
     <axis xyz="1 0 0"/>
       <limit effort="0.0" lower="-3.14159" upper="3.14159" velocity="0.0"/>
    </joint>
    <joint name="Leg1_Leg2" type="revolute">
       <parent link="Leg1"/>
       <child  link="Leg2"/>
       <origin rpy="0 0 0" xyz="0 1.671519634633602 0" />
     <axis xyz="1 0 0"/>
       <limit effort="0.0" lower="-3.14159" upper="3.14159" velocity="0.0"/>
    </joint>
    <joint name="Leg1_Leg3" type="revolute">
       <parent link="Leg1"/>
       <child  link="Leg3"/>
       <origin rpy="0 0 0" xyz="1.0293434849213723 1.671519634633602 0" />
     <axis xyz="1 0 0"/>
       <limit effort="0.0" lower="-3.14159" upper="3.14159" velocity="0.0"/>
    </joint>
    <joint name="Torso_Leg4" type="revolute">
       <parent link="Torso"/>
       <child  link="Leg4"/>
       <origin rpy="0 0 0" xyz="0 1.0729347827653604 0.7641941049828446" />
     <axis xyz="1 0 0"/>
       <limit effort="0.0" lower="-3.14159" upper="3.14159" velocity="0.0"/>
    </joint>
    <joint name="Leg3_Leg5" type="revolute">
       <parent link="Leg3"/>
       <child  link="Leg5"/>
       <origin rpy="0 0 0" xyz="1.3236470859433964 0.9748468266679117 0" />
     <axis xyz="1 0 0"/>
       <limit effort="0.0" lower="-3.14159" upper="3.14159" velocity="0.0"/>
    </joint>
    <joint name="Leg2_Leg6" type="revolute">
       <parent link="Leg2"/>
       <child  link="Leg6"/>
       <origin rpy="0 0 0" xyz="0.5896354346999386 1.2982580752601158 0" />
     <axis xyz="1 0 0"/>
       <limit effort="0.0" lower="-3.14159" upper="3.14159" velocity="0.0"/>
    </joint>
    <joint name="Leg6_Leg7" type="revolute">
       <parent link="Leg6"/>
       <child  link="Leg7"/>
       <origin rpy="0 0 0" xyz="0 0 1.0244791879415136" />
     <axis xyz="1 0 0"/>
       <limit effort="0.0" lower="-3.14159" upper="3.14159" velocity="0.0"/>
    </joint>
    <joint name="Leg4_Leg8" type="revolute">
       <parent link="Leg4"/>
       <child  link="Leg8"/>
       <origin rpy="0 0 0" xyz="0.8916634957820915 0 0.9008138747366864" />
     <axis xyz="1 0 0"/>
       <limit effort="0.0" lower="-3.14159" upper="3.14159" velocity="0.0"/>
    </joint>
    <joint name="Leg1_Leg9" type="revolute">
       <parent link="Leg1"/>
       <child  link="Leg9"/>
       <origin rpy="0 0 0" xyz="1.0293434849213723 1.671519634633602 1.3647844423225464" />
     <axis xyz="1 0 0"/>
       <limit effort="0.0" lower="-3.14159" upper="3.14159" velocity="0.0"/>
    </joint>
    <joint name="Leg3_Leg10" type="revolute">
       <parent link="Leg3"/>
       <child  link="Leg10"/>
       <origin rpy="0 0 0" xyz="1.3236470859433964 0.9748468266679117 0.691057349172243" />
     <axis xyz="1 0 0"/>
       <limit effort="0.0" lower="-3.14159" upper="3.14159" velocity="0.0"/>
    </joint>
    <joint name="Leg7_Leg11" type="revolute">
       <parent link="Leg7"/>
       <child  link="Leg11"/>
       <origin rpy="0 0 0" xyz="0 0 1.8331971661747337" />
     <axis xyz="1 0 0"/>
       <limit effort="0.0" lower="-3.14159" upper="3.14159" velocity="0.0"/>
    </joint>
    <joint name="Leg9_Leg12" type="revolute">
       <parent link="Leg9"/>
       <child  link="Leg12"/>
       <origin rpy="0 0 0" xyz="0.6359977244827231 0 0.5709188400599715" />
     <axis xyz="1 0 0"/>
       <limit effort="0.0" lower="-3.14159" upper="3.14159" velocity="0.0"/>
    </joint>
    <joint name="Torso_Leg13" type="revolute">
       <parent link="Torso"/>
       <child  link="Leg13"/>
       <origin rpy="0 0 0" xyz="1.3643000342189013 1.0729347827653604 0.7641941049828446" />
     <axis xyz="1 0 0"/>
       <limit effort="0.0" lower="-3.14159" upper="3.14159" velocity="0.0"/>
    </joint>
    <joint name="Leg11_Leg14" type="revolute">
       <parent link="Leg11"/>
       <child  link="Leg14"/>
       <origin rpy="0 0 0" xyz="2.751616404455329 0 0" />
     <axis xyz="1 0 0"/>
       <limit effort="0.0" lower="-3.14159" upper="3.14159" velocity="0.0"/>
    </joint>
    <joint name="Leg10_Leg15" type="revolute">
       <parent link="Leg10"/>
       <child  link="Leg15"/>
       <origin rpy="0 0 0" xyz="0 0 2.005999430714264" />
     <axis xyz="1 0 0"/>
       <limit effort="0.0" lower="-3.14159" upper="3.14159" velocity="0.0"/>
    </joint>
    <joint name="Leg9_Leg16" type="revolute">
       <parent link="Leg9"/>
       <child  link="Leg16"/>
       <origin rpy="0 0 0" xyz="0.6359977244827231 0 1.141837680119943" />
     <axis xyz="1 0 0"/>
       <limit effort="0.0" lower="-3.14159" upper="3.14159" velocity="0.0"/>
    </joint>
    <joint name="Leg8_Leg17" type="revolute">
       <parent link="Leg8"/>
       <child  link="Leg17"/>
       <origin rpy="0 0 0" xyz="0.757706490342928 0 0.932592101261566" />
     <axis xyz="1 0 0"/>
       <limit effort="0.0" lower="-3.14159" upper="3.14159" velocity="0.0"/>
    </joint>
    <joint name="Leg8_Leg18" type="revolute">
       <parent link="Leg8"/>
       <child  link="Leg18"/>
       <origin rpy="0 0 0" xyz="0.757706490342928 0 1.865184202523132" />
     <axis xyz="1 0 0"/>
       <limit effort="0.0" lower="-3.14159" upper="3.14159" velocity="0.0"/>
    </joint>
    <joint name="Leg13_Leg19" type="revolute">
       <parent link="Leg13"/>
       <child  link="Leg19"/>
       <origin rpy="0 0 0" xyz="1.7874899285257435 0 0" />
     <axis xyz="1 0 0"/>
       <limit effort="0.0" lower="-3.14159" upper="3.14159" velocity="0.0"/>
    </joint>
    <joint name="Leg7_Leg20" type="revolute">
       <parent link="Leg7"/>
       <child  link="Leg20"/>
       <origin rpy="0 0 0" xyz="1.2160383142262416 0 1.8331971661747337" />
     <axis xyz="1 0 0"/>
       <limit effort="0.0" lower="-3.14159" upper="3.14159" velocity="0.0"/>
    </joint>
    <joint name="Leg4_Leg21" type="revolute">
       <parent link="Leg4"/>
       <child  link="Leg21"/>
       <origin rpy="0 0 0" xyz="1.783326991564183 0 0.9008138747366864" />
     <axis xyz="1 0 0"/>
       <limit effort="0.0" lower="-3.14159" upper="3.14159" velocity="0.0"/>
    </joint>
    <joint name="Leg2_Leg22" type="revolute">
       <parent link="Leg2"/>
       <child  link="Leg22"/>
       <origin rpy="0 0 0" xyz="0.5896354346999386 1.2982580752601158 0.969429470810042" />
     <axis xyz="1 0 0"/>
       <limit effort="0.0" lower="-3.14159" upper="3.14159" velocity="0.0"/>
    </joint>
    <joint name="Leg15_Leg23" type="revolute">
       <parent link="Leg15"/>
       <child  link="Leg23"/>
       <origin rpy="0 0 0" xyz="0 0 2.1956139387452795" />
     <axis xyz="1 0 0"/>
       <limit effort="0.0" lower="-3.14159" upper="3.14159" velocity="0.0"/>
    </joint>
    <joint name="Leg20_Leg24" type="revolute">
       <parent link="Leg20"/>
       <child  link="Leg24"/>
       <origin rpy="0 0 0" xyz="0.6939021049209702 0 0.7503256665754336" />
     <axis xyz="1 0 0"/>
       <limit effort="0.0" lower="-3.14159" upper="3.14159" velocity="0.0"/>
    </joint>
</robot>