<robot name = "robot">
    <link name="Torso">
        <inertial>
            <origin xyz="0 0 0.5634203059860814" rpy="0 0 0"/>
            <mass value="1" />
            <inertia ixx="100" ixy="0" ixz="0" iyy="100" iyz="0" izz="100" />
        </inertial>
        <visual>
            <origin xyz="0 0 0.5634203059860814" rpy="0 0 0"/>
            <geometry>
                <box size="2.945314704518875 1.3794322906119678 1.1268406119721628" />
            </geometry>
            <material name="Green">
                <color rgba="0 180.0 0.0 1.0"/>
            </material>
        </visual>
        <collision>
            <origin xyz="0 0 0.5634203059860814" rpy="0 0 0"/>
            <geometry>
                <box size="2.945314704518875 1.3794322906119678 1.1268406119721628" />
            </geometry>
        </collision>
    </link>
    <link name="Leg1">
        <inertial>
            <origin xyz="0 1.3644328974995699 0" rpy="0 0 0"/>
            <mass value="1" />
            <inertia ixx="100" ixy="0" ixz="0" iyy="100" iyz="0" izz="100" />
        </inertial>
        <visual>
            <origin xyz="0 1.3644328974995699 0" rpy="0 0 0"/>
            <geometry>
                <box size="1.6258458671109277 2.7288657949991397 1.214961733102087" />
            </geometry>
            <material name="Green">
                <color rgba="0 180.0 0.0 1.0"/>
            </material>
        </visual>
        <collision>
            <origin xyz="0 1.3644328974995699 0" rpy="0 0 0"/>
            <geometry>
                <box size="1.6258458671109277 2.7288657949991397 1.214961733102087" />
            </geometry>
        </collision>
    </link>
    <link name="Leg2">
        <inertial>
            <origin xyz="0 1.1436473625375831 0" rpy="0 0 0"/>
            <mass value="1" />
            <inertia ixx="100" ixy="0" ixz="0" iyy="100" iyz="0" izz="100" />
        </inertial>
        <visual>
            <origin xyz="0 1.1436473625375831 0" rpy="0 0 0"/>
            <geometry>
                <box size="2.423094942648073 2.2872947250751663 1.1726137437924833" />
            </geometry>
            <material name="Green">
                <color rgba="0 180.0 0.0 1.0"/>
            </material>
        </visual>
        <collision>
            <origin xyz="0 1.1436473625375831 0" rpy="0 0 0"/>
            <geometry>
                <box size="2.423094942648073 2.2872947250751663 1.1726137437924833" />
            </geometry>
        </collision>
    </link>
    <link name="Leg3">
        <inertial>
            <origin xyz="0 0 1.081975678383491" rpy="0 0 0"/>
            <mass value="1" />
            <inertia ixx="100" ixy="0" ixz="0" iyy="100" iyz="0" izz="100" />
        </inertial>
        <visual>
            <origin xyz="0 0 1.081975678383491" rpy="0 0 0"/>
            <geometry>
                <box size="2.5533464329467526 2.678611208768702 2.163951356766982" />
            </geometry>
            <material name="Green">
                <color rgba="0 180.0 0.0 1.0"/>
            </material>
        </visual>
        <collision>
            <origin xyz="0 0 1.081975678383491" rpy="0 0 0"/>
            <geometry>
                <box size="2.5533464329467526 2.678611208768702 2.163951356766982" />
            </geometry>
        </collision>
    </link>
    <link name="Leg4">
        <inertial>
            <origin xyz="0.7655666273630696 0 0" rpy="0 0 0"/>
            <mass value="1" />
            <inertia ixx="100" ixy="0" ixz="0" iyy="100" iyz="0" izz="100" />
        </inertial>
        <visual>
            <origin xyz="0.7655666273630696 0 0" rpy="0 0 0"/>
            <geometry>
                <box size="1.5311332547261391 2.9081749698157853 2.9188567479346705" />
            </geometry>
            <material name="Green">
                <color rgba="0 180.0 0.0 1.0"/>
            </material>
        </visual>
        <collision>
            <origin xyz="0.7655666273630696 0 0" rpy="0 0 0"/>
            <geometry>
                <box size="1.5311332547261391 2.9081749698157853 2.9188567479346705" />
            </geometry>
        </collision>
    </link>
    <link name="Leg5">
        <inertial>
            <origin xyz="0 1.028885834235501 0" rpy="0 0 0"/>
            <mass value="1" />
            <inertia ixx="100" ixy="0" ixz="0" iyy="100" iyz="0" izz="100" />
        </inertial>
        <visual>
            <origin xyz="0 1.028885834235501 0" rpy="0 0 0"/>
            <geometry>
                <box size="2.4043151543172105 2.057771668471002 2.9250457328630093" />
            </geometry>
            <material name="Green">
                <color rgba="0 180.0 0.0 1.0"/>
            </material>
        </visual>
        <collision>
            <origin xyz="0 1.028885834235501 0" rpy="0 0 0"/>
            <geometry>
                <box size="2.4043151543172105 2.057771668471002 2.9250457328630093" />
            </geometry>
        </collision>
    </link>
    <link name="Leg6">
        <inertial>
            <origin xyz="0 0 1.0539391086832404" rpy="0 0 0"/>
            <mass value="1" />
            <inertia ixx="100" ixy="0" ixz="0" iyy="100" iyz="0" izz="100" />
        </inertial>
        <visual>
            <origin xyz="0 0 1.0539391086832404" rpy="0 0 0"/>
            <geometry>
                <box size="2.03077424521089 1.5506523837282014 2.1078782173664807" />
            </geometry>
            <material name="Blue">
                <color rgba="0 1.0 1.0 1.0"/>
            </material>
        </visual>
        <collision>
            <origin xyz="0 0 1.0539391086832404" rpy="0 0 0"/>
            <geometry>
                <box size="2.03077424521089 1.5506523837282014 2.1078782173664807" />
            </geometry>
        </collision>
    </link>
    <link name="Leg7">
        <inertial>
            <origin xyz="0 1.37272154298439 0" rpy="0 0 0"/>
            <mass value="1" />
            <inertia ixx="100" ixy="0" ixz="0" iyy="100" iyz="0" izz="100" />
        </inertial>
        <visual>
            <origin xyz="0 1.37272154298439 0" rpy="0 0 0"/>
            <geometry>
                <box size="1.8917545327814622 2.74544308596878 1.8996219013959947" />
            </geometry>
            <material name="Green">
                <color rgba="0 180.0 0.0 1.0"/>
            </material>
        </visual>
        <collision>
            <origin xyz="0 1.37272154298439 0" rpy="0 0 0"/>
            <geometry>
                <box size="1.8917545327814622 2.74544308596878 1.8996219013959947" />
            </geometry>
        </collision>
    </link>
    <link name="Leg8">
        <inertial>
            <origin xyz="0 0 1.1040905179074696" rpy="0 0 0"/>
            <mass value="1" />
            <inertia ixx="100" ixy="0" ixz="0" iyy="100" iyz="0" izz="100" />
        </inertial>
        <visual>
            <origin xyz="0 0 1.1040905179074696" rpy="0 0 0"/>
            <geometry>
                <box size="1.1814260652554496 1.5310864578508754 2.208181035814939" />
            </geometry>
            <material name="Blue">
                <color rgba="0 1.0 1.0 1.0"/>
            </material>
        </visual>
        <collision>
            <origin xyz="0 0 1.1040905179074696" rpy="0 0 0"/>
            <geometry>
                <box size="1.1814260652554496 1.5310864578508754 2.208181035814939" />
            </geometry>
        </collision>
    </link>
    <link name="Leg9">
        <inertial>
            <origin xyz="1.2981146954048657 0 0" rpy="0 0 0"/>
            <mass value="1" />
            <inertia ixx="100" ixy="0" ixz="0" iyy="100" iyz="0" izz="100" />
        </inertial>
        <visual>
            <origin xyz="1.2981146954048657 0 0" rpy="0 0 0"/>
            <geometry>
                <box size="2.5962293908097314 2.5643311727714835 2.7019760133425756" />
            </geometry>
            <material name="Green">
                <color rgba="0 180.0 0.0 1.0"/>
            </material>
        </visual>
        <collision>
            <origin xyz="1.2981146954048657 0 0" rpy="0 0 0"/>
            <geometry>
                <box size="2.5962293908097314 2.5643311727714835 2.7019760133425756" />
            </geometry>
        </collision>
    </link>
    <link name="Leg10">
        <inertial>
            <origin xyz="0 0 0.6268328498827052" rpy="0 0 0"/>
            <mass value="1" />
            <inertia ixx="100" ixy="0" ixz="0" iyy="100" iyz="0" izz="100" />
        </inertial>
        <visual>
            <origin xyz="0 0 0.6268328498827052" rpy="0 0 0"/>
            <geometry>
                <box size="2.80524477655172 2.11336139283112 1.2536656997654103" />
            </geometry>
            <material name="Blue">
                <color rgba="0 1.0 1.0 1.0"/>
            </material>
        </visual>
        <collision>
            <origin xyz="0 0 0.6268328498827052" rpy="0 0 0"/>
            <geometry>
                <box size="2.80524477655172 2.11336139283112 1.2536656997654103" />
            </geometry>
        </collision>
    </link>
    <link name="Leg11">
        <inertial>
            <origin xyz="0 0 0.9563332060690105" rpy="0 0 0"/>
            <mass value="1" />
            <inertia ixx="100" ixy="0" ixz="0" iyy="100" iyz="0" izz="100" />
        </inertial>
        <visual>
            <origin xyz="0 0 0.9563332060690105" rpy="0 0 0"/>
            <geometry>
                <box size="2.5410481748469476 2.2125467628757054 1.912666412138021" />
            </geometry>
            <material name="Blue">
                <color rgba="0 1.0 1.0 1.0"/>
            </material>
        </visual>
        <collision>
            <origin xyz="0 0 0.9563332060690105" rpy="0 0 0"/>
            <geometry>
                <box size="2.5410481748469476 2.2125467628757054 1.912666412138021" />
            </geometry>
        </collision>
    </link>
    <link name="Leg12">
        <inertial>
            <origin xyz="0 1.1944257311900448 0" rpy="0 0 0"/>
            <mass value="1" />
            <inertia ixx="100" ixy="0" ixz="0" iyy="100" iyz="0" izz="100" />
        </inertial>
        <visual>
            <origin xyz="0 1.1944257311900448 0" rpy="0 0 0"/>
            <geometry>
                <box size="1.3910633410995235 2.3888514623800896 1.8944327810967165" />
            </geometry>
            <material name="Green">
                <color rgba="0 180.0 0.0 1.0"/>
            </material>
        </visual>
        <collision>
            <origin xyz="0 1.1944257311900448 0" rpy="0 0 0"/>
            <geometry>
                <box size="1.3910633410995235 2.3888514623800896 1.8944327810967165" />
            </geometry>
        </collision>
    </link>
    <link name="Leg13">
        <inertial>
            <origin xyz="0 0.5372879476827783 0" rpy="0 0 0"/>
            <mass value="1" />
            <inertia ixx="100" ixy="0" ixz="0" iyy="100" iyz="0" izz="100" />
        </inertial>
        <visual>
            <origin xyz="0 0.5372879476827783 0" rpy="0 0 0"/>
            <geometry>
                <box size="2.4063474157468714 1.0745758953655566 2.089786781331772" />
            </geometry>
            <material name="Blue">
                <color rgba="0 1.0 1.0 1.0"/>
            </material>
        </visual>
        <collision>
            <origin xyz="0 0.5372879476827783 0" rpy="0 0 0"/>
            <geometry>
                <box size="2.4063474157468714 1.0745758953655566 2.089786781331772" />
            </geometry>
        </collision>
    </link>
    <link name="Leg14">
        <inertial>
            <origin xyz="0 0.8912155951153595 0" rpy="0 0 0"/>
            <mass value="1" />
            <inertia ixx="100" ixy="0" ixz="0" iyy="100" iyz="0" izz="100" />
        </inertial>
        <visual>
            <origin xyz="0 0.8912155951153595 0" rpy="0 0 0"/>
            <geometry>
                <box size="2.705431469948845 1.782431190230719 2.3333366238107254" />
            </geometry>
            <material name="Green">
                <color rgba="0 180.0 0.0 1.0"/>
            </material>
        </visual>
        <collision>
            <origin xyz="0 0.8912155951153595 0" rpy="0 0 0"/>
            <geometry>
                <box size="2.705431469948845 1.782431190230719 2.3333366238107254" />
            </geometry>
        </collision>
    </link>
    <link name="Leg15">
        <inertial>
            <origin xyz="1.4022004619445965 0 0" rpy="0 0 0"/>
            <mass value="1" />
            <inertia ixx="100" ixy="0" ixz="0" iyy="100" iyz="0" izz="100" />
        </inertial>
        <visual>
            <origin xyz="1.4022004619445965 0 0" rpy="0 0 0"/>
            <geometry>
                <box size="2.804400923889193 1.0854123623523126 1.5712539052512664" />
            </geometry>
            <material name="Green">
                <color rgba="0 180.0 0.0 1.0"/>
            </material>
        </visual>
        <collision>
            <origin xyz="1.4022004619445965 0 0" rpy="0 0 0"/>
            <geometry>
                <box size="2.804400923889193 1.0854123623523126 1.5712539052512664" />
            </geometry>
        </collision>
    </link>
    <link name="Leg16">
        <inertial>
            <origin xyz="1.3626368599204621 0 0" rpy="0 0 0"/>
            <mass value="1" />
            <inertia ixx="100" ixy="0" ixz="0" iyy="100" iyz="0" izz="100" />
        </inertial>
        <visual>
            <origin xyz="1.3626368599204621 0 0" rpy="0 0 0"/>
            <geometry>
                <box size="2.7252737198409243 1.3286337404178146 1.0844079696489417" />
            </geometry>
            <material name="Green">
                <color rgba="0 180.0 0.0 1.0"/>
            </material>
        </visual>
        <collision>
            <origin xyz="1.3626368599204621 0 0" rpy="0 0 0"/>
            <geometry>
                <box size="2.7252737198409243 1.3286337404178146 1.0844079696489417" />
            </geometry>
        </collision>
    </link>
    <link name="Leg17">
        <inertial>
            <origin xyz="0 0.7513753920945933 0" rpy="0 0 0"/>
            <mass value="1" />
            <inertia ixx="100" ixy="0" ixz="0" iyy="100" iyz="0" izz="100" />
        </inertial>
        <visual>
            <origin xyz="0 0.7513753920945933 0" rpy="0 0 0"/>
            <geometry>
                <box size="2.2040039739717727 1.5027507841891865 1.9725182229978788" />
            </geometry>
            <material name="Green">
                <color rgba="0 180.0 0.0 1.0"/>
            </material>
        </visual>
        <collision>
            <origin xyz="0 0.7513753920945933 0" rpy="0 0 0"/>
            <geometry>
                <box size="2.2040039739717727 1.5027507841891865 1.9725182229978788" />
            </geometry>
        </collision>
    </link>
    <link name="Leg18">
        <inertial>
            <origin xyz="1.3192783869001445 0 0" rpy="0 0 0"/>
            <mass value="1" />
            <inertia ixx="100" ixy="0" ixz="0" iyy="100" iyz="0" izz="100" />
        </inertial>
        <visual>
            <origin xyz="1.3192783869001445 0 0" rpy="0 0 0"/>
            <geometry>
                <box size="2.638556773800289 1.620132739765895 2.149938418131364" />
            </geometry>
            <material name="Green">
                <color rgba="0 180.0 0.0 1.0"/>
            </material>
        </visual>
        <collision>
            <origin xyz="1.3192783869001445 0 0" rpy="0 0 0"/>
            <geometry>
                <box size="2.638556773800289 1.620132739765895 2.149938418131364" />
            </geometry>
        </collision>
    </link>
    <link name="Leg19">
        <inertial>
            <origin xyz="0 0 0.6336252897858823" rpy="0 0 0"/>
            <mass value="1" />
            <inertia ixx="100" ixy="0" ixz="0" iyy="100" iyz="0" izz="100" />
        </inertial>
        <visual>
            <origin xyz="0 0 0.6336252897858823" rpy="0 0 0"/>
            <geometry>
                <box size="2.319912931495492 2.0210224436113986 1.2672505795717646" />
            </geometry>
            <material name="Green">
                <color rgba="0 180.0 0.0 1.0"/>
            </material>
        </visual>
        <collision>
            <origin xyz="0 0 0.6336252897858823" rpy="0 0 0"/>
            <geometry>
                <box size="2.319912931495492 2.0210224436113986 1.2672505795717646" />
            </geometry>
        </collision>
    </link>
    <link name="Leg20">
        <inertial>
            <origin xyz="0 0 1.0305261063683684" rpy="0 0 0"/>
            <mass value="1" />
            <inertia ixx="100" ixy="0" ixz="0" iyy="100" iyz="0" izz="100" />
        </inertial>
        <visual>
            <origin xyz="0 0 1.0305261063683684" rpy="0 0 0"/>
            <geometry>
                <box size="2.9970292398149345 2.462987147265542 2.0610522127367368" />
            </geometry>
            <material name="Green">
                <color rgba="0 180.0 0.0 1.0"/>
            </material>
        </visual>
        <collision>
            <origin xyz="0 0 1.0305261063683684" rpy="0 0 0"/>
            <geometry>
                <box size="2.9970292398149345 2.462987147265542 2.0610522127367368" />
            </geometry>
        </collision>
    </link>
    <link name="Leg21">
        <inertial>
            <origin xyz="0 1.3326937633586606 0" rpy="0 0 0"/>
            <mass value="1" />
            <inertia ixx="100" ixy="0" ixz="0" iyy="100" iyz="0" izz="100" />
        </inertial>
        <visual>
            <origin xyz="0 1.3326937633586606 0" rpy="0 0 0"/>
            <geometry>
                <box size="1.8935273349253414 2.6653875267173213 2.7696415443985547" />
            </geometry>
            <material name="Green">
                <color rgba="0 180.0 0.0 1.0"/>
            </material>
        </visual>
        <collision>
            <origin xyz="0 1.3326937633586606 0" rpy="0 0 0"/>
            <geometry>
                <box size="1.8935273349253414 2.6653875267173213 2.7696415443985547" />
            </geometry>
        </collision>
    </link>
    <link name="Leg22">
        <inertial>
            <origin xyz="0.5213927033739902 0 0" rpy="0 0 0"/>
            <mass value="1" />
            <inertia ixx="100" ixy="0" ixz="0" iyy="100" iyz="0" izz="100" />
        </inertial>
        <visual>
            <origin xyz="0.5213927033739902 0 0" rpy="0 0 0"/>
            <geometry>
                <box size="1.0427854067479805 1.7375402689477053 2.2331375645432905" />
            </geometry>
            <material name="Blue">
                <color rgba="0 1.0 1.0 1.0"/>
            </material>
        </visual>
        <collision>
            <origin xyz="0.5213927033739902 0 0" rpy="0 0 0"/>
            <geometry>
                <box size="1.0427854067479805 1.7375402689477053 2.2331375645432905" />
            </geometry>
        </collision>
    </link>
    <link name="Leg23">
        <inertial>
            <origin xyz="0 0 1.3821301052331143" rpy="0 0 0"/>
            <mass value="1" />
            <inertia ixx="100" ixy="0" ixz="0" iyy="100" iyz="0" izz="100" />
        </inertial>
        <visual>
            <origin xyz="0 0 1.3821301052331143" rpy="0 0 0"/>
            <geometry>
                <box size="1.4052905178882036 1.6984514088015747 2.7642602104662286" />
            </geometry>
            <material name="Blue">
                <color rgba="0 1.0 1.0 1.0"/>
            </material>
        </visual>
        <collision>
            <origin xyz="0 0 1.3821301052331143" rpy="0 0 0"/>
            <geometry>
                <box size="1.4052905178882036 1.6984514088015747 2.7642602104662286" />
            </geometry>
        </collision>
    </link>
    <link name="Leg24">
        <inertial>
            <origin xyz="0 0.9189851553432706 0" rpy="0 0 0"/>
            <mass value="1" />
            <inertia ixx="100" ixy="0" ixz="0" iyy="100" iyz="0" izz="100" />
        </inertial>
        <visual>
            <origin xyz="0 0.9189851553432706 0" rpy="0 0 0"/>
            <geometry>
                <box size="2.8341484726613793 1.8379703106865413 2.5826505191801354" />
            </geometry>
            <material name="Blue">
                <color rgba="0 1.0 1.0 1.0"/>
            </material>
        </visual>
        <collision>
            <origin xyz="0 0.9189851553432706 0" rpy="0 0 0"/>
            <geometry>
                <box size="2.8341484726613793 1.8379703106865413 2.5826505191801354" />
            </geometry>
        </collision>
    </link>
    <joint name="Torso_Leg1" type="revolute">
       <parent link="Torso"/>
       <child  link="Leg1"/>
       <origin rpy="0 0 0" xyz="0 0.6897161453059839 0.5634203059860814" />
     <axis xyz="1 0 0"/>
       <limit effort="0.0" lower="-3.14159" upper="3.14159" velocity="0.0"/>
    </joint>
    <joint name="Leg1_Leg2" type="revolute">
       <parent link="Leg1"/>
       <child  link="Leg2"/>
       <origin rpy="0 0 0" xyz="0 2.2872947250751663 0" />
     <axis xyz="1 0 0"/>
       <limit effort="0.0" lower="-3.14159" upper="3.14159" velocity="0.0"/>
    </joint>
    <joint name="Leg2_Leg3" type="revolute">
       <parent link="Leg2"/>
       <child  link="Leg3"/>
       <origin rpy="0 0 0" xyz="0 0 2.163951356766982" />
     <axis xyz="1 0 0"/>
       <limit effort="0.0" lower="-3.14159" upper="3.14159" velocity="0.0"/>
    </joint>
    <joint name="Torso_Leg4" type="revolute">
       <parent link="Torso"/>
       <child  link="Leg4"/>
       <origin rpy="0 0 0" xyz="0.8129229335554639 1.3644328974995699 0" />
     <axis xyz="1 0 0"/>
       <limit effort="0.0" lower="-3.14159" upper="3.14159" velocity="0.0"/>
    </joint>
    <joint name="Leg4_Leg5" type="revolute">
       <parent link="Leg4"/>
       <child  link="Leg5"/>
       <origin rpy="0 0 0" xyz="0 2.057771668471002 0" />
     <axis xyz="1 0 0"/>
       <limit effort="0.0" lower="-3.14159" upper="3.14159" velocity="0.0"/>
    </joint>
    <joint name="Leg5_Leg6" type="revolute">
       <parent link="Leg5"/>
       <child  link="Leg6"/>
       <origin rpy="0 0 0" xyz="0 0 2.1078782173664807" />
     <axis xyz="1 0 0"/>
       <limit effort="0.0" lower="-3.14159" upper="3.14159" velocity="0.0"/>
    </joint>
    <joint name="Leg3_Leg7" type="revolute">
       <parent link="Leg3"/>
       <child  link="Leg7"/>
       <origin rpy="0 0 0" xyz="0.7655666273630696 1.4540874849078926 0" />
     <axis xyz="1 0 0"/>
       <limit effort="0.0" lower="-3.14159" upper="3.14159" velocity="0.0"/>
    </joint>
    <joint name="Leg6_Leg8" type="revolute">
       <parent link="Leg6"/>
       <child  link="Leg8"/>
       <origin rpy="0 0 0" xyz="0 1.37272154298439 0.9498109506979974" />
     <axis xyz="1 0 0"/>
       <limit effort="0.0" lower="-3.14159" upper="3.14159" velocity="0.0"/>
    </joint>
    <joint name="Leg2_Leg9" type="revolute">
       <parent link="Leg2"/>
       <child  link="Leg9"/>
       <origin rpy="0 0 0" xyz="1.2766732164733763 0 2.163951356766982" />
     <axis xyz="1 0 0"/>
       <limit effort="0.0" lower="-3.14159" upper="3.14159" velocity="0.0"/>
    </joint>
    <joint name="Leg8_Leg10" type="revolute">
       <parent link="Leg8"/>
       <child  link="Leg10"/>
       <origin rpy="0 0 0" xyz="1.2981146954048657 0 1.3509880066712878" />
     <axis xyz="1 0 0"/>
       <limit effort="0.0" lower="-3.14159" upper="3.14159" velocity="0.0"/>
    </joint>
    <joint name="Leg10_Leg11" type="revolute">
       <parent link="Leg10"/>
       <child  link="Leg11"/>
       <origin rpy="0 0 0" xyz="0 0 1.912666412138021" />
     <axis xyz="1 0 0"/>
       <limit effort="0.0" lower="-3.14159" upper="3.14159" velocity="0.0"/>
    </joint>
    <joint name="Leg9_Leg12" type="revolute">
       <parent link="Leg9"/>
       <child  link="Leg12"/>
       <origin rpy="0 0 0" xyz="0 1.05668069641556 0.6268328498827052" />
     <axis xyz="1 0 0"/>
       <limit effort="0.0" lower="-3.14159" upper="3.14159" velocity="0.0"/>
    </joint>
    <joint name="Leg10_Leg13" type="revolute">
       <parent link="Leg10"/>
       <child  link="Leg13"/>
       <origin rpy="0 0 0" xyz="0 1.1062733814378527 1.912666412138021" />
     <axis xyz="1 0 0"/>
       <limit effort="0.0" lower="-3.14159" upper="3.14159" velocity="0.0"/>
    </joint>
    <joint name="Leg11_Leg14" type="revolute">
       <parent link="Leg11"/>
       <child  link="Leg14"/>
       <origin rpy="0 0 0" xyz="0 2.3888514623800896 0" />
     <axis xyz="1 0 0"/>
       <limit effort="0.0" lower="-3.14159" upper="3.14159" velocity="0.0"/>
    </joint>
    <joint name="Leg11_Leg15" type="revolute">
       <parent link="Leg11"/>
       <child  link="Leg15"/>
       <origin rpy="0 0 0" xyz="0.6955316705497617 2.3888514623800896 0" />
     <axis xyz="1 0 0"/>
       <limit effort="0.0" lower="-3.14159" upper="3.14159" velocity="0.0"/>
    </joint>
    <joint name="Leg3_Leg16" type="revolute">
       <parent link="Leg3"/>
       <child  link="Leg16"/>
       <origin rpy="0 0 0" xyz="1.5311332547261391 1.4540874849078926 0" />
     <axis xyz="1 0 0"/>
       <limit effort="0.0" lower="-3.14159" upper="3.14159" velocity="0.0"/>
    </joint>
    <joint name="Leg7_Leg17" type="revolute">
       <parent link="Leg7"/>
       <child  link="Leg17"/>
       <origin rpy="0 0 0" xyz="0 0.7655432289254377 1.1040905179074696" />
     <axis xyz="1 0 0"/>
       <limit effort="0.0" lower="-3.14159" upper="3.14159" velocity="0.0"/>
    </joint>
    <joint name="Leg1_Leg18" type="revolute">
       <parent link="Leg1"/>
       <child  link="Leg18"/>
       <origin rpy="0 0 0" xyz="1.2115474713240364 2.2872947250751663 0" />
     <axis xyz="1 0 0"/>
       <limit effort="0.0" lower="-3.14159" upper="3.14159" velocity="0.0"/>
    </joint>
    <joint name="Leg16_Leg19" type="revolute">
       <parent link="Leg16"/>
       <child  link="Leg19"/>
       <origin rpy="0 0 0" xyz="0 0.7513753920945933 0.9862591114989394" />
     <axis xyz="1 0 0"/>
       <limit effort="0.0" lower="-3.14159" upper="3.14159" velocity="0.0"/>
    </joint>
    <joint name="Leg19_Leg20" type="revolute">
       <parent link="Leg19"/>
       <child  link="Leg20"/>
       <origin rpy="0 0 0" xyz="0 0 2.0610522127367368" />
     <axis xyz="1 0 0"/>
       <limit effort="0.0" lower="-3.14159" upper="3.14159" velocity="0.0"/>
    </joint>
    <joint name="Leg8_Leg21" type="revolute">
       <parent link="Leg8"/>
       <child  link="Leg21"/>
       <origin rpy="0 0 0" xyz="1.2981146954048657 1.2821655863857417 1.3509880066712878" />
     <axis xyz="1 0 0"/>
       <limit effort="0.0" lower="-3.14159" upper="3.14159" velocity="0.0"/>
    </joint>
    <joint name="Leg9_Leg22" type="revolute">
       <parent link="Leg9"/>
       <child  link="Leg22"/>
       <origin rpy="0 0 0" xyz="1.40262238827586 1.05668069641556 0.6268328498827052" />
     <axis xyz="1 0 0"/>
       <limit effort="0.0" lower="-3.14159" upper="3.14159" velocity="0.0"/>
    </joint>
    <joint name="Leg12_Leg23" type="revolute">
       <parent link="Leg12"/>
       <child  link="Leg23"/>
       <origin rpy="0 0 0" xyz="0 0.5372879476827783 1.044893390665886" />
     <axis xyz="1 0 0"/>
       <limit effort="0.0" lower="-3.14159" upper="3.14159" velocity="0.0"/>
    </joint>
    <joint name="Leg17_Leg24" type="revolute">
       <parent link="Leg17"/>
       <child  link="Leg24"/>
       <origin rpy="0 0 0" xyz="1.3192783869001445 0.8100663698829474 0" />
     <axis xyz="1 0 0"/>
       <limit effort="0.0" lower="-3.14159" upper="3.14159" velocity="0.0"/>
    </joint>
</robot>