<robot name = "robot">
    <link name="Torso">
        <inertial>
            <origin xyz="0 0 0.9728082611633145" rpy="0 0 0"/>
            <mass value="1" />
            <inertia ixx="100" ixy="0" ixz="0" iyy="100" iyz="0" izz="100" />
        </inertial>
        <visual>
            <origin xyz="0 0 0.9728082611633145" rpy="0 0 0"/>
            <geometry>
                <box size="2.2772409232363087 1.955433688987526 1.945616522326629" />
            </geometry>
            <material name="Green">
                <color rgba="0 180.0 0.0 1.0"/>
            </material>
        </visual>
        <collision>
            <origin xyz="0 0 0.9728082611633145" rpy="0 0 0"/>
            <geometry>
                <box size="2.2772409232363087 1.955433688987526 1.945616522326629" />
            </geometry>
        </collision>
    </link>
    <link name="Leg1">
        <inertial>
            <origin xyz="1.4603208242260592 0 0" rpy="0 0 0"/>
            <mass value="1" />
            <inertia ixx="100" ixy="0" ixz="0" iyy="100" iyz="0" izz="100" />
        </inertial>
        <visual>
            <origin xyz="1.4603208242260592 0 0" rpy="0 0 0"/>
            <geometry>
                <box size="2.9206416484521185 1.2797605648478114 2.374577110391785" />
            </geometry>
            <material name="Blue">
                <color rgba="0 1.0 1.0 1.0"/>
            </material>
        </visual>
        <collision>
            <origin xyz="1.4603208242260592 0 0" rpy="0 0 0"/>
            <geometry>
                <box size="2.9206416484521185 1.2797605648478114 2.374577110391785" />
            </geometry>
        </collision>
    </link>
    <link name="Leg2">
        <inertial>
            <origin xyz="0 0 0.964407376522867" rpy="0 0 0"/>
            <mass value="1" />
            <inertia ixx="100" ixy="0" ixz="0" iyy="100" iyz="0" izz="100" />
        </inertial>
        <visual>
            <origin xyz="0 0 0.964407376522867" rpy="0 0 0"/>
            <geometry>
                <box size="1.6614436001884454 1.6996727747265954 1.928814753045734" />
            </geometry>
            <material name="Blue">
                <color rgba="0 1.0 1.0 1.0"/>
            </material>
        </visual>
        <collision>
            <origin xyz="0 0 0.964407376522867" rpy="0 0 0"/>
            <geometry>
                <box size="1.6614436001884454 1.6996727747265954 1.928814753045734" />
            </geometry>
        </collision>
    </link>
    <link name="Leg3">
        <inertial>
            <origin xyz="0 0.6549247126139778 0" rpy="0 0 0"/>
            <mass value="1" />
            <inertia ixx="100" ixy="0" ixz="0" iyy="100" iyz="0" izz="100" />
        </inertial>
        <visual>
            <origin xyz="0 0.6549247126139778 0" rpy="0 0 0"/>
            <geometry>
                <box size="1.0018397845236353 1.3098494252279556 2.0729066474218705" />
            </geometry>
            <material name="Blue">
                <color rgba="0 1.0 1.0 1.0"/>
            </material>
        </visual>
        <collision>
            <origin xyz="0 0.6549247126139778 0" rpy="0 0 0"/>
            <geometry>
                <box size="1.0018397845236353 1.3098494252279556 2.0729066474218705" />
            </geometry>
        </collision>
    </link>
    <link name="Leg4">
        <inertial>
            <origin xyz="0 0 0.9925388714215133" rpy="0 0 0"/>
            <mass value="1" />
            <inertia ixx="100" ixy="0" ixz="0" iyy="100" iyz="0" izz="100" />
        </inertial>
        <visual>
            <origin xyz="0 0 0.9925388714215133" rpy="0 0 0"/>
            <geometry>
                <box size="2.7385942207024225 1.7410866920422776 1.9850777428430266" />
            </geometry>
            <material name="Green">
                <color rgba="0 180.0 0.0 1.0"/>
            </material>
        </visual>
        <collision>
            <origin xyz="0 0 0.9925388714215133" rpy="0 0 0"/>
            <geometry>
                <box size="2.7385942207024225 1.7410866920422776 1.9850777428430266" />
            </geometry>
        </collision>
    </link>
    <link name="Leg5">
        <inertial>
            <origin xyz="1.1604050209786758 0 0" rpy="0 0 0"/>
            <mass value="1" />
            <inertia ixx="100" ixy="0" ixz="0" iyy="100" iyz="0" izz="100" />
        </inertial>
        <visual>
            <origin xyz="1.1604050209786758 0 0" rpy="0 0 0"/>
            <geometry>
                <box size="2.3208100419573516 1.8649686060403832 1.4179252711978674" />
            </geometry>
            <material name="Blue">
                <color rgba="0 1.0 1.0 1.0"/>
            </material>
        </visual>
        <collision>
            <origin xyz="1.1604050209786758 0 0" rpy="0 0 0"/>
            <geometry>
                <box size="2.3208100419573516 1.8649686060403832 1.4179252711978674" />
            </geometry>
        </collision>
    </link>
    <link name="Leg6">
        <inertial>
            <origin xyz="0 0 0.7042708035218702" rpy="0 0 0"/>
            <mass value="1" />
            <inertia ixx="100" ixy="0" ixz="0" iyy="100" iyz="0" izz="100" />
        </inertial>
        <visual>
            <origin xyz="0 0 0.7042708035218702" rpy="0 0 0"/>
            <geometry>
                <box size="1.734532057597401 2.392483947188418 1.4085416070437404" />
            </geometry>
            <material name="Blue">
                <color rgba="0 1.0 1.0 1.0"/>
            </material>
        </visual>
        <collision>
            <origin xyz="0 0 0.7042708035218702" rpy="0 0 0"/>
            <geometry>
                <box size="1.734532057597401 2.392483947188418 1.4085416070437404" />
            </geometry>
        </collision>
    </link>
    <link name="Leg7">
        <inertial>
            <origin xyz="0 1.460850778469608 0" rpy="0 0 0"/>
            <mass value="1" />
            <inertia ixx="100" ixy="0" ixz="0" iyy="100" iyz="0" izz="100" />
        </inertial>
        <visual>
            <origin xyz="0 1.460850778469608 0" rpy="0 0 0"/>
            <geometry>
                <box size="2.7032667603879847 2.921701556939216 1.4643262188008264" />
            </geometry>
            <material name="Green">
                <color rgba="0 180.0 0.0 1.0"/>
            </material>
        </visual>
        <collision>
            <origin xyz="0 1.460850778469608 0" rpy="0 0 0"/>
            <geometry>
                <box size="2.7032667603879847 2.921701556939216 1.4643262188008264" />
            </geometry>
        </collision>
    </link>
    <link name="Leg8">
        <inertial>
            <origin xyz="0.898387807789655 0 0" rpy="0 0 0"/>
            <mass value="1" />
            <inertia ixx="100" ixy="0" ixz="0" iyy="100" iyz="0" izz="100" />
        </inertial>
        <visual>
            <origin xyz="0.898387807789655 0 0" rpy="0 0 0"/>
            <geometry>
                <box size="1.79677561557931 1.5852153917357217 1.1188470364932679" />
            </geometry>
            <material name="Blue">
                <color rgba="0 1.0 1.0 1.0"/>
            </material>
        </visual>
        <collision>
            <origin xyz="0.898387807789655 0 0" rpy="0 0 0"/>
            <geometry>
                <box size="1.79677561557931 1.5852153917357217 1.1188470364932679" />
            </geometry>
        </collision>
    </link>
    <link name="Leg9">
        <inertial>
            <origin xyz="0 0 1.2119411389893076" rpy="0 0 0"/>
            <mass value="1" />
            <inertia ixx="100" ixy="0" ixz="0" iyy="100" iyz="0" izz="100" />
        </inertial>
        <visual>
            <origin xyz="0 0 1.2119411389893076" rpy="0 0 0"/>
            <geometry>
                <box size="2.4006434369821044 1.2497363719331656 2.423882277978615" />
            </geometry>
            <material name="Blue">
                <color rgba="0 1.0 1.0 1.0"/>
            </material>
        </visual>
        <collision>
            <origin xyz="0 0 1.2119411389893076" rpy="0 0 0"/>
            <geometry>
                <box size="2.4006434369821044 1.2497363719331656 2.423882277978615" />
            </geometry>
        </collision>
    </link>
    <link name="Leg10">
        <inertial>
            <origin xyz="0.6003561289510925 0 0" rpy="0 0 0"/>
            <mass value="1" />
            <inertia ixx="100" ixy="0" ixz="0" iyy="100" iyz="0" izz="100" />
        </inertial>
        <visual>
            <origin xyz="0.6003561289510925 0 0" rpy="0 0 0"/>
            <geometry>
                <box size="1.200712257902185 2.000260291069914 2.7911036053073923" />
            </geometry>
            <material name="Blue">
                <color rgba="0 1.0 1.0 1.0"/>
            </material>
        </visual>
        <collision>
            <origin xyz="0.6003561289510925 0 0" rpy="0 0 0"/>
            <geometry>
                <box size="1.200712257902185 2.000260291069914 2.7911036053073923" />
            </geometry>
        </collision>
    </link>
    <link name="Leg11">
        <inertial>
            <origin xyz="1.3500952007487106 0 0" rpy="0 0 0"/>
            <mass value="1" />
            <inertia ixx="100" ixy="0" ixz="0" iyy="100" iyz="0" izz="100" />
        </inertial>
        <visual>
            <origin xyz="1.3500952007487106 0 0" rpy="0 0 0"/>
            <geometry>
                <box size="2.700190401497421 1.769324271916193 1.348404425764051" />
            </geometry>
            <material name="Blue">
                <color rgba="0 1.0 1.0 1.0"/>
            </material>
        </visual>
        <collision>
            <origin xyz="1.3500952007487106 0 0" rpy="0 0 0"/>
            <geometry>
                <box size="2.700190401497421 1.769324271916193 1.348404425764051" />
            </geometry>
        </collision>
    </link>
    <link name="Leg12">
        <inertial>
            <origin xyz="1.2462399107124718 0 0" rpy="0 0 0"/>
            <mass value="1" />
            <inertia ixx="100" ixy="0" ixz="0" iyy="100" iyz="0" izz="100" />
        </inertial>
        <visual>
            <origin xyz="1.2462399107124718 0 0" rpy="0 0 0"/>
            <geometry>
                <box size="2.4924798214249435 1.864581309059087 2.5229616172078817" />
            </geometry>
            <material name="Blue">
                <color rgba="0 1.0 1.0 1.0"/>
            </material>
        </visual>
        <collision>
            <origin xyz="1.2462399107124718 0 0" rpy="0 0 0"/>
            <geometry>
                <box size="2.4924798214249435 1.864581309059087 2.5229616172078817" />
            </geometry>
        </collision>
    </link>
    <link name="Leg13">
        <inertial>
            <origin xyz="0 0 1.0380663684163791" rpy="0 0 0"/>
            <mass value="1" />
            <inertia ixx="100" ixy="0" ixz="0" iyy="100" iyz="0" izz="100" />
        </inertial>
        <visual>
            <origin xyz="0 0 1.0380663684163791" rpy="0 0 0"/>
            <geometry>
                <box size="1.8461276399575652 1.870575268457866 2.0761327368327582" />
            </geometry>
            <material name="Green">
                <color rgba="0 180.0 0.0 1.0"/>
            </material>
        </visual>
        <collision>
            <origin xyz="0 0 1.0380663684163791" rpy="0 0 0"/>
            <geometry>
                <box size="1.8461276399575652 1.870575268457866 2.0761327368327582" />
            </geometry>
        </collision>
    </link>
    <link name="Leg14">
        <inertial>
            <origin xyz="1.2548841103136996 0 0" rpy="0 0 0"/>
            <mass value="1" />
            <inertia ixx="100" ixy="0" ixz="0" iyy="100" iyz="0" izz="100" />
        </inertial>
        <visual>
            <origin xyz="1.2548841103136996 0 0" rpy="0 0 0"/>
            <geometry>
                <box size="2.5097682206273992 1.2976505064066333 1.8894469740991495" />
            </geometry>
            <material name="Green">
                <color rgba="0 180.0 0.0 1.0"/>
            </material>
        </visual>
        <collision>
            <origin xyz="1.2548841103136996 0 0" rpy="0 0 0"/>
            <geometry>
                <box size="2.5097682206273992 1.2976505064066333 1.8894469740991495" />
            </geometry>
        </collision>
    </link>
    <link name="Leg15">
        <inertial>
            <origin xyz="0 0 0.6477345638193367" rpy="0 0 0"/>
            <mass value="1" />
            <inertia ixx="100" ixy="0" ixz="0" iyy="100" iyz="0" izz="100" />
        </inertial>
        <visual>
            <origin xyz="0 0 0.6477345638193367" rpy="0 0 0"/>
            <geometry>
                <box size="1.0779539176369788 1.718143268945516 1.2954691276386734" />
            </geometry>
            <material name="Blue">
                <color rgba="0 1.0 1.0 1.0"/>
            </material>
        </visual>
        <collision>
            <origin xyz="0 0 0.6477345638193367" rpy="0 0 0"/>
            <geometry>
                <box size="1.0779539176369788 1.718143268945516 1.2954691276386734" />
            </geometry>
        </collision>
    </link>
    <link name="Leg16">
        <inertial>
            <origin xyz="0 0.8660081993231701 0" rpy="0 0 0"/>
            <mass value="1" />
            <inertia ixx="100" ixy="0" ixz="0" iyy="100" iyz="0" izz="100" />
        </inertial>
        <visual>
            <origin xyz="0 0.8660081993231701 0" rpy="0 0 0"/>
            <geometry>
                <box size="1.343567843069389 1.7320163986463402 1.503877180705849" />
            </geometry>
            <material name="Green">
                <color rgba="0 180.0 0.0 1.0"/>
            </material>
        </visual>
        <collision>
            <origin xyz="0 0.8660081993231701 0" rpy="0 0 0"/>
            <geometry>
                <box size="1.343567843069389 1.7320163986463402 1.503877180705849" />
            </geometry>
        </collision>
    </link>
    <link name="Leg17">
        <inertial>
            <origin xyz="0.5805494544670161 0 0" rpy="0 0 0"/>
            <mass value="1" />
            <inertia ixx="100" ixy="0" ixz="0" iyy="100" iyz="0" izz="100" />
        </inertial>
        <visual>
            <origin xyz="0.5805494544670161 0 0" rpy="0 0 0"/>
            <geometry>
                <box size="1.1610989089340322 1.0087087985574923 1.8420976545618168" />
            </geometry>
            <material name="Blue">
                <color rgba="0 1.0 1.0 1.0"/>
            </material>
        </visual>
        <collision>
            <origin xyz="0.5805494544670161 0 0" rpy="0 0 0"/>
            <geometry>
                <box size="1.1610989089340322 1.0087087985574923 1.8420976545618168" />
            </geometry>
        </collision>
    </link>
    <link name="Leg18">
        <inertial>
            <origin xyz="0 0 1.2466987110215575" rpy="0 0 0"/>
            <mass value="1" />
            <inertia ixx="100" ixy="0" ixz="0" iyy="100" iyz="0" izz="100" />
        </inertial>
        <visual>
            <origin xyz="0 0 1.2466987110215575" rpy="0 0 0"/>
            <geometry>
                <box size="1.2586288007334463 1.0657099330749804 2.493397422043115" />
            </geometry>
            <material name="Blue">
                <color rgba="0 1.0 1.0 1.0"/>
            </material>
        </visual>
        <collision>
            <origin xyz="0 0 1.2466987110215575" rpy="0 0 0"/>
            <geometry>
                <box size="1.2586288007334463 1.0657099330749804 2.493397422043115" />
            </geometry>
        </collision>
    </link>
    <link name="Leg19">
        <inertial>
            <origin xyz="0 1.409040135515931 0" rpy="0 0 0"/>
            <mass value="1" />
            <inertia ixx="100" ixy="0" ixz="0" iyy="100" iyz="0" izz="100" />
        </inertial>
        <visual>
            <origin xyz="0 1.409040135515931 0" rpy="0 0 0"/>
            <geometry>
                <box size="2.2812389354136045 2.818080271031862 2.837993704181442" />
            </geometry>
            <material name="Green">
                <color rgba="0 180.0 0.0 1.0"/>
            </material>
        </visual>
        <collision>
            <origin xyz="0 1.409040135515931 0" rpy="0 0 0"/>
            <geometry>
                <box size="2.2812389354136045 2.818080271031862 2.837993704181442" />
            </geometry>
        </collision>
    </link>
    <link name="Leg20">
        <inertial>
            <origin xyz="0 0.9815041557529451 0" rpy="0 0 0"/>
            <mass value="1" />
            <inertia ixx="100" ixy="0" ixz="0" iyy="100" iyz="0" izz="100" />
        </inertial>
        <visual>
            <origin xyz="0 0.9815041557529451 0" rpy="0 0 0"/>
            <geometry>
                <box size="2.347226655268876 1.9630083115058903 2.43918971600836" />
            </geometry>
            <material name="Blue">
                <color rgba="0 1.0 1.0 1.0"/>
            </material>
        </visual>
        <collision>
            <origin xyz="0 0.9815041557529451 0" rpy="0 0 0"/>
            <geometry>
                <box size="2.347226655268876 1.9630083115058903 2.43918971600836" />
            </geometry>
        </collision>
    </link>
    <link name="Leg21">
        <inertial>
            <origin xyz="1.4072691082343614 0 0" rpy="0 0 0"/>
            <mass value="1" />
            <inertia ixx="100" ixy="0" ixz="0" iyy="100" iyz="0" izz="100" />
        </inertial>
        <visual>
            <origin xyz="1.4072691082343614 0 0" rpy="0 0 0"/>
            <geometry>
                <box size="2.8145382164687227 1.775723222232185 1.824876639053269" />
            </geometry>
            <material name="Blue">
                <color rgba="0 1.0 1.0 1.0"/>
            </material>
        </visual>
        <collision>
            <origin xyz="1.4072691082343614 0 0" rpy="0 0 0"/>
            <geometry>
                <box size="2.8145382164687227 1.775723222232185 1.824876639053269" />
            </geometry>
        </collision>
    </link>
    <link name="Leg22">
        <inertial>
            <origin xyz="1.051681451593595 0 0" rpy="0 0 0"/>
            <mass value="1" />
            <inertia ixx="100" ixy="0" ixz="0" iyy="100" iyz="0" izz="100" />
        </inertial>
        <visual>
            <origin xyz="1.051681451593595 0 0" rpy="0 0 0"/>
            <geometry>
                <box size="2.10336290318719 2.148066786192659 1.6263639509897796" />
            </geometry>
            <material name="Blue">
                <color rgba="0 1.0 1.0 1.0"/>
            </material>
        </visual>
        <collision>
            <origin xyz="1.051681451593595 0 0" rpy="0 0 0"/>
            <geometry>
                <box size="2.10336290318719 2.148066786192659 1.6263639509897796" />
            </geometry>
        </collision>
    </link>
    <link name="Leg23">
        <inertial>
            <origin xyz="0 0 0.9943785104404861" rpy="0 0 0"/>
            <mass value="1" />
            <inertia ixx="100" ixy="0" ixz="0" iyy="100" iyz="0" izz="100" />
        </inertial>
        <visual>
            <origin xyz="0 0 0.9943785104404861" rpy="0 0 0"/>
            <geometry>
                <box size="1.4942787419613 1.3885285864188464 1.9887570208809722" />
            </geometry>
            <material name="Green">
                <color rgba="0 180.0 0.0 1.0"/>
            </material>
        </visual>
        <collision>
            <origin xyz="0 0 0.9943785104404861" rpy="0 0 0"/>
            <geometry>
                <box size="1.4942787419613 1.3885285864188464 1.9887570208809722" />
            </geometry>
        </collision>
    </link>
    <link name="Leg24">
        <inertial>
            <origin xyz="0 1.021040676006287 0" rpy="0 0 0"/>
            <mass value="1" />
            <inertia ixx="100" ixy="0" ixz="0" iyy="100" iyz="0" izz="100" />
        </inertial>
        <visual>
            <origin xyz="0 1.021040676006287 0" rpy="0 0 0"/>
            <geometry>
                <box size="1.931466566241493 2.042081352012574 2.3500974093009384" />
            </geometry>
            <material name="Green">
                <color rgba="0 180.0 0.0 1.0"/>
            </material>
        </visual>
        <collision>
            <origin xyz="0 1.021040676006287 0" rpy="0 0 0"/>
            <geometry>
                <box size="1.931466566241493 2.042081352012574 2.3500974093009384" />
            </geometry>
        </collision>
    </link>
    <joint name="Torso_Leg1" type="revolute">
       <parent link="Torso"/>
       <child  link="Leg1"/>
       <origin rpy="0 0 0" xyz="1.1386204616181543 0 0.9728082611633145" />
     <axis xyz="1 0 0"/>
       <limit effort="0.0" lower="-3.14159" upper="3.14159" velocity="0.0"/>
    </joint>
    <joint name="Leg1_Leg2" type="revolute">
       <parent link="Leg1"/>
       <child  link="Leg2"/>
       <origin rpy="0 0 0" xyz="0 0 1.928814753045734" />
     <axis xyz="1 0 0"/>
       <limit effort="0.0" lower="-3.14159" upper="3.14159" velocity="0.0"/>
    </joint>
    <joint name="Leg2_Leg3" type="revolute">
       <parent link="Leg2"/>
       <child  link="Leg3"/>
       <origin rpy="0 0 0" xyz="0 1.3098494252279556 0" />
     <axis xyz="1 0 0"/>
       <limit effort="0.0" lower="-3.14159" upper="3.14159" velocity="0.0"/>
    </joint>
    <joint name="Torso_Leg4" type="revolute">
       <parent link="Torso"/>
       <child  link="Leg4"/>
       <origin rpy="0 0 0" xyz="1.4603208242260592 0 1.1872885551958925" />
     <axis xyz="1 0 0"/>
       <limit effort="0.0" lower="-3.14159" upper="3.14159" velocity="0.0"/>
    </joint>
    <joint name="Leg1_Leg5" type="revolute">
       <parent link="Leg1"/>
       <child  link="Leg5"/>
       <origin rpy="0 0 0" xyz="0.8307218000942227 0 1.928814753045734" />
     <axis xyz="1 0 0"/>
       <limit effort="0.0" lower="-3.14159" upper="3.14159" velocity="0.0"/>
    </joint>
    <joint name="Leg5_Leg6" type="revolute">
       <parent link="Leg5"/>
       <child  link="Leg6"/>
       <origin rpy="0 0 0" xyz="0 0 1.4085416070437404" />
     <axis xyz="1 0 0"/>
       <limit effort="0.0" lower="-3.14159" upper="3.14159" velocity="0.0"/>
    </joint>
    <joint name="Leg4_Leg7" type="revolute">
       <parent link="Leg4"/>
       <child  link="Leg7"/>
       <origin rpy="0 0 0" xyz="1.1604050209786758 0.9324843030201916 0" />
     <axis xyz="1 0 0"/>
       <limit effort="0.0" lower="-3.14159" upper="3.14159" velocity="0.0"/>
    </joint>
    <joint name="Leg2_Leg8" type="revolute">
       <parent link="Leg2"/>
       <child  link="Leg8"/>
       <origin rpy="0 0 0" xyz="0.5009198922618177 1.3098494252279556 0" />
     <axis xyz="1 0 0"/>
       <limit effort="0.0" lower="-3.14159" upper="3.14159" velocity="0.0"/>
    </joint>
    <joint name="Leg4_Leg9" type="revolute">
       <parent link="Leg4"/>
       <child  link="Leg9"/>
       <origin rpy="0 0 0" xyz="1.1604050209786758 0.9324843030201916 0.7089626355989337" />
     <axis xyz="1 0 0"/>
       <limit effort="0.0" lower="-3.14159" upper="3.14159" velocity="0.0"/>
    </joint>
    <joint name="Leg5_Leg10" type="revolute">
       <parent link="Leg5"/>
       <child  link="Leg10"/>
       <origin rpy="0 0 0" xyz="0.8672660287987005 0 1.4085416070437404" />
     <axis xyz="1 0 0"/>
       <limit effort="0.0" lower="-3.14159" upper="3.14159" velocity="0.0"/>
    </joint>
    <joint name="Leg6_Leg11" type="revolute">
       <parent link="Leg6"/>
       <child  link="Leg11"/>
       <origin rpy="0 0 0" xyz="1.3516333801939924 1.460850778469608 0" />
     <axis xyz="1 0 0"/>
       <limit effort="0.0" lower="-3.14159" upper="3.14159" velocity="0.0"/>
    </joint>
    <joint name="Leg10_Leg12" type="revolute">
       <parent link="Leg10"/>
       <child  link="Leg12"/>
       <origin rpy="0 0 0" xyz="2.700190401497421 0 0" />
     <axis xyz="1 0 0"/>
       <limit effort="0.0" lower="-3.14159" upper="3.14159" velocity="0.0"/>
    </joint>
    <joint name="Leg9_Leg13" type="revolute">
       <parent link="Leg9"/>
       <child  link="Leg13"/>
       <origin rpy="0 0 0" xyz="0.6003561289510925 0 1.3955518026536962" />
     <axis xyz="1 0 0"/>
       <limit effort="0.0" lower="-3.14159" upper="3.14159" velocity="0.0"/>
    </joint>
    <joint name="Leg4_Leg14" type="revolute">
       <parent link="Leg4"/>
       <child  link="Leg14"/>
       <origin rpy="0 0 0" xyz="2.3208100419573516 0.9324843030201916 0.7089626355989337" />
     <axis xyz="1 0 0"/>
       <limit effort="0.0" lower="-3.14159" upper="3.14159" velocity="0.0"/>
    </joint>
    <joint name="Leg2_Leg15" type="revolute">
       <parent link="Leg2"/>
       <child  link="Leg15"/>
       <origin rpy="0 0 0" xyz="0.5009198922618177 1.3098494252279556 1.0364533237109352" />
     <axis xyz="1 0 0"/>
       <limit effort="0.0" lower="-3.14159" upper="3.14159" velocity="0.0"/>
    </joint>
    <joint name="Leg7_Leg16" type="revolute">
       <parent link="Leg7"/>
       <child  link="Leg16"/>
       <origin rpy="0 0 0" xyz="0.898387807789655 0.7926076958678608 0" />
     <axis xyz="1 0 0"/>
       <limit effort="0.0" lower="-3.14159" upper="3.14159" velocity="0.0"/>
    </joint>
    <joint name="Leg16_Leg17" type="revolute">
       <parent link="Leg16"/>
       <child  link="Leg17"/>
       <origin rpy="0 0 0" xyz="1.1610989089340322 0 0" />
     <axis xyz="1 0 0"/>
       <limit effort="0.0" lower="-3.14159" upper="3.14159" velocity="0.0"/>
    </joint>
    <joint name="Leg11_Leg18" type="revolute">
       <parent link="Leg11"/>
       <child  link="Leg18"/>
       <origin rpy="0 0 0" xyz="1.2462399107124718 0 1.2614808086039409" />
     <axis xyz="1 0 0"/>
       <limit effort="0.0" lower="-3.14159" upper="3.14159" velocity="0.0"/>
    </joint>
    <joint name="Leg16_Leg19" type="revolute">
       <parent link="Leg16"/>
       <child  link="Leg19"/>
       <origin rpy="0 0 0" xyz="1.1610989089340322 0.5043543992787461 0" />
     <axis xyz="1 0 0"/>
       <limit effort="0.0" lower="-3.14159" upper="3.14159" velocity="0.0"/>
    </joint>
    <joint name="Leg9_Leg20" type="revolute">
       <parent link="Leg9"/>
       <child  link="Leg20"/>
       <origin rpy="0 0 0" xyz="0.6003561289510925 1.000130145534957 1.3955518026536962" />
     <axis xyz="1 0 0"/>
       <limit effort="0.0" lower="-3.14159" upper="3.14159" velocity="0.0"/>
    </joint>
    <joint name="Leg19_Leg21" type="revolute">
       <parent link="Leg19"/>
       <child  link="Leg21"/>
       <origin rpy="0 0 0" xyz="1.173613327634438 0.9815041557529451 0" />
     <axis xyz="1 0 0"/>
       <limit effort="0.0" lower="-3.14159" upper="3.14159" velocity="0.0"/>
    </joint>
    <joint name="Leg21_Leg22" type="revolute">
       <parent link="Leg21"/>
       <child  link="Leg22"/>
       <origin rpy="0 0 0" xyz="2.10336290318719 0 0" />
     <axis xyz="1 0 0"/>
       <limit effort="0.0" lower="-3.14159" upper="3.14159" velocity="0.0"/>
    </joint>
    <joint name="Leg6_Leg23" type="revolute">
       <parent link="Leg6"/>
       <child  link="Leg23"/>
       <origin rpy="0 0 0" xyz="1.3516333801939924 1.460850778469608 0.7321631094004132" />
     <axis xyz="1 0 0"/>
       <limit effort="0.0" lower="-3.14159" upper="3.14159" velocity="0.0"/>
    </joint>
    <joint name="Leg10_Leg24" type="revolute">
       <parent link="Leg10"/>
       <child  link="Leg24"/>
       <origin rpy="0 0 0" xyz="2.700190401497421 0.8846621359580965 0" />
     <axis xyz="1 0 0"/>
       <limit effort="0.0" lower="-3.14159" upper="3.14159" velocity="0.0"/>
    </joint>
</robot>