<robot name = "robot">
    <link name="Torso">
        <inertial>
            <origin xyz="0 0 1.1630243955618418" rpy="0 0 0"/>
            <mass value="1" />
            <inertia ixx="100" ixy="0" ixz="0" iyy="100" iyz="0" izz="100" />
        </inertial>
        <visual>
            <origin xyz="0 0 1.1630243955618418" rpy="0 0 0"/>
            <geometry>
                <box size="2.3508496940662993 2.3854255187072138 2.3260487911236836" />
            </geometry>
            <material name="Green">
                <color rgba="0 180.0 0.0 1.0"/>
            </material>
        </visual>
        <collision>
            <origin xyz="0 0 1.1630243955618418" rpy="0 0 0"/>
            <geometry>
                <box size="2.3508496940662993 2.3854255187072138 2.3260487911236836" />
            </geometry>
        </collision>
    </link>
    <link name="Leg1">
        <inertial>
            <origin xyz="0.7890019910495346 0 0" rpy="0 0 0"/>
            <mass value="1" />
            <inertia ixx="100" ixy="0" ixz="0" iyy="100" iyz="0" izz="100" />
        </inertial>
        <visual>
            <origin xyz="0.7890019910495346 0 0" rpy="0 0 0"/>
            <geometry>
                <box size="1.5780039820990692 1.6918457389279424 1.1977143074900807" />
            </geometry>
            <material name="Blue">
                <color rgba="0 1.0 1.0 1.0"/>
            </material>
        </visual>
        <collision>
            <origin xyz="0.7890019910495346 0 0" rpy="0 0 0"/>
            <geometry>
                <box size="1.5780039820990692 1.6918457389279424 1.1977143074900807" />
            </geometry>
        </collision>
    </link>
    <link name="Leg2">
        <inertial>
            <origin xyz="0 0.5015507507399196 0" rpy="0 0 0"/>
            <mass value="1" />
            <inertia ixx="100" ixy="0" ixz="0" iyy="100" iyz="0" izz="100" />
        </inertial>
        <visual>
            <origin xyz="0 0.5015507507399196 0" rpy="0 0 0"/>
            <geometry>
                <box size="2.1852813051617535 1.0031015014798392 1.0737836612790592" />
            </geometry>
            <material name="Blue">
                <color rgba="0 1.0 1.0 1.0"/>
            </material>
        </visual>
        <collision>
            <origin xyz="0 0.5015507507399196 0" rpy="0 0 0"/>
            <geometry>
                <box size="2.1852813051617535 1.0031015014798392 1.0737836612790592" />
            </geometry>
        </collision>
    </link>
    <link name="Leg3">
        <inertial>
            <origin xyz="0 0 1.279572147369592" rpy="0 0 0"/>
            <mass value="1" />
            <inertia ixx="100" ixy="0" ixz="0" iyy="100" iyz="0" izz="100" />
        </inertial>
        <visual>
            <origin xyz="0 0 1.279572147369592" rpy="0 0 0"/>
            <geometry>
                <box size="2.986356721573289 2.2965252313293973 2.559144294739184" />
            </geometry>
            <material name="Blue">
                <color rgba="0 1.0 1.0 1.0"/>
            </material>
        </visual>
        <collision>
            <origin xyz="0 0 1.279572147369592" rpy="0 0 0"/>
            <geometry>
                <box size="2.986356721573289 2.2965252313293973 2.559144294739184" />
            </geometry>
        </collision>
    </link>
    <link name="Leg4">
        <inertial>
            <origin xyz="1.1012763344053034 0 0" rpy="0 0 0"/>
            <mass value="1" />
            <inertia ixx="100" ixy="0" ixz="0" iyy="100" iyz="0" izz="100" />
        </inertial>
        <visual>
            <origin xyz="1.1012763344053034 0 0" rpy="0 0 0"/>
            <geometry>
                <box size="2.2025526688106067 1.3745695999245204 1.5721261871143957" />
            </geometry>
            <material name="Blue">
                <color rgba="0 1.0 1.0 1.0"/>
            </material>
        </visual>
        <collision>
            <origin xyz="1.1012763344053034 0 0" rpy="0 0 0"/>
            <geometry>
                <box size="2.2025526688106067 1.3745695999245204 1.5721261871143957" />
            </geometry>
        </collision>
    </link>
    <link name="Leg5">
        <inertial>
            <origin xyz="0.5831409643710507 0 0" rpy="0 0 0"/>
            <mass value="1" />
            <inertia ixx="100" ixy="0" ixz="0" iyy="100" iyz="0" izz="100" />
        </inertial>
        <visual>
            <origin xyz="0.5831409643710507 0 0" rpy="0 0 0"/>
            <geometry>
                <box size="1.1662819287421013 2.28738016174834 2.7183507404895355" />
            </geometry>
            <material name="Blue">
                <color rgba="0 1.0 1.0 1.0"/>
            </material>
        </visual>
        <collision>
            <origin xyz="0.5831409643710507 0 0" rpy="0 0 0"/>
            <geometry>
                <box size="1.1662819287421013 2.28738016174834 2.7183507404895355" />
            </geometry>
        </collision>
    </link>
    <link name="Leg6">
        <inertial>
            <origin xyz="0.936384038211345 0 0" rpy="0 0 0"/>
            <mass value="1" />
            <inertia ixx="100" ixy="0" ixz="0" iyy="100" iyz="0" izz="100" />
        </inertial>
        <visual>
            <origin xyz="0.936384038211345 0 0" rpy="0 0 0"/>
            <geometry>
                <box size="1.87276807642269 1.141973522320663 2.657260261520335" />
            </geometry>
            <material name="Green">
                <color rgba="0 180.0 0.0 1.0"/>
            </material>
        </visual>
        <collision>
            <origin xyz="0.936384038211345 0 0" rpy="0 0 0"/>
            <geometry>
                <box size="1.87276807642269 1.141973522320663 2.657260261520335" />
            </geometry>
        </collision>
    </link>
    <link name="Leg7">
        <inertial>
            <origin xyz="0 0 1.2153045920958694" rpy="0 0 0"/>
            <mass value="1" />
            <inertia ixx="100" ixy="0" ixz="0" iyy="100" iyz="0" izz="100" />
        </inertial>
        <visual>
            <origin xyz="0 0 1.2153045920958694" rpy="0 0 0"/>
            <geometry>
                <box size="1.846310232693978 1.3774844521265224 2.4306091841917388" />
            </geometry>
            <material name="Blue">
                <color rgba="0 1.0 1.0 1.0"/>
            </material>
        </visual>
        <collision>
            <origin xyz="0 0 1.2153045920958694" rpy="0 0 0"/>
            <geometry>
                <box size="1.846310232693978 1.3774844521265224 2.4306091841917388" />
            </geometry>
        </collision>
    </link>
    <link name="Leg8">
        <inertial>
            <origin xyz="1.0637855045173843 0 0" rpy="0 0 0"/>
            <mass value="1" />
            <inertia ixx="100" ixy="0" ixz="0" iyy="100" iyz="0" izz="100" />
        </inertial>
        <visual>
            <origin xyz="1.0637855045173843 0 0" rpy="0 0 0"/>
            <geometry>
                <box size="2.1275710090347686 1.0476858277720074 1.0821188313733252" />
            </geometry>
            <material name="Green">
                <color rgba="0 180.0 0.0 1.0"/>
            </material>
        </visual>
        <collision>
            <origin xyz="1.0637855045173843 0 0" rpy="0 0 0"/>
            <geometry>
                <box size="2.1275710090347686 1.0476858277720074 1.0821188313733252" />
            </geometry>
        </collision>
    </link>
    <link name="Leg9">
        <inertial>
            <origin xyz="0.8942758311484938 0 0" rpy="0 0 0"/>
            <mass value="1" />
            <inertia ixx="100" ixy="0" ixz="0" iyy="100" iyz="0" izz="100" />
        </inertial>
        <visual>
            <origin xyz="0.8942758311484938 0 0" rpy="0 0 0"/>
            <geometry>
                <box size="1.7885516622969877 2.387632734196087 1.2207114492218811" />
            </geometry>
            <material name="Green">
                <color rgba="0 180.0 0.0 1.0"/>
            </material>
        </visual>
        <collision>
            <origin xyz="0.8942758311484938 0 0" rpy="0 0 0"/>
            <geometry>
                <box size="1.7885516622969877 2.387632734196087 1.2207114492218811" />
            </geometry>
        </collision>
    </link>
    <link name="Leg10">
        <inertial>
            <origin xyz="0 0.9633404026385429 0" rpy="0 0 0"/>
            <mass value="1" />
            <inertia ixx="100" ixy="0" ixz="0" iyy="100" iyz="0" izz="100" />
        </inertial>
        <visual>
            <origin xyz="0 0.9633404026385429 0" rpy="0 0 0"/>
            <geometry>
                <box size="1.9829328798194792 1.9266808052770859 2.763267940032141" />
            </geometry>
            <material name="Green">
                <color rgba="0 180.0 0.0 1.0"/>
            </material>
        </visual>
        <collision>
            <origin xyz="0 0.9633404026385429 0" rpy="0 0 0"/>
            <geometry>
                <box size="1.9829328798194792 1.9266808052770859 2.763267940032141" />
            </geometry>
        </collision>
    </link>
    <link name="Leg11">
        <inertial>
            <origin xyz="0 1.3403385852070289 0" rpy="0 0 0"/>
            <mass value="1" />
            <inertia ixx="100" ixy="0" ixz="0" iyy="100" iyz="0" izz="100" />
        </inertial>
        <visual>
            <origin xyz="0 1.3403385852070289 0" rpy="0 0 0"/>
            <geometry>
                <box size="2.0455765799851955 2.6806771704140577 2.582579349556008" />
            </geometry>
            <material name="Blue">
                <color rgba="0 1.0 1.0 1.0"/>
            </material>
        </visual>
        <collision>
            <origin xyz="0 1.3403385852070289 0" rpy="0 0 0"/>
            <geometry>
                <box size="2.0455765799851955 2.6806771704140577 2.582579349556008" />
            </geometry>
        </collision>
    </link>
    <link name="Leg12">
        <inertial>
            <origin xyz="0.6679329480809028 0 0" rpy="0 0 0"/>
            <mass value="1" />
            <inertia ixx="100" ixy="0" ixz="0" iyy="100" iyz="0" izz="100" />
        </inertial>
        <visual>
            <origin xyz="0.6679329480809028 0 0" rpy="0 0 0"/>
            <geometry>
                <box size="1.3358658961618055 2.0118832691825252 1.6020315240720153" />
            </geometry>
            <material name="Blue">
                <color rgba="0 1.0 1.0 1.0"/>
            </material>
        </visual>
        <collision>
            <origin xyz="0.6679329480809028 0 0" rpy="0 0 0"/>
            <geometry>
                <box size="1.3358658961618055 2.0118832691825252 1.6020315240720153" />
            </geometry>
        </collision>
    </link>
    <link name="Leg13">
        <inertial>
            <origin xyz="0 1.2721484059032706 0" rpy="0 0 0"/>
            <mass value="1" />
            <inertia ixx="100" ixy="0" ixz="0" iyy="100" iyz="0" izz="100" />
        </inertial>
        <visual>
            <origin xyz="0 1.2721484059032706 0" rpy="0 0 0"/>
            <geometry>
                <box size="1.9773776276271495 2.544296811806541 1.383800899744224" />
            </geometry>
            <material name="Green">
                <color rgba="0 180.0 0.0 1.0"/>
            </material>
        </visual>
        <collision>
            <origin xyz="0 1.2721484059032706 0" rpy="0 0 0"/>
            <geometry>
                <box size="1.9773776276271495 2.544296811806541 1.383800899744224" />
            </geometry>
        </collision>
    </link>
    <link name="Leg14">
        <inertial>
            <origin xyz="0.8068191021597404 0 0" rpy="0 0 0"/>
            <mass value="1" />
            <inertia ixx="100" ixy="0" ixz="0" iyy="100" iyz="0" izz="100" />
        </inertial>
        <visual>
            <origin xyz="0.8068191021597404 0 0" rpy="0 0 0"/>
            <geometry>
                <box size="1.6136382043194808 2.984668009510975 2.8445857118023667" />
            </geometry>
            <material name="Green">
                <color rgba="0 180.0 0.0 1.0"/>
            </material>
        </visual>
        <collision>
            <origin xyz="0.8068191021597404 0 0" rpy="0 0 0"/>
            <geometry>
                <box size="1.6136382043194808 2.984668009510975 2.8445857118023667" />
            </geometry>
        </collision>
    </link>
    <link name="Leg15">
        <inertial>
            <origin xyz="1.1994618206416465 0 0" rpy="0 0 0"/>
            <mass value="1" />
            <inertia ixx="100" ixy="0" ixz="0" iyy="100" iyz="0" izz="100" />
        </inertial>
        <visual>
            <origin xyz="1.1994618206416465 0 0" rpy="0 0 0"/>
            <geometry>
                <box size="2.398923641283293 2.569965494997544 2.6704203314098613" />
            </geometry>
            <material name="Blue">
                <color rgba="0 1.0 1.0 1.0"/>
            </material>
        </visual>
        <collision>
            <origin xyz="1.1994618206416465 0 0" rpy="0 0 0"/>
            <geometry>
                <box size="2.398923641283293 2.569965494997544 2.6704203314098613" />
            </geometry>
        </collision>
    </link>
    <link name="Leg16">
        <inertial>
            <origin xyz="0.8161465686824989 0 0" rpy="0 0 0"/>
            <mass value="1" />
            <inertia ixx="100" ixy="0" ixz="0" iyy="100" iyz="0" izz="100" />
        </inertial>
        <visual>
            <origin xyz="0.8161465686824989 0 0" rpy="0 0 0"/>
            <geometry>
                <box size="1.6322931373649978 1.3230206892024998 1.131142177902846" />
            </geometry>
            <material name="Green">
                <color rgba="0 180.0 0.0 1.0"/>
            </material>
        </visual>
        <collision>
            <origin xyz="0.8161465686824989 0 0" rpy="0 0 0"/>
            <geometry>
                <box size="1.6322931373649978 1.3230206892024998 1.131142177902846" />
            </geometry>
        </collision>
    </link>
    <link name="Leg17">
        <inertial>
            <origin xyz="1.3548679126583245 0 0" rpy="0 0 0"/>
            <mass value="1" />
            <inertia ixx="100" ixy="0" ixz="0" iyy="100" iyz="0" izz="100" />
        </inertial>
        <visual>
            <origin xyz="1.3548679126583245 0 0" rpy="0 0 0"/>
            <geometry>
                <box size="2.709735825316649 1.4783676421254826 2.19763812168359" />
            </geometry>
            <material name="Green">
                <color rgba="0 180.0 0.0 1.0"/>
            </material>
        </visual>
        <collision>
            <origin xyz="1.3548679126583245 0 0" rpy="0 0 0"/>
            <geometry>
                <box size="2.709735825316649 1.4783676421254826 2.19763812168359" />
            </geometry>
        </collision>
    </link>
    <link name="Leg18">
        <inertial>
            <origin xyz="0 0 1.153063185115248" rpy="0 0 0"/>
            <mass value="1" />
            <inertia ixx="100" ixy="0" ixz="0" iyy="100" iyz="0" izz="100" />
        </inertial>
        <visual>
            <origin xyz="0 0 1.153063185115248" rpy="0 0 0"/>
            <geometry>
                <box size="2.083787083404757 2.067029010993246 2.306126370230496" />
            </geometry>
            <material name="Blue">
                <color rgba="0 1.0 1.0 1.0"/>
            </material>
        </visual>
        <collision>
            <origin xyz="0 0 1.153063185115248" rpy="0 0 0"/>
            <geometry>
                <box size="2.083787083404757 2.067029010993246 2.306126370230496" />
            </geometry>
        </collision>
    </link>
    <link name="Leg19">
        <inertial>
            <origin xyz="1.0025182102249448 0 0" rpy="0 0 0"/>
            <mass value="1" />
            <inertia ixx="100" ixy="0" ixz="0" iyy="100" iyz="0" izz="100" />
        </inertial>
        <visual>
            <origin xyz="1.0025182102249448 0 0" rpy="0 0 0"/>
            <geometry>
                <box size="2.0050364204498896 2.314127067204333 2.4776058160201044" />
            </geometry>
            <material name="Green">
                <color rgba="0 180.0 0.0 1.0"/>
            </material>
        </visual>
        <collision>
            <origin xyz="1.0025182102249448 0 0" rpy="0 0 0"/>
            <geometry>
                <box size="2.0050364204498896 2.314127067204333 2.4776058160201044" />
            </geometry>
        </collision>
    </link>
    <link name="Leg20">
        <inertial>
            <origin xyz="0 1.0111820740997386 0" rpy="0 0 0"/>
            <mass value="1" />
            <inertia ixx="100" ixy="0" ixz="0" iyy="100" iyz="0" izz="100" />
        </inertial>
        <visual>
            <origin xyz="0 1.0111820740997386 0" rpy="0 0 0"/>
            <geometry>
                <box size="1.510614010777202 2.022364148199477 1.0121792255387927" />
            </geometry>
            <material name="Green">
                <color rgba="0 180.0 0.0 1.0"/>
            </material>
        </visual>
        <collision>
            <origin xyz="0 1.0111820740997386 0" rpy="0 0 0"/>
            <geometry>
                <box size="1.510614010777202 2.022364148199477 1.0121792255387927" />
            </geometry>
        </collision>
    </link>
    <link name="Leg21">
        <inertial>
            <origin xyz="0 0 0.549254913223842" rpy="0 0 0"/>
            <mass value="1" />
            <inertia ixx="100" ixy="0" ixz="0" iyy="100" iyz="0" izz="100" />
        </inertial>
        <visual>
            <origin xyz="0 0 0.549254913223842" rpy="0 0 0"/>
            <geometry>
                <box size="2.1028544586542495 1.300455084574177 1.098509826447684" />
            </geometry>
            <material name="Green">
                <color rgba="0 180.0 0.0 1.0"/>
            </material>
        </visual>
        <collision>
            <origin xyz="0 0 0.549254913223842" rpy="0 0 0"/>
            <geometry>
                <box size="2.1028544586542495 1.300455084574177 1.098509826447684" />
            </geometry>
        </collision>
    </link>
    <link name="Leg22">
        <inertial>
            <origin xyz="0 1.002253522734465 0" rpy="0 0 0"/>
            <mass value="1" />
            <inertia ixx="100" ixy="0" ixz="0" iyy="100" iyz="0" izz="100" />
        </inertial>
        <visual>
            <origin xyz="0 1.002253522734465 0" rpy="0 0 0"/>
            <geometry>
                <box size="1.4702281568968694 2.00450704546893 1.2030306269728828" />
            </geometry>
            <material name="Blue">
                <color rgba="0 1.0 1.0 1.0"/>
            </material>
        </visual>
        <collision>
            <origin xyz="0 1.002253522734465 0" rpy="0 0 0"/>
            <geometry>
                <box size="1.4702281568968694 2.00450704546893 1.2030306269728828" />
            </geometry>
        </collision>
    </link>
    <link name="Leg23">
        <inertial>
            <origin xyz="0 1.0669326522672864 0" rpy="0 0 0"/>
            <mass value="1" />
            <inertia ixx="100" ixy="0" ixz="0" iyy="100" iyz="0" izz="100" />
        </inertial>
        <visual>
            <origin xyz="0 1.0669326522672864 0" rpy="0 0 0"/>
            <geometry>
                <box size="1.67657817958334 2.133865304534573 2.551000889745473" />
            </geometry>
            <material name="Blue">
                <color rgba="0 1.0 1.0 1.0"/>
            </material>
        </visual>
        <collision>
            <origin xyz="0 1.0669326522672864 0" rpy="0 0 0"/>
            <geometry>
                <box size="1.67657817958334 2.133865304534573 2.551000889745473" />
            </geometry>
        </collision>
    </link>
    <link name="Leg24">
        <inertial>
            <origin xyz="0 0.9238564363407064 0" rpy="0 0 0"/>
            <mass value="1" />
            <inertia ixx="100" ixy="0" ixz="0" iyy="100" iyz="0" izz="100" />
        </inertial>
        <visual>
            <origin xyz="0 0.9238564363407064 0" rpy="0 0 0"/>
            <geometry>
                <box size="1.541374690668158 1.8477128726814127 1.0746950581238297" />
            </geometry>
            <material name="Blue">
                <color rgba="0 1.0 1.0 1.0"/>
            </material>
        </visual>
        <collision>
            <origin xyz="0 0.9238564363407064 0" rpy="0 0 0"/>
            <geometry>
                <box size="1.541374690668158 1.8477128726814127 1.0746950581238297" />
            </geometry>
        </collision>
    </link>
    <link name="Leg25">
        <inertial>
            <origin xyz="0 0.5160179610439762 0" rpy="0 0 0"/>
            <mass value="1" />
            <inertia ixx="100" ixy="0" ixz="0" iyy="100" iyz="0" izz="100" />
        </inertial>
        <visual>
            <origin xyz="0 0.5160179610439762 0" rpy="0 0 0"/>
            <geometry>
                <box size="2.1150682480030083 1.0320359220879525 1.428742117280696" />
            </geometry>
            <material name="Blue">
                <color rgba="0 1.0 1.0 1.0"/>
            </material>
        </visual>
        <collision>
            <origin xyz="0 0.5160179610439762 0" rpy="0 0 0"/>
            <geometry>
                <box size="2.1150682480030083 1.0320359220879525 1.428742117280696" />
            </geometry>
        </collision>
    </link>
    <link name="Leg26">
        <inertial>
            <origin xyz="0 0 1.235460839131632" rpy="0 0 0"/>
            <mass value="1" />
            <inertia ixx="100" ixy="0" ixz="0" iyy="100" iyz="0" izz="100" />
        </inertial>
        <visual>
            <origin xyz="0 0 1.235460839131632" rpy="0 0 0"/>
            <geometry>
                <box size="1.0954755389065896 1.5190960633077497 2.470921678263264" />
            </geometry>
            <material name="Green">
                <color rgba="0 180.0 0.0 1.0"/>
            </material>
        </visual>
        <collision>
            <origin xyz="0 0 1.235460839131632" rpy="0 0 0"/>
            <geometry>
                <box size="1.0954755389065896 1.5190960633077497 2.470921678263264" />
            </geometry>
        </collision>
    </link>
    <link name="Leg27">
        <inertial>
            <origin xyz="0 0 1.1192475803273023" rpy="0 0 0"/>
            <mass value="1" />
            <inertia ixx="100" ixy="0" ixz="0" iyy="100" iyz="0" izz="100" />
        </inertial>
        <visual>
            <origin xyz="0 0 1.1192475803273023" rpy="0 0 0"/>
            <geometry>
                <box size="1.2293155862222243 1.7508056746954772 2.2384951606546046" />
            </geometry>
            <material name="Green">
                <color rgba="0 180.0 0.0 1.0"/>
            </material>
        </visual>
        <collision>
            <origin xyz="0 0 1.1192475803273023" rpy="0 0 0"/>
            <geometry>
                <box size="1.2293155862222243 1.7508056746954772 2.2384951606546046" />
            </geometry>
        </collision>
    </link>
    <joint name="Torso_Leg1" type="revolute">
       <parent link="Torso"/>
       <child  link="Leg1"/>
       <origin rpy="0 0 0" xyz="1.1754248470331496 0 1.1630243955618418" />
     <axis xyz="1 0 0"/>
       <limit effort="0.0" lower="-3.14159" upper="3.14159" velocity="0.0"/>
    </joint>
    <joint name="Torso_Leg2" type="revolute">
       <parent link="Torso"/>
       <child  link="Leg2"/>
       <origin rpy="0 0 0" xyz="0.7890019910495346 0.8459228694639712 0" />
     <axis xyz="1 0 0"/>
       <limit effort="0.0" lower="-3.14159" upper="3.14159" velocity="0.0"/>
    </joint>
    <joint name="Leg1_Leg3" type="revolute">
       <parent link="Leg1"/>
       <child  link="Leg3"/>
       <origin rpy="0 0 0" xyz="0 0.5015507507399196 0.5368918306395296" />
     <axis xyz="1 0 0"/>
       <limit effort="0.0" lower="-3.14159" upper="3.14159" velocity="0.0"/>
    </joint>
    <joint name="Leg2_Leg4" type="revolute">
       <parent link="Leg2"/>
       <child  link="Leg4"/>
       <origin rpy="0 0 0" xyz="1.4931783607866445 0 1.279572147369592" />
     <axis xyz="1 0 0"/>
       <limit effort="0.0" lower="-3.14159" upper="3.14159" velocity="0.0"/>
    </joint>
    <joint name="Leg3_Leg5" type="revolute">
       <parent link="Leg3"/>
       <child  link="Leg5"/>
       <origin rpy="0 0 0" xyz="2.2025526688106067 0 0" />
     <axis xyz="1 0 0"/>
       <limit effort="0.0" lower="-3.14159" upper="3.14159" velocity="0.0"/>
    </joint>
    <joint name="Leg4_Leg6" type="revolute">
       <parent link="Leg4"/>
       <child  link="Leg6"/>
       <origin rpy="0 0 0" xyz="1.1662819287421013 0 0" />
     <axis xyz="1 0 0"/>
       <limit effort="0.0" lower="-3.14159" upper="3.14159" velocity="0.0"/>
    </joint>
    <joint name="Leg4_Leg7" type="revolute">
       <parent link="Leg4"/>
       <child  link="Leg7"/>
       <origin rpy="0 0 0" xyz="1.1662819287421013 0 1.3591753702447678" />
     <axis xyz="1 0 0"/>
       <limit effort="0.0" lower="-3.14159" upper="3.14159" velocity="0.0"/>
    </joint>
    <joint name="Leg6_Leg8" type="revolute">
       <parent link="Leg6"/>
       <child  link="Leg8"/>
       <origin rpy="0 0 0" xyz="0.923155116346989 0 1.2153045920958694" />
     <axis xyz="1 0 0"/>
       <limit effort="0.0" lower="-3.14159" upper="3.14159" velocity="0.0"/>
    </joint>
    <joint name="Leg5_Leg9" type="revolute">
       <parent link="Leg5"/>
       <child  link="Leg9"/>
       <origin rpy="0 0 0" xyz="1.87276807642269 0 0" />
     <axis xyz="1 0 0"/>
       <limit effort="0.0" lower="-3.14159" upper="3.14159" velocity="0.0"/>
    </joint>
    <joint name="Leg2_Leg10" type="revolute">
       <parent link="Leg2"/>
       <child  link="Leg10"/>
       <origin rpy="0 0 0" xyz="1.4931783607866445 1.1482626156646987 1.279572147369592" />
     <axis xyz="1 0 0"/>
       <limit effort="0.0" lower="-3.14159" upper="3.14159" velocity="0.0"/>
    </joint>
    <joint name="Leg8_Leg11" type="revolute">
       <parent link="Leg8"/>
       <child  link="Leg11"/>
       <origin rpy="0 0 0" xyz="0.8942758311484938 1.1938163670980435 0" />
     <axis xyz="1 0 0"/>
       <limit effort="0.0" lower="-3.14159" upper="3.14159" velocity="0.0"/>
    </joint>
    <joint name="Leg11_Leg12" type="revolute">
       <parent link="Leg11"/>
       <child  link="Leg12"/>
       <origin rpy="0 0 0" xyz="1.3358658961618055 0 0" />
     <axis xyz="1 0 0"/>
       <limit effort="0.0" lower="-3.14159" upper="3.14159" velocity="0.0"/>
    </joint>
    <joint name="Leg10_Leg13" type="revolute">
       <parent link="Leg10"/>
       <child  link="Leg13"/>
       <origin rpy="0 0 0" xyz="0 2.6806771704140577 0" />
     <axis xyz="1 0 0"/>
       <limit effort="0.0" lower="-3.14159" upper="3.14159" velocity="0.0"/>
    </joint>
    <joint name="Leg9_Leg14" type="revolute">
       <parent link="Leg9"/>
       <child  link="Leg14"/>
       <origin rpy="0 0 0" xyz="0.9914664399097396 0.9633404026385429 0" />
     <axis xyz="1 0 0"/>
       <limit effort="0.0" lower="-3.14159" upper="3.14159" velocity="0.0"/>
    </joint>
    <joint name="Leg10_Leg15" type="revolute">
       <parent link="Leg10"/>
       <child  link="Leg15"/>
       <origin rpy="0 0 0" xyz="1.0227882899925977 2.6806771704140577 0" />
     <axis xyz="1 0 0"/>
       <limit effort="0.0" lower="-3.14159" upper="3.14159" velocity="0.0"/>
    </joint>
    <joint name="Leg14_Leg16" type="revolute">
       <parent link="Leg14"/>
       <child  link="Leg16"/>
       <origin rpy="0 0 0" xyz="2.398923641283293 0 0" />
     <axis xyz="1 0 0"/>
       <limit effort="0.0" lower="-3.14159" upper="3.14159" velocity="0.0"/>
    </joint>
    <joint name="Leg13_Leg17" type="revolute">
       <parent link="Leg13"/>
       <child  link="Leg17"/>
       <origin rpy="0 0 0" xyz="1.6136382043194808 0 0" />
     <axis xyz="1 0 0"/>
       <limit effort="0.0" lower="-3.14159" upper="3.14159" velocity="0.0"/>
    </joint>
    <joint name="Leg12_Leg18" type="revolute">
       <parent link="Leg12"/>
       <child  link="Leg18"/>
       <origin rpy="0 0 0" xyz="0 1.2721484059032706 0.691900449872112" />
     <axis xyz="1 0 0"/>
       <limit effort="0.0" lower="-3.14159" upper="3.14159" velocity="0.0"/>
    </joint>
    <joint name="Leg16_Leg19" type="revolute">
       <parent link="Leg16"/>
       <child  link="Leg19"/>
       <origin rpy="0 0 0" xyz="2.709735825316649 0 0" />
     <axis xyz="1 0 0"/>
       <limit effort="0.0" lower="-3.14159" upper="3.14159" velocity="0.0"/>
    </joint>
    <joint name="Leg3_Leg20" type="revolute">
       <parent link="Leg3"/>
       <child  link="Leg20"/>
       <origin rpy="0 0 0" xyz="2.2025526688106067 0.6872847999622602 0" />
     <axis xyz="1 0 0"/>
       <limit effort="0.0" lower="-3.14159" upper="3.14159" velocity="0.0"/>
    </joint>
    <joint name="Leg3_Leg21" type="revolute">
       <parent link="Leg3"/>
       <child  link="Leg21"/>
       <origin rpy="0 0 0" xyz="2.2025526688106067 0.6872847999622602 0.7860630935571978" />
     <axis xyz="1 0 0"/>
       <limit effort="0.0" lower="-3.14159" upper="3.14159" velocity="0.0"/>
    </joint>
    <joint name="Leg14_Leg22" type="revolute">
       <parent link="Leg14"/>
       <child  link="Leg22"/>
       <origin rpy="0 0 0" xyz="2.398923641283293 1.284982747498772 0" />
     <axis xyz="1 0 0"/>
       <limit effort="0.0" lower="-3.14159" upper="3.14159" velocity="0.0"/>
    </joint>
    <joint name="Leg12_Leg23" type="revolute">
       <parent link="Leg12"/>
       <child  link="Leg23"/>
       <origin rpy="0 0 0" xyz="0 2.544296811806541 0.691900449872112" />
     <axis xyz="1 0 0"/>
       <limit effort="0.0" lower="-3.14159" upper="3.14159" velocity="0.0"/>
    </joint>
    <joint name="Leg19_Leg24" type="revolute">
       <parent link="Leg19"/>
       <child  link="Leg24"/>
       <origin rpy="0 0 0" xyz="0 2.022364148199477 0" />
     <axis xyz="1 0 0"/>
       <limit effort="0.0" lower="-3.14159" upper="3.14159" velocity="0.0"/>
    </joint>
    <joint name="Leg15_Leg25" type="revolute">
       <parent link="Leg15"/>
       <child  link="Leg25"/>
       <origin rpy="0 0 0" xyz="0.8161465686824989 0.6615103446012499 0" />
     <axis xyz="1 0 0"/>
       <limit effort="0.0" lower="-3.14159" upper="3.14159" velocity="0.0"/>
    </joint>
    <joint name="Leg19_Leg26" type="revolute">
       <parent link="Leg19"/>
       <child  link="Leg26"/>
       <origin rpy="0 0 0" xyz="0 2.022364148199477 0.5060896127693963" />
     <axis xyz="1 0 0"/>
       <limit effort="0.0" lower="-3.14159" upper="3.14159" velocity="0.0"/>
    </joint>
    <joint name="Leg14_Leg27" type="revolute">
       <parent link="Leg14"/>
       <child  link="Leg27"/>
       <origin rpy="0 0 0" xyz="2.398923641283293 1.284982747498772 1.3352101657049307" />
     <axis xyz="1 0 0"/>
       <limit effort="0.0" lower="-3.14159" upper="3.14159" velocity="0.0"/>
    </joint>
</robot>