<robot name = "robot">
    <link name="Torso">
        <inertial>
            <origin xyz="0 0 0.5652484247187491" rpy="0 0 0"/>
            <mass value="1" />
            <inertia ixx="100" ixy="0" ixz="0" iyy="100" iyz="0" izz="100" />
        </inertial>
        <visual>
            <origin xyz="0 0 0.5652484247187491" rpy="0 0 0"/>
            <geometry>
                <box size="2.4402045671971786 1.0872470443236975 1.1304968494374983" />
            </geometry>
            <material name="Green">
                <color rgba="0 180.0 0.0 1.0"/>
            </material>
        </visual>
        <collision>
            <origin xyz="0 0 0.5652484247187491" rpy="0 0 0"/>
            <geometry>
                <box size="2.4402045671971786 1.0872470443236975 1.1304968494374983" />
            </geometry>
        </collision>
    </link>
    <link name="Leg1">
        <inertial>
            <origin xyz="0 0 0.6598846101725276" rpy="0 0 0"/>
            <mass value="1" />
            <inertia ixx="100" ixy="0" ixz="0" iyy="100" iyz="0" izz="100" />
        </inertial>
        <visual>
            <origin xyz="0 0 0.6598846101725276" rpy="0 0 0"/>
            <geometry>
                <box size="1.6614297564102363 2.2399776313149697 1.3197692203450553" />
            </geometry>
            <material name="Green">
                <color rgba="0 180.0 0.0 1.0"/>
            </material>
        </visual>
        <collision>
            <origin xyz="0 0 0.6598846101725276" rpy="0 0 0"/>
            <geometry>
                <box size="1.6614297564102363 2.2399776313149697 1.3197692203450553" />
            </geometry>
        </collision>
    </link>
    <link name="Leg2">
        <inertial>
            <origin xyz="0 0 0.5009871150429326" rpy="0 0 0"/>
            <mass value="1" />
            <inertia ixx="100" ixy="0" ixz="0" iyy="100" iyz="0" izz="100" />
        </inertial>
        <visual>
            <origin xyz="0 0 0.5009871150429326" rpy="0 0 0"/>
            <geometry>
                <box size="2.3533038163895146 2.8584392551889897 1.0019742300858652" />
            </geometry>
            <material name="Blue">
                <color rgba="0 1.0 1.0 1.0"/>
            </material>
        </visual>
        <collision>
            <origin xyz="0 0 0.5009871150429326" rpy="0 0 0"/>
            <geometry>
                <box size="2.3533038163895146 2.8584392551889897 1.0019742300858652" />
            </geometry>
        </collision>
    </link>
    <link name="Leg3">
        <inertial>
            <origin xyz="1.1127041148320447 0 0" rpy="0 0 0"/>
            <mass value="1" />
            <inertia ixx="100" ixy="0" ixz="0" iyy="100" iyz="0" izz="100" />
        </inertial>
        <visual>
            <origin xyz="1.1127041148320447 0 0" rpy="0 0 0"/>
            <geometry>
                <box size="2.2254082296640894 2.943416453808884 1.3711669309964056" />
            </geometry>
            <material name="Blue">
                <color rgba="0 1.0 1.0 1.0"/>
            </material>
        </visual>
        <collision>
            <origin xyz="1.1127041148320447 0 0" rpy="0 0 0"/>
            <geometry>
                <box size="2.2254082296640894 2.943416453808884 1.3711669309964056" />
            </geometry>
        </collision>
    </link>
    <link name="Leg4">
        <inertial>
            <origin xyz="0 0 0.6020331208628072" rpy="0 0 0"/>
            <mass value="1" />
            <inertia ixx="100" ixy="0" ixz="0" iyy="100" iyz="0" izz="100" />
        </inertial>
        <visual>
            <origin xyz="0 0 0.6020331208628072" rpy="0 0 0"/>
            <geometry>
                <box size="1.2763076925793337 1.4168346107844156 1.2040662417256145" />
            </geometry>
            <material name="Blue">
                <color rgba="0 1.0 1.0 1.0"/>
            </material>
        </visual>
        <collision>
            <origin xyz="0 0 0.6020331208628072" rpy="0 0 0"/>
            <geometry>
                <box size="1.2763076925793337 1.4168346107844156 1.2040662417256145" />
            </geometry>
        </collision>
    </link>
    <link name="Leg5">
        <inertial>
            <origin xyz="0 0 0.5198172084946867" rpy="0 0 0"/>
            <mass value="1" />
            <inertia ixx="100" ixy="0" ixz="0" iyy="100" iyz="0" izz="100" />
        </inertial>
        <visual>
            <origin xyz="0 0 0.5198172084946867" rpy="0 0 0"/>
            <geometry>
                <box size="2.836813498781714 2.5635728456558837 1.0396344169893734" />
            </geometry>
            <material name="Blue">
                <color rgba="0 1.0 1.0 1.0"/>
            </material>
        </visual>
        <collision>
            <origin xyz="0 0 0.5198172084946867" rpy="0 0 0"/>
            <geometry>
                <box size="2.836813498781714 2.5635728456558837 1.0396344169893734" />
            </geometry>
        </collision>
    </link>
    <link name="Leg6">
        <inertial>
            <origin xyz="0 1.3169231100350909 0" rpy="0 0 0"/>
            <mass value="1" />
            <inertia ixx="100" ixy="0" ixz="0" iyy="100" iyz="0" izz="100" />
        </inertial>
        <visual>
            <origin xyz="0 1.3169231100350909 0" rpy="0 0 0"/>
            <geometry>
                <box size="2.5362171011517463 2.6338462200701818 2.2473349434376586" />
            </geometry>
            <material name="Blue">
                <color rgba="0 1.0 1.0 1.0"/>
            </material>
        </visual>
        <collision>
            <origin xyz="0 1.3169231100350909 0" rpy="0 0 0"/>
            <geometry>
                <box size="2.5362171011517463 2.6338462200701818 2.2473349434376586" />
            </geometry>
        </collision>
    </link>
    <link name="Leg7">
        <inertial>
            <origin xyz="0 1.0305662848149315 0" rpy="0 0 0"/>
            <mass value="1" />
            <inertia ixx="100" ixy="0" ixz="0" iyy="100" iyz="0" izz="100" />
        </inertial>
        <visual>
            <origin xyz="0 1.0305662848149315 0" rpy="0 0 0"/>
            <geometry>
                <box size="2.5608518020254314 2.061132569629863 2.6260901590344785" />
            </geometry>
            <material name="Blue">
                <color rgba="0 1.0 1.0 1.0"/>
            </material>
        </visual>
        <collision>
            <origin xyz="0 1.0305662848149315 0" rpy="0 0 0"/>
            <geometry>
                <box size="2.5608518020254314 2.061132569629863 2.6260901590344785" />
            </geometry>
        </collision>
    </link>
    <link name="Leg8">
        <inertial>
            <origin xyz="0 1.1134268229585156 0" rpy="0 0 0"/>
            <mass value="1" />
            <inertia ixx="100" ixy="0" ixz="0" iyy="100" iyz="0" izz="100" />
        </inertial>
        <visual>
            <origin xyz="0 1.1134268229585156 0" rpy="0 0 0"/>
            <geometry>
                <box size="2.5690175131102677 2.226853645917031 1.8615416579455344" />
            </geometry>
            <material name="Blue">
                <color rgba="0 1.0 1.0 1.0"/>
            </material>
        </visual>
        <collision>
            <origin xyz="0 1.1134268229585156 0" rpy="0 0 0"/>
            <geometry>
                <box size="2.5690175131102677 2.226853645917031 1.8615416579455344" />
            </geometry>
        </collision>
    </link>
    <link name="Leg9">
        <inertial>
            <origin xyz="1.3256756102746956 0 0" rpy="0 0 0"/>
            <mass value="1" />
            <inertia ixx="100" ixy="0" ixz="0" iyy="100" iyz="0" izz="100" />
        </inertial>
        <visual>
            <origin xyz="1.3256756102746956 0 0" rpy="0 0 0"/>
            <geometry>
                <box size="2.651351220549391 1.3338368499965314 1.904439297249122" />
            </geometry>
            <material name="Blue">
                <color rgba="0 1.0 1.0 1.0"/>
            </material>
        </visual>
        <collision>
            <origin xyz="1.3256756102746956 0 0" rpy="0 0 0"/>
            <geometry>
                <box size="2.651351220549391 1.3338368499965314 1.904439297249122" />
            </geometry>
        </collision>
    </link>
    <link name="Leg10">
        <inertial>
            <origin xyz="1.132969954660342 0 0" rpy="0 0 0"/>
            <mass value="1" />
            <inertia ixx="100" ixy="0" ixz="0" iyy="100" iyz="0" izz="100" />
        </inertial>
        <visual>
            <origin xyz="1.132969954660342 0 0" rpy="0 0 0"/>
            <geometry>
                <box size="2.265939909320684 2.3908478907649506 2.720664759346503" />
            </geometry>
            <material name="Blue">
                <color rgba="0 1.0 1.0 1.0"/>
            </material>
        </visual>
        <collision>
            <origin xyz="1.132969954660342 0 0" rpy="0 0 0"/>
            <geometry>
                <box size="2.265939909320684 2.3908478907649506 2.720664759346503" />
            </geometry>
        </collision>
    </link>
    <link name="Leg11">
        <inertial>
            <origin xyz="0.8627076902966023 0 0" rpy="0 0 0"/>
            <mass value="1" />
            <inertia ixx="100" ixy="0" ixz="0" iyy="100" iyz="0" izz="100" />
        </inertial>
        <visual>
            <origin xyz="0.8627076902966023 0 0" rpy="0 0 0"/>
            <geometry>
                <box size="1.7254153805932047 2.184843569253228 2.314685236621612" />
            </geometry>
            <material name="Green">
                <color rgba="0 180.0 0.0 1.0"/>
            </material>
        </visual>
        <collision>
            <origin xyz="0.8627076902966023 0 0" rpy="0 0 0"/>
            <geometry>
                <box size="1.7254153805932047 2.184843569253228 2.314685236621612" />
            </geometry>
        </collision>
    </link>
    <link name="Leg12">
        <inertial>
            <origin xyz="0 0 1.1349507625080844" rpy="0 0 0"/>
            <mass value="1" />
            <inertia ixx="100" ixy="0" ixz="0" iyy="100" iyz="0" izz="100" />
        </inertial>
        <visual>
            <origin xyz="0 0 1.1349507625080844" rpy="0 0 0"/>
            <geometry>
                <box size="2.3774542157285365 1.461883681391258 2.2699015250161687" />
            </geometry>
            <material name="Blue">
                <color rgba="0 1.0 1.0 1.0"/>
            </material>
        </visual>
        <collision>
            <origin xyz="0 0 1.1349507625080844" rpy="0 0 0"/>
            <geometry>
                <box size="2.3774542157285365 1.461883681391258 2.2699015250161687" />
            </geometry>
        </collision>
    </link>
    <link name="Leg13">
        <inertial>
            <origin xyz="1.2079090277461155 0 0" rpy="0 0 0"/>
            <mass value="1" />
            <inertia ixx="100" ixy="0" ixz="0" iyy="100" iyz="0" izz="100" />
        </inertial>
        <visual>
            <origin xyz="1.2079090277461155 0 0" rpy="0 0 0"/>
            <geometry>
                <box size="2.415818055492231 2.0408569953327045 1.7291514292815937" />
            </geometry>
            <material name="Green">
                <color rgba="0 180.0 0.0 1.0"/>
            </material>
        </visual>
        <collision>
            <origin xyz="1.2079090277461155 0 0" rpy="0 0 0"/>
            <geometry>
                <box size="2.415818055492231 2.0408569953327045 1.7291514292815937" />
            </geometry>
        </collision>
    </link>
    <link name="Leg14">
        <inertial>
            <origin xyz="0.6099441694890217 0 0" rpy="0 0 0"/>
            <mass value="1" />
            <inertia ixx="100" ixy="0" ixz="0" iyy="100" iyz="0" izz="100" />
        </inertial>
        <visual>
            <origin xyz="0.6099441694890217 0 0" rpy="0 0 0"/>
            <geometry>
                <box size="1.2198883389780435 1.3795104398639233 2.172705229220744" />
            </geometry>
            <material name="Blue">
                <color rgba="0 1.0 1.0 1.0"/>
            </material>
        </visual>
        <collision>
            <origin xyz="0.6099441694890217 0 0" rpy="0 0 0"/>
            <geometry>
                <box size="1.2198883389780435 1.3795104398639233 2.172705229220744" />
            </geometry>
        </collision>
    </link>
    <link name="Leg15">
        <inertial>
            <origin xyz="0 0 1.0243848751535434" rpy="0 0 0"/>
            <mass value="1" />
            <inertia ixx="100" ixy="0" ixz="0" iyy="100" iyz="0" izz="100" />
        </inertial>
        <visual>
            <origin xyz="0 0 1.0243848751535434" rpy="0 0 0"/>
            <geometry>
                <box size="1.272278157511338 1.3601477219938416 2.0487697503070867" />
            </geometry>
            <material name="Blue">
                <color rgba="0 1.0 1.0 1.0"/>
            </material>
        </visual>
        <collision>
            <origin xyz="0 0 1.0243848751535434" rpy="0 0 0"/>
            <geometry>
                <box size="1.272278157511338 1.3601477219938416 2.0487697503070867" />
            </geometry>
        </collision>
    </link>
    <link name="Leg16">
        <inertial>
            <origin xyz="0 0 0.6924699803575134" rpy="0 0 0"/>
            <mass value="1" />
            <inertia ixx="100" ixy="0" ixz="0" iyy="100" iyz="0" izz="100" />
        </inertial>
        <visual>
            <origin xyz="0 0 0.6924699803575134" rpy="0 0 0"/>
            <geometry>
                <box size="1.613939086509072 2.3143877966083366 1.3849399607150268" />
            </geometry>
            <material name="Green">
                <color rgba="0 180.0 0.0 1.0"/>
            </material>
        </visual>
        <collision>
            <origin xyz="0 0 0.6924699803575134" rpy="0 0 0"/>
            <geometry>
                <box size="1.613939086509072 2.3143877966083366 1.3849399607150268" />
            </geometry>
        </collision>
    </link>
    <link name="Leg17">
        <inertial>
            <origin xyz="1.0103508230664695 0 0" rpy="0 0 0"/>
            <mass value="1" />
            <inertia ixx="100" ixy="0" ixz="0" iyy="100" iyz="0" izz="100" />
        </inertial>
        <visual>
            <origin xyz="1.0103508230664695 0 0" rpy="0 0 0"/>
            <geometry>
                <box size="2.020701646132939 2.0328254615899812 2.358571190757859" />
            </geometry>
            <material name="Green">
                <color rgba="0 180.0 0.0 1.0"/>
            </material>
        </visual>
        <collision>
            <origin xyz="1.0103508230664695 0 0" rpy="0 0 0"/>
            <geometry>
                <box size="2.020701646132939 2.0328254615899812 2.358571190757859" />
            </geometry>
        </collision>
    </link>
    <link name="Leg18">
        <inertial>
            <origin xyz="0 1.4328248838849693 0" rpy="0 0 0"/>
            <mass value="1" />
            <inertia ixx="100" ixy="0" ixz="0" iyy="100" iyz="0" izz="100" />
        </inertial>
        <visual>
            <origin xyz="0 1.4328248838849693 0" rpy="0 0 0"/>
            <geometry>
                <box size="1.5945755628612492 2.8656497677699386 2.580670710226352" />
            </geometry>
            <material name="Green">
                <color rgba="0 180.0 0.0 1.0"/>
            </material>
        </visual>
        <collision>
            <origin xyz="0 1.4328248838849693 0" rpy="0 0 0"/>
            <geometry>
                <box size="1.5945755628612492 2.8656497677699386 2.580670710226352" />
            </geometry>
        </collision>
    </link>
    <link name="Leg19">
        <inertial>
            <origin xyz="0.9498458930574751 0 0" rpy="0 0 0"/>
            <mass value="1" />
            <inertia ixx="100" ixy="0" ixz="0" iyy="100" iyz="0" izz="100" />
        </inertial>
        <visual>
            <origin xyz="0.9498458930574751 0 0" rpy="0 0 0"/>
            <geometry>
                <box size="1.8996917861149503 1.2511099430588182 1.3607417957913823" />
            </geometry>
            <material name="Green">
                <color rgba="0 180.0 0.0 1.0"/>
            </material>
        </visual>
        <collision>
            <origin xyz="0.9498458930574751 0 0" rpy="0 0 0"/>
            <geometry>
                <box size="1.8996917861149503 1.2511099430588182 1.3607417957913823" />
            </geometry>
        </collision>
    </link>
    <link name="Leg20">
        <inertial>
            <origin xyz="0 0 1.438482632553232" rpy="0 0 0"/>
            <mass value="1" />
            <inertia ixx="100" ixy="0" ixz="0" iyy="100" iyz="0" izz="100" />
        </inertial>
        <visual>
            <origin xyz="0 0 1.438482632553232" rpy="0 0 0"/>
            <geometry>
                <box size="1.0588486125158532 1.575502420272244 2.876965265106464" />
            </geometry>
            <material name="Green">
                <color rgba="0 180.0 0.0 1.0"/>
            </material>
        </visual>
        <collision>
            <origin xyz="0 0 1.438482632553232" rpy="0 0 0"/>
            <geometry>
                <box size="1.0588486125158532 1.575502420272244 2.876965265106464" />
            </geometry>
        </collision>
    </link>
    <link name="Leg21">
        <inertial>
            <origin xyz="0 1.1779964778468903 0" rpy="0 0 0"/>
            <mass value="1" />
            <inertia ixx="100" ixy="0" ixz="0" iyy="100" iyz="0" izz="100" />
        </inertial>
        <visual>
            <origin xyz="0 1.1779964778468903 0" rpy="0 0 0"/>
            <geometry>
                <box size="2.6504872971334397 2.3559929556937806 1.1288945223413585" />
            </geometry>
            <material name="Blue">
                <color rgba="0 1.0 1.0 1.0"/>
            </material>
        </visual>
        <collision>
            <origin xyz="0 1.1779964778468903 0" rpy="0 0 0"/>
            <geometry>
                <box size="2.6504872971334397 2.3559929556937806 1.1288945223413585" />
            </geometry>
        </collision>
    </link>
    <link name="Leg22">
        <inertial>
            <origin xyz="1.2558409642771697 0 0" rpy="0 0 0"/>
            <mass value="1" />
            <inertia ixx="100" ixy="0" ixz="0" iyy="100" iyz="0" izz="100" />
        </inertial>
        <visual>
            <origin xyz="1.2558409642771697 0 0" rpy="0 0 0"/>
            <geometry>
                <box size="2.5116819285543395 2.8632325262604654 1.0059195851775817" />
            </geometry>
            <material name="Green">
                <color rgba="0 180.0 0.0 1.0"/>
            </material>
        </visual>
        <collision>
            <origin xyz="1.2558409642771697 0 0" rpy="0 0 0"/>
            <geometry>
                <box size="2.5116819285543395 2.8632325262604654 1.0059195851775817" />
            </geometry>
        </collision>
    </link>
    <link name="Leg23">
        <inertial>
            <origin xyz="1.0614149155424601 0 0" rpy="0 0 0"/>
            <mass value="1" />
            <inertia ixx="100" ixy="0" ixz="0" iyy="100" iyz="0" izz="100" />
        </inertial>
        <visual>
            <origin xyz="1.0614149155424601 0 0" rpy="0 0 0"/>
            <geometry>
                <box size="2.1228298310849203 1.847785013389227 2.046973118169188" />
            </geometry>
            <material name="Blue">
                <color rgba="0 1.0 1.0 1.0"/>
            </material>
        </visual>
        <collision>
            <origin xyz="1.0614149155424601 0 0" rpy="0 0 0"/>
            <geometry>
                <box size="2.1228298310849203 1.847785013389227 2.046973118169188" />
            </geometry>
        </collision>
    </link>
    <link name="Leg24">
        <inertial>
            <origin xyz="0 0.7990740948930007 0" rpy="0 0 0"/>
            <mass value="1" />
            <inertia ixx="100" ixy="0" ixz="0" iyy="100" iyz="0" izz="100" />
        </inertial>
        <visual>
            <origin xyz="0 0.7990740948930007 0" rpy="0 0 0"/>
            <geometry>
                <box size="2.926316843405573 1.5981481897860015 1.2910861864450094" />
            </geometry>
            <material name="Blue">
                <color rgba="0 1.0 1.0 1.0"/>
            </material>
        </visual>
        <collision>
            <origin xyz="0 0.7990740948930007 0" rpy="0 0 0"/>
            <geometry>
                <box size="2.926316843405573 1.5981481897860015 1.2910861864450094" />
            </geometry>
        </collision>
    </link>
    <link name="Leg25">
        <inertial>
            <origin xyz="0 0 0.731503819037379" rpy="0 0 0"/>
            <mass value="1" />
            <inertia ixx="100" ixy="0" ixz="0" iyy="100" iyz="0" izz="100" />
        </inertial>
        <visual>
            <origin xyz="0 0 0.731503819037379" rpy="0 0 0"/>
            <geometry>
                <box size="1.665023743574429 2.8919320949870704 1.463007638074758" />
            </geometry>
            <material name="Blue">
                <color rgba="0 1.0 1.0 1.0"/>
            </material>
        </visual>
        <collision>
            <origin xyz="0 0 0.731503819037379" rpy="0 0 0"/>
            <geometry>
                <box size="1.665023743574429 2.8919320949870704 1.463007638074758" />
            </geometry>
        </collision>
    </link>
    <link name="Leg26">
        <inertial>
            <origin xyz="0 0 1.2145140115297326" rpy="0 0 0"/>
            <mass value="1" />
            <inertia ixx="100" ixy="0" ixz="0" iyy="100" iyz="0" izz="100" />
        </inertial>
        <visual>
            <origin xyz="0 0 1.2145140115297326" rpy="0 0 0"/>
            <geometry>
                <box size="1.2998436036474699 2.5683704761688637 2.429028023059465" />
            </geometry>
            <material name="Blue">
                <color rgba="0 1.0 1.0 1.0"/>
            </material>
        </visual>
        <collision>
            <origin xyz="0 0 1.2145140115297326" rpy="0 0 0"/>
            <geometry>
                <box size="1.2998436036474699 2.5683704761688637 2.429028023059465" />
            </geometry>
        </collision>
    </link>
    <joint name="Torso_Leg1" type="revolute">
       <parent link="Torso"/>
       <child  link="Leg1"/>
       <origin rpy="0 0 0" xyz="0 0 1.1304968494374983" />
     <axis xyz="1 0 0"/>
       <limit effort="0.0" lower="-3.14159" upper="3.14159" velocity="0.0"/>
    </joint>
    <joint name="Leg1_Leg2" type="revolute">
       <parent link="Leg1"/>
       <child  link="Leg2"/>
       <origin rpy="0 0 0" xyz="0 0 1.0019742300858652" />
     <axis xyz="1 0 0"/>
       <limit effort="0.0" lower="-3.14159" upper="3.14159" velocity="0.0"/>
    </joint>
    <joint name="Leg1_Leg3" type="revolute">
       <parent link="Leg1"/>
       <child  link="Leg3"/>
       <origin rpy="0 0 0" xyz="1.1766519081947573 0 1.0019742300858652" />
     <axis xyz="1 0 0"/>
       <limit effort="0.0" lower="-3.14159" upper="3.14159" velocity="0.0"/>
    </joint>
    <joint name="Leg3_Leg4" type="revolute">
       <parent link="Leg3"/>
       <child  link="Leg4"/>
       <origin rpy="0 0 0" xyz="0 0 1.2040662417256145" />
     <axis xyz="1 0 0"/>
       <limit effort="0.0" lower="-3.14159" upper="3.14159" velocity="0.0"/>
    </joint>
    <joint name="Leg4_Leg5" type="revolute">
       <parent link="Leg4"/>
       <child  link="Leg5"/>
       <origin rpy="0 0 0" xyz="0 0 1.0396344169893734" />
     <axis xyz="1 0 0"/>
       <limit effort="0.0" lower="-3.14159" upper="3.14159" velocity="0.0"/>
    </joint>
    <joint name="Leg2_Leg6" type="revolute">
       <parent link="Leg2"/>
       <child  link="Leg6"/>
       <origin rpy="0 0 0" xyz="1.1127041148320447 1.471708226904442 0" />
     <axis xyz="1 0 0"/>
       <limit effort="0.0" lower="-3.14159" upper="3.14159" velocity="0.0"/>
    </joint>
    <joint name="Leg3_Leg7" type="revolute">
       <parent link="Leg3"/>
       <child  link="Leg7"/>
       <origin rpy="0 0 0" xyz="0 0.7084173053922078 1.2040662417256145" />
     <axis xyz="1 0 0"/>
       <limit effort="0.0" lower="-3.14159" upper="3.14159" velocity="0.0"/>
    </joint>
    <joint name="Leg6_Leg8" type="revolute">
       <parent link="Leg6"/>
       <child  link="Leg8"/>
       <origin rpy="0 0 0" xyz="0 2.061132569629863 0" />
     <axis xyz="1 0 0"/>
       <limit effort="0.0" lower="-3.14159" upper="3.14159" velocity="0.0"/>
    </joint>
    <joint name="Leg7_Leg9" type="revolute">
       <parent link="Leg7"/>
       <child  link="Leg9"/>
       <origin rpy="0 0 0" xyz="1.2845087565551339 1.1134268229585156 0" />
     <axis xyz="1 0 0"/>
       <limit effort="0.0" lower="-3.14159" upper="3.14159" velocity="0.0"/>
    </joint>
    <joint name="Leg3_Leg10" type="revolute">
       <parent link="Leg3"/>
       <child  link="Leg10"/>
       <origin rpy="0 0 0" xyz="0.6381538462896669 0.7084173053922078 1.2040662417256145" />
     <axis xyz="1 0 0"/>
       <limit effort="0.0" lower="-3.14159" upper="3.14159" velocity="0.0"/>
    </joint>
    <joint name="Leg5_Leg11" type="revolute">
       <parent link="Leg5"/>
       <child  link="Leg11"/>
       <origin rpy="0 0 0" xyz="1.2681085505758731 1.3169231100350909 0" />
     <axis xyz="1 0 0"/>
       <limit effort="0.0" lower="-3.14159" upper="3.14159" velocity="0.0"/>
    </joint>
    <joint name="Leg7_Leg12" type="revolute">
       <parent link="Leg7"/>
       <child  link="Leg12"/>
       <origin rpy="0 0 0" xyz="1.2845087565551339 1.1134268229585156 0.9307708289727672" />
     <axis xyz="1 0 0"/>
       <limit effort="0.0" lower="-3.14159" upper="3.14159" velocity="0.0"/>
    </joint>
    <joint name="Leg10_Leg13" type="revolute">
       <parent link="Leg10"/>
       <child  link="Leg13"/>
       <origin rpy="0 0 0" xyz="1.7254153805932047 0 0" />
     <axis xyz="1 0 0"/>
       <limit effort="0.0" lower="-3.14159" upper="3.14159" velocity="0.0"/>
    </joint>
    <joint name="Leg4_Leg14" type="revolute">
       <parent link="Leg4"/>
       <child  link="Leg14"/>
       <origin rpy="0 0 0" xyz="1.418406749390857 0 1.0396344169893734" />
     <axis xyz="1 0 0"/>
       <limit effort="0.0" lower="-3.14159" upper="3.14159" velocity="0.0"/>
    </joint>
    <joint name="Leg2_Leg15" type="revolute">
       <parent link="Leg2"/>
       <child  link="Leg15"/>
       <origin rpy="0 0 0" xyz="1.1127041148320447 1.471708226904442 0.6855834654982028" />
     <axis xyz="1 0 0"/>
       <limit effort="0.0" lower="-3.14159" upper="3.14159" velocity="0.0"/>
    </joint>
    <joint name="Leg11_Leg16" type="revolute">
       <parent link="Leg11"/>
       <child  link="Leg16"/>
       <origin rpy="0 0 0" xyz="0 0 2.2699015250161687" />
     <axis xyz="1 0 0"/>
       <limit effort="0.0" lower="-3.14159" upper="3.14159" velocity="0.0"/>
    </joint>
    <joint name="Leg13_Leg17" type="revolute">
       <parent link="Leg13"/>
       <child  link="Leg17"/>
       <origin rpy="0 0 0" xyz="1.2198883389780435 0 0" />
     <axis xyz="1 0 0"/>
       <limit effort="0.0" lower="-3.14159" upper="3.14159" velocity="0.0"/>
    </joint>
    <joint name="Leg1_Leg18" type="revolute">
       <parent link="Leg1"/>
       <child  link="Leg18"/>
       <origin rpy="0 0 0" xyz="1.1766519081947573 1.4292196275944948 1.0019742300858652" />
     <axis xyz="1 0 0"/>
       <limit effort="0.0" lower="-3.14159" upper="3.14159" velocity="0.0"/>
    </joint>
    <joint name="Leg18_Leg19" type="revolute">
       <parent link="Leg18"/>
       <child  link="Leg19"/>
       <origin rpy="0 0 0" xyz="1.8996917861149503 0 0" />
     <axis xyz="1 0 0"/>
       <limit effort="0.0" lower="-3.14159" upper="3.14159" velocity="0.0"/>
    </joint>
    <joint name="Leg19_Leg20" type="revolute">
       <parent link="Leg19"/>
       <child  link="Leg20"/>
       <origin rpy="0 0 0" xyz="0 0 2.876965265106464" />
     <axis xyz="1 0 0"/>
       <limit effort="0.0" lower="-3.14159" upper="3.14159" velocity="0.0"/>
    </joint>
    <joint name="Leg11_Leg21" type="revolute">
       <parent link="Leg11"/>
       <child  link="Leg21"/>
       <origin rpy="0 0 0" xyz="0 0.730941840695629 2.2699015250161687" />
     <axis xyz="1 0 0"/>
       <limit effort="0.0" lower="-3.14159" upper="3.14159" velocity="0.0"/>
    </joint>
    <joint name="Leg15_Leg22" type="revolute">
       <parent link="Leg15"/>
       <child  link="Leg22"/>
       <origin rpy="0 0 0" xyz="0.806969543254536 0 0.6924699803575134" />
     <axis xyz="1 0 0"/>
       <limit effort="0.0" lower="-3.14159" upper="3.14159" velocity="0.0"/>
    </joint>
    <joint name="Leg9_Leg23" type="revolute">
       <parent link="Leg9"/>
       <child  link="Leg23"/>
       <origin rpy="0 0 0" xyz="2.265939909320684 0 0" />
     <axis xyz="1 0 0"/>
       <limit effort="0.0" lower="-3.14159" upper="3.14159" velocity="0.0"/>
    </joint>
    <joint name="Leg7_Leg24" type="revolute">
       <parent link="Leg7"/>
       <child  link="Leg24"/>
       <origin rpy="0 0 0" xyz="1.2845087565551339 2.226853645917031 0.9307708289727672" />
     <axis xyz="1 0 0"/>
       <limit effort="0.0" lower="-3.14159" upper="3.14159" velocity="0.0"/>
    </joint>
    <joint name="Leg8_Leg25" type="revolute">
       <parent link="Leg8"/>
       <child  link="Leg25"/>
       <origin rpy="0 0 0" xyz="1.3256756102746956 0 0.952219648624561" />
     <axis xyz="1 0 0"/>
       <limit effort="0.0" lower="-3.14159" upper="3.14159" velocity="0.0"/>
    </joint>
    <joint name="Leg16_Leg26" type="revolute">
       <parent link="Leg16"/>
       <child  link="Leg26"/>
       <origin rpy="0 0 0" xyz="1.0103508230664695 0 1.1792855953789294" />
     <axis xyz="1 0 0"/>
       <limit effort="0.0" lower="-3.14159" upper="3.14159" velocity="0.0"/>
    </joint>
</robot>