<robot name = "robot">
    <link name="Torso">
        <inertial>
            <origin xyz="0 0 1.2824047997271348" rpy="0 0 0"/>
            <mass value="1" />
            <inertia ixx="100" ixy="0" ixz="0" iyy="100" iyz="0" izz="100" />
        </inertial>
        <visual>
            <origin xyz="0 0 1.2824047997271348" rpy="0 0 0"/>
            <geometry>
                <box size="1.8573179578494539 1.2389162410109353 2.5648095994542697" />
            </geometry>
            <material name="Green">
                <color rgba="0 180.0 0.0 1.0"/>
            </material>
        </visual>
        <collision>
            <origin xyz="0 0 1.2824047997271348" rpy="0 0 0"/>
            <geometry>
                <box size="1.8573179578494539 1.2389162410109353 2.5648095994542697" />
            </geometry>
        </collision>
    </link>
    <link name="Leg1">
        <inertial>
            <origin xyz="0 0.5015854023779043 0" rpy="0 0 0"/>
            <mass value="1" />
            <inertia ixx="100" ixy="0" ixz="0" iyy="100" iyz="0" izz="100" />
        </inertial>
        <visual>
            <origin xyz="0 0.5015854023779043 0" rpy="0 0 0"/>
            <geometry>
                <box size="1.6477634895137914 1.0031708047558086 1.5708611517327684" />
            </geometry>
            <material name="Green">
                <color rgba="0 180.0 0.0 1.0"/>
            </material>
        </visual>
        <collision>
            <origin xyz="0 0.5015854023779043 0" rpy="0 0 0"/>
            <geometry>
                <box size="1.6477634895137914 1.0031708047558086 1.5708611517327684" />
            </geometry>
        </collision>
    </link>
    <link name="Leg2">
        <inertial>
            <origin xyz="0 1.3440771791968005 0" rpy="0 0 0"/>
            <mass value="1" />
            <inertia ixx="100" ixy="0" ixz="0" iyy="100" iyz="0" izz="100" />
        </inertial>
        <visual>
            <origin xyz="0 1.3440771791968005 0" rpy="0 0 0"/>
            <geometry>
                <box size="1.2754027460786481 2.688154358393601 2.1129317095564466" />
            </geometry>
            <material name="Blue">
                <color rgba="0 1.0 1.0 1.0"/>
            </material>
        </visual>
        <collision>
            <origin xyz="0 1.3440771791968005 0" rpy="0 0 0"/>
            <geometry>
                <box size="1.2754027460786481 2.688154358393601 2.1129317095564466" />
            </geometry>
        </collision>
    </link>
    <link name="Leg3">
        <inertial>
            <origin xyz="1.4064969218884409 0 0" rpy="0 0 0"/>
            <mass value="1" />
            <inertia ixx="100" ixy="0" ixz="0" iyy="100" iyz="0" izz="100" />
        </inertial>
        <visual>
            <origin xyz="1.4064969218884409 0 0" rpy="0 0 0"/>
            <geometry>
                <box size="2.8129938437768818 1.4662116208865124 1.603115865298208" />
            </geometry>
            <material name="Blue">
                <color rgba="0 1.0 1.0 1.0"/>
            </material>
        </visual>
        <collision>
            <origin xyz="1.4064969218884409 0 0" rpy="0 0 0"/>
            <geometry>
                <box size="2.8129938437768818 1.4662116208865124 1.603115865298208" />
            </geometry>
        </collision>
    </link>
    <link name="Leg4">
        <inertial>
            <origin xyz="1.4796938719306008 0 0" rpy="0 0 0"/>
            <mass value="1" />
            <inertia ixx="100" ixy="0" ixz="0" iyy="100" iyz="0" izz="100" />
        </inertial>
        <visual>
            <origin xyz="1.4796938719306008 0 0" rpy="0 0 0"/>
            <geometry>
                <box size="2.9593877438612015 1.2584861670748666 2.6157062502766726" />
            </geometry>
            <material name="Blue">
                <color rgba="0 1.0 1.0 1.0"/>
            </material>
        </visual>
        <collision>
            <origin xyz="1.4796938719306008 0 0" rpy="0 0 0"/>
            <geometry>
                <box size="2.9593877438612015 1.2584861670748666 2.6157062502766726" />
            </geometry>
        </collision>
    </link>
    <link name="Leg5">
        <inertial>
            <origin xyz="0.614346161006477 0 0" rpy="0 0 0"/>
            <mass value="1" />
            <inertia ixx="100" ixy="0" ixz="0" iyy="100" iyz="0" izz="100" />
        </inertial>
        <visual>
            <origin xyz="0.614346161006477 0 0" rpy="0 0 0"/>
            <geometry>
                <box size="1.228692322012954 1.3821745069677356 2.2899544608128073" />
            </geometry>
            <material name="Green">
                <color rgba="0 180.0 0.0 1.0"/>
            </material>
        </visual>
        <collision>
            <origin xyz="0.614346161006477 0 0" rpy="0 0 0"/>
            <geometry>
                <box size="1.228692322012954 1.3821745069677356 2.2899544608128073" />
            </geometry>
        </collision>
    </link>
    <link name="Leg6">
        <inertial>
            <origin xyz="0.7463436383010673 0 0" rpy="0 0 0"/>
            <mass value="1" />
            <inertia ixx="100" ixy="0" ixz="0" iyy="100" iyz="0" izz="100" />
        </inertial>
        <visual>
            <origin xyz="0.7463436383010673 0 0" rpy="0 0 0"/>
            <geometry>
                <box size="1.4926872766021346 2.085401474210464 1.959735733410745" />
            </geometry>
            <material name="Blue">
                <color rgba="0 1.0 1.0 1.0"/>
            </material>
        </visual>
        <collision>
            <origin xyz="0.7463436383010673 0 0" rpy="0 0 0"/>
            <geometry>
                <box size="1.4926872766021346 2.085401474210464 1.959735733410745" />
            </geometry>
        </collision>
    </link>
    <link name="Leg7">
        <inertial>
            <origin xyz="0 0 0.9712475663185706" rpy="0 0 0"/>
            <mass value="1" />
            <inertia ixx="100" ixy="0" ixz="0" iyy="100" iyz="0" izz="100" />
        </inertial>
        <visual>
            <origin xyz="0 0 0.9712475663185706" rpy="0 0 0"/>
            <geometry>
                <box size="2.7495184905800416 1.3737509072521925 1.9424951326371411" />
            </geometry>
            <material name="Green">
                <color rgba="0 180.0 0.0 1.0"/>
            </material>
        </visual>
        <collision>
            <origin xyz="0 0 0.9712475663185706" rpy="0 0 0"/>
            <geometry>
                <box size="2.7495184905800416 1.3737509072521925 1.9424951326371411" />
            </geometry>
        </collision>
    </link>
    <link name="Leg8">
        <inertial>
            <origin xyz="0 0.6166892189808872 0" rpy="0 0 0"/>
            <mass value="1" />
            <inertia ixx="100" ixy="0" ixz="0" iyy="100" iyz="0" izz="100" />
        </inertial>
        <visual>
            <origin xyz="0 0.6166892189808872 0" rpy="0 0 0"/>
            <geometry>
                <box size="1.7392891301092959 1.2333784379617745 2.710550406438687" />
            </geometry>
            <material name="Green">
                <color rgba="0 180.0 0.0 1.0"/>
            </material>
        </visual>
        <collision>
            <origin xyz="0 0.6166892189808872 0" rpy="0 0 0"/>
            <geometry>
                <box size="1.7392891301092959 1.2333784379617745 2.710550406438687" />
            </geometry>
        </collision>
    </link>
    <link name="Leg9">
        <inertial>
            <origin xyz="0.8420252342355306 0 0" rpy="0 0 0"/>
            <mass value="1" />
            <inertia ixx="100" ixy="0" ixz="0" iyy="100" iyz="0" izz="100" />
        </inertial>
        <visual>
            <origin xyz="0.8420252342355306 0 0" rpy="0 0 0"/>
            <geometry>
                <box size="1.684050468471061 1.1799390245821977 1.7304151013315656" />
            </geometry>
            <material name="Blue">
                <color rgba="0 1.0 1.0 1.0"/>
            </material>
        </visual>
        <collision>
            <origin xyz="0.8420252342355306 0 0" rpy="0 0 0"/>
            <geometry>
                <box size="1.684050468471061 1.1799390245821977 1.7304151013315656" />
            </geometry>
        </collision>
    </link>
    <link name="Leg10">
        <inertial>
            <origin xyz="0.9412530355769092 0 0" rpy="0 0 0"/>
            <mass value="1" />
            <inertia ixx="100" ixy="0" ixz="0" iyy="100" iyz="0" izz="100" />
        </inertial>
        <visual>
            <origin xyz="0.9412530355769092 0 0" rpy="0 0 0"/>
            <geometry>
                <box size="1.8825060711538184 2.0243224773358652 2.962437525607556" />
            </geometry>
            <material name="Blue">
                <color rgba="0 1.0 1.0 1.0"/>
            </material>
        </visual>
        <collision>
            <origin xyz="0.9412530355769092 0 0" rpy="0 0 0"/>
            <geometry>
                <box size="1.8825060711538184 2.0243224773358652 2.962437525607556" />
            </geometry>
        </collision>
    </link>
    <link name="Leg11">
        <inertial>
            <origin xyz="0 0.6063972558591401 0" rpy="0 0 0"/>
            <mass value="1" />
            <inertia ixx="100" ixy="0" ixz="0" iyy="100" iyz="0" izz="100" />
        </inertial>
        <visual>
            <origin xyz="0 0.6063972558591401 0" rpy="0 0 0"/>
            <geometry>
                <box size="2.121548342780231 1.2127945117182801 1.9146672983820305" />
            </geometry>
            <material name="Blue">
                <color rgba="0 1.0 1.0 1.0"/>
            </material>
        </visual>
        <collision>
            <origin xyz="0 0.6063972558591401 0" rpy="0 0 0"/>
            <geometry>
                <box size="2.121548342780231 1.2127945117182801 1.9146672983820305" />
            </geometry>
        </collision>
    </link>
    <link name="Leg12">
        <inertial>
            <origin xyz="0 0 0.8012565250246421" rpy="0 0 0"/>
            <mass value="1" />
            <inertia ixx="100" ixy="0" ixz="0" iyy="100" iyz="0" izz="100" />
        </inertial>
        <visual>
            <origin xyz="0 0 0.8012565250246421" rpy="0 0 0"/>
            <geometry>
                <box size="1.5422854387808582 2.8587360642928425 1.6025130500492841" />
            </geometry>
            <material name="Green">
                <color rgba="0 180.0 0.0 1.0"/>
            </material>
        </visual>
        <collision>
            <origin xyz="0 0 0.8012565250246421" rpy="0 0 0"/>
            <geometry>
                <box size="1.5422854387808582 2.8587360642928425 1.6025130500492841" />
            </geometry>
        </collision>
    </link>
    <link name="Leg13">
        <inertial>
            <origin xyz="0.5766319818974366 0 0" rpy="0 0 0"/>
            <mass value="1" />
            <inertia ixx="100" ixy="0" ixz="0" iyy="100" iyz="0" izz="100" />
        </inertial>
        <visual>
            <origin xyz="0.5766319818974366 0 0" rpy="0 0 0"/>
            <geometry>
                <box size="1.1532639637948732 2.6153821072750816 2.6231367188081407" />
            </geometry>
            <material name="Blue">
                <color rgba="0 1.0 1.0 1.0"/>
            </material>
        </visual>
        <collision>
            <origin xyz="0.5766319818974366 0 0" rpy="0 0 0"/>
            <geometry>
                <box size="1.1532639637948732 2.6153821072750816 2.6231367188081407" />
            </geometry>
        </collision>
    </link>
    <link name="Leg14">
        <inertial>
            <origin xyz="0 0.5985586160887253 0" rpy="0 0 0"/>
            <mass value="1" />
            <inertia ixx="100" ixy="0" ixz="0" iyy="100" iyz="0" izz="100" />
        </inertial>
        <visual>
            <origin xyz="0 0.5985586160887253 0" rpy="0 0 0"/>
            <geometry>
                <box size="1.4219520021785441 1.1971172321774506 1.3868461321877301" />
            </geometry>
            <material name="Blue">
                <color rgba="0 1.0 1.0 1.0"/>
            </material>
        </visual>
        <collision>
            <origin xyz="0 0.5985586160887253 0" rpy="0 0 0"/>
            <geometry>
                <box size="1.4219520021785441 1.1971172321774506 1.3868461321877301" />
            </geometry>
        </collision>
    </link>
    <link name="Leg15">
        <inertial>
            <origin xyz="0 0.7250903155745023 0" rpy="0 0 0"/>
            <mass value="1" />
            <inertia ixx="100" ixy="0" ixz="0" iyy="100" iyz="0" izz="100" />
        </inertial>
        <visual>
            <origin xyz="0 0.7250903155745023 0" rpy="0 0 0"/>
            <geometry>
                <box size="1.6637329361370565 1.4501806311490046 2.7387195880966866" />
            </geometry>
            <material name="Green">
                <color rgba="0 180.0 0.0 1.0"/>
            </material>
        </visual>
        <collision>
            <origin xyz="0 0.7250903155745023 0" rpy="0 0 0"/>
            <geometry>
                <box size="1.6637329361370565 1.4501806311490046 2.7387195880966866" />
            </geometry>
        </collision>
    </link>
    <link name="Leg16">
        <inertial>
            <origin xyz="0 0 0.9106546110562429" rpy="0 0 0"/>
            <mass value="1" />
            <inertia ixx="100" ixy="0" ixz="0" iyy="100" iyz="0" izz="100" />
        </inertial>
        <visual>
            <origin xyz="0 0 0.9106546110562429" rpy="0 0 0"/>
            <geometry>
                <box size="1.2881198427637066 2.0544756704786016 1.8213092221124858" />
            </geometry>
            <material name="Green">
                <color rgba="0 180.0 0.0 1.0"/>
            </material>
        </visual>
        <collision>
            <origin xyz="0 0 0.9106546110562429" rpy="0 0 0"/>
            <geometry>
                <box size="1.2881198427637066 2.0544756704786016 1.8213092221124858" />
            </geometry>
        </collision>
    </link>
    <link name="Leg17">
        <inertial>
            <origin xyz="0 0.7140882356808811 0" rpy="0 0 0"/>
            <mass value="1" />
            <inertia ixx="100" ixy="0" ixz="0" iyy="100" iyz="0" izz="100" />
        </inertial>
        <visual>
            <origin xyz="0 0.7140882356808811 0" rpy="0 0 0"/>
            <geometry>
                <box size="1.5508251426084936 1.4281764713617622 1.4003039036406377" />
            </geometry>
            <material name="Blue">
                <color rgba="0 1.0 1.0 1.0"/>
            </material>
        </visual>
        <collision>
            <origin xyz="0 0.7140882356808811 0" rpy="0 0 0"/>
            <geometry>
                <box size="1.5508251426084936 1.4281764713617622 1.4003039036406377" />
            </geometry>
        </collision>
    </link>
    <link name="Leg18">
        <inertial>
            <origin xyz="0.8662738698627341 0 0" rpy="0 0 0"/>
            <mass value="1" />
            <inertia ixx="100" ixy="0" ixz="0" iyy="100" iyz="0" izz="100" />
        </inertial>
        <visual>
            <origin xyz="0.8662738698627341 0 0" rpy="0 0 0"/>
            <geometry>
                <box size="1.7325477397254683 1.4006174478991034 1.5167728861612515" />
            </geometry>
            <material name="Blue">
                <color rgba="0 1.0 1.0 1.0"/>
            </material>
        </visual>
        <collision>
            <origin xyz="0.8662738698627341 0 0" rpy="0 0 0"/>
            <geometry>
                <box size="1.7325477397254683 1.4006174478991034 1.5167728861612515" />
            </geometry>
        </collision>
    </link>
    <link name="Leg19">
        <inertial>
            <origin xyz="0 0 1.0161507832382812" rpy="0 0 0"/>
            <mass value="1" />
            <inertia ixx="100" ixy="0" ixz="0" iyy="100" iyz="0" izz="100" />
        </inertial>
        <visual>
            <origin xyz="0 0 1.0161507832382812" rpy="0 0 0"/>
            <geometry>
                <box size="2.3965907676108484 2.2356363229847194 2.0323015664765625" />
            </geometry>
            <material name="Green">
                <color rgba="0 180.0 0.0 1.0"/>
            </material>
        </visual>
        <collision>
            <origin xyz="0 0 1.0161507832382812" rpy="0 0 0"/>
            <geometry>
                <box size="2.3965907676108484 2.2356363229847194 2.0323015664765625" />
            </geometry>
        </collision>
    </link>
    <link name="Leg20">
        <inertial>
            <origin xyz="0 0.5034286348299479 0" rpy="0 0 0"/>
            <mass value="1" />
            <inertia ixx="100" ixy="0" ixz="0" iyy="100" iyz="0" izz="100" />
        </inertial>
        <visual>
            <origin xyz="0 0.5034286348299479 0" rpy="0 0 0"/>
            <geometry>
                <box size="1.5985760574373853 1.0068572696598959 2.0096530622733315" />
            </geometry>
            <material name="Green">
                <color rgba="0 180.0 0.0 1.0"/>
            </material>
        </visual>
        <collision>
            <origin xyz="0 0.5034286348299479 0" rpy="0 0 0"/>
            <geometry>
                <box size="1.5985760574373853 1.0068572696598959 2.0096530622733315" />
            </geometry>
        </collision>
    </link>
    <link name="Leg21">
        <inertial>
            <origin xyz="0 0.5412455307288156 0" rpy="0 0 0"/>
            <mass value="1" />
            <inertia ixx="100" ixy="0" ixz="0" iyy="100" iyz="0" izz="100" />
        </inertial>
        <visual>
            <origin xyz="0 0.5412455307288156 0" rpy="0 0 0"/>
            <geometry>
                <box size="1.8394860550864705 1.0824910614576313 2.597805999196301" />
            </geometry>
            <material name="Blue">
                <color rgba="0 1.0 1.0 1.0"/>
            </material>
        </visual>
        <collision>
            <origin xyz="0 0.5412455307288156 0" rpy="0 0 0"/>
            <geometry>
                <box size="1.8394860550864705 1.0824910614576313 2.597805999196301" />
            </geometry>
        </collision>
    </link>
    <link name="Leg22">
        <inertial>
            <origin xyz="0 0 1.3126488156547045" rpy="0 0 0"/>
            <mass value="1" />
            <inertia ixx="100" ixy="0" ixz="0" iyy="100" iyz="0" izz="100" />
        </inertial>
        <visual>
            <origin xyz="0 0 1.3126488156547045" rpy="0 0 0"/>
            <geometry>
                <box size="2.0437071197844165 1.072259401451019 2.625297631309409" />
            </geometry>
            <material name="Green">
                <color rgba="0 180.0 0.0 1.0"/>
            </material>
        </visual>
        <collision>
            <origin xyz="0 0 1.3126488156547045" rpy="0 0 0"/>
            <geometry>
                <box size="2.0437071197844165 1.072259401451019 2.625297631309409" />
            </geometry>
        </collision>
    </link>
    <link name="Leg23">
        <inertial>
            <origin xyz="0.937156726780227 0 0" rpy="0 0 0"/>
            <mass value="1" />
            <inertia ixx="100" ixy="0" ixz="0" iyy="100" iyz="0" izz="100" />
        </inertial>
        <visual>
            <origin xyz="0.937156726780227 0 0" rpy="0 0 0"/>
            <geometry>
                <box size="1.874313453560454 2.6180311457426457 1.7102948767905573" />
            </geometry>
            <material name="Blue">
                <color rgba="0 1.0 1.0 1.0"/>
            </material>
        </visual>
        <collision>
            <origin xyz="0.937156726780227 0 0" rpy="0 0 0"/>
            <geometry>
                <box size="1.874313453560454 2.6180311457426457 1.7102948767905573" />
            </geometry>
        </collision>
    </link>
    <link name="Leg24">
        <inertial>
            <origin xyz="0 0.7643133147022396 0" rpy="0 0 0"/>
            <mass value="1" />
            <inertia ixx="100" ixy="0" ixz="0" iyy="100" iyz="0" izz="100" />
        </inertial>
        <visual>
            <origin xyz="0 0.7643133147022396 0" rpy="0 0 0"/>
            <geometry>
                <box size="1.355400444922081 1.5286266294044792 2.6229360947389138" />
            </geometry>
            <material name="Green">
                <color rgba="0 180.0 0.0 1.0"/>
            </material>
        </visual>
        <collision>
            <origin xyz="0 0.7643133147022396 0" rpy="0 0 0"/>
            <geometry>
                <box size="1.355400444922081 1.5286266294044792 2.6229360947389138" />
            </geometry>
        </collision>
    </link>
    <link name="Leg25">
        <inertial>
            <origin xyz="1.0358002323350992 0 0" rpy="0 0 0"/>
            <mass value="1" />
            <inertia ixx="100" ixy="0" ixz="0" iyy="100" iyz="0" izz="100" />
        </inertial>
        <visual>
            <origin xyz="1.0358002323350992 0 0" rpy="0 0 0"/>
            <geometry>
                <box size="2.0716004646701984 1.8714698509780494 1.2736860998587236" />
            </geometry>
            <material name="Blue">
                <color rgba="0 1.0 1.0 1.0"/>
            </material>
        </visual>
        <collision>
            <origin xyz="1.0358002323350992 0 0" rpy="0 0 0"/>
            <geometry>
                <box size="2.0716004646701984 1.8714698509780494 1.2736860998587236" />
            </geometry>
        </collision>
    </link>
    <joint name="Torso_Leg1" type="revolute">
       <parent link="Torso"/>
       <child  link="Leg1"/>
       <origin rpy="0 0 0" xyz="0 0.6194581205054677 1.2824047997271348" />
     <axis xyz="1 0 0"/>
       <limit effort="0.0" lower="-3.14159" upper="3.14159" velocity="0.0"/>
    </joint>
    <joint name="Leg1_Leg2" type="revolute">
       <parent link="Leg1"/>
       <child  link="Leg2"/>
       <origin rpy="0 0 0" xyz="0 2.688154358393601 0" />
     <axis xyz="1 0 0"/>
       <limit effort="0.0" lower="-3.14159" upper="3.14159" velocity="0.0"/>
    </joint>
    <joint name="Leg2_Leg3" type="revolute">
       <parent link="Leg2"/>
       <child  link="Leg3"/>
       <origin rpy="0 0 0" xyz="2.8129938437768818 0 0" />
     <axis xyz="1 0 0"/>
       <limit effort="0.0" lower="-3.14159" upper="3.14159" velocity="0.0"/>
    </joint>
    <joint name="Leg3_Leg4" type="revolute">
       <parent link="Leg3"/>
       <child  link="Leg4"/>
       <origin rpy="0 0 0" xyz="2.9593877438612015 0 0" />
     <axis xyz="1 0 0"/>
       <limit effort="0.0" lower="-3.14159" upper="3.14159" velocity="0.0"/>
    </joint>
    <joint name="Torso_Leg5" type="revolute">
       <parent link="Torso"/>
       <child  link="Leg5"/>
       <origin rpy="0 0 0" xyz="0.8238817447568957 0.5015854023779043 0" />
     <axis xyz="1 0 0"/>
       <limit effort="0.0" lower="-3.14159" upper="3.14159" velocity="0.0"/>
    </joint>
    <joint name="Leg4_Leg6" type="revolute">
       <parent link="Leg4"/>
       <child  link="Leg6"/>
       <origin rpy="0 0 0" xyz="1.228692322012954 0 0" />
     <axis xyz="1 0 0"/>
       <limit effort="0.0" lower="-3.14159" upper="3.14159" velocity="0.0"/>
    </joint>
    <joint name="Leg4_Leg7" type="revolute">
       <parent link="Leg4"/>
       <child  link="Leg7"/>
       <origin rpy="0 0 0" xyz="1.228692322012954 0 1.1449772304064036" />
     <axis xyz="1 0 0"/>
       <limit effort="0.0" lower="-3.14159" upper="3.14159" velocity="0.0"/>
    </joint>
    <joint name="Leg6_Leg8" type="revolute">
       <parent link="Leg6"/>
       <child  link="Leg8"/>
       <origin rpy="0 0 0" xyz="0 0.6868754536260963 0.9712475663185706" />
     <axis xyz="1 0 0"/>
       <limit effort="0.0" lower="-3.14159" upper="3.14159" velocity="0.0"/>
    </joint>
    <joint name="Leg7_Leg9" type="revolute">
       <parent link="Leg7"/>
       <child  link="Leg9"/>
       <origin rpy="0 0 0" xyz="0.8696445650546479 0.6166892189808872 0" />
     <axis xyz="1 0 0"/>
       <limit effort="0.0" lower="-3.14159" upper="3.14159" velocity="0.0"/>
    </joint>
    <joint name="Leg1_Leg10" type="revolute">
       <parent link="Leg1"/>
       <child  link="Leg10"/>
       <origin rpy="0 0 0" xyz="0.6377013730393241 2.688154358393601 0" />
     <axis xyz="1 0 0"/>
       <limit effort="0.0" lower="-3.14159" upper="3.14159" velocity="0.0"/>
    </joint>
    <joint name="Leg4_Leg11" type="revolute">
       <parent link="Leg4"/>
       <child  link="Leg11"/>
       <origin rpy="0 0 0" xyz="1.228692322012954 0.6910872534838678 1.1449772304064036" />
     <axis xyz="1 0 0"/>
       <limit effort="0.0" lower="-3.14159" upper="3.14159" velocity="0.0"/>
    </joint>
    <joint name="Leg1_Leg12" type="revolute">
       <parent link="Leg1"/>
       <child  link="Leg12"/>
       <origin rpy="0 0 0" xyz="0.6377013730393241 2.688154358393601 1.0564658547782233" />
     <axis xyz="1 0 0"/>
       <limit effort="0.0" lower="-3.14159" upper="3.14159" velocity="0.0"/>
    </joint>
    <joint name="Leg10_Leg13" type="revolute">
       <parent link="Leg10"/>
       <child  link="Leg13"/>
       <origin rpy="0 0 0" xyz="1.0607741713901155 0.6063972558591401 0" />
     <axis xyz="1 0 0"/>
       <limit effort="0.0" lower="-3.14159" upper="3.14159" velocity="0.0"/>
    </joint>
    <joint name="Leg8_Leg14" type="revolute">
       <parent link="Leg8"/>
       <child  link="Leg14"/>
       <origin rpy="0 0 0" xyz="0.8420252342355306 0.5899695122910988 0" />
     <axis xyz="1 0 0"/>
       <limit effort="0.0" lower="-3.14159" upper="3.14159" velocity="0.0"/>
    </joint>
    <joint name="Leg9_Leg15" type="revolute">
       <parent link="Leg9"/>
       <child  link="Leg15"/>
       <origin rpy="0 0 0" xyz="0.9412530355769092 1.0121612386679326 0" />
     <axis xyz="1 0 0"/>
       <limit effort="0.0" lower="-3.14159" upper="3.14159" velocity="0.0"/>
    </joint>
    <joint name="Leg11_Leg16" type="revolute">
       <parent link="Leg11"/>
       <child  link="Leg16"/>
       <origin rpy="0 0 0" xyz="0 0 1.6025130500492841" />
     <axis xyz="1 0 0"/>
       <limit effort="0.0" lower="-3.14159" upper="3.14159" velocity="0.0"/>
    </joint>
    <joint name="Leg2_Leg17" type="revolute">
       <parent link="Leg2"/>
       <child  link="Leg17"/>
       <origin rpy="0 0 0" xyz="2.8129938437768818 0.7331058104432562 0" />
     <axis xyz="1 0 0"/>
       <limit effort="0.0" lower="-3.14159" upper="3.14159" velocity="0.0"/>
    </joint>
    <joint name="Leg16_Leg18" type="revolute">
       <parent link="Leg16"/>
       <child  link="Leg18"/>
       <origin rpy="0 0 0" xyz="0.7754125713042468 0.7140882356808811 0" />
     <axis xyz="1 0 0"/>
       <limit effort="0.0" lower="-3.14159" upper="3.14159" velocity="0.0"/>
    </joint>
    <joint name="Leg12_Leg19" type="revolute">
       <parent link="Leg12"/>
       <child  link="Leg19"/>
       <origin rpy="0 0 0" xyz="0.5766319818974366 0 1.3115683594040703" />
     <axis xyz="1 0 0"/>
       <limit effort="0.0" lower="-3.14159" upper="3.14159" velocity="0.0"/>
    </joint>
    <joint name="Leg7_Leg20" type="revolute">
       <parent link="Leg7"/>
       <child  link="Leg20"/>
       <origin rpy="0 0 0" xyz="0.8696445650546479 1.2333784379617745 0" />
     <axis xyz="1 0 0"/>
       <limit effort="0.0" lower="-3.14159" upper="3.14159" velocity="0.0"/>
    </joint>
    <joint name="Leg3_Leg21" type="revolute">
       <parent link="Leg3"/>
       <child  link="Leg21"/>
       <origin rpy="0 0 0" xyz="2.9593877438612015 0.6292430835374333 0" />
     <axis xyz="1 0 0"/>
       <limit effort="0.0" lower="-3.14159" upper="3.14159" velocity="0.0"/>
    </joint>
    <joint name="Leg2_Leg22" type="revolute">
       <parent link="Leg2"/>
       <child  link="Leg22"/>
       <origin rpy="0 0 0" xyz="2.8129938437768818 0.7331058104432562 0.801557932649104" />
     <axis xyz="1 0 0"/>
       <limit effort="0.0" lower="-3.14159" upper="3.14159" velocity="0.0"/>
    </joint>
    <joint name="Leg15_Leg23" type="revolute">
       <parent link="Leg15"/>
       <child  link="Leg23"/>
       <origin rpy="0 0 0" xyz="0.6440599213818533 0 0.9106546110562429" />
     <axis xyz="1 0 0"/>
       <limit effort="0.0" lower="-3.14159" upper="3.14159" velocity="0.0"/>
    </joint>
    <joint name="Leg21_Leg24" type="revolute">
       <parent link="Leg21"/>
       <child  link="Leg24"/>
       <origin rpy="0 0 0" xyz="0 0.5361297007255095 1.3126488156547045" />
     <axis xyz="1 0 0"/>
       <limit effort="0.0" lower="-3.14159" upper="3.14159" velocity="0.0"/>
    </joint>
    <joint name="Leg22_Leg25" type="revolute">
       <parent link="Leg22"/>
       <child  link="Leg25"/>
       <origin rpy="0 0 0" xyz="1.874313453560454 0 0" />
     <axis xyz="1 0 0"/>
       <limit effort="0.0" lower="-3.14159" upper="3.14159" velocity="0.0"/>
    </joint>
</robot>