<robot name = "robot">
    <link name="Torso">
        <inertial>
            <origin xyz="0 0 0.6029442625252923" rpy="0 0 0"/>
            <mass value="1" />
            <inertia ixx="100" ixy="0" ixz="0" iyy="100" iyz="0" izz="100" />
        </inertial>
        <visual>
            <origin xyz="0 0 0.6029442625252923" rpy="0 0 0"/>
            <geometry>
                <box size="1.8243808568319118 2.290351974645447 1.2058885250505846" />
            </geometry>
            <material name="Green">
                <color rgba="0 180.0 0.0 1.0"/>
            </material>
        </visual>
        <collision>
            <origin xyz="0 0 0.6029442625252923" rpy="0 0 0"/>
            <geometry>
                <box size="1.8243808568319118 2.290351974645447 1.2058885250505846" />
            </geometry>
        </collision>
    </link>
    <link name="Leg1">
        <inertial>
            <origin xyz="0 0 0.5585775510059394" rpy="0 0 0"/>
            <mass value="1" />
            <inertia ixx="100" ixy="0" ixz="0" iyy="100" iyz="0" izz="100" />
        </inertial>
        <visual>
            <origin xyz="0 0 0.5585775510059394" rpy="0 0 0"/>
            <geometry>
                <box size="1.1130437191288158 1.8415293426387975 1.1171551020118788" />
            </geometry>
            <material name="Green">
                <color rgba="0 180.0 0.0 1.0"/>
            </material>
        </visual>
        <collision>
            <origin xyz="0 0 0.5585775510059394" rpy="0 0 0"/>
            <geometry>
                <box size="1.1130437191288158 1.8415293426387975 1.1171551020118788" />
            </geometry>
        </collision>
    </link>
    <link name="Leg2">
        <inertial>
            <origin xyz="0 0 0.799795779931341" rpy="0 0 0"/>
            <mass value="1" />
            <inertia ixx="100" ixy="0" ixz="0" iyy="100" iyz="0" izz="100" />
        </inertial>
        <visual>
            <origin xyz="0 0 0.799795779931341" rpy="0 0 0"/>
            <geometry>
                <box size="2.9765669278704197 1.0887551097007817 1.599591559862682" />
            </geometry>
            <material name="Green">
                <color rgba="0 180.0 0.0 1.0"/>
            </material>
        </visual>
        <collision>
            <origin xyz="0 0 0.799795779931341" rpy="0 0 0"/>
            <geometry>
                <box size="2.9765669278704197 1.0887551097007817 1.599591559862682" />
            </geometry>
        </collision>
    </link>
    <link name="Leg3">
        <inertial>
            <origin xyz="0 0.6703391408465814 0" rpy="0 0 0"/>
            <mass value="1" />
            <inertia ixx="100" ixy="0" ixz="0" iyy="100" iyz="0" izz="100" />
        </inertial>
        <visual>
            <origin xyz="0 0.6703391408465814 0" rpy="0 0 0"/>
            <geometry>
                <box size="2.8537310900211805 1.3406782816931628 1.004471553304492" />
            </geometry>
            <material name="Green">
                <color rgba="0 180.0 0.0 1.0"/>
            </material>
        </visual>
        <collision>
            <origin xyz="0 0.6703391408465814 0" rpy="0 0 0"/>
            <geometry>
                <box size="2.8537310900211805 1.3406782816931628 1.004471553304492" />
            </geometry>
        </collision>
    </link>
    <link name="Leg4">
        <inertial>
            <origin xyz="1.0240994735669324 0 0" rpy="0 0 0"/>
            <mass value="1" />
            <inertia ixx="100" ixy="0" ixz="0" iyy="100" iyz="0" izz="100" />
        </inertial>
        <visual>
            <origin xyz="1.0240994735669324 0 0" rpy="0 0 0"/>
            <geometry>
                <box size="2.048198947133865 2.586019120540765 2.049641148597926" />
            </geometry>
            <material name="Blue">
                <color rgba="0 1.0 1.0 1.0"/>
            </material>
        </visual>
        <collision>
            <origin xyz="1.0240994735669324 0 0" rpy="0 0 0"/>
            <geometry>
                <box size="2.048198947133865 2.586019120540765 2.049641148597926" />
            </geometry>
        </collision>
    </link>
    <link name="Leg5">
        <inertial>
            <origin xyz="0 0 1.3868161208361096" rpy="0 0 0"/>
            <mass value="1" />
            <inertia ixx="100" ixy="0" ixz="0" iyy="100" iyz="0" izz="100" />
        </inertial>
        <visual>
            <origin xyz="0 0 1.3868161208361096" rpy="0 0 0"/>
            <geometry>
                <box size="1.6657338042014984 2.208000672008618 2.7736322416722192" />
            </geometry>
            <material name="Blue">
                <color rgba="0 1.0 1.0 1.0"/>
            </material>
        </visual>
        <collision>
            <origin xyz="0 0 1.3868161208361096" rpy="0 0 0"/>
            <geometry>
                <box size="1.6657338042014984 2.208000672008618 2.7736322416722192" />
            </geometry>
        </collision>
    </link>
    <link name="Leg6">
        <inertial>
            <origin xyz="0 0 1.1126744004496911" rpy="0 0 0"/>
            <mass value="1" />
            <inertia ixx="100" ixy="0" ixz="0" iyy="100" iyz="0" izz="100" />
        </inertial>
        <visual>
            <origin xyz="0 0 1.1126744004496911" rpy="0 0 0"/>
            <geometry>
                <box size="2.996587245572032 2.8643073936688204 2.2253488008993823" />
            </geometry>
            <material name="Blue">
                <color rgba="0 1.0 1.0 1.0"/>
            </material>
        </visual>
        <collision>
            <origin xyz="0 0 1.1126744004496911" rpy="0 0 0"/>
            <geometry>
                <box size="2.996587245572032 2.8643073936688204 2.2253488008993823" />
            </geometry>
        </collision>
    </link>
    <link name="Leg7">
        <inertial>
            <origin xyz="1.315826513024621 0 0" rpy="0 0 0"/>
            <mass value="1" />
            <inertia ixx="100" ixy="0" ixz="0" iyy="100" iyz="0" izz="100" />
        </inertial>
        <visual>
            <origin xyz="1.315826513024621 0 0" rpy="0 0 0"/>
            <geometry>
                <box size="2.631653026049242 1.4085757706975433 1.8543296554530486" />
            </geometry>
            <material name="Blue">
                <color rgba="0 1.0 1.0 1.0"/>
            </material>
        </visual>
        <collision>
            <origin xyz="1.315826513024621 0 0" rpy="0 0 0"/>
            <geometry>
                <box size="2.631653026049242 1.4085757706975433 1.8543296554530486" />
            </geometry>
        </collision>
    </link>
    <link name="Leg8">
        <inertial>
            <origin xyz="0 0.9595568596510755 0" rpy="0 0 0"/>
            <mass value="1" />
            <inertia ixx="100" ixy="0" ixz="0" iyy="100" iyz="0" izz="100" />
        </inertial>
        <visual>
            <origin xyz="0 0.9595568596510755 0" rpy="0 0 0"/>
            <geometry>
                <box size="1.1570836360829087 1.919113719302151 1.111647466669412" />
            </geometry>
            <material name="Green">
                <color rgba="0 180.0 0.0 1.0"/>
            </material>
        </visual>
        <collision>
            <origin xyz="0 0.9595568596510755 0" rpy="0 0 0"/>
            <geometry>
                <box size="1.1570836360829087 1.919113719302151 1.111647466669412" />
            </geometry>
        </collision>
    </link>
    <link name="Leg9">
        <inertial>
            <origin xyz="0 0 0.6744408552663849" rpy="0 0 0"/>
            <mass value="1" />
            <inertia ixx="100" ixy="0" ixz="0" iyy="100" iyz="0" izz="100" />
        </inertial>
        <visual>
            <origin xyz="0 0 0.6744408552663849" rpy="0 0 0"/>
            <geometry>
                <box size="1.438495308223938 2.6465109184025453 1.3488817105327697" />
            </geometry>
            <material name="Green">
                <color rgba="0 180.0 0.0 1.0"/>
            </material>
        </visual>
        <collision>
            <origin xyz="0 0 0.6744408552663849" rpy="0 0 0"/>
            <geometry>
                <box size="1.438495308223938 2.6465109184025453 1.3488817105327697" />
            </geometry>
        </collision>
    </link>
    <link name="Leg10">
        <inertial>
            <origin xyz="0 1.0557853466330294 0" rpy="0 0 0"/>
            <mass value="1" />
            <inertia ixx="100" ixy="0" ixz="0" iyy="100" iyz="0" izz="100" />
        </inertial>
        <visual>
            <origin xyz="0 1.0557853466330294 0" rpy="0 0 0"/>
            <geometry>
                <box size="1.0892595751113856 2.1115706932660587 1.4701580189591745" />
            </geometry>
            <material name="Blue">
                <color rgba="0 1.0 1.0 1.0"/>
            </material>
        </visual>
        <collision>
            <origin xyz="0 1.0557853466330294 0" rpy="0 0 0"/>
            <geometry>
                <box size="1.0892595751113856 2.1115706932660587 1.4701580189591745" />
            </geometry>
        </collision>
    </link>
    <link name="Leg11">
        <inertial>
            <origin xyz="0 1.2873511484544258 0" rpy="0 0 0"/>
            <mass value="1" />
            <inertia ixx="100" ixy="0" ixz="0" iyy="100" iyz="0" izz="100" />
        </inertial>
        <visual>
            <origin xyz="0 1.2873511484544258 0" rpy="0 0 0"/>
            <geometry>
                <box size="1.6734459524089431 2.5747022969088516 1.1369374435933384" />
            </geometry>
            <material name="Green">
                <color rgba="0 180.0 0.0 1.0"/>
            </material>
        </visual>
        <collision>
            <origin xyz="0 1.2873511484544258 0" rpy="0 0 0"/>
            <geometry>
                <box size="1.6734459524089431 2.5747022969088516 1.1369374435933384" />
            </geometry>
        </collision>
    </link>
    <link name="Leg12">
        <inertial>
            <origin xyz="0 0 0.8622383185328253" rpy="0 0 0"/>
            <mass value="1" />
            <inertia ixx="100" ixy="0" ixz="0" iyy="100" iyz="0" izz="100" />
        </inertial>
        <visual>
            <origin xyz="0 0 0.8622383185328253" rpy="0 0 0"/>
            <geometry>
                <box size="1.7092658781632009 2.4319788998662513 1.7244766370656506" />
            </geometry>
            <material name="Blue">
                <color rgba="0 1.0 1.0 1.0"/>
            </material>
        </visual>
        <collision>
            <origin xyz="0 0 0.8622383185328253" rpy="0 0 0"/>
            <geometry>
                <box size="1.7092658781632009 2.4319788998662513 1.7244766370656506" />
            </geometry>
        </collision>
    </link>
    <link name="Leg13">
        <inertial>
            <origin xyz="0 0 0.6985155661926239" rpy="0 0 0"/>
            <mass value="1" />
            <inertia ixx="100" ixy="0" ixz="0" iyy="100" iyz="0" izz="100" />
        </inertial>
        <visual>
            <origin xyz="0 0 0.6985155661926239" rpy="0 0 0"/>
            <geometry>
                <box size="2.6900459975087347 1.7248410491289414 1.3970311323852478" />
            </geometry>
            <material name="Green">
                <color rgba="0 180.0 0.0 1.0"/>
            </material>
        </visual>
        <collision>
            <origin xyz="0 0 0.6985155661926239" rpy="0 0 0"/>
            <geometry>
                <box size="2.6900459975087347 1.7248410491289414 1.3970311323852478" />
            </geometry>
        </collision>
    </link>
    <link name="Leg14">
        <inertial>
            <origin xyz="0 0 0.6240801928866285" rpy="0 0 0"/>
            <mass value="1" />
            <inertia ixx="100" ixy="0" ixz="0" iyy="100" iyz="0" izz="100" />
        </inertial>
        <visual>
            <origin xyz="0 0 0.6240801928866285" rpy="0 0 0"/>
            <geometry>
                <box size="1.3399491496168832 1.2629867078074954 1.248160385773257" />
            </geometry>
            <material name="Blue">
                <color rgba="0 1.0 1.0 1.0"/>
            </material>
        </visual>
        <collision>
            <origin xyz="0 0 0.6240801928866285" rpy="0 0 0"/>
            <geometry>
                <box size="1.3399491496168832 1.2629867078074954 1.248160385773257" />
            </geometry>
        </collision>
    </link>
    <link name="Leg15">
        <inertial>
            <origin xyz="0 1.235886647369899 0" rpy="0 0 0"/>
            <mass value="1" />
            <inertia ixx="100" ixy="0" ixz="0" iyy="100" iyz="0" izz="100" />
        </inertial>
        <visual>
            <origin xyz="0 1.235886647369899 0" rpy="0 0 0"/>
            <geometry>
                <box size="2.6880157452636926 2.471773294739798 1.8307998016727325" />
            </geometry>
            <material name="Green">
                <color rgba="0 180.0 0.0 1.0"/>
            </material>
        </visual>
        <collision>
            <origin xyz="0 1.235886647369899 0" rpy="0 0 0"/>
            <geometry>
                <box size="2.6880157452636926 2.471773294739798 1.8307998016727325" />
            </geometry>
        </collision>
    </link>
    <link name="Leg16">
        <inertial>
            <origin xyz="1.2983920139658567 0 0" rpy="0 0 0"/>
            <mass value="1" />
            <inertia ixx="100" ixy="0" ixz="0" iyy="100" iyz="0" izz="100" />
        </inertial>
        <visual>
            <origin xyz="1.2983920139658567 0 0" rpy="0 0 0"/>
            <geometry>
                <box size="2.5967840279317134 1.9940527176089629 1.3929011888010263" />
            </geometry>
            <material name="Blue">
                <color rgba="0 1.0 1.0 1.0"/>
            </material>
        </visual>
        <collision>
            <origin xyz="1.2983920139658567 0 0" rpy="0 0 0"/>
            <geometry>
                <box size="2.5967840279317134 1.9940527176089629 1.3929011888010263" />
            </geometry>
        </collision>
    </link>
    <link name="Leg17">
        <inertial>
            <origin xyz="0.6365428199525637 0 0" rpy="0 0 0"/>
            <mass value="1" />
            <inertia ixx="100" ixy="0" ixz="0" iyy="100" iyz="0" izz="100" />
        </inertial>
        <visual>
            <origin xyz="0.6365428199525637 0 0" rpy="0 0 0"/>
            <geometry>
                <box size="1.2730856399051274 1.2505907990833431 1.6084417216367517" />
            </geometry>
            <material name="Blue">
                <color rgba="0 1.0 1.0 1.0"/>
            </material>
        </visual>
        <collision>
            <origin xyz="0.6365428199525637 0 0" rpy="0 0 0"/>
            <geometry>
                <box size="1.2730856399051274 1.2505907990833431 1.6084417216367517" />
            </geometry>
        </collision>
    </link>
    <link name="Leg18">
        <inertial>
            <origin xyz="0 0 1.1915683166611482" rpy="0 0 0"/>
            <mass value="1" />
            <inertia ixx="100" ixy="0" ixz="0" iyy="100" iyz="0" izz="100" />
        </inertial>
        <visual>
            <origin xyz="0 0 1.1915683166611482" rpy="0 0 0"/>
            <geometry>
                <box size="2.8321063692787605 1.9147297613839072 2.3831366333222963" />
            </geometry>
            <material name="Green">
                <color rgba="0 180.0 0.0 1.0"/>
            </material>
        </visual>
        <collision>
            <origin xyz="0 0 1.1915683166611482" rpy="0 0 0"/>
            <geometry>
                <box size="2.8321063692787605 1.9147297613839072 2.3831366333222963" />
            </geometry>
        </collision>
    </link>
    <link name="Leg19">
        <inertial>
            <origin xyz="0 0.6898933180395436 0" rpy="0 0 0"/>
            <mass value="1" />
            <inertia ixx="100" ixy="0" ixz="0" iyy="100" iyz="0" izz="100" />
        </inertial>
        <visual>
            <origin xyz="0 0.6898933180395436 0" rpy="0 0 0"/>
            <geometry>
                <box size="2.1612583119040556 1.3797866360790871 1.5896766204971966" />
            </geometry>
            <material name="Green">
                <color rgba="0 180.0 0.0 1.0"/>
            </material>
        </visual>
        <collision>
            <origin xyz="0 0.6898933180395436 0" rpy="0 0 0"/>
            <geometry>
                <box size="2.1612583119040556 1.3797866360790871 1.5896766204971966" />
            </geometry>
        </collision>
    </link>
    <link name="Leg20">
        <inertial>
            <origin xyz="1.0547673470199648 0 0" rpy="0 0 0"/>
            <mass value="1" />
            <inertia ixx="100" ixy="0" ixz="0" iyy="100" iyz="0" izz="100" />
        </inertial>
        <visual>
            <origin xyz="1.0547673470199648 0 0" rpy="0 0 0"/>
            <geometry>
                <box size="2.1095346940399295 2.322533645147529 1.1806823079914595" />
            </geometry>
            <material name="Blue">
                <color rgba="0 1.0 1.0 1.0"/>
            </material>
        </visual>
        <collision>
            <origin xyz="1.0547673470199648 0 0" rpy="0 0 0"/>
            <geometry>
                <box size="2.1095346940399295 2.322533645147529 1.1806823079914595" />
            </geometry>
        </collision>
    </link>
    <link name="Leg21">
        <inertial>
            <origin xyz="0 0 0.716993963884747" rpy="0 0 0"/>
            <mass value="1" />
            <inertia ixx="100" ixy="0" ixz="0" iyy="100" iyz="0" izz="100" />
        </inertial>
        <visual>
            <origin xyz="0 0 0.716993963884747" rpy="0 0 0"/>
            <geometry>
                <box size="1.7373347585659882 1.3954292581426593 1.433987927769494" />
            </geometry>
            <material name="Blue">
                <color rgba="0 1.0 1.0 1.0"/>
            </material>
        </visual>
        <collision>
            <origin xyz="0 0 0.716993963884747" rpy="0 0 0"/>
            <geometry>
                <box size="1.7373347585659882 1.3954292581426593 1.433987927769494" />
            </geometry>
        </collision>
    </link>
    <link name="Leg22">
        <inertial>
            <origin xyz="0.7648857103580076 0 0" rpy="0 0 0"/>
            <mass value="1" />
            <inertia ixx="100" ixy="0" ixz="0" iyy="100" iyz="0" izz="100" />
        </inertial>
        <visual>
            <origin xyz="0.7648857103580076 0 0" rpy="0 0 0"/>
            <geometry>
                <box size="1.5297714207160151 1.8916917176894659 2.845127299596386" />
            </geometry>
            <material name="Green">
                <color rgba="0 180.0 0.0 1.0"/>
            </material>
        </visual>
        <collision>
            <origin xyz="0.7648857103580076 0 0" rpy="0 0 0"/>
            <geometry>
                <box size="1.5297714207160151 1.8916917176894659 2.845127299596386" />
            </geometry>
        </collision>
    </link>
    <link name="Leg23">
        <inertial>
            <origin xyz="1.4595641924243834 0 0" rpy="0 0 0"/>
            <mass value="1" />
            <inertia ixx="100" ixy="0" ixz="0" iyy="100" iyz="0" izz="100" />
        </inertial>
        <visual>
            <origin xyz="1.4595641924243834 0 0" rpy="0 0 0"/>
            <geometry>
                <box size="2.919128384848767 2.469387488585381 2.8797096155366892" />
            </geometry>
            <material name="Blue">
                <color rgba="0 1.0 1.0 1.0"/>
            </material>
        </visual>
        <collision>
            <origin xyz="1.4595641924243834 0 0" rpy="0 0 0"/>
            <geometry>
                <box size="2.919128384848767 2.469387488585381 2.8797096155366892" />
            </geometry>
        </collision>
    </link>
    <link name="Leg24">
        <inertial>
            <origin xyz="0 0.8246022021096714 0" rpy="0 0 0"/>
            <mass value="1" />
            <inertia ixx="100" ixy="0" ixz="0" iyy="100" iyz="0" izz="100" />
        </inertial>
        <visual>
            <origin xyz="0 0.8246022021096714 0" rpy="0 0 0"/>
            <geometry>
                <box size="2.614636820817527 1.6492044042193428 1.3834380417467178" />
            </geometry>
            <material name="Blue">
                <color rgba="0 1.0 1.0 1.0"/>
            </material>
        </visual>
        <collision>
            <origin xyz="0 0.8246022021096714 0" rpy="0 0 0"/>
            <geometry>
                <box size="2.614636820817527 1.6492044042193428 1.3834380417467178" />
            </geometry>
        </collision>
    </link>
    <link name="Leg25">
        <inertial>
            <origin xyz="1.3159934495228485 0 0" rpy="0 0 0"/>
            <mass value="1" />
            <inertia ixx="100" ixy="0" ixz="0" iyy="100" iyz="0" izz="100" />
        </inertial>
        <visual>
            <origin xyz="1.3159934495228485 0 0" rpy="0 0 0"/>
            <geometry>
                <box size="2.631986899045697 2.5890865068100695 2.2734919522600205" />
            </geometry>
            <material name="Blue">
                <color rgba="0 1.0 1.0 1.0"/>
            </material>
        </visual>
        <collision>
            <origin xyz="1.3159934495228485 0 0" rpy="0 0 0"/>
            <geometry>
                <box size="2.631986899045697 2.5890865068100695 2.2734919522600205" />
            </geometry>
        </collision>
    </link>
    <link name="Leg26">
        <inertial>
            <origin xyz="0 0 1.2171679351381923" rpy="0 0 0"/>
            <mass value="1" />
            <inertia ixx="100" ixy="0" ixz="0" iyy="100" iyz="0" izz="100" />
        </inertial>
        <visual>
            <origin xyz="0 0 1.2171679351381923" rpy="0 0 0"/>
            <geometry>
                <box size="1.7493874511890377 1.0248552849693122 2.4343358702763847" />
            </geometry>
            <material name="Blue">
                <color rgba="0 1.0 1.0 1.0"/>
            </material>
        </visual>
        <collision>
            <origin xyz="0 0 1.2171679351381923" rpy="0 0 0"/>
            <geometry>
                <box size="1.7493874511890377 1.0248552849693122 2.4343358702763847" />
            </geometry>
        </collision>
    </link>
    <joint name="Torso_Leg1" type="revolute">
       <parent link="Torso"/>
       <child  link="Leg1"/>
       <origin rpy="0 0 0" xyz="0 0 1.2058885250505846" />
     <axis xyz="1 0 0"/>
       <limit effort="0.0" lower="-3.14159" upper="3.14159" velocity="0.0"/>
    </joint>
    <joint name="Leg1_Leg2" type="revolute">
       <parent link="Leg1"/>
       <child  link="Leg2"/>
       <origin rpy="0 0 0" xyz="0 0 1.599591559862682" />
     <axis xyz="1 0 0"/>
       <limit effort="0.0" lower="-3.14159" upper="3.14159" velocity="0.0"/>
    </joint>
    <joint name="Leg1_Leg3" type="revolute">
       <parent link="Leg1"/>
       <child  link="Leg3"/>
       <origin rpy="0 0 0" xyz="0 0.5443775548503909 1.599591559862682" />
     <axis xyz="1 0 0"/>
       <limit effort="0.0" lower="-3.14159" upper="3.14159" velocity="0.0"/>
    </joint>
    <joint name="Leg2_Leg4" type="revolute">
       <parent link="Leg2"/>
       <child  link="Leg4"/>
       <origin rpy="0 0 0" xyz="1.4268655450105903 0.6703391408465814 0" />
     <axis xyz="1 0 0"/>
       <limit effort="0.0" lower="-3.14159" upper="3.14159" velocity="0.0"/>
    </joint>
    <joint name="Leg2_Leg5" type="revolute">
       <parent link="Leg2"/>
       <child  link="Leg5"/>
       <origin rpy="0 0 0" xyz="1.4268655450105903 0.6703391408465814 0.502235776652246" />
     <axis xyz="1 0 0"/>
       <limit effort="0.0" lower="-3.14159" upper="3.14159" velocity="0.0"/>
    </joint>
    <joint name="Leg4_Leg6" type="revolute">
       <parent link="Leg4"/>
       <child  link="Leg6"/>
       <origin rpy="0 0 0" xyz="0 0 2.7736322416722192" />
     <axis xyz="1 0 0"/>
       <limit effort="0.0" lower="-3.14159" upper="3.14159" velocity="0.0"/>
    </joint>
    <joint name="Torso_Leg7" type="revolute">
       <parent link="Torso"/>
       <child  link="Leg7"/>
       <origin rpy="0 0 0" xyz="0.5565218595644079 0 0.5585775510059394" />
     <axis xyz="1 0 0"/>
       <limit effort="0.0" lower="-3.14159" upper="3.14159" velocity="0.0"/>
    </joint>
    <joint name="Leg3_Leg8" type="revolute">
       <parent link="Leg3"/>
       <child  link="Leg8"/>
       <origin rpy="0 0 0" xyz="1.0240994735669324 1.2930095602703826 0" />
     <axis xyz="1 0 0"/>
       <limit effort="0.0" lower="-3.14159" upper="3.14159" velocity="0.0"/>
    </joint>
    <joint name="Leg8_Leg9" type="revolute">
       <parent link="Leg8"/>
       <child  link="Leg9"/>
       <origin rpy="0 0 0" xyz="0 0 1.3488817105327697" />
     <axis xyz="1 0 0"/>
       <limit effort="0.0" lower="-3.14159" upper="3.14159" velocity="0.0"/>
    </joint>
    <joint name="Leg2_Leg10" type="revolute">
       <parent link="Leg2"/>
       <child  link="Leg10"/>
       <origin rpy="0 0 0" xyz="1.4268655450105903 1.3406782816931628 0.502235776652246" />
     <axis xyz="1 0 0"/>
       <limit effort="0.0" lower="-3.14159" upper="3.14159" velocity="0.0"/>
    </joint>
    <joint name="Leg10_Leg11" type="revolute">
       <parent link="Leg10"/>
       <child  link="Leg11"/>
       <origin rpy="0 0 0" xyz="0 2.5747022969088516 0" />
     <axis xyz="1 0 0"/>
       <limit effort="0.0" lower="-3.14159" upper="3.14159" velocity="0.0"/>
    </joint>
    <joint name="Leg7_Leg12" type="revolute">
       <parent link="Leg7"/>
       <child  link="Leg12"/>
       <origin rpy="0 0 0" xyz="0 0.9595568596510755 0.555823733334706" />
     <axis xyz="1 0 0"/>
       <limit effort="0.0" lower="-3.14159" upper="3.14159" velocity="0.0"/>
    </joint>
    <joint name="Leg5_Leg13" type="revolute">
       <parent link="Leg5"/>
       <child  link="Leg13"/>
       <origin rpy="0 0 0" xyz="0 0 2.2253488008993823" />
     <axis xyz="1 0 0"/>
       <limit effort="0.0" lower="-3.14159" upper="3.14159" velocity="0.0"/>
    </joint>
    <joint name="Leg3_Leg14" type="revolute">
       <parent link="Leg3"/>
       <child  link="Leg14"/>
       <origin rpy="0 0 0" xyz="1.0240994735669324 1.2930095602703826 1.024820574298963" />
     <axis xyz="1 0 0"/>
       <limit effort="0.0" lower="-3.14159" upper="3.14159" velocity="0.0"/>
    </joint>
    <joint name="Leg11_Leg15" type="revolute">
       <parent link="Leg11"/>
       <child  link="Leg15"/>
       <origin rpy="0 0 0" xyz="0 1.2159894499331256 0.8622383185328253" />
     <axis xyz="1 0 0"/>
       <limit effort="0.0" lower="-3.14159" upper="3.14159" velocity="0.0"/>
    </joint>
    <joint name="Leg6_Leg16" type="revolute">
       <parent link="Leg6"/>
       <child  link="Leg16"/>
       <origin rpy="0 0 0" xyz="2.631653026049242 0 0" />
     <axis xyz="1 0 0"/>
       <limit effort="0.0" lower="-3.14159" upper="3.14159" velocity="0.0"/>
    </joint>
    <joint name="Leg7_Leg17" type="revolute">
       <parent link="Leg7"/>
       <child  link="Leg17"/>
       <origin rpy="0 0 0" xyz="0.5785418180414543 0.9595568596510755 0.555823733334706" />
     <axis xyz="1 0 0"/>
       <limit effort="0.0" lower="-3.14159" upper="3.14159" velocity="0.0"/>
    </joint>
    <joint name="Leg15_Leg18" type="revolute">
       <parent link="Leg15"/>
       <child  link="Leg18"/>
       <origin rpy="0 0 0" xyz="1.2983920139658567 0 0.6964505944005132" />
     <axis xyz="1 0 0"/>
       <limit effort="0.0" lower="-3.14159" upper="3.14159" velocity="0.0"/>
    </joint>
    <joint name="Leg5_Leg19" type="revolute">
       <parent link="Leg5"/>
       <child  link="Leg19"/>
       <origin rpy="0 0 0" xyz="0 1.4321536968344102 2.2253488008993823" />
     <axis xyz="1 0 0"/>
       <limit effort="0.0" lower="-3.14159" upper="3.14159" velocity="0.0"/>
    </joint>
    <joint name="Leg5_Leg20" type="revolute">
       <parent link="Leg5"/>
       <child  link="Leg20"/>
       <origin rpy="0 0 0" xyz="1.498293622786016 1.4321536968344102 2.2253488008993823" />
     <axis xyz="1 0 0"/>
       <limit effort="0.0" lower="-3.14159" upper="3.14159" velocity="0.0"/>
    </joint>
    <joint name="Leg14_Leg21" type="revolute">
       <parent link="Leg14"/>
       <child  link="Leg21"/>
       <origin rpy="0 0 0" xyz="0 1.235886647369899 0.9153999008363662" />
     <axis xyz="1 0 0"/>
       <limit effort="0.0" lower="-3.14159" upper="3.14159" velocity="0.0"/>
    </joint>
    <joint name="Leg19_Leg22" type="revolute">
       <parent link="Leg19"/>
       <child  link="Leg22"/>
       <origin rpy="0 0 0" xyz="2.1095346940399295 0 0" />
     <axis xyz="1 0 0"/>
       <limit effort="0.0" lower="-3.14159" upper="3.14159" velocity="0.0"/>
    </joint>
    <joint name="Leg1_Leg23" type="revolute">
       <parent link="Leg1"/>
       <child  link="Leg23"/>
       <origin rpy="0 0 0" xyz="1.4882834639352098 0.5443775548503909 1.599591559862682" />
     <axis xyz="1 0 0"/>
       <limit effort="0.0" lower="-3.14159" upper="3.14159" velocity="0.0"/>
    </joint>
    <joint name="Leg4_Leg24" type="revolute">
       <parent link="Leg4"/>
       <child  link="Leg24"/>
       <origin rpy="0 0 0" xyz="0 1.104000336004309 2.7736322416722192" />
     <axis xyz="1 0 0"/>
       <limit effort="0.0" lower="-3.14159" upper="3.14159" velocity="0.0"/>
    </joint>
    <joint name="Leg11_Leg25" type="revolute">
       <parent link="Leg11"/>
       <child  link="Leg25"/>
       <origin rpy="0 0 0" xyz="0.8546329390816004 1.2159894499331256 0.8622383185328253" />
     <axis xyz="1 0 0"/>
       <limit effort="0.0" lower="-3.14159" upper="3.14159" velocity="0.0"/>
    </joint>
    <joint name="Leg12_Leg26" type="revolute">
       <parent link="Leg12"/>
       <child  link="Leg26"/>
       <origin rpy="0 0 0" xyz="0 0 1.3970311323852478" />
     <axis xyz="1 0 0"/>
       <limit effort="0.0" lower="-3.14159" upper="3.14159" velocity="0.0"/>
    </joint>
</robot>