<robot name = "robot">
    <link name="Torso">
        <inertial>
            <origin xyz="0 0 0.5775566888205396" rpy="0 0 0"/>
            <mass value="1" />
            <inertia ixx="100" ixy="0" ixz="0" iyy="100" iyz="0" izz="100" />
        </inertial>
        <visual>
            <origin xyz="0 0 0.5775566888205396" rpy="0 0 0"/>
            <geometry>
                <box size="1.5336901110718768 2.7749822706971314 1.1551133776410791" />
            </geometry>
            <material name="Green">
                <color rgba="0 180.0 0.0 1.0"/>
            </material>
        </visual>
        <collision>
            <origin xyz="0 0 0.5775566888205396" rpy="0 0 0"/>
            <geometry>
                <box size="1.5336901110718768 2.7749822706971314 1.1551133776410791" />
            </geometry>
        </collision>
    </link>
    <link name="Leg1">
        <inertial>
            <origin xyz="0 0 1.3830704234282911" rpy="0 0 0"/>
            <mass value="1" />
            <inertia ixx="100" ixy="0" ixz="0" iyy="100" iyz="0" izz="100" />
        </inertial>
        <visual>
            <origin xyz="0 0 1.3830704234282911" rpy="0 0 0"/>
            <geometry>
                <box size="1.113590059648514 2.4456393242093544 2.7661408468565822" />
            </geometry>
            <material name="Green">
                <color rgba="0 180.0 0.0 1.0"/>
            </material>
        </visual>
        <collision>
            <origin xyz="0 0 1.3830704234282911" rpy="0 0 0"/>
            <geometry>
                <box size="1.113590059648514 2.4456393242093544 2.7661408468565822" />
            </geometry>
        </collision>
    </link>
    <link name="Leg2">
        <inertial>
            <origin xyz="0 1.4849648482040427 0" rpy="0 0 0"/>
            <mass value="1" />
            <inertia ixx="100" ixy="0" ixz="0" iyy="100" iyz="0" izz="100" />
        </inertial>
        <visual>
            <origin xyz="0 1.4849648482040427 0" rpy="0 0 0"/>
            <geometry>
                <box size="1.0284271529335425 2.9699296964080855 2.1654356828191803" />
            </geometry>
            <material name="Green">
                <color rgba="0 180.0 0.0 1.0"/>
            </material>
        </visual>
        <collision>
            <origin xyz="0 1.4849648482040427 0" rpy="0 0 0"/>
            <geometry>
                <box size="1.0284271529335425 2.9699296964080855 2.1654356828191803" />
            </geometry>
        </collision>
    </link>
    <link name="Leg3">
        <inertial>
            <origin xyz="1.0469489070431117 0 0" rpy="0 0 0"/>
            <mass value="1" />
            <inertia ixx="100" ixy="0" ixz="0" iyy="100" iyz="0" izz="100" />
        </inertial>
        <visual>
            <origin xyz="1.0469489070431117 0 0" rpy="0 0 0"/>
            <geometry>
                <box size="2.0938978140862234 2.0645230821490683 2.8930101223500717" />
            </geometry>
            <material name="Blue">
                <color rgba="0 1.0 1.0 1.0"/>
            </material>
        </visual>
        <collision>
            <origin xyz="1.0469489070431117 0 0" rpy="0 0 0"/>
            <geometry>
                <box size="2.0938978140862234 2.0645230821490683 2.8930101223500717" />
            </geometry>
        </collision>
    </link>
    <link name="Leg4">
        <inertial>
            <origin xyz="0 0.7932879246258421 0" rpy="0 0 0"/>
            <mass value="1" />
            <inertia ixx="100" ixy="0" ixz="0" iyy="100" iyz="0" izz="100" />
        </inertial>
        <visual>
            <origin xyz="0 0.7932879246258421 0" rpy="0 0 0"/>
            <geometry>
                <box size="2.400201656214981 1.5865758492516842 1.5791754522173247" />
            </geometry>
            <material name="Blue">
                <color rgba="0 1.0 1.0 1.0"/>
            </material>
        </visual>
        <collision>
            <origin xyz="0 0.7932879246258421 0" rpy="0 0 0"/>
            <geometry>
                <box size="2.400201656214981 1.5865758492516842 1.5791754522173247" />
            </geometry>
        </collision>
    </link>
    <link name="Leg5">
        <inertial>
            <origin xyz="1.4944065418980177 0 0" rpy="0 0 0"/>
            <mass value="1" />
            <inertia ixx="100" ixy="0" ixz="0" iyy="100" iyz="0" izz="100" />
        </inertial>
        <visual>
            <origin xyz="1.4944065418980177 0 0" rpy="0 0 0"/>
            <geometry>
                <box size="2.9888130837960354 1.0444633167844406 2.0496056013845485" />
            </geometry>
            <material name="Blue">
                <color rgba="0 1.0 1.0 1.0"/>
            </material>
        </visual>
        <collision>
            <origin xyz="1.4944065418980177 0 0" rpy="0 0 0"/>
            <geometry>
                <box size="2.9888130837960354 1.0444633167844406 2.0496056013845485" />
            </geometry>
        </collision>
    </link>
    <link name="Leg6">
        <inertial>
            <origin xyz="0 0 0.6229419197215984" rpy="0 0 0"/>
            <mass value="1" />
            <inertia ixx="100" ixy="0" ixz="0" iyy="100" iyz="0" izz="100" />
        </inertial>
        <visual>
            <origin xyz="0 0 0.6229419197215984" rpy="0 0 0"/>
            <geometry>
                <box size="1.196590736482217 1.7402179344796413 1.2458838394431968" />
            </geometry>
            <material name="Blue">
                <color rgba="0 1.0 1.0 1.0"/>
            </material>
        </visual>
        <collision>
            <origin xyz="0 0 0.6229419197215984" rpy="0 0 0"/>
            <geometry>
                <box size="1.196590736482217 1.7402179344796413 1.2458838394431968" />
            </geometry>
        </collision>
    </link>
    <link name="Leg7">
        <inertial>
            <origin xyz="0 0 0.5115167429983191" rpy="0 0 0"/>
            <mass value="1" />
            <inertia ixx="100" ixy="0" ixz="0" iyy="100" iyz="0" izz="100" />
        </inertial>
        <visual>
            <origin xyz="0 0 0.5115167429983191" rpy="0 0 0"/>
            <geometry>
                <box size="1.5813718637779224 1.5790822118705545 1.0230334859966381" />
            </geometry>
            <material name="Green">
                <color rgba="0 180.0 0.0 1.0"/>
            </material>
        </visual>
        <collision>
            <origin xyz="0 0 0.5115167429983191" rpy="0 0 0"/>
            <geometry>
                <box size="1.5813718637779224 1.5790822118705545 1.0230334859966381" />
            </geometry>
        </collision>
    </link>
    <link name="Leg8">
        <inertial>
            <origin xyz="0 0 1.129232557525134" rpy="0 0 0"/>
            <mass value="1" />
            <inertia ixx="100" ixy="0" ixz="0" iyy="100" iyz="0" izz="100" />
        </inertial>
        <visual>
            <origin xyz="0 0 1.129232557525134" rpy="0 0 0"/>
            <geometry>
                <box size="1.144350788390683 1.5690591244701633 2.258465115050268" />
            </geometry>
            <material name="Blue">
                <color rgba="0 1.0 1.0 1.0"/>
            </material>
        </visual>
        <collision>
            <origin xyz="0 0 1.129232557525134" rpy="0 0 0"/>
            <geometry>
                <box size="1.144350788390683 1.5690591244701633 2.258465115050268" />
            </geometry>
        </collision>
    </link>
    <link name="Leg9">
        <inertial>
            <origin xyz="0 0.5119144679988638 0" rpy="0 0 0"/>
            <mass value="1" />
            <inertia ixx="100" ixy="0" ixz="0" iyy="100" iyz="0" izz="100" />
        </inertial>
        <visual>
            <origin xyz="0 0.5119144679988638 0" rpy="0 0 0"/>
            <geometry>
                <box size="1.8053333986019657 1.0238289359977275 2.9974497881479545" />
            </geometry>
            <material name="Blue">
                <color rgba="0 1.0 1.0 1.0"/>
            </material>
        </visual>
        <collision>
            <origin xyz="0 0.5119144679988638 0" rpy="0 0 0"/>
            <geometry>
                <box size="1.8053333986019657 1.0238289359977275 2.9974497881479545" />
            </geometry>
        </collision>
    </link>
    <link name="Leg10">
        <inertial>
            <origin xyz="0 0 1.0584473975329658" rpy="0 0 0"/>
            <mass value="1" />
            <inertia ixx="100" ixy="0" ixz="0" iyy="100" iyz="0" izz="100" />
        </inertial>
        <visual>
            <origin xyz="0 0 1.0584473975329658" rpy="0 0 0"/>
            <geometry>
                <box size="2.455032145792932 1.0120267954957969 2.1168947950659316" />
            </geometry>
            <material name="Green">
                <color rgba="0 180.0 0.0 1.0"/>
            </material>
        </visual>
        <collision>
            <origin xyz="0 0 1.0584473975329658" rpy="0 0 0"/>
            <geometry>
                <box size="2.455032145792932 1.0120267954957969 2.1168947950659316" />
            </geometry>
        </collision>
    </link>
    <link name="Leg11">
        <inertial>
            <origin xyz="0 0 1.0814792275270169" rpy="0 0 0"/>
            <mass value="1" />
            <inertia ixx="100" ixy="0" ixz="0" iyy="100" iyz="0" izz="100" />
        </inertial>
        <visual>
            <origin xyz="0 0 1.0814792275270169" rpy="0 0 0"/>
            <geometry>
                <box size="2.785388675934331 2.061846562297184 2.1629584550540337" />
            </geometry>
            <material name="Blue">
                <color rgba="0 1.0 1.0 1.0"/>
            </material>
        </visual>
        <collision>
            <origin xyz="0 0 1.0814792275270169" rpy="0 0 0"/>
            <geometry>
                <box size="2.785388675934331 2.061846562297184 2.1629584550540337" />
            </geometry>
        </collision>
    </link>
    <link name="Leg12">
        <inertial>
            <origin xyz="0 0 1.260375232923756" rpy="0 0 0"/>
            <mass value="1" />
            <inertia ixx="100" ixy="0" ixz="0" iyy="100" iyz="0" izz="100" />
        </inertial>
        <visual>
            <origin xyz="0 0 1.260375232923756" rpy="0 0 0"/>
            <geometry>
                <box size="1.6622379186300242 2.958584653242683 2.520750465847512" />
            </geometry>
            <material name="Blue">
                <color rgba="0 1.0 1.0 1.0"/>
            </material>
        </visual>
        <collision>
            <origin xyz="0 0 1.260375232923756" rpy="0 0 0"/>
            <geometry>
                <box size="1.6622379186300242 2.958584653242683 2.520750465847512" />
            </geometry>
        </collision>
    </link>
    <link name="Leg13">
        <inertial>
            <origin xyz="0.9519194068231758 0 0" rpy="0 0 0"/>
            <mass value="1" />
            <inertia ixx="100" ixy="0" ixz="0" iyy="100" iyz="0" izz="100" />
        </inertial>
        <visual>
            <origin xyz="0.9519194068231758 0 0" rpy="0 0 0"/>
            <geometry>
                <box size="1.9038388136463515 1.1985629903411938 1.5657438048966559" />
            </geometry>
            <material name="Blue">
                <color rgba="0 1.0 1.0 1.0"/>
            </material>
        </visual>
        <collision>
            <origin xyz="0.9519194068231758 0 0" rpy="0 0 0"/>
            <geometry>
                <box size="1.9038388136463515 1.1985629903411938 1.5657438048966559" />
            </geometry>
        </collision>
    </link>
    <link name="Leg14">
        <inertial>
            <origin xyz="0 0 1.064254839113866" rpy="0 0 0"/>
            <mass value="1" />
            <inertia ixx="100" ixy="0" ixz="0" iyy="100" iyz="0" izz="100" />
        </inertial>
        <visual>
            <origin xyz="0 0 1.064254839113866" rpy="0 0 0"/>
            <geometry>
                <box size="1.4680573728553392 1.6388025244104927 2.128509678227732" />
            </geometry>
            <material name="Green">
                <color rgba="0 180.0 0.0 1.0"/>
            </material>
        </visual>
        <collision>
            <origin xyz="0 0 1.064254839113866" rpy="0 0 0"/>
            <geometry>
                <box size="1.4680573728553392 1.6388025244104927 2.128509678227732" />
            </geometry>
        </collision>
    </link>
    <link name="Leg15">
        <inertial>
            <origin xyz="0 0.7064366092968744 0" rpy="0 0 0"/>
            <mass value="1" />
            <inertia ixx="100" ixy="0" ixz="0" iyy="100" iyz="0" izz="100" />
        </inertial>
        <visual>
            <origin xyz="0 0.7064366092968744 0" rpy="0 0 0"/>
            <geometry>
                <box size="1.1124803845217635 1.4128732185937487 1.368103063188716" />
            </geometry>
            <material name="Blue">
                <color rgba="0 1.0 1.0 1.0"/>
            </material>
        </visual>
        <collision>
            <origin xyz="0 0.7064366092968744 0" rpy="0 0 0"/>
            <geometry>
                <box size="1.1124803845217635 1.4128732185937487 1.368103063188716" />
            </geometry>
        </collision>
    </link>
    <link name="Leg16">
        <inertial>
            <origin xyz="0 1.1095053164203168 0" rpy="0 0 0"/>
            <mass value="1" />
            <inertia ixx="100" ixy="0" ixz="0" iyy="100" iyz="0" izz="100" />
        </inertial>
        <visual>
            <origin xyz="0 1.1095053164203168 0" rpy="0 0 0"/>
            <geometry>
                <box size="1.8025593350477953 2.2190106328406336 1.1730607472576553" />
            </geometry>
            <material name="Green">
                <color rgba="0 180.0 0.0 1.0"/>
            </material>
        </visual>
        <collision>
            <origin xyz="0 1.1095053164203168 0" rpy="0 0 0"/>
            <geometry>
                <box size="1.8025593350477953 2.2190106328406336 1.1730607472576553" />
            </geometry>
        </collision>
    </link>
    <link name="Leg17">
        <inertial>
            <origin xyz="0 0 0.9796069751104266" rpy="0 0 0"/>
            <mass value="1" />
            <inertia ixx="100" ixy="0" ixz="0" iyy="100" iyz="0" izz="100" />
        </inertial>
        <visual>
            <origin xyz="0 0 0.9796069751104266" rpy="0 0 0"/>
            <geometry>
                <box size="2.036616432306408 2.2023225542913973 1.9592139502208532" />
            </geometry>
            <material name="Green">
                <color rgba="0 180.0 0.0 1.0"/>
            </material>
        </visual>
        <collision>
            <origin xyz="0 0 0.9796069751104266" rpy="0 0 0"/>
            <geometry>
                <box size="2.036616432306408 2.2023225542913973 1.9592139502208532" />
            </geometry>
        </collision>
    </link>
    <link name="Leg18">
        <inertial>
            <origin xyz="0 1.231190674187066 0" rpy="0 0 0"/>
            <mass value="1" />
            <inertia ixx="100" ixy="0" ixz="0" iyy="100" iyz="0" izz="100" />
        </inertial>
        <visual>
            <origin xyz="0 1.231190674187066 0" rpy="0 0 0"/>
            <geometry>
                <box size="2.2982577773490913 2.462381348374132 1.9777880865650441" />
            </geometry>
            <material name="Green">
                <color rgba="0 180.0 0.0 1.0"/>
            </material>
        </visual>
        <collision>
            <origin xyz="0 1.231190674187066 0" rpy="0 0 0"/>
            <geometry>
                <box size="2.2982577773490913 2.462381348374132 1.9777880865650441" />
            </geometry>
        </collision>
    </link>
    <link name="Leg19">
        <inertial>
            <origin xyz="0 0 0.8230367284513159" rpy="0 0 0"/>
            <mass value="1" />
            <inertia ixx="100" ixy="0" ixz="0" iyy="100" iyz="0" izz="100" />
        </inertial>
        <visual>
            <origin xyz="0 0 0.8230367284513159" rpy="0 0 0"/>
            <geometry>
                <box size="1.340458838223133 2.49969116776826 1.6460734569026318" />
            </geometry>
            <material name="Green">
                <color rgba="0 180.0 0.0 1.0"/>
            </material>
        </visual>
        <collision>
            <origin xyz="0 0 0.8230367284513159" rpy="0 0 0"/>
            <geometry>
                <box size="1.340458838223133 2.49969116776826 1.6460734569026318" />
            </geometry>
        </collision>
    </link>
    <link name="Leg20">
        <inertial>
            <origin xyz="0.595106874828685 0 0" rpy="0 0 0"/>
            <mass value="1" />
            <inertia ixx="100" ixy="0" ixz="0" iyy="100" iyz="0" izz="100" />
        </inertial>
        <visual>
            <origin xyz="0.595106874828685 0 0" rpy="0 0 0"/>
            <geometry>
                <box size="1.19021374965737 1.3385138359868067 2.7859933457392017" />
            </geometry>
            <material name="Blue">
                <color rgba="0 1.0 1.0 1.0"/>
            </material>
        </visual>
        <collision>
            <origin xyz="0.595106874828685 0 0" rpy="0 0 0"/>
            <geometry>
                <box size="1.19021374965737 1.3385138359868067 2.7859933457392017" />
            </geometry>
        </collision>
    </link>
    <link name="Leg21">
        <inertial>
            <origin xyz="0.7970443289911351 0 0" rpy="0 0 0"/>
            <mass value="1" />
            <inertia ixx="100" ixy="0" ixz="0" iyy="100" iyz="0" izz="100" />
        </inertial>
        <visual>
            <origin xyz="0.7970443289911351 0 0" rpy="0 0 0"/>
            <geometry>
                <box size="1.5940886579822702 1.1369924408136982 1.5218742849475262" />
            </geometry>
            <material name="Green">
                <color rgba="0 180.0 0.0 1.0"/>
            </material>
        </visual>
        <collision>
            <origin xyz="0.7970443289911351 0 0" rpy="0 0 0"/>
            <geometry>
                <box size="1.5940886579822702 1.1369924408136982 1.5218742849475262" />
            </geometry>
        </collision>
    </link>
    <link name="Leg22">
        <inertial>
            <origin xyz="0 1.3352717640687641 0" rpy="0 0 0"/>
            <mass value="1" />
            <inertia ixx="100" ixy="0" ixz="0" iyy="100" iyz="0" izz="100" />
        </inertial>
        <visual>
            <origin xyz="0 1.3352717640687641 0" rpy="0 0 0"/>
            <geometry>
                <box size="1.9387677323731816 2.6705435281375283 1.8031497139167099" />
            </geometry>
            <material name="Green">
                <color rgba="0 180.0 0.0 1.0"/>
            </material>
        </visual>
        <collision>
            <origin xyz="0 1.3352717640687641 0" rpy="0 0 0"/>
            <geometry>
                <box size="1.9387677323731816 2.6705435281375283 1.8031497139167099" />
            </geometry>
        </collision>
    </link>
    <link name="Leg23">
        <inertial>
            <origin xyz="1.19407850073972 0 0" rpy="0 0 0"/>
            <mass value="1" />
            <inertia ixx="100" ixy="0" ixz="0" iyy="100" iyz="0" izz="100" />
        </inertial>
        <visual>
            <origin xyz="1.19407850073972 0 0" rpy="0 0 0"/>
            <geometry>
                <box size="2.38815700147944 1.5893943130220722 2.1841457570257083" />
            </geometry>
            <material name="Blue">
                <color rgba="0 1.0 1.0 1.0"/>
            </material>
        </visual>
        <collision>
            <origin xyz="1.19407850073972 0 0" rpy="0 0 0"/>
            <geometry>
                <box size="2.38815700147944 1.5893943130220722 2.1841457570257083" />
            </geometry>
        </collision>
    </link>
    <link name="Leg24">
        <inertial>
            <origin xyz="0 0 1.439783552377293" rpy="0 0 0"/>
            <mass value="1" />
            <inertia ixx="100" ixy="0" ixz="0" iyy="100" iyz="0" izz="100" />
        </inertial>
        <visual>
            <origin xyz="0 0 1.439783552377293" rpy="0 0 0"/>
            <geometry>
                <box size="2.4830143188888485 2.145770661505217 2.879567104754586" />
            </geometry>
            <material name="Green">
                <color rgba="0 180.0 0.0 1.0"/>
            </material>
        </visual>
        <collision>
            <origin xyz="0 0 1.439783552377293" rpy="0 0 0"/>
            <geometry>
                <box size="2.4830143188888485 2.145770661505217 2.879567104754586" />
            </geometry>
        </collision>
    </link>
    <link name="Leg25">
        <inertial>
            <origin xyz="1.2131494525529047 0 0" rpy="0 0 0"/>
            <mass value="1" />
            <inertia ixx="100" ixy="0" ixz="0" iyy="100" iyz="0" izz="100" />
        </inertial>
        <visual>
            <origin xyz="1.2131494525529047 0 0" rpy="0 0 0"/>
            <geometry>
                <box size="2.4262989051058095 1.2559985647988126 2.482700328585996" />
            </geometry>
            <material name="Green">
                <color rgba="0 180.0 0.0 1.0"/>
            </material>
        </visual>
        <collision>
            <origin xyz="1.2131494525529047 0 0" rpy="0 0 0"/>
            <geometry>
                <box size="2.4262989051058095 1.2559985647988126 2.482700328585996" />
            </geometry>
        </collision>
    </link>
    <link name="Leg26">
        <inertial>
            <origin xyz="0 0.6446398914766142 0" rpy="0 0 0"/>
            <mass value="1" />
            <inertia ixx="100" ixy="0" ixz="0" iyy="100" iyz="0" izz="100" />
        </inertial>
        <visual>
            <origin xyz="0 0.6446398914766142 0" rpy="0 0 0"/>
            <geometry>
                <box size="1.3386674152876719 1.2892797829532283 2.781957307648841" />
            </geometry>
            <material name="Blue">
                <color rgba="0 1.0 1.0 1.0"/>
            </material>
        </visual>
        <collision>
            <origin xyz="0 0.6446398914766142 0" rpy="0 0 0"/>
            <geometry>
                <box size="1.3386674152876719 1.2892797829532283 2.781957307648841" />
            </geometry>
        </collision>
    </link>
    <joint name="Torso_Leg1" type="revolute">
       <parent link="Torso"/>
       <child  link="Leg1"/>
       <origin rpy="0 0 0" xyz="0 0 1.1551133776410791" />
     <axis xyz="1 0 0"/>
       <limit effort="0.0" lower="-3.14159" upper="3.14159" velocity="0.0"/>
    </joint>
    <joint name="Torso_Leg2" type="revolute">
       <parent link="Torso"/>
       <child  link="Leg2"/>
       <origin rpy="0 0 0" xyz="0 1.2228196621046772 1.3830704234282911" />
     <axis xyz="1 0 0"/>
       <limit effort="0.0" lower="-3.14159" upper="3.14159" velocity="0.0"/>
    </joint>
    <joint name="Leg1_Leg3" type="revolute">
       <parent link="Leg1"/>
       <child  link="Leg3"/>
       <origin rpy="0 0 0" xyz="0.5142135764667712 1.4849648482040427 0" />
     <axis xyz="1 0 0"/>
       <limit effort="0.0" lower="-3.14159" upper="3.14159" velocity="0.0"/>
    </joint>
    <joint name="Leg1_Leg4" type="revolute">
       <parent link="Leg1"/>
       <child  link="Leg4"/>
       <origin rpy="0 0 0" xyz="0.5142135764667712 2.9699296964080855 0" />
     <axis xyz="1 0 0"/>
       <limit effort="0.0" lower="-3.14159" upper="3.14159" velocity="0.0"/>
    </joint>
    <joint name="Leg3_Leg5" type="revolute">
       <parent link="Leg3"/>
       <child  link="Leg5"/>
       <origin rpy="0 0 0" xyz="1.2001008281074905 0.7932879246258421 0" />
     <axis xyz="1 0 0"/>
       <limit effort="0.0" lower="-3.14159" upper="3.14159" velocity="0.0"/>
    </joint>
    <joint name="Leg3_Leg6" type="revolute">
       <parent link="Leg3"/>
       <child  link="Leg6"/>
       <origin rpy="0 0 0" xyz="1.2001008281074905 0.7932879246258421 0.7895877261086623" />
     <axis xyz="1 0 0"/>
       <limit effort="0.0" lower="-3.14159" upper="3.14159" velocity="0.0"/>
    </joint>
    <joint name="Leg5_Leg7" type="revolute">
       <parent link="Leg5"/>
       <child  link="Leg7"/>
       <origin rpy="0 0 0" xyz="0 0 1.2458838394431968" />
     <axis xyz="1 0 0"/>
       <limit effort="0.0" lower="-3.14159" upper="3.14159" velocity="0.0"/>
    </joint>
    <joint name="Leg7_Leg8" type="revolute">
       <parent link="Leg7"/>
       <child  link="Leg8"/>
       <origin rpy="0 0 0" xyz="0 0 2.258465115050268" />
     <axis xyz="1 0 0"/>
       <limit effort="0.0" lower="-3.14159" upper="3.14159" velocity="0.0"/>
    </joint>
    <joint name="Leg8_Leg9" type="revolute">
       <parent link="Leg8"/>
       <child  link="Leg9"/>
       <origin rpy="0 0 0" xyz="0 1.0238289359977275 0" />
     <axis xyz="1 0 0"/>
       <limit effort="0.0" lower="-3.14159" upper="3.14159" velocity="0.0"/>
    </joint>
    <joint name="Leg1_Leg10" type="revolute">
       <parent link="Leg1"/>
       <child  link="Leg10"/>
       <origin rpy="0 0 0" xyz="0.5142135764667712 2.9699296964080855 1.0827178414095902" />
     <axis xyz="1 0 0"/>
       <limit effort="0.0" lower="-3.14159" upper="3.14159" velocity="0.0"/>
    </joint>
    <joint name="Leg4_Leg11" type="revolute">
       <parent link="Leg4"/>
       <child  link="Leg11"/>
       <origin rpy="0 0 0" xyz="1.4944065418980177 0 1.0248028006922743" />
     <axis xyz="1 0 0"/>
       <limit effort="0.0" lower="-3.14159" upper="3.14159" velocity="0.0"/>
    </joint>
    <joint name="Leg11_Leg12" type="revolute">
       <parent link="Leg11"/>
       <child  link="Leg12"/>
       <origin rpy="0 0 0" xyz="0 0 2.520750465847512" />
     <axis xyz="1 0 0"/>
       <limit effort="0.0" lower="-3.14159" upper="3.14159" velocity="0.0"/>
    </joint>
    <joint name="Leg8_Leg13" type="revolute">
       <parent link="Leg8"/>
       <child  link="Leg13"/>
       <origin rpy="0 0 0" xyz="0.9026666993009829 1.0238289359977275 0" />
     <axis xyz="1 0 0"/>
       <limit effort="0.0" lower="-3.14159" upper="3.14159" velocity="0.0"/>
    </joint>
    <joint name="Leg8_Leg14" type="revolute">
       <parent link="Leg8"/>
       <child  link="Leg14"/>
       <origin rpy="0 0 0" xyz="0.9026666993009829 1.0238289359977275 1.4987248940739772" />
     <axis xyz="1 0 0"/>
       <limit effort="0.0" lower="-3.14159" upper="3.14159" velocity="0.0"/>
    </joint>
    <joint name="Leg11_Leg15" type="revolute">
       <parent link="Leg11"/>
       <child  link="Leg15"/>
       <origin rpy="0 0 0" xyz="0 1.4792923266213416 2.520750465847512" />
     <axis xyz="1 0 0"/>
       <limit effort="0.0" lower="-3.14159" upper="3.14159" velocity="0.0"/>
    </joint>
    <joint name="Leg5_Leg16" type="revolute">
       <parent link="Leg5"/>
       <child  link="Leg16"/>
       <origin rpy="0 0 0" xyz="0 0.8701089672398207 1.2458838394431968" />
     <axis xyz="1 0 0"/>
       <limit effort="0.0" lower="-3.14159" upper="3.14159" velocity="0.0"/>
    </joint>
    <joint name="Leg9_Leg17" type="revolute">
       <parent link="Leg9"/>
       <child  link="Leg17"/>
       <origin rpy="0 0 0" xyz="0 0 2.1168947950659316" />
     <axis xyz="1 0 0"/>
       <limit effort="0.0" lower="-3.14159" upper="3.14159" velocity="0.0"/>
    </joint>
    <joint name="Leg7_Leg18" type="revolute">
       <parent link="Leg7"/>
       <child  link="Leg18"/>
       <origin rpy="0 0 0" xyz="0 0.7845295622350816 2.258465115050268" />
     <axis xyz="1 0 0"/>
       <limit effort="0.0" lower="-3.14159" upper="3.14159" velocity="0.0"/>
    </joint>
    <joint name="Leg14_Leg19" type="revolute">
       <parent link="Leg14"/>
       <child  link="Leg19"/>
       <origin rpy="0 0 0" xyz="0 0.7064366092968744 0.684051531594358" />
     <axis xyz="1 0 0"/>
       <limit effort="0.0" lower="-3.14159" upper="3.14159" velocity="0.0"/>
    </joint>
    <joint name="Leg17_Leg20" type="revolute">
       <parent link="Leg17"/>
       <child  link="Leg20"/>
       <origin rpy="0 0 0" xyz="1.1491288886745457 1.231190674187066 0" />
     <axis xyz="1 0 0"/>
       <limit effort="0.0" lower="-3.14159" upper="3.14159" velocity="0.0"/>
    </joint>
    <joint name="Leg9_Leg21" type="revolute">
       <parent link="Leg9"/>
       <child  link="Leg21"/>
       <origin rpy="0 0 0" xyz="1.227516072896466 0 2.1168947950659316" />
     <axis xyz="1 0 0"/>
       <limit effort="0.0" lower="-3.14159" upper="3.14159" velocity="0.0"/>
    </joint>
    <joint name="Leg2_Leg22" type="revolute">
       <parent link="Leg2"/>
       <child  link="Leg22"/>
       <origin rpy="0 0 0" xyz="1.0469489070431117 1.0322615410745342 0" />
     <axis xyz="1 0 0"/>
       <limit effort="0.0" lower="-3.14159" upper="3.14159" velocity="0.0"/>
    </joint>
    <joint name="Leg14_Leg23" type="revolute">
       <parent link="Leg14"/>
       <child  link="Leg23"/>
       <origin rpy="0 0 0" xyz="0.5562401922608817 0.7064366092968744 0.684051531594358" />
     <axis xyz="1 0 0"/>
       <limit effort="0.0" lower="-3.14159" upper="3.14159" velocity="0.0"/>
    </joint>
    <joint name="Leg21_Leg24" type="revolute">
       <parent link="Leg21"/>
       <child  link="Leg24"/>
       <origin rpy="0 0 0" xyz="0 1.3352717640687641 0.9015748569583549" />
     <axis xyz="1 0 0"/>
       <limit effort="0.0" lower="-3.14159" upper="3.14159" velocity="0.0"/>
    </joint>
    <joint name="Leg10_Leg25" type="revolute">
       <parent link="Leg10"/>
       <child  link="Leg25"/>
       <origin rpy="0 0 0" xyz="1.3926943379671655 0 1.0814792275270169" />
     <axis xyz="1 0 0"/>
       <limit effort="0.0" lower="-3.14159" upper="3.14159" velocity="0.0"/>
    </joint>
    <joint name="Leg6_Leg26" type="revolute">
       <parent link="Leg6"/>
       <child  link="Leg26"/>
       <origin rpy="0 0 0" xyz="0 0.7895411059352773 0.5115167429983191" />
     <axis xyz="1 0 0"/>
       <limit effort="0.0" lower="-3.14159" upper="3.14159" velocity="0.0"/>
    </joint>
</robot>