<robot name = "robot">
    <link name="Torso">
        <inertial>
            <origin xyz="0 0 0.7702262347041431" rpy="0 0 0"/>
            <mass value="1" />
            <inertia ixx="100" ixy="0" ixz="0" iyy="100" iyz="0" izz="100" />
        </inertial>
        <visual>
            <origin xyz="0 0 0.7702262347041431" rpy="0 0 0"/>
            <geometry>
                <box size="1.0138635986834212 2.7146005424620245 1.5404524694082862" />
            </geometry>
            <material name="Green">
                <color rgba="0 180.0 0.0 1.0"/>
            </material>
        </visual>
        <collision>
            <origin xyz="0 0 0.7702262347041431" rpy="0 0 0"/>
            <geometry>
                <box size="1.0138635986834212 2.7146005424620245 1.5404524694082862" />
            </geometry>
        </collision>
    </link>
    <link name="Leg1">
        <inertial>
            <origin xyz="1.2967581206541845 0 0" rpy="0 0 0"/>
            <mass value="1" />
            <inertia ixx="100" ixy="0" ixz="0" iyy="100" iyz="0" izz="100" />
        </inertial>
        <visual>
            <origin xyz="1.2967581206541845 0 0" rpy="0 0 0"/>
            <geometry>
                <box size="2.593516241308369 2.360706598735653 1.6405957341825066" />
            </geometry>
            <material name="Blue">
                <color rgba="0 1.0 1.0 1.0"/>
            </material>
        </visual>
        <collision>
            <origin xyz="1.2967581206541845 0 0" rpy="0 0 0"/>
            <geometry>
                <box size="2.593516241308369 2.360706598735653 1.6405957341825066" />
            </geometry>
        </collision>
    </link>
    <link name="Leg2">
        <inertial>
            <origin xyz="0 0.8997215729308061 0" rpy="0 0 0"/>
            <mass value="1" />
            <inertia ixx="100" ixy="0" ixz="0" iyy="100" iyz="0" izz="100" />
        </inertial>
        <visual>
            <origin xyz="0 0.8997215729308061 0" rpy="0 0 0"/>
            <geometry>
                <box size="1.6673028460843917 1.7994431458616122 1.447405574125708" />
            </geometry>
            <material name="Green">
                <color rgba="0 180.0 0.0 1.0"/>
            </material>
        </visual>
        <collision>
            <origin xyz="0 0.8997215729308061 0" rpy="0 0 0"/>
            <geometry>
                <box size="1.6673028460843917 1.7994431458616122 1.447405574125708" />
            </geometry>
        </collision>
    </link>
    <link name="Leg3">
        <inertial>
            <origin xyz="1.4010861355414148 0 0" rpy="0 0 0"/>
            <mass value="1" />
            <inertia ixx="100" ixy="0" ixz="0" iyy="100" iyz="0" izz="100" />
        </inertial>
        <visual>
            <origin xyz="1.4010861355414148 0 0" rpy="0 0 0"/>
            <geometry>
                <box size="2.8021722710828296 2.2768220914130017 2.1715353871374043" />
            </geometry>
            <material name="Green">
                <color rgba="0 180.0 0.0 1.0"/>
            </material>
        </visual>
        <collision>
            <origin xyz="1.4010861355414148 0 0" rpy="0 0 0"/>
            <geometry>
                <box size="2.8021722710828296 2.2768220914130017 2.1715353871374043" />
            </geometry>
        </collision>
    </link>
    <link name="Leg4">
        <inertial>
            <origin xyz="0 0 1.3937848564980158" rpy="0 0 0"/>
            <mass value="1" />
            <inertia ixx="100" ixy="0" ixz="0" iyy="100" iyz="0" izz="100" />
        </inertial>
        <visual>
            <origin xyz="0 0 1.3937848564980158" rpy="0 0 0"/>
            <geometry>
                <box size="2.8921448453807006 1.7054786565458042 2.7875697129960315" />
            </geometry>
            <material name="Green">
                <color rgba="0 180.0 0.0 1.0"/>
            </material>
        </visual>
        <collision>
            <origin xyz="0 0 1.3937848564980158" rpy="0 0 0"/>
            <geometry>
                <box size="2.8921448453807006 1.7054786565458042 2.7875697129960315" />
            </geometry>
        </collision>
    </link>
    <link name="Leg5">
        <inertial>
            <origin xyz="0 1.3230656426983582 0" rpy="0 0 0"/>
            <mass value="1" />
            <inertia ixx="100" ixy="0" ixz="0" iyy="100" iyz="0" izz="100" />
        </inertial>
        <visual>
            <origin xyz="0 1.3230656426983582 0" rpy="0 0 0"/>
            <geometry>
                <box size="2.2729359839346874 2.6461312853967165 2.306810704892264" />
            </geometry>
            <material name="Green">
                <color rgba="0 180.0 0.0 1.0"/>
            </material>
        </visual>
        <collision>
            <origin xyz="0 1.3230656426983582 0" rpy="0 0 0"/>
            <geometry>
                <box size="2.2729359839346874 2.6461312853967165 2.306810704892264" />
            </geometry>
        </collision>
    </link>
    <link name="Leg6">
        <inertial>
            <origin xyz="0 0 0.6051095009652919" rpy="0 0 0"/>
            <mass value="1" />
            <inertia ixx="100" ixy="0" ixz="0" iyy="100" iyz="0" izz="100" />
        </inertial>
        <visual>
            <origin xyz="0 0 0.6051095009652919" rpy="0 0 0"/>
            <geometry>
                <box size="2.504039589827882 2.2913882488251525 1.2102190019305838" />
            </geometry>
            <material name="Blue">
                <color rgba="0 1.0 1.0 1.0"/>
            </material>
        </visual>
        <collision>
            <origin xyz="0 0 0.6051095009652919" rpy="0 0 0"/>
            <geometry>
                <box size="2.504039589827882 2.2913882488251525 1.2102190019305838" />
            </geometry>
        </collision>
    </link>
    <link name="Leg7">
        <inertial>
            <origin xyz="0 0 1.4860316089857837" rpy="0 0 0"/>
            <mass value="1" />
            <inertia ixx="100" ixy="0" ixz="0" iyy="100" iyz="0" izz="100" />
        </inertial>
        <visual>
            <origin xyz="0 0 1.4860316089857837" rpy="0 0 0"/>
            <geometry>
                <box size="2.9679628810103686 1.2841706398582111 2.9720632179715674" />
            </geometry>
            <material name="Green">
                <color rgba="0 180.0 0.0 1.0"/>
            </material>
        </visual>
        <collision>
            <origin xyz="0 0 1.4860316089857837" rpy="0 0 0"/>
            <geometry>
                <box size="2.9679628810103686 1.2841706398582111 2.9720632179715674" />
            </geometry>
        </collision>
    </link>
    <link name="Leg8">
        <inertial>
            <origin xyz="0 0 1.3056495015342766" rpy="0 0 0"/>
            <mass value="1" />
            <inertia ixx="100" ixy="0" ixz="0" iyy="100" iyz="0" izz="100" />
        </inertial>
        <visual>
            <origin xyz="0 0 1.3056495015342766" rpy="0 0 0"/>
            <geometry>
                <box size="1.0523798898736314 1.6241272047624984 2.6112990030685532" />
            </geometry>
            <material name="Blue">
                <color rgba="0 1.0 1.0 1.0"/>
            </material>
        </visual>
        <collision>
            <origin xyz="0 0 1.3056495015342766" rpy="0 0 0"/>
            <geometry>
                <box size="1.0523798898736314 1.6241272047624984 2.6112990030685532" />
            </geometry>
        </collision>
    </link>
    <link name="Leg9">
        <inertial>
            <origin xyz="0 1.0574650870127522 0" rpy="0 0 0"/>
            <mass value="1" />
            <inertia ixx="100" ixy="0" ixz="0" iyy="100" iyz="0" izz="100" />
        </inertial>
        <visual>
            <origin xyz="0 1.0574650870127522 0" rpy="0 0 0"/>
            <geometry>
                <box size="1.869741263208505 2.1149301740255044 2.4273186478825073" />
            </geometry>
            <material name="Blue">
                <color rgba="0 1.0 1.0 1.0"/>
            </material>
        </visual>
        <collision>
            <origin xyz="0 1.0574650870127522 0" rpy="0 0 0"/>
            <geometry>
                <box size="1.869741263208505 2.1149301740255044 2.4273186478825073" />
            </geometry>
        </collision>
    </link>
    <link name="Leg10">
        <inertial>
            <origin xyz="0.6327178586580007 0 0" rpy="0 0 0"/>
            <mass value="1" />
            <inertia ixx="100" ixy="0" ixz="0" iyy="100" iyz="0" izz="100" />
        </inertial>
        <visual>
            <origin xyz="0.6327178586580007 0 0" rpy="0 0 0"/>
            <geometry>
                <box size="1.2654357173160014 2.843640575255869 1.2301635567058133" />
            </geometry>
            <material name="Green">
                <color rgba="0 180.0 0.0 1.0"/>
            </material>
        </visual>
        <collision>
            <origin xyz="0.6327178586580007 0 0" rpy="0 0 0"/>
            <geometry>
                <box size="1.2654357173160014 2.843640575255869 1.2301635567058133" />
            </geometry>
        </collision>
    </link>
    <link name="Leg11">
        <inertial>
            <origin xyz="1.136523661037245 0 0" rpy="0 0 0"/>
            <mass value="1" />
            <inertia ixx="100" ixy="0" ixz="0" iyy="100" iyz="0" izz="100" />
        </inertial>
        <visual>
            <origin xyz="1.136523661037245 0 0" rpy="0 0 0"/>
            <geometry>
                <box size="2.27304732207449 1.9104121004069738 2.873150036782122" />
            </geometry>
            <material name="Blue">
                <color rgba="0 1.0 1.0 1.0"/>
            </material>
        </visual>
        <collision>
            <origin xyz="1.136523661037245 0 0" rpy="0 0 0"/>
            <geometry>
                <box size="2.27304732207449 1.9104121004069738 2.873150036782122" />
            </geometry>
        </collision>
    </link>
    <link name="Leg12">
        <inertial>
            <origin xyz="0 0 1.299970474662259" rpy="0 0 0"/>
            <mass value="1" />
            <inertia ixx="100" ixy="0" ixz="0" iyy="100" iyz="0" izz="100" />
        </inertial>
        <visual>
            <origin xyz="0 0 1.299970474662259" rpy="0 0 0"/>
            <geometry>
                <box size="2.675594152781951 1.225748912477076 2.599940949324518" />
            </geometry>
            <material name="Blue">
                <color rgba="0 1.0 1.0 1.0"/>
            </material>
        </visual>
        <collision>
            <origin xyz="0 0 1.299970474662259" rpy="0 0 0"/>
            <geometry>
                <box size="2.675594152781951 1.225748912477076 2.599940949324518" />
            </geometry>
        </collision>
    </link>
    <link name="Leg13">
        <inertial>
            <origin xyz="0 0 1.4654095298660652" rpy="0 0 0"/>
            <mass value="1" />
            <inertia ixx="100" ixy="0" ixz="0" iyy="100" iyz="0" izz="100" />
        </inertial>
        <visual>
            <origin xyz="0 0 1.4654095298660652" rpy="0 0 0"/>
            <geometry>
                <box size="2.006102240489536 1.3843127825780492 2.9308190597321304" />
            </geometry>
            <material name="Blue">
                <color rgba="0 1.0 1.0 1.0"/>
            </material>
        </visual>
        <collision>
            <origin xyz="0 0 1.4654095298660652" rpy="0 0 0"/>
            <geometry>
                <box size="2.006102240489536 1.3843127825780492 2.9308190597321304" />
            </geometry>
        </collision>
    </link>
    <link name="Leg14">
        <inertial>
            <origin xyz="0 0 0.6531993260356428" rpy="0 0 0"/>
            <mass value="1" />
            <inertia ixx="100" ixy="0" ixz="0" iyy="100" iyz="0" izz="100" />
        </inertial>
        <visual>
            <origin xyz="0 0 0.6531993260356428" rpy="0 0 0"/>
            <geometry>
                <box size="2.739528444204415 1.229339637848865 1.3063986520712856" />
            </geometry>
            <material name="Green">
                <color rgba="0 180.0 0.0 1.0"/>
            </material>
        </visual>
        <collision>
            <origin xyz="0 0 0.6531993260356428" rpy="0 0 0"/>
            <geometry>
                <box size="2.739528444204415 1.229339637848865 1.3063986520712856" />
            </geometry>
        </collision>
    </link>
    <link name="Leg15">
        <inertial>
            <origin xyz="0 1.423732834883952 0" rpy="0 0 0"/>
            <mass value="1" />
            <inertia ixx="100" ixy="0" ixz="0" iyy="100" iyz="0" izz="100" />
        </inertial>
        <visual>
            <origin xyz="0 1.423732834883952 0" rpy="0 0 0"/>
            <geometry>
                <box size="2.180514399353003 2.847465669767904 1.7810587655557422" />
            </geometry>
            <material name="Blue">
                <color rgba="0 1.0 1.0 1.0"/>
            </material>
        </visual>
        <collision>
            <origin xyz="0 1.423732834883952 0" rpy="0 0 0"/>
            <geometry>
                <box size="2.180514399353003 2.847465669767904 1.7810587655557422" />
            </geometry>
        </collision>
    </link>
    <link name="Leg16">
        <inertial>
            <origin xyz="0 1.4273296908377175 0" rpy="0 0 0"/>
            <mass value="1" />
            <inertia ixx="100" ixy="0" ixz="0" iyy="100" iyz="0" izz="100" />
        </inertial>
        <visual>
            <origin xyz="0 1.4273296908377175 0" rpy="0 0 0"/>
            <geometry>
                <box size="1.7328324225748193 2.854659381675435 2.8014929603773284" />
            </geometry>
            <material name="Blue">
                <color rgba="0 1.0 1.0 1.0"/>
            </material>
        </visual>
        <collision>
            <origin xyz="0 1.4273296908377175 0" rpy="0 0 0"/>
            <geometry>
                <box size="1.7328324225748193 2.854659381675435 2.8014929603773284" />
            </geometry>
        </collision>
    </link>
    <link name="Leg17">
        <inertial>
            <origin xyz="0 0.9935836527947894 0" rpy="0 0 0"/>
            <mass value="1" />
            <inertia ixx="100" ixy="0" ixz="0" iyy="100" iyz="0" izz="100" />
        </inertial>
        <visual>
            <origin xyz="0 0.9935836527947894 0" rpy="0 0 0"/>
            <geometry>
                <box size="2.719958957522704 1.9871673055895789 2.6843808702992513" />
            </geometry>
            <material name="Green">
                <color rgba="0 180.0 0.0 1.0"/>
            </material>
        </visual>
        <collision>
            <origin xyz="0 0.9935836527947894 0" rpy="0 0 0"/>
            <geometry>
                <box size="2.719958957522704 1.9871673055895789 2.6843808702992513" />
            </geometry>
        </collision>
    </link>
    <link name="Leg18">
        <inertial>
            <origin xyz="0 0 0.629551617312338" rpy="0 0 0"/>
            <mass value="1" />
            <inertia ixx="100" ixy="0" ixz="0" iyy="100" iyz="0" izz="100" />
        </inertial>
        <visual>
            <origin xyz="0 0 0.629551617312338" rpy="0 0 0"/>
            <geometry>
                <box size="1.9636655751363459 2.600865245797972 1.259103234624676" />
            </geometry>
            <material name="Green">
                <color rgba="0 180.0 0.0 1.0"/>
            </material>
        </visual>
        <collision>
            <origin xyz="0 0 0.629551617312338" rpy="0 0 0"/>
            <geometry>
                <box size="1.9636655751363459 2.600865245797972 1.259103234624676" />
            </geometry>
        </collision>
    </link>
    <link name="Leg19">
        <inertial>
            <origin xyz="1.069605306001895 0 0" rpy="0 0 0"/>
            <mass value="1" />
            <inertia ixx="100" ixy="0" ixz="0" iyy="100" iyz="0" izz="100" />
        </inertial>
        <visual>
            <origin xyz="1.069605306001895 0 0" rpy="0 0 0"/>
            <geometry>
                <box size="2.13921061200379 2.0308015219950932 1.7270489379845775" />
            </geometry>
            <material name="Green">
                <color rgba="0 180.0 0.0 1.0"/>
            </material>
        </visual>
        <collision>
            <origin xyz="1.069605306001895 0 0" rpy="0 0 0"/>
            <geometry>
                <box size="2.13921061200379 2.0308015219950932 1.7270489379845775" />
            </geometry>
        </collision>
    </link>
    <link name="Leg20">
        <inertial>
            <origin xyz="0.862251733690463 0 0" rpy="0 0 0"/>
            <mass value="1" />
            <inertia ixx="100" ixy="0" ixz="0" iyy="100" iyz="0" izz="100" />
        </inertial>
        <visual>
            <origin xyz="0.862251733690463 0 0" rpy="0 0 0"/>
            <geometry>
                <box size="1.724503467380926 1.6291225335253487 1.6011415246171172" />
            </geometry>
            <material name="Green">
                <color rgba="0 180.0 0.0 1.0"/>
            </material>
        </visual>
        <collision>
            <origin xyz="0.862251733690463 0 0" rpy="0 0 0"/>
            <geometry>
                <box size="1.724503467380926 1.6291225335253487 1.6011415246171172" />
            </geometry>
        </collision>
    </link>
    <link name="Leg21">
        <inertial>
            <origin xyz="0.5604913726170186 0 0" rpy="0 0 0"/>
            <mass value="1" />
            <inertia ixx="100" ixy="0" ixz="0" iyy="100" iyz="0" izz="100" />
        </inertial>
        <visual>
            <origin xyz="0.5604913726170186 0 0" rpy="0 0 0"/>
            <geometry>
                <box size="1.1209827452340373 2.046949268700336 2.8843678975370874" />
            </geometry>
            <material name="Green">
                <color rgba="0 180.0 0.0 1.0"/>
            </material>
        </visual>
        <collision>
            <origin xyz="0.5604913726170186 0 0" rpy="0 0 0"/>
            <geometry>
                <box size="1.1209827452340373 2.046949268700336 2.8843678975370874" />
            </geometry>
        </collision>
    </link>
    <link name="Leg22">
        <inertial>
            <origin xyz="0.7720760061490574 0 0" rpy="0 0 0"/>
            <mass value="1" />
            <inertia ixx="100" ixy="0" ixz="0" iyy="100" iyz="0" izz="100" />
        </inertial>
        <visual>
            <origin xyz="0.7720760061490574 0 0" rpy="0 0 0"/>
            <geometry>
                <box size="1.5441520122981147 2.903148942434151 1.2853553656989616" />
            </geometry>
            <material name="Blue">
                <color rgba="0 1.0 1.0 1.0"/>
            </material>
        </visual>
        <collision>
            <origin xyz="0.7720760061490574 0 0" rpy="0 0 0"/>
            <geometry>
                <box size="1.5441520122981147 2.903148942434151 1.2853553656989616" />
            </geometry>
        </collision>
    </link>
    <link name="Leg23">
        <inertial>
            <origin xyz="0 0 0.7958729068206551" rpy="0 0 0"/>
            <mass value="1" />
            <inertia ixx="100" ixy="0" ixz="0" iyy="100" iyz="0" izz="100" />
        </inertial>
        <visual>
            <origin xyz="0 0 0.7958729068206551" rpy="0 0 0"/>
            <geometry>
                <box size="1.4324814469496767 1.4933498293012164 1.5917458136413103" />
            </geometry>
            <material name="Blue">
                <color rgba="0 1.0 1.0 1.0"/>
            </material>
        </visual>
        <collision>
            <origin xyz="0 0 0.7958729068206551" rpy="0 0 0"/>
            <geometry>
                <box size="1.4324814469496767 1.4933498293012164 1.5917458136413103" />
            </geometry>
        </collision>
    </link>
    <link name="Leg24">
        <inertial>
            <origin xyz="0 1.3412929933445232 0" rpy="0 0 0"/>
            <mass value="1" />
            <inertia ixx="100" ixy="0" ixz="0" iyy="100" iyz="0" izz="100" />
        </inertial>
        <visual>
            <origin xyz="0 1.3412929933445232 0" rpy="0 0 0"/>
            <geometry>
                <box size="1.1794897301779108 2.6825859866890465 1.9830722445246032" />
            </geometry>
            <material name="Blue">
                <color rgba="0 1.0 1.0 1.0"/>
            </material>
        </visual>
        <collision>
            <origin xyz="0 1.3412929933445232 0" rpy="0 0 0"/>
            <geometry>
                <box size="1.1794897301779108 2.6825859866890465 1.9830722445246032" />
            </geometry>
        </collision>
    </link>
    <link name="Leg25">
        <inertial>
            <origin xyz="0 1.173457698025011 0" rpy="0 0 0"/>
            <mass value="1" />
            <inertia ixx="100" ixy="0" ixz="0" iyy="100" iyz="0" izz="100" />
        </inertial>
        <visual>
            <origin xyz="0 1.173457698025011 0" rpy="0 0 0"/>
            <geometry>
                <box size="2.27414404265949 2.346915396050022 2.1426687746235835" />
            </geometry>
            <material name="Blue">
                <color rgba="0 1.0 1.0 1.0"/>
            </material>
        </visual>
        <collision>
            <origin xyz="0 1.173457698025011 0" rpy="0 0 0"/>
            <geometry>
                <box size="2.27414404265949 2.346915396050022 2.1426687746235835" />
            </geometry>
        </collision>
    </link>
    <joint name="Torso_Leg1" type="revolute">
       <parent link="Torso"/>
       <child  link="Leg1"/>
       <origin rpy="0 0 0" xyz="0.5069317993417106 0 0.7702262347041431" />
     <axis xyz="1 0 0"/>
       <limit effort="0.0" lower="-3.14159" upper="3.14159" velocity="0.0"/>
    </joint>
    <joint name="Leg1_Leg2" type="revolute">
       <parent link="Leg1"/>
       <child  link="Leg2"/>
       <origin rpy="0 0 0" xyz="0 1.7994431458616122 0" />
     <axis xyz="1 0 0"/>
       <limit effort="0.0" lower="-3.14159" upper="3.14159" velocity="0.0"/>
    </joint>
    <joint name="Leg1_Leg3" type="revolute">
       <parent link="Leg1"/>
       <child  link="Leg3"/>
       <origin rpy="0 0 0" xyz="0.8336514230421959 1.7994431458616122 0" />
     <axis xyz="1 0 0"/>
       <limit effort="0.0" lower="-3.14159" upper="3.14159" velocity="0.0"/>
    </joint>
    <joint name="Leg3_Leg4" type="revolute">
       <parent link="Leg3"/>
       <child  link="Leg4"/>
       <origin rpy="0 0 0" xyz="0 0 2.7875697129960315" />
     <axis xyz="1 0 0"/>
       <limit effort="0.0" lower="-3.14159" upper="3.14159" velocity="0.0"/>
    </joint>
    <joint name="Torso_Leg5" type="revolute">
       <parent link="Torso"/>
       <child  link="Leg5"/>
       <origin rpy="0 0 0" xyz="1.2967581206541845 1.1803532993678265 0" />
     <axis xyz="1 0 0"/>
       <limit effort="0.0" lower="-3.14159" upper="3.14159" velocity="0.0"/>
    </joint>
    <joint name="Leg2_Leg6" type="revolute">
       <parent link="Leg2"/>
       <child  link="Leg6"/>
       <origin rpy="0 0 0" xyz="1.4010861355414148 0 1.0857676935687022" />
     <axis xyz="1 0 0"/>
       <limit effort="0.0" lower="-3.14159" upper="3.14159" velocity="0.0"/>
    </joint>
    <joint name="Leg6_Leg7" type="revolute">
       <parent link="Leg6"/>
       <child  link="Leg7"/>
       <origin rpy="0 0 0" xyz="0 0 2.9720632179715674" />
     <axis xyz="1 0 0"/>
       <limit effort="0.0" lower="-3.14159" upper="3.14159" velocity="0.0"/>
    </joint>
    <joint name="Leg5_Leg8" type="revolute">
       <parent link="Leg5"/>
       <child  link="Leg8"/>
       <origin rpy="0 0 0" xyz="0 0 1.2102190019305838" />
     <axis xyz="1 0 0"/>
       <limit effort="0.0" lower="-3.14159" upper="3.14159" velocity="0.0"/>
    </joint>
    <joint name="Leg6_Leg9" type="revolute">
       <parent link="Leg6"/>
       <child  link="Leg9"/>
       <origin rpy="0 0 0" xyz="0 0.6420853199291056 2.9720632179715674" />
     <axis xyz="1 0 0"/>
       <limit effort="0.0" lower="-3.14159" upper="3.14159" velocity="0.0"/>
    </joint>
    <joint name="Leg3_Leg10" type="revolute">
       <parent link="Leg3"/>
       <child  link="Leg10"/>
       <origin rpy="0 0 0" xyz="1.4460724226903503 0 2.7875697129960315" />
     <axis xyz="1 0 0"/>
       <limit effort="0.0" lower="-3.14159" upper="3.14159" velocity="0.0"/>
    </joint>
    <joint name="Leg5_Leg11" type="revolute">
       <parent link="Leg5"/>
       <child  link="Leg11"/>
       <origin rpy="0 0 0" xyz="1.252019794913941 0 1.2102190019305838" />
     <axis xyz="1 0 0"/>
       <limit effort="0.0" lower="-3.14159" upper="3.14159" velocity="0.0"/>
    </joint>
    <joint name="Leg9_Leg12" type="revolute">
       <parent link="Leg9"/>
       <child  link="Leg12"/>
       <origin rpy="0 0 0" xyz="0.6327178586580007 0 0.6150817783529067" />
     <axis xyz="1 0 0"/>
       <limit effort="0.0" lower="-3.14159" upper="3.14159" velocity="0.0"/>
    </joint>
    <joint name="Leg7_Leg13" type="revolute">
       <parent link="Leg7"/>
       <child  link="Leg13"/>
       <origin rpy="0 0 0" xyz="0 0 2.6112990030685532" />
     <axis xyz="1 0 0"/>
       <limit effort="0.0" lower="-3.14159" upper="3.14159" velocity="0.0"/>
    </joint>
    <joint name="Leg13_Leg14" type="revolute">
       <parent link="Leg13"/>
       <child  link="Leg14"/>
       <origin rpy="0 0 0" xyz="0 0 1.3063986520712856" />
     <axis xyz="1 0 0"/>
       <limit effort="0.0" lower="-3.14159" upper="3.14159" velocity="0.0"/>
    </joint>
    <joint name="Leg5_Leg15" type="revolute">
       <parent link="Leg5"/>
       <child  link="Leg15"/>
       <origin rpy="0 0 0" xyz="1.252019794913941 1.1456941244125762 1.2102190019305838" />
     <axis xyz="1 0 0"/>
       <limit effort="0.0" lower="-3.14159" upper="3.14159" velocity="0.0"/>
    </joint>
    <joint name="Leg10_Leg16" type="revolute">
       <parent link="Leg10"/>
       <child  link="Leg16"/>
       <origin rpy="0 0 0" xyz="1.136523661037245 0.9552060502034869 0" />
     <axis xyz="1 0 0"/>
       <limit effort="0.0" lower="-3.14159" upper="3.14159" velocity="0.0"/>
    </joint>
    <joint name="Leg13_Leg17" type="revolute">
       <parent link="Leg13"/>
       <child  link="Leg17"/>
       <origin rpy="0 0 0" xyz="0 0.6146698189244325 1.3063986520712856" />
     <axis xyz="1 0 0"/>
       <limit effort="0.0" lower="-3.14159" upper="3.14159" velocity="0.0"/>
    </joint>
    <joint name="Leg12_Leg18" type="revolute">
       <parent link="Leg12"/>
       <child  link="Leg18"/>
       <origin rpy="0 0 0" xyz="0 0 2.9308190597321304" />
     <axis xyz="1 0 0"/>
       <limit effort="0.0" lower="-3.14159" upper="3.14159" velocity="0.0"/>
    </joint>
    <joint name="Leg13_Leg19" type="revolute">
       <parent link="Leg13"/>
       <child  link="Leg19"/>
       <origin rpy="0 0 0" xyz="1.3697642221022075 0.6146698189244325 1.3063986520712856" />
     <axis xyz="1 0 0"/>
       <limit effort="0.0" lower="-3.14159" upper="3.14159" velocity="0.0"/>
    </joint>
    <joint name="Leg10_Leg20" type="revolute">
       <parent link="Leg10"/>
       <child  link="Leg20"/>
       <origin rpy="0 0 0" xyz="2.27304732207449 0.9552060502034869 0" />
     <axis xyz="1 0 0"/>
       <limit effort="0.0" lower="-3.14159" upper="3.14159" velocity="0.0"/>
    </joint>
    <joint name="Leg11_Leg21" type="revolute">
       <parent link="Leg11"/>
       <child  link="Leg21"/>
       <origin rpy="0 0 0" xyz="1.3377970763909754 0 1.299970474662259" />
     <axis xyz="1 0 0"/>
       <limit effort="0.0" lower="-3.14159" upper="3.14159" velocity="0.0"/>
    </joint>
    <joint name="Leg6_Leg22" type="revolute">
       <parent link="Leg6"/>
       <child  link="Leg22"/>
       <origin rpy="0 0 0" xyz="1.4839814405051843 0.6420853199291056 2.9720632179715674" />
     <axis xyz="1 0 0"/>
       <limit effort="0.0" lower="-3.14159" upper="3.14159" velocity="0.0"/>
    </joint>
    <joint name="Leg1_Leg23" type="revolute">
       <parent link="Leg1"/>
       <child  link="Leg23"/>
       <origin rpy="0 0 0" xyz="0.8336514230421959 1.7994431458616122 0.723702787062854" />
     <axis xyz="1 0 0"/>
       <limit effort="0.0" lower="-3.14159" upper="3.14159" velocity="0.0"/>
    </joint>
    <joint name="Leg19_Leg24" type="revolute">
       <parent link="Leg19"/>
       <child  link="Leg24"/>
       <origin rpy="0 0 0" xyz="0.862251733690463 0.8145612667626744 0" />
     <axis xyz="1 0 0"/>
       <limit effort="0.0" lower="-3.14159" upper="3.14159" velocity="0.0"/>
    </joint>
    <joint name="Leg17_Leg25" type="revolute">
       <parent link="Leg17"/>
       <child  link="Leg25"/>
       <origin rpy="0 0 0" xyz="0 1.300432622898986 0.629551617312338" />
     <axis xyz="1 0 0"/>
       <limit effort="0.0" lower="-3.14159" upper="3.14159" velocity="0.0"/>
    </joint>
</robot>