<robot name = "robot">
    <link name="Torso">
        <inertial>
            <origin xyz="0 0 1.3522314065138819" rpy="0 0 0"/>
            <mass value="1" />
            <inertia ixx="100" ixy="0" ixz="0" iyy="100" iyz="0" izz="100" />
        </inertial>
        <visual>
            <origin xyz="0 0 1.3522314065138819" rpy="0 0 0"/>
            <geometry>
                <box size="2.738696861873608 1.366460253473621 2.7044628130277637" />
            </geometry>
            <material name="Green">
                <color rgba="0 180.0 0.0 1.0"/>
            </material>
        </visual>
        <collision>
            <origin xyz="0 0 1.3522314065138819" rpy="0 0 0"/>
            <geometry>
                <box size="2.738696861873608 1.366460253473621 2.7044628130277637" />
            </geometry>
        </collision>
    </link>
    <link name="Leg1">
        <inertial>
            <origin xyz="0 0 0.6836630582136493" rpy="0 0 0"/>
            <mass value="1" />
            <inertia ixx="100" ixy="0" ixz="0" iyy="100" iyz="0" izz="100" />
        </inertial>
        <visual>
            <origin xyz="0 0 0.6836630582136493" rpy="0 0 0"/>
            <geometry>
                <box size="2.9572252395683805 2.2360824326424433 1.3673261164272985" />
            </geometry>
            <material name="Green">
                <color rgba="0 180.0 0.0 1.0"/>
            </material>
        </visual>
        <collision>
            <origin xyz="0 0 0.6836630582136493" rpy="0 0 0"/>
            <geometry>
                <box size="2.9572252395683805 2.2360824326424433 1.3673261164272985" />
            </geometry>
        </collision>
    </link>
    <link name="Leg2">
        <inertial>
            <origin xyz="1.1688522189150399 0 0" rpy="0 0 0"/>
            <mass value="1" />
            <inertia ixx="100" ixy="0" ixz="0" iyy="100" iyz="0" izz="100" />
        </inertial>
        <visual>
            <origin xyz="1.1688522189150399 0 0" rpy="0 0 0"/>
            <geometry>
                <box size="2.3377044378300798 1.8295062084771407 1.7818762627241143" />
            </geometry>
            <material name="Blue">
                <color rgba="0 1.0 1.0 1.0"/>
            </material>
        </visual>
        <collision>
            <origin xyz="1.1688522189150399 0 0" rpy="0 0 0"/>
            <geometry>
                <box size="2.3377044378300798 1.8295062084771407 1.7818762627241143" />
            </geometry>
        </collision>
    </link>
    <link name="Leg3">
        <inertial>
            <origin xyz="0 1.2471613952496385 0" rpy="0 0 0"/>
            <mass value="1" />
            <inertia ixx="100" ixy="0" ixz="0" iyy="100" iyz="0" izz="100" />
        </inertial>
        <visual>
            <origin xyz="0 1.2471613952496385 0" rpy="0 0 0"/>
            <geometry>
                <box size="2.8057071563172276 2.494322790499277 1.661312308952968" />
            </geometry>
            <material name="Green">
                <color rgba="0 180.0 0.0 1.0"/>
            </material>
        </visual>
        <collision>
            <origin xyz="0 1.2471613952496385 0" rpy="0 0 0"/>
            <geometry>
                <box size="2.8057071563172276 2.494322790499277 1.661312308952968" />
            </geometry>
        </collision>
    </link>
    <link name="Leg4">
        <inertial>
            <origin xyz="0 1.3184249099492882 0" rpy="0 0 0"/>
            <mass value="1" />
            <inertia ixx="100" ixy="0" ixz="0" iyy="100" iyz="0" izz="100" />
        </inertial>
        <visual>
            <origin xyz="0 1.3184249099492882 0" rpy="0 0 0"/>
            <geometry>
                <box size="1.403280606857246 2.6368498198985764 2.323568835037655" />
            </geometry>
            <material name="Blue">
                <color rgba="0 1.0 1.0 1.0"/>
            </material>
        </visual>
        <collision>
            <origin xyz="0 1.3184249099492882 0" rpy="0 0 0"/>
            <geometry>
                <box size="1.403280606857246 2.6368498198985764 2.323568835037655" />
            </geometry>
        </collision>
    </link>
    <link name="Leg5">
        <inertial>
            <origin xyz="0 1.4889142897184584 0" rpy="0 0 0"/>
            <mass value="1" />
            <inertia ixx="100" ixy="0" ixz="0" iyy="100" iyz="0" izz="100" />
        </inertial>
        <visual>
            <origin xyz="0 1.4889142897184584 0" rpy="0 0 0"/>
            <geometry>
                <box size="1.036069995278851 2.977828579436917 1.0285813948681275" />
            </geometry>
            <material name="Blue">
                <color rgba="0 1.0 1.0 1.0"/>
            </material>
        </visual>
        <collision>
            <origin xyz="0 1.4889142897184584 0" rpy="0 0 0"/>
            <geometry>
                <box size="1.036069995278851 2.977828579436917 1.0285813948681275" />
            </geometry>
        </collision>
    </link>
    <link name="Leg6">
        <inertial>
            <origin xyz="0.7580789375215649 0 0" rpy="0 0 0"/>
            <mass value="1" />
            <inertia ixx="100" ixy="0" ixz="0" iyy="100" iyz="0" izz="100" />
        </inertial>
        <visual>
            <origin xyz="0.7580789375215649 0 0" rpy="0 0 0"/>
            <geometry>
                <box size="1.5161578750431297 1.1192511164688133 2.9150177874077885" />
            </geometry>
            <material name="Green">
                <color rgba="0 180.0 0.0 1.0"/>
            </material>
        </visual>
        <collision>
            <origin xyz="0.7580789375215649 0 0" rpy="0 0 0"/>
            <geometry>
                <box size="1.5161578750431297 1.1192511164688133 2.9150177874077885" />
            </geometry>
        </collision>
    </link>
    <link name="Leg7">
        <inertial>
            <origin xyz="0.5902211886699197 0 0" rpy="0 0 0"/>
            <mass value="1" />
            <inertia ixx="100" ixy="0" ixz="0" iyy="100" iyz="0" izz="100" />
        </inertial>
        <visual>
            <origin xyz="0.5902211886699197 0 0" rpy="0 0 0"/>
            <geometry>
                <box size="1.1804423773398394 2.553131550950255 1.4899787560252173" />
            </geometry>
            <material name="Blue">
                <color rgba="0 1.0 1.0 1.0"/>
            </material>
        </visual>
        <collision>
            <origin xyz="0.5902211886699197 0 0" rpy="0 0 0"/>
            <geometry>
                <box size="1.1804423773398394 2.553131550950255 1.4899787560252173" />
            </geometry>
        </collision>
    </link>
    <link name="Leg8">
        <inertial>
            <origin xyz="0.5036319248239525 0 0" rpy="0 0 0"/>
            <mass value="1" />
            <inertia ixx="100" ixy="0" ixz="0" iyy="100" iyz="0" izz="100" />
        </inertial>
        <visual>
            <origin xyz="0.5036319248239525 0 0" rpy="0 0 0"/>
            <geometry>
                <box size="1.007263849647905 2.3181643239935212 1.5442155296199724" />
            </geometry>
            <material name="Blue">
                <color rgba="0 1.0 1.0 1.0"/>
            </material>
        </visual>
        <collision>
            <origin xyz="0.5036319248239525 0 0" rpy="0 0 0"/>
            <geometry>
                <box size="1.007263849647905 2.3181643239935212 1.5442155296199724" />
            </geometry>
        </collision>
    </link>
    <link name="Leg9">
        <inertial>
            <origin xyz="0 0 1.2680281991562141" rpy="0 0 0"/>
            <mass value="1" />
            <inertia ixx="100" ixy="0" ixz="0" iyy="100" iyz="0" izz="100" />
        </inertial>
        <visual>
            <origin xyz="0 0 1.2680281991562141" rpy="0 0 0"/>
            <geometry>
                <box size="1.0098378287393432 2.537953137750496 2.5360563983124282" />
            </geometry>
            <material name="Green">
                <color rgba="0 180.0 0.0 1.0"/>
            </material>
        </visual>
        <collision>
            <origin xyz="0 0 1.2680281991562141" rpy="0 0 0"/>
            <geometry>
                <box size="1.0098378287393432 2.537953137750496 2.5360563983124282" />
            </geometry>
        </collision>
    </link>
    <link name="Leg10">
        <inertial>
            <origin xyz="0 0.8463354773818187 0" rpy="0 0 0"/>
            <mass value="1" />
            <inertia ixx="100" ixy="0" ixz="0" iyy="100" iyz="0" izz="100" />
        </inertial>
        <visual>
            <origin xyz="0 0.8463354773818187 0" rpy="0 0 0"/>
            <geometry>
                <box size="1.4031814807464944 1.6926709547636374 2.8054951312450425" />
            </geometry>
            <material name="Green">
                <color rgba="0 180.0 0.0 1.0"/>
            </material>
        </visual>
        <collision>
            <origin xyz="0 0.8463354773818187 0" rpy="0 0 0"/>
            <geometry>
                <box size="1.4031814807464944 1.6926709547636374 2.8054951312450425" />
            </geometry>
        </collision>
    </link>
    <link name="Leg11">
        <inertial>
            <origin xyz="0 0 1.1568900091068346" rpy="0 0 0"/>
            <mass value="1" />
            <inertia ixx="100" ixy="0" ixz="0" iyy="100" iyz="0" izz="100" />
        </inertial>
        <visual>
            <origin xyz="0 0 1.1568900091068346" rpy="0 0 0"/>
            <geometry>
                <box size="2.3105336668847434 1.5690714691413028 2.313780018213669" />
            </geometry>
            <material name="Green">
                <color rgba="0 180.0 0.0 1.0"/>
            </material>
        </visual>
        <collision>
            <origin xyz="0 0 1.1568900091068346" rpy="0 0 0"/>
            <geometry>
                <box size="2.3105336668847434 1.5690714691413028 2.313780018213669" />
            </geometry>
        </collision>
    </link>
    <link name="Leg12">
        <inertial>
            <origin xyz="0 0 0.5781492084228841" rpy="0 0 0"/>
            <mass value="1" />
            <inertia ixx="100" ixy="0" ixz="0" iyy="100" iyz="0" izz="100" />
        </inertial>
        <visual>
            <origin xyz="0 0 0.5781492084228841" rpy="0 0 0"/>
            <geometry>
                <box size="1.5929743197785722 1.7424876340478863 1.1562984168457682" />
            </geometry>
            <material name="Blue">
                <color rgba="0 1.0 1.0 1.0"/>
            </material>
        </visual>
        <collision>
            <origin xyz="0 0 0.5781492084228841" rpy="0 0 0"/>
            <geometry>
                <box size="1.5929743197785722 1.7424876340478863 1.1562984168457682" />
            </geometry>
        </collision>
    </link>
    <link name="Leg13">
        <inertial>
            <origin xyz="0 1.474473079629456 0" rpy="0 0 0"/>
            <mass value="1" />
            <inertia ixx="100" ixy="0" ixz="0" iyy="100" iyz="0" izz="100" />
        </inertial>
        <visual>
            <origin xyz="0 1.474473079629456 0" rpy="0 0 0"/>
            <geometry>
                <box size="1.5319470897476244 2.948946159258912 1.7176799229945978" />
            </geometry>
            <material name="Blue">
                <color rgba="0 1.0 1.0 1.0"/>
            </material>
        </visual>
        <collision>
            <origin xyz="0 1.474473079629456 0" rpy="0 0 0"/>
            <geometry>
                <box size="1.5319470897476244 2.948946159258912 1.7176799229945978" />
            </geometry>
        </collision>
    </link>
    <link name="Leg14">
        <inertial>
            <origin xyz="0 1.3994142470656152 0" rpy="0 0 0"/>
            <mass value="1" />
            <inertia ixx="100" ixy="0" ixz="0" iyy="100" iyz="0" izz="100" />
        </inertial>
        <visual>
            <origin xyz="0 1.3994142470656152 0" rpy="0 0 0"/>
            <geometry>
                <box size="1.196958416036021 2.7988284941312305 2.1476126713516552" />
            </geometry>
            <material name="Blue">
                <color rgba="0 1.0 1.0 1.0"/>
            </material>
        </visual>
        <collision>
            <origin xyz="0 1.3994142470656152 0" rpy="0 0 0"/>
            <geometry>
                <box size="1.196958416036021 2.7988284941312305 2.1476126713516552" />
            </geometry>
        </collision>
    </link>
    <link name="Leg15">
        <inertial>
            <origin xyz="0 0 0.9650129516766698" rpy="0 0 0"/>
            <mass value="1" />
            <inertia ixx="100" ixy="0" ixz="0" iyy="100" iyz="0" izz="100" />
        </inertial>
        <visual>
            <origin xyz="0 0 0.9650129516766698" rpy="0 0 0"/>
            <geometry>
                <box size="2.121130718194235 1.8906048368613868 1.9300259033533396" />
            </geometry>
            <material name="Green">
                <color rgba="0 180.0 0.0 1.0"/>
            </material>
        </visual>
        <collision>
            <origin xyz="0 0 0.9650129516766698" rpy="0 0 0"/>
            <geometry>
                <box size="2.121130718194235 1.8906048368613868 1.9300259033533396" />
            </geometry>
        </collision>
    </link>
    <link name="Leg16">
        <inertial>
            <origin xyz="0 0.5084070337782679 0" rpy="0 0 0"/>
            <mass value="1" />
            <inertia ixx="100" ixy="0" ixz="0" iyy="100" iyz="0" izz="100" />
        </inertial>
        <visual>
            <origin xyz="0 0.5084070337782679 0" rpy="0 0 0"/>
            <geometry>
                <box size="1.730027602947327 1.0168140675565358 2.4332569378614357" />
            </geometry>
            <material name="Blue">
                <color rgba="0 1.0 1.0 1.0"/>
            </material>
        </visual>
        <collision>
            <origin xyz="0 0.5084070337782679 0" rpy="0 0 0"/>
            <geometry>
                <box size="1.730027602947327 1.0168140675565358 2.4332569378614357" />
            </geometry>
        </collision>
    </link>
    <link name="Leg17">
        <inertial>
            <origin xyz="0 1.4121414078193815 0" rpy="0 0 0"/>
            <mass value="1" />
            <inertia ixx="100" ixy="0" ixz="0" iyy="100" iyz="0" izz="100" />
        </inertial>
        <visual>
            <origin xyz="0 1.4121414078193815 0" rpy="0 0 0"/>
            <geometry>
                <box size="1.6348980890206926 2.824282815638763 1.2782297254757924" />
            </geometry>
            <material name="Blue">
                <color rgba="0 1.0 1.0 1.0"/>
            </material>
        </visual>
        <collision>
            <origin xyz="0 1.4121414078193815 0" rpy="0 0 0"/>
            <geometry>
                <box size="1.6348980890206926 2.824282815638763 1.2782297254757924" />
            </geometry>
        </collision>
    </link>
    <link name="Leg18">
        <inertial>
            <origin xyz="0 0 0.7864009979016773" rpy="0 0 0"/>
            <mass value="1" />
            <inertia ixx="100" ixy="0" ixz="0" iyy="100" iyz="0" izz="100" />
        </inertial>
        <visual>
            <origin xyz="0 0 0.7864009979016773" rpy="0 0 0"/>
            <geometry>
                <box size="1.3613871273220899 1.1001415655302023 1.5728019958033546" />
            </geometry>
            <material name="Green">
                <color rgba="0 180.0 0.0 1.0"/>
            </material>
        </visual>
        <collision>
            <origin xyz="0 0 0.7864009979016773" rpy="0 0 0"/>
            <geometry>
                <box size="1.3613871273220899 1.1001415655302023 1.5728019958033546" />
            </geometry>
        </collision>
    </link>
    <link name="Leg19">
        <inertial>
            <origin xyz="0 0 1.3111319618752186" rpy="0 0 0"/>
            <mass value="1" />
            <inertia ixx="100" ixy="0" ixz="0" iyy="100" iyz="0" izz="100" />
        </inertial>
        <visual>
            <origin xyz="0 0 1.3111319618752186" rpy="0 0 0"/>
            <geometry>
                <box size="2.9385021542388428 1.5662018330023 2.6222639237504373" />
            </geometry>
            <material name="Green">
                <color rgba="0 180.0 0.0 1.0"/>
            </material>
        </visual>
        <collision>
            <origin xyz="0 0 1.3111319618752186" rpy="0 0 0"/>
            <geometry>
                <box size="2.9385021542388428 1.5662018330023 2.6222639237504373" />
            </geometry>
        </collision>
    </link>
    <link name="Leg20">
        <inertial>
            <origin xyz="0 0.9800601121368141 0" rpy="0 0 0"/>
            <mass value="1" />
            <inertia ixx="100" ixy="0" ixz="0" iyy="100" iyz="0" izz="100" />
        </inertial>
        <visual>
            <origin xyz="0 0.9800601121368141 0" rpy="0 0 0"/>
            <geometry>
                <box size="2.3357503544125837 1.9601202242736282 1.8213524892075532" />
            </geometry>
            <material name="Green">
                <color rgba="0 180.0 0.0 1.0"/>
            </material>
        </visual>
        <collision>
            <origin xyz="0 0.9800601121368141 0" rpy="0 0 0"/>
            <geometry>
                <box size="2.3357503544125837 1.9601202242736282 1.8213524892075532" />
            </geometry>
        </collision>
    </link>
    <link name="Leg21">
        <inertial>
            <origin xyz="0 0 1.4045942275444199" rpy="0 0 0"/>
            <mass value="1" />
            <inertia ixx="100" ixy="0" ixz="0" iyy="100" iyz="0" izz="100" />
        </inertial>
        <visual>
            <origin xyz="0 0 1.4045942275444199" rpy="0 0 0"/>
            <geometry>
                <box size="2.3428615794385674 1.9620074953487885 2.8091884550888397" />
            </geometry>
            <material name="Blue">
                <color rgba="0 1.0 1.0 1.0"/>
            </material>
        </visual>
        <collision>
            <origin xyz="0 0 1.4045942275444199" rpy="0 0 0"/>
            <geometry>
                <box size="2.3428615794385674 1.9620074953487885 2.8091884550888397" />
            </geometry>
        </collision>
    </link>
    <link name="Leg22">
        <inertial>
            <origin xyz="1.1076256190813583 0 0" rpy="0 0 0"/>
            <mass value="1" />
            <inertia ixx="100" ixy="0" ixz="0" iyy="100" iyz="0" izz="100" />
        </inertial>
        <visual>
            <origin xyz="1.1076256190813583 0 0" rpy="0 0 0"/>
            <geometry>
                <box size="2.2152512381627165 2.8834861811891197 2.141025893931487" />
            </geometry>
            <material name="Blue">
                <color rgba="0 1.0 1.0 1.0"/>
            </material>
        </visual>
        <collision>
            <origin xyz="1.1076256190813583 0 0" rpy="0 0 0"/>
            <geometry>
                <box size="2.2152512381627165 2.8834861811891197 2.141025893931487" />
            </geometry>
        </collision>
    </link>
    <link name="Leg23">
        <inertial>
            <origin xyz="0 0 1.2033709413349678" rpy="0 0 0"/>
            <mass value="1" />
            <inertia ixx="100" ixy="0" ixz="0" iyy="100" iyz="0" izz="100" />
        </inertial>
        <visual>
            <origin xyz="0 0 1.2033709413349678" rpy="0 0 0"/>
            <geometry>
                <box size="2.5462115932496188 1.2166291193302186 2.4067418826699356" />
            </geometry>
            <material name="Green">
                <color rgba="0 180.0 0.0 1.0"/>
            </material>
        </visual>
        <collision>
            <origin xyz="0 0 1.2033709413349678" rpy="0 0 0"/>
            <geometry>
                <box size="2.5462115932496188 1.2166291193302186 2.4067418826699356" />
            </geometry>
        </collision>
    </link>
    <link name="Leg24">
        <inertial>
            <origin xyz="0 0 1.1940239292320451" rpy="0 0 0"/>
            <mass value="1" />
            <inertia ixx="100" ixy="0" ixz="0" iyy="100" iyz="0" izz="100" />
        </inertial>
        <visual>
            <origin xyz="0 0 1.1940239292320451" rpy="0 0 0"/>
            <geometry>
                <box size="1.9187275379219118 1.711405788667291 2.3880478584640903" />
            </geometry>
            <material name="Green">
                <color rgba="0 180.0 0.0 1.0"/>
            </material>
        </visual>
        <collision>
            <origin xyz="0 0 1.1940239292320451" rpy="0 0 0"/>
            <geometry>
                <box size="1.9187275379219118 1.711405788667291 2.3880478584640903" />
            </geometry>
        </collision>
    </link>
    <link name="Leg25">
        <inertial>
            <origin xyz="1.4003692932713971 0 0" rpy="0 0 0"/>
            <mass value="1" />
            <inertia ixx="100" ixy="0" ixz="0" iyy="100" iyz="0" izz="100" />
        </inertial>
        <visual>
            <origin xyz="1.4003692932713971 0 0" rpy="0 0 0"/>
            <geometry>
                <box size="2.8007385865427943 1.9163051373024196 1.3996595993516188" />
            </geometry>
            <material name="Green">
                <color rgba="0 180.0 0.0 1.0"/>
            </material>
        </visual>
        <collision>
            <origin xyz="1.4003692932713971 0 0" rpy="0 0 0"/>
            <geometry>
                <box size="2.8007385865427943 1.9163051373024196 1.3996595993516188" />
            </geometry>
        </collision>
    </link>
    <link name="Leg26">
        <inertial>
            <origin xyz="0 0.6835817563162072 0" rpy="0 0 0"/>
            <mass value="1" />
            <inertia ixx="100" ixy="0" ixz="0" iyy="100" iyz="0" izz="100" />
        </inertial>
        <visual>
            <origin xyz="0 0.6835817563162072 0" rpy="0 0 0"/>
            <geometry>
                <box size="1.0337621747709724 1.3671635126324144 1.1419847712105713" />
            </geometry>
            <material name="Blue">
                <color rgba="0 1.0 1.0 1.0"/>
            </material>
        </visual>
        <collision>
            <origin xyz="0 0.6835817563162072 0" rpy="0 0 0"/>
            <geometry>
                <box size="1.0337621747709724 1.3671635126324144 1.1419847712105713" />
            </geometry>
        </collision>
    </link>
    <link name="Leg27">
        <inertial>
            <origin xyz="0 0 0.5620288828551301" rpy="0 0 0"/>
            <mass value="1" />
            <inertia ixx="100" ixy="0" ixz="0" iyy="100" iyz="0" izz="100" />
        </inertial>
        <visual>
            <origin xyz="0 0 0.5620288828551301" rpy="0 0 0"/>
            <geometry>
                <box size="2.1540235535247865 2.9733295666726454 1.1240577657102602" />
            </geometry>
            <material name="Blue">
                <color rgba="0 1.0 1.0 1.0"/>
            </material>
        </visual>
        <collision>
            <origin xyz="0 0 0.5620288828551301" rpy="0 0 0"/>
            <geometry>
                <box size="2.1540235535247865 2.9733295666726454 1.1240577657102602" />
            </geometry>
        </collision>
    </link>
    <link name="Leg28">
        <inertial>
            <origin xyz="0.8505303473785699 0 0" rpy="0 0 0"/>
            <mass value="1" />
            <inertia ixx="100" ixy="0" ixz="0" iyy="100" iyz="0" izz="100" />
        </inertial>
        <visual>
            <origin xyz="0.8505303473785699 0 0" rpy="0 0 0"/>
            <geometry>
                <box size="1.7010606947571398 2.75840483596338 1.1719921064798893" />
            </geometry>
            <material name="Green">
                <color rgba="0 180.0 0.0 1.0"/>
            </material>
        </visual>
        <collision>
            <origin xyz="0.8505303473785699 0 0" rpy="0 0 0"/>
            <geometry>
                <box size="1.7010606947571398 2.75840483596338 1.1719921064798893" />
            </geometry>
        </collision>
    </link>
    <joint name="Torso_Leg1" type="revolute">
       <parent link="Torso"/>
       <child  link="Leg1"/>
       <origin rpy="0 0 0" xyz="0 0 2.7044628130277637" />
     <axis xyz="1 0 0"/>
       <limit effort="0.0" lower="-3.14159" upper="3.14159" velocity="0.0"/>
    </joint>
    <joint name="Leg1_Leg2" type="revolute">
       <parent link="Leg1"/>
       <child  link="Leg2"/>
       <origin rpy="0 0 0" xyz="2.3377044378300798 0 0" />
     <axis xyz="1 0 0"/>
       <limit effort="0.0" lower="-3.14159" upper="3.14159" velocity="0.0"/>
    </joint>
    <joint name="Leg1_Leg3" type="revolute">
       <parent link="Leg1"/>
       <child  link="Leg3"/>
       <origin rpy="0 0 0" xyz="2.3377044378300798 0.9147531042385704 0" />
     <axis xyz="1 0 0"/>
       <limit effort="0.0" lower="-3.14159" upper="3.14159" velocity="0.0"/>
    </joint>
    <joint name="Torso_Leg4" type="revolute">
       <parent link="Torso"/>
       <child  link="Leg4"/>
       <origin rpy="0 0 0" xyz="0 1.1180412163212217 0.6836630582136493" />
     <axis xyz="1 0 0"/>
       <limit effort="0.0" lower="-3.14159" upper="3.14159" velocity="0.0"/>
    </joint>
    <joint name="Leg3_Leg5" type="revolute">
       <parent link="Leg3"/>
       <child  link="Leg5"/>
       <origin rpy="0 0 0" xyz="0 2.6368498198985764 0" />
     <axis xyz="1 0 0"/>
       <limit effort="0.0" lower="-3.14159" upper="3.14159" velocity="0.0"/>
    </joint>
    <joint name="Leg3_Leg6" type="revolute">
       <parent link="Leg3"/>
       <child  link="Leg6"/>
       <origin rpy="0 0 0" xyz="0.701640303428623 2.6368498198985764 0" />
     <axis xyz="1 0 0"/>
       <limit effort="0.0" lower="-3.14159" upper="3.14159" velocity="0.0"/>
    </joint>
    <joint name="Leg6_Leg7" type="revolute">
       <parent link="Leg6"/>
       <child  link="Leg7"/>
       <origin rpy="0 0 0" xyz="1.1804423773398394 0 0" />
     <axis xyz="1 0 0"/>
       <limit effort="0.0" lower="-3.14159" upper="3.14159" velocity="0.0"/>
    </joint>
    <joint name="Leg2_Leg8" type="revolute">
       <parent link="Leg2"/>
       <child  link="Leg8"/>
       <origin rpy="0 0 0" xyz="1.4028535781586138 1.2471613952496385 0" />
     <axis xyz="1 0 0"/>
       <limit effort="0.0" lower="-3.14159" upper="3.14159" velocity="0.0"/>
    </joint>
    <joint name="Leg5_Leg9" type="revolute">
       <parent link="Leg5"/>
       <child  link="Leg9"/>
       <origin rpy="0 0 0" xyz="0.7580789375215649 0 1.4575088937038942" />
     <axis xyz="1 0 0"/>
       <limit effort="0.0" lower="-3.14159" upper="3.14159" velocity="0.0"/>
    </joint>
    <joint name="Leg7_Leg10" type="revolute">
       <parent link="Leg7"/>
       <child  link="Leg10"/>
       <origin rpy="0 0 0" xyz="0.5036319248239525 1.1590821619967606 0" />
     <axis xyz="1 0 0"/>
       <limit effort="0.0" lower="-3.14159" upper="3.14159" velocity="0.0"/>
    </joint>
    <joint name="Leg9_Leg11" type="revolute">
       <parent link="Leg9"/>
       <child  link="Leg11"/>
       <origin rpy="0 0 0" xyz="0 0.8463354773818187 1.4027475656225212" />
     <axis xyz="1 0 0"/>
       <limit effort="0.0" lower="-3.14159" upper="3.14159" velocity="0.0"/>
    </joint>
    <joint name="Leg1_Leg12" type="revolute">
       <parent link="Leg1"/>
       <child  link="Leg12"/>
       <origin rpy="0 0 0" xyz="2.3377044378300798 0.9147531042385704 0.8909381313620571" />
     <axis xyz="1 0 0"/>
       <limit effort="0.0" lower="-3.14159" upper="3.14159" velocity="0.0"/>
    </joint>
    <joint name="Leg6_Leg13" type="revolute">
       <parent link="Leg6"/>
       <child  link="Leg13"/>
       <origin rpy="0 0 0" xyz="1.1804423773398394 1.2765657754751274 0" />
     <axis xyz="1 0 0"/>
       <limit effort="0.0" lower="-3.14159" upper="3.14159" velocity="0.0"/>
    </joint>
    <joint name="Leg11_Leg14" type="revolute">
       <parent link="Leg11"/>
       <child  link="Leg14"/>
       <origin rpy="0 0 0" xyz="0 0.8712438170239432 0.5781492084228841" />
     <axis xyz="1 0 0"/>
       <limit effort="0.0" lower="-3.14159" upper="3.14159" velocity="0.0"/>
    </joint>
    <joint name="Leg2_Leg15" type="revolute">
       <parent link="Leg2"/>
       <child  link="Leg15"/>
       <origin rpy="0 0 0" xyz="1.4028535781586138 1.2471613952496385 0.830656154476484" />
     <axis xyz="1 0 0"/>
       <limit effort="0.0" lower="-3.14159" upper="3.14159" velocity="0.0"/>
    </joint>
    <joint name="Leg4_Leg16" type="revolute">
       <parent link="Leg4"/>
       <child  link="Leg16"/>
       <origin rpy="0 0 0" xyz="0 2.977828579436917 0" />
     <axis xyz="1 0 0"/>
       <limit effort="0.0" lower="-3.14159" upper="3.14159" velocity="0.0"/>
    </joint>
    <joint name="Leg12_Leg17" type="revolute">
       <parent link="Leg12"/>
       <child  link="Leg17"/>
       <origin rpy="0 0 0" xyz="0 2.948946159258912 0" />
     <axis xyz="1 0 0"/>
       <limit effort="0.0" lower="-3.14159" upper="3.14159" velocity="0.0"/>
    </joint>
    <joint name="Leg14_Leg18" type="revolute">
       <parent link="Leg14"/>
       <child  link="Leg18"/>
       <origin rpy="0 0 0" xyz="0 0 1.9300259033533396" />
     <axis xyz="1 0 0"/>
       <limit effort="0.0" lower="-3.14159" upper="3.14159" velocity="0.0"/>
    </joint>
    <joint name="Leg12_Leg19" type="revolute">
       <parent link="Leg12"/>
       <child  link="Leg19"/>
       <origin rpy="0 0 0" xyz="0 2.948946159258912 0.8588399614972989" />
     <axis xyz="1 0 0"/>
       <limit effort="0.0" lower="-3.14159" upper="3.14159" velocity="0.0"/>
    </joint>
    <joint name="Leg16_Leg20" type="revolute">
       <parent link="Leg16"/>
       <child  link="Leg20"/>
       <origin rpy="0 0 0" xyz="0 2.824282815638763 0" />
     <axis xyz="1 0 0"/>
       <limit effort="0.0" lower="-3.14159" upper="3.14159" velocity="0.0"/>
    </joint>
    <joint name="Leg17_Leg21" type="revolute">
       <parent link="Leg17"/>
       <child  link="Leg21"/>
       <origin rpy="0 0 0" xyz="0 0 1.5728019958033546" />
     <axis xyz="1 0 0"/>
       <limit effort="0.0" lower="-3.14159" upper="3.14159" velocity="0.0"/>
    </joint>
    <joint name="Leg8_Leg22" type="revolute">
       <parent link="Leg8"/>
       <child  link="Leg22"/>
       <origin rpy="0 0 0" xyz="0.5049189143696716 0 1.2680281991562141" />
     <axis xyz="1 0 0"/>
       <limit effort="0.0" lower="-3.14159" upper="3.14159" velocity="0.0"/>
    </joint>
    <joint name="Leg10_Leg23" type="revolute">
       <parent link="Leg10"/>
       <child  link="Leg23"/>
       <origin rpy="0 0 0" xyz="0 0 2.313780018213669" />
     <axis xyz="1 0 0"/>
       <limit effort="0.0" lower="-3.14159" upper="3.14159" velocity="0.0"/>
    </joint>
    <joint name="Leg13_Leg24" type="revolute">
       <parent link="Leg13"/>
       <child  link="Leg24"/>
       <origin rpy="0 0 0" xyz="0 1.3994142470656152 1.0738063356758276" />
     <axis xyz="1 0 0"/>
       <limit effort="0.0" lower="-3.14159" upper="3.14159" velocity="0.0"/>
    </joint>
    <joint name="Leg5_Leg25" type="revolute">
       <parent link="Leg5"/>
       <child  link="Leg25"/>
       <origin rpy="0 0 0" xyz="1.5161578750431297 0 1.4575088937038942" />
     <axis xyz="1 0 0"/>
       <limit effort="0.0" lower="-3.14159" upper="3.14159" velocity="0.0"/>
    </joint>
    <joint name="Leg2_Leg26" type="revolute">
       <parent link="Leg2"/>
       <child  link="Leg26"/>
       <origin rpy="0 0 0" xyz="1.4028535781586138 2.494322790499277 0.830656154476484" />
     <axis xyz="1 0 0"/>
       <limit effort="0.0" lower="-3.14159" upper="3.14159" velocity="0.0"/>
    </joint>
    <joint name="Leg6_Leg27" type="revolute">
       <parent link="Leg6"/>
       <child  link="Leg27"/>
       <origin rpy="0 0 0" xyz="1.1804423773398394 1.2765657754751274 0.7449893780126087" />
     <axis xyz="1 0 0"/>
       <limit effort="0.0" lower="-3.14159" upper="3.14159" velocity="0.0"/>
    </joint>
    <joint name="Leg7_Leg28" type="revolute">
       <parent link="Leg7"/>
       <child  link="Leg28"/>
       <origin rpy="0 0 0" xyz="1.007263849647905 1.1590821619967606 0" />
     <axis xyz="1 0 0"/>
       <limit effort="0.0" lower="-3.14159" upper="3.14159" velocity="0.0"/>
    </joint>
</robot>