<robot name = "robot">
    <link name="Torso">
        <inertial>
            <origin xyz="0 0 0.9302522921799341" rpy="0 0 0"/>
            <mass value="1" />
            <inertia ixx="100" ixy="0" ixz="0" iyy="100" iyz="0" izz="100" />
        </inertial>
        <visual>
            <origin xyz="0 0 0.9302522921799341" rpy="0 0 0"/>
            <geometry>
                <box size="1.5674461705500735 2.378633960367792 1.8605045843598682" />
            </geometry>
            <material name="Green">
                <color rgba="0 180.0 0.0 1.0"/>
            </material>
        </visual>
        <collision>
            <origin xyz="0 0 0.9302522921799341" rpy="0 0 0"/>
            <geometry>
                <box size="1.5674461705500735 2.378633960367792 1.8605045843598682" />
            </geometry>
        </collision>
    </link>
    <link name="Leg1">
        <inertial>
            <origin xyz="0.7987636784939236 0 0" rpy="0 0 0"/>
            <mass value="1" />
            <inertia ixx="100" ixy="0" ixz="0" iyy="100" iyz="0" izz="100" />
        </inertial>
        <visual>
            <origin xyz="0.7987636784939236 0 0" rpy="0 0 0"/>
            <geometry>
                <box size="1.5975273569878472 2.586725152136894 1.4210788167369923" />
            </geometry>
            <material name="Blue">
                <color rgba="0 1.0 1.0 1.0"/>
            </material>
        </visual>
        <collision>
            <origin xyz="0.7987636784939236 0 0" rpy="0 0 0"/>
            <geometry>
                <box size="1.5975273569878472 2.586725152136894 1.4210788167369923" />
            </geometry>
        </collision>
    </link>
    <link name="Leg2">
        <inertial>
            <origin xyz="0.9066870381982811 0 0" rpy="0 0 0"/>
            <mass value="1" />
            <inertia ixx="100" ixy="0" ixz="0" iyy="100" iyz="0" izz="100" />
        </inertial>
        <visual>
            <origin xyz="0.9066870381982811 0 0" rpy="0 0 0"/>
            <geometry>
                <box size="1.8133740763965622 1.1682684570490327 2.8912152786911234" />
            </geometry>
            <material name="Green">
                <color rgba="0 180.0 0.0 1.0"/>
            </material>
        </visual>
        <collision>
            <origin xyz="0.9066870381982811 0 0" rpy="0 0 0"/>
            <geometry>
                <box size="1.8133740763965622 1.1682684570490327 2.8912152786911234" />
            </geometry>
        </collision>
    </link>
    <link name="Leg3">
        <inertial>
            <origin xyz="0 0.5900869873604607 0" rpy="0 0 0"/>
            <mass value="1" />
            <inertia ixx="100" ixy="0" ixz="0" iyy="100" iyz="0" izz="100" />
        </inertial>
        <visual>
            <origin xyz="0 0.5900869873604607 0" rpy="0 0 0"/>
            <geometry>
                <box size="2.137903269658408 1.1801739747209214 1.46857359577023" />
            </geometry>
            <material name="Blue">
                <color rgba="0 1.0 1.0 1.0"/>
            </material>
        </visual>
        <collision>
            <origin xyz="0 0.5900869873604607 0" rpy="0 0 0"/>
            <geometry>
                <box size="2.137903269658408 1.1801739747209214 1.46857359577023" />
            </geometry>
        </collision>
    </link>
    <link name="Leg4">
        <inertial>
            <origin xyz="1.3154957477984488 0 0" rpy="0 0 0"/>
            <mass value="1" />
            <inertia ixx="100" ixy="0" ixz="0" iyy="100" iyz="0" izz="100" />
        </inertial>
        <visual>
            <origin xyz="1.3154957477984488 0 0" rpy="0 0 0"/>
            <geometry>
                <box size="2.6309914955968976 2.7670139919277026 1.3911457500925044" />
            </geometry>
            <material name="Blue">
                <color rgba="0 1.0 1.0 1.0"/>
            </material>
        </visual>
        <collision>
            <origin xyz="1.3154957477984488 0 0" rpy="0 0 0"/>
            <geometry>
                <box size="2.6309914955968976 2.7670139919277026 1.3911457500925044" />
            </geometry>
        </collision>
    </link>
    <link name="Leg5">
        <inertial>
            <origin xyz="0 0 1.448322706283286" rpy="0 0 0"/>
            <mass value="1" />
            <inertia ixx="100" ixy="0" ixz="0" iyy="100" iyz="0" izz="100" />
        </inertial>
        <visual>
            <origin xyz="0 0 1.448322706283286" rpy="0 0 0"/>
            <geometry>
                <box size="1.2479664206866405 2.1167348391995633 2.896645412566572" />
            </geometry>
            <material name="Green">
                <color rgba="0 180.0 0.0 1.0"/>
            </material>
        </visual>
        <collision>
            <origin xyz="0 0 1.448322706283286" rpy="0 0 0"/>
            <geometry>
                <box size="1.2479664206866405 2.1167348391995633 2.896645412566572" />
            </geometry>
        </collision>
    </link>
    <link name="Leg6">
        <inertial>
            <origin xyz="0.630302197500625 0 0" rpy="0 0 0"/>
            <mass value="1" />
            <inertia ixx="100" ixy="0" ixz="0" iyy="100" iyz="0" izz="100" />
        </inertial>
        <visual>
            <origin xyz="0.630302197500625 0 0" rpy="0 0 0"/>
            <geometry>
                <box size="1.26060439500125 2.98219363149681 1.7858771501970738" />
            </geometry>
            <material name="Blue">
                <color rgba="0 1.0 1.0 1.0"/>
            </material>
        </visual>
        <collision>
            <origin xyz="0.630302197500625 0 0" rpy="0 0 0"/>
            <geometry>
                <box size="1.26060439500125 2.98219363149681 1.7858771501970738" />
            </geometry>
        </collision>
    </link>
    <link name="Leg7">
        <inertial>
            <origin xyz="0 0 0.8022189345477231" rpy="0 0 0"/>
            <mass value="1" />
            <inertia ixx="100" ixy="0" ixz="0" iyy="100" iyz="0" izz="100" />
        </inertial>
        <visual>
            <origin xyz="0 0 0.8022189345477231" rpy="0 0 0"/>
            <geometry>
                <box size="1.4097531325975785 1.371250682144778 1.6044378690954462" />
            </geometry>
            <material name="Blue">
                <color rgba="0 1.0 1.0 1.0"/>
            </material>
        </visual>
        <collision>
            <origin xyz="0 0 0.8022189345477231" rpy="0 0 0"/>
            <geometry>
                <box size="1.4097531325975785 1.371250682144778 1.6044378690954462" />
            </geometry>
        </collision>
    </link>
    <link name="Leg8">
        <inertial>
            <origin xyz="0 0 1.4948873207518862" rpy="0 0 0"/>
            <mass value="1" />
            <inertia ixx="100" ixy="0" ixz="0" iyy="100" iyz="0" izz="100" />
        </inertial>
        <visual>
            <origin xyz="0 0 1.4948873207518862" rpy="0 0 0"/>
            <geometry>
                <box size="1.5492703327731956 1.207323777445766 2.9897746415037725" />
            </geometry>
            <material name="Green">
                <color rgba="0 180.0 0.0 1.0"/>
            </material>
        </visual>
        <collision>
            <origin xyz="0 0 1.4948873207518862" rpy="0 0 0"/>
            <geometry>
                <box size="1.5492703327731956 1.207323777445766 2.9897746415037725" />
            </geometry>
        </collision>
    </link>
    <link name="Leg9">
        <inertial>
            <origin xyz="0 0 0.567779691369576" rpy="0 0 0"/>
            <mass value="1" />
            <inertia ixx="100" ixy="0" ixz="0" iyy="100" iyz="0" izz="100" />
        </inertial>
        <visual>
            <origin xyz="0 0 0.567779691369576" rpy="0 0 0"/>
            <geometry>
                <box size="1.7275630270809919 2.7746387759705184 1.135559382739152" />
            </geometry>
            <material name="Blue">
                <color rgba="0 1.0 1.0 1.0"/>
            </material>
        </visual>
        <collision>
            <origin xyz="0 0 0.567779691369576" rpy="0 0 0"/>
            <geometry>
                <box size="1.7275630270809919 2.7746387759705184 1.135559382739152" />
            </geometry>
        </collision>
    </link>
    <link name="Leg10">
        <inertial>
            <origin xyz="0.9733472220207402 0 0" rpy="0 0 0"/>
            <mass value="1" />
            <inertia ixx="100" ixy="0" ixz="0" iyy="100" iyz="0" izz="100" />
        </inertial>
        <visual>
            <origin xyz="0.9733472220207402 0 0" rpy="0 0 0"/>
            <geometry>
                <box size="1.9466944440414804 1.6739517485930382 1.102204413945341" />
            </geometry>
            <material name="Blue">
                <color rgba="0 1.0 1.0 1.0"/>
            </material>
        </visual>
        <collision>
            <origin xyz="0.9733472220207402 0 0" rpy="0 0 0"/>
            <geometry>
                <box size="1.9466944440414804 1.6739517485930382 1.102204413945341" />
            </geometry>
        </collision>
    </link>
    <link name="Leg11">
        <inertial>
            <origin xyz="0.671569794149947 0 0" rpy="0 0 0"/>
            <mass value="1" />
            <inertia ixx="100" ixy="0" ixz="0" iyy="100" iyz="0" izz="100" />
        </inertial>
        <visual>
            <origin xyz="0.671569794149947 0 0" rpy="0 0 0"/>
            <geometry>
                <box size="1.343139588299894 2.871555876594036 1.4624911731536319" />
            </geometry>
            <material name="Blue">
                <color rgba="0 1.0 1.0 1.0"/>
            </material>
        </visual>
        <collision>
            <origin xyz="0.671569794149947 0 0" rpy="0 0 0"/>
            <geometry>
                <box size="1.343139588299894 2.871555876594036 1.4624911731536319" />
            </geometry>
        </collision>
    </link>
    <link name="Leg12">
        <inertial>
            <origin xyz="0 1.2007238986650246 0" rpy="0 0 0"/>
            <mass value="1" />
            <inertia ixx="100" ixy="0" ixz="0" iyy="100" iyz="0" izz="100" />
        </inertial>
        <visual>
            <origin xyz="0 1.2007238986650246 0" rpy="0 0 0"/>
            <geometry>
                <box size="2.9437286310030855 2.401447797330049 1.3623198807123322" />
            </geometry>
            <material name="Blue">
                <color rgba="0 1.0 1.0 1.0"/>
            </material>
        </visual>
        <collision>
            <origin xyz="0 1.2007238986650246 0" rpy="0 0 0"/>
            <geometry>
                <box size="2.9437286310030855 2.401447797330049 1.3623198807123322" />
            </geometry>
        </collision>
    </link>
    <link name="Leg13">
        <inertial>
            <origin xyz="0.6842467326528245 0 0" rpy="0 0 0"/>
            <mass value="1" />
            <inertia ixx="100" ixy="0" ixz="0" iyy="100" iyz="0" izz="100" />
        </inertial>
        <visual>
            <origin xyz="0.6842467326528245 0 0" rpy="0 0 0"/>
            <geometry>
                <box size="1.368493465305649 2.306101912627124 1.3510924713417136" />
            </geometry>
            <material name="Blue">
                <color rgba="0 1.0 1.0 1.0"/>
            </material>
        </visual>
        <collision>
            <origin xyz="0.6842467326528245 0 0" rpy="0 0 0"/>
            <geometry>
                <box size="1.368493465305649 2.306101912627124 1.3510924713417136" />
            </geometry>
        </collision>
    </link>
    <link name="Leg14">
        <inertial>
            <origin xyz="0 1.4993256472864505 0" rpy="0 0 0"/>
            <mass value="1" />
            <inertia ixx="100" ixy="0" ixz="0" iyy="100" iyz="0" izz="100" />
        </inertial>
        <visual>
            <origin xyz="0 1.4993256472864505 0" rpy="0 0 0"/>
            <geometry>
                <box size="1.1765149017580054 2.998651294572901 2.2460313278027337" />
            </geometry>
            <material name="Blue">
                <color rgba="0 1.0 1.0 1.0"/>
            </material>
        </visual>
        <collision>
            <origin xyz="0 1.4993256472864505 0" rpy="0 0 0"/>
            <geometry>
                <box size="1.1765149017580054 2.998651294572901 2.2460313278027337" />
            </geometry>
        </collision>
    </link>
    <link name="Leg15">
        <inertial>
            <origin xyz="0 0 1.0450638057153507" rpy="0 0 0"/>
            <mass value="1" />
            <inertia ixx="100" ixy="0" ixz="0" iyy="100" iyz="0" izz="100" />
        </inertial>
        <visual>
            <origin xyz="0 0 1.0450638057153507" rpy="0 0 0"/>
            <geometry>
                <box size="2.9300190168174205 1.770615541225909 2.0901276114307015" />
            </geometry>
            <material name="Blue">
                <color rgba="0 1.0 1.0 1.0"/>
            </material>
        </visual>
        <collision>
            <origin xyz="0 0 1.0450638057153507" rpy="0 0 0"/>
            <geometry>
                <box size="2.9300190168174205 1.770615541225909 2.0901276114307015" />
            </geometry>
        </collision>
    </link>
    <link name="Leg16">
        <inertial>
            <origin xyz="0 0 1.0737302378940052" rpy="0 0 0"/>
            <mass value="1" />
            <inertia ixx="100" ixy="0" ixz="0" iyy="100" iyz="0" izz="100" />
        </inertial>
        <visual>
            <origin xyz="0 0 1.0737302378940052" rpy="0 0 0"/>
            <geometry>
                <box size="1.6587201838600456 1.6721156968234578 2.1474604757880105" />
            </geometry>
            <material name="Green">
                <color rgba="0 180.0 0.0 1.0"/>
            </material>
        </visual>
        <collision>
            <origin xyz="0 0 1.0737302378940052" rpy="0 0 0"/>
            <geometry>
                <box size="1.6587201838600456 1.6721156968234578 2.1474604757880105" />
            </geometry>
        </collision>
    </link>
    <link name="Leg17">
        <inertial>
            <origin xyz="0 0 0.6640290373072445" rpy="0 0 0"/>
            <mass value="1" />
            <inertia ixx="100" ixy="0" ixz="0" iyy="100" iyz="0" izz="100" />
        </inertial>
        <visual>
            <origin xyz="0 0 0.6640290373072445" rpy="0 0 0"/>
            <geometry>
                <box size="1.0262785790845836 2.2773276975884684 1.328058074614489" />
            </geometry>
            <material name="Blue">
                <color rgba="0 1.0 1.0 1.0"/>
            </material>
        </visual>
        <collision>
            <origin xyz="0 0 0.6640290373072445" rpy="0 0 0"/>
            <geometry>
                <box size="1.0262785790845836 2.2773276975884684 1.328058074614489" />
            </geometry>
        </collision>
    </link>
    <link name="Leg18">
        <inertial>
            <origin xyz="0 0 0.8480039102080105" rpy="0 0 0"/>
            <mass value="1" />
            <inertia ixx="100" ixy="0" ixz="0" iyy="100" iyz="0" izz="100" />
        </inertial>
        <visual>
            <origin xyz="0 0 0.8480039102080105" rpy="0 0 0"/>
            <geometry>
                <box size="2.8898412353320753 1.5941903171016658 1.696007820416021" />
            </geometry>
            <material name="Green">
                <color rgba="0 180.0 0.0 1.0"/>
            </material>
        </visual>
        <collision>
            <origin xyz="0 0 0.8480039102080105" rpy="0 0 0"/>
            <geometry>
                <box size="2.8898412353320753 1.5941903171016658 1.696007820416021" />
            </geometry>
        </collision>
    </link>
    <link name="Leg19">
        <inertial>
            <origin xyz="0 0 0.8223282789324243" rpy="0 0 0"/>
            <mass value="1" />
            <inertia ixx="100" ixy="0" ixz="0" iyy="100" iyz="0" izz="100" />
        </inertial>
        <visual>
            <origin xyz="0 0 0.8223282789324243" rpy="0 0 0"/>
            <geometry>
                <box size="1.6146175352154366 2.3936644976559256 1.6446565578648487" />
            </geometry>
            <material name="Blue">
                <color rgba="0 1.0 1.0 1.0"/>
            </material>
        </visual>
        <collision>
            <origin xyz="0 0 0.8223282789324243" rpy="0 0 0"/>
            <geometry>
                <box size="1.6146175352154366 2.3936644976559256 1.6446565578648487" />
            </geometry>
        </collision>
    </link>
    <link name="Leg20">
        <inertial>
            <origin xyz="0 0 0.7291817121337615" rpy="0 0 0"/>
            <mass value="1" />
            <inertia ixx="100" ixy="0" ixz="0" iyy="100" iyz="0" izz="100" />
        </inertial>
        <visual>
            <origin xyz="0 0 0.7291817121337615" rpy="0 0 0"/>
            <geometry>
                <box size="2.2962718616440876 1.6683470237509845 1.458363424267523" />
            </geometry>
            <material name="Blue">
                <color rgba="0 1.0 1.0 1.0"/>
            </material>
        </visual>
        <collision>
            <origin xyz="0 0 0.7291817121337615" rpy="0 0 0"/>
            <geometry>
                <box size="2.2962718616440876 1.6683470237509845 1.458363424267523" />
            </geometry>
        </collision>
    </link>
    <link name="Leg21">
        <inertial>
            <origin xyz="0 0 0.8945578501767832" rpy="0 0 0"/>
            <mass value="1" />
            <inertia ixx="100" ixy="0" ixz="0" iyy="100" iyz="0" izz="100" />
        </inertial>
        <visual>
            <origin xyz="0 0 0.8945578501767832" rpy="0 0 0"/>
            <geometry>
                <box size="2.9271732186171064 2.0527542798627287 1.7891157003535665" />
            </geometry>
            <material name="Green">
                <color rgba="0 180.0 0.0 1.0"/>
            </material>
        </visual>
        <collision>
            <origin xyz="0 0 0.8945578501767832" rpy="0 0 0"/>
            <geometry>
                <box size="2.9271732186171064 2.0527542798627287 1.7891157003535665" />
            </geometry>
        </collision>
    </link>
    <link name="Leg22">
        <inertial>
            <origin xyz="0 0.7693273068113665 0" rpy="0 0 0"/>
            <mass value="1" />
            <inertia ixx="100" ixy="0" ixz="0" iyy="100" iyz="0" izz="100" />
        </inertial>
        <visual>
            <origin xyz="0 0.7693273068113665 0" rpy="0 0 0"/>
            <geometry>
                <box size="1.545316351125177 1.538654613622733 2.91714894373441" />
            </geometry>
            <material name="Blue">
                <color rgba="0 1.0 1.0 1.0"/>
            </material>
        </visual>
        <collision>
            <origin xyz="0 0.7693273068113665 0" rpy="0 0 0"/>
            <geometry>
                <box size="1.545316351125177 1.538654613622733 2.91714894373441" />
            </geometry>
        </collision>
    </link>
    <link name="Leg23">
        <inertial>
            <origin xyz="0.6940332568857978 0 0" rpy="0 0 0"/>
            <mass value="1" />
            <inertia ixx="100" ixy="0" ixz="0" iyy="100" iyz="0" izz="100" />
        </inertial>
        <visual>
            <origin xyz="0.6940332568857978 0 0" rpy="0 0 0"/>
            <geometry>
                <box size="1.3880665137715955 1.6967440950794443 2.3698130351837463" />
            </geometry>
            <material name="Green">
                <color rgba="0 180.0 0.0 1.0"/>
            </material>
        </visual>
        <collision>
            <origin xyz="0.6940332568857978 0 0" rpy="0 0 0"/>
            <geometry>
                <box size="1.3880665137715955 1.6967440950794443 2.3698130351837463" />
            </geometry>
        </collision>
    </link>
    <link name="Leg24">
        <inertial>
            <origin xyz="0 0 0.9221991883538936" rpy="0 0 0"/>
            <mass value="1" />
            <inertia ixx="100" ixy="0" ixz="0" iyy="100" iyz="0" izz="100" />
        </inertial>
        <visual>
            <origin xyz="0 0 0.9221991883538936" rpy="0 0 0"/>
            <geometry>
                <box size="2.440603750833879 1.4506801200070534 1.8443983767077872" />
            </geometry>
            <material name="Blue">
                <color rgba="0 1.0 1.0 1.0"/>
            </material>
        </visual>
        <collision>
            <origin xyz="0 0 0.9221991883538936" rpy="0 0 0"/>
            <geometry>
                <box size="2.440603750833879 1.4506801200070534 1.8443983767077872" />
            </geometry>
        </collision>
    </link>
    <link name="Leg25">
        <inertial>
            <origin xyz="1.0003638264365882 0 0" rpy="0 0 0"/>
            <mass value="1" />
            <inertia ixx="100" ixy="0" ixz="0" iyy="100" iyz="0" izz="100" />
        </inertial>
        <visual>
            <origin xyz="1.0003638264365882 0 0" rpy="0 0 0"/>
            <geometry>
                <box size="2.0007276528731763 1.8012161652395868 1.9278449733063692" />
            </geometry>
            <material name="Green">
                <color rgba="0 180.0 0.0 1.0"/>
            </material>
        </visual>
        <collision>
            <origin xyz="1.0003638264365882 0 0" rpy="0 0 0"/>
            <geometry>
                <box size="2.0007276528731763 1.8012161652395868 1.9278449733063692" />
            </geometry>
        </collision>
    </link>
    <link name="Leg26">
        <inertial>
            <origin xyz="0 1.2244833399221582 0" rpy="0 0 0"/>
            <mass value="1" />
            <inertia ixx="100" ixy="0" ixz="0" iyy="100" iyz="0" izz="100" />
        </inertial>
        <visual>
            <origin xyz="0 1.2244833399221582 0" rpy="0 0 0"/>
            <geometry>
                <box size="2.449960390935944 2.4489666798443164 2.616722786266955" />
            </geometry>
            <material name="Blue">
                <color rgba="0 1.0 1.0 1.0"/>
            </material>
        </visual>
        <collision>
            <origin xyz="0 1.2244833399221582 0" rpy="0 0 0"/>
            <geometry>
                <box size="2.449960390935944 2.4489666798443164 2.616722786266955" />
            </geometry>
        </collision>
    </link>
    <joint name="Torso_Leg1" type="revolute">
       <parent link="Torso"/>
       <child  link="Leg1"/>
       <origin rpy="0 0 0" xyz="0.7837230852750368 0 0.9302522921799341" />
     <axis xyz="1 0 0"/>
       <limit effort="0.0" lower="-3.14159" upper="3.14159" velocity="0.0"/>
    </joint>
    <joint name="Leg1_Leg2" type="revolute">
       <parent link="Leg1"/>
       <child  link="Leg2"/>
       <origin rpy="0 0 0" xyz="1.8133740763965622 0 0" />
     <axis xyz="1 0 0"/>
       <limit effort="0.0" lower="-3.14159" upper="3.14159" velocity="0.0"/>
    </joint>
    <joint name="Leg1_Leg3" type="revolute">
       <parent link="Leg1"/>
       <child  link="Leg3"/>
       <origin rpy="0 0 0" xyz="1.8133740763965622 0.5841342285245164 0" />
     <axis xyz="1 0 0"/>
       <limit effort="0.0" lower="-3.14159" upper="3.14159" velocity="0.0"/>
    </joint>
    <joint name="Leg2_Leg4" type="revolute">
       <parent link="Leg2"/>
       <child  link="Leg4"/>
       <origin rpy="0 0 0" xyz="1.068951634829204 0.5900869873604607 0" />
     <axis xyz="1 0 0"/>
       <limit effort="0.0" lower="-3.14159" upper="3.14159" velocity="0.0"/>
    </joint>
    <joint name="Leg2_Leg5" type="revolute">
       <parent link="Leg2"/>
       <child  link="Leg5"/>
       <origin rpy="0 0 0" xyz="1.068951634829204 0.5900869873604607 0.734286797885115" />
     <axis xyz="1 0 0"/>
       <limit effort="0.0" lower="-3.14159" upper="3.14159" velocity="0.0"/>
    </joint>
    <joint name="Leg3_Leg6" type="revolute">
       <parent link="Leg3"/>
       <child  link="Leg6"/>
       <origin rpy="0 0 0" xyz="2.6309914955968976 0 0" />
     <axis xyz="1 0 0"/>
       <limit effort="0.0" lower="-3.14159" upper="3.14159" velocity="0.0"/>
    </joint>
    <joint name="Leg3_Leg7" type="revolute">
       <parent link="Leg3"/>
       <child  link="Leg7"/>
       <origin rpy="0 0 0" xyz="2.6309914955968976 0 0.6955728750462522" />
     <axis xyz="1 0 0"/>
       <limit effort="0.0" lower="-3.14159" upper="3.14159" velocity="0.0"/>
    </joint>
    <joint name="Leg1_Leg8" type="revolute">
       <parent link="Leg1"/>
       <child  link="Leg8"/>
       <origin rpy="0 0 0" xyz="1.8133740763965622 0.5841342285245164 1.4456076393455617" />
     <axis xyz="1 0 0"/>
       <limit effort="0.0" lower="-3.14159" upper="3.14159" velocity="0.0"/>
    </joint>
    <joint name="Torso_Leg9" type="revolute">
       <parent link="Torso"/>
       <child  link="Leg9"/>
       <origin rpy="0 0 0" xyz="0.7987636784939236 0 0.7105394083684962" />
     <axis xyz="1 0 0"/>
       <limit effort="0.0" lower="-3.14159" upper="3.14159" velocity="0.0"/>
    </joint>
    <joint name="Leg5_Leg10" type="revolute">
       <parent link="Leg5"/>
       <child  link="Leg10"/>
       <origin rpy="0 0 0" xyz="1.26060439500125 0 0" />
     <axis xyz="1 0 0"/>
       <limit effort="0.0" lower="-3.14159" upper="3.14159" velocity="0.0"/>
    </joint>
    <joint name="Leg7_Leg11" type="revolute">
       <parent link="Leg7"/>
       <child  link="Leg11"/>
       <origin rpy="0 0 0" xyz="0.7746351663865978 0 1.4948873207518862" />
     <axis xyz="1 0 0"/>
       <limit effort="0.0" lower="-3.14159" upper="3.14159" velocity="0.0"/>
    </joint>
    <joint name="Leg2_Leg12" type="revolute">
       <parent link="Leg2"/>
       <child  link="Leg12"/>
       <origin rpy="0 0 0" xyz="1.068951634829204 1.1801739747209214 0.734286797885115" />
     <axis xyz="1 0 0"/>
       <limit effort="0.0" lower="-3.14159" upper="3.14159" velocity="0.0"/>
    </joint>
    <joint name="Leg10_Leg13" type="revolute">
       <parent link="Leg10"/>
       <child  link="Leg13"/>
       <origin rpy="0 0 0" xyz="1.343139588299894 0 0" />
     <axis xyz="1 0 0"/>
       <limit effort="0.0" lower="-3.14159" upper="3.14159" velocity="0.0"/>
    </joint>
    <joint name="Torso_Leg14" type="revolute">
       <parent link="Torso"/>
       <child  link="Leg14"/>
       <origin rpy="0 0 0" xyz="0.7987636784939236 1.293362576068447 0.7105394083684962" />
     <axis xyz="1 0 0"/>
       <limit effort="0.0" lower="-3.14159" upper="3.14159" velocity="0.0"/>
    </joint>
    <joint name="Leg12_Leg15" type="revolute">
       <parent link="Leg12"/>
       <child  link="Leg15"/>
       <origin rpy="0 0 0" xyz="0.6842467326528245 0 0.6755462356708568" />
     <axis xyz="1 0 0"/>
       <limit effort="0.0" lower="-3.14159" upper="3.14159" velocity="0.0"/>
    </joint>
    <joint name="Leg10_Leg16" type="revolute">
       <parent link="Leg10"/>
       <child  link="Leg16"/>
       <origin rpy="0 0 0" xyz="1.343139588299894 0 0.7312455865768159" />
     <axis xyz="1 0 0"/>
       <limit effort="0.0" lower="-3.14159" upper="3.14159" velocity="0.0"/>
    </joint>
    <joint name="Leg4_Leg17" type="revolute">
       <parent link="Leg4"/>
       <child  link="Leg17"/>
       <origin rpy="0 0 0" xyz="0 0 2.896645412566572" />
     <axis xyz="1 0 0"/>
       <limit effort="0.0" lower="-3.14159" upper="3.14159" velocity="0.0"/>
    </joint>
    <joint name="Leg5_Leg18" type="revolute">
       <parent link="Leg5"/>
       <child  link="Leg18"/>
       <origin rpy="0 0 0" xyz="1.26060439500125 0 0.8929385750985369" />
     <axis xyz="1 0 0"/>
       <limit effort="0.0" lower="-3.14159" upper="3.14159" velocity="0.0"/>
    </joint>
    <joint name="Leg6_Leg19" type="revolute">
       <parent link="Leg6"/>
       <child  link="Leg19"/>
       <origin rpy="0 0 0" xyz="0 0 1.6044378690954462" />
     <axis xyz="1 0 0"/>
       <limit effort="0.0" lower="-3.14159" upper="3.14159" velocity="0.0"/>
    </joint>
    <joint name="Leg13_Leg20" type="revolute">
       <parent link="Leg13"/>
       <child  link="Leg20"/>
       <origin rpy="0 0 0" xyz="0 1.4993256472864505 1.1230156639013669" />
     <axis xyz="1 0 0"/>
       <limit effort="0.0" lower="-3.14159" upper="3.14159" velocity="0.0"/>
    </joint>
    <joint name="Leg20_Leg21" type="revolute">
       <parent link="Leg20"/>
       <child  link="Leg21"/>
       <origin rpy="0 0 0" xyz="0 0 1.7891157003535665" />
     <axis xyz="1 0 0"/>
       <limit effort="0.0" lower="-3.14159" upper="3.14159" velocity="0.0"/>
    </joint>
    <joint name="Leg6_Leg22" type="revolute">
       <parent link="Leg6"/>
       <child  link="Leg22"/>
       <origin rpy="0 0 0" xyz="0 0.685625341072389 1.6044378690954462" />
     <axis xyz="1 0 0"/>
       <limit effort="0.0" lower="-3.14159" upper="3.14159" velocity="0.0"/>
    </joint>
    <joint name="Leg8_Leg23" type="revolute">
       <parent link="Leg8"/>
       <child  link="Leg23"/>
       <origin rpy="0 0 0" xyz="0.8637815135404959 0 0.567779691369576" />
     <axis xyz="1 0 0"/>
       <limit effort="0.0" lower="-3.14159" upper="3.14159" velocity="0.0"/>
    </joint>
    <joint name="Leg19_Leg24" type="revolute">
       <parent link="Leg19"/>
       <child  link="Leg24"/>
       <origin rpy="0 0 0" xyz="0 0 1.458363424267523" />
     <axis xyz="1 0 0"/>
       <limit effort="0.0" lower="-3.14159" upper="3.14159" velocity="0.0"/>
    </joint>
    <joint name="Leg16_Leg25" type="revolute">
       <parent link="Leg16"/>
       <child  link="Leg25"/>
       <origin rpy="0 0 0" xyz="0.5131392895422918 0 0.6640290373072445" />
     <axis xyz="1 0 0"/>
       <limit effort="0.0" lower="-3.14159" upper="3.14159" velocity="0.0"/>
    </joint>
    <joint name="Leg14_Leg26" type="revolute">
       <parent link="Leg14"/>
       <child  link="Leg26"/>
       <origin rpy="0 0 0" xyz="0 0.8853077706129545 1.0450638057153507" />
     <axis xyz="1 0 0"/>
       <limit effort="0.0" lower="-3.14159" upper="3.14159" velocity="0.0"/>
    </joint>
</robot>