<robot name = "robot">
    <link name="Torso">
        <inertial>
            <origin xyz="0 0 1.4613544811092287" rpy="0 0 0"/>
            <mass value="1" />
            <inertia ixx="100" ixy="0" ixz="0" iyy="100" iyz="0" izz="100" />
        </inertial>
        <visual>
            <origin xyz="0 0 1.4613544811092287" rpy="0 0 0"/>
            <geometry>
                <box size="2.978305140148932 2.344617511304123 2.9227089622184574" />
            </geometry>
            <material name="Green">
                <color rgba="0 180.0 0.0 1.0"/>
            </material>
        </visual>
        <collision>
            <origin xyz="0 0 1.4613544811092287" rpy="0 0 0"/>
            <geometry>
                <box size="2.978305140148932 2.344617511304123 2.9227089622184574" />
            </geometry>
        </collision>
    </link>
    <link name="Leg1">
        <inertial>
            <origin xyz="0 0.8692433116222 0" rpy="0 0 0"/>
            <mass value="1" />
            <inertia ixx="100" ixy="0" ixz="0" iyy="100" iyz="0" izz="100" />
        </inertial>
        <visual>
            <origin xyz="0 0.8692433116222 0" rpy="0 0 0"/>
            <geometry>
                <box size="2.594860947783679 1.7384866232444 1.4822192642522118" />
            </geometry>
            <material name="Blue">
                <color rgba="0 1.0 1.0 1.0"/>
            </material>
        </visual>
        <collision>
            <origin xyz="0 0.8692433116222 0" rpy="0 0 0"/>
            <geometry>
                <box size="2.594860947783679 1.7384866232444 1.4822192642522118" />
            </geometry>
        </collision>
    </link>
    <link name="Leg2">
        <inertial>
            <origin xyz="0 0.8239446846422642 0" rpy="0 0 0"/>
            <mass value="1" />
            <inertia ixx="100" ixy="0" ixz="0" iyy="100" iyz="0" izz="100" />
        </inertial>
        <visual>
            <origin xyz="0 0.8239446846422642 0" rpy="0 0 0"/>
            <geometry>
                <box size="2.8226106406151192 1.6478893692845284 1.1430150982470078" />
            </geometry>
            <material name="Blue">
                <color rgba="0 1.0 1.0 1.0"/>
            </material>
        </visual>
        <collision>
            <origin xyz="0 0.8239446846422642 0" rpy="0 0 0"/>
            <geometry>
                <box size="2.8226106406151192 1.6478893692845284 1.1430150982470078" />
            </geometry>
        </collision>
    </link>
    <link name="Leg3">
        <inertial>
            <origin xyz="0 0.9594203388044058 0" rpy="0 0 0"/>
            <mass value="1" />
            <inertia ixx="100" ixy="0" ixz="0" iyy="100" iyz="0" izz="100" />
        </inertial>
        <visual>
            <origin xyz="0 0.9594203388044058 0" rpy="0 0 0"/>
            <geometry>
                <box size="1.7043191923375731 1.9188406776088116 1.0582154963030963" />
            </geometry>
            <material name="Green">
                <color rgba="0 180.0 0.0 1.0"/>
            </material>
        </visual>
        <collision>
            <origin xyz="0 0.9594203388044058 0" rpy="0 0 0"/>
            <geometry>
                <box size="1.7043191923375731 1.9188406776088116 1.0582154963030963" />
            </geometry>
        </collision>
    </link>
    <link name="Leg4">
        <inertial>
            <origin xyz="0 0 0.6355953312545548" rpy="0 0 0"/>
            <mass value="1" />
            <inertia ixx="100" ixy="0" ixz="0" iyy="100" iyz="0" izz="100" />
        </inertial>
        <visual>
            <origin xyz="0 0 0.6355953312545548" rpy="0 0 0"/>
            <geometry>
                <box size="2.8094207710079493 1.8976352380155697 1.2711906625091096" />
            </geometry>
            <material name="Green">
                <color rgba="0 180.0 0.0 1.0"/>
            </material>
        </visual>
        <collision>
            <origin xyz="0 0 0.6355953312545548" rpy="0 0 0"/>
            <geometry>
                <box size="2.8094207710079493 1.8976352380155697 1.2711906625091096" />
            </geometry>
        </collision>
    </link>
    <link name="Leg5">
        <inertial>
            <origin xyz="0 1.2024623226849553 0" rpy="0 0 0"/>
            <mass value="1" />
            <inertia ixx="100" ixy="0" ixz="0" iyy="100" iyz="0" izz="100" />
        </inertial>
        <visual>
            <origin xyz="0 1.2024623226849553 0" rpy="0 0 0"/>
            <geometry>
                <box size="1.835752078035049 2.4049246453699107 2.4319498202047987" />
            </geometry>
            <material name="Blue">
                <color rgba="0 1.0 1.0 1.0"/>
            </material>
        </visual>
        <collision>
            <origin xyz="0 1.2024623226849553 0" rpy="0 0 0"/>
            <geometry>
                <box size="1.835752078035049 2.4049246453699107 2.4319498202047987" />
            </geometry>
        </collision>
    </link>
    <link name="Leg6">
        <inertial>
            <origin xyz="0 0.5156680469017029 0" rpy="0 0 0"/>
            <mass value="1" />
            <inertia ixx="100" ixy="0" ixz="0" iyy="100" iyz="0" izz="100" />
        </inertial>
        <visual>
            <origin xyz="0 0.5156680469017029 0" rpy="0 0 0"/>
            <geometry>
                <box size="1.9026253151386563 1.0313360938034057 2.375773608275802" />
            </geometry>
            <material name="Blue">
                <color rgba="0 1.0 1.0 1.0"/>
            </material>
        </visual>
        <collision>
            <origin xyz="0 0.5156680469017029 0" rpy="0 0 0"/>
            <geometry>
                <box size="1.9026253151386563 1.0313360938034057 2.375773608275802" />
            </geometry>
        </collision>
    </link>
    <link name="Leg7">
        <inertial>
            <origin xyz="0 0 0.6053132004027514" rpy="0 0 0"/>
            <mass value="1" />
            <inertia ixx="100" ixy="0" ixz="0" iyy="100" iyz="0" izz="100" />
        </inertial>
        <visual>
            <origin xyz="0 0 0.6053132004027514" rpy="0 0 0"/>
            <geometry>
                <box size="1.0144564063631099 1.8850889347406707 1.2106264008055028" />
            </geometry>
            <material name="Green">
                <color rgba="0 180.0 0.0 1.0"/>
            </material>
        </visual>
        <collision>
            <origin xyz="0 0 0.6053132004027514" rpy="0 0 0"/>
            <geometry>
                <box size="1.0144564063631099 1.8850889347406707 1.2106264008055028" />
            </geometry>
        </collision>
    </link>
    <link name="Leg8">
        <inertial>
            <origin xyz="0 0 0.612295245195915" rpy="0 0 0"/>
            <mass value="1" />
            <inertia ixx="100" ixy="0" ixz="0" iyy="100" iyz="0" izz="100" />
        </inertial>
        <visual>
            <origin xyz="0 0 0.612295245195915" rpy="0 0 0"/>
            <geometry>
                <box size="1.6191929422602989 2.9788683104154443 1.22459049039183" />
            </geometry>
            <material name="Green">
                <color rgba="0 180.0 0.0 1.0"/>
            </material>
        </visual>
        <collision>
            <origin xyz="0 0 0.612295245195915" rpy="0 0 0"/>
            <geometry>
                <box size="1.6191929422602989 2.9788683104154443 1.22459049039183" />
            </geometry>
        </collision>
    </link>
    <link name="Leg9">
        <inertial>
            <origin xyz="0 0.8954556722359825 0" rpy="0 0 0"/>
            <mass value="1" />
            <inertia ixx="100" ixy="0" ixz="0" iyy="100" iyz="0" izz="100" />
        </inertial>
        <visual>
            <origin xyz="0 0.8954556722359825 0" rpy="0 0 0"/>
            <geometry>
                <box size="2.323727811895875 1.790911344471965 1.0366851314555527" />
            </geometry>
            <material name="Green">
                <color rgba="0 180.0 0.0 1.0"/>
            </material>
        </visual>
        <collision>
            <origin xyz="0 0.8954556722359825 0" rpy="0 0 0"/>
            <geometry>
                <box size="2.323727811895875 1.790911344471965 1.0366851314555527" />
            </geometry>
        </collision>
    </link>
    <link name="Leg10">
        <inertial>
            <origin xyz="0.9577776235872134 0 0" rpy="0 0 0"/>
            <mass value="1" />
            <inertia ixx="100" ixy="0" ixz="0" iyy="100" iyz="0" izz="100" />
        </inertial>
        <visual>
            <origin xyz="0.9577776235872134 0 0" rpy="0 0 0"/>
            <geometry>
                <box size="1.9155552471744268 2.6248385542006254 2.326394618801202" />
            </geometry>
            <material name="Green">
                <color rgba="0 180.0 0.0 1.0"/>
            </material>
        </visual>
        <collision>
            <origin xyz="0.9577776235872134 0 0" rpy="0 0 0"/>
            <geometry>
                <box size="1.9155552471744268 2.6248385542006254 2.326394618801202" />
            </geometry>
        </collision>
    </link>
    <link name="Leg11">
        <inertial>
            <origin xyz="0 0.6202374113325327 0" rpy="0 0 0"/>
            <mass value="1" />
            <inertia ixx="100" ixy="0" ixz="0" iyy="100" iyz="0" izz="100" />
        </inertial>
        <visual>
            <origin xyz="0 0.6202374113325327 0" rpy="0 0 0"/>
            <geometry>
                <box size="2.313883716913291 1.2404748226650655 2.438528236348029" />
            </geometry>
            <material name="Blue">
                <color rgba="0 1.0 1.0 1.0"/>
            </material>
        </visual>
        <collision>
            <origin xyz="0 0.6202374113325327 0" rpy="0 0 0"/>
            <geometry>
                <box size="2.313883716913291 1.2404748226650655 2.438528236348029" />
            </geometry>
        </collision>
    </link>
    <link name="Leg12">
        <inertial>
            <origin xyz="0 1.3088247780400535 0" rpy="0 0 0"/>
            <mass value="1" />
            <inertia ixx="100" ixy="0" ixz="0" iyy="100" iyz="0" izz="100" />
        </inertial>
        <visual>
            <origin xyz="0 1.3088247780400535 0" rpy="0 0 0"/>
            <geometry>
                <box size="2.0807330662467525 2.617649556080107 2.9087868375485777" />
            </geometry>
            <material name="Blue">
                <color rgba="0 1.0 1.0 1.0"/>
            </material>
        </visual>
        <collision>
            <origin xyz="0 1.3088247780400535 0" rpy="0 0 0"/>
            <geometry>
                <box size="2.0807330662467525 2.617649556080107 2.9087868375485777" />
            </geometry>
        </collision>
    </link>
    <link name="Leg13">
        <inertial>
            <origin xyz="0 0 0.8050850506376267" rpy="0 0 0"/>
            <mass value="1" />
            <inertia ixx="100" ixy="0" ixz="0" iyy="100" iyz="0" izz="100" />
        </inertial>
        <visual>
            <origin xyz="0 0 0.8050850506376267" rpy="0 0 0"/>
            <geometry>
                <box size="1.5513345270306995 2.2278194111609233 1.6101701012752534" />
            </geometry>
            <material name="Green">
                <color rgba="0 180.0 0.0 1.0"/>
            </material>
        </visual>
        <collision>
            <origin xyz="0 0 0.8050850506376267" rpy="0 0 0"/>
            <geometry>
                <box size="1.5513345270306995 2.2278194111609233 1.6101701012752534" />
            </geometry>
        </collision>
    </link>
    <link name="Leg14">
        <inertial>
            <origin xyz="0 0.5691973405546439 0" rpy="0 0 0"/>
            <mass value="1" />
            <inertia ixx="100" ixy="0" ixz="0" iyy="100" iyz="0" izz="100" />
        </inertial>
        <visual>
            <origin xyz="0 0.5691973405546439 0" rpy="0 0 0"/>
            <geometry>
                <box size="2.5240615540711167 1.1383946811092878 1.9435417361259235" />
            </geometry>
            <material name="Blue">
                <color rgba="0 1.0 1.0 1.0"/>
            </material>
        </visual>
        <collision>
            <origin xyz="0 0.5691973405546439 0" rpy="0 0 0"/>
            <geometry>
                <box size="2.5240615540711167 1.1383946811092878 1.9435417361259235" />
            </geometry>
        </collision>
    </link>
    <link name="Leg15">
        <inertial>
            <origin xyz="0 0.6459473271285684 0" rpy="0 0 0"/>
            <mass value="1" />
            <inertia ixx="100" ixy="0" ixz="0" iyy="100" iyz="0" izz="100" />
        </inertial>
        <visual>
            <origin xyz="0 0.6459473271285684 0" rpy="0 0 0"/>
            <geometry>
                <box size="1.43450985852363 1.2918946542571368 1.193343881571927" />
            </geometry>
            <material name="Green">
                <color rgba="0 180.0 0.0 1.0"/>
            </material>
        </visual>
        <collision>
            <origin xyz="0 0.6459473271285684 0" rpy="0 0 0"/>
            <geometry>
                <box size="1.43450985852363 1.2918946542571368 1.193343881571927" />
            </geometry>
        </collision>
    </link>
    <link name="Leg16">
        <inertial>
            <origin xyz="0.6743378084181235 0 0" rpy="0 0 0"/>
            <mass value="1" />
            <inertia ixx="100" ixy="0" ixz="0" iyy="100" iyz="0" izz="100" />
        </inertial>
        <visual>
            <origin xyz="0.6743378084181235 0 0" rpy="0 0 0"/>
            <geometry>
                <box size="1.348675616836247 2.9959003964190645 1.7468801558536577" />
            </geometry>
            <material name="Green">
                <color rgba="0 180.0 0.0 1.0"/>
            </material>
        </visual>
        <collision>
            <origin xyz="0.6743378084181235 0 0" rpy="0 0 0"/>
            <geometry>
                <box size="1.348675616836247 2.9959003964190645 1.7468801558536577" />
            </geometry>
        </collision>
    </link>
    <link name="Leg17">
        <inertial>
            <origin xyz="0.8071878489797066 0 0" rpy="0 0 0"/>
            <mass value="1" />
            <inertia ixx="100" ixy="0" ixz="0" iyy="100" iyz="0" izz="100" />
        </inertial>
        <visual>
            <origin xyz="0.8071878489797066 0 0" rpy="0 0 0"/>
            <geometry>
                <box size="1.6143756979594133 2.8846971344577725 2.3344334919552674" />
            </geometry>
            <material name="Blue">
                <color rgba="0 1.0 1.0 1.0"/>
            </material>
        </visual>
        <collision>
            <origin xyz="0.8071878489797066 0 0" rpy="0 0 0"/>
            <geometry>
                <box size="1.6143756979594133 2.8846971344577725 2.3344334919552674" />
            </geometry>
        </collision>
    </link>
    <link name="Leg18">
        <inertial>
            <origin xyz="1.4170369706359782 0 0" rpy="0 0 0"/>
            <mass value="1" />
            <inertia ixx="100" ixy="0" ixz="0" iyy="100" iyz="0" izz="100" />
        </inertial>
        <visual>
            <origin xyz="1.4170369706359782 0 0" rpy="0 0 0"/>
            <geometry>
                <box size="2.8340739412719564 1.4791210388821472 1.5819931534988296" />
            </geometry>
            <material name="Green">
                <color rgba="0 180.0 0.0 1.0"/>
            </material>
        </visual>
        <collision>
            <origin xyz="1.4170369706359782 0 0" rpy="0 0 0"/>
            <geometry>
                <box size="2.8340739412719564 1.4791210388821472 1.5819931534988296" />
            </geometry>
        </collision>
    </link>
    <link name="Leg19">
        <inertial>
            <origin xyz="0 0 1.1514027811080072" rpy="0 0 0"/>
            <mass value="1" />
            <inertia ixx="100" ixy="0" ixz="0" iyy="100" iyz="0" izz="100" />
        </inertial>
        <visual>
            <origin xyz="0 0 1.1514027811080072" rpy="0 0 0"/>
            <geometry>
                <box size="2.6119592604804813 2.258342449909824 2.3028055622160144" />
            </geometry>
            <material name="Blue">
                <color rgba="0 1.0 1.0 1.0"/>
            </material>
        </visual>
        <collision>
            <origin xyz="0 0 1.1514027811080072" rpy="0 0 0"/>
            <geometry>
                <box size="2.6119592604804813 2.258342449909824 2.3028055622160144" />
            </geometry>
        </collision>
    </link>
    <link name="Leg20">
        <inertial>
            <origin xyz="0 0.8729223205558436 0" rpy="0 0 0"/>
            <mass value="1" />
            <inertia ixx="100" ixy="0" ixz="0" iyy="100" iyz="0" izz="100" />
        </inertial>
        <visual>
            <origin xyz="0 0.8729223205558436 0" rpy="0 0 0"/>
            <geometry>
                <box size="2.7752233046820187 1.7458446411116872 1.0478285975363149" />
            </geometry>
            <material name="Blue">
                <color rgba="0 1.0 1.0 1.0"/>
            </material>
        </visual>
        <collision>
            <origin xyz="0 0.8729223205558436 0" rpy="0 0 0"/>
            <geometry>
                <box size="2.7752233046820187 1.7458446411116872 1.0478285975363149" />
            </geometry>
        </collision>
    </link>
    <link name="Leg21">
        <inertial>
            <origin xyz="0 0 1.326175786011256" rpy="0 0 0"/>
            <mass value="1" />
            <inertia ixx="100" ixy="0" ixz="0" iyy="100" iyz="0" izz="100" />
        </inertial>
        <visual>
            <origin xyz="0 0 1.326175786011256" rpy="0 0 0"/>
            <geometry>
                <box size="1.0082809590092876 2.540401136572976 2.652351572022512" />
            </geometry>
            <material name="Green">
                <color rgba="0 180.0 0.0 1.0"/>
            </material>
        </visual>
        <collision>
            <origin xyz="0 0 1.326175786011256" rpy="0 0 0"/>
            <geometry>
                <box size="1.0082809590092876 2.540401136572976 2.652351572022512" />
            </geometry>
        </collision>
    </link>
    <link name="Leg22">
        <inertial>
            <origin xyz="1.4841412541942045 0 0" rpy="0 0 0"/>
            <mass value="1" />
            <inertia ixx="100" ixy="0" ixz="0" iyy="100" iyz="0" izz="100" />
        </inertial>
        <visual>
            <origin xyz="1.4841412541942045 0 0" rpy="0 0 0"/>
            <geometry>
                <box size="2.968282508388409 1.4058119124172184 1.9274266944343934" />
            </geometry>
            <material name="Blue">
                <color rgba="0 1.0 1.0 1.0"/>
            </material>
        </visual>
        <collision>
            <origin xyz="1.4841412541942045 0 0" rpy="0 0 0"/>
            <geometry>
                <box size="2.968282508388409 1.4058119124172184 1.9274266944343934" />
            </geometry>
        </collision>
    </link>
    <link name="Leg23">
        <inertial>
            <origin xyz="0 0 0.7760879573760257" rpy="0 0 0"/>
            <mass value="1" />
            <inertia ixx="100" ixy="0" ixz="0" iyy="100" iyz="0" izz="100" />
        </inertial>
        <visual>
            <origin xyz="0 0 0.7760879573760257" rpy="0 0 0"/>
            <geometry>
                <box size="2.6243426188596373 2.352571902064319 1.5521759147520513" />
            </geometry>
            <material name="Green">
                <color rgba="0 180.0 0.0 1.0"/>
            </material>
        </visual>
        <collision>
            <origin xyz="0 0 0.7760879573760257" rpy="0 0 0"/>
            <geometry>
                <box size="2.6243426188596373 2.352571902064319 1.5521759147520513" />
            </geometry>
        </collision>
    </link>
    <link name="Leg24">
        <inertial>
            <origin xyz="0 1.0129527434655707 0" rpy="0 0 0"/>
            <mass value="1" />
            <inertia ixx="100" ixy="0" ixz="0" iyy="100" iyz="0" izz="100" />
        </inertial>
        <visual>
            <origin xyz="0 1.0129527434655707 0" rpy="0 0 0"/>
            <geometry>
                <box size="2.7720909460662124 2.0259054869311415 1.7592809632026314" />
            </geometry>
            <material name="Blue">
                <color rgba="0 1.0 1.0 1.0"/>
            </material>
        </visual>
        <collision>
            <origin xyz="0 1.0129527434655707 0" rpy="0 0 0"/>
            <geometry>
                <box size="2.7720909460662124 2.0259054869311415 1.7592809632026314" />
            </geometry>
        </collision>
    </link>
    <link name="Leg25">
        <inertial>
            <origin xyz="0 0 1.443122475032821" rpy="0 0 0"/>
            <mass value="1" />
            <inertia ixx="100" ixy="0" ixz="0" iyy="100" iyz="0" izz="100" />
        </inertial>
        <visual>
            <origin xyz="0 0 1.443122475032821" rpy="0 0 0"/>
            <geometry>
                <box size="1.7768266988349177 2.2310657671461627 2.886244950065642" />
            </geometry>
            <material name="Green">
                <color rgba="0 180.0 0.0 1.0"/>
            </material>
        </visual>
        <collision>
            <origin xyz="0 0 1.443122475032821" rpy="0 0 0"/>
            <geometry>
                <box size="1.7768266988349177 2.2310657671461627 2.886244950065642" />
            </geometry>
        </collision>
    </link>
    <link name="Leg26">
        <inertial>
            <origin xyz="0 1.3329215365051374 0" rpy="0 0 0"/>
            <mass value="1" />
            <inertia ixx="100" ixy="0" ixz="0" iyy="100" iyz="0" izz="100" />
        </inertial>
        <visual>
            <origin xyz="0 1.3329215365051374 0" rpy="0 0 0"/>
            <geometry>
                <box size="1.8111108277790675 2.665843073010275 2.0790464815784278" />
            </geometry>
            <material name="Blue">
                <color rgba="0 1.0 1.0 1.0"/>
            </material>
        </visual>
        <collision>
            <origin xyz="0 1.3329215365051374 0" rpy="0 0 0"/>
            <geometry>
                <box size="1.8111108277790675 2.665843073010275 2.0790464815784278" />
            </geometry>
        </collision>
    </link>
    <joint name="Torso_Leg1" type="revolute">
       <parent link="Torso"/>
       <child  link="Leg1"/>
       <origin rpy="0 0 0" xyz="0 1.1723087556520615 1.4613544811092287" />
     <axis xyz="1 0 0"/>
       <limit effort="0.0" lower="-3.14159" upper="3.14159" velocity="0.0"/>
    </joint>
    <joint name="Leg1_Leg2" type="revolute">
       <parent link="Leg1"/>
       <child  link="Leg2"/>
       <origin rpy="0 0 0" xyz="0 1.6478893692845284 0" />
     <axis xyz="1 0 0"/>
       <limit effort="0.0" lower="-3.14159" upper="3.14159" velocity="0.0"/>
    </joint>
    <joint name="Leg2_Leg3" type="revolute">
       <parent link="Leg2"/>
       <child  link="Leg3"/>
       <origin rpy="0 0 0" xyz="0 1.9188406776088116 0" />
     <axis xyz="1 0 0"/>
       <limit effort="0.0" lower="-3.14159" upper="3.14159" velocity="0.0"/>
    </joint>
    <joint name="Leg1_Leg4" type="revolute">
       <parent link="Leg1"/>
       <child  link="Leg4"/>
       <origin rpy="0 0 0" xyz="0 1.6478893692845284 0.5715075491235039" />
     <axis xyz="1 0 0"/>
       <limit effort="0.0" lower="-3.14159" upper="3.14159" velocity="0.0"/>
    </joint>
    <joint name="Leg4_Leg5" type="revolute">
       <parent link="Leg4"/>
       <child  link="Leg5"/>
       <origin rpy="0 0 0" xyz="0 2.4049246453699107 0" />
     <axis xyz="1 0 0"/>
       <limit effort="0.0" lower="-3.14159" upper="3.14159" velocity="0.0"/>
    </joint>
    <joint name="Leg5_Leg6" type="revolute">
       <parent link="Leg5"/>
       <child  link="Leg6"/>
       <origin rpy="0 0 0" xyz="0 1.0313360938034057 0" />
     <axis xyz="1 0 0"/>
       <limit effort="0.0" lower="-3.14159" upper="3.14159" velocity="0.0"/>
    </joint>
    <joint name="Torso_Leg7" type="revolute">
       <parent link="Torso"/>
       <child  link="Leg7"/>
       <origin rpy="0 0 0" xyz="0 0.8692433116222 0.7411096321261059" />
     <axis xyz="1 0 0"/>
       <limit effort="0.0" lower="-3.14159" upper="3.14159" velocity="0.0"/>
    </joint>
    <joint name="Leg3_Leg8" type="revolute">
       <parent link="Leg3"/>
       <child  link="Leg8"/>
       <origin rpy="0 0 0" xyz="0 0 1.2711906625091096" />
     <axis xyz="1 0 0"/>
       <limit effort="0.0" lower="-3.14159" upper="3.14159" velocity="0.0"/>
    </joint>
    <joint name="Leg3_Leg9" type="revolute">
       <parent link="Leg3"/>
       <child  link="Leg9"/>
       <origin rpy="0 0 0" xyz="0 0.9488176190077848 1.2711906625091096" />
     <axis xyz="1 0 0"/>
       <limit effort="0.0" lower="-3.14159" upper="3.14159" velocity="0.0"/>
    </joint>
    <joint name="Leg2_Leg10" type="revolute">
       <parent link="Leg2"/>
       <child  link="Leg10"/>
       <origin rpy="0 0 0" xyz="0.8521595961687866 1.9188406776088116 0" />
     <axis xyz="1 0 0"/>
       <limit effort="0.0" lower="-3.14159" upper="3.14159" velocity="0.0"/>
    </joint>
    <joint name="Leg9_Leg11" type="revolute">
       <parent link="Leg9"/>
       <child  link="Leg11"/>
       <origin rpy="0 0 0" xyz="0.9577776235872134 1.3124192771003127 0" />
     <axis xyz="1 0 0"/>
       <limit effort="0.0" lower="-3.14159" upper="3.14159" velocity="0.0"/>
    </joint>
    <joint name="Leg10_Leg12" type="revolute">
       <parent link="Leg10"/>
       <child  link="Leg12"/>
       <origin rpy="0 0 0" xyz="0 1.2404748226650655 0" />
     <axis xyz="1 0 0"/>
       <limit effort="0.0" lower="-3.14159" upper="3.14159" velocity="0.0"/>
    </joint>
    <joint name="Leg9_Leg13" type="revolute">
       <parent link="Leg9"/>
       <child  link="Leg13"/>
       <origin rpy="0 0 0" xyz="0.9577776235872134 1.3124192771003127 1.163197309400601" />
     <axis xyz="1 0 0"/>
       <limit effort="0.0" lower="-3.14159" upper="3.14159" velocity="0.0"/>
    </joint>
    <joint name="Leg6_Leg14" type="revolute">
       <parent link="Leg6"/>
       <child  link="Leg14"/>
       <origin rpy="0 0 0" xyz="0 0.9425444673703354 0.6053132004027514" />
     <axis xyz="1 0 0"/>
       <limit effort="0.0" lower="-3.14159" upper="3.14159" velocity="0.0"/>
    </joint>
    <joint name="Leg11_Leg15" type="revolute">
       <parent link="Leg11"/>
       <child  link="Leg15"/>
       <origin rpy="0 0 0" xyz="0 2.617649556080107 0" />
     <axis xyz="1 0 0"/>
       <limit effort="0.0" lower="-3.14159" upper="3.14159" velocity="0.0"/>
    </joint>
    <joint name="Leg4_Leg16" type="revolute">
       <parent link="Leg4"/>
       <child  link="Leg16"/>
       <origin rpy="0 0 0" xyz="0.9178760390175245 2.4049246453699107 0" />
     <axis xyz="1 0 0"/>
       <limit effort="0.0" lower="-3.14159" upper="3.14159" velocity="0.0"/>
    </joint>
    <joint name="Leg9_Leg17" type="revolute">
       <parent link="Leg9"/>
       <child  link="Leg17"/>
       <origin rpy="0 0 0" xyz="1.9155552471744268 1.3124192771003127 1.163197309400601" />
     <axis xyz="1 0 0"/>
       <limit effort="0.0" lower="-3.14159" upper="3.14159" velocity="0.0"/>
    </joint>
    <joint name="Leg1_Leg18" type="revolute">
       <parent link="Leg1"/>
       <child  link="Leg18"/>
       <origin rpy="0 0 0" xyz="1.4113053203075596 1.6478893692845284 0.5715075491235039" />
     <axis xyz="1 0 0"/>
       <limit effort="0.0" lower="-3.14159" upper="3.14159" velocity="0.0"/>
    </joint>
    <joint name="Leg12_Leg19" type="revolute">
       <parent link="Leg12"/>
       <child  link="Leg19"/>
       <origin rpy="0 0 0" xyz="0 0 1.6101701012752534" />
     <axis xyz="1 0 0"/>
       <limit effort="0.0" lower="-3.14159" upper="3.14159" velocity="0.0"/>
    </joint>
    <joint name="Leg7_Leg20" type="revolute">
       <parent link="Leg7"/>
       <child  link="Leg20"/>
       <origin rpy="0 0 0" xyz="0 1.4894341552077222 0.612295245195915" />
     <axis xyz="1 0 0"/>
       <limit effort="0.0" lower="-3.14159" upper="3.14159" velocity="0.0"/>
    </joint>
    <joint name="Leg6_Leg21" type="revolute">
       <parent link="Leg6"/>
       <child  link="Leg21"/>
       <origin rpy="0 0 0" xyz="0 0.9425444673703354 1.2106264008055028" />
     <axis xyz="1 0 0"/>
       <limit effort="0.0" lower="-3.14159" upper="3.14159" velocity="0.0"/>
    </joint>
    <joint name="Leg14_Leg22" type="revolute">
       <parent link="Leg14"/>
       <child  link="Leg22"/>
       <origin rpy="0 0 0" xyz="0.717254929261815 0.6459473271285684 0" />
     <axis xyz="1 0 0"/>
       <limit effort="0.0" lower="-3.14159" upper="3.14159" velocity="0.0"/>
    </joint>
    <joint name="Leg8_Leg23" type="revolute">
       <parent link="Leg8"/>
       <child  link="Leg23"/>
       <origin rpy="0 0 0" xyz="0 0.8954556722359825 0.5183425657277764" />
     <axis xyz="1 0 0"/>
       <limit effort="0.0" lower="-3.14159" upper="3.14159" velocity="0.0"/>
    </joint>
    <joint name="Leg22_Leg24" type="revolute">
       <parent link="Leg22"/>
       <child  link="Leg24"/>
       <origin rpy="0 0 0" xyz="0 1.1762859510321595 0.7760879573760257" />
     <axis xyz="1 0 0"/>
       <limit effort="0.0" lower="-3.14159" upper="3.14159" velocity="0.0"/>
    </joint>
    <joint name="Leg20_Leg25" type="revolute">
       <parent link="Leg20"/>
       <child  link="Leg25"/>
       <origin rpy="0 0 0" xyz="0 0 2.652351572022512" />
     <axis xyz="1 0 0"/>
       <limit effort="0.0" lower="-3.14159" upper="3.14159" velocity="0.0"/>
    </joint>
    <joint name="Leg18_Leg26" type="revolute">
       <parent link="Leg18"/>
       <child  link="Leg26"/>
       <origin rpy="0 0 0" xyz="0 1.129171224954912 1.1514027811080072" />
     <axis xyz="1 0 0"/>
       <limit effort="0.0" lower="-3.14159" upper="3.14159" velocity="0.0"/>
    </joint>
</robot>