<robot name = "robot">
    <link name="Torso">
        <inertial>
            <origin xyz="0 0 1.3052567767189582" rpy="0 0 0"/>
            <mass value="1" />
            <inertia ixx="100" ixy="0" ixz="0" iyy="100" iyz="0" izz="100" />
        </inertial>
        <visual>
            <origin xyz="0 0 1.3052567767189582" rpy="0 0 0"/>
            <geometry>
                <box size="1.4496838795968165 1.053240527242066 2.6105135534379165" />
            </geometry>
            <material name="Green">
                <color rgba="0 180.0 0.0 1.0"/>
            </material>
        </visual>
        <collision>
            <origin xyz="0 0 1.3052567767189582" rpy="0 0 0"/>
            <geometry>
                <box size="1.4496838795968165 1.053240527242066 2.6105135534379165" />
            </geometry>
        </collision>
    </link>
    <link name="Leg1">
        <inertial>
            <origin xyz="1.0350578648899185 0 0" rpy="0 0 0"/>
            <mass value="1" />
            <inertia ixx="100" ixy="0" ixz="0" iyy="100" iyz="0" izz="100" />
        </inertial>
        <visual>
            <origin xyz="1.0350578648899185 0 0" rpy="0 0 0"/>
            <geometry>
                <box size="2.070115729779837 1.4718488009779425 1.3906363909088393" />
            </geometry>
            <material name="Green">
                <color rgba="0 180.0 0.0 1.0"/>
            </material>
        </visual>
        <collision>
            <origin xyz="1.0350578648899185 0 0" rpy="0 0 0"/>
            <geometry>
                <box size="2.070115729779837 1.4718488009779425 1.3906363909088393" />
            </geometry>
        </collision>
    </link>
    <link name="Leg2">
        <inertial>
            <origin xyz="0.5288824985650341 0 0" rpy="0 0 0"/>
            <mass value="1" />
            <inertia ixx="100" ixy="0" ixz="0" iyy="100" iyz="0" izz="100" />
        </inertial>
        <visual>
            <origin xyz="0.5288824985650341 0 0" rpy="0 0 0"/>
            <geometry>
                <box size="1.0577649971300682 1.1409559706998482 2.7306835247759036" />
            </geometry>
            <material name="Green">
                <color rgba="0 180.0 0.0 1.0"/>
            </material>
        </visual>
        <collision>
            <origin xyz="0.5288824985650341 0 0" rpy="0 0 0"/>
            <geometry>
                <box size="1.0577649971300682 1.1409559706998482 2.7306835247759036" />
            </geometry>
        </collision>
    </link>
    <link name="Leg3">
        <inertial>
            <origin xyz="0 0 1.0729579448896422" rpy="0 0 0"/>
            <mass value="1" />
            <inertia ixx="100" ixy="0" ixz="0" iyy="100" iyz="0" izz="100" />
        </inertial>
        <visual>
            <origin xyz="0 0 1.0729579448896422" rpy="0 0 0"/>
            <geometry>
                <box size="2.2287572220178076 1.4904311447835394 2.1459158897792845" />
            </geometry>
            <material name="Green">
                <color rgba="0 180.0 0.0 1.0"/>
            </material>
        </visual>
        <collision>
            <origin xyz="0 0 1.0729579448896422" rpy="0 0 0"/>
            <geometry>
                <box size="2.2287572220178076 1.4904311447835394 2.1459158897792845" />
            </geometry>
        </collision>
    </link>
    <link name="Leg4">
        <inertial>
            <origin xyz="0.6956824037988326 0 0" rpy="0 0 0"/>
            <mass value="1" />
            <inertia ixx="100" ixy="0" ixz="0" iyy="100" iyz="0" izz="100" />
        </inertial>
        <visual>
            <origin xyz="0.6956824037988326 0 0" rpy="0 0 0"/>
            <geometry>
                <box size="1.3913648075976652 2.9846957839961497 2.500137426104788" />
            </geometry>
            <material name="Blue">
                <color rgba="0 1.0 1.0 1.0"/>
            </material>
        </visual>
        <collision>
            <origin xyz="0.6956824037988326 0 0" rpy="0 0 0"/>
            <geometry>
                <box size="1.3913648075976652 2.9846957839961497 2.500137426104788" />
            </geometry>
        </collision>
    </link>
    <link name="Leg5">
        <inertial>
            <origin xyz="0 0 1.3148285716981842" rpy="0 0 0"/>
            <mass value="1" />
            <inertia ixx="100" ixy="0" ixz="0" iyy="100" iyz="0" izz="100" />
        </inertial>
        <visual>
            <origin xyz="0 0 1.3148285716981842" rpy="0 0 0"/>
            <geometry>
                <box size="1.5066726590192319 2.11138727678345 2.6296571433963685" />
            </geometry>
            <material name="Blue">
                <color rgba="0 1.0 1.0 1.0"/>
            </material>
        </visual>
        <collision>
            <origin xyz="0 0 1.3148285716981842" rpy="0 0 0"/>
            <geometry>
                <box size="1.5066726590192319 2.11138727678345 2.6296571433963685" />
            </geometry>
        </collision>
    </link>
    <link name="Leg6">
        <inertial>
            <origin xyz="0 0 1.1583854451033613" rpy="0 0 0"/>
            <mass value="1" />
            <inertia ixx="100" ixy="0" ixz="0" iyy="100" iyz="0" izz="100" />
        </inertial>
        <visual>
            <origin xyz="0 0 1.1583854451033613" rpy="0 0 0"/>
            <geometry>
                <box size="1.0407984029096864 1.5712953420179618 2.3167708902067226" />
            </geometry>
            <material name="Blue">
                <color rgba="0 1.0 1.0 1.0"/>
            </material>
        </visual>
        <collision>
            <origin xyz="0 0 1.1583854451033613" rpy="0 0 0"/>
            <geometry>
                <box size="1.0407984029096864 1.5712953420179618 2.3167708902067226" />
            </geometry>
        </collision>
    </link>
    <link name="Leg7">
        <inertial>
            <origin xyz="0 0 0.8241001676966945" rpy="0 0 0"/>
            <mass value="1" />
            <inertia ixx="100" ixy="0" ixz="0" iyy="100" iyz="0" izz="100" />
        </inertial>
        <visual>
            <origin xyz="0 0 0.8241001676966945" rpy="0 0 0"/>
            <geometry>
                <box size="1.3154345672260066 2.8208748735930835 1.648200335393389" />
            </geometry>
            <material name="Blue">
                <color rgba="0 1.0 1.0 1.0"/>
            </material>
        </visual>
        <collision>
            <origin xyz="0 0 0.8241001676966945" rpy="0 0 0"/>
            <geometry>
                <box size="1.3154345672260066 2.8208748735930835 1.648200335393389" />
            </geometry>
        </collision>
    </link>
    <link name="Leg8">
        <inertial>
            <origin xyz="0 1.0455143077020879 0" rpy="0 0 0"/>
            <mass value="1" />
            <inertia ixx="100" ixy="0" ixz="0" iyy="100" iyz="0" izz="100" />
        </inertial>
        <visual>
            <origin xyz="0 1.0455143077020879 0" rpy="0 0 0"/>
            <geometry>
                <box size="2.4357006600614017 2.0910286154041757 1.4561746794275008" />
            </geometry>
            <material name="Green">
                <color rgba="0 180.0 0.0 1.0"/>
            </material>
        </visual>
        <collision>
            <origin xyz="0 1.0455143077020879 0" rpy="0 0 0"/>
            <geometry>
                <box size="2.4357006600614017 2.0910286154041757 1.4561746794275008" />
            </geometry>
        </collision>
    </link>
    <link name="Leg9">
        <inertial>
            <origin xyz="0 0 0.5913469212047006" rpy="0 0 0"/>
            <mass value="1" />
            <inertia ixx="100" ixy="0" ixz="0" iyy="100" iyz="0" izz="100" />
        </inertial>
        <visual>
            <origin xyz="0 0 0.5913469212047006" rpy="0 0 0"/>
            <geometry>
                <box size="2.7273902962350265 1.7754497380818544 1.1826938424094011" />
            </geometry>
            <material name="Green">
                <color rgba="0 180.0 0.0 1.0"/>
            </material>
        </visual>
        <collision>
            <origin xyz="0 0 0.5913469212047006" rpy="0 0 0"/>
            <geometry>
                <box size="2.7273902962350265 1.7754497380818544 1.1826938424094011" />
            </geometry>
        </collision>
    </link>
    <link name="Leg10">
        <inertial>
            <origin xyz="0 0 1.093169759966695" rpy="0 0 0"/>
            <mass value="1" />
            <inertia ixx="100" ixy="0" ixz="0" iyy="100" iyz="0" izz="100" />
        </inertial>
        <visual>
            <origin xyz="0 0 1.093169759966695" rpy="0 0 0"/>
            <geometry>
                <box size="2.1037941567179015 1.6180526974453977 2.18633951993339" />
            </geometry>
            <material name="Green">
                <color rgba="0 180.0 0.0 1.0"/>
            </material>
        </visual>
        <collision>
            <origin xyz="0 0 1.093169759966695" rpy="0 0 0"/>
            <geometry>
                <box size="2.1037941567179015 1.6180526974453977 2.18633951993339" />
            </geometry>
        </collision>
    </link>
    <link name="Leg11">
        <inertial>
            <origin xyz="0 1.006771740329648 0" rpy="0 0 0"/>
            <mass value="1" />
            <inertia ixx="100" ixy="0" ixz="0" iyy="100" iyz="0" izz="100" />
        </inertial>
        <visual>
            <origin xyz="0 1.006771740329648 0" rpy="0 0 0"/>
            <geometry>
                <box size="2.6197419089207306 2.013543480659296 2.032600766403556" />
            </geometry>
            <material name="Green">
                <color rgba="0 180.0 0.0 1.0"/>
            </material>
        </visual>
        <collision>
            <origin xyz="0 1.006771740329648 0" rpy="0 0 0"/>
            <geometry>
                <box size="2.6197419089207306 2.013543480659296 2.032600766403556" />
            </geometry>
        </collision>
    </link>
    <link name="Leg12">
        <inertial>
            <origin xyz="0.6674324695725589 0 0" rpy="0 0 0"/>
            <mass value="1" />
            <inertia ixx="100" ixy="0" ixz="0" iyy="100" iyz="0" izz="100" />
        </inertial>
        <visual>
            <origin xyz="0.6674324695725589 0 0" rpy="0 0 0"/>
            <geometry>
                <box size="1.3348649391451177 1.3261813143685168 1.8082529582836961" />
            </geometry>
            <material name="Blue">
                <color rgba="0 1.0 1.0 1.0"/>
            </material>
        </visual>
        <collision>
            <origin xyz="0.6674324695725589 0 0" rpy="0 0 0"/>
            <geometry>
                <box size="1.3348649391451177 1.3261813143685168 1.8082529582836961" />
            </geometry>
        </collision>
    </link>
    <link name="Leg13">
        <inertial>
            <origin xyz="1.1049386763503188 0 0" rpy="0 0 0"/>
            <mass value="1" />
            <inertia ixx="100" ixy="0" ixz="0" iyy="100" iyz="0" izz="100" />
        </inertial>
        <visual>
            <origin xyz="1.1049386763503188 0 0" rpy="0 0 0"/>
            <geometry>
                <box size="2.2098773527006377 1.9066002776815347 1.7515333351461542" />
            </geometry>
            <material name="Blue">
                <color rgba="0 1.0 1.0 1.0"/>
            </material>
        </visual>
        <collision>
            <origin xyz="1.1049386763503188 0 0" rpy="0 0 0"/>
            <geometry>
                <box size="2.2098773527006377 1.9066002776815347 1.7515333351461542" />
            </geometry>
        </collision>
    </link>
    <link name="Leg14">
        <inertial>
            <origin xyz="0.7487322690844936 0 0" rpy="0 0 0"/>
            <mass value="1" />
            <inertia ixx="100" ixy="0" ixz="0" iyy="100" iyz="0" izz="100" />
        </inertial>
        <visual>
            <origin xyz="0.7487322690844936 0 0" rpy="0 0 0"/>
            <geometry>
                <box size="1.4974645381689873 1.1985044683148038 2.059644810861998" />
            </geometry>
            <material name="Green">
                <color rgba="0 180.0 0.0 1.0"/>
            </material>
        </visual>
        <collision>
            <origin xyz="0.7487322690844936 0 0" rpy="0 0 0"/>
            <geometry>
                <box size="1.4974645381689873 1.1985044683148038 2.059644810861998" />
            </geometry>
        </collision>
    </link>
    <link name="Leg15">
        <inertial>
            <origin xyz="0 0 0.9107881685791146" rpy="0 0 0"/>
            <mass value="1" />
            <inertia ixx="100" ixy="0" ixz="0" iyy="100" iyz="0" izz="100" />
        </inertial>
        <visual>
            <origin xyz="0 0 0.9107881685791146" rpy="0 0 0"/>
            <geometry>
                <box size="1.3650816789140965 2.364706917411962 1.8215763371582292" />
            </geometry>
            <material name="Green">
                <color rgba="0 180.0 0.0 1.0"/>
            </material>
        </visual>
        <collision>
            <origin xyz="0 0 0.9107881685791146" rpy="0 0 0"/>
            <geometry>
                <box size="1.3650816789140965 2.364706917411962 1.8215763371582292" />
            </geometry>
        </collision>
    </link>
    <link name="Leg16">
        <inertial>
            <origin xyz="1.0662334698946152 0 0" rpy="0 0 0"/>
            <mass value="1" />
            <inertia ixx="100" ixy="0" ixz="0" iyy="100" iyz="0" izz="100" />
        </inertial>
        <visual>
            <origin xyz="1.0662334698946152 0 0" rpy="0 0 0"/>
            <geometry>
                <box size="2.1324669397892304 2.354408625990582 2.489180210304526" />
            </geometry>
            <material name="Green">
                <color rgba="0 180.0 0.0 1.0"/>
            </material>
        </visual>
        <collision>
            <origin xyz="1.0662334698946152 0 0" rpy="0 0 0"/>
            <geometry>
                <box size="2.1324669397892304 2.354408625990582 2.489180210304526" />
            </geometry>
        </collision>
    </link>
    <link name="Leg17">
        <inertial>
            <origin xyz="0 0.8027775030500579 0" rpy="0 0 0"/>
            <mass value="1" />
            <inertia ixx="100" ixy="0" ixz="0" iyy="100" iyz="0" izz="100" />
        </inertial>
        <visual>
            <origin xyz="0 0.8027775030500579 0" rpy="0 0 0"/>
            <geometry>
                <box size="2.625615793895362 1.6055550061001158 1.5157279905036418" />
            </geometry>
            <material name="Green">
                <color rgba="0 180.0 0.0 1.0"/>
            </material>
        </visual>
        <collision>
            <origin xyz="0 0.8027775030500579 0" rpy="0 0 0"/>
            <geometry>
                <box size="2.625615793895362 1.6055550061001158 1.5157279905036418" />
            </geometry>
        </collision>
    </link>
    <link name="Leg18">
        <inertial>
            <origin xyz="0 0 1.0785915469053489" rpy="0 0 0"/>
            <mass value="1" />
            <inertia ixx="100" ixy="0" ixz="0" iyy="100" iyz="0" izz="100" />
        </inertial>
        <visual>
            <origin xyz="0 0 1.0785915469053489" rpy="0 0 0"/>
            <geometry>
                <box size="1.8402833747240908 2.9740733434016335 2.1571830938106977" />
            </geometry>
            <material name="Green">
                <color rgba="0 180.0 0.0 1.0"/>
            </material>
        </visual>
        <collision>
            <origin xyz="0 0 1.0785915469053489" rpy="0 0 0"/>
            <geometry>
                <box size="1.8402833747240908 2.9740733434016335 2.1571830938106977" />
            </geometry>
        </collision>
    </link>
    <link name="Leg19">
        <inertial>
            <origin xyz="0.8828247864614287 0 0" rpy="0 0 0"/>
            <mass value="1" />
            <inertia ixx="100" ixy="0" ixz="0" iyy="100" iyz="0" izz="100" />
        </inertial>
        <visual>
            <origin xyz="0.8828247864614287 0 0" rpy="0 0 0"/>
            <geometry>
                <box size="1.7656495729228574 1.0721714238814457 2.0508378872656126" />
            </geometry>
            <material name="Green">
                <color rgba="0 180.0 0.0 1.0"/>
            </material>
        </visual>
        <collision>
            <origin xyz="0.8828247864614287 0 0" rpy="0 0 0"/>
            <geometry>
                <box size="1.7656495729228574 1.0721714238814457 2.0508378872656126" />
            </geometry>
        </collision>
    </link>
    <link name="Leg20">
        <inertial>
            <origin xyz="0 0 0.7706767051179572" rpy="0 0 0"/>
            <mass value="1" />
            <inertia ixx="100" ixy="0" ixz="0" iyy="100" iyz="0" izz="100" />
        </inertial>
        <visual>
            <origin xyz="0 0 0.7706767051179572" rpy="0 0 0"/>
            <geometry>
                <box size="1.9160508052829548 1.8713514833174143 1.5413534102359143" />
            </geometry>
            <material name="Green">
                <color rgba="0 180.0 0.0 1.0"/>
            </material>
        </visual>
        <collision>
            <origin xyz="0 0 0.7706767051179572" rpy="0 0 0"/>
            <geometry>
                <box size="1.9160508052829548 1.8713514833174143 1.5413534102359143" />
            </geometry>
        </collision>
    </link>
    <link name="Leg21">
        <inertial>
            <origin xyz="0 0 1.2729614857767628" rpy="0 0 0"/>
            <mass value="1" />
            <inertia ixx="100" ixy="0" ixz="0" iyy="100" iyz="0" izz="100" />
        </inertial>
        <visual>
            <origin xyz="0 0 1.2729614857767628" rpy="0 0 0"/>
            <geometry>
                <box size="1.8322370064336948 2.4172951799994937 2.5459229715535256" />
            </geometry>
            <material name="Blue">
                <color rgba="0 1.0 1.0 1.0"/>
            </material>
        </visual>
        <collision>
            <origin xyz="0 0 1.2729614857767628" rpy="0 0 0"/>
            <geometry>
                <box size="1.8322370064336948 2.4172951799994937 2.5459229715535256" />
            </geometry>
        </collision>
    </link>
    <link name="Leg22">
        <inertial>
            <origin xyz="0 0.548396242755652 0" rpy="0 0 0"/>
            <mass value="1" />
            <inertia ixx="100" ixy="0" ixz="0" iyy="100" iyz="0" izz="100" />
        </inertial>
        <visual>
            <origin xyz="0 0.548396242755652 0" rpy="0 0 0"/>
            <geometry>
                <box size="2.4208593651873187 1.096792485511304 1.0075018056406213" />
            </geometry>
            <material name="Blue">
                <color rgba="0 1.0 1.0 1.0"/>
            </material>
        </visual>
        <collision>
            <origin xyz="0 0.548396242755652 0" rpy="0 0 0"/>
            <geometry>
                <box size="2.4208593651873187 1.096792485511304 1.0075018056406213" />
            </geometry>
        </collision>
    </link>
    <link name="Leg23">
        <inertial>
            <origin xyz="0 0.9964312643677209 0" rpy="0 0 0"/>
            <mass value="1" />
            <inertia ixx="100" ixy="0" ixz="0" iyy="100" iyz="0" izz="100" />
        </inertial>
        <visual>
            <origin xyz="0 0.9964312643677209 0" rpy="0 0 0"/>
            <geometry>
                <box size="2.00840079828433 1.9928625287354418 1.5400113222950806" />
            </geometry>
            <material name="Green">
                <color rgba="0 180.0 0.0 1.0"/>
            </material>
        </visual>
        <collision>
            <origin xyz="0 0.9964312643677209 0" rpy="0 0 0"/>
            <geometry>
                <box size="2.00840079828433 1.9928625287354418 1.5400113222950806" />
            </geometry>
        </collision>
    </link>
    <link name="Leg24">
        <inertial>
            <origin xyz="0 1.3201443185896276 0" rpy="0 0 0"/>
            <mass value="1" />
            <inertia ixx="100" ixy="0" ixz="0" iyy="100" iyz="0" izz="100" />
        </inertial>
        <visual>
            <origin xyz="0 1.3201443185896276 0" rpy="0 0 0"/>
            <geometry>
                <box size="1.457740820226884 2.640288637179255 2.1852385988154253" />
            </geometry>
            <material name="Blue">
                <color rgba="0 1.0 1.0 1.0"/>
            </material>
        </visual>
        <collision>
            <origin xyz="0 1.3201443185896276 0" rpy="0 0 0"/>
            <geometry>
                <box size="1.457740820226884 2.640288637179255 2.1852385988154253" />
            </geometry>
        </collision>
    </link>
    <link name="Leg25">
        <inertial>
            <origin xyz="0.8538525151369171 0 0" rpy="0 0 0"/>
            <mass value="1" />
            <inertia ixx="100" ixy="0" ixz="0" iyy="100" iyz="0" izz="100" />
        </inertial>
        <visual>
            <origin xyz="0.8538525151369171 0 0" rpy="0 0 0"/>
            <geometry>
                <box size="1.7077050302738341 2.2327340342332787 2.5628818708455094" />
            </geometry>
            <material name="Blue">
                <color rgba="0 1.0 1.0 1.0"/>
            </material>
        </visual>
        <collision>
            <origin xyz="0.8538525151369171 0 0" rpy="0 0 0"/>
            <geometry>
                <box size="1.7077050302738341 2.2327340342332787 2.5628818708455094" />
            </geometry>
        </collision>
    </link>
    <link name="Leg26">
        <inertial>
            <origin xyz="0 0 0.9949036155114304" rpy="0 0 0"/>
            <mass value="1" />
            <inertia ixx="100" ixy="0" ixz="0" iyy="100" iyz="0" izz="100" />
        </inertial>
        <visual>
            <origin xyz="0 0 0.9949036155114304" rpy="0 0 0"/>
            <geometry>
                <box size="1.6801405964985348 1.8178651641309316 1.9898072310228607" />
            </geometry>
            <material name="Blue">
                <color rgba="0 1.0 1.0 1.0"/>
            </material>
        </visual>
        <collision>
            <origin xyz="0 0 0.9949036155114304" rpy="0 0 0"/>
            <geometry>
                <box size="1.6801405964985348 1.8178651641309316 1.9898072310228607" />
            </geometry>
        </collision>
    </link>
    <link name="Leg27">
        <inertial>
            <origin xyz="0 0 0.9859827590205469" rpy="0 0 0"/>
            <mass value="1" />
            <inertia ixx="100" ixy="0" ixz="0" iyy="100" iyz="0" izz="100" />
        </inertial>
        <visual>
            <origin xyz="0 0 0.9859827590205469" rpy="0 0 0"/>
            <geometry>
                <box size="2.028178360109224 1.7112649002576326 1.9719655180410938" />
            </geometry>
            <material name="Green">
                <color rgba="0 180.0 0.0 1.0"/>
            </material>
        </visual>
        <collision>
            <origin xyz="0 0 0.9859827590205469" rpy="0 0 0"/>
            <geometry>
                <box size="2.028178360109224 1.7112649002576326 1.9719655180410938" />
            </geometry>
        </collision>
    </link>
    <link name="Leg28">
        <inertial>
            <origin xyz="0 1.107887296679336 0" rpy="0 0 0"/>
            <mass value="1" />
            <inertia ixx="100" ixy="0" ixz="0" iyy="100" iyz="0" izz="100" />
        </inertial>
        <visual>
            <origin xyz="0 1.107887296679336 0" rpy="0 0 0"/>
            <geometry>
                <box size="2.492987479468655 2.215774593358672 1.023571721523283" />
            </geometry>
            <material name="Green">
                <color rgba="0 180.0 0.0 1.0"/>
            </material>
        </visual>
        <collision>
            <origin xyz="0 1.107887296679336 0" rpy="0 0 0"/>
            <geometry>
                <box size="2.492987479468655 2.215774593358672 1.023571721523283" />
            </geometry>
        </collision>
    </link>
    <joint name="Torso_Leg1" type="revolute">
       <parent link="Torso"/>
       <child  link="Leg1"/>
       <origin rpy="0 0 0" xyz="0.7248419397984083 0 1.3052567767189582" />
     <axis xyz="1 0 0"/>
       <limit effort="0.0" lower="-3.14159" upper="3.14159" velocity="0.0"/>
    </joint>
    <joint name="Leg1_Leg2" type="revolute">
       <parent link="Leg1"/>
       <child  link="Leg2"/>
       <origin rpy="0 0 0" xyz="1.0577649971300682 0 0" />
     <axis xyz="1 0 0"/>
       <limit effort="0.0" lower="-3.14159" upper="3.14159" velocity="0.0"/>
    </joint>
    <joint name="Leg2_Leg3" type="revolute">
       <parent link="Leg2"/>
       <child  link="Leg3"/>
       <origin rpy="0 0 0" xyz="0 0 2.1459158897792845" />
     <axis xyz="1 0 0"/>
       <limit effort="0.0" lower="-3.14159" upper="3.14159" velocity="0.0"/>
    </joint>
    <joint name="Leg2_Leg4" type="revolute">
       <parent link="Leg2"/>
       <child  link="Leg4"/>
       <origin rpy="0 0 0" xyz="1.1143786110089038 0 2.1459158897792845" />
     <axis xyz="1 0 0"/>
       <limit effort="0.0" lower="-3.14159" upper="3.14159" velocity="0.0"/>
    </joint>
    <joint name="Torso_Leg5" type="revolute">
       <parent link="Torso"/>
       <child  link="Leg5"/>
       <origin rpy="0 0 0" xyz="1.0350578648899185 0 0.6953181954544196" />
     <axis xyz="1 0 0"/>
       <limit effort="0.0" lower="-3.14159" upper="3.14159" velocity="0.0"/>
    </joint>
    <joint name="Leg4_Leg6" type="revolute">
       <parent link="Leg4"/>
       <child  link="Leg6"/>
       <origin rpy="0 0 0" xyz="0 0 2.6296571433963685" />
     <axis xyz="1 0 0"/>
       <limit effort="0.0" lower="-3.14159" upper="3.14159" velocity="0.0"/>
    </joint>
    <joint name="Leg6_Leg7" type="revolute">
       <parent link="Leg6"/>
       <child  link="Leg7"/>
       <origin rpy="0 0 0" xyz="0 0 1.648200335393389" />
     <axis xyz="1 0 0"/>
       <limit effort="0.0" lower="-3.14159" upper="3.14159" velocity="0.0"/>
    </joint>
    <joint name="Leg4_Leg8" type="revolute">
       <parent link="Leg4"/>
       <child  link="Leg8"/>
       <origin rpy="0 0 0" xyz="0 1.055693638391725 2.6296571433963685" />
     <axis xyz="1 0 0"/>
       <limit effort="0.0" lower="-3.14159" upper="3.14159" velocity="0.0"/>
    </joint>
    <joint name="Leg5_Leg9" type="revolute">
       <parent link="Leg5"/>
       <child  link="Leg9"/>
       <origin rpy="0 0 0" xyz="0 0 2.3167708902067226" />
     <axis xyz="1 0 0"/>
       <limit effort="0.0" lower="-3.14159" upper="3.14159" velocity="0.0"/>
    </joint>
    <joint name="Leg1_Leg10" type="revolute">
       <parent link="Leg1"/>
       <child  link="Leg10"/>
       <origin rpy="0 0 0" xyz="1.0577649971300682 0 1.3653417623879518" />
     <axis xyz="1 0 0"/>
       <limit effort="0.0" lower="-3.14159" upper="3.14159" velocity="0.0"/>
    </joint>
    <joint name="Leg5_Leg11" type="revolute">
       <parent link="Leg5"/>
       <child  link="Leg11"/>
       <origin rpy="0 0 0" xyz="0 0.7856476710089809 2.3167708902067226" />
     <axis xyz="1 0 0"/>
       <limit effort="0.0" lower="-3.14159" upper="3.14159" velocity="0.0"/>
    </joint>
    <joint name="Leg7_Leg12" type="revolute">
       <parent link="Leg7"/>
       <child  link="Leg12"/>
       <origin rpy="0 0 0" xyz="1.2178503300307009 1.0455143077020879 0" />
     <axis xyz="1 0 0"/>
       <limit effort="0.0" lower="-3.14159" upper="3.14159" velocity="0.0"/>
    </joint>
    <joint name="Leg3_Leg13" type="revolute">
       <parent link="Leg3"/>
       <child  link="Leg13"/>
       <origin rpy="0 0 0" xyz="1.3913648075976652 0 0" />
     <axis xyz="1 0 0"/>
       <limit effort="0.0" lower="-3.14159" upper="3.14159" velocity="0.0"/>
    </joint>
    <joint name="Leg11_Leg14" type="revolute">
       <parent link="Leg11"/>
       <child  link="Leg14"/>
       <origin rpy="0 0 0" xyz="1.3348649391451177 0 0" />
     <axis xyz="1 0 0"/>
       <limit effort="0.0" lower="-3.14159" upper="3.14159" velocity="0.0"/>
    </joint>
    <joint name="Leg8_Leg15" type="revolute">
       <parent link="Leg8"/>
       <child  link="Leg15"/>
       <origin rpy="0 0 0" xyz="0 0 1.1826938424094011" />
     <axis xyz="1 0 0"/>
       <limit effort="0.0" lower="-3.14159" upper="3.14159" velocity="0.0"/>
    </joint>
    <joint name="Leg14_Leg16" type="revolute">
       <parent link="Leg14"/>
       <child  link="Leg16"/>
       <origin rpy="0 0 0" xyz="0.6825408394570482 0 0.9107881685791146" />
     <axis xyz="1 0 0"/>
       <limit effort="0.0" lower="-3.14159" upper="3.14159" velocity="0.0"/>
    </joint>
    <joint name="Leg13_Leg17" type="revolute">
       <parent link="Leg13"/>
       <child  link="Leg17"/>
       <origin rpy="0 0 0" xyz="0.7487322690844936 0.5992522341574019 0" />
     <axis xyz="1 0 0"/>
       <limit effort="0.0" lower="-3.14159" upper="3.14159" velocity="0.0"/>
    </joint>
    <joint name="Leg15_Leg18" type="revolute">
       <parent link="Leg15"/>
       <child  link="Leg18"/>
       <origin rpy="0 0 0" xyz="1.0662334698946152 0 1.244590105152263" />
     <axis xyz="1 0 0"/>
       <limit effort="0.0" lower="-3.14159" upper="3.14159" velocity="0.0"/>
    </joint>
    <joint name="Leg13_Leg19" type="revolute">
       <parent link="Leg13"/>
       <child  link="Leg19"/>
       <origin rpy="0 0 0" xyz="1.4974645381689873 0.5992522341574019 0" />
     <axis xyz="1 0 0"/>
       <limit effort="0.0" lower="-3.14159" upper="3.14159" velocity="0.0"/>
    </joint>
    <joint name="Leg12_Leg20" type="revolute">
       <parent link="Leg12"/>
       <child  link="Leg20"/>
       <origin rpy="0 0 0" xyz="1.1049386763503188 0 0.8757666675730771" />
     <axis xyz="1 0 0"/>
       <limit effort="0.0" lower="-3.14159" upper="3.14159" velocity="0.0"/>
    </joint>
    <joint name="Leg18_Leg21" type="revolute">
       <parent link="Leg18"/>
       <child  link="Leg21"/>
       <origin rpy="0 0 0" xyz="0.8828247864614287 0 1.0254189436328063" />
     <axis xyz="1 0 0"/>
       <limit effort="0.0" lower="-3.14159" upper="3.14159" velocity="0.0"/>
    </joint>
    <joint name="Leg19_Leg22" type="revolute">
       <parent link="Leg19"/>
       <child  link="Leg22"/>
       <origin rpy="0 0 0" xyz="0 0.9356757416587071 0.7706767051179572" />
     <axis xyz="1 0 0"/>
       <limit effort="0.0" lower="-3.14159" upper="3.14159" velocity="0.0"/>
    </joint>
    <joint name="Leg14_Leg23" type="revolute">
       <parent link="Leg14"/>
       <child  link="Leg23"/>
       <origin rpy="0 0 0" xyz="0.6825408394570482 1.182353458705981 0.9107881685791146" />
     <axis xyz="1 0 0"/>
       <limit effort="0.0" lower="-3.14159" upper="3.14159" velocity="0.0"/>
    </joint>
    <joint name="Leg10_Leg24" type="revolute">
       <parent link="Leg10"/>
       <child  link="Leg24"/>
       <origin rpy="0 0 0" xyz="0 2.013543480659296 0" />
     <axis xyz="1 0 0"/>
       <limit effort="0.0" lower="-3.14159" upper="3.14159" velocity="0.0"/>
    </joint>
    <joint name="Leg21_Leg25" type="revolute">
       <parent link="Leg21"/>
       <child  link="Leg25"/>
       <origin rpy="0 0 0" xyz="1.2104296825936594 0.548396242755652 0" />
     <axis xyz="1 0 0"/>
       <limit effort="0.0" lower="-3.14159" upper="3.14159" velocity="0.0"/>
    </joint>
    <joint name="Leg10_Leg26" type="revolute">
       <parent link="Leg10"/>
       <child  link="Leg26"/>
       <origin rpy="0 0 0" xyz="0 2.013543480659296 1.016300383201778" />
     <axis xyz="1 0 0"/>
       <limit effort="0.0" lower="-3.14159" upper="3.14159" velocity="0.0"/>
    </joint>
    <joint name="Leg20_Leg27" type="revolute">
       <parent link="Leg20"/>
       <child  link="Leg27"/>
       <origin rpy="0 0 0" xyz="0 0 2.5459229715535256" />
     <axis xyz="1 0 0"/>
       <limit effort="0.0" lower="-3.14159" upper="3.14159" velocity="0.0"/>
    </joint>
    <joint name="Leg3_Leg28" type="revolute">
       <parent link="Leg3"/>
       <child  link="Leg28"/>
       <origin rpy="0 0 0" xyz="1.3913648075976652 1.4923478919980748 0" />
     <axis xyz="1 0 0"/>
       <limit effort="0.0" lower="-3.14159" upper="3.14159" velocity="0.0"/>
    </joint>
</robot>