<robot name = "robot">
    <link name="Torso">
        <inertial>
            <origin xyz="0 0 1.3522688148498228" rpy="0 0 0"/>
            <mass value="1" />
            <inertia ixx="100" ixy="0" ixz="0" iyy="100" iyz="0" izz="100" />
        </inertial>
        <visual>
            <origin xyz="0 0 1.3522688148498228" rpy="0 0 0"/>
            <geometry>
                <box size="2.796567646338132 1.0209525181571801 2.7045376296996455" />
            </geometry>
            <material name="Green">
                <color rgba="0 180.0 0.0 1.0"/>
            </material>
        </visual>
        <collision>
            <origin xyz="0 0 1.3522688148498228" rpy="0 0 0"/>
            <geometry>
                <box size="2.796567646338132 1.0209525181571801 2.7045376296996455" />
            </geometry>
        </collision>
    </link>
    <link name="Leg1">
        <inertial>
            <origin xyz="0 1.3703183966449493 0" rpy="0 0 0"/>
            <mass value="1" />
            <inertia ixx="100" ixy="0" ixz="0" iyy="100" iyz="0" izz="100" />
        </inertial>
        <visual>
            <origin xyz="0 1.3703183966449493 0" rpy="0 0 0"/>
            <geometry>
                <box size="2.5769018389328404 2.7406367932898985 1.7856451730104348" />
            </geometry>
            <material name="Blue">
                <color rgba="0 1.0 1.0 1.0"/>
            </material>
        </visual>
        <collision>
            <origin xyz="0 1.3703183966449493 0" rpy="0 0 0"/>
            <geometry>
                <box size="2.5769018389328404 2.7406367932898985 1.7856451730104348" />
            </geometry>
        </collision>
    </link>
    <link name="Leg2">
        <inertial>
            <origin xyz="1.3265876707608193 0 0" rpy="0 0 0"/>
            <mass value="1" />
            <inertia ixx="100" ixy="0" ixz="0" iyy="100" iyz="0" izz="100" />
        </inertial>
        <visual>
            <origin xyz="1.3265876707608193 0 0" rpy="0 0 0"/>
            <geometry>
                <box size="2.6531753415216386 2.939812176345467 1.6702581631883686" />
            </geometry>
            <material name="Blue">
                <color rgba="0 1.0 1.0 1.0"/>
            </material>
        </visual>
        <collision>
            <origin xyz="1.3265876707608193 0 0" rpy="0 0 0"/>
            <geometry>
                <box size="2.6531753415216386 2.939812176345467 1.6702581631883686" />
            </geometry>
        </collision>
    </link>
    <link name="Leg3">
        <inertial>
            <origin xyz="1.435566331699318 0 0" rpy="0 0 0"/>
            <mass value="1" />
            <inertia ixx="100" ixy="0" ixz="0" iyy="100" iyz="0" izz="100" />
        </inertial>
        <visual>
            <origin xyz="1.435566331699318 0 0" rpy="0 0 0"/>
            <geometry>
                <box size="2.871132663398636 1.9349210191781785 2.14355992091866" />
            </geometry>
            <material name="Blue">
                <color rgba="0 1.0 1.0 1.0"/>
            </material>
        </visual>
        <collision>
            <origin xyz="1.435566331699318 0 0" rpy="0 0 0"/>
            <geometry>
                <box size="2.871132663398636 1.9349210191781785 2.14355992091866" />
            </geometry>
        </collision>
    </link>
    <link name="Leg4">
        <inertial>
            <origin xyz="1.0453366795193242 0 0" rpy="0 0 0"/>
            <mass value="1" />
            <inertia ixx="100" ixy="0" ixz="0" iyy="100" iyz="0" izz="100" />
        </inertial>
        <visual>
            <origin xyz="1.0453366795193242 0 0" rpy="0 0 0"/>
            <geometry>
                <box size="2.0906733590386484 1.191509969656596 1.1310214259669433" />
            </geometry>
            <material name="Blue">
                <color rgba="0 1.0 1.0 1.0"/>
            </material>
        </visual>
        <collision>
            <origin xyz="1.0453366795193242 0 0" rpy="0 0 0"/>
            <geometry>
                <box size="2.0906733590386484 1.191509969656596 1.1310214259669433" />
            </geometry>
        </collision>
    </link>
    <link name="Leg5">
        <inertial>
            <origin xyz="1.0252530363444725 0 0" rpy="0 0 0"/>
            <mass value="1" />
            <inertia ixx="100" ixy="0" ixz="0" iyy="100" iyz="0" izz="100" />
        </inertial>
        <visual>
            <origin xyz="1.0252530363444725 0 0" rpy="0 0 0"/>
            <geometry>
                <box size="2.050506072688945 1.716999977555314 2.1116750684776293" />
            </geometry>
            <material name="Blue">
                <color rgba="0 1.0 1.0 1.0"/>
            </material>
        </visual>
        <collision>
            <origin xyz="1.0252530363444725 0 0" rpy="0 0 0"/>
            <geometry>
                <box size="2.050506072688945 1.716999977555314 2.1116750684776293" />
            </geometry>
        </collision>
    </link>
    <link name="Leg6">
        <inertial>
            <origin xyz="0.778019214262072 0 0" rpy="0 0 0"/>
            <mass value="1" />
            <inertia ixx="100" ixy="0" ixz="0" iyy="100" iyz="0" izz="100" />
        </inertial>
        <visual>
            <origin xyz="0.778019214262072 0 0" rpy="0 0 0"/>
            <geometry>
                <box size="1.556038428524144 2.13470291043056 2.3745007031747036" />
            </geometry>
            <material name="Blue">
                <color rgba="0 1.0 1.0 1.0"/>
            </material>
        </visual>
        <collision>
            <origin xyz="0.778019214262072 0 0" rpy="0 0 0"/>
            <geometry>
                <box size="1.556038428524144 2.13470291043056 2.3745007031747036" />
            </geometry>
        </collision>
    </link>
    <link name="Leg7">
        <inertial>
            <origin xyz="0 0.728289607130558 0" rpy="0 0 0"/>
            <mass value="1" />
            <inertia ixx="100" ixy="0" ixz="0" iyy="100" iyz="0" izz="100" />
        </inertial>
        <visual>
            <origin xyz="0 0.728289607130558 0" rpy="0 0 0"/>
            <geometry>
                <box size="2.0448345204755567 1.456579214261116 2.361360649755115" />
            </geometry>
            <material name="Green">
                <color rgba="0 180.0 0.0 1.0"/>
            </material>
        </visual>
        <collision>
            <origin xyz="0 0.728289607130558 0" rpy="0 0 0"/>
            <geometry>
                <box size="2.0448345204755567 1.456579214261116 2.361360649755115" />
            </geometry>
        </collision>
    </link>
    <link name="Leg8">
        <inertial>
            <origin xyz="0 0 1.2116681573665269" rpy="0 0 0"/>
            <mass value="1" />
            <inertia ixx="100" ixy="0" ixz="0" iyy="100" iyz="0" izz="100" />
        </inertial>
        <visual>
            <origin xyz="0 0 1.2116681573665269" rpy="0 0 0"/>
            <geometry>
                <box size="2.8964176255276697 2.45371482620521 2.4233363147330538" />
            </geometry>
            <material name="Blue">
                <color rgba="0 1.0 1.0 1.0"/>
            </material>
        </visual>
        <collision>
            <origin xyz="0 0 1.2116681573665269" rpy="0 0 0"/>
            <geometry>
                <box size="2.8964176255276697 2.45371482620521 2.4233363147330538" />
            </geometry>
        </collision>
    </link>
    <link name="Leg9">
        <inertial>
            <origin xyz="0 0 1.4519388489710539" rpy="0 0 0"/>
            <mass value="1" />
            <inertia ixx="100" ixy="0" ixz="0" iyy="100" iyz="0" izz="100" />
        </inertial>
        <visual>
            <origin xyz="0 0 1.4519388489710539" rpy="0 0 0"/>
            <geometry>
                <box size="1.601369290257193 1.8991888192181618 2.9038776979421077" />
            </geometry>
            <material name="Blue">
                <color rgba="0 1.0 1.0 1.0"/>
            </material>
        </visual>
        <collision>
            <origin xyz="0 0 1.4519388489710539" rpy="0 0 0"/>
            <geometry>
                <box size="1.601369290257193 1.8991888192181618 2.9038776979421077" />
            </geometry>
        </collision>
    </link>
    <link name="Leg10">
        <inertial>
            <origin xyz="0 0 1.2693414907810439" rpy="0 0 0"/>
            <mass value="1" />
            <inertia ixx="100" ixy="0" ixz="0" iyy="100" iyz="0" izz="100" />
        </inertial>
        <visual>
            <origin xyz="0 0 1.2693414907810439" rpy="0 0 0"/>
            <geometry>
                <box size="1.7202098531500645 1.8448066566682497 2.5386829815620877" />
            </geometry>
            <material name="Blue">
                <color rgba="0 1.0 1.0 1.0"/>
            </material>
        </visual>
        <collision>
            <origin xyz="0 0 1.2693414907810439" rpy="0 0 0"/>
            <geometry>
                <box size="1.7202098531500645 1.8448066566682497 2.5386829815620877" />
            </geometry>
        </collision>
    </link>
    <link name="Leg11">
        <inertial>
            <origin xyz="1.4011300868457686 0 0" rpy="0 0 0"/>
            <mass value="1" />
            <inertia ixx="100" ixy="0" ixz="0" iyy="100" iyz="0" izz="100" />
        </inertial>
        <visual>
            <origin xyz="1.4011300868457686 0 0" rpy="0 0 0"/>
            <geometry>
                <box size="2.802260173691537 2.747036518946809 1.4816959365163382" />
            </geometry>
            <material name="Green">
                <color rgba="0 180.0 0.0 1.0"/>
            </material>
        </visual>
        <collision>
            <origin xyz="1.4011300868457686 0 0" rpy="0 0 0"/>
            <geometry>
                <box size="2.802260173691537 2.747036518946809 1.4816959365163382" />
            </geometry>
        </collision>
    </link>
    <link name="Leg12">
        <inertial>
            <origin xyz="1.3893370517298143 0 0" rpy="0 0 0"/>
            <mass value="1" />
            <inertia ixx="100" ixy="0" ixz="0" iyy="100" iyz="0" izz="100" />
        </inertial>
        <visual>
            <origin xyz="1.3893370517298143 0 0" rpy="0 0 0"/>
            <geometry>
                <box size="2.7786741034596285 2.0882009947377793 1.7968851618139985" />
            </geometry>
            <material name="Green">
                <color rgba="0 180.0 0.0 1.0"/>
            </material>
        </visual>
        <collision>
            <origin xyz="1.3893370517298143 0 0" rpy="0 0 0"/>
            <geometry>
                <box size="2.7786741034596285 2.0882009947377793 1.7968851618139985" />
            </geometry>
        </collision>
    </link>
    <link name="Leg13">
        <inertial>
            <origin xyz="0 1.1629087499996649 0" rpy="0 0 0"/>
            <mass value="1" />
            <inertia ixx="100" ixy="0" ixz="0" iyy="100" iyz="0" izz="100" />
        </inertial>
        <visual>
            <origin xyz="0 1.1629087499996649 0" rpy="0 0 0"/>
            <geometry>
                <box size="2.1374435335439594 2.3258174999993297 2.509611887618648" />
            </geometry>
            <material name="Blue">
                <color rgba="0 1.0 1.0 1.0"/>
            </material>
        </visual>
        <collision>
            <origin xyz="0 1.1629087499996649 0" rpy="0 0 0"/>
            <geometry>
                <box size="2.1374435335439594 2.3258174999993297 2.509611887618648" />
            </geometry>
        </collision>
    </link>
    <link name="Leg14">
        <inertial>
            <origin xyz="0 0.6652910583522005 0" rpy="0 0 0"/>
            <mass value="1" />
            <inertia ixx="100" ixy="0" ixz="0" iyy="100" iyz="0" izz="100" />
        </inertial>
        <visual>
            <origin xyz="0 0.6652910583522005 0" rpy="0 0 0"/>
            <geometry>
                <box size="1.8878346684749276 1.330582116704401 2.6024466671375914" />
            </geometry>
            <material name="Green">
                <color rgba="0 180.0 0.0 1.0"/>
            </material>
        </visual>
        <collision>
            <origin xyz="0 0.6652910583522005 0" rpy="0 0 0"/>
            <geometry>
                <box size="1.8878346684749276 1.330582116704401 2.6024466671375914" />
            </geometry>
        </collision>
    </link>
    <link name="Leg15">
        <inertial>
            <origin xyz="0 0 0.5023579132864837" rpy="0 0 0"/>
            <mass value="1" />
            <inertia ixx="100" ixy="0" ixz="0" iyy="100" iyz="0" izz="100" />
        </inertial>
        <visual>
            <origin xyz="0 0 0.5023579132864837" rpy="0 0 0"/>
            <geometry>
                <box size="2.9696962561426647 1.91134444807745 1.0047158265729674" />
            </geometry>
            <material name="Blue">
                <color rgba="0 1.0 1.0 1.0"/>
            </material>
        </visual>
        <collision>
            <origin xyz="0 0 0.5023579132864837" rpy="0 0 0"/>
            <geometry>
                <box size="2.9696962561426647 1.91134444807745 1.0047158265729674" />
            </geometry>
        </collision>
    </link>
    <link name="Leg16">
        <inertial>
            <origin xyz="0.6161155139202021 0 0" rpy="0 0 0"/>
            <mass value="1" />
            <inertia ixx="100" ixy="0" ixz="0" iyy="100" iyz="0" izz="100" />
        </inertial>
        <visual>
            <origin xyz="0.6161155139202021 0 0" rpy="0 0 0"/>
            <geometry>
                <box size="1.2322310278404043 2.3346641621769195 2.781794379062771" />
            </geometry>
            <material name="Green">
                <color rgba="0 180.0 0.0 1.0"/>
            </material>
        </visual>
        <collision>
            <origin xyz="0.6161155139202021 0 0" rpy="0 0 0"/>
            <geometry>
                <box size="1.2322310278404043 2.3346641621769195 2.781794379062771" />
            </geometry>
        </collision>
    </link>
    <link name="Leg17">
        <inertial>
            <origin xyz="0 0 0.6273102188733987" rpy="0 0 0"/>
            <mass value="1" />
            <inertia ixx="100" ixy="0" ixz="0" iyy="100" iyz="0" izz="100" />
        </inertial>
        <visual>
            <origin xyz="0 0 0.6273102188733987" rpy="0 0 0"/>
            <geometry>
                <box size="2.1989176290621844 2.8082449142163117 1.2546204377467973" />
            </geometry>
            <material name="Green">
                <color rgba="0 180.0 0.0 1.0"/>
            </material>
        </visual>
        <collision>
            <origin xyz="0 0 0.6273102188733987" rpy="0 0 0"/>
            <geometry>
                <box size="2.1989176290621844 2.8082449142163117 1.2546204377467973" />
            </geometry>
        </collision>
    </link>
    <link name="Leg18">
        <inertial>
            <origin xyz="0 0 0.766746319835252" rpy="0 0 0"/>
            <mass value="1" />
            <inertia ixx="100" ixy="0" ixz="0" iyy="100" iyz="0" izz="100" />
        </inertial>
        <visual>
            <origin xyz="0 0 0.766746319835252" rpy="0 0 0"/>
            <geometry>
                <box size="2.3407610401288887 2.750038540630614 1.533492639670504" />
            </geometry>
            <material name="Green">
                <color rgba="0 180.0 0.0 1.0"/>
            </material>
        </visual>
        <collision>
            <origin xyz="0 0 0.766746319835252" rpy="0 0 0"/>
            <geometry>
                <box size="2.3407610401288887 2.750038540630614 1.533492639670504" />
            </geometry>
        </collision>
    </link>
    <link name="Leg19">
        <inertial>
            <origin xyz="0 0.6671894147210764 0" rpy="0 0 0"/>
            <mass value="1" />
            <inertia ixx="100" ixy="0" ixz="0" iyy="100" iyz="0" izz="100" />
        </inertial>
        <visual>
            <origin xyz="0 0.6671894147210764 0" rpy="0 0 0"/>
            <geometry>
                <box size="2.0063302067116244 1.3343788294421528 1.338020350929438" />
            </geometry>
            <material name="Green">
                <color rgba="0 180.0 0.0 1.0"/>
            </material>
        </visual>
        <collision>
            <origin xyz="0 0.6671894147210764 0" rpy="0 0 0"/>
            <geometry>
                <box size="2.0063302067116244 1.3343788294421528 1.338020350929438" />
            </geometry>
        </collision>
    </link>
    <link name="Leg20">
        <inertial>
            <origin xyz="0.723569273365466 0 0" rpy="0 0 0"/>
            <mass value="1" />
            <inertia ixx="100" ixy="0" ixz="0" iyy="100" iyz="0" izz="100" />
        </inertial>
        <visual>
            <origin xyz="0.723569273365466 0 0" rpy="0 0 0"/>
            <geometry>
                <box size="1.447138546730932 2.8354720888515326 2.8012109422022338" />
            </geometry>
            <material name="Blue">
                <color rgba="0 1.0 1.0 1.0"/>
            </material>
        </visual>
        <collision>
            <origin xyz="0.723569273365466 0 0" rpy="0 0 0"/>
            <geometry>
                <box size="1.447138546730932 2.8354720888515326 2.8012109422022338" />
            </geometry>
        </collision>
    </link>
    <link name="Leg21">
        <inertial>
            <origin xyz="0.7415658386077758 0 0" rpy="0 0 0"/>
            <mass value="1" />
            <inertia ixx="100" ixy="0" ixz="0" iyy="100" iyz="0" izz="100" />
        </inertial>
        <visual>
            <origin xyz="0.7415658386077758 0 0" rpy="0 0 0"/>
            <geometry>
                <box size="1.4831316772155516 2.1368963931998093 2.726519428516923" />
            </geometry>
            <material name="Blue">
                <color rgba="0 1.0 1.0 1.0"/>
            </material>
        </visual>
        <collision>
            <origin xyz="0.7415658386077758 0 0" rpy="0 0 0"/>
            <geometry>
                <box size="1.4831316772155516 2.1368963931998093 2.726519428516923" />
            </geometry>
        </collision>
    </link>
    <link name="Leg22">
        <inertial>
            <origin xyz="0 0 1.1136881179608151" rpy="0 0 0"/>
            <mass value="1" />
            <inertia ixx="100" ixy="0" ixz="0" iyy="100" iyz="0" izz="100" />
        </inertial>
        <visual>
            <origin xyz="0 0 1.1136881179608151" rpy="0 0 0"/>
            <geometry>
                <box size="1.2513367037169751 1.759672397692022 2.2273762359216303" />
            </geometry>
            <material name="Green">
                <color rgba="0 180.0 0.0 1.0"/>
            </material>
        </visual>
        <collision>
            <origin xyz="0 0 1.1136881179608151" rpy="0 0 0"/>
            <geometry>
                <box size="1.2513367037169751 1.759672397692022 2.2273762359216303" />
            </geometry>
        </collision>
    </link>
    <link name="Leg23">
        <inertial>
            <origin xyz="0 0.8363183026878152 0" rpy="0 0 0"/>
            <mass value="1" />
            <inertia ixx="100" ixy="0" ixz="0" iyy="100" iyz="0" izz="100" />
        </inertial>
        <visual>
            <origin xyz="0 0.8363183026878152 0" rpy="0 0 0"/>
            <geometry>
                <box size="2.4379692458081315 1.6726366053756303 1.1357265897082536" />
            </geometry>
            <material name="Green">
                <color rgba="0 180.0 0.0 1.0"/>
            </material>
        </visual>
        <collision>
            <origin xyz="0 0.8363183026878152 0" rpy="0 0 0"/>
            <geometry>
                <box size="2.4379692458081315 1.6726366053756303 1.1357265897082536" />
            </geometry>
        </collision>
    </link>
    <link name="Leg24">
        <inertial>
            <origin xyz="0 0 0.9395187055653478" rpy="0 0 0"/>
            <mass value="1" />
            <inertia ixx="100" ixy="0" ixz="0" iyy="100" iyz="0" izz="100" />
        </inertial>
        <visual>
            <origin xyz="0 0 0.9395187055653478" rpy="0 0 0"/>
            <geometry>
                <box size="2.3713663579448183 1.9369974718216225 1.8790374111306956" />
            </geometry>
            <material name="Green">
                <color rgba="0 180.0 0.0 1.0"/>
            </material>
        </visual>
        <collision>
            <origin xyz="0 0 0.9395187055653478" rpy="0 0 0"/>
            <geometry>
                <box size="2.3713663579448183 1.9369974718216225 1.8790374111306956" />
            </geometry>
        </collision>
    </link>
    <joint name="Torso_Leg1" type="revolute">
       <parent link="Torso"/>
       <child  link="Leg1"/>
       <origin rpy="0 0 0" xyz="0 0.5104762590785901 1.3522688148498228" />
     <axis xyz="1 0 0"/>
       <limit effort="0.0" lower="-3.14159" upper="3.14159" velocity="0.0"/>
    </joint>
    <joint name="Torso_Leg2" type="revolute">
       <parent link="Torso"/>
       <child  link="Leg2"/>
       <origin rpy="0 0 0" xyz="1.2884509194664202 1.3703183966449493 0" />
     <axis xyz="1 0 0"/>
       <limit effort="0.0" lower="-3.14159" upper="3.14159" velocity="0.0"/>
    </joint>
    <joint name="Leg2_Leg3" type="revolute">
       <parent link="Leg2"/>
       <child  link="Leg3"/>
       <origin rpy="0 0 0" xyz="2.871132663398636 0 0" />
     <axis xyz="1 0 0"/>
       <limit effort="0.0" lower="-3.14159" upper="3.14159" velocity="0.0"/>
    </joint>
    <joint name="Leg3_Leg4" type="revolute">
       <parent link="Leg3"/>
       <child  link="Leg4"/>
       <origin rpy="0 0 0" xyz="2.0906733590386484 0 0" />
     <axis xyz="1 0 0"/>
       <limit effort="0.0" lower="-3.14159" upper="3.14159" velocity="0.0"/>
    </joint>
    <joint name="Leg4_Leg5" type="revolute">
       <parent link="Leg4"/>
       <child  link="Leg5"/>
       <origin rpy="0 0 0" xyz="2.050506072688945 0 0" />
     <axis xyz="1 0 0"/>
       <limit effort="0.0" lower="-3.14159" upper="3.14159" velocity="0.0"/>
    </joint>
    <joint name="Leg1_Leg6" type="revolute">
       <parent link="Leg1"/>
       <child  link="Leg6"/>
       <origin rpy="0 0 0" xyz="2.6531753415216386 0 0" />
     <axis xyz="1 0 0"/>
       <limit effort="0.0" lower="-3.14159" upper="3.14159" velocity="0.0"/>
    </joint>
    <joint name="Leg6_Leg7" type="revolute">
       <parent link="Leg6"/>
       <child  link="Leg7"/>
       <origin rpy="0 0 0" xyz="0 1.456579214261116 0" />
     <axis xyz="1 0 0"/>
       <limit effort="0.0" lower="-3.14159" upper="3.14159" velocity="0.0"/>
    </joint>
    <joint name="Leg2_Leg8" type="revolute">
       <parent link="Leg2"/>
       <child  link="Leg8"/>
       <origin rpy="0 0 0" xyz="2.871132663398636 0 1.07177996045933" />
     <axis xyz="1 0 0"/>
       <limit effort="0.0" lower="-3.14159" upper="3.14159" velocity="0.0"/>
    </joint>
    <joint name="Leg4_Leg9" type="revolute">
       <parent link="Leg4"/>
       <child  link="Leg9"/>
       <origin rpy="0 0 0" xyz="2.050506072688945 0 1.0558375342388147" />
     <axis xyz="1 0 0"/>
       <limit effort="0.0" lower="-3.14159" upper="3.14159" velocity="0.0"/>
    </joint>
    <joint name="Leg3_Leg10" type="revolute">
       <parent link="Leg3"/>
       <child  link="Leg10"/>
       <origin rpy="0 0 0" xyz="2.0906733590386484 0 0.5655107129834717" />
     <axis xyz="1 0 0"/>
       <limit effort="0.0" lower="-3.14159" upper="3.14159" velocity="0.0"/>
    </joint>
    <joint name="Leg9_Leg11" type="revolute">
       <parent link="Leg9"/>
       <child  link="Leg11"/>
       <origin rpy="0 0 0" xyz="0.8601049265750322 0 1.2693414907810439" />
     <axis xyz="1 0 0"/>
       <limit effort="0.0" lower="-3.14159" upper="3.14159" velocity="0.0"/>
    </joint>
    <joint name="Leg11_Leg12" type="revolute">
       <parent link="Leg11"/>
       <child  link="Leg12"/>
       <origin rpy="0 0 0" xyz="2.7786741034596285 0 0" />
     <axis xyz="1 0 0"/>
       <limit effort="0.0" lower="-3.14159" upper="3.14159" velocity="0.0"/>
    </joint>
    <joint name="Leg5_Leg13" type="revolute">
       <parent link="Leg5"/>
       <child  link="Leg13"/>
       <origin rpy="0 0 0" xyz="0.778019214262072 1.06735145521528 0" />
     <axis xyz="1 0 0"/>
       <limit effort="0.0" lower="-3.14159" upper="3.14159" velocity="0.0"/>
    </joint>
    <joint name="Leg13_Leg14" type="revolute">
       <parent link="Leg13"/>
       <child  link="Leg14"/>
       <origin rpy="0 0 0" xyz="0 1.330582116704401 0" />
     <axis xyz="1 0 0"/>
       <limit effort="0.0" lower="-3.14159" upper="3.14159" velocity="0.0"/>
    </joint>
    <joint name="Leg13_Leg15" type="revolute">
       <parent link="Leg13"/>
       <child  link="Leg15"/>
       <origin rpy="0 0 0" xyz="0 1.330582116704401 1.3012233335687957" />
     <axis xyz="1 0 0"/>
       <limit effort="0.0" lower="-3.14159" upper="3.14159" velocity="0.0"/>
    </joint>
    <joint name="Leg7_Leg16" type="revolute">
       <parent link="Leg7"/>
       <child  link="Leg16"/>
       <origin rpy="0 0 0" xyz="1.4482088127638348 0 1.2116681573665269" />
     <axis xyz="1 0 0"/>
       <limit effort="0.0" lower="-3.14159" upper="3.14159" velocity="0.0"/>
    </joint>
    <joint name="Leg6_Leg17" type="revolute">
       <parent link="Leg6"/>
       <child  link="Leg17"/>
       <origin rpy="0 0 0" xyz="0 1.456579214261116 1.1806803248775575" />
     <axis xyz="1 0 0"/>
       <limit effort="0.0" lower="-3.14159" upper="3.14159" velocity="0.0"/>
    </joint>
    <joint name="Leg15_Leg18" type="revolute">
       <parent link="Leg15"/>
       <child  link="Leg18"/>
       <origin rpy="0 0 0" xyz="0.6161155139202021 0 1.3908971895313855" />
     <axis xyz="1 0 0"/>
       <limit effort="0.0" lower="-3.14159" upper="3.14159" velocity="0.0"/>
    </joint>
    <joint name="Leg2_Leg19" type="revolute">
       <parent link="Leg2"/>
       <child  link="Leg19"/>
       <origin rpy="0 0 0" xyz="2.871132663398636 0.9674605095890892 1.07177996045933" />
     <axis xyz="1 0 0"/>
       <limit effort="0.0" lower="-3.14159" upper="3.14159" velocity="0.0"/>
    </joint>
    <joint name="Leg14_Leg20" type="revolute">
       <parent link="Leg14"/>
       <child  link="Leg20"/>
       <origin rpy="0 0 0" xyz="1.4848481280713324 0 0.5023579132864837" />
     <axis xyz="1 0 0"/>
       <limit effort="0.0" lower="-3.14159" upper="3.14159" velocity="0.0"/>
    </joint>
    <joint name="Leg10_Leg21" type="revolute">
       <parent link="Leg10"/>
       <child  link="Leg21"/>
       <origin rpy="0 0 0" xyz="2.802260173691537 0 0" />
     <axis xyz="1 0 0"/>
       <limit effort="0.0" lower="-3.14159" upper="3.14159" velocity="0.0"/>
    </joint>
    <joint name="Leg16_Leg22" type="revolute">
       <parent link="Leg16"/>
       <child  link="Leg22"/>
       <origin rpy="0 0 0" xyz="0 0 1.2546204377467973" />
     <axis xyz="1 0 0"/>
       <limit effort="0.0" lower="-3.14159" upper="3.14159" velocity="0.0"/>
    </joint>
    <joint name="Leg19_Leg23" type="revolute">
       <parent link="Leg19"/>
       <child  link="Leg23"/>
       <origin rpy="0 0 0" xyz="0.723569273365466 1.4177360444257663 0" />
     <axis xyz="1 0 0"/>
       <limit effort="0.0" lower="-3.14159" upper="3.14159" velocity="0.0"/>
    </joint>
    <joint name="Leg1_Leg24" type="revolute">
       <parent link="Leg1"/>
       <child  link="Leg24"/>
       <origin rpy="0 0 0" xyz="2.6531753415216386 0 0.8351290815941843" />
     <axis xyz="1 0 0"/>
       <limit effort="0.0" lower="-3.14159" upper="3.14159" velocity="0.0"/>
    </joint>
</robot>