<robot name = "robot">
    <link name="Torso">
        <inertial>
            <origin xyz="0 0 1.2035441290441231" rpy="0 0 0"/>
            <mass value="1" />
            <inertia ixx="100" ixy="0" ixz="0" iyy="100" iyz="0" izz="100" />
        </inertial>
        <visual>
            <origin xyz="0 0 1.2035441290441231" rpy="0 0 0"/>
            <geometry>
                <box size="2.9404550650604744 1.8800241053439528 2.4070882580882462" />
            </geometry>
            <material name="Green">
                <color rgba="0 180.0 0.0 1.0"/>
            </material>
        </visual>
        <collision>
            <origin xyz="0 0 1.2035441290441231" rpy="0 0 0"/>
            <geometry>
                <box size="2.9404550650604744 1.8800241053439528 2.4070882580882462" />
            </geometry>
        </collision>
    </link>
    <link name="Leg1">
        <inertial>
            <origin xyz="1.3221597941378946 0 0" rpy="0 0 0"/>
            <mass value="1" />
            <inertia ixx="100" ixy="0" ixz="0" iyy="100" iyz="0" izz="100" />
        </inertial>
        <visual>
            <origin xyz="1.3221597941378946 0 0" rpy="0 0 0"/>
            <geometry>
                <box size="2.6443195882757893 2.01887629490267 1.6256870021547607" />
            </geometry>
            <material name="Blue">
                <color rgba="0 1.0 1.0 1.0"/>
            </material>
        </visual>
        <collision>
            <origin xyz="1.3221597941378946 0 0" rpy="0 0 0"/>
            <geometry>
                <box size="2.6443195882757893 2.01887629490267 1.6256870021547607" />
            </geometry>
        </collision>
    </link>
    <link name="Leg2">
        <inertial>
            <origin xyz="0.5969851335807896 0 0" rpy="0 0 0"/>
            <mass value="1" />
            <inertia ixx="100" ixy="0" ixz="0" iyy="100" iyz="0" izz="100" />
        </inertial>
        <visual>
            <origin xyz="0.5969851335807896 0 0" rpy="0 0 0"/>
            <geometry>
                <box size="1.1939702671615793 2.7168857897350813 1.708403069272978" />
            </geometry>
            <material name="Blue">
                <color rgba="0 1.0 1.0 1.0"/>
            </material>
        </visual>
        <collision>
            <origin xyz="0.5969851335807896 0 0" rpy="0 0 0"/>
            <geometry>
                <box size="1.1939702671615793 2.7168857897350813 1.708403069272978" />
            </geometry>
        </collision>
    </link>
    <link name="Leg3">
        <inertial>
            <origin xyz="1.0421915533114239 0 0" rpy="0 0 0"/>
            <mass value="1" />
            <inertia ixx="100" ixy="0" ixz="0" iyy="100" iyz="0" izz="100" />
        </inertial>
        <visual>
            <origin xyz="1.0421915533114239 0 0" rpy="0 0 0"/>
            <geometry>
                <box size="2.0843831066228478 1.1282682142147016 2.0794413895335238" />
            </geometry>
            <material name="Blue">
                <color rgba="0 1.0 1.0 1.0"/>
            </material>
        </visual>
        <collision>
            <origin xyz="1.0421915533114239 0 0" rpy="0 0 0"/>
            <geometry>
                <box size="2.0843831066228478 1.1282682142147016 2.0794413895335238" />
            </geometry>
        </collision>
    </link>
    <link name="Leg4">
        <inertial>
            <origin xyz="0 1.033264673268661 0" rpy="0 0 0"/>
            <mass value="1" />
            <inertia ixx="100" ixy="0" ixz="0" iyy="100" iyz="0" izz="100" />
        </inertial>
        <visual>
            <origin xyz="0 1.033264673268661 0" rpy="0 0 0"/>
            <geometry>
                <box size="1.8323667774068495 2.066529346537322 1.5144251671239932" />
            </geometry>
            <material name="Green">
                <color rgba="0 180.0 0.0 1.0"/>
            </material>
        </visual>
        <collision>
            <origin xyz="0 1.033264673268661 0" rpy="0 0 0"/>
            <geometry>
                <box size="1.8323667774068495 2.066529346537322 1.5144251671239932" />
            </geometry>
        </collision>
    </link>
    <link name="Leg5">
        <inertial>
            <origin xyz="0 0 1.4503019215575474" rpy="0 0 0"/>
            <mass value="1" />
            <inertia ixx="100" ixy="0" ixz="0" iyy="100" iyz="0" izz="100" />
        </inertial>
        <visual>
            <origin xyz="0 0 1.4503019215575474" rpy="0 0 0"/>
            <geometry>
                <box size="1.0894429615280143 2.5898643437377835 2.900603843115095" />
            </geometry>
            <material name="Blue">
                <color rgba="0 1.0 1.0 1.0"/>
            </material>
        </visual>
        <collision>
            <origin xyz="0 0 1.4503019215575474" rpy="0 0 0"/>
            <geometry>
                <box size="1.0894429615280143 2.5898643437377835 2.900603843115095" />
            </geometry>
        </collision>
    </link>
    <link name="Leg6">
        <inertial>
            <origin xyz="0 0.9518781617993954 0" rpy="0 0 0"/>
            <mass value="1" />
            <inertia ixx="100" ixy="0" ixz="0" iyy="100" iyz="0" izz="100" />
        </inertial>
        <visual>
            <origin xyz="0 0.9518781617993954 0" rpy="0 0 0"/>
            <geometry>
                <box size="1.4301298266324673 1.9037563235987909 1.7834941785173057" />
            </geometry>
            <material name="Blue">
                <color rgba="0 1.0 1.0 1.0"/>
            </material>
        </visual>
        <collision>
            <origin xyz="0 0.9518781617993954 0" rpy="0 0 0"/>
            <geometry>
                <box size="1.4301298266324673 1.9037563235987909 1.7834941785173057" />
            </geometry>
        </collision>
    </link>
    <link name="Leg7">
        <inertial>
            <origin xyz="0.5664059209559288 0 0" rpy="0 0 0"/>
            <mass value="1" />
            <inertia ixx="100" ixy="0" ixz="0" iyy="100" iyz="0" izz="100" />
        </inertial>
        <visual>
            <origin xyz="0.5664059209559288 0 0" rpy="0 0 0"/>
            <geometry>
                <box size="1.1328118419118576 2.751280947864306 1.357477976767533" />
            </geometry>
            <material name="Green">
                <color rgba="0 180.0 0.0 1.0"/>
            </material>
        </visual>
        <collision>
            <origin xyz="0.5664059209559288 0 0" rpy="0 0 0"/>
            <geometry>
                <box size="1.1328118419118576 2.751280947864306 1.357477976767533" />
            </geometry>
        </collision>
    </link>
    <link name="Leg8">
        <inertial>
            <origin xyz="1.025592662355462 0 0" rpy="0 0 0"/>
            <mass value="1" />
            <inertia ixx="100" ixy="0" ixz="0" iyy="100" iyz="0" izz="100" />
        </inertial>
        <visual>
            <origin xyz="1.025592662355462 0 0" rpy="0 0 0"/>
            <geometry>
                <box size="2.051185324710924 2.202550692264876 2.9382567778491926" />
            </geometry>
            <material name="Blue">
                <color rgba="0 1.0 1.0 1.0"/>
            </material>
        </visual>
        <collision>
            <origin xyz="1.025592662355462 0 0" rpy="0 0 0"/>
            <geometry>
                <box size="2.051185324710924 2.202550692264876 2.9382567778491926" />
            </geometry>
        </collision>
    </link>
    <link name="Leg9">
        <inertial>
            <origin xyz="1.266998612103622 0 0" rpy="0 0 0"/>
            <mass value="1" />
            <inertia ixx="100" ixy="0" ixz="0" iyy="100" iyz="0" izz="100" />
        </inertial>
        <visual>
            <origin xyz="1.266998612103622 0 0" rpy="0 0 0"/>
            <geometry>
                <box size="2.533997224207244 2.303124988141264 2.800989516475792" />
            </geometry>
            <material name="Green">
                <color rgba="0 180.0 0.0 1.0"/>
            </material>
        </visual>
        <collision>
            <origin xyz="1.266998612103622 0 0" rpy="0 0 0"/>
            <geometry>
                <box size="2.533997224207244 2.303124988141264 2.800989516475792" />
            </geometry>
        </collision>
    </link>
    <link name="Leg10">
        <inertial>
            <origin xyz="0 0 1.460713383368159" rpy="0 0 0"/>
            <mass value="1" />
            <inertia ixx="100" ixy="0" ixz="0" iyy="100" iyz="0" izz="100" />
        </inertial>
        <visual>
            <origin xyz="0 0 1.460713383368159" rpy="0 0 0"/>
            <geometry>
                <box size="1.251250126010313 2.711532789486782 2.921426766736318" />
            </geometry>
            <material name="Green">
                <color rgba="0 180.0 0.0 1.0"/>
            </material>
        </visual>
        <collision>
            <origin xyz="0 0 1.460713383368159" rpy="0 0 0"/>
            <geometry>
                <box size="1.251250126010313 2.711532789486782 2.921426766736318" />
            </geometry>
        </collision>
    </link>
    <link name="Leg11">
        <inertial>
            <origin xyz="0 0.9757213847699754 0" rpy="0 0 0"/>
            <mass value="1" />
            <inertia ixx="100" ixy="0" ixz="0" iyy="100" iyz="0" izz="100" />
        </inertial>
        <visual>
            <origin xyz="0 0.9757213847699754 0" rpy="0 0 0"/>
            <geometry>
                <box size="1.8290444887470105 1.9514427695399508 1.0388448403247794" />
            </geometry>
            <material name="Green">
                <color rgba="0 180.0 0.0 1.0"/>
            </material>
        </visual>
        <collision>
            <origin xyz="0 0.9757213847699754 0" rpy="0 0 0"/>
            <geometry>
                <box size="1.8290444887470105 1.9514427695399508 1.0388448403247794" />
            </geometry>
        </collision>
    </link>
    <link name="Leg12">
        <inertial>
            <origin xyz="0.7151683724396143 0 0" rpy="0 0 0"/>
            <mass value="1" />
            <inertia ixx="100" ixy="0" ixz="0" iyy="100" iyz="0" izz="100" />
        </inertial>
        <visual>
            <origin xyz="0.7151683724396143 0 0" rpy="0 0 0"/>
            <geometry>
                <box size="1.4303367448792286 1.4644673124950864 1.6461499709942133" />
            </geometry>
            <material name="Green">
                <color rgba="0 180.0 0.0 1.0"/>
            </material>
        </visual>
        <collision>
            <origin xyz="0.7151683724396143 0 0" rpy="0 0 0"/>
            <geometry>
                <box size="1.4303367448792286 1.4644673124950864 1.6461499709942133" />
            </geometry>
        </collision>
    </link>
    <link name="Leg13">
        <inertial>
            <origin xyz="1.0569124362102684 0 0" rpy="0 0 0"/>
            <mass value="1" />
            <inertia ixx="100" ixy="0" ixz="0" iyy="100" iyz="0" izz="100" />
        </inertial>
        <visual>
            <origin xyz="1.0569124362102684 0 0" rpy="0 0 0"/>
            <geometry>
                <box size="2.113824872420537 1.6825718670737675 1.2018463737601264" />
            </geometry>
            <material name="Blue">
                <color rgba="0 1.0 1.0 1.0"/>
            </material>
        </visual>
        <collision>
            <origin xyz="1.0569124362102684 0 0" rpy="0 0 0"/>
            <geometry>
                <box size="2.113824872420537 1.6825718670737675 1.2018463737601264" />
            </geometry>
        </collision>
    </link>
    <link name="Leg14">
        <inertial>
            <origin xyz="1.075949952368752 0 0" rpy="0 0 0"/>
            <mass value="1" />
            <inertia ixx="100" ixy="0" ixz="0" iyy="100" iyz="0" izz="100" />
        </inertial>
        <visual>
            <origin xyz="1.075949952368752 0 0" rpy="0 0 0"/>
            <geometry>
                <box size="2.151899904737504 2.803180172727298 1.5796331249604012" />
            </geometry>
            <material name="Blue">
                <color rgba="0 1.0 1.0 1.0"/>
            </material>
        </visual>
        <collision>
            <origin xyz="1.075949952368752 0 0" rpy="0 0 0"/>
            <geometry>
                <box size="2.151899904737504 2.803180172727298 1.5796331249604012" />
            </geometry>
        </collision>
    </link>
    <link name="Leg15">
        <inertial>
            <origin xyz="0 0 0.7176226402539309" rpy="0 0 0"/>
            <mass value="1" />
            <inertia ixx="100" ixy="0" ixz="0" iyy="100" iyz="0" izz="100" />
        </inertial>
        <visual>
            <origin xyz="0 0 0.7176226402539309" rpy="0 0 0"/>
            <geometry>
                <box size="2.0584422826557502 1.9770487801488734 1.4352452805078617" />
            </geometry>
            <material name="Blue">
                <color rgba="0 1.0 1.0 1.0"/>
            </material>
        </visual>
        <collision>
            <origin xyz="0 0 0.7176226402539309" rpy="0 0 0"/>
            <geometry>
                <box size="2.0584422826557502 1.9770487801488734 1.4352452805078617" />
            </geometry>
        </collision>
    </link>
    <link name="Leg16">
        <inertial>
            <origin xyz="1.0544995714731675 0 0" rpy="0 0 0"/>
            <mass value="1" />
            <inertia ixx="100" ixy="0" ixz="0" iyy="100" iyz="0" izz="100" />
        </inertial>
        <visual>
            <origin xyz="1.0544995714731675 0 0" rpy="0 0 0"/>
            <geometry>
                <box size="2.108999142946335 2.497244706830606 2.97477450275269" />
            </geometry>
            <material name="Green">
                <color rgba="0 180.0 0.0 1.0"/>
            </material>
        </visual>
        <collision>
            <origin xyz="1.0544995714731675 0 0" rpy="0 0 0"/>
            <geometry>
                <box size="2.108999142946335 2.497244706830606 2.97477450275269" />
            </geometry>
        </collision>
    </link>
    <link name="Leg17">
        <inertial>
            <origin xyz="0 0 1.380272112855693" rpy="0 0 0"/>
            <mass value="1" />
            <inertia ixx="100" ixy="0" ixz="0" iyy="100" iyz="0" izz="100" />
        </inertial>
        <visual>
            <origin xyz="0 0 1.380272112855693" rpy="0 0 0"/>
            <geometry>
                <box size="2.5020540517310765 1.368089132478442 2.760544225711386" />
            </geometry>
            <material name="Blue">
                <color rgba="0 1.0 1.0 1.0"/>
            </material>
        </visual>
        <collision>
            <origin xyz="0 0 1.380272112855693" rpy="0 0 0"/>
            <geometry>
                <box size="2.5020540517310765 1.368089132478442 2.760544225711386" />
            </geometry>
        </collision>
    </link>
    <link name="Leg18">
        <inertial>
            <origin xyz="0 0 1.2746105255506102" rpy="0 0 0"/>
            <mass value="1" />
            <inertia ixx="100" ixy="0" ixz="0" iyy="100" iyz="0" izz="100" />
        </inertial>
        <visual>
            <origin xyz="0 0 1.2746105255506102" rpy="0 0 0"/>
            <geometry>
                <box size="1.8963742930113883 2.1856128565297803 2.5492210511012203" />
            </geometry>
            <material name="Green">
                <color rgba="0 180.0 0.0 1.0"/>
            </material>
        </visual>
        <collision>
            <origin xyz="0 0 1.2746105255506102" rpy="0 0 0"/>
            <geometry>
                <box size="1.8963742930113883 2.1856128565297803 2.5492210511012203" />
            </geometry>
        </collision>
    </link>
    <link name="Leg19">
        <inertial>
            <origin xyz="0.9292416394667561 0 0" rpy="0 0 0"/>
            <mass value="1" />
            <inertia ixx="100" ixy="0" ixz="0" iyy="100" iyz="0" izz="100" />
        </inertial>
        <visual>
            <origin xyz="0.9292416394667561 0 0" rpy="0 0 0"/>
            <geometry>
                <box size="1.8584832789335122 1.4036790345270294 1.1080476710502498" />
            </geometry>
            <material name="Blue">
                <color rgba="0 1.0 1.0 1.0"/>
            </material>
        </visual>
        <collision>
            <origin xyz="0.9292416394667561 0 0" rpy="0 0 0"/>
            <geometry>
                <box size="1.8584832789335122 1.4036790345270294 1.1080476710502498" />
            </geometry>
        </collision>
    </link>
    <link name="Leg20">
        <inertial>
            <origin xyz="1.0714057872305949 0 0" rpy="0 0 0"/>
            <mass value="1" />
            <inertia ixx="100" ixy="0" ixz="0" iyy="100" iyz="0" izz="100" />
        </inertial>
        <visual>
            <origin xyz="1.0714057872305949 0 0" rpy="0 0 0"/>
            <geometry>
                <box size="2.1428115744611897 1.4161203085911491 1.5976898031063218" />
            </geometry>
            <material name="Green">
                <color rgba="0 180.0 0.0 1.0"/>
            </material>
        </visual>
        <collision>
            <origin xyz="1.0714057872305949 0 0" rpy="0 0 0"/>
            <geometry>
                <box size="2.1428115744611897 1.4161203085911491 1.5976898031063218" />
            </geometry>
        </collision>
    </link>
    <link name="Leg21">
        <inertial>
            <origin xyz="0 0.890095123742806 0" rpy="0 0 0"/>
            <mass value="1" />
            <inertia ixx="100" ixy="0" ixz="0" iyy="100" iyz="0" izz="100" />
        </inertial>
        <visual>
            <origin xyz="0 0.890095123742806 0" rpy="0 0 0"/>
            <geometry>
                <box size="2.772155176044847 1.780190247485612 1.0172810946408186" />
            </geometry>
            <material name="Green">
                <color rgba="0 180.0 0.0 1.0"/>
            </material>
        </visual>
        <collision>
            <origin xyz="0 0.890095123742806 0" rpy="0 0 0"/>
            <geometry>
                <box size="2.772155176044847 1.780190247485612 1.0172810946408186" />
            </geometry>
        </collision>
    </link>
    <link name="Leg22">
        <inertial>
            <origin xyz="0 1.0260850625463651 0" rpy="0 0 0"/>
            <mass value="1" />
            <inertia ixx="100" ixy="0" ixz="0" iyy="100" iyz="0" izz="100" />
        </inertial>
        <visual>
            <origin xyz="0 1.0260850625463651 0" rpy="0 0 0"/>
            <geometry>
                <box size="1.0982953665022146 2.0521701250927302 1.9169979243383233" />
            </geometry>
            <material name="Green">
                <color rgba="0 180.0 0.0 1.0"/>
            </material>
        </visual>
        <collision>
            <origin xyz="0 1.0260850625463651 0" rpy="0 0 0"/>
            <geometry>
                <box size="1.0982953665022146 2.0521701250927302 1.9169979243383233" />
            </geometry>
        </collision>
    </link>
    <link name="Leg23">
        <inertial>
            <origin xyz="0.7304656582346081 0 0" rpy="0 0 0"/>
            <mass value="1" />
            <inertia ixx="100" ixy="0" ixz="0" iyy="100" iyz="0" izz="100" />
        </inertial>
        <visual>
            <origin xyz="0.7304656582346081 0 0" rpy="0 0 0"/>
            <geometry>
                <box size="1.4609313164692161 1.088076487592799 1.1668987792187413" />
            </geometry>
            <material name="Green">
                <color rgba="0 180.0 0.0 1.0"/>
            </material>
        </visual>
        <collision>
            <origin xyz="0.7304656582346081 0 0" rpy="0 0 0"/>
            <geometry>
                <box size="1.4609313164692161 1.088076487592799 1.1668987792187413" />
            </geometry>
        </collision>
    </link>
    <link name="Leg24">
        <inertial>
            <origin xyz="0 0 1.431251178542521" rpy="0 0 0"/>
            <mass value="1" />
            <inertia ixx="100" ixy="0" ixz="0" iyy="100" iyz="0" izz="100" />
        </inertial>
        <visual>
            <origin xyz="0 0 1.431251178542521" rpy="0 0 0"/>
            <geometry>
                <box size="2.514254754887503 1.3837498616597592 2.862502357085042" />
            </geometry>
            <material name="Green">
                <color rgba="0 180.0 0.0 1.0"/>
            </material>
        </visual>
        <collision>
            <origin xyz="0 0 1.431251178542521" rpy="0 0 0"/>
            <geometry>
                <box size="2.514254754887503 1.3837498616597592 2.862502357085042" />
            </geometry>
        </collision>
    </link>
    <link name="Leg25">
        <inertial>
            <origin xyz="0 0 1.0214154370560768" rpy="0 0 0"/>
            <mass value="1" />
            <inertia ixx="100" ixy="0" ixz="0" iyy="100" iyz="0" izz="100" />
        </inertial>
        <visual>
            <origin xyz="0 0 1.0214154370560768" rpy="0 0 0"/>
            <geometry>
                <box size="2.3318566723906446 1.8587032887622148 2.0428308741121537" />
            </geometry>
            <material name="Green">
                <color rgba="0 180.0 0.0 1.0"/>
            </material>
        </visual>
        <collision>
            <origin xyz="0 0 1.0214154370560768" rpy="0 0 0"/>
            <geometry>
                <box size="2.3318566723906446 1.8587032887622148 2.0428308741121537" />
            </geometry>
        </collision>
    </link>
    <link name="Leg26">
        <inertial>
            <origin xyz="0 0.6567545729621833 0" rpy="0 0 0"/>
            <mass value="1" />
            <inertia ixx="100" ixy="0" ixz="0" iyy="100" iyz="0" izz="100" />
        </inertial>
        <visual>
            <origin xyz="0 0.6567545729621833 0" rpy="0 0 0"/>
            <geometry>
                <box size="1.4767053878756653 1.3135091459243666 1.3623727340261333" />
            </geometry>
            <material name="Green">
                <color rgba="0 180.0 0.0 1.0"/>
            </material>
        </visual>
        <collision>
            <origin xyz="0 0.6567545729621833 0" rpy="0 0 0"/>
            <geometry>
                <box size="1.4767053878756653 1.3135091459243666 1.3623727340261333" />
            </geometry>
        </collision>
    </link>
    <link name="Leg27">
        <inertial>
            <origin xyz="1.2764972664663277 0 0" rpy="0 0 0"/>
            <mass value="1" />
            <inertia ixx="100" ixy="0" ixz="0" iyy="100" iyz="0" izz="100" />
        </inertial>
        <visual>
            <origin xyz="1.2764972664663277 0 0" rpy="0 0 0"/>
            <geometry>
                <box size="2.5529945329326553 1.2261497955568788 2.9980253223961615" />
            </geometry>
            <material name="Blue">
                <color rgba="0 1.0 1.0 1.0"/>
            </material>
        </visual>
        <collision>
            <origin xyz="1.2764972664663277 0 0" rpy="0 0 0"/>
            <geometry>
                <box size="2.5529945329326553 1.2261497955568788 2.9980253223961615" />
            </geometry>
        </collision>
    </link>
    <link name="Leg28">
        <inertial>
            <origin xyz="0 0 0.9693169406316657" rpy="0 0 0"/>
            <mass value="1" />
            <inertia ixx="100" ixy="0" ixz="0" iyy="100" iyz="0" izz="100" />
        </inertial>
        <visual>
            <origin xyz="0 0 0.9693169406316657" rpy="0 0 0"/>
            <geometry>
                <box size="1.0006761650348386 2.85506728108958 1.9386338812633315" />
            </geometry>
            <material name="Green">
                <color rgba="0 180.0 0.0 1.0"/>
            </material>
        </visual>
        <collision>
            <origin xyz="0 0 0.9693169406316657" rpy="0 0 0"/>
            <geometry>
                <box size="1.0006761650348386 2.85506728108958 1.9386338812633315" />
            </geometry>
        </collision>
    </link>
    <joint name="Torso_Leg1" type="revolute">
       <parent link="Torso"/>
       <child  link="Leg1"/>
       <origin rpy="0 0 0" xyz="1.4702275325302372 0 1.2035441290441231" />
     <axis xyz="1 0 0"/>
       <limit effort="0.0" lower="-3.14159" upper="3.14159" velocity="0.0"/>
    </joint>
    <joint name="Leg1_Leg2" type="revolute">
       <parent link="Leg1"/>
       <child  link="Leg2"/>
       <origin rpy="0 0 0" xyz="1.1939702671615793 0 0" />
     <axis xyz="1 0 0"/>
       <limit effort="0.0" lower="-3.14159" upper="3.14159" velocity="0.0"/>
    </joint>
    <joint name="Leg2_Leg3" type="revolute">
       <parent link="Leg2"/>
       <child  link="Leg3"/>
       <origin rpy="0 0 0" xyz="2.0843831066228478 0 0" />
     <axis xyz="1 0 0"/>
       <limit effort="0.0" lower="-3.14159" upper="3.14159" velocity="0.0"/>
    </joint>
    <joint name="Torso_Leg4" type="revolute">
       <parent link="Torso"/>
       <child  link="Leg4"/>
       <origin rpy="0 0 0" xyz="1.3221597941378946 1.009438147451335 0" />
     <axis xyz="1 0 0"/>
       <limit effort="0.0" lower="-3.14159" upper="3.14159" velocity="0.0"/>
    </joint>
    <joint name="Leg4_Leg5" type="revolute">
       <parent link="Leg4"/>
       <child  link="Leg5"/>
       <origin rpy="0 0 0" xyz="0 0 2.900603843115095" />
     <axis xyz="1 0 0"/>
       <limit effort="0.0" lower="-3.14159" upper="3.14159" velocity="0.0"/>
    </joint>
    <joint name="Leg1_Leg6" type="revolute">
       <parent link="Leg1"/>
       <child  link="Leg6"/>
       <origin rpy="0 0 0" xyz="1.1939702671615793 1.3584428948675407 0" />
     <axis xyz="1 0 0"/>
       <limit effort="0.0" lower="-3.14159" upper="3.14159" velocity="0.0"/>
    </joint>
    <joint name="Leg6_Leg7" type="revolute">
       <parent link="Leg6"/>
       <child  link="Leg7"/>
       <origin rpy="0 0 0" xyz="1.1328118419118576 0 0" />
     <axis xyz="1 0 0"/>
       <limit effort="0.0" lower="-3.14159" upper="3.14159" velocity="0.0"/>
    </joint>
    <joint name="Leg5_Leg8" type="revolute">
       <parent link="Leg5"/>
       <child  link="Leg8"/>
       <origin rpy="0 0 0" xyz="0.7150649133162337 0.9518781617993954 0" />
     <axis xyz="1 0 0"/>
       <limit effort="0.0" lower="-3.14159" upper="3.14159" velocity="0.0"/>
    </joint>
    <joint name="Leg4_Leg9" type="revolute">
       <parent link="Leg4"/>
       <child  link="Leg9"/>
       <origin rpy="0 0 0" xyz="0.5447214807640072 0 2.900603843115095" />
     <axis xyz="1 0 0"/>
       <limit effort="0.0" lower="-3.14159" upper="3.14159" velocity="0.0"/>
    </joint>
    <joint name="Leg9_Leg10" type="revolute">
       <parent link="Leg9"/>
       <child  link="Leg10"/>
       <origin rpy="0 0 0" xyz="0 0 2.921426766736318" />
     <axis xyz="1 0 0"/>
       <limit effort="0.0" lower="-3.14159" upper="3.14159" velocity="0.0"/>
    </joint>
    <joint name="Leg9_Leg11" type="revolute">
       <parent link="Leg9"/>
       <child  link="Leg11"/>
       <origin rpy="0 0 0" xyz="0 1.355766394743391 2.921426766736318" />
     <axis xyz="1 0 0"/>
       <limit effort="0.0" lower="-3.14159" upper="3.14159" velocity="0.0"/>
    </joint>
    <joint name="Leg10_Leg12" type="revolute">
       <parent link="Leg10"/>
       <child  link="Leg12"/>
       <origin rpy="0 0 0" xyz="0.9145222443735053 0.9757213847699754 0" />
     <axis xyz="1 0 0"/>
       <limit effort="0.0" lower="-3.14159" upper="3.14159" velocity="0.0"/>
    </joint>
    <joint name="Leg12_Leg13" type="revolute">
       <parent link="Leg12"/>
       <child  link="Leg13"/>
       <origin rpy="0 0 0" xyz="2.113824872420537 0 0" />
     <axis xyz="1 0 0"/>
       <limit effort="0.0" lower="-3.14159" upper="3.14159" velocity="0.0"/>
    </joint>
    <joint name="Leg8_Leg14" type="revolute">
       <parent link="Leg8"/>
       <child  link="Leg14"/>
       <origin rpy="0 0 0" xyz="2.533997224207244 0 0" />
     <axis xyz="1 0 0"/>
       <limit effort="0.0" lower="-3.14159" upper="3.14159" velocity="0.0"/>
    </joint>
    <joint name="Leg13_Leg15" type="revolute">
       <parent link="Leg13"/>
       <child  link="Leg15"/>
       <origin rpy="0 0 0" xyz="1.075949952368752 0 0.7898165624802006" />
     <axis xyz="1 0 0"/>
       <limit effort="0.0" lower="-3.14159" upper="3.14159" velocity="0.0"/>
    </joint>
    <joint name="Leg9_Leg16" type="revolute">
       <parent link="Leg9"/>
       <child  link="Leg16"/>
       <origin rpy="0 0 0" xyz="0.6256250630051565 1.355766394743391 2.921426766736318" />
     <axis xyz="1 0 0"/>
       <limit effort="0.0" lower="-3.14159" upper="3.14159" velocity="0.0"/>
    </joint>
    <joint name="Leg1_Leg17" type="revolute">
       <parent link="Leg1"/>
       <child  link="Leg17"/>
       <origin rpy="0 0 0" xyz="1.1939702671615793 1.3584428948675407 0.854201534636489" />
     <axis xyz="1 0 0"/>
       <limit effort="0.0" lower="-3.14159" upper="3.14159" velocity="0.0"/>
    </joint>
    <joint name="Leg7_Leg18" type="revolute">
       <parent link="Leg7"/>
       <child  link="Leg18"/>
       <origin rpy="0 0 0" xyz="1.025592662355462 0 1.4691283889245963" />
     <axis xyz="1 0 0"/>
       <limit effort="0.0" lower="-3.14159" upper="3.14159" velocity="0.0"/>
    </joint>
    <joint name="Leg17_Leg19" type="revolute">
       <parent link="Leg17"/>
       <child  link="Leg19"/>
       <origin rpy="0 0 0" xyz="0.9481871465056941 0 1.2746105255506102" />
     <axis xyz="1 0 0"/>
       <limit effort="0.0" lower="-3.14159" upper="3.14159" velocity="0.0"/>
    </joint>
    <joint name="Leg11_Leg20" type="revolute">
       <parent link="Leg11"/>
       <child  link="Leg20"/>
       <origin rpy="0 0 0" xyz="1.4303367448792286 0 0" />
     <axis xyz="1 0 0"/>
       <limit effort="0.0" lower="-3.14159" upper="3.14159" velocity="0.0"/>
    </joint>
    <joint name="Leg13_Leg21" type="revolute">
       <parent link="Leg13"/>
       <child  link="Leg21"/>
       <origin rpy="0 0 0" xyz="1.075949952368752 1.401590086363649 0.7898165624802006" />
     <axis xyz="1 0 0"/>
       <limit effort="0.0" lower="-3.14159" upper="3.14159" velocity="0.0"/>
    </joint>
    <joint name="Leg3_Leg22" type="revolute">
       <parent link="Leg3"/>
       <child  link="Leg22"/>
       <origin rpy="0 0 0" xyz="0 2.066529346537322 0" />
     <axis xyz="1 0 0"/>
       <limit effort="0.0" lower="-3.14159" upper="3.14159" velocity="0.0"/>
    </joint>
    <joint name="Leg16_Leg23" type="revolute">
       <parent link="Leg16"/>
       <child  link="Leg23"/>
       <origin rpy="0 0 0" xyz="1.2510270258655383 0 1.380272112855693" />
     <axis xyz="1 0 0"/>
       <limit effort="0.0" lower="-3.14159" upper="3.14159" velocity="0.0"/>
    </joint>
    <joint name="Leg5_Leg24" type="revolute">
       <parent link="Leg5"/>
       <child  link="Leg24"/>
       <origin rpy="0 0 0" xyz="0.7150649133162337 0.9518781617993954 0.8917470892586529" />
     <axis xyz="1 0 0"/>
       <limit effort="0.0" lower="-3.14159" upper="3.14159" velocity="0.0"/>
    </joint>
    <joint name="Leg16_Leg25" type="revolute">
       <parent link="Leg16"/>
       <child  link="Leg25"/>
       <origin rpy="0 0 0" xyz="1.2510270258655383 0 2.760544225711386" />
     <axis xyz="1 0 0"/>
       <limit effort="0.0" lower="-3.14159" upper="3.14159" velocity="0.0"/>
    </joint>
    <joint name="Leg25_Leg26" type="revolute">
       <parent link="Leg25"/>
       <child  link="Leg26"/>
       <origin rpy="0 0 0" xyz="0 1.3135091459243666 0" />
     <axis xyz="1 0 0"/>
       <limit effort="0.0" lower="-3.14159" upper="3.14159" velocity="0.0"/>
    </joint>
    <joint name="Leg3_Leg27" type="revolute">
       <parent link="Leg3"/>
       <child  link="Leg27"/>
       <origin rpy="0 0 0" xyz="0.9161833887034248 2.066529346537322 0" />
     <axis xyz="1 0 0"/>
       <limit effort="0.0" lower="-3.14159" upper="3.14159" velocity="0.0"/>
    </joint>
    <joint name="Leg6_Leg28" type="revolute">
       <parent link="Leg6"/>
       <child  link="Leg28"/>
       <origin rpy="0 0 0" xyz="1.1328118419118576 0 0.6787389883837665" />
     <axis xyz="1 0 0"/>
       <limit effort="0.0" lower="-3.14159" upper="3.14159" velocity="0.0"/>
    </joint>
</robot>