<robot name = "robot">
    <link name="Torso">
        <inertial>
            <origin xyz="0 0 0.7763462291016829" rpy="0 0 0"/>
            <mass value="1" />
            <inertia ixx="100" ixy="0" ixz="0" iyy="100" iyz="0" izz="100" />
        </inertial>
        <visual>
            <origin xyz="0 0 0.7763462291016829" rpy="0 0 0"/>
            <geometry>
                <box size="1.0283183831148899 2.9509864735028346 1.5526924582033659" />
            </geometry>
            <material name="Green">
                <color rgba="0 180.0 0.0 1.0"/>
            </material>
        </visual>
        <collision>
            <origin xyz="0 0 0.7763462291016829" rpy="0 0 0"/>
            <geometry>
                <box size="1.0283183831148899 2.9509864735028346 1.5526924582033659" />
            </geometry>
        </collision>
    </link>
    <link name="Leg1">
        <inertial>
            <origin xyz="0.6002732612476351 0 0" rpy="0 0 0"/>
            <mass value="1" />
            <inertia ixx="100" ixy="0" ixz="0" iyy="100" iyz="0" izz="100" />
        </inertial>
        <visual>
            <origin xyz="0.6002732612476351 0 0" rpy="0 0 0"/>
            <geometry>
                <box size="1.2005465224952703 1.1671580165275965 1.062349171182029" />
            </geometry>
            <material name="Blue">
                <color rgba="0 1.0 1.0 1.0"/>
            </material>
        </visual>
        <collision>
            <origin xyz="0.6002732612476351 0 0" rpy="0 0 0"/>
            <geometry>
                <box size="1.2005465224952703 1.1671580165275965 1.062349171182029" />
            </geometry>
        </collision>
    </link>
    <link name="Leg2">
        <inertial>
            <origin xyz="1.0688216022926817 0 0" rpy="0 0 0"/>
            <mass value="1" />
            <inertia ixx="100" ixy="0" ixz="0" iyy="100" iyz="0" izz="100" />
        </inertial>
        <visual>
            <origin xyz="1.0688216022926817 0 0" rpy="0 0 0"/>
            <geometry>
                <box size="2.1376432045853635 2.71424346870638 1.4481108933896727" />
            </geometry>
            <material name="Green">
                <color rgba="0 180.0 0.0 1.0"/>
            </material>
        </visual>
        <collision>
            <origin xyz="1.0688216022926817 0 0" rpy="0 0 0"/>
            <geometry>
                <box size="2.1376432045853635 2.71424346870638 1.4481108933896727" />
            </geometry>
        </collision>
    </link>
    <link name="Leg3">
        <inertial>
            <origin xyz="0 0 1.4688784318344157" rpy="0 0 0"/>
            <mass value="1" />
            <inertia ixx="100" ixy="0" ixz="0" iyy="100" iyz="0" izz="100" />
        </inertial>
        <visual>
            <origin xyz="0 0 1.4688784318344157" rpy="0 0 0"/>
            <geometry>
                <box size="2.627915693454203 2.582112532035376 2.9377568636688314" />
            </geometry>
            <material name="Blue">
                <color rgba="0 1.0 1.0 1.0"/>
            </material>
        </visual>
        <collision>
            <origin xyz="0 0 1.4688784318344157" rpy="0 0 0"/>
            <geometry>
                <box size="2.627915693454203 2.582112532035376 2.9377568636688314" />
            </geometry>
        </collision>
    </link>
    <link name="Leg4">
        <inertial>
            <origin xyz="0 1.3319521387527353 0" rpy="0 0 0"/>
            <mass value="1" />
            <inertia ixx="100" ixy="0" ixz="0" iyy="100" iyz="0" izz="100" />
        </inertial>
        <visual>
            <origin xyz="0 1.3319521387527353 0" rpy="0 0 0"/>
            <geometry>
                <box size="2.843306658288159 2.6639042775054707 1.3754021618503238" />
            </geometry>
            <material name="Green">
                <color rgba="0 180.0 0.0 1.0"/>
            </material>
        </visual>
        <collision>
            <origin xyz="0 1.3319521387527353 0" rpy="0 0 0"/>
            <geometry>
                <box size="2.843306658288159 2.6639042775054707 1.3754021618503238" />
            </geometry>
        </collision>
    </link>
    <link name="Leg5">
        <inertial>
            <origin xyz="0.9244529906425415 0 0" rpy="0 0 0"/>
            <mass value="1" />
            <inertia ixx="100" ixy="0" ixz="0" iyy="100" iyz="0" izz="100" />
        </inertial>
        <visual>
            <origin xyz="0.9244529906425415 0 0" rpy="0 0 0"/>
            <geometry>
                <box size="1.848905981285083 2.5198367879264882 2.906154333610811" />
            </geometry>
            <material name="Blue">
                <color rgba="0 1.0 1.0 1.0"/>
            </material>
        </visual>
        <collision>
            <origin xyz="0.9244529906425415 0 0" rpy="0 0 0"/>
            <geometry>
                <box size="1.848905981285083 2.5198367879264882 2.906154333610811" />
            </geometry>
        </collision>
    </link>
    <link name="Leg6">
        <inertial>
            <origin xyz="0 0 1.0064092779307479" rpy="0 0 0"/>
            <mass value="1" />
            <inertia ixx="100" ixy="0" ixz="0" iyy="100" iyz="0" izz="100" />
        </inertial>
        <visual>
            <origin xyz="0 0 1.0064092779307479" rpy="0 0 0"/>
            <geometry>
                <box size="1.6176751511414789 2.821609566480115 2.0128185558614957" />
            </geometry>
            <material name="Blue">
                <color rgba="0 1.0 1.0 1.0"/>
            </material>
        </visual>
        <collision>
            <origin xyz="0 0 1.0064092779307479" rpy="0 0 0"/>
            <geometry>
                <box size="1.6176751511414789 2.821609566480115 2.0128185558614957" />
            </geometry>
        </collision>
    </link>
    <link name="Leg7">
        <inertial>
            <origin xyz="0 0 1.2703614401318404" rpy="0 0 0"/>
            <mass value="1" />
            <inertia ixx="100" ixy="0" ixz="0" iyy="100" iyz="0" izz="100" />
        </inertial>
        <visual>
            <origin xyz="0 0 1.2703614401318404" rpy="0 0 0"/>
            <geometry>
                <box size="2.8808853732388973 1.5191886176052705 2.5407228802636808" />
            </geometry>
            <material name="Green">
                <color rgba="0 180.0 0.0 1.0"/>
            </material>
        </visual>
        <collision>
            <origin xyz="0 0 1.2703614401318404" rpy="0 0 0"/>
            <geometry>
                <box size="2.8808853732388973 1.5191886176052705 2.5407228802636808" />
            </geometry>
        </collision>
    </link>
    <link name="Leg8">
        <inertial>
            <origin xyz="0 0 1.319073244587266" rpy="0 0 0"/>
            <mass value="1" />
            <inertia ixx="100" ixy="0" ixz="0" iyy="100" iyz="0" izz="100" />
        </inertial>
        <visual>
            <origin xyz="0 0 1.319073244587266" rpy="0 0 0"/>
            <geometry>
                <box size="1.6079212588710337 1.4532180762508566 2.638146489174532" />
            </geometry>
            <material name="Green">
                <color rgba="0 180.0 0.0 1.0"/>
            </material>
        </visual>
        <collision>
            <origin xyz="0 0 1.319073244587266" rpy="0 0 0"/>
            <geometry>
                <box size="1.6079212588710337 1.4532180762508566 2.638146489174532" />
            </geometry>
        </collision>
    </link>
    <link name="Leg9">
        <inertial>
            <origin xyz="0 0.9672035536382282 0" rpy="0 0 0"/>
            <mass value="1" />
            <inertia ixx="100" ixy="0" ixz="0" iyy="100" iyz="0" izz="100" />
        </inertial>
        <visual>
            <origin xyz="0 0.9672035536382282 0" rpy="0 0 0"/>
            <geometry>
                <box size="2.6471177793109706 1.9344071072764564 1.5130170248029648" />
            </geometry>
            <material name="Green">
                <color rgba="0 180.0 0.0 1.0"/>
            </material>
        </visual>
        <collision>
            <origin xyz="0 0.9672035536382282 0" rpy="0 0 0"/>
            <geometry>
                <box size="2.6471177793109706 1.9344071072764564 1.5130170248029648" />
            </geometry>
        </collision>
    </link>
    <link name="Leg10">
        <inertial>
            <origin xyz="0 0 1.4803144558626569" rpy="0 0 0"/>
            <mass value="1" />
            <inertia ixx="100" ixy="0" ixz="0" iyy="100" iyz="0" izz="100" />
        </inertial>
        <visual>
            <origin xyz="0 0 1.4803144558626569" rpy="0 0 0"/>
            <geometry>
                <box size="1.5081692075868292 2.5071211849846837 2.9606289117253137" />
            </geometry>
            <material name="Blue">
                <color rgba="0 1.0 1.0 1.0"/>
            </material>
        </visual>
        <collision>
            <origin xyz="0 0 1.4803144558626569" rpy="0 0 0"/>
            <geometry>
                <box size="1.5081692075868292 2.5071211849846837 2.9606289117253137" />
            </geometry>
        </collision>
    </link>
    <link name="Leg11">
        <inertial>
            <origin xyz="0 0.8875813529012175 0" rpy="0 0 0"/>
            <mass value="1" />
            <inertia ixx="100" ixy="0" ixz="0" iyy="100" iyz="0" izz="100" />
        </inertial>
        <visual>
            <origin xyz="0 0.8875813529012175 0" rpy="0 0 0"/>
            <geometry>
                <box size="2.407897999496314 1.775162705802435 2.18490458754897" />
            </geometry>
            <material name="Green">
                <color rgba="0 180.0 0.0 1.0"/>
            </material>
        </visual>
        <collision>
            <origin xyz="0 0.8875813529012175 0" rpy="0 0 0"/>
            <geometry>
                <box size="2.407897999496314 1.775162705802435 2.18490458754897" />
            </geometry>
        </collision>
    </link>
    <link name="Leg12">
        <inertial>
            <origin xyz="0 0.7608474944883603 0" rpy="0 0 0"/>
            <mass value="1" />
            <inertia ixx="100" ixy="0" ixz="0" iyy="100" iyz="0" izz="100" />
        </inertial>
        <visual>
            <origin xyz="0 0.7608474944883603 0" rpy="0 0 0"/>
            <geometry>
                <box size="2.7021488337061976 1.5216949889767206 1.1675525581344646" />
            </geometry>
            <material name="Green">
                <color rgba="0 180.0 0.0 1.0"/>
            </material>
        </visual>
        <collision>
            <origin xyz="0 0.7608474944883603 0" rpy="0 0 0"/>
            <geometry>
                <box size="2.7021488337061976 1.5216949889767206 1.1675525581344646" />
            </geometry>
        </collision>
    </link>
    <link name="Leg13">
        <inertial>
            <origin xyz="0.7322281307175353 0 0" rpy="0 0 0"/>
            <mass value="1" />
            <inertia ixx="100" ixy="0" ixz="0" iyy="100" iyz="0" izz="100" />
        </inertial>
        <visual>
            <origin xyz="0.7322281307175353 0 0" rpy="0 0 0"/>
            <geometry>
                <box size="1.4644562614350707 1.6993457883429308 1.4567364735846526" />
            </geometry>
            <material name="Green">
                <color rgba="0 180.0 0.0 1.0"/>
            </material>
        </visual>
        <collision>
            <origin xyz="0.7322281307175353 0 0" rpy="0 0 0"/>
            <geometry>
                <box size="1.4644562614350707 1.6993457883429308 1.4567364735846526" />
            </geometry>
        </collision>
    </link>
    <link name="Leg14">
        <inertial>
            <origin xyz="0 0 1.1262968446383526" rpy="0 0 0"/>
            <mass value="1" />
            <inertia ixx="100" ixy="0" ixz="0" iyy="100" iyz="0" izz="100" />
        </inertial>
        <visual>
            <origin xyz="0 0 1.1262968446383526" rpy="0 0 0"/>
            <geometry>
                <box size="2.350940285047537 2.989179184448604 2.252593689276705" />
            </geometry>
            <material name="Green">
                <color rgba="0 180.0 0.0 1.0"/>
            </material>
        </visual>
        <collision>
            <origin xyz="0 0 1.1262968446383526" rpy="0 0 0"/>
            <geometry>
                <box size="2.350940285047537 2.989179184448604 2.252593689276705" />
            </geometry>
        </collision>
    </link>
    <link name="Leg15">
        <inertial>
            <origin xyz="0 0 1.101104448899596" rpy="0 0 0"/>
            <mass value="1" />
            <inertia ixx="100" ixy="0" ixz="0" iyy="100" iyz="0" izz="100" />
        </inertial>
        <visual>
            <origin xyz="0 0 1.101104448899596" rpy="0 0 0"/>
            <geometry>
                <box size="1.3547540201032446 2.733845783450831 2.202208897799192" />
            </geometry>
            <material name="Blue">
                <color rgba="0 1.0 1.0 1.0"/>
            </material>
        </visual>
        <collision>
            <origin xyz="0 0 1.101104448899596" rpy="0 0 0"/>
            <geometry>
                <box size="1.3547540201032446 2.733845783450831 2.202208897799192" />
            </geometry>
        </collision>
    </link>
    <link name="Leg16">
        <inertial>
            <origin xyz="0 0 0.8765887468100472" rpy="0 0 0"/>
            <mass value="1" />
            <inertia ixx="100" ixy="0" ixz="0" iyy="100" iyz="0" izz="100" />
        </inertial>
        <visual>
            <origin xyz="0 0 0.8765887468100472" rpy="0 0 0"/>
            <geometry>
                <box size="2.0980745999251185 2.6839456108293653 1.7531774936200943" />
            </geometry>
            <material name="Green">
                <color rgba="0 180.0 0.0 1.0"/>
            </material>
        </visual>
        <collision>
            <origin xyz="0 0 0.8765887468100472" rpy="0 0 0"/>
            <geometry>
                <box size="2.0980745999251185 2.6839456108293653 1.7531774936200943" />
            </geometry>
        </collision>
    </link>
    <link name="Leg17">
        <inertial>
            <origin xyz="0 0 0.7989306236789329" rpy="0 0 0"/>
            <mass value="1" />
            <inertia ixx="100" ixy="0" ixz="0" iyy="100" iyz="0" izz="100" />
        </inertial>
        <visual>
            <origin xyz="0 0 0.7989306236789329" rpy="0 0 0"/>
            <geometry>
                <box size="1.8395954691433778 1.281096478104269 1.5978612473578657" />
            </geometry>
            <material name="Blue">
                <color rgba="0 1.0 1.0 1.0"/>
            </material>
        </visual>
        <collision>
            <origin xyz="0 0 0.7989306236789329" rpy="0 0 0"/>
            <geometry>
                <box size="1.8395954691433778 1.281096478104269 1.5978612473578657" />
            </geometry>
        </collision>
    </link>
    <link name="Leg18">
        <inertial>
            <origin xyz="0.9238827318933708 0 0" rpy="0 0 0"/>
            <mass value="1" />
            <inertia ixx="100" ixy="0" ixz="0" iyy="100" iyz="0" izz="100" />
        </inertial>
        <visual>
            <origin xyz="0.9238827318933708 0 0" rpy="0 0 0"/>
            <geometry>
                <box size="1.8477654637867416 2.441319973715224 2.1066581360917365" />
            </geometry>
            <material name="Blue">
                <color rgba="0 1.0 1.0 1.0"/>
            </material>
        </visual>
        <collision>
            <origin xyz="0.9238827318933708 0 0" rpy="0 0 0"/>
            <geometry>
                <box size="1.8477654637867416 2.441319973715224 2.1066581360917365" />
            </geometry>
        </collision>
    </link>
    <link name="Leg19">
        <inertial>
            <origin xyz="0 1.3019386549170826 0" rpy="0 0 0"/>
            <mass value="1" />
            <inertia ixx="100" ixy="0" ixz="0" iyy="100" iyz="0" izz="100" />
        </inertial>
        <visual>
            <origin xyz="0 1.3019386549170826 0" rpy="0 0 0"/>
            <geometry>
                <box size="1.3732355632623947 2.603877309834165 2.6376530121900457" />
            </geometry>
            <material name="Blue">
                <color rgba="0 1.0 1.0 1.0"/>
            </material>
        </visual>
        <collision>
            <origin xyz="0 1.3019386549170826 0" rpy="0 0 0"/>
            <geometry>
                <box size="1.3732355632623947 2.603877309834165 2.6376530121900457" />
            </geometry>
        </collision>
    </link>
    <link name="Leg20">
        <inertial>
            <origin xyz="0 0.9929165581794903 0" rpy="0 0 0"/>
            <mass value="1" />
            <inertia ixx="100" ixy="0" ixz="0" iyy="100" iyz="0" izz="100" />
        </inertial>
        <visual>
            <origin xyz="0 0.9929165581794903 0" rpy="0 0 0"/>
            <geometry>
                <box size="2.710960565335989 1.9858331163589806 1.7624061007841219" />
            </geometry>
            <material name="Blue">
                <color rgba="0 1.0 1.0 1.0"/>
            </material>
        </visual>
        <collision>
            <origin xyz="0 0.9929165581794903 0" rpy="0 0 0"/>
            <geometry>
                <box size="2.710960565335989 1.9858331163589806 1.7624061007841219" />
            </geometry>
        </collision>
    </link>
    <link name="Leg21">
        <inertial>
            <origin xyz="1.2268797708665202 0 0" rpy="0 0 0"/>
            <mass value="1" />
            <inertia ixx="100" ixy="0" ixz="0" iyy="100" iyz="0" izz="100" />
        </inertial>
        <visual>
            <origin xyz="1.2268797708665202 0 0" rpy="0 0 0"/>
            <geometry>
                <box size="2.4537595417330405 1.2878136624634562 2.036293783204557" />
            </geometry>
            <material name="Green">
                <color rgba="0 180.0 0.0 1.0"/>
            </material>
        </visual>
        <collision>
            <origin xyz="1.2268797708665202 0 0" rpy="0 0 0"/>
            <geometry>
                <box size="2.4537595417330405 1.2878136624634562 2.036293783204557" />
            </geometry>
        </collision>
    </link>
    <link name="Leg22">
        <inertial>
            <origin xyz="0 1.4745873896770032 0" rpy="0 0 0"/>
            <mass value="1" />
            <inertia ixx="100" ixy="0" ixz="0" iyy="100" iyz="0" izz="100" />
        </inertial>
        <visual>
            <origin xyz="0 1.4745873896770032 0" rpy="0 0 0"/>
            <geometry>
                <box size="2.289528350535229 2.9491747793540064 2.1361867299981956" />
            </geometry>
            <material name="Green">
                <color rgba="0 180.0 0.0 1.0"/>
            </material>
        </visual>
        <collision>
            <origin xyz="0 1.4745873896770032 0" rpy="0 0 0"/>
            <geometry>
                <box size="2.289528350535229 2.9491747793540064 2.1361867299981956" />
            </geometry>
        </collision>
    </link>
    <link name="Leg23">
        <inertial>
            <origin xyz="0 0 0.5682637271629646" rpy="0 0 0"/>
            <mass value="1" />
            <inertia ixx="100" ixy="0" ixz="0" iyy="100" iyz="0" izz="100" />
        </inertial>
        <visual>
            <origin xyz="0 0 0.5682637271629646" rpy="0 0 0"/>
            <geometry>
                <box size="2.9141332117773215 2.925164953772796 1.1365274543259292" />
            </geometry>
            <material name="Blue">
                <color rgba="0 1.0 1.0 1.0"/>
            </material>
        </visual>
        <collision>
            <origin xyz="0 0 0.5682637271629646" rpy="0 0 0"/>
            <geometry>
                <box size="2.9141332117773215 2.925164953772796 1.1365274543259292" />
            </geometry>
        </collision>
    </link>
    <link name="Leg24">
        <inertial>
            <origin xyz="0 0 0.7935591796087881" rpy="0 0 0"/>
            <mass value="1" />
            <inertia ixx="100" ixy="0" ixz="0" iyy="100" iyz="0" izz="100" />
        </inertial>
        <visual>
            <origin xyz="0 0 0.7935591796087881" rpy="0 0 0"/>
            <geometry>
                <box size="1.5190398709938158 2.0062966404468807 1.5871183592175762" />
            </geometry>
            <material name="Green">
                <color rgba="0 180.0 0.0 1.0"/>
            </material>
        </visual>
        <collision>
            <origin xyz="0 0 0.7935591796087881" rpy="0 0 0"/>
            <geometry>
                <box size="1.5190398709938158 2.0062966404468807 1.5871183592175762" />
            </geometry>
        </collision>
    </link>
    <link name="Leg25">
        <inertial>
            <origin xyz="0 0.9272335093688862 0" rpy="0 0 0"/>
            <mass value="1" />
            <inertia ixx="100" ixy="0" ixz="0" iyy="100" iyz="0" izz="100" />
        </inertial>
        <visual>
            <origin xyz="0 0.9272335093688862 0" rpy="0 0 0"/>
            <geometry>
                <box size="2.770773343774761 1.8544670187377723 1.1614087322378115" />
            </geometry>
            <material name="Green">
                <color rgba="0 180.0 0.0 1.0"/>
            </material>
        </visual>
        <collision>
            <origin xyz="0 0.9272335093688862 0" rpy="0 0 0"/>
            <geometry>
                <box size="2.770773343774761 1.8544670187377723 1.1614087322378115" />
            </geometry>
        </collision>
    </link>
    <link name="Leg26">
        <inertial>
            <origin xyz="0 0 1.250849576750463" rpy="0 0 0"/>
            <mass value="1" />
            <inertia ixx="100" ixy="0" ixz="0" iyy="100" iyz="0" izz="100" />
        </inertial>
        <visual>
            <origin xyz="0 0 1.250849576750463" rpy="0 0 0"/>
            <geometry>
                <box size="1.415890431998204 2.4665832057214034 2.501699153500926" />
            </geometry>
            <material name="Green">
                <color rgba="0 180.0 0.0 1.0"/>
            </material>
        </visual>
        <collision>
            <origin xyz="0 0 1.250849576750463" rpy="0 0 0"/>
            <geometry>
                <box size="1.415890431998204 2.4665832057214034 2.501699153500926" />
            </geometry>
        </collision>
    </link>
    <joint name="Torso_Leg1" type="revolute">
       <parent link="Torso"/>
       <child  link="Leg1"/>
       <origin rpy="0 0 0" xyz="0.5141591915574449 0 0.7763462291016829" />
     <axis xyz="1 0 0"/>
       <limit effort="0.0" lower="-3.14159" upper="3.14159" velocity="0.0"/>
    </joint>
    <joint name="Leg1_Leg2" type="revolute">
       <parent link="Leg1"/>
       <child  link="Leg2"/>
       <origin rpy="0 0 0" xyz="2.1376432045853635 0 0" />
     <axis xyz="1 0 0"/>
       <limit effort="0.0" lower="-3.14159" upper="3.14159" velocity="0.0"/>
    </joint>
    <joint name="Leg1_Leg3" type="revolute">
       <parent link="Leg1"/>
       <child  link="Leg3"/>
       <origin rpy="0 0 0" xyz="2.1376432045853635 0 0.7240554466948363" />
     <axis xyz="1 0 0"/>
       <limit effort="0.0" lower="-3.14159" upper="3.14159" velocity="0.0"/>
    </joint>
    <joint name="Leg2_Leg4" type="revolute">
       <parent link="Leg2"/>
       <child  link="Leg4"/>
       <origin rpy="0 0 0" xyz="0 1.291056266017688 1.4688784318344157" />
     <axis xyz="1 0 0"/>
       <limit effort="0.0" lower="-3.14159" upper="3.14159" velocity="0.0"/>
    </joint>
    <joint name="Leg4_Leg5" type="revolute">
       <parent link="Leg4"/>
       <child  link="Leg5"/>
       <origin rpy="0 0 0" xyz="1.848905981285083 0 0" />
     <axis xyz="1 0 0"/>
       <limit effort="0.0" lower="-3.14159" upper="3.14159" velocity="0.0"/>
    </joint>
    <joint name="Leg5_Leg6" type="revolute">
       <parent link="Leg5"/>
       <child  link="Leg6"/>
       <origin rpy="0 0 0" xyz="0 0 2.0128185558614957" />
     <axis xyz="1 0 0"/>
       <limit effort="0.0" lower="-3.14159" upper="3.14159" velocity="0.0"/>
    </joint>
    <joint name="Torso_Leg7" type="revolute">
       <parent link="Torso"/>
       <child  link="Leg7"/>
       <origin rpy="0 0 0" xyz="0.6002732612476351 0 0.5311745855910145" />
     <axis xyz="1 0 0"/>
       <limit effort="0.0" lower="-3.14159" upper="3.14159" velocity="0.0"/>
    </joint>
    <joint name="Leg3_Leg8" type="revolute">
       <parent link="Leg3"/>
       <child  link="Leg8"/>
       <origin rpy="0 0 0" xyz="0 1.3319521387527353 0.6877010809251619" />
     <axis xyz="1 0 0"/>
       <limit effort="0.0" lower="-3.14159" upper="3.14159" velocity="0.0"/>
    </joint>
    <joint name="Leg1_Leg9" type="revolute">
       <parent link="Leg1"/>
       <child  link="Leg9"/>
       <origin rpy="0 0 0" xyz="2.1376432045853635 1.35712173435319 0.7240554466948363" />
     <axis xyz="1 0 0"/>
       <limit effort="0.0" lower="-3.14159" upper="3.14159" velocity="0.0"/>
    </joint>
    <joint name="Leg7_Leg10" type="revolute">
       <parent link="Leg7"/>
       <child  link="Leg10"/>
       <origin rpy="0 0 0" xyz="0 0 2.638146489174532" />
     <axis xyz="1 0 0"/>
       <limit effort="0.0" lower="-3.14159" upper="3.14159" velocity="0.0"/>
    </joint>
    <joint name="Leg9_Leg11" type="revolute">
       <parent link="Leg9"/>
       <child  link="Leg11"/>
       <origin rpy="0 0 0" xyz="0 1.2535605924923419 1.4803144558626569" />
     <axis xyz="1 0 0"/>
       <limit effort="0.0" lower="-3.14159" upper="3.14159" velocity="0.0"/>
    </joint>
    <joint name="Leg10_Leg12" type="revolute">
       <parent link="Leg10"/>
       <child  link="Leg12"/>
       <origin rpy="0 0 0" xyz="0 1.775162705802435 0" />
     <axis xyz="1 0 0"/>
       <limit effort="0.0" lower="-3.14159" upper="3.14159" velocity="0.0"/>
    </joint>
    <joint name="Leg7_Leg13" type="revolute">
       <parent link="Leg7"/>
       <child  link="Leg13"/>
       <origin rpy="0 0 0" xyz="0.8039606294355168 0 2.638146489174532" />
     <axis xyz="1 0 0"/>
       <limit effort="0.0" lower="-3.14159" upper="3.14159" velocity="0.0"/>
    </joint>
    <joint name="Leg11_Leg14" type="revolute">
       <parent link="Leg11"/>
       <child  link="Leg14"/>
       <origin rpy="0 0 0" xyz="0 0.7608474944883603 0.5837762790672323" />
     <axis xyz="1 0 0"/>
       <limit effort="0.0" lower="-3.14159" upper="3.14159" velocity="0.0"/>
    </joint>
    <joint name="Leg10_Leg15" type="revolute">
       <parent link="Leg10"/>
       <child  link="Leg15"/>
       <origin rpy="0 0 0" xyz="0 1.775162705802435 1.092452293774485" />
     <axis xyz="1 0 0"/>
       <limit effort="0.0" lower="-3.14159" upper="3.14159" velocity="0.0"/>
    </joint>
    <joint name="Leg6_Leg16" type="revolute">
       <parent link="Leg6"/>
       <child  link="Leg16"/>
       <origin rpy="0 0 0" xyz="0 0 2.5407228802636808" />
     <axis xyz="1 0 0"/>
       <limit effort="0.0" lower="-3.14159" upper="3.14159" velocity="0.0"/>
    </joint>
    <joint name="Leg13_Leg17" type="revolute">
       <parent link="Leg13"/>
       <child  link="Leg17"/>
       <origin rpy="0 0 0" xyz="0 0 2.252593689276705" />
     <axis xyz="1 0 0"/>
       <limit effort="0.0" lower="-3.14159" upper="3.14159" velocity="0.0"/>
    </joint>
    <joint name="Leg10_Leg18" type="revolute">
       <parent link="Leg10"/>
       <child  link="Leg18"/>
       <origin rpy="0 0 0" xyz="1.203948999748157 1.775162705802435 1.092452293774485" />
     <axis xyz="1 0 0"/>
       <limit effort="0.0" lower="-3.14159" upper="3.14159" velocity="0.0"/>
    </joint>
    <joint name="Leg14_Leg19" type="revolute">
       <parent link="Leg14"/>
       <child  link="Leg19"/>
       <origin rpy="0 0 0" xyz="0 1.3669228917254155 1.101104448899596" />
     <axis xyz="1 0 0"/>
       <limit effort="0.0" lower="-3.14159" upper="3.14159" velocity="0.0"/>
    </joint>
    <joint name="Leg7_Leg20" type="revolute">
       <parent link="Leg7"/>
       <child  link="Leg20"/>
       <origin rpy="0 0 0" xyz="0.8039606294355168 0.7266090381254283 2.638146489174532" />
     <axis xyz="1 0 0"/>
       <limit effort="0.0" lower="-3.14159" upper="3.14159" velocity="0.0"/>
    </joint>
    <joint name="Leg16_Leg21" type="revolute">
       <parent link="Leg16"/>
       <child  link="Leg21"/>
       <origin rpy="0 0 0" xyz="0.9197977345716889 0 0.7989306236789329" />
     <axis xyz="1 0 0"/>
       <limit effort="0.0" lower="-3.14159" upper="3.14159" velocity="0.0"/>
    </joint>
    <joint name="Leg5_Leg22" type="revolute">
       <parent link="Leg5"/>
       <child  link="Leg22"/>
       <origin rpy="0 0 0" xyz="0 1.4108047832400574 2.0128185558614957" />
     <axis xyz="1 0 0"/>
       <limit effort="0.0" lower="-3.14159" upper="3.14159" velocity="0.0"/>
    </joint>
    <joint name="Leg19_Leg23" type="revolute">
       <parent link="Leg19"/>
       <child  link="Leg23"/>
       <origin rpy="0 0 0" xyz="0 0.9929165581794903 0.8812030503920609" />
     <axis xyz="1 0 0"/>
       <limit effort="0.0" lower="-3.14159" upper="3.14159" velocity="0.0"/>
    </joint>
    <joint name="Leg4_Leg24" type="revolute">
       <parent link="Leg4"/>
       <child  link="Leg24"/>
       <origin rpy="0 0 0" xyz="1.848905981285083 0 1.4530771668054054" />
     <axis xyz="1 0 0"/>
       <limit effort="0.0" lower="-3.14159" upper="3.14159" velocity="0.0"/>
    </joint>
    <joint name="Leg16_Leg25" type="revolute">
       <parent link="Leg16"/>
       <child  link="Leg25"/>
       <origin rpy="0 0 0" xyz="0.9197977345716889 0.6405482390521345 0.7989306236789329" />
     <axis xyz="1 0 0"/>
       <limit effort="0.0" lower="-3.14159" upper="3.14159" velocity="0.0"/>
    </joint>
    <joint name="Leg17_Leg26" type="revolute">
       <parent link="Leg17"/>
       <child  link="Leg26"/>
       <origin rpy="0 0 0" xyz="0.9238827318933708 0 1.0533290680458682" />
     <axis xyz="1 0 0"/>
       <limit effort="0.0" lower="-3.14159" upper="3.14159" velocity="0.0"/>
    </joint>
</robot>