<robot name = "robot">
    <link name="Torso">
        <inertial>
            <origin xyz="0 0 0.7983463552218258" rpy="0 0 0"/>
            <mass value="1" />
            <inertia ixx="100" ixy="0" ixz="0" iyy="100" iyz="0" izz="100" />
        </inertial>
        <visual>
            <origin xyz="0 0 0.7983463552218258" rpy="0 0 0"/>
            <geometry>
                <box size="2.86076342862195 1.1961140043599874 1.5966927104436517" />
            </geometry>
            <material name="Green">
                <color rgba="0 180.0 0.0 1.0"/>
            </material>
        </visual>
        <collision>
            <origin xyz="0 0 0.7983463552218258" rpy="0 0 0"/>
            <geometry>
                <box size="2.86076342862195 1.1961140043599874 1.5966927104436517" />
            </geometry>
        </collision>
    </link>
    <link name="Leg1">
        <inertial>
            <origin xyz="1.1544814178672438 0 0" rpy="0 0 0"/>
            <mass value="1" />
            <inertia ixx="100" ixy="0" ixz="0" iyy="100" iyz="0" izz="100" />
        </inertial>
        <visual>
            <origin xyz="1.1544814178672438 0 0" rpy="0 0 0"/>
            <geometry>
                <box size="2.3089628357344876 1.5453949146384953 1.5986652212021664" />
            </geometry>
            <material name="Green">
                <color rgba="0 180.0 0.0 1.0"/>
            </material>
        </visual>
        <collision>
            <origin xyz="1.1544814178672438 0 0" rpy="0 0 0"/>
            <geometry>
                <box size="2.3089628357344876 1.5453949146384953 1.5986652212021664" />
            </geometry>
        </collision>
    </link>
    <link name="Leg2">
        <inertial>
            <origin xyz="0 0.9222225742347879 0" rpy="0 0 0"/>
            <mass value="1" />
            <inertia ixx="100" ixy="0" ixz="0" iyy="100" iyz="0" izz="100" />
        </inertial>
        <visual>
            <origin xyz="0 0.9222225742347879 0" rpy="0 0 0"/>
            <geometry>
                <box size="2.5103201950117446 1.8444451484695759 2.6957026987603006" />
            </geometry>
            <material name="Green">
                <color rgba="0 180.0 0.0 1.0"/>
            </material>
        </visual>
        <collision>
            <origin xyz="0 0.9222225742347879 0" rpy="0 0 0"/>
            <geometry>
                <box size="2.5103201950117446 1.8444451484695759 2.6957026987603006" />
            </geometry>
        </collision>
    </link>
    <link name="Leg3">
        <inertial>
            <origin xyz="0 0 1.343168478790893" rpy="0 0 0"/>
            <mass value="1" />
            <inertia ixx="100" ixy="0" ixz="0" iyy="100" iyz="0" izz="100" />
        </inertial>
        <visual>
            <origin xyz="0 0 1.343168478790893" rpy="0 0 0"/>
            <geometry>
                <box size="1.6355098969916708 1.9416472815482895 2.686336957581786" />
            </geometry>
            <material name="Blue">
                <color rgba="0 1.0 1.0 1.0"/>
            </material>
        </visual>
        <collision>
            <origin xyz="0 0 1.343168478790893" rpy="0 0 0"/>
            <geometry>
                <box size="1.6355098969916708 1.9416472815482895 2.686336957581786" />
            </geometry>
        </collision>
    </link>
    <link name="Leg4">
        <inertial>
            <origin xyz="1.0361531552579009 0 0" rpy="0 0 0"/>
            <mass value="1" />
            <inertia ixx="100" ixy="0" ixz="0" iyy="100" iyz="0" izz="100" />
        </inertial>
        <visual>
            <origin xyz="1.0361531552579009 0 0" rpy="0 0 0"/>
            <geometry>
                <box size="2.0723063105158017 1.1531977719664783 2.4317166416604197" />
            </geometry>
            <material name="Green">
                <color rgba="0 180.0 0.0 1.0"/>
            </material>
        </visual>
        <collision>
            <origin xyz="1.0361531552579009 0 0" rpy="0 0 0"/>
            <geometry>
                <box size="2.0723063105158017 1.1531977719664783 2.4317166416604197" />
            </geometry>
        </collision>
    </link>
    <link name="Leg5">
        <inertial>
            <origin xyz="0.6285382523908908 0 0" rpy="0 0 0"/>
            <mass value="1" />
            <inertia ixx="100" ixy="0" ixz="0" iyy="100" iyz="0" izz="100" />
        </inertial>
        <visual>
            <origin xyz="0.6285382523908908 0 0" rpy="0 0 0"/>
            <geometry>
                <box size="1.2570765047817816 1.3955824814422506 1.6778687566713404" />
            </geometry>
            <material name="Green">
                <color rgba="0 180.0 0.0 1.0"/>
            </material>
        </visual>
        <collision>
            <origin xyz="0.6285382523908908 0 0" rpy="0 0 0"/>
            <geometry>
                <box size="1.2570765047817816 1.3955824814422506 1.6778687566713404" />
            </geometry>
        </collision>
    </link>
    <link name="Leg6">
        <inertial>
            <origin xyz="1.4931759949573624 0 0" rpy="0 0 0"/>
            <mass value="1" />
            <inertia ixx="100" ixy="0" ixz="0" iyy="100" iyz="0" izz="100" />
        </inertial>
        <visual>
            <origin xyz="1.4931759949573624 0 0" rpy="0 0 0"/>
            <geometry>
                <box size="2.986351989914725 2.9432519746617656 2.9024347098935577" />
            </geometry>
            <material name="Blue">
                <color rgba="0 1.0 1.0 1.0"/>
            </material>
        </visual>
        <collision>
            <origin xyz="1.4931759949573624 0 0" rpy="0 0 0"/>
            <geometry>
                <box size="2.986351989914725 2.9432519746617656 2.9024347098935577" />
            </geometry>
        </collision>
    </link>
    <link name="Leg7">
        <inertial>
            <origin xyz="1.2135526135520265 0 0" rpy="0 0 0"/>
            <mass value="1" />
            <inertia ixx="100" ixy="0" ixz="0" iyy="100" iyz="0" izz="100" />
        </inertial>
        <visual>
            <origin xyz="1.2135526135520265 0 0" rpy="0 0 0"/>
            <geometry>
                <box size="2.427105227104053 1.757537753698184 2.1138107203447047" />
            </geometry>
            <material name="Green">
                <color rgba="0 180.0 0.0 1.0"/>
            </material>
        </visual>
        <collision>
            <origin xyz="1.2135526135520265 0 0" rpy="0 0 0"/>
            <geometry>
                <box size="2.427105227104053 1.757537753698184 2.1138107203447047" />
            </geometry>
        </collision>
    </link>
    <link name="Leg8">
        <inertial>
            <origin xyz="1.331052195787998 0 0" rpy="0 0 0"/>
            <mass value="1" />
            <inertia ixx="100" ixy="0" ixz="0" iyy="100" iyz="0" izz="100" />
        </inertial>
        <visual>
            <origin xyz="1.331052195787998 0 0" rpy="0 0 0"/>
            <geometry>
                <box size="2.662104391575996 2.169476003377272 1.447003364889452" />
            </geometry>
            <material name="Blue">
                <color rgba="0 1.0 1.0 1.0"/>
            </material>
        </visual>
        <collision>
            <origin xyz="1.331052195787998 0 0" rpy="0 0 0"/>
            <geometry>
                <box size="2.662104391575996 2.169476003377272 1.447003364889452" />
            </geometry>
        </collision>
    </link>
    <link name="Leg9">
        <inertial>
            <origin xyz="0 1.1841597949169271 0" rpy="0 0 0"/>
            <mass value="1" />
            <inertia ixx="100" ixy="0" ixz="0" iyy="100" iyz="0" izz="100" />
        </inertial>
        <visual>
            <origin xyz="0 1.1841597949169271 0" rpy="0 0 0"/>
            <geometry>
                <box size="1.2111339289584455 2.3683195898338543 1.4453304274904377" />
            </geometry>
            <material name="Blue">
                <color rgba="0 1.0 1.0 1.0"/>
            </material>
        </visual>
        <collision>
            <origin xyz="0 1.1841597949169271 0" rpy="0 0 0"/>
            <geometry>
                <box size="1.2111339289584455 2.3683195898338543 1.4453304274904377" />
            </geometry>
        </collision>
    </link>
    <link name="Leg10">
        <inertial>
            <origin xyz="0 0.9736219936627015 0" rpy="0 0 0"/>
            <mass value="1" />
            <inertia ixx="100" ixy="0" ixz="0" iyy="100" iyz="0" izz="100" />
        </inertial>
        <visual>
            <origin xyz="0 0.9736219936627015 0" rpy="0 0 0"/>
            <geometry>
                <box size="2.078195869994474 1.947243987325403 1.7257529612272244" />
            </geometry>
            <material name="Blue">
                <color rgba="0 1.0 1.0 1.0"/>
            </material>
        </visual>
        <collision>
            <origin xyz="0 0.9736219936627015 0" rpy="0 0 0"/>
            <geometry>
                <box size="2.078195869994474 1.947243987325403 1.7257529612272244" />
            </geometry>
        </collision>
    </link>
    <link name="Leg11">
        <inertial>
            <origin xyz="0 1.1597977984674563 0" rpy="0 0 0"/>
            <mass value="1" />
            <inertia ixx="100" ixy="0" ixz="0" iyy="100" iyz="0" izz="100" />
        </inertial>
        <visual>
            <origin xyz="0 1.1597977984674563 0" rpy="0 0 0"/>
            <geometry>
                <box size="1.1862841543789522 2.3195955969349127 2.677535873263003" />
            </geometry>
            <material name="Blue">
                <color rgba="0 1.0 1.0 1.0"/>
            </material>
        </visual>
        <collision>
            <origin xyz="0 1.1597977984674563 0" rpy="0 0 0"/>
            <geometry>
                <box size="1.1862841543789522 2.3195955969349127 2.677535873263003" />
            </geometry>
        </collision>
    </link>
    <link name="Leg12">
        <inertial>
            <origin xyz="0 1.2509668693600027 0" rpy="0 0 0"/>
            <mass value="1" />
            <inertia ixx="100" ixy="0" ixz="0" iyy="100" iyz="0" izz="100" />
        </inertial>
        <visual>
            <origin xyz="0 1.2509668693600027 0" rpy="0 0 0"/>
            <geometry>
                <box size="2.448563050059536 2.5019337387200054 1.8836532584443995" />
            </geometry>
            <material name="Blue">
                <color rgba="0 1.0 1.0 1.0"/>
            </material>
        </visual>
        <collision>
            <origin xyz="0 1.2509668693600027 0" rpy="0 0 0"/>
            <geometry>
                <box size="2.448563050059536 2.5019337387200054 1.8836532584443995" />
            </geometry>
        </collision>
    </link>
    <link name="Leg13">
        <inertial>
            <origin xyz="0.8995796361914246 0 0" rpy="0 0 0"/>
            <mass value="1" />
            <inertia ixx="100" ixy="0" ixz="0" iyy="100" iyz="0" izz="100" />
        </inertial>
        <visual>
            <origin xyz="0.8995796361914246 0 0" rpy="0 0 0"/>
            <geometry>
                <box size="1.7991592723828491 1.6228335355446513 1.841707268465191" />
            </geometry>
            <material name="Green">
                <color rgba="0 180.0 0.0 1.0"/>
            </material>
        </visual>
        <collision>
            <origin xyz="0.8995796361914246 0 0" rpy="0 0 0"/>
            <geometry>
                <box size="1.7991592723828491 1.6228335355446513 1.841707268465191" />
            </geometry>
        </collision>
    </link>
    <link name="Leg14">
        <inertial>
            <origin xyz="0 0.6724012020132581 0" rpy="0 0 0"/>
            <mass value="1" />
            <inertia ixx="100" ixy="0" ixz="0" iyy="100" iyz="0" izz="100" />
        </inertial>
        <visual>
            <origin xyz="0 0.6724012020132581 0" rpy="0 0 0"/>
            <geometry>
                <box size="1.5226258169893183 1.3448024040265163 1.3516688517513122" />
            </geometry>
            <material name="Blue">
                <color rgba="0 1.0 1.0 1.0"/>
            </material>
        </visual>
        <collision>
            <origin xyz="0 0.6724012020132581 0" rpy="0 0 0"/>
            <geometry>
                <box size="1.5226258169893183 1.3448024040265163 1.3516688517513122" />
            </geometry>
        </collision>
    </link>
    <link name="Leg15">
        <inertial>
            <origin xyz="1.0515147740387891 0 0" rpy="0 0 0"/>
            <mass value="1" />
            <inertia ixx="100" ixy="0" ixz="0" iyy="100" iyz="0" izz="100" />
        </inertial>
        <visual>
            <origin xyz="1.0515147740387891 0 0" rpy="0 0 0"/>
            <geometry>
                <box size="2.1030295480775782 2.7438116165200084 1.4179703211204835" />
            </geometry>
            <material name="Green">
                <color rgba="0 180.0 0.0 1.0"/>
            </material>
        </visual>
        <collision>
            <origin xyz="1.0515147740387891 0 0" rpy="0 0 0"/>
            <geometry>
                <box size="2.1030295480775782 2.7438116165200084 1.4179703211204835" />
            </geometry>
        </collision>
    </link>
    <link name="Leg16">
        <inertial>
            <origin xyz="0 1.3150114565184925 0" rpy="0 0 0"/>
            <mass value="1" />
            <inertia ixx="100" ixy="0" ixz="0" iyy="100" iyz="0" izz="100" />
        </inertial>
        <visual>
            <origin xyz="0 1.3150114565184925 0" rpy="0 0 0"/>
            <geometry>
                <box size="2.677410174458794 2.630022913036985 1.24969494350682" />
            </geometry>
            <material name="Blue">
                <color rgba="0 1.0 1.0 1.0"/>
            </material>
        </visual>
        <collision>
            <origin xyz="0 1.3150114565184925 0" rpy="0 0 0"/>
            <geometry>
                <box size="2.677410174458794 2.630022913036985 1.24969494350682" />
            </geometry>
        </collision>
    </link>
    <link name="Leg17">
        <inertial>
            <origin xyz="1.3880749418259797 0 0" rpy="0 0 0"/>
            <mass value="1" />
            <inertia ixx="100" ixy="0" ixz="0" iyy="100" iyz="0" izz="100" />
        </inertial>
        <visual>
            <origin xyz="1.3880749418259797 0 0" rpy="0 0 0"/>
            <geometry>
                <box size="2.7761498836519594 2.4789360166477197 1.676629840403818" />
            </geometry>
            <material name="Green">
                <color rgba="0 180.0 0.0 1.0"/>
            </material>
        </visual>
        <collision>
            <origin xyz="1.3880749418259797 0 0" rpy="0 0 0"/>
            <geometry>
                <box size="2.7761498836519594 2.4789360166477197 1.676629840403818" />
            </geometry>
        </collision>
    </link>
    <link name="Leg18">
        <inertial>
            <origin xyz="0 0.5541949824416315 0" rpy="0 0 0"/>
            <mass value="1" />
            <inertia ixx="100" ixy="0" ixz="0" iyy="100" iyz="0" izz="100" />
        </inertial>
        <visual>
            <origin xyz="0 0.5541949824416315 0" rpy="0 0 0"/>
            <geometry>
                <box size="1.6246193426007443 1.108389964883263 2.471897290179882" />
            </geometry>
            <material name="Green">
                <color rgba="0 180.0 0.0 1.0"/>
            </material>
        </visual>
        <collision>
            <origin xyz="0 0.5541949824416315 0" rpy="0 0 0"/>
            <geometry>
                <box size="1.6246193426007443 1.108389964883263 2.471897290179882" />
            </geometry>
        </collision>
    </link>
    <link name="Leg19">
        <inertial>
            <origin xyz="0 0 0.8992355684118547" rpy="0 0 0"/>
            <mass value="1" />
            <inertia ixx="100" ixy="0" ixz="0" iyy="100" iyz="0" izz="100" />
        </inertial>
        <visual>
            <origin xyz="0 0 0.8992355684118547" rpy="0 0 0"/>
            <geometry>
                <box size="2.2491910424768857 2.5376509493356156 1.7984711368237094" />
            </geometry>
            <material name="Blue">
                <color rgba="0 1.0 1.0 1.0"/>
            </material>
        </visual>
        <collision>
            <origin xyz="0 0 0.8992355684118547" rpy="0 0 0"/>
            <geometry>
                <box size="2.2491910424768857 2.5376509493356156 1.7984711368237094" />
            </geometry>
        </collision>
    </link>
    <link name="Leg20">
        <inertial>
            <origin xyz="0 1.1352163200831291 0" rpy="0 0 0"/>
            <mass value="1" />
            <inertia ixx="100" ixy="0" ixz="0" iyy="100" iyz="0" izz="100" />
        </inertial>
        <visual>
            <origin xyz="0 1.1352163200831291 0" rpy="0 0 0"/>
            <geometry>
                <box size="2.3527792720049066 2.2704326401662582 1.0131328834149163" />
            </geometry>
            <material name="Blue">
                <color rgba="0 1.0 1.0 1.0"/>
            </material>
        </visual>
        <collision>
            <origin xyz="0 1.1352163200831291 0" rpy="0 0 0"/>
            <geometry>
                <box size="2.3527792720049066 2.2704326401662582 1.0131328834149163" />
            </geometry>
        </collision>
    </link>
    <link name="Leg21">
        <inertial>
            <origin xyz="1.1728362106179717 0 0" rpy="0 0 0"/>
            <mass value="1" />
            <inertia ixx="100" ixy="0" ixz="0" iyy="100" iyz="0" izz="100" />
        </inertial>
        <visual>
            <origin xyz="1.1728362106179717 0 0" rpy="0 0 0"/>
            <geometry>
                <box size="2.3456724212359434 1.36222079121271 2.0743429830870292" />
            </geometry>
            <material name="Green">
                <color rgba="0 180.0 0.0 1.0"/>
            </material>
        </visual>
        <collision>
            <origin xyz="1.1728362106179717 0 0" rpy="0 0 0"/>
            <geometry>
                <box size="2.3456724212359434 1.36222079121271 2.0743429830870292" />
            </geometry>
        </collision>
    </link>
    <link name="Leg22">
        <inertial>
            <origin xyz="0 0 0.6223484357015061" rpy="0 0 0"/>
            <mass value="1" />
            <inertia ixx="100" ixy="0" ixz="0" iyy="100" iyz="0" izz="100" />
        </inertial>
        <visual>
            <origin xyz="0 0 0.6223484357015061" rpy="0 0 0"/>
            <geometry>
                <box size="2.5805004545747634 1.7017548458382246 1.2446968714030122" />
            </geometry>
            <material name="Green">
                <color rgba="0 180.0 0.0 1.0"/>
            </material>
        </visual>
        <collision>
            <origin xyz="0 0 0.6223484357015061" rpy="0 0 0"/>
            <geometry>
                <box size="2.5805004545747634 1.7017548458382246 1.2446968714030122" />
            </geometry>
        </collision>
    </link>
    <link name="Leg23">
        <inertial>
            <origin xyz="0 0 0.619627301318778" rpy="0 0 0"/>
            <mass value="1" />
            <inertia ixx="100" ixy="0" ixz="0" iyy="100" iyz="0" izz="100" />
        </inertial>
        <visual>
            <origin xyz="0 0 0.619627301318778" rpy="0 0 0"/>
            <geometry>
                <box size="1.2512657407886203 2.02753692154575 1.239254602637556" />
            </geometry>
            <material name="Blue">
                <color rgba="0 1.0 1.0 1.0"/>
            </material>
        </visual>
        <collision>
            <origin xyz="0 0 0.619627301318778" rpy="0 0 0"/>
            <geometry>
                <box size="1.2512657407886203 2.02753692154575 1.239254602637556" />
            </geometry>
        </collision>
    </link>
    <link name="Leg24">
        <inertial>
            <origin xyz="0 0 1.4689335172573486" rpy="0 0 0"/>
            <mass value="1" />
            <inertia ixx="100" ixy="0" ixz="0" iyy="100" iyz="0" izz="100" />
        </inertial>
        <visual>
            <origin xyz="0 0 1.4689335172573486" rpy="0 0 0"/>
            <geometry>
                <box size="2.3511164051172475 2.3058527782560994 2.937867034514697" />
            </geometry>
            <material name="Blue">
                <color rgba="0 1.0 1.0 1.0"/>
            </material>
        </visual>
        <collision>
            <origin xyz="0 0 1.4689335172573486" rpy="0 0 0"/>
            <geometry>
                <box size="2.3511164051172475 2.3058527782560994 2.937867034514697" />
            </geometry>
        </collision>
    </link>
    <link name="Leg25">
        <inertial>
            <origin xyz="0 0.5196331894576129 0" rpy="0 0 0"/>
            <mass value="1" />
            <inertia ixx="100" ixy="0" ixz="0" iyy="100" iyz="0" izz="100" />
        </inertial>
        <visual>
            <origin xyz="0 0.5196331894576129 0" rpy="0 0 0"/>
            <geometry>
                <box size="2.5953275436954 1.0392663789152259 2.394292460150213" />
            </geometry>
            <material name="Green">
                <color rgba="0 180.0 0.0 1.0"/>
            </material>
        </visual>
        <collision>
            <origin xyz="0 0.5196331894576129 0" rpy="0 0 0"/>
            <geometry>
                <box size="2.5953275436954 1.0392663789152259 2.394292460150213" />
            </geometry>
        </collision>
    </link>
    <joint name="Torso_Leg1" type="revolute">
       <parent link="Torso"/>
       <child  link="Leg1"/>
       <origin rpy="0 0 0" xyz="1.430381714310975 0 0.7983463552218258" />
     <axis xyz="1 0 0"/>
       <limit effort="0.0" lower="-3.14159" upper="3.14159" velocity="0.0"/>
    </joint>
    <joint name="Leg1_Leg2" type="revolute">
       <parent link="Leg1"/>
       <child  link="Leg2"/>
       <origin rpy="0 0 0" xyz="0 1.8444451484695759 0" />
     <axis xyz="1 0 0"/>
       <limit effort="0.0" lower="-3.14159" upper="3.14159" velocity="0.0"/>
    </joint>
    <joint name="Leg2_Leg3" type="revolute">
       <parent link="Leg2"/>
       <child  link="Leg3"/>
       <origin rpy="0 0 0" xyz="0 0 2.686336957581786" />
     <axis xyz="1 0 0"/>
       <limit effort="0.0" lower="-3.14159" upper="3.14159" velocity="0.0"/>
    </joint>
    <joint name="Leg3_Leg4" type="revolute">
       <parent link="Leg3"/>
       <child  link="Leg4"/>
       <origin rpy="0 0 0" xyz="2.0723063105158017 0 0" />
     <axis xyz="1 0 0"/>
       <limit effort="0.0" lower="-3.14159" upper="3.14159" velocity="0.0"/>
    </joint>
    <joint name="Leg2_Leg5" type="revolute">
       <parent link="Leg2"/>
       <child  link="Leg5"/>
       <origin rpy="0 0 0" xyz="0.8177549484958354 0 2.686336957581786" />
     <axis xyz="1 0 0"/>
       <limit effort="0.0" lower="-3.14159" upper="3.14159" velocity="0.0"/>
    </joint>
    <joint name="Leg4_Leg6" type="revolute">
       <parent link="Leg4"/>
       <child  link="Leg6"/>
       <origin rpy="0 0 0" xyz="1.2570765047817816 0 0" />
     <axis xyz="1 0 0"/>
       <limit effort="0.0" lower="-3.14159" upper="3.14159" velocity="0.0"/>
    </joint>
    <joint name="Leg6_Leg7" type="revolute">
       <parent link="Leg6"/>
       <child  link="Leg7"/>
       <origin rpy="0 0 0" xyz="2.427105227104053 0 0" />
     <axis xyz="1 0 0"/>
       <limit effort="0.0" lower="-3.14159" upper="3.14159" velocity="0.0"/>
    </joint>
    <joint name="Leg1_Leg8" type="revolute">
       <parent link="Leg1"/>
       <child  link="Leg8"/>
       <origin rpy="0 0 0" xyz="1.2551600975058723 1.8444451484695759 0" />
     <axis xyz="1 0 0"/>
       <limit effort="0.0" lower="-3.14159" upper="3.14159" velocity="0.0"/>
    </joint>
    <joint name="Leg5_Leg9" type="revolute">
       <parent link="Leg5"/>
       <child  link="Leg9"/>
       <origin rpy="0 0 0" xyz="1.4931759949573624 1.4716259873308828 0" />
     <axis xyz="1 0 0"/>
       <limit effort="0.0" lower="-3.14159" upper="3.14159" velocity="0.0"/>
    </joint>
    <joint name="Leg4_Leg10" type="revolute">
       <parent link="Leg4"/>
       <child  link="Leg10"/>
       <origin rpy="0 0 0" xyz="1.2570765047817816 0.6977912407211253 0" />
     <axis xyz="1 0 0"/>
       <limit effort="0.0" lower="-3.14159" upper="3.14159" velocity="0.0"/>
    </joint>
    <joint name="Leg6_Leg11" type="revolute">
       <parent link="Leg6"/>
       <child  link="Leg11"/>
       <origin rpy="0 0 0" xyz="2.427105227104053 0.878768876849092 0" />
     <axis xyz="1 0 0"/>
       <limit effort="0.0" lower="-3.14159" upper="3.14159" velocity="0.0"/>
    </joint>
    <joint name="Leg8_Leg12" type="revolute">
       <parent link="Leg8"/>
       <child  link="Leg12"/>
       <origin rpy="0 0 0" xyz="0 2.3683195898338543 0" />
     <axis xyz="1 0 0"/>
       <limit effort="0.0" lower="-3.14159" upper="3.14159" velocity="0.0"/>
    </joint>
    <joint name="Leg11_Leg13" type="revolute">
       <parent link="Leg11"/>
       <child  link="Leg13"/>
       <origin rpy="0 0 0" xyz="1.224281525029768 1.2509668693600027 0" />
     <axis xyz="1 0 0"/>
       <limit effort="0.0" lower="-3.14159" upper="3.14159" velocity="0.0"/>
    </joint>
    <joint name="Torso_Leg14" type="revolute">
       <parent link="Torso"/>
       <child  link="Leg14"/>
       <origin rpy="0 0 0" xyz="1.1544814178672438 0.7726974573192477 0" />
     <axis xyz="1 0 0"/>
       <limit effort="0.0" lower="-3.14159" upper="3.14159" velocity="0.0"/>
    </joint>
    <joint name="Leg9_Leg15" type="revolute">
       <parent link="Leg9"/>
       <child  link="Leg15"/>
       <origin rpy="0 0 0" xyz="1.039097934997237 0.9736219936627015 0" />
     <axis xyz="1 0 0"/>
       <limit effort="0.0" lower="-3.14159" upper="3.14159" velocity="0.0"/>
    </joint>
    <joint name="Leg9_Leg16" type="revolute">
       <parent link="Leg9"/>
       <child  link="Leg16"/>
       <origin rpy="0 0 0" xyz="1.039097934997237 1.947243987325403 0" />
     <axis xyz="1 0 0"/>
       <limit effort="0.0" lower="-3.14159" upper="3.14159" velocity="0.0"/>
    </joint>
    <joint name="Leg12_Leg17" type="revolute">
       <parent link="Leg12"/>
       <child  link="Leg17"/>
       <origin rpy="0 0 0" xyz="1.7991592723828491 0 0" />
     <axis xyz="1 0 0"/>
       <limit effort="0.0" lower="-3.14159" upper="3.14159" velocity="0.0"/>
    </joint>
    <joint name="Leg16_Leg18" type="revolute">
       <parent link="Leg16"/>
       <child  link="Leg18"/>
       <origin rpy="0 0 0" xyz="1.3880749418259797 1.2394680083238598 0" />
     <axis xyz="1 0 0"/>
       <limit effort="0.0" lower="-3.14159" upper="3.14159" velocity="0.0"/>
    </joint>
    <joint name="Leg17_Leg19" type="revolute">
       <parent link="Leg17"/>
       <child  link="Leg19"/>
       <origin rpy="0 0 0" xyz="0 0.5541949824416315 1.235948645089941" />
     <axis xyz="1 0 0"/>
       <limit effort="0.0" lower="-3.14159" upper="3.14159" velocity="0.0"/>
    </joint>
    <joint name="Leg10_Leg20" type="revolute">
       <parent link="Leg10"/>
       <child  link="Leg20"/>
       <origin rpy="0 0 0" xyz="0 2.3195955969349127 0" />
     <axis xyz="1 0 0"/>
       <limit effort="0.0" lower="-3.14159" upper="3.14159" velocity="0.0"/>
    </joint>
    <joint name="Leg15_Leg21" type="revolute">
       <parent link="Leg15"/>
       <child  link="Leg21"/>
       <origin rpy="0 0 0" xyz="1.338705087229397 1.3150114565184925 0" />
     <axis xyz="1 0 0"/>
       <limit effort="0.0" lower="-3.14159" upper="3.14159" velocity="0.0"/>
    </joint>
    <joint name="Leg9_Leg22" type="revolute">
       <parent link="Leg9"/>
       <child  link="Leg22"/>
       <origin rpy="0 0 0" xyz="1.039097934997237 1.947243987325403 0.8628764806136122" />
     <axis xyz="1 0 0"/>
       <limit effort="0.0" lower="-3.14159" upper="3.14159" velocity="0.0"/>
    </joint>
    <joint name="Leg15_Leg23" type="revolute">
       <parent link="Leg15"/>
       <child  link="Leg23"/>
       <origin rpy="0 0 0" xyz="1.338705087229397 1.3150114565184925 0.62484747175341" />
     <axis xyz="1 0 0"/>
       <limit effort="0.0" lower="-3.14159" upper="3.14159" velocity="0.0"/>
    </joint>
    <joint name="Leg14_Leg24" type="revolute">
       <parent link="Leg14"/>
       <child  link="Leg24"/>
       <origin rpy="0 0 0" xyz="1.0515147740387891 0 0.7089851605602417" />
     <axis xyz="1 0 0"/>
       <limit effort="0.0" lower="-3.14159" upper="3.14159" velocity="0.0"/>
    </joint>
    <joint name="Leg19_Leg25" type="revolute">
       <parent link="Leg19"/>
       <child  link="Leg25"/>
       <origin rpy="0 0 0" xyz="0 2.2704326401662582 0" />
     <axis xyz="1 0 0"/>
       <limit effort="0.0" lower="-3.14159" upper="3.14159" velocity="0.0"/>
    </joint>
</robot>