<robot name = "robot">
    <link name="Torso">
        <inertial>
            <origin xyz="0 0 0.5087102984435963" rpy="0 0 0"/>
            <mass value="1" />
            <inertia ixx="100" ixy="0" ixz="0" iyy="100" iyz="0" izz="100" />
        </inertial>
        <visual>
            <origin xyz="0 0 0.5087102984435963" rpy="0 0 0"/>
            <geometry>
                <box size="2.948592739228901 1.9780810434287226 1.0174205968871926" />
            </geometry>
            <material name="Green">
                <color rgba="0 180.0 0.0 1.0"/>
            </material>
        </visual>
        <collision>
            <origin xyz="0 0 0.5087102984435963" rpy="0 0 0"/>
            <geometry>
                <box size="2.948592739228901 1.9780810434287226 1.0174205968871926" />
            </geometry>
        </collision>
    </link>
    <link name="Leg1">
        <inertial>
            <origin xyz="1.303662383097809 0 0" rpy="0 0 0"/>
            <mass value="1" />
            <inertia ixx="100" ixy="0" ixz="0" iyy="100" iyz="0" izz="100" />
        </inertial>
        <visual>
            <origin xyz="1.303662383097809 0 0" rpy="0 0 0"/>
            <geometry>
                <box size="2.607324766195618 2.6419780292042825 2.2654336438787093" />
            </geometry>
            <material name="Green">
                <color rgba="0 180.0 0.0 1.0"/>
            </material>
        </visual>
        <collision>
            <origin xyz="1.303662383097809 0 0" rpy="0 0 0"/>
            <geometry>
                <box size="2.607324766195618 2.6419780292042825 2.2654336438787093" />
            </geometry>
        </collision>
    </link>
    <link name="Leg2">
        <inertial>
            <origin xyz="0 0.5038377310753582 0" rpy="0 0 0"/>
            <mass value="1" />
            <inertia ixx="100" ixy="0" ixz="0" iyy="100" iyz="0" izz="100" />
        </inertial>
        <visual>
            <origin xyz="0 0.5038377310753582 0" rpy="0 0 0"/>
            <geometry>
                <box size="1.9595018969642533 1.0076754621507165 1.8136904648888919" />
            </geometry>
            <material name="Green">
                <color rgba="0 180.0 0.0 1.0"/>
            </material>
        </visual>
        <collision>
            <origin xyz="0 0.5038377310753582 0" rpy="0 0 0"/>
            <geometry>
                <box size="1.9595018969642533 1.0076754621507165 1.8136904648888919" />
            </geometry>
        </collision>
    </link>
    <link name="Leg3">
        <inertial>
            <origin xyz="0 1.225895442929712 0" rpy="0 0 0"/>
            <mass value="1" />
            <inertia ixx="100" ixy="0" ixz="0" iyy="100" iyz="0" izz="100" />
        </inertial>
        <visual>
            <origin xyz="0 1.225895442929712 0" rpy="0 0 0"/>
            <geometry>
                <box size="2.232142027485526 2.451790885859424 1.528532396116098" />
            </geometry>
            <material name="Blue">
                <color rgba="0 1.0 1.0 1.0"/>
            </material>
        </visual>
        <collision>
            <origin xyz="0 1.225895442929712 0" rpy="0 0 0"/>
            <geometry>
                <box size="2.232142027485526 2.451790885859424 1.528532396116098" />
            </geometry>
        </collision>
    </link>
    <link name="Leg4">
        <inertial>
            <origin xyz="1.418051609609813 0 0" rpy="0 0 0"/>
            <mass value="1" />
            <inertia ixx="100" ixy="0" ixz="0" iyy="100" iyz="0" izz="100" />
        </inertial>
        <visual>
            <origin xyz="1.418051609609813 0 0" rpy="0 0 0"/>
            <geometry>
                <box size="2.836103219219626 2.530952602519744 2.1793164012114232" />
            </geometry>
            <material name="Green">
                <color rgba="0 180.0 0.0 1.0"/>
            </material>
        </visual>
        <collision>
            <origin xyz="1.418051609609813 0 0" rpy="0 0 0"/>
            <geometry>
                <box size="2.836103219219626 2.530952602519744 2.1793164012114232" />
            </geometry>
        </collision>
    </link>
    <link name="Leg5">
        <inertial>
            <origin xyz="1.3798589170700746 0 0" rpy="0 0 0"/>
            <mass value="1" />
            <inertia ixx="100" ixy="0" ixz="0" iyy="100" iyz="0" izz="100" />
        </inertial>
        <visual>
            <origin xyz="1.3798589170700746 0 0" rpy="0 0 0"/>
            <geometry>
                <box size="2.759717834140149 2.3777056443312263 2.531930037882731" />
            </geometry>
            <material name="Green">
                <color rgba="0 180.0 0.0 1.0"/>
            </material>
        </visual>
        <collision>
            <origin xyz="1.3798589170700746 0 0" rpy="0 0 0"/>
            <geometry>
                <box size="2.759717834140149 2.3777056443312263 2.531930037882731" />
            </geometry>
        </collision>
    </link>
    <link name="Leg6">
        <inertial>
            <origin xyz="0.5359597772685138 0 0" rpy="0 0 0"/>
            <mass value="1" />
            <inertia ixx="100" ixy="0" ixz="0" iyy="100" iyz="0" izz="100" />
        </inertial>
        <visual>
            <origin xyz="0.5359597772685138 0 0" rpy="0 0 0"/>
            <geometry>
                <box size="1.0719195545370277 2.1429309414190714 1.7968182605790444" />
            </geometry>
            <material name="Green">
                <color rgba="0 180.0 0.0 1.0"/>
            </material>
        </visual>
        <collision>
            <origin xyz="0.5359597772685138 0 0" rpy="0 0 0"/>
            <geometry>
                <box size="1.0719195545370277 2.1429309414190714 1.7968182605790444" />
            </geometry>
        </collision>
    </link>
    <link name="Leg7">
        <inertial>
            <origin xyz="0.5903876466569398 0 0" rpy="0 0 0"/>
            <mass value="1" />
            <inertia ixx="100" ixy="0" ixz="0" iyy="100" iyz="0" izz="100" />
        </inertial>
        <visual>
            <origin xyz="0.5903876466569398 0 0" rpy="0 0 0"/>
            <geometry>
                <box size="1.1807752933138795 2.021519894218579 1.4923927805284822" />
            </geometry>
            <material name="Blue">
                <color rgba="0 1.0 1.0 1.0"/>
            </material>
        </visual>
        <collision>
            <origin xyz="0.5903876466569398 0 0" rpy="0 0 0"/>
            <geometry>
                <box size="1.1807752933138795 2.021519894218579 1.4923927805284822" />
            </geometry>
        </collision>
    </link>
    <link name="Leg8">
        <inertial>
            <origin xyz="0.8879392894478151 0 0" rpy="0 0 0"/>
            <mass value="1" />
            <inertia ixx="100" ixy="0" ixz="0" iyy="100" iyz="0" izz="100" />
        </inertial>
        <visual>
            <origin xyz="0.8879392894478151 0 0" rpy="0 0 0"/>
            <geometry>
                <box size="1.7758785788956302 2.0606131333736526 1.152348630331933" />
            </geometry>
            <material name="Blue">
                <color rgba="0 1.0 1.0 1.0"/>
            </material>
        </visual>
        <collision>
            <origin xyz="0.8879392894478151 0 0" rpy="0 0 0"/>
            <geometry>
                <box size="1.7758785788956302 2.0606131333736526 1.152348630331933" />
            </geometry>
        </collision>
    </link>
    <link name="Leg9">
        <inertial>
            <origin xyz="0 0 1.4016815536075615" rpy="0 0 0"/>
            <mass value="1" />
            <inertia ixx="100" ixy="0" ixz="0" iyy="100" iyz="0" izz="100" />
        </inertial>
        <visual>
            <origin xyz="0 0 1.4016815536075615" rpy="0 0 0"/>
            <geometry>
                <box size="1.5679704555546985 1.130155053871871 2.803363107215123" />
            </geometry>
            <material name="Green">
                <color rgba="0 180.0 0.0 1.0"/>
            </material>
        </visual>
        <collision>
            <origin xyz="0 0 1.4016815536075615" rpy="0 0 0"/>
            <geometry>
                <box size="1.5679704555546985 1.130155053871871 2.803363107215123" />
            </geometry>
        </collision>
    </link>
    <link name="Leg10">
        <inertial>
            <origin xyz="0 0 0.8775101912771633" rpy="0 0 0"/>
            <mass value="1" />
            <inertia ixx="100" ixy="0" ixz="0" iyy="100" iyz="0" izz="100" />
        </inertial>
        <visual>
            <origin xyz="0 0 0.8775101912771633" rpy="0 0 0"/>
            <geometry>
                <box size="2.976504211505132 1.5189475685647194 1.7550203825543267" />
            </geometry>
            <material name="Blue">
                <color rgba="0 1.0 1.0 1.0"/>
            </material>
        </visual>
        <collision>
            <origin xyz="0 0 0.8775101912771633" rpy="0 0 0"/>
            <geometry>
                <box size="2.976504211505132 1.5189475685647194 1.7550203825543267" />
            </geometry>
        </collision>
    </link>
    <link name="Leg11">
        <inertial>
            <origin xyz="1.4301596719879037 0 0" rpy="0 0 0"/>
            <mass value="1" />
            <inertia ixx="100" ixy="0" ixz="0" iyy="100" iyz="0" izz="100" />
        </inertial>
        <visual>
            <origin xyz="1.4301596719879037 0 0" rpy="0 0 0"/>
            <geometry>
                <box size="2.8603193439758074 2.5655300318395025 1.2493057607254898" />
            </geometry>
            <material name="Green">
                <color rgba="0 180.0 0.0 1.0"/>
            </material>
        </visual>
        <collision>
            <origin xyz="1.4301596719879037 0 0" rpy="0 0 0"/>
            <geometry>
                <box size="2.8603193439758074 2.5655300318395025 1.2493057607254898" />
            </geometry>
        </collision>
    </link>
    <link name="Leg12">
        <inertial>
            <origin xyz="0 1.0389288812420139 0" rpy="0 0 0"/>
            <mass value="1" />
            <inertia ixx="100" ixy="0" ixz="0" iyy="100" iyz="0" izz="100" />
        </inertial>
        <visual>
            <origin xyz="0 1.0389288812420139 0" rpy="0 0 0"/>
            <geometry>
                <box size="1.1137058219732705 2.0778577624840278 1.0151058932694759" />
            </geometry>
            <material name="Blue">
                <color rgba="0 1.0 1.0 1.0"/>
            </material>
        </visual>
        <collision>
            <origin xyz="0 1.0389288812420139 0" rpy="0 0 0"/>
            <geometry>
                <box size="1.1137058219732705 2.0778577624840278 1.0151058932694759" />
            </geometry>
        </collision>
    </link>
    <link name="Leg13">
        <inertial>
            <origin xyz="0 0 1.410087571189838" rpy="0 0 0"/>
            <mass value="1" />
            <inertia ixx="100" ixy="0" ixz="0" iyy="100" iyz="0" izz="100" />
        </inertial>
        <visual>
            <origin xyz="0 0 1.410087571189838" rpy="0 0 0"/>
            <geometry>
                <box size="1.6722223882894036 2.143565621292124 2.820175142379676" />
            </geometry>
            <material name="Green">
                <color rgba="0 180.0 0.0 1.0"/>
            </material>
        </visual>
        <collision>
            <origin xyz="0 0 1.410087571189838" rpy="0 0 0"/>
            <geometry>
                <box size="1.6722223882894036 2.143565621292124 2.820175142379676" />
            </geometry>
        </collision>
    </link>
    <link name="Leg14">
        <inertial>
            <origin xyz="0 0 0.9446034526523956" rpy="0 0 0"/>
            <mass value="1" />
            <inertia ixx="100" ixy="0" ixz="0" iyy="100" iyz="0" izz="100" />
        </inertial>
        <visual>
            <origin xyz="0 0 0.9446034526523956" rpy="0 0 0"/>
            <geometry>
                <box size="2.263358256820512 2.1411571323793983 1.8892069053047913" />
            </geometry>
            <material name="Blue">
                <color rgba="0 1.0 1.0 1.0"/>
            </material>
        </visual>
        <collision>
            <origin xyz="0 0 0.9446034526523956" rpy="0 0 0"/>
            <geometry>
                <box size="2.263358256820512 2.1411571323793983 1.8892069053047913" />
            </geometry>
        </collision>
    </link>
    <link name="Leg15">
        <inertial>
            <origin xyz="0 1.084622708827681 0" rpy="0 0 0"/>
            <mass value="1" />
            <inertia ixx="100" ixy="0" ixz="0" iyy="100" iyz="0" izz="100" />
        </inertial>
        <visual>
            <origin xyz="0 1.084622708827681 0" rpy="0 0 0"/>
            <geometry>
                <box size="1.2006612777920243 2.169245417655362 2.2001387042992295" />
            </geometry>
            <material name="Blue">
                <color rgba="0 1.0 1.0 1.0"/>
            </material>
        </visual>
        <collision>
            <origin xyz="0 1.084622708827681 0" rpy="0 0 0"/>
            <geometry>
                <box size="1.2006612777920243 2.169245417655362 2.2001387042992295" />
            </geometry>
        </collision>
    </link>
    <link name="Leg16">
        <inertial>
            <origin xyz="0.8340044021128252 0 0" rpy="0 0 0"/>
            <mass value="1" />
            <inertia ixx="100" ixy="0" ixz="0" iyy="100" iyz="0" izz="100" />
        </inertial>
        <visual>
            <origin xyz="0.8340044021128252 0 0" rpy="0 0 0"/>
            <geometry>
                <box size="1.6680088042256505 2.8580875099092253 1.14162686326477" />
            </geometry>
            <material name="Green">
                <color rgba="0 180.0 0.0 1.0"/>
            </material>
        </visual>
        <collision>
            <origin xyz="0.8340044021128252 0 0" rpy="0 0 0"/>
            <geometry>
                <box size="1.6680088042256505 2.8580875099092253 1.14162686326477" />
            </geometry>
        </collision>
    </link>
    <link name="Leg17">
        <inertial>
            <origin xyz="1.255363148513983 0 0" rpy="0 0 0"/>
            <mass value="1" />
            <inertia ixx="100" ixy="0" ixz="0" iyy="100" iyz="0" izz="100" />
        </inertial>
        <visual>
            <origin xyz="1.255363148513983 0 0" rpy="0 0 0"/>
            <geometry>
                <box size="2.510726297027966 1.521178870614889 1.1694957286629482" />
            </geometry>
            <material name="Green">
                <color rgba="0 180.0 0.0 1.0"/>
            </material>
        </visual>
        <collision>
            <origin xyz="1.255363148513983 0 0" rpy="0 0 0"/>
            <geometry>
                <box size="2.510726297027966 1.521178870614889 1.1694957286629482" />
            </geometry>
        </collision>
    </link>
    <link name="Leg18">
        <inertial>
            <origin xyz="0 1.2347508300508911 0" rpy="0 0 0"/>
            <mass value="1" />
            <inertia ixx="100" ixy="0" ixz="0" iyy="100" iyz="0" izz="100" />
        </inertial>
        <visual>
            <origin xyz="0 1.2347508300508911 0" rpy="0 0 0"/>
            <geometry>
                <box size="2.3751719240389586 2.4695016601017823 1.06864626403948" />
            </geometry>
            <material name="Blue">
                <color rgba="0 1.0 1.0 1.0"/>
            </material>
        </visual>
        <collision>
            <origin xyz="0 1.2347508300508911 0" rpy="0 0 0"/>
            <geometry>
                <box size="2.3751719240389586 2.4695016601017823 1.06864626403948" />
            </geometry>
        </collision>
    </link>
    <link name="Leg19">
        <inertial>
            <origin xyz="0 0 1.4687066143047933" rpy="0 0 0"/>
            <mass value="1" />
            <inertia ixx="100" ixy="0" ixz="0" iyy="100" iyz="0" izz="100" />
        </inertial>
        <visual>
            <origin xyz="0 0 1.4687066143047933" rpy="0 0 0"/>
            <geometry>
                <box size="2.1267948843609776 2.2924623758408504 2.9374132286095866" />
            </geometry>
            <material name="Blue">
                <color rgba="0 1.0 1.0 1.0"/>
            </material>
        </visual>
        <collision>
            <origin xyz="0 0 1.4687066143047933" rpy="0 0 0"/>
            <geometry>
                <box size="2.1267948843609776 2.2924623758408504 2.9374132286095866" />
            </geometry>
        </collision>
    </link>
    <link name="Leg20">
        <inertial>
            <origin xyz="0 0.5309311692292475 0" rpy="0 0 0"/>
            <mass value="1" />
            <inertia ixx="100" ixy="0" ixz="0" iyy="100" iyz="0" izz="100" />
        </inertial>
        <visual>
            <origin xyz="0 0.5309311692292475 0" rpy="0 0 0"/>
            <geometry>
                <box size="2.2581353061546903 1.061862338458495 2.7615802126332167" />
            </geometry>
            <material name="Blue">
                <color rgba="0 1.0 1.0 1.0"/>
            </material>
        </visual>
        <collision>
            <origin xyz="0 0.5309311692292475 0" rpy="0 0 0"/>
            <geometry>
                <box size="2.2581353061546903 1.061862338458495 2.7615802126332167" />
            </geometry>
        </collision>
    </link>
    <link name="Leg21">
        <inertial>
            <origin xyz="0 0.5269645222713563 0" rpy="0 0 0"/>
            <mass value="1" />
            <inertia ixx="100" ixy="0" ixz="0" iyy="100" iyz="0" izz="100" />
        </inertial>
        <visual>
            <origin xyz="0 0.5269645222713563 0" rpy="0 0 0"/>
            <geometry>
                <box size="2.4582366910156868 1.0539290445427125 2.101924857586467" />
            </geometry>
            <material name="Green">
                <color rgba="0 180.0 0.0 1.0"/>
            </material>
        </visual>
        <collision>
            <origin xyz="0 0.5269645222713563 0" rpy="0 0 0"/>
            <geometry>
                <box size="2.4582366910156868 1.0539290445427125 2.101924857586467" />
            </geometry>
        </collision>
    </link>
    <link name="Leg22">
        <inertial>
            <origin xyz="0 1.0967831640541248 0" rpy="0 0 0"/>
            <mass value="1" />
            <inertia ixx="100" ixy="0" ixz="0" iyy="100" iyz="0" izz="100" />
        </inertial>
        <visual>
            <origin xyz="0 1.0967831640541248 0" rpy="0 0 0"/>
            <geometry>
                <box size="2.0721227190998865 2.1935663281082496 1.492613691938803" />
            </geometry>
            <material name="Blue">
                <color rgba="0 1.0 1.0 1.0"/>
            </material>
        </visual>
        <collision>
            <origin xyz="0 1.0967831640541248 0" rpy="0 0 0"/>
            <geometry>
                <box size="2.0721227190998865 2.1935663281082496 1.492613691938803" />
            </geometry>
        </collision>
    </link>
    <link name="Leg23">
        <inertial>
            <origin xyz="0 0.5346568674175655 0" rpy="0 0 0"/>
            <mass value="1" />
            <inertia ixx="100" ixy="0" ixz="0" iyy="100" iyz="0" izz="100" />
        </inertial>
        <visual>
            <origin xyz="0 0.5346568674175655 0" rpy="0 0 0"/>
            <geometry>
                <box size="2.72453962151955 1.069313734835131 1.6726104024551274" />
            </geometry>
            <material name="Blue">
                <color rgba="0 1.0 1.0 1.0"/>
            </material>
        </visual>
        <collision>
            <origin xyz="0 0.5346568674175655 0" rpy="0 0 0"/>
            <geometry>
                <box size="2.72453962151955 1.069313734835131 1.6726104024551274" />
            </geometry>
        </collision>
    </link>
    <link name="Leg24">
        <inertial>
            <origin xyz="0 0.6632813229825988 0" rpy="0 0 0"/>
            <mass value="1" />
            <inertia ixx="100" ixy="0" ixz="0" iyy="100" iyz="0" izz="100" />
        </inertial>
        <visual>
            <origin xyz="0 0.6632813229825988 0" rpy="0 0 0"/>
            <geometry>
                <box size="2.243352196070556 1.3265626459651976 2.761899653281527" />
            </geometry>
            <material name="Blue">
                <color rgba="0 1.0 1.0 1.0"/>
            </material>
        </visual>
        <collision>
            <origin xyz="0 0.6632813229825988 0" rpy="0 0 0"/>
            <geometry>
                <box size="2.243352196070556 1.3265626459651976 2.761899653281527" />
            </geometry>
        </collision>
    </link>
    <link name="Leg25">
        <inertial>
            <origin xyz="0 1.1399719186758748 0" rpy="0 0 0"/>
            <mass value="1" />
            <inertia ixx="100" ixy="0" ixz="0" iyy="100" iyz="0" izz="100" />
        </inertial>
        <visual>
            <origin xyz="0 1.1399719186758748 0" rpy="0 0 0"/>
            <geometry>
                <box size="2.586865521625489 2.2799438373517495 1.203816334617889" />
            </geometry>
            <material name="Green">
                <color rgba="0 180.0 0.0 1.0"/>
            </material>
        </visual>
        <collision>
            <origin xyz="0 1.1399719186758748 0" rpy="0 0 0"/>
            <geometry>
                <box size="2.586865521625489 2.2799438373517495 1.203816334617889" />
            </geometry>
        </collision>
    </link>
    <link name="Leg26">
        <inertial>
            <origin xyz="0.9659624586963422 0 0" rpy="0 0 0"/>
            <mass value="1" />
            <inertia ixx="100" ixy="0" ixz="0" iyy="100" iyz="0" izz="100" />
        </inertial>
        <visual>
            <origin xyz="0.9659624586963422 0 0" rpy="0 0 0"/>
            <geometry>
                <box size="1.9319249173926845 1.1034675055128542 1.3265254967739621" />
            </geometry>
            <material name="Blue">
                <color rgba="0 1.0 1.0 1.0"/>
            </material>
        </visual>
        <collision>
            <origin xyz="0.9659624586963422 0 0" rpy="0 0 0"/>
            <geometry>
                <box size="1.9319249173926845 1.1034675055128542 1.3265254967739621" />
            </geometry>
        </collision>
    </link>
    <link name="Leg27">
        <inertial>
            <origin xyz="0 0.8522281505571193 0" rpy="0 0 0"/>
            <mass value="1" />
            <inertia ixx="100" ixy="0" ixz="0" iyy="100" iyz="0" izz="100" />
        </inertial>
        <visual>
            <origin xyz="0 0.8522281505571193 0" rpy="0 0 0"/>
            <geometry>
                <box size="1.4180040795968782 1.7044563011142386 2.9445786237886615" />
            </geometry>
            <material name="Blue">
                <color rgba="0 1.0 1.0 1.0"/>
            </material>
        </visual>
        <collision>
            <origin xyz="0 0.8522281505571193 0" rpy="0 0 0"/>
            <geometry>
                <box size="1.4180040795968782 1.7044563011142386 2.9445786237886615" />
            </geometry>
        </collision>
    </link>
    <link name="Leg28">
        <inertial>
            <origin xyz="0 0.811728936831331 0" rpy="0 0 0"/>
            <mass value="1" />
            <inertia ixx="100" ixy="0" ixz="0" iyy="100" iyz="0" izz="100" />
        </inertial>
        <visual>
            <origin xyz="0 0.811728936831331 0" rpy="0 0 0"/>
            <geometry>
                <box size="1.861730656535526 1.623457873662662 2.0244845419050987" />
            </geometry>
            <material name="Blue">
                <color rgba="0 1.0 1.0 1.0"/>
            </material>
        </visual>
        <collision>
            <origin xyz="0 0.811728936831331 0" rpy="0 0 0"/>
            <geometry>
                <box size="1.861730656535526 1.623457873662662 2.0244845419050987" />
            </geometry>
        </collision>
    </link>
    <joint name="Torso_Leg1" type="revolute">
       <parent link="Torso"/>
       <child  link="Leg1"/>
       <origin rpy="0 0 0" xyz="1.4742963696144504 0 0.5087102984435963" />
     <axis xyz="1 0 0"/>
       <limit effort="0.0" lower="-3.14159" upper="3.14159" velocity="0.0"/>
    </joint>
    <joint name="Leg1_Leg2" type="revolute">
       <parent link="Leg1"/>
       <child  link="Leg2"/>
       <origin rpy="0 0 0" xyz="0 1.0076754621507165 0" />
     <axis xyz="1 0 0"/>
       <limit effort="0.0" lower="-3.14159" upper="3.14159" velocity="0.0"/>
    </joint>
    <joint name="Torso_Leg3" type="revolute">
       <parent link="Torso"/>
       <child  link="Leg3"/>
       <origin rpy="0 0 0" xyz="1.303662383097809 1.3209890146021412 0" />
     <axis xyz="1 0 0"/>
       <limit effort="0.0" lower="-3.14159" upper="3.14159" velocity="0.0"/>
    </joint>
    <joint name="Leg1_Leg4" type="revolute">
       <parent link="Leg1"/>
       <child  link="Leg4"/>
       <origin rpy="0 0 0" xyz="0.9797509484821266 1.0076754621507165 0" />
     <axis xyz="1 0 0"/>
       <limit effort="0.0" lower="-3.14159" upper="3.14159" velocity="0.0"/>
    </joint>
    <joint name="Leg3_Leg5" type="revolute">
       <parent link="Leg3"/>
       <child  link="Leg5"/>
       <origin rpy="0 0 0" xyz="2.836103219219626 0 0" />
     <axis xyz="1 0 0"/>
       <limit effort="0.0" lower="-3.14159" upper="3.14159" velocity="0.0"/>
    </joint>
    <joint name="Leg4_Leg6" type="revolute">
       <parent link="Leg4"/>
       <child  link="Leg6"/>
       <origin rpy="0 0 0" xyz="2.759717834140149 0 0" />
     <axis xyz="1 0 0"/>
       <limit effort="0.0" lower="-3.14159" upper="3.14159" velocity="0.0"/>
    </joint>
    <joint name="Leg6_Leg7" type="revolute">
       <parent link="Leg6"/>
       <child  link="Leg7"/>
       <origin rpy="0 0 0" xyz="1.1807752933138795 0 0" />
     <axis xyz="1 0 0"/>
       <limit effort="0.0" lower="-3.14159" upper="3.14159" velocity="0.0"/>
    </joint>
    <joint name="Leg5_Leg8" type="revolute">
       <parent link="Leg5"/>
       <child  link="Leg8"/>
       <origin rpy="0 0 0" xyz="1.0719195545370277 0 0" />
     <axis xyz="1 0 0"/>
       <limit effort="0.0" lower="-3.14159" upper="3.14159" velocity="0.0"/>
    </joint>
    <joint name="Leg3_Leg9" type="revolute">
       <parent link="Leg3"/>
       <child  link="Leg9"/>
       <origin rpy="0 0 0" xyz="2.836103219219626 0 1.0896582006057116" />
     <axis xyz="1 0 0"/>
       <limit effort="0.0" lower="-3.14159" upper="3.14159" velocity="0.0"/>
    </joint>
    <joint name="Leg6_Leg10" type="revolute">
       <parent link="Leg6"/>
       <child  link="Leg10"/>
       <origin rpy="0 0 0" xyz="1.1807752933138795 0 0.7461963902642411" />
     <axis xyz="1 0 0"/>
       <limit effort="0.0" lower="-3.14159" upper="3.14159" velocity="0.0"/>
    </joint>
    <joint name="Leg8_Leg11" type="revolute">
       <parent link="Leg8"/>
       <child  link="Leg11"/>
       <origin rpy="0 0 0" xyz="0.7839852277773492 0 1.4016815536075615" />
     <axis xyz="1 0 0"/>
       <limit effort="0.0" lower="-3.14159" upper="3.14159" velocity="0.0"/>
    </joint>
    <joint name="Leg9_Leg12" type="revolute">
       <parent link="Leg9"/>
       <child  link="Leg12"/>
       <origin rpy="0 0 0" xyz="0 0.7594737842823597 0.8775101912771633" />
     <axis xyz="1 0 0"/>
       <limit effort="0.0" lower="-3.14159" upper="3.14159" velocity="0.0"/>
    </joint>
    <joint name="Torso_Leg13" type="revolute">
       <parent link="Torso"/>
       <child  link="Leg13"/>
       <origin rpy="0 0 0" xyz="1.303662383097809 1.3209890146021412 1.1327168219393546" />
     <axis xyz="1 0 0"/>
       <limit effort="0.0" lower="-3.14159" upper="3.14159" velocity="0.0"/>
    </joint>
    <joint name="Leg7_Leg14" type="revolute">
       <parent link="Leg7"/>
       <child  link="Leg14"/>
       <origin rpy="0 0 0" xyz="0.8879392894478151 0 0.5761743151659665" />
     <axis xyz="1 0 0"/>
       <limit effort="0.0" lower="-3.14159" upper="3.14159" velocity="0.0"/>
    </joint>
    <joint name="Leg12_Leg15" type="revolute">
       <parent link="Leg12"/>
       <child  link="Leg15"/>
       <origin rpy="0 0 0" xyz="0 1.071782810646062 1.410087571189838" />
     <axis xyz="1 0 0"/>
       <limit effort="0.0" lower="-3.14159" upper="3.14159" velocity="0.0"/>
    </joint>
    <joint name="Leg2_Leg16" type="revolute">
       <parent link="Leg2"/>
       <child  link="Leg16"/>
       <origin rpy="0 0 0" xyz="1.116071013742763 1.225895442929712 0" />
     <axis xyz="1 0 0"/>
       <limit effort="0.0" lower="-3.14159" upper="3.14159" velocity="0.0"/>
    </joint>
    <joint name="Leg12_Leg17" type="revolute">
       <parent link="Leg12"/>
       <child  link="Leg17"/>
       <origin rpy="0 0 0" xyz="0.8361111941447018 1.071782810646062 1.410087571189838" />
     <axis xyz="1 0 0"/>
       <limit effort="0.0" lower="-3.14159" upper="3.14159" velocity="0.0"/>
    </joint>
    <joint name="Leg3_Leg18" type="revolute">
       <parent link="Leg3"/>
       <child  link="Leg18"/>
       <origin rpy="0 0 0" xyz="2.836103219219626 1.265476301259872 1.0896582006057116" />
     <axis xyz="1 0 0"/>
       <limit effort="0.0" lower="-3.14159" upper="3.14159" velocity="0.0"/>
    </joint>
    <joint name="Leg16_Leg19" type="revolute">
       <parent link="Leg16"/>
       <child  link="Leg19"/>
       <origin rpy="0 0 0" xyz="1.255363148513983 0 0.5847478643314741" />
     <axis xyz="1 0 0"/>
       <limit effort="0.0" lower="-3.14159" upper="3.14159" velocity="0.0"/>
    </joint>
    <joint name="Leg8_Leg20" type="revolute">
       <parent link="Leg8"/>
       <child  link="Leg20"/>
       <origin rpy="0 0 0" xyz="0.7839852277773492 0.5650775269359355 1.4016815536075615" />
     <axis xyz="1 0 0"/>
       <limit effort="0.0" lower="-3.14159" upper="3.14159" velocity="0.0"/>
    </joint>
    <joint name="Leg7_Leg21" type="revolute">
       <parent link="Leg7"/>
       <child  link="Leg21"/>
       <origin rpy="0 0 0" xyz="0.8879392894478151 1.0303065666868263 0.5761743151659665" />
     <axis xyz="1 0 0"/>
       <limit effort="0.0" lower="-3.14159" upper="3.14159" velocity="0.0"/>
    </joint>
    <joint name="Leg14_Leg22" type="revolute">
       <parent link="Leg14"/>
       <child  link="Leg22"/>
       <origin rpy="0 0 0" xyz="0 2.169245417655362 0" />
     <axis xyz="1 0 0"/>
       <limit effort="0.0" lower="-3.14159" upper="3.14159" velocity="0.0"/>
    </joint>
    <joint name="Leg22_Leg23" type="revolute">
       <parent link="Leg22"/>
       <child  link="Leg23"/>
       <origin rpy="0 0 0" xyz="0 1.069313734835131 0" />
     <axis xyz="1 0 0"/>
       <limit effort="0.0" lower="-3.14159" upper="3.14159" velocity="0.0"/>
    </joint>
    <joint name="Leg4_Leg24" type="revolute">
       <parent link="Leg4"/>
       <child  link="Leg24"/>
       <origin rpy="0 0 0" xyz="2.759717834140149 1.1888528221656132 0" />
     <axis xyz="1 0 0"/>
       <limit effort="0.0" lower="-3.14159" upper="3.14159" velocity="0.0"/>
    </joint>
    <joint name="Leg15_Leg25" type="revolute">
       <parent link="Leg15"/>
       <child  link="Leg25"/>
       <origin rpy="0 0 0" xyz="0.8340044021128252 1.4290437549546127 0" />
     <axis xyz="1 0 0"/>
       <limit effort="0.0" lower="-3.14159" upper="3.14159" velocity="0.0"/>
    </joint>
    <joint name="Leg24_Leg26" type="revolute">
       <parent link="Leg24"/>
       <child  link="Leg26"/>
       <origin rpy="0 0 0" xyz="1.2934327608127445 1.1399719186758748 0" />
     <axis xyz="1 0 0"/>
       <limit effort="0.0" lower="-3.14159" upper="3.14159" velocity="0.0"/>
    </joint>
    <joint name="Leg6_Leg27" type="revolute">
       <parent link="Leg6"/>
       <child  link="Leg27"/>
       <origin rpy="0 0 0" xyz="1.1807752933138795 1.0107599471092894 0.7461963902642411" />
     <axis xyz="1 0 0"/>
       <limit effort="0.0" lower="-3.14159" upper="3.14159" velocity="0.0"/>
    </joint>
    <joint name="Leg23_Leg28" type="revolute">
       <parent link="Leg23"/>
       <child  link="Leg28"/>
       <origin rpy="0 0 0" xyz="0 1.3265626459651976 0" />
     <axis xyz="1 0 0"/>
       <limit effort="0.0" lower="-3.14159" upper="3.14159" velocity="0.0"/>
    </joint>
</robot>