<robot name = "robot">
    <link name="Torso">
        <inertial>
            <origin xyz="0 0 0.9890482431029823" rpy="0 0 0"/>
            <mass value="1" />
            <inertia ixx="100" ixy="0" ixz="0" iyy="100" iyz="0" izz="100" />
        </inertial>
        <visual>
            <origin xyz="0 0 0.9890482431029823" rpy="0 0 0"/>
            <geometry>
                <box size="2.3711032590388132 1.503610323085492 1.9780964862059647" />
            </geometry>
            <material name="Green">
                <color rgba="0 180.0 0.0 1.0"/>
            </material>
        </visual>
        <collision>
            <origin xyz="0 0 0.9890482431029823" rpy="0 0 0"/>
            <geometry>
                <box size="2.3711032590388132 1.503610323085492 1.9780964862059647" />
            </geometry>
        </collision>
    </link>
    <link name="Leg1">
        <inertial>
            <origin xyz="1.054285361675692 0 0" rpy="0 0 0"/>
            <mass value="1" />
            <inertia ixx="100" ixy="0" ixz="0" iyy="100" iyz="0" izz="100" />
        </inertial>
        <visual>
            <origin xyz="1.054285361675692 0 0" rpy="0 0 0"/>
            <geometry>
                <box size="2.108570723351384 1.0497696726842478 1.5192694180306752" />
            </geometry>
            <material name="Blue">
                <color rgba="0 1.0 1.0 1.0"/>
            </material>
        </visual>
        <collision>
            <origin xyz="1.054285361675692 0 0" rpy="0 0 0"/>
            <geometry>
                <box size="2.108570723351384 1.0497696726842478 1.5192694180306752" />
            </geometry>
        </collision>
    </link>
    <link name="Leg2">
        <inertial>
            <origin xyz="0 0 1.4239796089263357" rpy="0 0 0"/>
            <mass value="1" />
            <inertia ixx="100" ixy="0" ixz="0" iyy="100" iyz="0" izz="100" />
        </inertial>
        <visual>
            <origin xyz="0 0 1.4239796089263357" rpy="0 0 0"/>
            <geometry>
                <box size="1.682651436557225 2.9637973579026555 2.8479592178526714" />
            </geometry>
            <material name="Green">
                <color rgba="0 180.0 0.0 1.0"/>
            </material>
        </visual>
        <collision>
            <origin xyz="0 0 1.4239796089263357" rpy="0 0 0"/>
            <geometry>
                <box size="1.682651436557225 2.9637973579026555 2.8479592178526714" />
            </geometry>
        </collision>
    </link>
    <link name="Leg3">
        <inertial>
            <origin xyz="1.1188866861431264 0 0" rpy="0 0 0"/>
            <mass value="1" />
            <inertia ixx="100" ixy="0" ixz="0" iyy="100" iyz="0" izz="100" />
        </inertial>
        <visual>
            <origin xyz="1.1188866861431264 0 0" rpy="0 0 0"/>
            <geometry>
                <box size="2.2377733722862527 2.228066389674294 2.76474474526447" />
            </geometry>
            <material name="Green">
                <color rgba="0 180.0 0.0 1.0"/>
            </material>
        </visual>
        <collision>
            <origin xyz="1.1188866861431264 0 0" rpy="0 0 0"/>
            <geometry>
                <box size="2.2377733722862527 2.228066389674294 2.76474474526447" />
            </geometry>
        </collision>
    </link>
    <link name="Leg4">
        <inertial>
            <origin xyz="0 0 1.4046242138324212" rpy="0 0 0"/>
            <mass value="1" />
            <inertia ixx="100" ixy="0" ixz="0" iyy="100" iyz="0" izz="100" />
        </inertial>
        <visual>
            <origin xyz="0 0 1.4046242138324212" rpy="0 0 0"/>
            <geometry>
                <box size="2.696848191318563 1.085608808012289 2.8092484276648424" />
            </geometry>
            <material name="Blue">
                <color rgba="0 1.0 1.0 1.0"/>
            </material>
        </visual>
        <collision>
            <origin xyz="0 0 1.4046242138324212" rpy="0 0 0"/>
            <geometry>
                <box size="2.696848191318563 1.085608808012289 2.8092484276648424" />
            </geometry>
        </collision>
    </link>
    <link name="Leg5">
        <inertial>
            <origin xyz="1.225409445034232 0 0" rpy="0 0 0"/>
            <mass value="1" />
            <inertia ixx="100" ixy="0" ixz="0" iyy="100" iyz="0" izz="100" />
        </inertial>
        <visual>
            <origin xyz="1.225409445034232 0 0" rpy="0 0 0"/>
            <geometry>
                <box size="2.450818890068464 2.4138730497807934 1.3084554334423764" />
            </geometry>
            <material name="Green">
                <color rgba="0 180.0 0.0 1.0"/>
            </material>
        </visual>
        <collision>
            <origin xyz="1.225409445034232 0 0" rpy="0 0 0"/>
            <geometry>
                <box size="2.450818890068464 2.4138730497807934 1.3084554334423764" />
            </geometry>
        </collision>
    </link>
    <link name="Leg6">
        <inertial>
            <origin xyz="0.8513280886669868 0 0" rpy="0 0 0"/>
            <mass value="1" />
            <inertia ixx="100" ixy="0" ixz="0" iyy="100" iyz="0" izz="100" />
        </inertial>
        <visual>
            <origin xyz="0.8513280886669868 0 0" rpy="0 0 0"/>
            <geometry>
                <box size="1.7026561773339737 2.409513880123005 1.1353679965895547" />
            </geometry>
            <material name="Blue">
                <color rgba="0 1.0 1.0 1.0"/>
            </material>
        </visual>
        <collision>
            <origin xyz="0.8513280886669868 0 0" rpy="0 0 0"/>
            <geometry>
                <box size="1.7026561773339737 2.409513880123005 1.1353679965895547" />
            </geometry>
        </collision>
    </link>
    <link name="Leg7">
        <inertial>
            <origin xyz="1.4532153076575431 0 0" rpy="0 0 0"/>
            <mass value="1" />
            <inertia ixx="100" ixy="0" ixz="0" iyy="100" iyz="0" izz="100" />
        </inertial>
        <visual>
            <origin xyz="1.4532153076575431 0 0" rpy="0 0 0"/>
            <geometry>
                <box size="2.9064306153150863 2.0190848860953245 2.503837824763087" />
            </geometry>
            <material name="Blue">
                <color rgba="0 1.0 1.0 1.0"/>
            </material>
        </visual>
        <collision>
            <origin xyz="1.4532153076575431 0 0" rpy="0 0 0"/>
            <geometry>
                <box size="2.9064306153150863 2.0190848860953245 2.503837824763087" />
            </geometry>
        </collision>
    </link>
    <link name="Leg8">
        <inertial>
            <origin xyz="0 1.0243701058537056 0" rpy="0 0 0"/>
            <mass value="1" />
            <inertia ixx="100" ixy="0" ixz="0" iyy="100" iyz="0" izz="100" />
        </inertial>
        <visual>
            <origin xyz="0 1.0243701058537056 0" rpy="0 0 0"/>
            <geometry>
                <box size="1.718534426528516 2.048740211707411 1.0178988381179426" />
            </geometry>
            <material name="Blue">
                <color rgba="0 1.0 1.0 1.0"/>
            </material>
        </visual>
        <collision>
            <origin xyz="0 1.0243701058537056 0" rpy="0 0 0"/>
            <geometry>
                <box size="1.718534426528516 2.048740211707411 1.0178988381179426" />
            </geometry>
        </collision>
    </link>
    <link name="Leg9">
        <inertial>
            <origin xyz="1.183833513865483 0 0" rpy="0 0 0"/>
            <mass value="1" />
            <inertia ixx="100" ixy="0" ixz="0" iyy="100" iyz="0" izz="100" />
        </inertial>
        <visual>
            <origin xyz="1.183833513865483 0 0" rpy="0 0 0"/>
            <geometry>
                <box size="2.367667027730966 2.011877574909452 2.522063492241337" />
            </geometry>
            <material name="Green">
                <color rgba="0 180.0 0.0 1.0"/>
            </material>
        </visual>
        <collision>
            <origin xyz="1.183833513865483 0 0" rpy="0 0 0"/>
            <geometry>
                <box size="2.367667027730966 2.011877574909452 2.522063492241337" />
            </geometry>
        </collision>
    </link>
    <link name="Leg10">
        <inertial>
            <origin xyz="0.6440746242961675 0 0" rpy="0 0 0"/>
            <mass value="1" />
            <inertia ixx="100" ixy="0" ixz="0" iyy="100" iyz="0" izz="100" />
        </inertial>
        <visual>
            <origin xyz="0.6440746242961675 0 0" rpy="0 0 0"/>
            <geometry>
                <box size="1.288149248592335 1.7934120815596426 1.158774101989933" />
            </geometry>
            <material name="Green">
                <color rgba="0 180.0 0.0 1.0"/>
            </material>
        </visual>
        <collision>
            <origin xyz="0.6440746242961675 0 0" rpy="0 0 0"/>
            <geometry>
                <box size="1.288149248592335 1.7934120815596426 1.158774101989933" />
            </geometry>
        </collision>
    </link>
    <link name="Leg11">
        <inertial>
            <origin xyz="0 0 1.408587590546409" rpy="0 0 0"/>
            <mass value="1" />
            <inertia ixx="100" ixy="0" ixz="0" iyy="100" iyz="0" izz="100" />
        </inertial>
        <visual>
            <origin xyz="0 0 1.408587590546409" rpy="0 0 0"/>
            <geometry>
                <box size="2.475134332703753 2.575859766117273 2.817175181092818" />
            </geometry>
            <material name="Green">
                <color rgba="0 180.0 0.0 1.0"/>
            </material>
        </visual>
        <collision>
            <origin xyz="0 0 1.408587590546409" rpy="0 0 0"/>
            <geometry>
                <box size="2.475134332703753 2.575859766117273 2.817175181092818" />
            </geometry>
        </collision>
    </link>
    <link name="Leg12">
        <inertial>
            <origin xyz="0 0 0.9033346267444259" rpy="0 0 0"/>
            <mass value="1" />
            <inertia ixx="100" ixy="0" ixz="0" iyy="100" iyz="0" izz="100" />
        </inertial>
        <visual>
            <origin xyz="0 0 0.9033346267444259" rpy="0 0 0"/>
            <geometry>
                <box size="1.347179331566596 1.696688283516585 1.8066692534888518" />
            </geometry>
            <material name="Green">
                <color rgba="0 180.0 0.0 1.0"/>
            </material>
        </visual>
        <collision>
            <origin xyz="0 0 0.9033346267444259" rpy="0 0 0"/>
            <geometry>
                <box size="1.347179331566596 1.696688283516585 1.8066692534888518" />
            </geometry>
        </collision>
    </link>
    <link name="Leg13">
        <inertial>
            <origin xyz="0 1.4155420935209242 0" rpy="0 0 0"/>
            <mass value="1" />
            <inertia ixx="100" ixy="0" ixz="0" iyy="100" iyz="0" izz="100" />
        </inertial>
        <visual>
            <origin xyz="0 1.4155420935209242 0" rpy="0 0 0"/>
            <geometry>
                <box size="2.6396679041799924 2.8310841870418484 1.7349696128653047" />
            </geometry>
            <material name="Blue">
                <color rgba="0 1.0 1.0 1.0"/>
            </material>
        </visual>
        <collision>
            <origin xyz="0 1.4155420935209242 0" rpy="0 0 0"/>
            <geometry>
                <box size="2.6396679041799924 2.8310841870418484 1.7349696128653047" />
            </geometry>
        </collision>
    </link>
    <link name="Leg14">
        <inertial>
            <origin xyz="0 1.440416957918131 0" rpy="0 0 0"/>
            <mass value="1" />
            <inertia ixx="100" ixy="0" ixz="0" iyy="100" iyz="0" izz="100" />
        </inertial>
        <visual>
            <origin xyz="0 1.440416957918131 0" rpy="0 0 0"/>
            <geometry>
                <box size="2.9337071338122365 2.880833915836262 1.6167465760575361" />
            </geometry>
            <material name="Blue">
                <color rgba="0 1.0 1.0 1.0"/>
            </material>
        </visual>
        <collision>
            <origin xyz="0 1.440416957918131 0" rpy="0 0 0"/>
            <geometry>
                <box size="2.9337071338122365 2.880833915836262 1.6167465760575361" />
            </geometry>
        </collision>
    </link>
    <link name="Leg15">
        <inertial>
            <origin xyz="0 1.3526527508715858 0" rpy="0 0 0"/>
            <mass value="1" />
            <inertia ixx="100" ixy="0" ixz="0" iyy="100" iyz="0" izz="100" />
        </inertial>
        <visual>
            <origin xyz="0 1.3526527508715858 0" rpy="0 0 0"/>
            <geometry>
                <box size="1.67390574334657 2.7053055017431715 1.0367008479279916" />
            </geometry>
            <material name="Blue">
                <color rgba="0 1.0 1.0 1.0"/>
            </material>
        </visual>
        <collision>
            <origin xyz="0 1.3526527508715858 0" rpy="0 0 0"/>
            <geometry>
                <box size="1.67390574334657 2.7053055017431715 1.0367008479279916" />
            </geometry>
        </collision>
    </link>
    <link name="Leg16">
        <inertial>
            <origin xyz="0.6334119240283375 0 0" rpy="0 0 0"/>
            <mass value="1" />
            <inertia ixx="100" ixy="0" ixz="0" iyy="100" iyz="0" izz="100" />
        </inertial>
        <visual>
            <origin xyz="0.6334119240283375 0 0" rpy="0 0 0"/>
            <geometry>
                <box size="1.266823848056675 1.6930223628644963 1.7694692078816665" />
            </geometry>
            <material name="Blue">
                <color rgba="0 1.0 1.0 1.0"/>
            </material>
        </visual>
        <collision>
            <origin xyz="0.6334119240283375 0 0" rpy="0 0 0"/>
            <geometry>
                <box size="1.266823848056675 1.6930223628644963 1.7694692078816665" />
            </geometry>
        </collision>
    </link>
    <link name="Leg17">
        <inertial>
            <origin xyz="0.6779501733843335 0 0" rpy="0 0 0"/>
            <mass value="1" />
            <inertia ixx="100" ixy="0" ixz="0" iyy="100" iyz="0" izz="100" />
        </inertial>
        <visual>
            <origin xyz="0.6779501733843335 0 0" rpy="0 0 0"/>
            <geometry>
                <box size="1.355900346768667 1.9132853243026138 1.8310623773822658" />
            </geometry>
            <material name="Blue">
                <color rgba="0 1.0 1.0 1.0"/>
            </material>
        </visual>
        <collision>
            <origin xyz="0.6779501733843335 0 0" rpy="0 0 0"/>
            <geometry>
                <box size="1.355900346768667 1.9132853243026138 1.8310623773822658" />
            </geometry>
        </collision>
    </link>
    <link name="Leg18">
        <inertial>
            <origin xyz="0 0 1.182094331443953" rpy="0 0 0"/>
            <mass value="1" />
            <inertia ixx="100" ixy="0" ixz="0" iyy="100" iyz="0" izz="100" />
        </inertial>
        <visual>
            <origin xyz="0 0 1.182094331443953" rpy="0 0 0"/>
            <geometry>
                <box size="1.3154859115662694 2.9134308908298916 2.364188662887906" />
            </geometry>
            <material name="Blue">
                <color rgba="0 1.0 1.0 1.0"/>
            </material>
        </visual>
        <collision>
            <origin xyz="0 0 1.182094331443953" rpy="0 0 0"/>
            <geometry>
                <box size="1.3154859115662694 2.9134308908298916 2.364188662887906" />
            </geometry>
        </collision>
    </link>
    <link name="Leg19">
        <inertial>
            <origin xyz="0 0 0.5138240328439319" rpy="0 0 0"/>
            <mass value="1" />
            <inertia ixx="100" ixy="0" ixz="0" iyy="100" iyz="0" izz="100" />
        </inertial>
        <visual>
            <origin xyz="0 0 0.5138240328439319" rpy="0 0 0"/>
            <geometry>
                <box size="1.4484720785933962 1.915101445022645 1.0276480656878637" />
            </geometry>
            <material name="Blue">
                <color rgba="0 1.0 1.0 1.0"/>
            </material>
        </visual>
        <collision>
            <origin xyz="0 0 0.5138240328439319" rpy="0 0 0"/>
            <geometry>
                <box size="1.4484720785933962 1.915101445022645 1.0276480656878637" />
            </geometry>
        </collision>
    </link>
    <link name="Leg20">
        <inertial>
            <origin xyz="0.9242845443404695 0 0" rpy="0 0 0"/>
            <mass value="1" />
            <inertia ixx="100" ixy="0" ixz="0" iyy="100" iyz="0" izz="100" />
        </inertial>
        <visual>
            <origin xyz="0.9242845443404695 0 0" rpy="0 0 0"/>
            <geometry>
                <box size="1.848569088680939 1.764932976780751 1.9348329004606986" />
            </geometry>
            <material name="Blue">
                <color rgba="0 1.0 1.0 1.0"/>
            </material>
        </visual>
        <collision>
            <origin xyz="0.9242845443404695 0 0" rpy="0 0 0"/>
            <geometry>
                <box size="1.848569088680939 1.764932976780751 1.9348329004606986" />
            </geometry>
        </collision>
    </link>
    <link name="Leg21">
        <inertial>
            <origin xyz="1.0168849930427541 0 0" rpy="0 0 0"/>
            <mass value="1" />
            <inertia ixx="100" ixy="0" ixz="0" iyy="100" iyz="0" izz="100" />
        </inertial>
        <visual>
            <origin xyz="1.0168849930427541 0 0" rpy="0 0 0"/>
            <geometry>
                <box size="2.0337699860855083 2.0381009540632675 2.3261215829516217" />
            </geometry>
            <material name="Blue">
                <color rgba="0 1.0 1.0 1.0"/>
            </material>
        </visual>
        <collision>
            <origin xyz="1.0168849930427541 0 0" rpy="0 0 0"/>
            <geometry>
                <box size="2.0337699860855083 2.0381009540632675 2.3261215829516217" />
            </geometry>
        </collision>
    </link>
    <link name="Leg22">
        <inertial>
            <origin xyz="0 0.9641681924038964 0" rpy="0 0 0"/>
            <mass value="1" />
            <inertia ixx="100" ixy="0" ixz="0" iyy="100" iyz="0" izz="100" />
        </inertial>
        <visual>
            <origin xyz="0 0.9641681924038964 0" rpy="0 0 0"/>
            <geometry>
                <box size="1.1297331833563613 1.9283363848077928 2.302225192717775" />
            </geometry>
            <material name="Green">
                <color rgba="0 180.0 0.0 1.0"/>
            </material>
        </visual>
        <collision>
            <origin xyz="0 0.9641681924038964 0" rpy="0 0 0"/>
            <geometry>
                <box size="1.1297331833563613 1.9283363848077928 2.302225192717775" />
            </geometry>
        </collision>
    </link>
    <link name="Leg23">
        <inertial>
            <origin xyz="0 0 1.4690890557277456" rpy="0 0 0"/>
            <mass value="1" />
            <inertia ixx="100" ixy="0" ixz="0" iyy="100" iyz="0" izz="100" />
        </inertial>
        <visual>
            <origin xyz="0 0 1.4690890557277456" rpy="0 0 0"/>
            <geometry>
                <box size="1.158504942683134 1.3082304824254407 2.9381781114554912" />
            </geometry>
            <material name="Green">
                <color rgba="0 180.0 0.0 1.0"/>
            </material>
        </visual>
        <collision>
            <origin xyz="0 0 1.4690890557277456" rpy="0 0 0"/>
            <geometry>
                <box size="1.158504942683134 1.3082304824254407 2.9381781114554912" />
            </geometry>
        </collision>
    </link>
    <link name="Leg24">
        <inertial>
            <origin xyz="1.323436709840652 0 0" rpy="0 0 0"/>
            <mass value="1" />
            <inertia ixx="100" ixy="0" ixz="0" iyy="100" iyz="0" izz="100" />
        </inertial>
        <visual>
            <origin xyz="1.323436709840652 0 0" rpy="0 0 0"/>
            <geometry>
                <box size="2.646873419681304 1.8705049346181335 2.101883766226177" />
            </geometry>
            <material name="Blue">
                <color rgba="0 1.0 1.0 1.0"/>
            </material>
        </visual>
        <collision>
            <origin xyz="1.323436709840652 0 0" rpy="0 0 0"/>
            <geometry>
                <box size="2.646873419681304 1.8705049346181335 2.101883766226177" />
            </geometry>
        </collision>
    </link>
    <link name="Leg25">
        <inertial>
            <origin xyz="0 0.9404692533106053 0" rpy="0 0 0"/>
            <mass value="1" />
            <inertia ixx="100" ixy="0" ixz="0" iyy="100" iyz="0" izz="100" />
        </inertial>
        <visual>
            <origin xyz="0 0.9404692533106053 0" rpy="0 0 0"/>
            <geometry>
                <box size="1.485792603270106 1.8809385066212105 2.015818558379121" />
            </geometry>
            <material name="Green">
                <color rgba="0 180.0 0.0 1.0"/>
            </material>
        </visual>
        <collision>
            <origin xyz="0 0.9404692533106053 0" rpy="0 0 0"/>
            <geometry>
                <box size="1.485792603270106 1.8809385066212105 2.015818558379121" />
            </geometry>
        </collision>
    </link>
    <link name="Leg26">
        <inertial>
            <origin xyz="0.5256778926707294 0 0" rpy="0 0 0"/>
            <mass value="1" />
            <inertia ixx="100" ixy="0" ixz="0" iyy="100" iyz="0" izz="100" />
        </inertial>
        <visual>
            <origin xyz="0.5256778926707294 0 0" rpy="0 0 0"/>
            <geometry>
                <box size="1.0513557853414588 1.9561652602028452 2.762259359721015" />
            </geometry>
            <material name="Blue">
                <color rgba="0 1.0 1.0 1.0"/>
            </material>
        </visual>
        <collision>
            <origin xyz="0.5256778926707294 0 0" rpy="0 0 0"/>
            <geometry>
                <box size="1.0513557853414588 1.9561652602028452 2.762259359721015" />
            </geometry>
        </collision>
    </link>
    <joint name="Torso_Leg1" type="revolute">
       <parent link="Torso"/>
       <child  link="Leg1"/>
       <origin rpy="0 0 0" xyz="1.1855516295194066 0 0.9890482431029823" />
     <axis xyz="1 0 0"/>
       <limit effort="0.0" lower="-3.14159" upper="3.14159" velocity="0.0"/>
    </joint>
    <joint name="Torso_Leg2" type="revolute">
       <parent link="Torso"/>
       <child  link="Leg2"/>
       <origin rpy="0 0 0" xyz="1.054285361675692 0 0.7596347090153376" />
     <axis xyz="1 0 0"/>
       <limit effort="0.0" lower="-3.14159" upper="3.14159" velocity="0.0"/>
    </joint>
    <joint name="Leg1_Leg3" type="revolute">
       <parent link="Leg1"/>
       <child  link="Leg3"/>
       <origin rpy="0 0 0" xyz="0.8413257182786125 0 1.4239796089263357" />
     <axis xyz="1 0 0"/>
       <limit effort="0.0" lower="-3.14159" upper="3.14159" velocity="0.0"/>
    </joint>
    <joint name="Leg1_Leg4" type="revolute">
       <parent link="Leg1"/>
       <child  link="Leg4"/>
       <origin rpy="0 0 0" xyz="0.8413257182786125 0 2.8479592178526714" />
     <axis xyz="1 0 0"/>
       <limit effort="0.0" lower="-3.14159" upper="3.14159" velocity="0.0"/>
    </joint>
    <joint name="Leg2_Leg5" type="revolute">
       <parent link="Leg2"/>
       <child  link="Leg5"/>
       <origin rpy="0 0 0" xyz="2.2377733722862527 0 0" />
     <axis xyz="1 0 0"/>
       <limit effort="0.0" lower="-3.14159" upper="3.14159" velocity="0.0"/>
    </joint>
    <joint name="Leg3_Leg6" type="revolute">
       <parent link="Leg3"/>
       <child  link="Leg6"/>
       <origin rpy="0 0 0" xyz="1.3484240956592815 0 1.4046242138324212" />
     <axis xyz="1 0 0"/>
       <limit effort="0.0" lower="-3.14159" upper="3.14159" velocity="0.0"/>
    </joint>
    <joint name="Leg6_Leg7" type="revolute">
       <parent link="Leg6"/>
       <child  link="Leg7"/>
       <origin rpy="0 0 0" xyz="2.9064306153150863 0 0" />
     <axis xyz="1 0 0"/>
       <limit effort="0.0" lower="-3.14159" upper="3.14159" velocity="0.0"/>
    </joint>
    <joint name="Torso_Leg8" type="revolute">
       <parent link="Torso"/>
       <child  link="Leg8"/>
       <origin rpy="0 0 0" xyz="1.054285361675692 0.5248848363421239 0.7596347090153376" />
     <axis xyz="1 0 0"/>
       <limit effort="0.0" lower="-3.14159" upper="3.14159" velocity="0.0"/>
    </joint>
    <joint name="Leg8_Leg9" type="revolute">
       <parent link="Leg8"/>
       <child  link="Leg9"/>
       <origin rpy="0 0 0" xyz="2.367667027730966 0 0" />
     <axis xyz="1 0 0"/>
       <limit effort="0.0" lower="-3.14159" upper="3.14159" velocity="0.0"/>
    </joint>
    <joint name="Leg7_Leg10" type="revolute">
       <parent link="Leg7"/>
       <child  link="Leg10"/>
       <origin rpy="0 0 0" xyz="0.859267213264258 1.0243701058537056 0" />
     <axis xyz="1 0 0"/>
       <limit effort="0.0" lower="-3.14159" upper="3.14159" velocity="0.0"/>
    </joint>
    <joint name="Leg3_Leg11" type="revolute">
       <parent link="Leg3"/>
       <child  link="Leg11"/>
       <origin rpy="0 0 0" xyz="1.3484240956592815 0 2.8092484276648424" />
     <axis xyz="1 0 0"/>
       <limit effort="0.0" lower="-3.14159" upper="3.14159" velocity="0.0"/>
    </joint>
    <joint name="Leg4_Leg12" type="revolute">
       <parent link="Leg4"/>
       <child  link="Leg12"/>
       <origin rpy="0 0 0" xyz="1.225409445034232 0 0.6542277167211882" />
     <axis xyz="1 0 0"/>
       <limit effort="0.0" lower="-3.14159" upper="3.14159" velocity="0.0"/>
    </joint>
    <joint name="Leg10_Leg13" type="revolute">
       <parent link="Leg10"/>
       <child  link="Leg13"/>
       <origin rpy="0 0 0" xyz="0 1.2879298830586365 1.408587590546409" />
     <axis xyz="1 0 0"/>
       <limit effort="0.0" lower="-3.14159" upper="3.14159" velocity="0.0"/>
    </joint>
    <joint name="Leg6_Leg14" type="revolute">
       <parent link="Leg6"/>
       <child  link="Leg14"/>
       <origin rpy="0 0 0" xyz="2.9064306153150863 1.0095424430476623 0" />
     <axis xyz="1 0 0"/>
       <limit effort="0.0" lower="-3.14159" upper="3.14159" velocity="0.0"/>
    </joint>
    <joint name="Leg5_Leg15" type="revolute">
       <parent link="Leg5"/>
       <child  link="Leg15"/>
       <origin rpy="0 0 0" xyz="0.8513280886669868 1.2047569400615026 0" />
     <axis xyz="1 0 0"/>
       <limit effort="0.0" lower="-3.14159" upper="3.14159" velocity="0.0"/>
    </joint>
    <joint name="Leg4_Leg16" type="revolute">
       <parent link="Leg4"/>
       <child  link="Leg16"/>
       <origin rpy="0 0 0" xyz="2.450818890068464 0 0.6542277167211882" />
     <axis xyz="1 0 0"/>
       <limit effort="0.0" lower="-3.14159" upper="3.14159" velocity="0.0"/>
    </joint>
    <joint name="Leg10_Leg17" type="revolute">
       <parent link="Leg10"/>
       <child  link="Leg17"/>
       <origin rpy="0 0 0" xyz="1.2375671663518766 1.2879298830586365 1.408587590546409" />
     <axis xyz="1 0 0"/>
       <limit effort="0.0" lower="-3.14159" upper="3.14159" velocity="0.0"/>
    </joint>
    <joint name="Leg6_Leg18" type="revolute">
       <parent link="Leg6"/>
       <child  link="Leg18"/>
       <origin rpy="0 0 0" xyz="2.9064306153150863 1.0095424430476623 1.2519189123815435" />
     <axis xyz="1 0 0"/>
       <limit effort="0.0" lower="-3.14159" upper="3.14159" velocity="0.0"/>
    </joint>
    <joint name="Leg10_Leg19" type="revolute">
       <parent link="Leg10"/>
       <child  link="Leg19"/>
       <origin rpy="0 0 0" xyz="1.2375671663518766 1.2879298830586365 2.817175181092818" />
     <axis xyz="1 0 0"/>
       <limit effort="0.0" lower="-3.14159" upper="3.14159" velocity="0.0"/>
    </joint>
    <joint name="Leg14_Leg20" type="revolute">
       <parent link="Leg14"/>
       <child  link="Leg20"/>
       <origin rpy="0 0 0" xyz="0.836952871673285 1.3526527508715858 0" />
     <axis xyz="1 0 0"/>
       <limit effort="0.0" lower="-3.14159" upper="3.14159" velocity="0.0"/>
    </joint>
    <joint name="Leg19_Leg21" type="revolute">
       <parent link="Leg19"/>
       <child  link="Leg21"/>
       <origin rpy="0 0 0" xyz="1.848569088680939 0 0" />
     <axis xyz="1 0 0"/>
       <limit effort="0.0" lower="-3.14159" upper="3.14159" velocity="0.0"/>
    </joint>
    <joint name="Leg4_Leg22" type="revolute">
       <parent link="Leg4"/>
       <child  link="Leg22"/>
       <origin rpy="0 0 0" xyz="2.450818890068464 1.2069365248903967 0.6542277167211882" />
     <axis xyz="1 0 0"/>
       <limit effort="0.0" lower="-3.14159" upper="3.14159" velocity="0.0"/>
    </joint>
    <joint name="Leg11_Leg23" type="revolute">
       <parent link="Leg11"/>
       <child  link="Leg23"/>
       <origin rpy="0 0 0" xyz="0 0 1.8066692534888518" />
     <axis xyz="1 0 0"/>
       <limit effort="0.0" lower="-3.14159" upper="3.14159" velocity="0.0"/>
    </joint>
    <joint name="Leg17_Leg24" type="revolute">
       <parent link="Leg17"/>
       <child  link="Leg24"/>
       <origin rpy="0 0 0" xyz="0.6577429557831347 0 1.182094331443953" />
     <axis xyz="1 0 0"/>
       <limit effort="0.0" lower="-3.14159" upper="3.14159" velocity="0.0"/>
    </joint>
    <joint name="Leg15_Leg25" type="revolute">
       <parent link="Leg15"/>
       <child  link="Leg25"/>
       <origin rpy="0 0 0" xyz="0.6334119240283375 0.8465111814322481 0" />
     <axis xyz="1 0 0"/>
       <limit effort="0.0" lower="-3.14159" upper="3.14159" velocity="0.0"/>
    </joint>
    <joint name="Leg12_Leg26" type="revolute">
       <parent link="Leg12"/>
       <child  link="Leg26"/>
       <origin rpy="0 0 0" xyz="1.3198339520899962 1.4155420935209242 0" />
     <axis xyz="1 0 0"/>
       <limit effort="0.0" lower="-3.14159" upper="3.14159" velocity="0.0"/>
    </joint>
</robot>