<robot name = "robot">
    <link name="Torso">
        <inertial>
            <origin xyz="0 0 0.5053771408538884" rpy="0 0 0"/>
            <mass value="1" />
            <inertia ixx="100" ixy="0" ixz="0" iyy="100" iyz="0" izz="100" />
        </inertial>
        <visual>
            <origin xyz="0 0 0.5053771408538884" rpy="0 0 0"/>
            <geometry>
                <box size="2.13429830525582 2.5306552701388014 1.0107542817077768" />
            </geometry>
            <material name="Green">
                <color rgba="0 180.0 0.0 1.0"/>
            </material>
        </visual>
        <collision>
            <origin xyz="0 0 0.5053771408538884" rpy="0 0 0"/>
            <geometry>
                <box size="2.13429830525582 2.5306552701388014 1.0107542817077768" />
            </geometry>
        </collision>
    </link>
    <link name="Leg1">
        <inertial>
            <origin xyz="1.4501595719285967 0 0" rpy="0 0 0"/>
            <mass value="1" />
            <inertia ixx="100" ixy="0" ixz="0" iyy="100" iyz="0" izz="100" />
        </inertial>
        <visual>
            <origin xyz="1.4501595719285967 0 0" rpy="0 0 0"/>
            <geometry>
                <box size="2.9003191438571934 2.606394528908485 1.9583426689161494" />
            </geometry>
            <material name="Blue">
                <color rgba="0 1.0 1.0 1.0"/>
            </material>
        </visual>
        <collision>
            <origin xyz="1.4501595719285967 0 0" rpy="0 0 0"/>
            <geometry>
                <box size="2.9003191438571934 2.606394528908485 1.9583426689161494" />
            </geometry>
        </collision>
    </link>
    <link name="Leg2">
        <inertial>
            <origin xyz="0 0.9548730077230285 0" rpy="0 0 0"/>
            <mass value="1" />
            <inertia ixx="100" ixy="0" ixz="0" iyy="100" iyz="0" izz="100" />
        </inertial>
        <visual>
            <origin xyz="0 0.9548730077230285 0" rpy="0 0 0"/>
            <geometry>
                <box size="1.285864513477388 1.909746015446057 2.8880448366843363" />
            </geometry>
            <material name="Blue">
                <color rgba="0 1.0 1.0 1.0"/>
            </material>
        </visual>
        <collision>
            <origin xyz="0 0.9548730077230285 0" rpy="0 0 0"/>
            <geometry>
                <box size="1.285864513477388 1.909746015446057 2.8880448366843363" />
            </geometry>
        </collision>
    </link>
    <link name="Leg3">
        <inertial>
            <origin xyz="0 0 0.9760275809396922" rpy="0 0 0"/>
            <mass value="1" />
            <inertia ixx="100" ixy="0" ixz="0" iyy="100" iyz="0" izz="100" />
        </inertial>
        <visual>
            <origin xyz="0 0 0.9760275809396922" rpy="0 0 0"/>
            <geometry>
                <box size="2.662725847742566 1.60204938172781 1.9520551618793844" />
            </geometry>
            <material name="Blue">
                <color rgba="0 1.0 1.0 1.0"/>
            </material>
        </visual>
        <collision>
            <origin xyz="0 0 0.9760275809396922" rpy="0 0 0"/>
            <geometry>
                <box size="2.662725847742566 1.60204938172781 1.9520551618793844" />
            </geometry>
        </collision>
    </link>
    <link name="Leg4">
        <inertial>
            <origin xyz="0.6013544838093727 0 0" rpy="0 0 0"/>
            <mass value="1" />
            <inertia ixx="100" ixy="0" ixz="0" iyy="100" iyz="0" izz="100" />
        </inertial>
        <visual>
            <origin xyz="0.6013544838093727 0 0" rpy="0 0 0"/>
            <geometry>
                <box size="1.2027089676187455 2.896271061200977 1.677561200020289" />
            </geometry>
            <material name="Blue">
                <color rgba="0 1.0 1.0 1.0"/>
            </material>
        </visual>
        <collision>
            <origin xyz="0.6013544838093727 0 0" rpy="0 0 0"/>
            <geometry>
                <box size="1.2027089676187455 2.896271061200977 1.677561200020289" />
            </geometry>
        </collision>
    </link>
    <link name="Leg5">
        <inertial>
            <origin xyz="0 0 0.7092044376992143" rpy="0 0 0"/>
            <mass value="1" />
            <inertia ixx="100" ixy="0" ixz="0" iyy="100" iyz="0" izz="100" />
        </inertial>
        <visual>
            <origin xyz="0 0 0.7092044376992143" rpy="0 0 0"/>
            <geometry>
                <box size="2.3417773920866085 2.249554808559725 1.4184088753984285" />
            </geometry>
            <material name="Blue">
                <color rgba="0 1.0 1.0 1.0"/>
            </material>
        </visual>
        <collision>
            <origin xyz="0 0 0.7092044376992143" rpy="0 0 0"/>
            <geometry>
                <box size="2.3417773920866085 2.249554808559725 1.4184088753984285" />
            </geometry>
        </collision>
    </link>
    <link name="Leg6">
        <inertial>
            <origin xyz="0.5965013047985022 0 0" rpy="0 0 0"/>
            <mass value="1" />
            <inertia ixx="100" ixy="0" ixz="0" iyy="100" iyz="0" izz="100" />
        </inertial>
        <visual>
            <origin xyz="0.5965013047985022 0 0" rpy="0 0 0"/>
            <geometry>
                <box size="1.1930026095970043 1.1992889623866216 1.1817121645784314" />
            </geometry>
            <material name="Blue">
                <color rgba="0 1.0 1.0 1.0"/>
            </material>
        </visual>
        <collision>
            <origin xyz="0.5965013047985022 0 0" rpy="0 0 0"/>
            <geometry>
                <box size="1.1930026095970043 1.1992889623866216 1.1817121645784314" />
            </geometry>
        </collision>
    </link>
    <link name="Leg7">
        <inertial>
            <origin xyz="0 1.3687874717425974 0" rpy="0 0 0"/>
            <mass value="1" />
            <inertia ixx="100" ixy="0" ixz="0" iyy="100" iyz="0" izz="100" />
        </inertial>
        <visual>
            <origin xyz="0 1.3687874717425974 0" rpy="0 0 0"/>
            <geometry>
                <box size="2.1659614736992214 2.737574943485195 2.43236918165967" />
            </geometry>
            <material name="Green">
                <color rgba="0 180.0 0.0 1.0"/>
            </material>
        </visual>
        <collision>
            <origin xyz="0 1.3687874717425974 0" rpy="0 0 0"/>
            <geometry>
                <box size="2.1659614736992214 2.737574943485195 2.43236918165967" />
            </geometry>
        </collision>
    </link>
    <link name="Leg8">
        <inertial>
            <origin xyz="0.5735882534423928 0 0" rpy="0 0 0"/>
            <mass value="1" />
            <inertia ixx="100" ixy="0" ixz="0" iyy="100" iyz="0" izz="100" />
        </inertial>
        <visual>
            <origin xyz="0.5735882534423928 0 0" rpy="0 0 0"/>
            <geometry>
                <box size="1.1471765068847857 2.196531435707122 1.979213068601426" />
            </geometry>
            <material name="Blue">
                <color rgba="0 1.0 1.0 1.0"/>
            </material>
        </visual>
        <collision>
            <origin xyz="0.5735882534423928 0 0" rpy="0 0 0"/>
            <geometry>
                <box size="1.1471765068847857 2.196531435707122 1.979213068601426" />
            </geometry>
        </collision>
    </link>
    <link name="Leg9">
        <inertial>
            <origin xyz="0 0 0.8290188928086786" rpy="0 0 0"/>
            <mass value="1" />
            <inertia ixx="100" ixy="0" ixz="0" iyy="100" iyz="0" izz="100" />
        </inertial>
        <visual>
            <origin xyz="0 0 0.8290188928086786" rpy="0 0 0"/>
            <geometry>
                <box size="2.1359078716012903 2.7175292856042463 1.6580377856173572" />
            </geometry>
            <material name="Blue">
                <color rgba="0 1.0 1.0 1.0"/>
            </material>
        </visual>
        <collision>
            <origin xyz="0 0 0.8290188928086786" rpy="0 0 0"/>
            <geometry>
                <box size="2.1359078716012903 2.7175292856042463 1.6580377856173572" />
            </geometry>
        </collision>
    </link>
    <link name="Leg10">
        <inertial>
            <origin xyz="0.5368130991099359 0 0" rpy="0 0 0"/>
            <mass value="1" />
            <inertia ixx="100" ixy="0" ixz="0" iyy="100" iyz="0" izz="100" />
        </inertial>
        <visual>
            <origin xyz="0.5368130991099359 0 0" rpy="0 0 0"/>
            <geometry>
                <box size="1.0736261982198718 2.061793314834403 2.19883132264283" />
            </geometry>
            <material name="Blue">
                <color rgba="0 1.0 1.0 1.0"/>
            </material>
        </visual>
        <collision>
            <origin xyz="0.5368130991099359 0 0" rpy="0 0 0"/>
            <geometry>
                <box size="1.0736261982198718 2.061793314834403 2.19883132264283" />
            </geometry>
        </collision>
    </link>
    <link name="Leg11">
        <inertial>
            <origin xyz="1.3167178203667698 0 0" rpy="0 0 0"/>
            <mass value="1" />
            <inertia ixx="100" ixy="0" ixz="0" iyy="100" iyz="0" izz="100" />
        </inertial>
        <visual>
            <origin xyz="1.3167178203667698 0 0" rpy="0 0 0"/>
            <geometry>
                <box size="2.6334356407335395 2.8231178025637975 2.1989484308823437" />
            </geometry>
            <material name="Blue">
                <color rgba="0 1.0 1.0 1.0"/>
            </material>
        </visual>
        <collision>
            <origin xyz="1.3167178203667698 0 0" rpy="0 0 0"/>
            <geometry>
                <box size="2.6334356407335395 2.8231178025637975 2.1989484308823437" />
            </geometry>
        </collision>
    </link>
    <link name="Leg12">
        <inertial>
            <origin xyz="0 0.8455957498474107 0" rpy="0 0 0"/>
            <mass value="1" />
            <inertia ixx="100" ixy="0" ixz="0" iyy="100" iyz="0" izz="100" />
        </inertial>
        <visual>
            <origin xyz="0 0.8455957498474107 0" rpy="0 0 0"/>
            <geometry>
                <box size="2.855704463948343 1.6911914996948214 1.5589433409702356" />
            </geometry>
            <material name="Blue">
                <color rgba="0 1.0 1.0 1.0"/>
            </material>
        </visual>
        <collision>
            <origin xyz="0 0.8455957498474107 0" rpy="0 0 0"/>
            <geometry>
                <box size="2.855704463948343 1.6911914996948214 1.5589433409702356" />
            </geometry>
        </collision>
    </link>
    <link name="Leg13">
        <inertial>
            <origin xyz="0.589883163187002 0 0" rpy="0 0 0"/>
            <mass value="1" />
            <inertia ixx="100" ixy="0" ixz="0" iyy="100" iyz="0" izz="100" />
        </inertial>
        <visual>
            <origin xyz="0.589883163187002 0 0" rpy="0 0 0"/>
            <geometry>
                <box size="1.179766326374004 2.998613463702749 1.1380961848496343" />
            </geometry>
            <material name="Blue">
                <color rgba="0 1.0 1.0 1.0"/>
            </material>
        </visual>
        <collision>
            <origin xyz="0.589883163187002 0 0" rpy="0 0 0"/>
            <geometry>
                <box size="1.179766326374004 2.998613463702749 1.1380961848496343" />
            </geometry>
        </collision>
    </link>
    <link name="Leg14">
        <inertial>
            <origin xyz="0 1.1403700963634553 0" rpy="0 0 0"/>
            <mass value="1" />
            <inertia ixx="100" ixy="0" ixz="0" iyy="100" iyz="0" izz="100" />
        </inertial>
        <visual>
            <origin xyz="0 1.1403700963634553 0" rpy="0 0 0"/>
            <geometry>
                <box size="1.4803726291528811 2.2807401927269106 1.8212075267208585" />
            </geometry>
            <material name="Blue">
                <color rgba="0 1.0 1.0 1.0"/>
            </material>
        </visual>
        <collision>
            <origin xyz="0 1.1403700963634553 0" rpy="0 0 0"/>
            <geometry>
                <box size="1.4803726291528811 2.2807401927269106 1.8212075267208585" />
            </geometry>
        </collision>
    </link>
    <link name="Leg15">
        <inertial>
            <origin xyz="0 0.88000955857589 0" rpy="0 0 0"/>
            <mass value="1" />
            <inertia ixx="100" ixy="0" ixz="0" iyy="100" iyz="0" izz="100" />
        </inertial>
        <visual>
            <origin xyz="0 0.88000955857589 0" rpy="0 0 0"/>
            <geometry>
                <box size="2.052325871525045 1.76001911715178 1.6414206210910536" />
            </geometry>
            <material name="Blue">
                <color rgba="0 1.0 1.0 1.0"/>
            </material>
        </visual>
        <collision>
            <origin xyz="0 0.88000955857589 0" rpy="0 0 0"/>
            <geometry>
                <box size="2.052325871525045 1.76001911715178 1.6414206210910536" />
            </geometry>
        </collision>
    </link>
    <link name="Leg16">
        <inertial>
            <origin xyz="1.3163840843273973 0 0" rpy="0 0 0"/>
            <mass value="1" />
            <inertia ixx="100" ixy="0" ixz="0" iyy="100" iyz="0" izz="100" />
        </inertial>
        <visual>
            <origin xyz="1.3163840843273973 0 0" rpy="0 0 0"/>
            <geometry>
                <box size="2.6327681686547946 1.0422556173378148 1.8428355762155266" />
            </geometry>
            <material name="Green">
                <color rgba="0 180.0 0.0 1.0"/>
            </material>
        </visual>
        <collision>
            <origin xyz="1.3163840843273973 0 0" rpy="0 0 0"/>
            <geometry>
                <box size="2.6327681686547946 1.0422556173378148 1.8428355762155266" />
            </geometry>
        </collision>
    </link>
    <link name="Leg17">
        <inertial>
            <origin xyz="1.0854684385325801 0 0" rpy="0 0 0"/>
            <mass value="1" />
            <inertia ixx="100" ixy="0" ixz="0" iyy="100" iyz="0" izz="100" />
        </inertial>
        <visual>
            <origin xyz="1.0854684385325801 0 0" rpy="0 0 0"/>
            <geometry>
                <box size="2.1709368770651603 1.16675718416934 1.6123178754034646" />
            </geometry>
            <material name="Blue">
                <color rgba="0 1.0 1.0 1.0"/>
            </material>
        </visual>
        <collision>
            <origin xyz="1.0854684385325801 0 0" rpy="0 0 0"/>
            <geometry>
                <box size="2.1709368770651603 1.16675718416934 1.6123178754034646" />
            </geometry>
        </collision>
    </link>
    <link name="Leg18">
        <inertial>
            <origin xyz="0 0 0.589540616022988" rpy="0 0 0"/>
            <mass value="1" />
            <inertia ixx="100" ixy="0" ixz="0" iyy="100" iyz="0" izz="100" />
        </inertial>
        <visual>
            <origin xyz="0 0 0.589540616022988" rpy="0 0 0"/>
            <geometry>
                <box size="2.8334373993909967 1.023550386256154 1.179081232045976" />
            </geometry>
            <material name="Green">
                <color rgba="0 180.0 0.0 1.0"/>
            </material>
        </visual>
        <collision>
            <origin xyz="0 0 0.589540616022988" rpy="0 0 0"/>
            <geometry>
                <box size="2.8334373993909967 1.023550386256154 1.179081232045976" />
            </geometry>
        </collision>
    </link>
    <link name="Leg19">
        <inertial>
            <origin xyz="0 0.5824308913721196 0" rpy="0 0 0"/>
            <mass value="1" />
            <inertia ixx="100" ixy="0" ixz="0" iyy="100" iyz="0" izz="100" />
        </inertial>
        <visual>
            <origin xyz="0 0.5824308913721196 0" rpy="0 0 0"/>
            <geometry>
                <box size="2.380963328123279 1.1648617827442391 2.643559506401374" />
            </geometry>
            <material name="Blue">
                <color rgba="0 1.0 1.0 1.0"/>
            </material>
        </visual>
        <collision>
            <origin xyz="0 0.5824308913721196 0" rpy="0 0 0"/>
            <geometry>
                <box size="2.380963328123279 1.1648617827442391 2.643559506401374" />
            </geometry>
        </collision>
    </link>
    <link name="Leg20">
        <inertial>
            <origin xyz="1.1095613336549746 0 0" rpy="0 0 0"/>
            <mass value="1" />
            <inertia ixx="100" ixy="0" ixz="0" iyy="100" iyz="0" izz="100" />
        </inertial>
        <visual>
            <origin xyz="1.1095613336549746 0 0" rpy="0 0 0"/>
            <geometry>
                <box size="2.219122667309949 1.1463420686170156 2.0483798719721227" />
            </geometry>
            <material name="Green">
                <color rgba="0 180.0 0.0 1.0"/>
            </material>
        </visual>
        <collision>
            <origin xyz="1.1095613336549746 0 0" rpy="0 0 0"/>
            <geometry>
                <box size="2.219122667309949 1.1463420686170156 2.0483798719721227" />
            </geometry>
        </collision>
    </link>
    <link name="Leg21">
        <inertial>
            <origin xyz="0 1.3667034619666008 0" rpy="0 0 0"/>
            <mass value="1" />
            <inertia ixx="100" ixy="0" ixz="0" iyy="100" iyz="0" izz="100" />
        </inertial>
        <visual>
            <origin xyz="0 1.3667034619666008 0" rpy="0 0 0"/>
            <geometry>
                <box size="1.9851159809547099 2.7334069239332015 2.770242358449769" />
            </geometry>
            <material name="Blue">
                <color rgba="0 1.0 1.0 1.0"/>
            </material>
        </visual>
        <collision>
            <origin xyz="0 1.3667034619666008 0" rpy="0 0 0"/>
            <geometry>
                <box size="1.9851159809547099 2.7334069239332015 2.770242358449769" />
            </geometry>
        </collision>
    </link>
    <link name="Leg22">
        <inertial>
            <origin xyz="0 0 1.004738124742565" rpy="0 0 0"/>
            <mass value="1" />
            <inertia ixx="100" ixy="0" ixz="0" iyy="100" iyz="0" izz="100" />
        </inertial>
        <visual>
            <origin xyz="0 0 1.004738124742565" rpy="0 0 0"/>
            <geometry>
                <box size="2.059952119613583 1.3287198932211362 2.00947624948513" />
            </geometry>
            <material name="Green">
                <color rgba="0 180.0 0.0 1.0"/>
            </material>
        </visual>
        <collision>
            <origin xyz="0 0 1.004738124742565" rpy="0 0 0"/>
            <geometry>
                <box size="2.059952119613583 1.3287198932211362 2.00947624948513" />
            </geometry>
        </collision>
    </link>
    <link name="Leg23">
        <inertial>
            <origin xyz="0.7328908893685218 0 0" rpy="0 0 0"/>
            <mass value="1" />
            <inertia ixx="100" ixy="0" ixz="0" iyy="100" iyz="0" izz="100" />
        </inertial>
        <visual>
            <origin xyz="0.7328908893685218 0 0" rpy="0 0 0"/>
            <geometry>
                <box size="1.4657817787370435 2.230125794344361 1.0622885484639317" />
            </geometry>
            <material name="Blue">
                <color rgba="0 1.0 1.0 1.0"/>
            </material>
        </visual>
        <collision>
            <origin xyz="0.7328908893685218 0 0" rpy="0 0 0"/>
            <geometry>
                <box size="1.4657817787370435 2.230125794344361 1.0622885484639317" />
            </geometry>
        </collision>
    </link>
    <link name="Leg24">
        <inertial>
            <origin xyz="0 0 1.1574916080525859" rpy="0 0 0"/>
            <mass value="1" />
            <inertia ixx="100" ixy="0" ixz="0" iyy="100" iyz="0" izz="100" />
        </inertial>
        <visual>
            <origin xyz="0 0 1.1574916080525859" rpy="0 0 0"/>
            <geometry>
                <box size="1.0397023671969505 1.0532581509500254 2.3149832161051718" />
            </geometry>
            <material name="Blue">
                <color rgba="0 1.0 1.0 1.0"/>
            </material>
        </visual>
        <collision>
            <origin xyz="0 0 1.1574916080525859" rpy="0 0 0"/>
            <geometry>
                <box size="1.0397023671969505 1.0532581509500254 2.3149832161051718" />
            </geometry>
        </collision>
    </link>
    <link name="Leg25">
        <inertial>
            <origin xyz="0 0 1.02431396716623" rpy="0 0 0"/>
            <mass value="1" />
            <inertia ixx="100" ixy="0" ixz="0" iyy="100" iyz="0" izz="100" />
        </inertial>
        <visual>
            <origin xyz="0 0 1.02431396716623" rpy="0 0 0"/>
            <geometry>
                <box size="1.1144831477336676 1.1429127670475534 2.04862793433246" />
            </geometry>
            <material name="Green">
                <color rgba="0 180.0 0.0 1.0"/>
            </material>
        </visual>
        <collision>
            <origin xyz="0 0 1.02431396716623" rpy="0 0 0"/>
            <geometry>
                <box size="1.1144831477336676 1.1429127670475534 2.04862793433246" />
            </geometry>
        </collision>
    </link>
    <link name="Leg26">
        <inertial>
            <origin xyz="0 1.4267912338237372 0" rpy="0 0 0"/>
            <mass value="1" />
            <inertia ixx="100" ixy="0" ixz="0" iyy="100" iyz="0" izz="100" />
        </inertial>
        <visual>
            <origin xyz="0 1.4267912338237372 0" rpy="0 0 0"/>
            <geometry>
                <box size="1.1675788684205053 2.8535824676474744 1.6635155960487482" />
            </geometry>
            <material name="Blue">
                <color rgba="0 1.0 1.0 1.0"/>
            </material>
        </visual>
        <collision>
            <origin xyz="0 1.4267912338237372 0" rpy="0 0 0"/>
            <geometry>
                <box size="1.1675788684205053 2.8535824676474744 1.6635155960487482" />
            </geometry>
        </collision>
    </link>
    <joint name="Torso_Leg1" type="revolute">
       <parent link="Torso"/>
       <child  link="Leg1"/>
       <origin rpy="0 0 0" xyz="1.06714915262791 0 0.5053771408538884" />
     <axis xyz="1 0 0"/>
       <limit effort="0.0" lower="-3.14159" upper="3.14159" velocity="0.0"/>
    </joint>
    <joint name="Leg1_Leg2" type="revolute">
       <parent link="Leg1"/>
       <child  link="Leg2"/>
       <origin rpy="0 0 0" xyz="0 1.909746015446057 0" />
     <axis xyz="1 0 0"/>
       <limit effort="0.0" lower="-3.14159" upper="3.14159" velocity="0.0"/>
    </joint>
    <joint name="Torso_Leg3" type="revolute">
       <parent link="Torso"/>
       <child  link="Leg3"/>
       <origin rpy="0 0 0" xyz="1.4501595719285967 0 0.9791713344580747" />
     <axis xyz="1 0 0"/>
       <limit effort="0.0" lower="-3.14159" upper="3.14159" velocity="0.0"/>
    </joint>
    <joint name="Leg3_Leg4" type="revolute">
       <parent link="Leg3"/>
       <child  link="Leg4"/>
       <origin rpy="0 0 0" xyz="1.2027089676187455 0 0" />
     <axis xyz="1 0 0"/>
       <limit effort="0.0" lower="-3.14159" upper="3.14159" velocity="0.0"/>
    </joint>
    <joint name="Leg1_Leg5" type="revolute">
       <parent link="Leg1"/>
       <child  link="Leg5"/>
       <origin rpy="0 0 0" xyz="0 1.909746015446057 1.4440224183421682" />
     <axis xyz="1 0 0"/>
       <limit effort="0.0" lower="-3.14159" upper="3.14159" velocity="0.0"/>
    </joint>
    <joint name="Leg5_Leg6" type="revolute">
       <parent link="Leg5"/>
       <child  link="Leg6"/>
       <origin rpy="0 0 0" xyz="1.1930026095970043 0 0" />
     <axis xyz="1 0 0"/>
       <limit effort="0.0" lower="-3.14159" upper="3.14159" velocity="0.0"/>
    </joint>
    <joint name="Leg3_Leg7" type="revolute">
       <parent link="Leg3"/>
       <child  link="Leg7"/>
       <origin rpy="0 0 0" xyz="1.2027089676187455 1.4481355306004886 0" />
     <axis xyz="1 0 0"/>
       <limit effort="0.0" lower="-3.14159" upper="3.14159" velocity="0.0"/>
    </joint>
    <joint name="Leg4_Leg8" type="revolute">
       <parent link="Leg4"/>
       <child  link="Leg8"/>
       <origin rpy="0 0 0" xyz="1.1708886960433043 0 0.7092044376992143" />
     <axis xyz="1 0 0"/>
       <limit effort="0.0" lower="-3.14159" upper="3.14159" velocity="0.0"/>
    </joint>
    <joint name="Leg3_Leg9" type="revolute">
       <parent link="Leg3"/>
       <child  link="Leg9"/>
       <origin rpy="0 0 0" xyz="1.2027089676187455 1.4481355306004886 0.8387806000101445" />
     <axis xyz="1 0 0"/>
       <limit effort="0.0" lower="-3.14159" upper="3.14159" velocity="0.0"/>
    </joint>
    <joint name="Leg7_Leg10" type="revolute">
       <parent link="Leg7"/>
       <child  link="Leg10"/>
       <origin rpy="0 0 0" xyz="1.1471765068847857 0 0" />
     <axis xyz="1 0 0"/>
       <limit effort="0.0" lower="-3.14159" upper="3.14159" velocity="0.0"/>
    </joint>
    <joint name="Leg8_Leg11" type="revolute">
       <parent link="Leg8"/>
       <child  link="Leg11"/>
       <origin rpy="0 0 0" xyz="1.0679539358006451 0 0.8290188928086786" />
     <axis xyz="1 0 0"/>
       <limit effort="0.0" lower="-3.14159" upper="3.14159" velocity="0.0"/>
    </joint>
    <joint name="Leg10_Leg12" type="revolute">
       <parent link="Leg10"/>
       <child  link="Leg12"/>
       <origin rpy="0 0 0" xyz="1.3167178203667698 1.4115589012818988 0" />
     <axis xyz="1 0 0"/>
       <limit effort="0.0" lower="-3.14159" upper="3.14159" velocity="0.0"/>
    </joint>
    <joint name="Leg9_Leg13" type="revolute">
       <parent link="Leg9"/>
       <child  link="Leg13"/>
       <origin rpy="0 0 0" xyz="1.0736261982198718 0 0" />
     <axis xyz="1 0 0"/>
       <limit effort="0.0" lower="-3.14159" upper="3.14159" velocity="0.0"/>
    </joint>
    <joint name="Leg12_Leg14" type="revolute">
       <parent link="Leg12"/>
       <child  link="Leg14"/>
       <origin rpy="0 0 0" xyz="0.589883163187002 1.4993067318513744 0" />
     <axis xyz="1 0 0"/>
       <limit effort="0.0" lower="-3.14159" upper="3.14159" velocity="0.0"/>
    </joint>
    <joint name="Leg14_Leg15" type="revolute">
       <parent link="Leg14"/>
       <child  link="Leg15"/>
       <origin rpy="0 0 0" xyz="0 1.76001911715178 0" />
     <axis xyz="1 0 0"/>
       <limit effort="0.0" lower="-3.14159" upper="3.14159" velocity="0.0"/>
    </joint>
    <joint name="Leg2_Leg16" type="revolute">
       <parent link="Leg2"/>
       <child  link="Leg16"/>
       <origin rpy="0 0 0" xyz="1.331362923871283 0 0.9760275809396922" />
     <axis xyz="1 0 0"/>
       <limit effort="0.0" lower="-3.14159" upper="3.14159" velocity="0.0"/>
    </joint>
    <joint name="Leg6_Leg17" type="revolute">
       <parent link="Leg6"/>
       <child  link="Leg17"/>
       <origin rpy="0 0 0" xyz="1.0829807368496107 1.3687874717425974 0" />
     <axis xyz="1 0 0"/>
       <limit effort="0.0" lower="-3.14159" upper="3.14159" velocity="0.0"/>
    </joint>
    <joint name="Leg12_Leg18" type="revolute">
       <parent link="Leg12"/>
       <child  link="Leg18"/>
       <origin rpy="0 0 0" xyz="0.589883163187002 1.4993067318513744 0.5690480924248171" />
     <axis xyz="1 0 0"/>
       <limit effort="0.0" lower="-3.14159" upper="3.14159" velocity="0.0"/>
    </joint>
    <joint name="Leg18_Leg19" type="revolute">
       <parent link="Leg18"/>
       <child  link="Leg19"/>
       <origin rpy="0 0 0" xyz="0 1.1648617827442391 0" />
     <axis xyz="1 0 0"/>
       <limit effort="0.0" lower="-3.14159" upper="3.14159" velocity="0.0"/>
    </joint>
    <joint name="Leg10_Leg20" type="revolute">
       <parent link="Leg10"/>
       <child  link="Leg20"/>
       <origin rpy="0 0 0" xyz="2.6334356407335395 1.4115589012818988 0" />
     <axis xyz="1 0 0"/>
       <limit effort="0.0" lower="-3.14159" upper="3.14159" velocity="0.0"/>
    </joint>
    <joint name="Leg15_Leg21" type="revolute">
       <parent link="Leg15"/>
       <child  link="Leg21"/>
       <origin rpy="0 0 0" xyz="1.3163840843273973 0.5211278086689074 0" />
     <axis xyz="1 0 0"/>
       <limit effort="0.0" lower="-3.14159" upper="3.14159" velocity="0.0"/>
    </joint>
    <joint name="Leg21_Leg22" type="revolute">
       <parent link="Leg21"/>
       <child  link="Leg22"/>
       <origin rpy="0 0 0" xyz="0 0 2.00947624948513" />
     <axis xyz="1 0 0"/>
       <limit effort="0.0" lower="-3.14159" upper="3.14159" velocity="0.0"/>
    </joint>
    <joint name="Leg21_Leg23" type="revolute">
       <parent link="Leg21"/>
       <child  link="Leg23"/>
       <origin rpy="0 0 0" xyz="1.0299760598067915 0 2.00947624948513" />
     <axis xyz="1 0 0"/>
       <limit effort="0.0" lower="-3.14159" upper="3.14159" velocity="0.0"/>
    </joint>
    <joint name="Leg4_Leg24" type="revolute">
       <parent link="Leg4"/>
       <child  link="Leg24"/>
       <origin rpy="0 0 0" xyz="1.1708886960433043 0 1.4184088753984285" />
     <axis xyz="1 0 0"/>
       <limit effort="0.0" lower="-3.14159" upper="3.14159" velocity="0.0"/>
    </joint>
    <joint name="Leg14_Leg25" type="revolute">
       <parent link="Leg14"/>
       <child  link="Leg25"/>
       <origin rpy="0 0 0" xyz="0 1.76001911715178 0.8207103105455268" />
     <axis xyz="1 0 0"/>
       <limit effort="0.0" lower="-3.14159" upper="3.14159" velocity="0.0"/>
    </joint>
    <joint name="Leg24_Leg26" type="revolute">
       <parent link="Leg24"/>
       <child  link="Leg26"/>
       <origin rpy="0 0 0" xyz="0 0.5714563835237767 1.02431396716623" />
     <axis xyz="1 0 0"/>
       <limit effort="0.0" lower="-3.14159" upper="3.14159" velocity="0.0"/>
    </joint>
</robot>