<robot name = "robot">
    <link name="Torso">
        <inertial>
            <origin xyz="0 0 0.9064678110278637" rpy="0 0 0"/>
            <mass value="1" />
            <inertia ixx="100" ixy="0" ixz="0" iyy="100" iyz="0" izz="100" />
        </inertial>
        <visual>
            <origin xyz="0 0 0.9064678110278637" rpy="0 0 0"/>
            <geometry>
                <box size="1.1258630776495318 2.9934168104560515 1.8129356220557273" />
            </geometry>
            <material name="Green">
                <color rgba="0 180.0 0.0 1.0"/>
            </material>
        </visual>
        <collision>
            <origin xyz="0 0 0.9064678110278637" rpy="0 0 0"/>
            <geometry>
                <box size="1.1258630776495318 2.9934168104560515 1.8129356220557273" />
            </geometry>
        </collision>
    </link>
    <link name="Leg1">
        <inertial>
            <origin xyz="1.0657579925805922 0 0" rpy="0 0 0"/>
            <mass value="1" />
            <inertia ixx="100" ixy="0" ixz="0" iyy="100" iyz="0" izz="100" />
        </inertial>
        <visual>
            <origin xyz="1.0657579925805922 0 0" rpy="0 0 0"/>
            <geometry>
                <box size="2.1315159851611845 2.559228201456055 1.2061139678836545" />
            </geometry>
            <material name="Blue">
                <color rgba="0 1.0 1.0 1.0"/>
            </material>
        </visual>
        <collision>
            <origin xyz="1.0657579925805922 0 0" rpy="0 0 0"/>
            <geometry>
                <box size="2.1315159851611845 2.559228201456055 1.2061139678836545" />
            </geometry>
        </collision>
    </link>
    <link name="Leg2">
        <inertial>
            <origin xyz="0 0 0.9065329297712046" rpy="0 0 0"/>
            <mass value="1" />
            <inertia ixx="100" ixy="0" ixz="0" iyy="100" iyz="0" izz="100" />
        </inertial>
        <visual>
            <origin xyz="0 0 0.9065329297712046" rpy="0 0 0"/>
            <geometry>
                <box size="2.577716346813138 2.4583548333740888 1.8130658595424092" />
            </geometry>
            <material name="Green">
                <color rgba="0 180.0 0.0 1.0"/>
            </material>
        </visual>
        <collision>
            <origin xyz="0 0 0.9065329297712046" rpy="0 0 0"/>
            <geometry>
                <box size="2.577716346813138 2.4583548333740888 1.8130658595424092" />
            </geometry>
        </collision>
    </link>
    <link name="Leg3">
        <inertial>
            <origin xyz="0.9984212741825975 0 0" rpy="0 0 0"/>
            <mass value="1" />
            <inertia ixx="100" ixy="0" ixz="0" iyy="100" iyz="0" izz="100" />
        </inertial>
        <visual>
            <origin xyz="0.9984212741825975 0 0" rpy="0 0 0"/>
            <geometry>
                <box size="1.996842548365195 2.789048463818304 2.2308779598567483" />
            </geometry>
            <material name="Green">
                <color rgba="0 180.0 0.0 1.0"/>
            </material>
        </visual>
        <collision>
            <origin xyz="0.9984212741825975 0 0" rpy="0 0 0"/>
            <geometry>
                <box size="1.996842548365195 2.789048463818304 2.2308779598567483" />
            </geometry>
        </collision>
    </link>
    <link name="Leg4">
        <inertial>
            <origin xyz="0 0.7795822330908206 0" rpy="0 0 0"/>
            <mass value="1" />
            <inertia ixx="100" ixy="0" ixz="0" iyy="100" iyz="0" izz="100" />
        </inertial>
        <visual>
            <origin xyz="0 0.7795822330908206 0" rpy="0 0 0"/>
            <geometry>
                <box size="2.200420266138325 1.5591644661816413 1.1861032153389603" />
            </geometry>
            <material name="Green">
                <color rgba="0 180.0 0.0 1.0"/>
            </material>
        </visual>
        <collision>
            <origin xyz="0 0.7795822330908206 0" rpy="0 0 0"/>
            <geometry>
                <box size="2.200420266138325 1.5591644661816413 1.1861032153389603" />
            </geometry>
        </collision>
    </link>
    <link name="Leg5">
        <inertial>
            <origin xyz="1.491314805416807 0 0" rpy="0 0 0"/>
            <mass value="1" />
            <inertia ixx="100" ixy="0" ixz="0" iyy="100" iyz="0" izz="100" />
        </inertial>
        <visual>
            <origin xyz="1.491314805416807 0 0" rpy="0 0 0"/>
            <geometry>
                <box size="2.982629610833614 2.27119124871717 2.372798126799569" />
            </geometry>
            <material name="Blue">
                <color rgba="0 1.0 1.0 1.0"/>
            </material>
        </visual>
        <collision>
            <origin xyz="1.491314805416807 0 0" rpy="0 0 0"/>
            <geometry>
                <box size="2.982629610833614 2.27119124871717 2.372798126799569" />
            </geometry>
        </collision>
    </link>
    <link name="Leg6">
        <inertial>
            <origin xyz="0 0 0.5108187010323891" rpy="0 0 0"/>
            <mass value="1" />
            <inertia ixx="100" ixy="0" ixz="0" iyy="100" iyz="0" izz="100" />
        </inertial>
        <visual>
            <origin xyz="0 0 0.5108187010323891" rpy="0 0 0"/>
            <geometry>
                <box size="1.6687681681071393 2.0283685050979985 1.0216374020647783" />
            </geometry>
            <material name="Green">
                <color rgba="0 180.0 0.0 1.0"/>
            </material>
        </visual>
        <collision>
            <origin xyz="0 0 0.5108187010323891" rpy="0 0 0"/>
            <geometry>
                <box size="1.6687681681071393 2.0283685050979985 1.0216374020647783" />
            </geometry>
        </collision>
    </link>
    <link name="Leg7">
        <inertial>
            <origin xyz="0 1.0276857239491823 0" rpy="0 0 0"/>
            <mass value="1" />
            <inertia ixx="100" ixy="0" ixz="0" iyy="100" iyz="0" izz="100" />
        </inertial>
        <visual>
            <origin xyz="0 1.0276857239491823 0" rpy="0 0 0"/>
            <geometry>
                <box size="2.552994554846557 2.0553714478983647 2.9390874570405563" />
            </geometry>
            <material name="Blue">
                <color rgba="0 1.0 1.0 1.0"/>
            </material>
        </visual>
        <collision>
            <origin xyz="0 1.0276857239491823 0" rpy="0 0 0"/>
            <geometry>
                <box size="2.552994554846557 2.0553714478983647 2.9390874570405563" />
            </geometry>
        </collision>
    </link>
    <link name="Leg8">
        <inertial>
            <origin xyz="0 0.7337177099319315 0" rpy="0 0 0"/>
            <mass value="1" />
            <inertia ixx="100" ixy="0" ixz="0" iyy="100" iyz="0" izz="100" />
        </inertial>
        <visual>
            <origin xyz="0 0.7337177099319315 0" rpy="0 0 0"/>
            <geometry>
                <box size="1.3053849033064475 1.467435419863863 2.2415199640947465" />
            </geometry>
            <material name="Blue">
                <color rgba="0 1.0 1.0 1.0"/>
            </material>
        </visual>
        <collision>
            <origin xyz="0 0.7337177099319315 0" rpy="0 0 0"/>
            <geometry>
                <box size="1.3053849033064475 1.467435419863863 2.2415199640947465" />
            </geometry>
        </collision>
    </link>
    <link name="Leg9">
        <inertial>
            <origin xyz="0 0 0.9720759446398215" rpy="0 0 0"/>
            <mass value="1" />
            <inertia ixx="100" ixy="0" ixz="0" iyy="100" iyz="0" izz="100" />
        </inertial>
        <visual>
            <origin xyz="0 0 0.9720759446398215" rpy="0 0 0"/>
            <geometry>
                <box size="1.4090079108324058 2.7585064241306054 1.944151889279643" />
            </geometry>
            <material name="Blue">
                <color rgba="0 1.0 1.0 1.0"/>
            </material>
        </visual>
        <collision>
            <origin xyz="0 0 0.9720759446398215" rpy="0 0 0"/>
            <geometry>
                <box size="1.4090079108324058 2.7585064241306054 1.944151889279643" />
            </geometry>
        </collision>
    </link>
    <link name="Leg10">
        <inertial>
            <origin xyz="1.4674524323412417 0 0" rpy="0 0 0"/>
            <mass value="1" />
            <inertia ixx="100" ixy="0" ixz="0" iyy="100" iyz="0" izz="100" />
        </inertial>
        <visual>
            <origin xyz="1.4674524323412417 0 0" rpy="0 0 0"/>
            <geometry>
                <box size="2.9349048646824833 2.3947918842392615 2.733193019265255" />
            </geometry>
            <material name="Blue">
                <color rgba="0 1.0 1.0 1.0"/>
            </material>
        </visual>
        <collision>
            <origin xyz="1.4674524323412417 0 0" rpy="0 0 0"/>
            <geometry>
                <box size="2.9349048646824833 2.3947918842392615 2.733193019265255" />
            </geometry>
        </collision>
    </link>
    <link name="Leg11">
        <inertial>
            <origin xyz="0.5436685315670038 0 0" rpy="0 0 0"/>
            <mass value="1" />
            <inertia ixx="100" ixy="0" ixz="0" iyy="100" iyz="0" izz="100" />
        </inertial>
        <visual>
            <origin xyz="0.5436685315670038 0 0" rpy="0 0 0"/>
            <geometry>
                <box size="1.0873370631340076 1.3421403162203718 1.0012309304376616" />
            </geometry>
            <material name="Green">
                <color rgba="0 180.0 0.0 1.0"/>
            </material>
        </visual>
        <collision>
            <origin xyz="0.5436685315670038 0 0" rpy="0 0 0"/>
            <geometry>
                <box size="1.0873370631340076 1.3421403162203718 1.0012309304376616" />
            </geometry>
        </collision>
    </link>
    <link name="Leg12">
        <inertial>
            <origin xyz="0.5784602157949617 0 0" rpy="0 0 0"/>
            <mass value="1" />
            <inertia ixx="100" ixy="0" ixz="0" iyy="100" iyz="0" izz="100" />
        </inertial>
        <visual>
            <origin xyz="0.5784602157949617 0 0" rpy="0 0 0"/>
            <geometry>
                <box size="1.1569204315899233 2.014295714693727 1.2438741741413324" />
            </geometry>
            <material name="Blue">
                <color rgba="0 1.0 1.0 1.0"/>
            </material>
        </visual>
        <collision>
            <origin xyz="0.5784602157949617 0 0" rpy="0 0 0"/>
            <geometry>
                <box size="1.1569204315899233 2.014295714693727 1.2438741741413324" />
            </geometry>
        </collision>
    </link>
    <link name="Leg13">
        <inertial>
            <origin xyz="1.393288171479859 0 0" rpy="0 0 0"/>
            <mass value="1" />
            <inertia ixx="100" ixy="0" ixz="0" iyy="100" iyz="0" izz="100" />
        </inertial>
        <visual>
            <origin xyz="1.393288171479859 0 0" rpy="0 0 0"/>
            <geometry>
                <box size="2.786576342959718 1.6968614677334706 2.8315332360160586" />
            </geometry>
            <material name="Blue">
                <color rgba="0 1.0 1.0 1.0"/>
            </material>
        </visual>
        <collision>
            <origin xyz="1.393288171479859 0 0" rpy="0 0 0"/>
            <geometry>
                <box size="2.786576342959718 1.6968614677334706 2.8315332360160586" />
            </geometry>
        </collision>
    </link>
    <link name="Leg14">
        <inertial>
            <origin xyz="0 0 0.525657781729905" rpy="0 0 0"/>
            <mass value="1" />
            <inertia ixx="100" ixy="0" ixz="0" iyy="100" iyz="0" izz="100" />
        </inertial>
        <visual>
            <origin xyz="0 0 0.525657781729905" rpy="0 0 0"/>
            <geometry>
                <box size="1.1528252315595706 2.094811183905339 1.05131556345981" />
            </geometry>
            <material name="Green">
                <color rgba="0 180.0 0.0 1.0"/>
            </material>
        </visual>
        <collision>
            <origin xyz="0 0 0.525657781729905" rpy="0 0 0"/>
            <geometry>
                <box size="1.1528252315595706 2.094811183905339 1.05131556345981" />
            </geometry>
        </collision>
    </link>
    <link name="Leg15">
        <inertial>
            <origin xyz="0.5030232484442823 0 0" rpy="0 0 0"/>
            <mass value="1" />
            <inertia ixx="100" ixy="0" ixz="0" iyy="100" iyz="0" izz="100" />
        </inertial>
        <visual>
            <origin xyz="0.5030232484442823 0 0" rpy="0 0 0"/>
            <geometry>
                <box size="1.0060464968885645 1.0795544843272982 1.726541494768295" />
            </geometry>
            <material name="Blue">
                <color rgba="0 1.0 1.0 1.0"/>
            </material>
        </visual>
        <collision>
            <origin xyz="0.5030232484442823 0 0" rpy="0 0 0"/>
            <geometry>
                <box size="1.0060464968885645 1.0795544843272982 1.726541494768295" />
            </geometry>
        </collision>
    </link>
    <link name="Leg16">
        <inertial>
            <origin xyz="1.325169299967047 0 0" rpy="0 0 0"/>
            <mass value="1" />
            <inertia ixx="100" ixy="0" ixz="0" iyy="100" iyz="0" izz="100" />
        </inertial>
        <visual>
            <origin xyz="1.325169299967047 0 0" rpy="0 0 0"/>
            <geometry>
                <box size="2.650338599934094 1.0180376655482894 1.8586767277625047" />
            </geometry>
            <material name="Green">
                <color rgba="0 180.0 0.0 1.0"/>
            </material>
        </visual>
        <collision>
            <origin xyz="1.325169299967047 0 0" rpy="0 0 0"/>
            <geometry>
                <box size="2.650338599934094 1.0180376655482894 1.8586767277625047" />
            </geometry>
        </collision>
    </link>
    <link name="Leg17">
        <inertial>
            <origin xyz="0 0 0.9577744807344215" rpy="0 0 0"/>
            <mass value="1" />
            <inertia ixx="100" ixy="0" ixz="0" iyy="100" iyz="0" izz="100" />
        </inertial>
        <visual>
            <origin xyz="0 0 0.9577744807344215" rpy="0 0 0"/>
            <geometry>
                <box size="2.2043394127024403 1.2521151329141456 1.915548961468843" />
            </geometry>
            <material name="Blue">
                <color rgba="0 1.0 1.0 1.0"/>
            </material>
        </visual>
        <collision>
            <origin xyz="0 0 0.9577744807344215" rpy="0 0 0"/>
            <geometry>
                <box size="2.2043394127024403 1.2521151329141456 1.915548961468843" />
            </geometry>
        </collision>
    </link>
    <link name="Leg18">
        <inertial>
            <origin xyz="1.324148846394602 0 0" rpy="0 0 0"/>
            <mass value="1" />
            <inertia ixx="100" ixy="0" ixz="0" iyy="100" iyz="0" izz="100" />
        </inertial>
        <visual>
            <origin xyz="1.324148846394602 0 0" rpy="0 0 0"/>
            <geometry>
                <box size="2.648297692789204 1.6739499582936652 2.7285324578036674" />
            </geometry>
            <material name="Green">
                <color rgba="0 180.0 0.0 1.0"/>
            </material>
        </visual>
        <collision>
            <origin xyz="1.324148846394602 0 0" rpy="0 0 0"/>
            <geometry>
                <box size="2.648297692789204 1.6739499582936652 2.7285324578036674" />
            </geometry>
        </collision>
    </link>
    <link name="Leg19">
        <inertial>
            <origin xyz="0 0 1.297936526785684" rpy="0 0 0"/>
            <mass value="1" />
            <inertia ixx="100" ixy="0" ixz="0" iyy="100" iyz="0" izz="100" />
        </inertial>
        <visual>
            <origin xyz="0 0 1.297936526785684" rpy="0 0 0"/>
            <geometry>
                <box size="2.0901488771684624 1.7895615629288457 2.595873053571368" />
            </geometry>
            <material name="Blue">
                <color rgba="0 1.0 1.0 1.0"/>
            </material>
        </visual>
        <collision>
            <origin xyz="0 0 1.297936526785684" rpy="0 0 0"/>
            <geometry>
                <box size="2.0901488771684624 1.7895615629288457 2.595873053571368" />
            </geometry>
        </collision>
    </link>
    <link name="Leg20">
        <inertial>
            <origin xyz="0.8424914712116897 0 0" rpy="0 0 0"/>
            <mass value="1" />
            <inertia ixx="100" ixy="0" ixz="0" iyy="100" iyz="0" izz="100" />
        </inertial>
        <visual>
            <origin xyz="0.8424914712116897 0 0" rpy="0 0 0"/>
            <geometry>
                <box size="1.6849829424233793 2.009735428015134 2.857797534309987" />
            </geometry>
            <material name="Blue">
                <color rgba="0 1.0 1.0 1.0"/>
            </material>
        </visual>
        <collision>
            <origin xyz="0.8424914712116897 0 0" rpy="0 0 0"/>
            <geometry>
                <box size="1.6849829424233793 2.009735428015134 2.857797534309987" />
            </geometry>
        </collision>
    </link>
    <link name="Leg21">
        <inertial>
            <origin xyz="0.6648970043566115 0 0" rpy="0 0 0"/>
            <mass value="1" />
            <inertia ixx="100" ixy="0" ixz="0" iyy="100" iyz="0" izz="100" />
        </inertial>
        <visual>
            <origin xyz="0.6648970043566115 0 0" rpy="0 0 0"/>
            <geometry>
                <box size="1.329794008713223 1.3083033501612755 2.2746933273537904" />
            </geometry>
            <material name="Green">
                <color rgba="0 180.0 0.0 1.0"/>
            </material>
        </visual>
        <collision>
            <origin xyz="0.6648970043566115 0 0" rpy="0 0 0"/>
            <geometry>
                <box size="1.329794008713223 1.3083033501612755 2.2746933273537904" />
            </geometry>
        </collision>
    </link>
    <link name="Leg22">
        <inertial>
            <origin xyz="0.717517655723675 0 0" rpy="0 0 0"/>
            <mass value="1" />
            <inertia ixx="100" ixy="0" ixz="0" iyy="100" iyz="0" izz="100" />
        </inertial>
        <visual>
            <origin xyz="0.717517655723675 0 0" rpy="0 0 0"/>
            <geometry>
                <box size="1.43503531144735 1.3771314809723625 1.2515221120916895" />
            </geometry>
            <material name="Blue">
                <color rgba="0 1.0 1.0 1.0"/>
            </material>
        </visual>
        <collision>
            <origin xyz="0.717517655723675 0 0" rpy="0 0 0"/>
            <geometry>
                <box size="1.43503531144735 1.3771314809723625 1.2515221120916895" />
            </geometry>
        </collision>
    </link>
    <link name="Leg23">
        <inertial>
            <origin xyz="0 0 1.133289444229296" rpy="0 0 0"/>
            <mass value="1" />
            <inertia ixx="100" ixy="0" ixz="0" iyy="100" iyz="0" izz="100" />
        </inertial>
        <visual>
            <origin xyz="0 0 1.133289444229296" rpy="0 0 0"/>
            <geometry>
                <box size="1.2896507860949211 2.76241856446582 2.266578888458592" />
            </geometry>
            <material name="Blue">
                <color rgba="0 1.0 1.0 1.0"/>
            </material>
        </visual>
        <collision>
            <origin xyz="0 0 1.133289444229296" rpy="0 0 0"/>
            <geometry>
                <box size="1.2896507860949211 2.76241856446582 2.266578888458592" />
            </geometry>
        </collision>
    </link>
    <link name="Leg24">
        <inertial>
            <origin xyz="0 0 1.2086793830503595" rpy="0 0 0"/>
            <mass value="1" />
            <inertia ixx="100" ixy="0" ixz="0" iyy="100" iyz="0" izz="100" />
        </inertial>
        <visual>
            <origin xyz="0 0 1.2086793830503595" rpy="0 0 0"/>
            <geometry>
                <box size="2.3622400442979528 1.0142026450221138 2.417358766100719" />
            </geometry>
            <material name="Green">
                <color rgba="0 180.0 0.0 1.0"/>
            </material>
        </visual>
        <collision>
            <origin xyz="0 0 1.2086793830503595" rpy="0 0 0"/>
            <geometry>
                <box size="2.3622400442979528 1.0142026450221138 2.417358766100719" />
            </geometry>
        </collision>
    </link>
    <link name="Leg25">
        <inertial>
            <origin xyz="0 0.6053507458338836 0" rpy="0 0 0"/>
            <mass value="1" />
            <inertia ixx="100" ixy="0" ixz="0" iyy="100" iyz="0" izz="100" />
        </inertial>
        <visual>
            <origin xyz="0 0.6053507458338836 0" rpy="0 0 0"/>
            <geometry>
                <box size="2.442293682267765 1.2107014916677672 1.7368651618637032" />
            </geometry>
            <material name="Green">
                <color rgba="0 180.0 0.0 1.0"/>
            </material>
        </visual>
        <collision>
            <origin xyz="0 0.6053507458338836 0" rpy="0 0 0"/>
            <geometry>
                <box size="2.442293682267765 1.2107014916677672 1.7368651618637032" />
            </geometry>
        </collision>
    </link>
    <link name="Leg26">
        <inertial>
            <origin xyz="0 0 1.2089681172664617" rpy="0 0 0"/>
            <mass value="1" />
            <inertia ixx="100" ixy="0" ixz="0" iyy="100" iyz="0" izz="100" />
        </inertial>
        <visual>
            <origin xyz="0 0 1.2089681172664617" rpy="0 0 0"/>
            <geometry>
                <box size="1.8841643708591986 1.995356808679919 2.4179362345329234" />
            </geometry>
            <material name="Blue">
                <color rgba="0 1.0 1.0 1.0"/>
            </material>
        </visual>
        <collision>
            <origin xyz="0 0 1.2089681172664617" rpy="0 0 0"/>
            <geometry>
                <box size="1.8841643708591986 1.995356808679919 2.4179362345329234" />
            </geometry>
        </collision>
    </link>
    <joint name="Torso_Leg1" type="revolute">
       <parent link="Torso"/>
       <child  link="Leg1"/>
       <origin rpy="0 0 0" xyz="0.5629315388247659 0 0.9064678110278637" />
     <axis xyz="1 0 0"/>
       <limit effort="0.0" lower="-3.14159" upper="3.14159" velocity="0.0"/>
    </joint>
    <joint name="Torso_Leg2" type="revolute">
       <parent link="Torso"/>
       <child  link="Leg2"/>
       <origin rpy="0 0 0" xyz="1.0657579925805922 0 0.6030569839418273" />
     <axis xyz="1 0 0"/>
       <limit effort="0.0" lower="-3.14159" upper="3.14159" velocity="0.0"/>
    </joint>
    <joint name="Leg1_Leg3" type="revolute">
       <parent link="Leg1"/>
       <child  link="Leg3"/>
       <origin rpy="0 0 0" xyz="1.288858173406569 0 0.9065329297712046" />
     <axis xyz="1 0 0"/>
       <limit effort="0.0" lower="-3.14159" upper="3.14159" velocity="0.0"/>
    </joint>
    <joint name="Leg3_Leg4" type="revolute">
       <parent link="Leg3"/>
       <child  link="Leg4"/>
       <origin rpy="0 0 0" xyz="0 1.5591644661816413 0" />
     <axis xyz="1 0 0"/>
       <limit effort="0.0" lower="-3.14159" upper="3.14159" velocity="0.0"/>
    </joint>
    <joint name="Leg4_Leg5" type="revolute">
       <parent link="Leg4"/>
       <child  link="Leg5"/>
       <origin rpy="0 0 0" xyz="2.982629610833614 0 0" />
     <axis xyz="1 0 0"/>
       <limit effort="0.0" lower="-3.14159" upper="3.14159" velocity="0.0"/>
    </joint>
    <joint name="Leg2_Leg6" type="revolute">
       <parent link="Leg2"/>
       <child  link="Leg6"/>
       <origin rpy="0 0 0" xyz="0.9984212741825975 0 1.1154389799283742" />
     <axis xyz="1 0 0"/>
       <limit effort="0.0" lower="-3.14159" upper="3.14159" velocity="0.0"/>
    </joint>
    <joint name="Torso_Leg7" type="revolute">
       <parent link="Torso"/>
       <child  link="Leg7"/>
       <origin rpy="0 0 0" xyz="1.0657579925805922 1.2796141007280275 0.6030569839418273" />
     <axis xyz="1 0 0"/>
       <limit effort="0.0" lower="-3.14159" upper="3.14159" velocity="0.0"/>
    </joint>
    <joint name="Leg5_Leg8" type="revolute">
       <parent link="Leg5"/>
       <child  link="Leg8"/>
       <origin rpy="0 0 0" xyz="0 1.0141842525489992 0.5108187010323891" />
     <axis xyz="1 0 0"/>
       <limit effort="0.0" lower="-3.14159" upper="3.14159" velocity="0.0"/>
    </joint>
    <joint name="Leg4_Leg9" type="revolute">
       <parent link="Leg4"/>
       <child  link="Leg9"/>
       <origin rpy="0 0 0" xyz="2.982629610833614 0 1.1863990633997845" />
     <axis xyz="1 0 0"/>
       <limit effort="0.0" lower="-3.14159" upper="3.14159" velocity="0.0"/>
    </joint>
    <joint name="Leg5_Leg10" type="revolute">
       <parent link="Leg5"/>
       <child  link="Leg10"/>
       <origin rpy="0 0 0" xyz="0.8343840840535697 1.0141842525489992 0.5108187010323891" />
     <axis xyz="1 0 0"/>
       <limit effort="0.0" lower="-3.14159" upper="3.14159" velocity="0.0"/>
    </joint>
    <joint name="Leg3_Leg11" type="revolute">
       <parent link="Leg3"/>
       <child  link="Leg11"/>
       <origin rpy="0 0 0" xyz="1.1002101330691625 1.5591644661816413 0" />
     <axis xyz="1 0 0"/>
       <limit effort="0.0" lower="-3.14159" upper="3.14159" velocity="0.0"/>
    </joint>
    <joint name="Leg2_Leg12" type="revolute">
       <parent link="Leg2"/>
       <child  link="Leg12"/>
       <origin rpy="0 0 0" xyz="1.996842548365195 0 1.1154389799283742" />
     <axis xyz="1 0 0"/>
       <limit effort="0.0" lower="-3.14159" upper="3.14159" velocity="0.0"/>
    </joint>
    <joint name="Leg11_Leg13" type="revolute">
       <parent link="Leg11"/>
       <child  link="Leg13"/>
       <origin rpy="0 0 0" xyz="1.1569204315899233 0 0" />
     <axis xyz="1 0 0"/>
       <limit effort="0.0" lower="-3.14159" upper="3.14159" velocity="0.0"/>
    </joint>
    <joint name="Leg1_Leg14" type="revolute">
       <parent link="Leg1"/>
       <child  link="Leg14"/>
       <origin rpy="0 0 0" xyz="1.288858173406569 0 1.8130658595424092" />
     <axis xyz="1 0 0"/>
       <limit effort="0.0" lower="-3.14159" upper="3.14159" velocity="0.0"/>
    </joint>
    <joint name="Leg8_Leg15" type="revolute">
       <parent link="Leg8"/>
       <child  link="Leg15"/>
       <origin rpy="0 0 0" xyz="0.7045039554162029 0 0.9720759446398215" />
     <axis xyz="1 0 0"/>
       <limit effort="0.0" lower="-3.14159" upper="3.14159" velocity="0.0"/>
    </joint>
    <joint name="Leg14_Leg16" type="revolute">
       <parent link="Leg14"/>
       <child  link="Leg16"/>
       <origin rpy="0 0 0" xyz="1.0060464968885645 0 0" />
     <axis xyz="1 0 0"/>
       <limit effort="0.0" lower="-3.14159" upper="3.14159" velocity="0.0"/>
    </joint>
    <joint name="Leg14_Leg17" type="revolute">
       <parent link="Leg14"/>
       <child  link="Leg17"/>
       <origin rpy="0 0 0" xyz="1.0060464968885645 0 0.8632707473841476" />
     <axis xyz="1 0 0"/>
       <limit effort="0.0" lower="-3.14159" upper="3.14159" velocity="0.0"/>
    </joint>
    <joint name="Leg6_Leg18" type="revolute">
       <parent link="Leg6"/>
       <child  link="Leg18"/>
       <origin rpy="0 0 0" xyz="1.2764972774232786 1.0276857239491823 0" />
     <axis xyz="1 0 0"/>
       <limit effort="0.0" lower="-3.14159" upper="3.14159" velocity="0.0"/>
    </joint>
    <joint name="Leg18_Leg19" type="revolute">
       <parent link="Leg18"/>
       <child  link="Leg19"/>
       <origin rpy="0 0 0" xyz="0 0 2.595873053571368" />
     <axis xyz="1 0 0"/>
       <limit effort="0.0" lower="-3.14159" upper="3.14159" velocity="0.0"/>
    </joint>
    <joint name="Leg13_Leg20" type="revolute">
       <parent link="Leg13"/>
       <child  link="Leg20"/>
       <origin rpy="0 0 0" xyz="0.5764126157797853 0 0.525657781729905" />
     <axis xyz="1 0 0"/>
       <limit effort="0.0" lower="-3.14159" upper="3.14159" velocity="0.0"/>
    </joint>
    <joint name="Leg20_Leg21" type="revolute">
       <parent link="Leg20"/>
       <child  link="Leg21"/>
       <origin rpy="0 0 0" xyz="1.329794008713223 0 0" />
     <axis xyz="1 0 0"/>
       <limit effort="0.0" lower="-3.14159" upper="3.14159" velocity="0.0"/>
    </joint>
    <joint name="Leg12_Leg22" type="revolute">
       <parent link="Leg12"/>
       <child  link="Leg22"/>
       <origin rpy="0 0 0" xyz="2.786576342959718 0 0" />
     <axis xyz="1 0 0"/>
       <limit effort="0.0" lower="-3.14159" upper="3.14159" velocity="0.0"/>
    </joint>
    <joint name="Leg12_Leg23" type="revolute">
       <parent link="Leg12"/>
       <child  link="Leg23"/>
       <origin rpy="0 0 0" xyz="2.786576342959718 0 1.4157666180080293" />
     <axis xyz="1 0 0"/>
       <limit effort="0.0" lower="-3.14159" upper="3.14159" velocity="0.0"/>
    </joint>
    <joint name="Leg16_Leg24" type="revolute">
       <parent link="Leg16"/>
       <child  link="Leg24"/>
       <origin rpy="0 0 0" xyz="0 0 1.915548961468843" />
     <axis xyz="1 0 0"/>
       <limit effort="0.0" lower="-3.14159" upper="3.14159" velocity="0.0"/>
    </joint>
    <joint name="Leg15_Leg25" type="revolute">
       <parent link="Leg15"/>
       <child  link="Leg25"/>
       <origin rpy="0 0 0" xyz="1.325169299967047 0.5090188327741447 0" />
     <axis xyz="1 0 0"/>
       <limit effort="0.0" lower="-3.14159" upper="3.14159" velocity="0.0"/>
    </joint>
    <joint name="Leg9_Leg26" type="revolute">
       <parent link="Leg9"/>
       <child  link="Leg26"/>
       <origin rpy="0 0 0" xyz="1.4674524323412417 0 1.3665965096326276" />
     <axis xyz="1 0 0"/>
       <limit effort="0.0" lower="-3.14159" upper="3.14159" velocity="0.0"/>
    </joint>
</robot>