<robot name = "robot">
    <link name="Torso">
        <inertial>
            <origin xyz="0 0 0.9662766994794822" rpy="0 0 0"/>
            <mass value="1" />
            <inertia ixx="100" ixy="0" ixz="0" iyy="100" iyz="0" izz="100" />
        </inertial>
        <visual>
            <origin xyz="0 0 0.9662766994794822" rpy="0 0 0"/>
            <geometry>
                <box size="1.8090548431790845 1.2962499034760002 1.9325533989589645" />
            </geometry>
            <material name="Green">
                <color rgba="0 180.0 0.0 1.0"/>
            </material>
        </visual>
        <collision>
            <origin xyz="0 0 0.9662766994794822" rpy="0 0 0"/>
            <geometry>
                <box size="1.8090548431790845 1.2962499034760002 1.9325533989589645" />
            </geometry>
        </collision>
    </link>
    <link name="Leg1">
        <inertial>
            <origin xyz="1.4825414670555994 0 0" rpy="0 0 0"/>
            <mass value="1" />
            <inertia ixx="100" ixy="0" ixz="0" iyy="100" iyz="0" izz="100" />
        </inertial>
        <visual>
            <origin xyz="1.4825414670555994 0 0" rpy="0 0 0"/>
            <geometry>
                <box size="2.965082934111199 2.9541325932022877 1.1003198182296399" />
            </geometry>
            <material name="Blue">
                <color rgba="0 1.0 1.0 1.0"/>
            </material>
        </visual>
        <collision>
            <origin xyz="1.4825414670555994 0 0" rpy="0 0 0"/>
            <geometry>
                <box size="2.965082934111199 2.9541325932022877 1.1003198182296399" />
            </geometry>
        </collision>
    </link>
    <link name="Leg2">
        <inertial>
            <origin xyz="0 0 0.9595394367499899" rpy="0 0 0"/>
            <mass value="1" />
            <inertia ixx="100" ixy="0" ixz="0" iyy="100" iyz="0" izz="100" />
        </inertial>
        <visual>
            <origin xyz="0 0 0.9595394367499899" rpy="0 0 0"/>
            <geometry>
                <box size="1.602601564287319 1.1006459662503911 1.9190788734999797" />
            </geometry>
            <material name="Green">
                <color rgba="0 180.0 0.0 1.0"/>
            </material>
        </visual>
        <collision>
            <origin xyz="0 0 0.9595394367499899" rpy="0 0 0"/>
            <geometry>
                <box size="1.602601564287319 1.1006459662503911 1.9190788734999797" />
            </geometry>
        </collision>
    </link>
    <link name="Leg3">
        <inertial>
            <origin xyz="0 0 1.1389648563546102" rpy="0 0 0"/>
            <mass value="1" />
            <inertia ixx="100" ixy="0" ixz="0" iyy="100" iyz="0" izz="100" />
        </inertial>
        <visual>
            <origin xyz="0 0 1.1389648563546102" rpy="0 0 0"/>
            <geometry>
                <box size="2.200152813333314 1.8023639014254236 2.2779297127092204" />
            </geometry>
            <material name="Green">
                <color rgba="0 180.0 0.0 1.0"/>
            </material>
        </visual>
        <collision>
            <origin xyz="0 0 1.1389648563546102" rpy="0 0 0"/>
            <geometry>
                <box size="2.200152813333314 1.8023639014254236 2.2779297127092204" />
            </geometry>
        </collision>
    </link>
    <link name="Leg4">
        <inertial>
            <origin xyz="0.5765657779027428 0 0" rpy="0 0 0"/>
            <mass value="1" />
            <inertia ixx="100" ixy="0" ixz="0" iyy="100" iyz="0" izz="100" />
        </inertial>
        <visual>
            <origin xyz="0.5765657779027428 0 0" rpy="0 0 0"/>
            <geometry>
                <box size="1.1531315558054855 1.7599427568445827 1.0766965690488668" />
            </geometry>
            <material name="Green">
                <color rgba="0 180.0 0.0 1.0"/>
            </material>
        </visual>
        <collision>
            <origin xyz="0.5765657779027428 0 0" rpy="0 0 0"/>
            <geometry>
                <box size="1.1531315558054855 1.7599427568445827 1.0766965690488668" />
            </geometry>
        </collision>
    </link>
    <link name="Leg5">
        <inertial>
            <origin xyz="0.6404426891004362 0 0" rpy="0 0 0"/>
            <mass value="1" />
            <inertia ixx="100" ixy="0" ixz="0" iyy="100" iyz="0" izz="100" />
        </inertial>
        <visual>
            <origin xyz="0.6404426891004362 0 0" rpy="0 0 0"/>
            <geometry>
                <box size="1.2808853782008724 2.5726049975842025 2.4347232460401447" />
            </geometry>
            <material name="Blue">
                <color rgba="0 1.0 1.0 1.0"/>
            </material>
        </visual>
        <collision>
            <origin xyz="0.6404426891004362 0 0" rpy="0 0 0"/>
            <geometry>
                <box size="1.2808853782008724 2.5726049975842025 2.4347232460401447" />
            </geometry>
        </collision>
    </link>
    <link name="Leg6">
        <inertial>
            <origin xyz="0.679980250353313 0 0" rpy="0 0 0"/>
            <mass value="1" />
            <inertia ixx="100" ixy="0" ixz="0" iyy="100" iyz="0" izz="100" />
        </inertial>
        <visual>
            <origin xyz="0.679980250353313 0 0" rpy="0 0 0"/>
            <geometry>
                <box size="1.359960500706626 1.3804438668321675 1.271253578905471" />
            </geometry>
            <material name="Blue">
                <color rgba="0 1.0 1.0 1.0"/>
            </material>
        </visual>
        <collision>
            <origin xyz="0.679980250353313 0 0" rpy="0 0 0"/>
            <geometry>
                <box size="1.359960500706626 1.3804438668321675 1.271253578905471" />
            </geometry>
        </collision>
    </link>
    <link name="Leg7">
        <inertial>
            <origin xyz="0.7343084359861206 0 0" rpy="0 0 0"/>
            <mass value="1" />
            <inertia ixx="100" ixy="0" ixz="0" iyy="100" iyz="0" izz="100" />
        </inertial>
        <visual>
            <origin xyz="0.7343084359861206 0 0" rpy="0 0 0"/>
            <geometry>
                <box size="1.4686168719722412 1.89658249498124 2.4174125426260753" />
            </geometry>
            <material name="Green">
                <color rgba="0 180.0 0.0 1.0"/>
            </material>
        </visual>
        <collision>
            <origin xyz="0.7343084359861206 0 0" rpy="0 0 0"/>
            <geometry>
                <box size="1.4686168719722412 1.89658249498124 2.4174125426260753" />
            </geometry>
        </collision>
    </link>
    <link name="Leg8">
        <inertial>
            <origin xyz="1.0462246547927867 0 0" rpy="0 0 0"/>
            <mass value="1" />
            <inertia ixx="100" ixy="0" ixz="0" iyy="100" iyz="0" izz="100" />
        </inertial>
        <visual>
            <origin xyz="1.0462246547927867 0 0" rpy="0 0 0"/>
            <geometry>
                <box size="2.0924493095855734 1.4789456682154953 2.6842891041883155" />
            </geometry>
            <material name="Blue">
                <color rgba="0 1.0 1.0 1.0"/>
            </material>
        </visual>
        <collision>
            <origin xyz="1.0462246547927867 0 0" rpy="0 0 0"/>
            <geometry>
                <box size="2.0924493095855734 1.4789456682154953 2.6842891041883155" />
            </geometry>
        </collision>
    </link>
    <link name="Leg9">
        <inertial>
            <origin xyz="0 0 0.6405315048723121" rpy="0 0 0"/>
            <mass value="1" />
            <inertia ixx="100" ixy="0" ixz="0" iyy="100" iyz="0" izz="100" />
        </inertial>
        <visual>
            <origin xyz="0 0 0.6405315048723121" rpy="0 0 0"/>
            <geometry>
                <box size="2.978893809370489 1.837934598387957 1.2810630097446243" />
            </geometry>
            <material name="Green">
                <color rgba="0 180.0 0.0 1.0"/>
            </material>
        </visual>
        <collision>
            <origin xyz="0 0 0.6405315048723121" rpy="0 0 0"/>
            <geometry>
                <box size="2.978893809370489 1.837934598387957 1.2810630097446243" />
            </geometry>
        </collision>
    </link>
    <link name="Leg10">
        <inertial>
            <origin xyz="0 0 1.300428590316895" rpy="0 0 0"/>
            <mass value="1" />
            <inertia ixx="100" ixy="0" ixz="0" iyy="100" iyz="0" izz="100" />
        </inertial>
        <visual>
            <origin xyz="0 0 1.300428590316895" rpy="0 0 0"/>
            <geometry>
                <box size="1.1474017292823901 1.6173869783799943 2.60085718063379" />
            </geometry>
            <material name="Blue">
                <color rgba="0 1.0 1.0 1.0"/>
            </material>
        </visual>
        <collision>
            <origin xyz="0 0 1.300428590316895" rpy="0 0 0"/>
            <geometry>
                <box size="1.1474017292823901 1.6173869783799943 2.60085718063379" />
            </geometry>
        </collision>
    </link>
    <link name="Leg11">
        <inertial>
            <origin xyz="1.1321536357192548 0 0" rpy="0 0 0"/>
            <mass value="1" />
            <inertia ixx="100" ixy="0" ixz="0" iyy="100" iyz="0" izz="100" />
        </inertial>
        <visual>
            <origin xyz="1.1321536357192548 0 0" rpy="0 0 0"/>
            <geometry>
                <box size="2.2643072714385095 2.1597999270442583 2.630858970172178" />
            </geometry>
            <material name="Green">
                <color rgba="0 180.0 0.0 1.0"/>
            </material>
        </visual>
        <collision>
            <origin xyz="1.1321536357192548 0 0" rpy="0 0 0"/>
            <geometry>
                <box size="2.2643072714385095 2.1597999270442583 2.630858970172178" />
            </geometry>
        </collision>
    </link>
    <link name="Leg12">
        <inertial>
            <origin xyz="0 0.8438730809591753 0" rpy="0 0 0"/>
            <mass value="1" />
            <inertia ixx="100" ixy="0" ixz="0" iyy="100" iyz="0" izz="100" />
        </inertial>
        <visual>
            <origin xyz="0 0.8438730809591753 0" rpy="0 0 0"/>
            <geometry>
                <box size="1.2605228163464306 1.6877461619183507 1.5842456377746685" />
            </geometry>
            <material name="Green">
                <color rgba="0 180.0 0.0 1.0"/>
            </material>
        </visual>
        <collision>
            <origin xyz="0 0.8438730809591753 0" rpy="0 0 0"/>
            <geometry>
                <box size="1.2605228163464306 1.6877461619183507 1.5842456377746685" />
            </geometry>
        </collision>
    </link>
    <link name="Leg13">
        <inertial>
            <origin xyz="0 0 1.4977379741676222" rpy="0 0 0"/>
            <mass value="1" />
            <inertia ixx="100" ixy="0" ixz="0" iyy="100" iyz="0" izz="100" />
        </inertial>
        <visual>
            <origin xyz="0 0 1.4977379741676222" rpy="0 0 0"/>
            <geometry>
                <box size="1.5569102907436 2.3187342624501555 2.9954759483352444" />
            </geometry>
            <material name="Green">
                <color rgba="0 180.0 0.0 1.0"/>
            </material>
        </visual>
        <collision>
            <origin xyz="0 0 1.4977379741676222" rpy="0 0 0"/>
            <geometry>
                <box size="1.5569102907436 2.3187342624501555 2.9954759483352444" />
            </geometry>
        </collision>
    </link>
    <link name="Leg14">
        <inertial>
            <origin xyz="0 1.3798810516455742 0" rpy="0 0 0"/>
            <mass value="1" />
            <inertia ixx="100" ixy="0" ixz="0" iyy="100" iyz="0" izz="100" />
        </inertial>
        <visual>
            <origin xyz="0 1.3798810516455742 0" rpy="0 0 0"/>
            <geometry>
                <box size="2.1771466087944673 2.7597621032911483 2.139392347511076" />
            </geometry>
            <material name="Green">
                <color rgba="0 180.0 0.0 1.0"/>
            </material>
        </visual>
        <collision>
            <origin xyz="0 1.3798810516455742 0" rpy="0 0 0"/>
            <geometry>
                <box size="2.1771466087944673 2.7597621032911483 2.139392347511076" />
            </geometry>
        </collision>
    </link>
    <link name="Leg15">
        <inertial>
            <origin xyz="0 1.2802563517183518 0" rpy="0 0 0"/>
            <mass value="1" />
            <inertia ixx="100" ixy="0" ixz="0" iyy="100" iyz="0" izz="100" />
        </inertial>
        <visual>
            <origin xyz="0 1.2802563517183518 0" rpy="0 0 0"/>
            <geometry>
                <box size="1.2813607131508131 2.5605127034367037 1.3372327246010802" />
            </geometry>
            <material name="Blue">
                <color rgba="0 1.0 1.0 1.0"/>
            </material>
        </visual>
        <collision>
            <origin xyz="0 1.2802563517183518 0" rpy="0 0 0"/>
            <geometry>
                <box size="1.2813607131508131 2.5605127034367037 1.3372327246010802" />
            </geometry>
        </collision>
    </link>
    <link name="Leg16">
        <inertial>
            <origin xyz="0 0.7316906598351411 0" rpy="0 0 0"/>
            <mass value="1" />
            <inertia ixx="100" ixy="0" ixz="0" iyy="100" iyz="0" izz="100" />
        </inertial>
        <visual>
            <origin xyz="0 0.7316906598351411 0" rpy="0 0 0"/>
            <geometry>
                <box size="1.9835031321658707 1.4633813196702823 1.9214305464907402" />
            </geometry>
            <material name="Blue">
                <color rgba="0 1.0 1.0 1.0"/>
            </material>
        </visual>
        <collision>
            <origin xyz="0 0.7316906598351411 0" rpy="0 0 0"/>
            <geometry>
                <box size="1.9835031321658707 1.4633813196702823 1.9214305464907402" />
            </geometry>
        </collision>
    </link>
    <link name="Leg17">
        <inertial>
            <origin xyz="0 0 1.0724001305140294" rpy="0 0 0"/>
            <mass value="1" />
            <inertia ixx="100" ixy="0" ixz="0" iyy="100" iyz="0" izz="100" />
        </inertial>
        <visual>
            <origin xyz="0 0 1.0724001305140294" rpy="0 0 0"/>
            <geometry>
                <box size="1.2626247969010842 2.1196855881094088 2.1448002610280588" />
            </geometry>
            <material name="Green">
                <color rgba="0 180.0 0.0 1.0"/>
            </material>
        </visual>
        <collision>
            <origin xyz="0 0 1.0724001305140294" rpy="0 0 0"/>
            <geometry>
                <box size="1.2626247969010842 2.1196855881094088 2.1448002610280588" />
            </geometry>
        </collision>
    </link>
    <link name="Leg18">
        <inertial>
            <origin xyz="0 1.297349593737883 0" rpy="0 0 0"/>
            <mass value="1" />
            <inertia ixx="100" ixy="0" ixz="0" iyy="100" iyz="0" izz="100" />
        </inertial>
        <visual>
            <origin xyz="0 1.297349593737883 0" rpy="0 0 0"/>
            <geometry>
                <box size="1.3971430939458012 2.594699187475766 1.3852565515546074" />
            </geometry>
            <material name="Blue">
                <color rgba="0 1.0 1.0 1.0"/>
            </material>
        </visual>
        <collision>
            <origin xyz="0 1.297349593737883 0" rpy="0 0 0"/>
            <geometry>
                <box size="1.3971430939458012 2.594699187475766 1.3852565515546074" />
            </geometry>
        </collision>
    </link>
    <link name="Leg19">
        <inertial>
            <origin xyz="0 0 1.2761847841673175" rpy="0 0 0"/>
            <mass value="1" />
            <inertia ixx="100" ixy="0" ixz="0" iyy="100" iyz="0" izz="100" />
        </inertial>
        <visual>
            <origin xyz="0 0 1.2761847841673175" rpy="0 0 0"/>
            <geometry>
                <box size="2.7042531161522625 1.5076062176794078 2.552369568334635" />
            </geometry>
            <material name="Blue">
                <color rgba="0 1.0 1.0 1.0"/>
            </material>
        </visual>
        <collision>
            <origin xyz="0 0 1.2761847841673175" rpy="0 0 0"/>
            <geometry>
                <box size="2.7042531161522625 1.5076062176794078 2.552369568334635" />
            </geometry>
        </collision>
    </link>
    <link name="Leg20">
        <inertial>
            <origin xyz="0 0 1.4205388622335091" rpy="0 0 0"/>
            <mass value="1" />
            <inertia ixx="100" ixy="0" ixz="0" iyy="100" iyz="0" izz="100" />
        </inertial>
        <visual>
            <origin xyz="0 0 1.4205388622335091" rpy="0 0 0"/>
            <geometry>
                <box size="2.114315674990386 2.2479870533285933 2.8410777244670182" />
            </geometry>
            <material name="Green">
                <color rgba="0 180.0 0.0 1.0"/>
            </material>
        </visual>
        <collision>
            <origin xyz="0 0 1.4205388622335091" rpy="0 0 0"/>
            <geometry>
                <box size="2.114315674990386 2.2479870533285933 2.8410777244670182" />
            </geometry>
        </collision>
    </link>
    <link name="Leg21">
        <inertial>
            <origin xyz="0 1.4462159445976384 0" rpy="0 0 0"/>
            <mass value="1" />
            <inertia ixx="100" ixy="0" ixz="0" iyy="100" iyz="0" izz="100" />
        </inertial>
        <visual>
            <origin xyz="0 1.4462159445976384 0" rpy="0 0 0"/>
            <geometry>
                <box size="2.505707636867779 2.8924318891952767 1.281371372918505" />
            </geometry>
            <material name="Blue">
                <color rgba="0 1.0 1.0 1.0"/>
            </material>
        </visual>
        <collision>
            <origin xyz="0 1.4462159445976384 0" rpy="0 0 0"/>
            <geometry>
                <box size="2.505707636867779 2.8924318891952767 1.281371372918505" />
            </geometry>
        </collision>
    </link>
    <link name="Leg22">
        <inertial>
            <origin xyz="0 0 0.7652482343552083" rpy="0 0 0"/>
            <mass value="1" />
            <inertia ixx="100" ixy="0" ixz="0" iyy="100" iyz="0" izz="100" />
        </inertial>
        <visual>
            <origin xyz="0 0 0.7652482343552083" rpy="0 0 0"/>
            <geometry>
                <box size="1.6976911799961145 2.526914986742999 1.5304964687104166" />
            </geometry>
            <material name="Blue">
                <color rgba="0 1.0 1.0 1.0"/>
            </material>
        </visual>
        <collision>
            <origin xyz="0 0 0.7652482343552083" rpy="0 0 0"/>
            <geometry>
                <box size="1.6976911799961145 2.526914986742999 1.5304964687104166" />
            </geometry>
        </collision>
    </link>
    <link name="Leg23">
        <inertial>
            <origin xyz="0 0.9950365237453758 0" rpy="0 0 0"/>
            <mass value="1" />
            <inertia ixx="100" ixy="0" ixz="0" iyy="100" iyz="0" izz="100" />
        </inertial>
        <visual>
            <origin xyz="0 0.9950365237453758 0" rpy="0 0 0"/>
            <geometry>
                <box size="1.9523181090829478 1.9900730474907515 1.5928493153854462" />
            </geometry>
            <material name="Blue">
                <color rgba="0 1.0 1.0 1.0"/>
            </material>
        </visual>
        <collision>
            <origin xyz="0 0.9950365237453758 0" rpy="0 0 0"/>
            <geometry>
                <box size="1.9523181090829478 1.9900730474907515 1.5928493153854462" />
            </geometry>
        </collision>
    </link>
    <link name="Leg24">
        <inertial>
            <origin xyz="0 0 0.6988148681748687" rpy="0 0 0"/>
            <mass value="1" />
            <inertia ixx="100" ixy="0" ixz="0" iyy="100" iyz="0" izz="100" />
        </inertial>
        <visual>
            <origin xyz="0 0 0.6988148681748687" rpy="0 0 0"/>
            <geometry>
                <box size="1.0230123287625859 1.3046147508336705 1.3976297363497374" />
            </geometry>
            <material name="Blue">
                <color rgba="0 1.0 1.0 1.0"/>
            </material>
        </visual>
        <collision>
            <origin xyz="0 0 0.6988148681748687" rpy="0 0 0"/>
            <geometry>
                <box size="1.0230123287625859 1.3046147508336705 1.3976297363497374" />
            </geometry>
        </collision>
    </link>
    <link name="Leg25">
        <inertial>
            <origin xyz="1.2617181090844105 0 0" rpy="0 0 0"/>
            <mass value="1" />
            <inertia ixx="100" ixy="0" ixz="0" iyy="100" iyz="0" izz="100" />
        </inertial>
        <visual>
            <origin xyz="1.2617181090844105 0 0" rpy="0 0 0"/>
            <geometry>
                <box size="2.523436218168821 2.055666051955888 2.0713035012693086" />
            </geometry>
            <material name="Green">
                <color rgba="0 180.0 0.0 1.0"/>
            </material>
        </visual>
        <collision>
            <origin xyz="1.2617181090844105 0 0" rpy="0 0 0"/>
            <geometry>
                <box size="2.523436218168821 2.055666051955888 2.0713035012693086" />
            </geometry>
        </collision>
    </link>
    <link name="Leg26">
        <inertial>
            <origin xyz="0 0.9286099947116561 0" rpy="0 0 0"/>
            <mass value="1" />
            <inertia ixx="100" ixy="0" ixz="0" iyy="100" iyz="0" izz="100" />
        </inertial>
        <visual>
            <origin xyz="0 0.9286099947116561 0" rpy="0 0 0"/>
            <geometry>
                <box size="1.3628357714044637 1.8572199894233121 2.1480567706077736" />
            </geometry>
            <material name="Blue">
                <color rgba="0 1.0 1.0 1.0"/>
            </material>
        </visual>
        <collision>
            <origin xyz="0 0.9286099947116561 0" rpy="0 0 0"/>
            <geometry>
                <box size="1.3628357714044637 1.8572199894233121 2.1480567706077736" />
            </geometry>
        </collision>
    </link>
    <joint name="Torso_Leg1" type="revolute">
       <parent link="Torso"/>
       <child  link="Leg1"/>
       <origin rpy="0 0 0" xyz="0.9045274215895422 0 0.9662766994794822" />
     <axis xyz="1 0 0"/>
       <limit effort="0.0" lower="-3.14159" upper="3.14159" velocity="0.0"/>
    </joint>
    <joint name="Torso_Leg2" type="revolute">
       <parent link="Torso"/>
       <child  link="Leg2"/>
       <origin rpy="0 0 0" xyz="1.4825414670555994 0 0.5501599091148199" />
     <axis xyz="1 0 0"/>
       <limit effort="0.0" lower="-3.14159" upper="3.14159" velocity="0.0"/>
    </joint>
    <joint name="Leg2_Leg3" type="revolute">
       <parent link="Leg2"/>
       <child  link="Leg3"/>
       <origin rpy="0 0 0" xyz="0 0 2.2779297127092204" />
     <axis xyz="1 0 0"/>
       <limit effort="0.0" lower="-3.14159" upper="3.14159" velocity="0.0"/>
    </joint>
    <joint name="Leg2_Leg4" type="revolute">
       <parent link="Leg2"/>
       <child  link="Leg4"/>
       <origin rpy="0 0 0" xyz="1.100076406666657 0 2.2779297127092204" />
     <axis xyz="1 0 0"/>
       <limit effort="0.0" lower="-3.14159" upper="3.14159" velocity="0.0"/>
    </joint>
    <joint name="Leg4_Leg5" type="revolute">
       <parent link="Leg4"/>
       <child  link="Leg5"/>
       <origin rpy="0 0 0" xyz="1.2808853782008724 0 0" />
     <axis xyz="1 0 0"/>
       <limit effort="0.0" lower="-3.14159" upper="3.14159" velocity="0.0"/>
    </joint>
    <joint name="Leg5_Leg6" type="revolute">
       <parent link="Leg5"/>
       <child  link="Leg6"/>
       <origin rpy="0 0 0" xyz="1.359960500706626 0 0" />
     <axis xyz="1 0 0"/>
       <limit effort="0.0" lower="-3.14159" upper="3.14159" velocity="0.0"/>
    </joint>
    <joint name="Leg1_Leg7" type="revolute">
       <parent link="Leg1"/>
       <child  link="Leg7"/>
       <origin rpy="0 0 0" xyz="0.8013007821436595 0 0.9595394367499899" />
     <axis xyz="1 0 0"/>
       <limit effort="0.0" lower="-3.14159" upper="3.14159" velocity="0.0"/>
    </joint>
    <joint name="Leg6_Leg8" type="revolute">
       <parent link="Leg6"/>
       <child  link="Leg8"/>
       <origin rpy="0 0 0" xyz="1.4686168719722412 0 0" />
     <axis xyz="1 0 0"/>
       <limit effort="0.0" lower="-3.14159" upper="3.14159" velocity="0.0"/>
    </joint>
    <joint name="Leg8_Leg9" type="revolute">
       <parent link="Leg8"/>
       <child  link="Leg9"/>
       <origin rpy="0 0 0" xyz="0 0 1.2810630097446243" />
     <axis xyz="1 0 0"/>
       <limit effort="0.0" lower="-3.14159" upper="3.14159" velocity="0.0"/>
    </joint>
    <joint name="Leg5_Leg10" type="revolute">
       <parent link="Leg5"/>
       <child  link="Leg10"/>
       <origin rpy="0 0 0" xyz="1.359960500706626 0 0.6356267894527355" />
     <axis xyz="1 0 0"/>
       <limit effort="0.0" lower="-3.14159" upper="3.14159" velocity="0.0"/>
    </joint>
    <joint name="Leg9_Leg11" type="revolute">
       <parent link="Leg9"/>
       <child  link="Leg11"/>
       <origin rpy="0 0 0" xyz="0.5737008646411951 0 1.300428590316895" />
     <axis xyz="1 0 0"/>
       <limit effort="0.0" lower="-3.14159" upper="3.14159" velocity="0.0"/>
    </joint>
    <joint name="Leg9_Leg12" type="revolute">
       <parent link="Leg9"/>
       <child  link="Leg12"/>
       <origin rpy="0 0 0" xyz="0.5737008646411951 0.8086934891899972 1.300428590316895" />
     <axis xyz="1 0 0"/>
       <limit effort="0.0" lower="-3.14159" upper="3.14159" velocity="0.0"/>
    </joint>
    <joint name="Leg11_Leg13" type="revolute">
       <parent link="Leg11"/>
       <child  link="Leg13"/>
       <origin rpy="0 0 0" xyz="0 0.8438730809591753 0.7921228188873343" />
     <axis xyz="1 0 0"/>
       <limit effort="0.0" lower="-3.14159" upper="3.14159" velocity="0.0"/>
    </joint>
    <joint name="Leg12_Leg14" type="revolute">
       <parent link="Leg12"/>
       <child  link="Leg14"/>
       <origin rpy="0 0 0" xyz="0 1.1593671312250777 1.4977379741676222" />
     <axis xyz="1 0 0"/>
       <limit effort="0.0" lower="-3.14159" upper="3.14159" velocity="0.0"/>
    </joint>
    <joint name="Torso_Leg15" type="revolute">
       <parent link="Torso"/>
       <child  link="Leg15"/>
       <origin rpy="0 0 0" xyz="1.4825414670555994 1.4770662966011439 0.5501599091148199" />
     <axis xyz="1 0 0"/>
       <limit effort="0.0" lower="-3.14159" upper="3.14159" velocity="0.0"/>
    </joint>
    <joint name="Leg14_Leg16" type="revolute">
       <parent link="Leg14"/>
       <child  link="Leg16"/>
       <origin rpy="0 0 0" xyz="0 2.5605127034367037 0" />
     <axis xyz="1 0 0"/>
       <limit effort="0.0" lower="-3.14159" upper="3.14159" velocity="0.0"/>
    </joint>
    <joint name="Leg15_Leg17" type="revolute">
       <parent link="Leg15"/>
       <child  link="Leg17"/>
       <origin rpy="0 0 0" xyz="0 0.7316906598351411 0.9607152732453701" />
     <axis xyz="1 0 0"/>
       <limit effort="0.0" lower="-3.14159" upper="3.14159" velocity="0.0"/>
    </joint>
    <joint name="Leg10_Leg18" type="revolute">
       <parent link="Leg10"/>
       <child  link="Leg18"/>
       <origin rpy="0 0 0" xyz="1.1321536357192548 1.0798999635221291 0" />
     <axis xyz="1 0 0"/>
       <limit effort="0.0" lower="-3.14159" upper="3.14159" velocity="0.0"/>
    </joint>
    <joint name="Leg1_Leg19" type="revolute">
       <parent link="Leg1"/>
       <child  link="Leg19"/>
       <origin rpy="0 0 0" xyz="0.8013007821436595 0 1.9190788734999797" />
     <axis xyz="1 0 0"/>
       <limit effort="0.0" lower="-3.14159" upper="3.14159" velocity="0.0"/>
    </joint>
    <joint name="Leg16_Leg20" type="revolute">
       <parent link="Leg16"/>
       <child  link="Leg20"/>
       <origin rpy="0 0 0" xyz="0 0 2.1448002610280588" />
     <axis xyz="1 0 0"/>
       <limit effort="0.0" lower="-3.14159" upper="3.14159" velocity="0.0"/>
    </joint>
    <joint name="Leg17_Leg21" type="revolute">
       <parent link="Leg17"/>
       <child  link="Leg21"/>
       <origin rpy="0 0 0" xyz="0 2.594699187475766 0" />
     <axis xyz="1 0 0"/>
       <limit effort="0.0" lower="-3.14159" upper="3.14159" velocity="0.0"/>
    </joint>
    <joint name="Leg10_Leg22" type="revolute">
       <parent link="Leg10"/>
       <child  link="Leg22"/>
       <origin rpy="0 0 0" xyz="1.1321536357192548 1.0798999635221291 1.315429485086089" />
     <axis xyz="1 0 0"/>
       <limit effort="0.0" lower="-3.14159" upper="3.14159" velocity="0.0"/>
    </joint>
    <joint name="Leg13_Leg23" type="revolute">
       <parent link="Leg13"/>
       <child  link="Leg23"/>
       <origin rpy="0 0 0" xyz="0 2.7597621032911483 0" />
     <axis xyz="1 0 0"/>
       <limit effort="0.0" lower="-3.14159" upper="3.14159" velocity="0.0"/>
    </joint>
    <joint name="Leg21_Leg24" type="revolute">
       <parent link="Leg21"/>
       <child  link="Leg24"/>
       <origin rpy="0 0 0" xyz="0 0 1.5304964687104166" />
     <axis xyz="1 0 0"/>
       <limit effort="0.0" lower="-3.14159" upper="3.14159" velocity="0.0"/>
    </joint>
    <joint name="Leg21_Leg25" type="revolute">
       <parent link="Leg21"/>
       <child  link="Leg25"/>
       <origin rpy="0 0 0" xyz="0.8488455899980573 0 1.5304964687104166" />
     <axis xyz="1 0 0"/>
       <limit effort="0.0" lower="-3.14159" upper="3.14159" velocity="0.0"/>
    </joint>
    <joint name="Leg2_Leg26" type="revolute">
       <parent link="Leg2"/>
       <child  link="Leg26"/>
       <origin rpy="0 0 0" xyz="1.100076406666657 0.9011819507127118 2.2779297127092204" />
     <axis xyz="1 0 0"/>
       <limit effort="0.0" lower="-3.14159" upper="3.14159" velocity="0.0"/>
    </joint>
</robot>