<robot name = "robot">
    <link name="Torso">
        <inertial>
            <origin xyz="0 0 0.723068386350265" rpy="0 0 0"/>
            <mass value="1" />
            <inertia ixx="100" ixy="0" ixz="0" iyy="100" iyz="0" izz="100" />
        </inertial>
        <visual>
            <origin xyz="0 0 0.723068386350265" rpy="0 0 0"/>
            <geometry>
                <box size="1.8267591911742922 2.0445549340896325 1.44613677270053" />
            </geometry>
            <material name="Green">
                <color rgba="0 180.0 0.0 1.0"/>
            </material>
        </visual>
        <collision>
            <origin xyz="0 0 0.723068386350265" rpy="0 0 0"/>
            <geometry>
                <box size="1.8267591911742922 2.0445549340896325 1.44613677270053" />
            </geometry>
        </collision>
    </link>
    <link name="Leg1">
        <inertial>
            <origin xyz="1.3516035214066955 0 0" rpy="0 0 0"/>
            <mass value="1" />
            <inertia ixx="100" ixy="0" ixz="0" iyy="100" iyz="0" izz="100" />
        </inertial>
        <visual>
            <origin xyz="1.3516035214066955 0 0" rpy="0 0 0"/>
            <geometry>
                <box size="2.703207042813391 1.2296112403697512 2.4200518843412677" />
            </geometry>
            <material name="Blue">
                <color rgba="0 1.0 1.0 1.0"/>
            </material>
        </visual>
        <collision>
            <origin xyz="1.3516035214066955 0 0" rpy="0 0 0"/>
            <geometry>
                <box size="2.703207042813391 1.2296112403697512 2.4200518843412677" />
            </geometry>
        </collision>
    </link>
    <link name="Leg2">
        <inertial>
            <origin xyz="0 0.9084818861355404 0" rpy="0 0 0"/>
            <mass value="1" />
            <inertia ixx="100" ixy="0" ixz="0" iyy="100" iyz="0" izz="100" />
        </inertial>
        <visual>
            <origin xyz="0 0.9084818861355404 0" rpy="0 0 0"/>
            <geometry>
                <box size="2.1152079297210946 1.8169637722710807 2.0647995551810596" />
            </geometry>
            <material name="Green">
                <color rgba="0 180.0 0.0 1.0"/>
            </material>
        </visual>
        <collision>
            <origin xyz="0 0.9084818861355404 0" rpy="0 0 0"/>
            <geometry>
                <box size="2.1152079297210946 1.8169637722710807 2.0647995551810596" />
            </geometry>
        </collision>
    </link>
    <link name="Leg3">
        <inertial>
            <origin xyz="0 0 1.0071335125511216" rpy="0 0 0"/>
            <mass value="1" />
            <inertia ixx="100" ixy="0" ixz="0" iyy="100" iyz="0" izz="100" />
        </inertial>
        <visual>
            <origin xyz="0 0 1.0071335125511216" rpy="0 0 0"/>
            <geometry>
                <box size="1.2470326675925114 2.1539390663944475 2.014267025102243" />
            </geometry>
            <material name="Blue">
                <color rgba="0 1.0 1.0 1.0"/>
            </material>
        </visual>
        <collision>
            <origin xyz="0 0 1.0071335125511216" rpy="0 0 0"/>
            <geometry>
                <box size="1.2470326675925114 2.1539390663944475 2.014267025102243" />
            </geometry>
        </collision>
    </link>
    <link name="Leg4">
        <inertial>
            <origin xyz="0 0.754406239048187 0" rpy="0 0 0"/>
            <mass value="1" />
            <inertia ixx="100" ixy="0" ixz="0" iyy="100" iyz="0" izz="100" />
        </inertial>
        <visual>
            <origin xyz="0 0.754406239048187 0" rpy="0 0 0"/>
            <geometry>
                <box size="2.3301919263457544 1.508812478096374 1.8607585108290399" />
            </geometry>
            <material name="Green">
                <color rgba="0 180.0 0.0 1.0"/>
            </material>
        </visual>
        <collision>
            <origin xyz="0 0.754406239048187 0" rpy="0 0 0"/>
            <geometry>
                <box size="2.3301919263457544 1.508812478096374 1.8607585108290399" />
            </geometry>
        </collision>
    </link>
    <link name="Leg5">
        <inertial>
            <origin xyz="0.5105952710942263 0 0" rpy="0 0 0"/>
            <mass value="1" />
            <inertia ixx="100" ixy="0" ixz="0" iyy="100" iyz="0" izz="100" />
        </inertial>
        <visual>
            <origin xyz="0.5105952710942263 0 0" rpy="0 0 0"/>
            <geometry>
                <box size="1.0211905421884526 2.1566535678789838 1.594405340310243" />
            </geometry>
            <material name="Blue">
                <color rgba="0 1.0 1.0 1.0"/>
            </material>
        </visual>
        <collision>
            <origin xyz="0.5105952710942263 0 0" rpy="0 0 0"/>
            <geometry>
                <box size="1.0211905421884526 2.1566535678789838 1.594405340310243" />
            </geometry>
        </collision>
    </link>
    <link name="Leg6">
        <inertial>
            <origin xyz="0 0 0.96057047605255" rpy="0 0 0"/>
            <mass value="1" />
            <inertia ixx="100" ixy="0" ixz="0" iyy="100" iyz="0" izz="100" />
        </inertial>
        <visual>
            <origin xyz="0 0 0.96057047605255" rpy="0 0 0"/>
            <geometry>
                <box size="1.4622215721710623 2.78836854693997 1.9211409521051" />
            </geometry>
            <material name="Blue">
                <color rgba="0 1.0 1.0 1.0"/>
            </material>
        </visual>
        <collision>
            <origin xyz="0 0 0.96057047605255" rpy="0 0 0"/>
            <geometry>
                <box size="1.4622215721710623 2.78836854693997 1.9211409521051" />
            </geometry>
        </collision>
    </link>
    <link name="Leg7">
        <inertial>
            <origin xyz="0 0 1.0270069423756536" rpy="0 0 0"/>
            <mass value="1" />
            <inertia ixx="100" ixy="0" ixz="0" iyy="100" iyz="0" izz="100" />
        </inertial>
        <visual>
            <origin xyz="0 0 1.0270069423756536" rpy="0 0 0"/>
            <geometry>
                <box size="2.843413082660964 2.474628859140717 2.054013884751307" />
            </geometry>
            <material name="Blue">
                <color rgba="0 1.0 1.0 1.0"/>
            </material>
        </visual>
        <collision>
            <origin xyz="0 0 1.0270069423756536" rpy="0 0 0"/>
            <geometry>
                <box size="2.843413082660964 2.474628859140717 2.054013884751307" />
            </geometry>
        </collision>
    </link>
    <link name="Leg8">
        <inertial>
            <origin xyz="0 0 1.2629644330052998" rpy="0 0 0"/>
            <mass value="1" />
            <inertia ixx="100" ixy="0" ixz="0" iyy="100" iyz="0" izz="100" />
        </inertial>
        <visual>
            <origin xyz="0 0 1.2629644330052998" rpy="0 0 0"/>
            <geometry>
                <box size="2.7038029787232665 2.614761416452371 2.5259288660105996" />
            </geometry>
            <material name="Blue">
                <color rgba="0 1.0 1.0 1.0"/>
            </material>
        </visual>
        <collision>
            <origin xyz="0 0 1.2629644330052998" rpy="0 0 0"/>
            <geometry>
                <box size="2.7038029787232665 2.614761416452371 2.5259288660105996" />
            </geometry>
        </collision>
    </link>
    <link name="Leg9">
        <inertial>
            <origin xyz="0 0 0.8644724941709365" rpy="0 0 0"/>
            <mass value="1" />
            <inertia ixx="100" ixy="0" ixz="0" iyy="100" iyz="0" izz="100" />
        </inertial>
        <visual>
            <origin xyz="0 0 0.8644724941709365" rpy="0 0 0"/>
            <geometry>
                <box size="1.9102486154515559 1.1205931006845415 1.728944988341873" />
            </geometry>
            <material name="Green">
                <color rgba="0 180.0 0.0 1.0"/>
            </material>
        </visual>
        <collision>
            <origin xyz="0 0 0.8644724941709365" rpy="0 0 0"/>
            <geometry>
                <box size="1.9102486154515559 1.1205931006845415 1.728944988341873" />
            </geometry>
        </collision>
    </link>
    <link name="Leg10">
        <inertial>
            <origin xyz="1.0708873607218194 0 0" rpy="0 0 0"/>
            <mass value="1" />
            <inertia ixx="100" ixy="0" ixz="0" iyy="100" iyz="0" izz="100" />
        </inertial>
        <visual>
            <origin xyz="1.0708873607218194 0 0" rpy="0 0 0"/>
            <geometry>
                <box size="2.141774721443639 1.5236897963883855 1.8268445055720857" />
            </geometry>
            <material name="Green">
                <color rgba="0 180.0 0.0 1.0"/>
            </material>
        </visual>
        <collision>
            <origin xyz="1.0708873607218194 0 0" rpy="0 0 0"/>
            <geometry>
                <box size="2.141774721443639 1.5236897963883855 1.8268445055720857" />
            </geometry>
        </collision>
    </link>
    <link name="Leg11">
        <inertial>
            <origin xyz="0 1.450752004950954 0" rpy="0 0 0"/>
            <mass value="1" />
            <inertia ixx="100" ixy="0" ixz="0" iyy="100" iyz="0" izz="100" />
        </inertial>
        <visual>
            <origin xyz="0 1.450752004950954 0" rpy="0 0 0"/>
            <geometry>
                <box size="2.7411339822476837 2.901504009901908 2.9112496407007042" />
            </geometry>
            <material name="Green">
                <color rgba="0 180.0 0.0 1.0"/>
            </material>
        </visual>
        <collision>
            <origin xyz="0 1.450752004950954 0" rpy="0 0 0"/>
            <geometry>
                <box size="2.7411339822476837 2.901504009901908 2.9112496407007042" />
            </geometry>
        </collision>
    </link>
    <link name="Leg12">
        <inertial>
            <origin xyz="0 0.8782297197503174 0" rpy="0 0 0"/>
            <mass value="1" />
            <inertia ixx="100" ixy="0" ixz="0" iyy="100" iyz="0" izz="100" />
        </inertial>
        <visual>
            <origin xyz="0 0.8782297197503174 0" rpy="0 0 0"/>
            <geometry>
                <box size="1.765472845309046 1.7564594395006348 2.937923762365241" />
            </geometry>
            <material name="Blue">
                <color rgba="0 1.0 1.0 1.0"/>
            </material>
        </visual>
        <collision>
            <origin xyz="0 0.8782297197503174 0" rpy="0 0 0"/>
            <geometry>
                <box size="1.765472845309046 1.7564594395006348 2.937923762365241" />
            </geometry>
        </collision>
    </link>
    <link name="Leg13">
        <inertial>
            <origin xyz="0 1.065958103387178 0" rpy="0 0 0"/>
            <mass value="1" />
            <inertia ixx="100" ixy="0" ixz="0" iyy="100" iyz="0" izz="100" />
        </inertial>
        <visual>
            <origin xyz="0 1.065958103387178 0" rpy="0 0 0"/>
            <geometry>
                <box size="2.205672369904855 2.131916206774356 2.438840739525696" />
            </geometry>
            <material name="Blue">
                <color rgba="0 1.0 1.0 1.0"/>
            </material>
        </visual>
        <collision>
            <origin xyz="0 1.065958103387178 0" rpy="0 0 0"/>
            <geometry>
                <box size="2.205672369904855 2.131916206774356 2.438840739525696" />
            </geometry>
        </collision>
    </link>
    <link name="Leg14">
        <inertial>
            <origin xyz="0 0 0.8362798637306407" rpy="0 0 0"/>
            <mass value="1" />
            <inertia ixx="100" ixy="0" ixz="0" iyy="100" iyz="0" izz="100" />
        </inertial>
        <visual>
            <origin xyz="0 0 0.8362798637306407" rpy="0 0 0"/>
            <geometry>
                <box size="2.1510690614410475 1.481622142074319 1.6725597274612813" />
            </geometry>
            <material name="Blue">
                <color rgba="0 1.0 1.0 1.0"/>
            </material>
        </visual>
        <collision>
            <origin xyz="0 0 0.8362798637306407" rpy="0 0 0"/>
            <geometry>
                <box size="2.1510690614410475 1.481622142074319 1.6725597274612813" />
            </geometry>
        </collision>
    </link>
    <link name="Leg15">
        <inertial>
            <origin xyz="0 0 0.6230740400229932" rpy="0 0 0"/>
            <mass value="1" />
            <inertia ixx="100" ixy="0" ixz="0" iyy="100" iyz="0" izz="100" />
        </inertial>
        <visual>
            <origin xyz="0 0 0.6230740400229932" rpy="0 0 0"/>
            <geometry>
                <box size="1.5463414466326246 1.5325368695379182 1.2461480800459863" />
            </geometry>
            <material name="Green">
                <color rgba="0 180.0 0.0 1.0"/>
            </material>
        </visual>
        <collision>
            <origin xyz="0 0 0.6230740400229932" rpy="0 0 0"/>
            <geometry>
                <box size="1.5463414466326246 1.5325368695379182 1.2461480800459863" />
            </geometry>
        </collision>
    </link>
    <link name="Leg16">
        <inertial>
            <origin xyz="0.5234460118483121 0 0" rpy="0 0 0"/>
            <mass value="1" />
            <inertia ixx="100" ixy="0" ixz="0" iyy="100" iyz="0" izz="100" />
        </inertial>
        <visual>
            <origin xyz="0.5234460118483121 0 0" rpy="0 0 0"/>
            <geometry>
                <box size="1.0468920236966242 2.3943945803626887 1.678011514434938" />
            </geometry>
            <material name="Green">
                <color rgba="0 180.0 0.0 1.0"/>
            </material>
        </visual>
        <collision>
            <origin xyz="0.5234460118483121 0 0" rpy="0 0 0"/>
            <geometry>
                <box size="1.0468920236966242 2.3943945803626887 1.678011514434938" />
            </geometry>
        </collision>
    </link>
    <link name="Leg17">
        <inertial>
            <origin xyz="1.219307299366525 0 0" rpy="0 0 0"/>
            <mass value="1" />
            <inertia ixx="100" ixy="0" ixz="0" iyy="100" iyz="0" izz="100" />
        </inertial>
        <visual>
            <origin xyz="1.219307299366525 0 0" rpy="0 0 0"/>
            <geometry>
                <box size="2.43861459873305 1.5948502243512868 1.2019821736299974" />
            </geometry>
            <material name="Green">
                <color rgba="0 180.0 0.0 1.0"/>
            </material>
        </visual>
        <collision>
            <origin xyz="1.219307299366525 0 0" rpy="0 0 0"/>
            <geometry>
                <box size="2.43861459873305 1.5948502243512868 1.2019821736299974" />
            </geometry>
        </collision>
    </link>
    <link name="Leg18">
        <inertial>
            <origin xyz="0 0 1.068843793029877" rpy="0 0 0"/>
            <mass value="1" />
            <inertia ixx="100" ixy="0" ixz="0" iyy="100" iyz="0" izz="100" />
        </inertial>
        <visual>
            <origin xyz="0 0 1.068843793029877" rpy="0 0 0"/>
            <geometry>
                <box size="1.902154941611586 1.684882659403803 2.137687586059754" />
            </geometry>
            <material name="Green">
                <color rgba="0 180.0 0.0 1.0"/>
            </material>
        </visual>
        <collision>
            <origin xyz="0 0 1.068843793029877" rpy="0 0 0"/>
            <geometry>
                <box size="1.902154941611586 1.684882659403803 2.137687586059754" />
            </geometry>
        </collision>
    </link>
    <link name="Leg19">
        <inertial>
            <origin xyz="0 1.1729253685185843 0" rpy="0 0 0"/>
            <mass value="1" />
            <inertia ixx="100" ixy="0" ixz="0" iyy="100" iyz="0" izz="100" />
        </inertial>
        <visual>
            <origin xyz="0 1.1729253685185843 0" rpy="0 0 0"/>
            <geometry>
                <box size="2.1081999172014454 2.3458507370371686 2.1466123114653346" />
            </geometry>
            <material name="Green">
                <color rgba="0 180.0 0.0 1.0"/>
            </material>
        </visual>
        <collision>
            <origin xyz="0 1.1729253685185843 0" rpy="0 0 0"/>
            <geometry>
                <box size="2.1081999172014454 2.3458507370371686 2.1466123114653346" />
            </geometry>
        </collision>
    </link>
    <link name="Leg20">
        <inertial>
            <origin xyz="0 0.9625285378900772 0" rpy="0 0 0"/>
            <mass value="1" />
            <inertia ixx="100" ixy="0" ixz="0" iyy="100" iyz="0" izz="100" />
        </inertial>
        <visual>
            <origin xyz="0 0.9625285378900772 0" rpy="0 0 0"/>
            <geometry>
                <box size="1.5091708114622675 1.9250570757801544 2.832534464690273" />
            </geometry>
            <material name="Blue">
                <color rgba="0 1.0 1.0 1.0"/>
            </material>
        </visual>
        <collision>
            <origin xyz="0 0.9625285378900772 0" rpy="0 0 0"/>
            <geometry>
                <box size="1.5091708114622675 1.9250570757801544 2.832534464690273" />
            </geometry>
        </collision>
    </link>
    <link name="Leg21">
        <inertial>
            <origin xyz="0 1.3994006807895225 0" rpy="0 0 0"/>
            <mass value="1" />
            <inertia ixx="100" ixy="0" ixz="0" iyy="100" iyz="0" izz="100" />
        </inertial>
        <visual>
            <origin xyz="0 1.3994006807895225 0" rpy="0 0 0"/>
            <geometry>
                <box size="2.754379307845639 2.798801361579045 2.1675889775172683" />
            </geometry>
            <material name="Blue">
                <color rgba="0 1.0 1.0 1.0"/>
            </material>
        </visual>
        <collision>
            <origin xyz="0 1.3994006807895225 0" rpy="0 0 0"/>
            <geometry>
                <box size="2.754379307845639 2.798801361579045 2.1675889775172683" />
            </geometry>
        </collision>
    </link>
    <link name="Leg22">
        <inertial>
            <origin xyz="0 0.5622188304171465 0" rpy="0 0 0"/>
            <mass value="1" />
            <inertia ixx="100" ixy="0" ixz="0" iyy="100" iyz="0" izz="100" />
        </inertial>
        <visual>
            <origin xyz="0 0.5622188304171465 0" rpy="0 0 0"/>
            <geometry>
                <box size="1.9101949030016838 1.124437660834293 1.727548166660885" />
            </geometry>
            <material name="Blue">
                <color rgba="0 1.0 1.0 1.0"/>
            </material>
        </visual>
        <collision>
            <origin xyz="0 0.5622188304171465 0" rpy="0 0 0"/>
            <geometry>
                <box size="1.9101949030016838 1.124437660834293 1.727548166660885" />
            </geometry>
        </collision>
    </link>
    <link name="Leg23">
        <inertial>
            <origin xyz="0 0 1.219043768381189" rpy="0 0 0"/>
            <mass value="1" />
            <inertia ixx="100" ixy="0" ixz="0" iyy="100" iyz="0" izz="100" />
        </inertial>
        <visual>
            <origin xyz="0 0 1.219043768381189" rpy="0 0 0"/>
            <geometry>
                <box size="1.981853715506146 1.671586922884923 2.438087536762378" />
            </geometry>
            <material name="Green">
                <color rgba="0 180.0 0.0 1.0"/>
            </material>
        </visual>
        <collision>
            <origin xyz="0 0 1.219043768381189" rpy="0 0 0"/>
            <geometry>
                <box size="1.981853715506146 1.671586922884923 2.438087536762378" />
            </geometry>
        </collision>
    </link>
    <link name="Leg24">
        <inertial>
            <origin xyz="0 1.1673583006818662 0" rpy="0 0 0"/>
            <mass value="1" />
            <inertia ixx="100" ixy="0" ixz="0" iyy="100" iyz="0" izz="100" />
        </inertial>
        <visual>
            <origin xyz="0 1.1673583006818662 0" rpy="0 0 0"/>
            <geometry>
                <box size="1.5955616076455836 2.3347166013637324 2.8584733292860447" />
            </geometry>
            <material name="Green">
                <color rgba="0 180.0 0.0 1.0"/>
            </material>
        </visual>
        <collision>
            <origin xyz="0 1.1673583006818662 0" rpy="0 0 0"/>
            <geometry>
                <box size="1.5955616076455836 2.3347166013637324 2.8584733292860447" />
            </geometry>
        </collision>
    </link>
    <link name="Leg25">
        <inertial>
            <origin xyz="0.5307258411372844 0 0" rpy="0 0 0"/>
            <mass value="1" />
            <inertia ixx="100" ixy="0" ixz="0" iyy="100" iyz="0" izz="100" />
        </inertial>
        <visual>
            <origin xyz="0.5307258411372844 0 0" rpy="0 0 0"/>
            <geometry>
                <box size="1.0614516822745688 2.1737846185313705 2.9934645060539076" />
            </geometry>
            <material name="Green">
                <color rgba="0 180.0 0.0 1.0"/>
            </material>
        </visual>
        <collision>
            <origin xyz="0.5307258411372844 0 0" rpy="0 0 0"/>
            <geometry>
                <box size="1.0614516822745688 2.1737846185313705 2.9934645060539076" />
            </geometry>
        </collision>
    </link>
    <link name="Leg26">
        <inertial>
            <origin xyz="0 0 1.3814128435124235" rpy="0 0 0"/>
            <mass value="1" />
            <inertia ixx="100" ixy="0" ixz="0" iyy="100" iyz="0" izz="100" />
        </inertial>
        <visual>
            <origin xyz="0 0 1.3814128435124235" rpy="0 0 0"/>
            <geometry>
                <box size="2.375559026484951 1.8469975094997548 2.762825687024847" />
            </geometry>
            <material name="Blue">
                <color rgba="0 1.0 1.0 1.0"/>
            </material>
        </visual>
        <collision>
            <origin xyz="0 0 1.3814128435124235" rpy="0 0 0"/>
            <geometry>
                <box size="2.375559026484951 1.8469975094997548 2.762825687024847" />
            </geometry>
        </collision>
    </link>
    <link name="Leg27">
        <inertial>
            <origin xyz="0 0 0.5904232484086326" rpy="0 0 0"/>
            <mass value="1" />
            <inertia ixx="100" ixy="0" ixz="0" iyy="100" iyz="0" izz="100" />
        </inertial>
        <visual>
            <origin xyz="0 0 0.5904232484086326" rpy="0 0 0"/>
            <geometry>
                <box size="1.892619109585686 1.0088228357056714 1.1808464968172652" />
            </geometry>
            <material name="Blue">
                <color rgba="0 1.0 1.0 1.0"/>
            </material>
        </visual>
        <collision>
            <origin xyz="0 0 0.5904232484086326" rpy="0 0 0"/>
            <geometry>
                <box size="1.892619109585686 1.0088228357056714 1.1808464968172652" />
            </geometry>
        </collision>
    </link>
    <joint name="Torso_Leg1" type="revolute">
       <parent link="Torso"/>
       <child  link="Leg1"/>
       <origin rpy="0 0 0" xyz="0.9133795955871461 0 0.723068386350265" />
     <axis xyz="1 0 0"/>
       <limit effort="0.0" lower="-3.14159" upper="3.14159" velocity="0.0"/>
    </joint>
    <joint name="Leg1_Leg2" type="revolute">
       <parent link="Leg1"/>
       <child  link="Leg2"/>
       <origin rpy="0 0 0" xyz="0 1.8169637722710807 0" />
     <axis xyz="1 0 0"/>
       <limit effort="0.0" lower="-3.14159" upper="3.14159" velocity="0.0"/>
    </joint>
    <joint name="Torso_Leg3" type="revolute">
       <parent link="Torso"/>
       <child  link="Leg3"/>
       <origin rpy="0 0 0" xyz="1.3516035214066955 0 1.2100259421706339" />
     <axis xyz="1 0 0"/>
       <limit effort="0.0" lower="-3.14159" upper="3.14159" velocity="0.0"/>
    </joint>
    <joint name="Torso_Leg4" type="revolute">
       <parent link="Torso"/>
       <child  link="Leg4"/>
       <origin rpy="0 0 0" xyz="1.3516035214066955 0.6148056201848756 1.2100259421706339" />
     <axis xyz="1 0 0"/>
       <limit effort="0.0" lower="-3.14159" upper="3.14159" velocity="0.0"/>
    </joint>
    <joint name="Leg4_Leg5" type="revolute">
       <parent link="Leg4"/>
       <child  link="Leg5"/>
       <origin rpy="0 0 0" xyz="1.0211905421884526 0 0" />
     <axis xyz="1 0 0"/>
       <limit effort="0.0" lower="-3.14159" upper="3.14159" velocity="0.0"/>
    </joint>
    <joint name="Leg4_Leg6" type="revolute">
       <parent link="Leg4"/>
       <child  link="Leg6"/>
       <origin rpy="0 0 0" xyz="1.0211905421884526 0 0.7972026701551215" />
     <axis xyz="1 0 0"/>
       <limit effort="0.0" lower="-3.14159" upper="3.14159" velocity="0.0"/>
    </joint>
    <joint name="Leg2_Leg7" type="revolute">
       <parent link="Leg2"/>
       <child  link="Leg7"/>
       <origin rpy="0 0 0" xyz="0 0 2.014267025102243" />
     <axis xyz="1 0 0"/>
       <limit effort="0.0" lower="-3.14159" upper="3.14159" velocity="0.0"/>
    </joint>
    <joint name="Leg6_Leg8" type="revolute">
       <parent link="Leg6"/>
       <child  link="Leg8"/>
       <origin rpy="0 0 0" xyz="0 0 2.054013884751307" />
     <axis xyz="1 0 0"/>
       <limit effort="0.0" lower="-3.14159" upper="3.14159" velocity="0.0"/>
    </joint>
    <joint name="Leg3_Leg9" type="revolute">
       <parent link="Leg3"/>
       <child  link="Leg9"/>
       <origin rpy="0 0 0" xyz="0 0.754406239048187 0.9303792554145199" />
     <axis xyz="1 0 0"/>
       <limit effort="0.0" lower="-3.14159" upper="3.14159" velocity="0.0"/>
    </joint>
    <joint name="Leg7_Leg10" type="revolute">
       <parent link="Leg7"/>
       <child  link="Leg10"/>
       <origin rpy="0 0 0" xyz="1.3519014893616332 0 1.2629644330052998" />
     <axis xyz="1 0 0"/>
       <limit effort="0.0" lower="-3.14159" upper="3.14159" velocity="0.0"/>
    </joint>
    <joint name="Leg6_Leg11" type="revolute">
       <parent link="Leg6"/>
       <child  link="Leg11"/>
       <origin rpy="0 0 0" xyz="0 1.2373144295703584 2.054013884751307" />
     <axis xyz="1 0 0"/>
       <limit effort="0.0" lower="-3.14159" upper="3.14159" velocity="0.0"/>
    </joint>
    <joint name="Leg3_Leg12" type="revolute">
       <parent link="Leg3"/>
       <child  link="Leg12"/>
       <origin rpy="0 0 0" xyz="0 1.508812478096374 0.9303792554145199" />
     <axis xyz="1 0 0"/>
       <limit effort="0.0" lower="-3.14159" upper="3.14159" velocity="0.0"/>
    </joint>
    <joint name="Leg10_Leg13" type="revolute">
       <parent link="Leg10"/>
       <child  link="Leg13"/>
       <origin rpy="0 0 0" xyz="0 2.901504009901908 0" />
     <axis xyz="1 0 0"/>
       <limit effort="0.0" lower="-3.14159" upper="3.14159" velocity="0.0"/>
    </joint>
    <joint name="Leg9_Leg14" type="revolute">
       <parent link="Leg9"/>
       <child  link="Leg14"/>
       <origin rpy="0 0 0" xyz="1.0708873607218194 0 0.9134222527860428" />
     <axis xyz="1 0 0"/>
       <limit effort="0.0" lower="-3.14159" upper="3.14159" velocity="0.0"/>
    </joint>
    <joint name="Leg11_Leg15" type="revolute">
       <parent link="Leg11"/>
       <child  link="Leg15"/>
       <origin rpy="0 0 0" xyz="0 0.8782297197503174 1.4689618811826206" />
     <axis xyz="1 0 0"/>
       <limit effort="0.0" lower="-3.14159" upper="3.14159" velocity="0.0"/>
    </joint>
    <joint name="Leg15_Leg16" type="revolute">
       <parent link="Leg15"/>
       <child  link="Leg16"/>
       <origin rpy="0 0 0" xyz="1.0468920236966242 0 0" />
     <axis xyz="1 0 0"/>
       <limit effort="0.0" lower="-3.14159" upper="3.14159" velocity="0.0"/>
    </joint>
    <joint name="Leg13_Leg17" type="revolute">
       <parent link="Leg13"/>
       <child  link="Leg17"/>
       <origin rpy="0 0 0" xyz="1.0755345307205237 0 0.8362798637306407" />
     <axis xyz="1 0 0"/>
       <limit effort="0.0" lower="-3.14159" upper="3.14159" velocity="0.0"/>
    </joint>
    <joint name="Leg14_Leg18" type="revolute">
       <parent link="Leg14"/>
       <child  link="Leg18"/>
       <origin rpy="0 0 0" xyz="0 0 1.2461480800459863" />
     <axis xyz="1 0 0"/>
       <limit effort="0.0" lower="-3.14159" upper="3.14159" velocity="0.0"/>
    </joint>
    <joint name="Leg13_Leg19" type="revolute">
       <parent link="Leg13"/>
       <child  link="Leg19"/>
       <origin rpy="0 0 0" xyz="1.0755345307205237 0.7408110710371595 0.8362798637306407" />
     <axis xyz="1 0 0"/>
       <limit effort="0.0" lower="-3.14159" upper="3.14159" velocity="0.0"/>
    </joint>
    <joint name="Leg9_Leg20" type="revolute">
       <parent link="Leg9"/>
       <child  link="Leg20"/>
       <origin rpy="0 0 0" xyz="1.0708873607218194 0.7618448981941928 0.9134222527860428" />
     <axis xyz="1 0 0"/>
       <limit effort="0.0" lower="-3.14159" upper="3.14159" velocity="0.0"/>
    </joint>
    <joint name="Leg19_Leg21" type="revolute">
       <parent link="Leg19"/>
       <child  link="Leg21"/>
       <origin rpy="0 0 0" xyz="0 1.9250570757801544 0" />
     <axis xyz="1 0 0"/>
       <limit effort="0.0" lower="-3.14159" upper="3.14159" velocity="0.0"/>
    </joint>
    <joint name="Leg16_Leg22" type="revolute">
       <parent link="Leg16"/>
       <child  link="Leg22"/>
       <origin rpy="0 0 0" xyz="1.219307299366525 0.7974251121756434 0" />
     <axis xyz="1 0 0"/>
       <limit effort="0.0" lower="-3.14159" upper="3.14159" velocity="0.0"/>
    </joint>
    <joint name="Leg18_Leg23" type="revolute">
       <parent link="Leg18"/>
       <child  link="Leg23"/>
       <origin rpy="0 0 0" xyz="0 1.1729253685185843 1.0733061557326673" />
     <axis xyz="1 0 0"/>
       <limit effort="0.0" lower="-3.14159" upper="3.14159" velocity="0.0"/>
    </joint>
    <joint name="Leg14_Leg24" type="revolute">
       <parent link="Leg14"/>
       <child  link="Leg24"/>
       <origin rpy="0 0 0" xyz="0 0.7662684347689591 1.2461480800459863" />
     <axis xyz="1 0 0"/>
       <limit effort="0.0" lower="-3.14159" upper="3.14159" velocity="0.0"/>
    </joint>
    <joint name="Leg23_Leg25" type="revolute">
       <parent link="Leg23"/>
       <child  link="Leg25"/>
       <origin rpy="0 0 0" xyz="0.7977808038227918 1.1673583006818662 0" />
     <axis xyz="1 0 0"/>
       <limit effort="0.0" lower="-3.14159" upper="3.14159" velocity="0.0"/>
    </joint>
    <joint name="Leg13_Leg26" type="revolute">
       <parent link="Leg13"/>
       <child  link="Leg26"/>
       <origin rpy="0 0 0" xyz="1.0755345307205237 0.7408110710371595 1.6725597274612813" />
     <axis xyz="1 0 0"/>
       <limit effort="0.0" lower="-3.14159" upper="3.14159" velocity="0.0"/>
    </joint>
    <joint name="Leg12_Leg27" type="revolute">
       <parent link="Leg12"/>
       <child  link="Leg27"/>
       <origin rpy="0 0 0" xyz="0 1.065958103387178 1.219420369762848" />
     <axis xyz="1 0 0"/>
       <limit effort="0.0" lower="-3.14159" upper="3.14159" velocity="0.0"/>
    </joint>
</robot>