<robot name = "robot">
    <link name="Torso">
        <inertial>
            <origin xyz="0 0 1.481862163253456" rpy="0 0 0"/>
            <mass value="1" />
            <inertia ixx="100" ixy="0" ixz="0" iyy="100" iyz="0" izz="100" />
        </inertial>
        <visual>
            <origin xyz="0 0 1.481862163253456" rpy="0 0 0"/>
            <geometry>
                <box size="1.8087595969744596 2.422530842013093 2.963724326506912" />
            </geometry>
            <material name="Green">
                <color rgba="0 180.0 0.0 1.0"/>
            </material>
        </visual>
        <collision>
            <origin xyz="0 0 1.481862163253456" rpy="0 0 0"/>
            <geometry>
                <box size="1.8087595969744596 2.422530842013093 2.963724326506912" />
            </geometry>
        </collision>
    </link>
    <link name="Leg1">
        <inertial>
            <origin xyz="0 0 0.8689705071797722" rpy="0 0 0"/>
            <mass value="1" />
            <inertia ixx="100" ixy="0" ixz="0" iyy="100" iyz="0" izz="100" />
        </inertial>
        <visual>
            <origin xyz="0 0 0.8689705071797722" rpy="0 0 0"/>
            <geometry>
                <box size="2.4390605928286755 1.9358410726136148 1.7379410143595444" />
            </geometry>
            <material name="Green">
                <color rgba="0 180.0 0.0 1.0"/>
            </material>
        </visual>
        <collision>
            <origin xyz="0 0 0.8689705071797722" rpy="0 0 0"/>
            <geometry>
                <box size="2.4390605928286755 1.9358410726136148 1.7379410143595444" />
            </geometry>
        </collision>
    </link>
    <link name="Leg2">
        <inertial>
            <origin xyz="0 0.7360587387072679 0" rpy="0 0 0"/>
            <mass value="1" />
            <inertia ixx="100" ixy="0" ixz="0" iyy="100" iyz="0" izz="100" />
        </inertial>
        <visual>
            <origin xyz="0 0.7360587387072679 0" rpy="0 0 0"/>
            <geometry>
                <box size="2.9394044887489006 1.4721174774145358 2.5809202259823962" />
            </geometry>
            <material name="Blue">
                <color rgba="0 1.0 1.0 1.0"/>
            </material>
        </visual>
        <collision>
            <origin xyz="0 0.7360587387072679 0" rpy="0 0 0"/>
            <geometry>
                <box size="2.9394044887489006 1.4721174774145358 2.5809202259823962" />
            </geometry>
        </collision>
    </link>
    <link name="Leg3">
        <inertial>
            <origin xyz="0 1.1926241391411474 0" rpy="0 0 0"/>
            <mass value="1" />
            <inertia ixx="100" ixy="0" ixz="0" iyy="100" iyz="0" izz="100" />
        </inertial>
        <visual>
            <origin xyz="0 1.1926241391411474 0" rpy="0 0 0"/>
            <geometry>
                <box size="1.1937529124497954 2.385248278282295 1.7041956292182379" />
            </geometry>
            <material name="Green">
                <color rgba="0 180.0 0.0 1.0"/>
            </material>
        </visual>
        <collision>
            <origin xyz="0 1.1926241391411474 0" rpy="0 0 0"/>
            <geometry>
                <box size="1.1937529124497954 2.385248278282295 1.7041956292182379" />
            </geometry>
        </collision>
    </link>
    <link name="Leg4">
        <inertial>
            <origin xyz="0 0.7499670481268489 0" rpy="0 0 0"/>
            <mass value="1" />
            <inertia ixx="100" ixy="0" ixz="0" iyy="100" iyz="0" izz="100" />
        </inertial>
        <visual>
            <origin xyz="0 0.7499670481268489 0" rpy="0 0 0"/>
            <geometry>
                <box size="2.0296546299239013 1.4999340962536978 1.2806335066205625" />
            </geometry>
            <material name="Blue">
                <color rgba="0 1.0 1.0 1.0"/>
            </material>
        </visual>
        <collision>
            <origin xyz="0 0.7499670481268489 0" rpy="0 0 0"/>
            <geometry>
                <box size="2.0296546299239013 1.4999340962536978 1.2806335066205625" />
            </geometry>
        </collision>
    </link>
    <link name="Leg5">
        <inertial>
            <origin xyz="0 0.6812987282169123 0" rpy="0 0 0"/>
            <mass value="1" />
            <inertia ixx="100" ixy="0" ixz="0" iyy="100" iyz="0" izz="100" />
        </inertial>
        <visual>
            <origin xyz="0 0.6812987282169123 0" rpy="0 0 0"/>
            <geometry>
                <box size="1.2911340635351145 1.3625974564338246 1.8238565168289158" />
            </geometry>
            <material name="Green">
                <color rgba="0 180.0 0.0 1.0"/>
            </material>
        </visual>
        <collision>
            <origin xyz="0 0.6812987282169123 0" rpy="0 0 0"/>
            <geometry>
                <box size="1.2911340635351145 1.3625974564338246 1.8238565168289158" />
            </geometry>
        </collision>
    </link>
    <link name="Leg6">
        <inertial>
            <origin xyz="0.6542153688714386 0 0" rpy="0 0 0"/>
            <mass value="1" />
            <inertia ixx="100" ixy="0" ixz="0" iyy="100" iyz="0" izz="100" />
        </inertial>
        <visual>
            <origin xyz="0.6542153688714386 0 0" rpy="0 0 0"/>
            <geometry>
                <box size="1.3084307377428772 2.5782403866912675 2.2500463759528326" />
            </geometry>
            <material name="Blue">
                <color rgba="0 1.0 1.0 1.0"/>
            </material>
        </visual>
        <collision>
            <origin xyz="0.6542153688714386 0 0" rpy="0 0 0"/>
            <geometry>
                <box size="1.3084307377428772 2.5782403866912675 2.2500463759528326" />
            </geometry>
        </collision>
    </link>
    <link name="Leg7">
        <inertial>
            <origin xyz="0.5714673873683139 0 0" rpy="0 0 0"/>
            <mass value="1" />
            <inertia ixx="100" ixy="0" ixz="0" iyy="100" iyz="0" izz="100" />
        </inertial>
        <visual>
            <origin xyz="0.5714673873683139 0 0" rpy="0 0 0"/>
            <geometry>
                <box size="1.1429347747366279 2.1371596299656144 2.425203254795843" />
            </geometry>
            <material name="Blue">
                <color rgba="0 1.0 1.0 1.0"/>
            </material>
        </visual>
        <collision>
            <origin xyz="0.5714673873683139 0 0" rpy="0 0 0"/>
            <geometry>
                <box size="1.1429347747366279 2.1371596299656144 2.425203254795843" />
            </geometry>
        </collision>
    </link>
    <link name="Leg8">
        <inertial>
            <origin xyz="1.249597987348469 0 0" rpy="0 0 0"/>
            <mass value="1" />
            <inertia ixx="100" ixy="0" ixz="0" iyy="100" iyz="0" izz="100" />
        </inertial>
        <visual>
            <origin xyz="1.249597987348469 0 0" rpy="0 0 0"/>
            <geometry>
                <box size="2.499195974696938 2.270843657132268 2.3422328671992765" />
            </geometry>
            <material name="Blue">
                <color rgba="0 1.0 1.0 1.0"/>
            </material>
        </visual>
        <collision>
            <origin xyz="1.249597987348469 0 0" rpy="0 0 0"/>
            <geometry>
                <box size="2.499195974696938 2.270843657132268 2.3422328671992765" />
            </geometry>
        </collision>
    </link>
    <link name="Leg9">
        <inertial>
            <origin xyz="0 0 0.897393449638089" rpy="0 0 0"/>
            <mass value="1" />
            <inertia ixx="100" ixy="0" ixz="0" iyy="100" iyz="0" izz="100" />
        </inertial>
        <visual>
            <origin xyz="0 0 0.897393449638089" rpy="0 0 0"/>
            <geometry>
                <box size="1.6183164568573392 2.549393229856881 1.794786899276178" />
            </geometry>
            <material name="Green">
                <color rgba="0 180.0 0.0 1.0"/>
            </material>
        </visual>
        <collision>
            <origin xyz="0 0 0.897393449638089" rpy="0 0 0"/>
            <geometry>
                <box size="1.6183164568573392 2.549393229856881 1.794786899276178" />
            </geometry>
        </collision>
    </link>
    <link name="Leg10">
        <inertial>
            <origin xyz="1.2993959869887532 0 0" rpy="0 0 0"/>
            <mass value="1" />
            <inertia ixx="100" ixy="0" ixz="0" iyy="100" iyz="0" izz="100" />
        </inertial>
        <visual>
            <origin xyz="1.2993959869887532 0 0" rpy="0 0 0"/>
            <geometry>
                <box size="2.5987919739775065 1.3150402518221658 1.350774750591241" />
            </geometry>
            <material name="Green">
                <color rgba="0 180.0 0.0 1.0"/>
            </material>
        </visual>
        <collision>
            <origin xyz="1.2993959869887532 0 0" rpy="0 0 0"/>
            <geometry>
                <box size="2.5987919739775065 1.3150402518221658 1.350774750591241" />
            </geometry>
        </collision>
    </link>
    <link name="Leg11">
        <inertial>
            <origin xyz="1.300716110027473 0 0" rpy="0 0 0"/>
            <mass value="1" />
            <inertia ixx="100" ixy="0" ixz="0" iyy="100" iyz="0" izz="100" />
        </inertial>
        <visual>
            <origin xyz="1.300716110027473 0 0" rpy="0 0 0"/>
            <geometry>
                <box size="2.601432220054946 1.8969430851858535 1.4733899147061833" />
            </geometry>
            <material name="Green">
                <color rgba="0 180.0 0.0 1.0"/>
            </material>
        </visual>
        <collision>
            <origin xyz="1.300716110027473 0 0" rpy="0 0 0"/>
            <geometry>
                <box size="2.601432220054946 1.8969430851858535 1.4733899147061833" />
            </geometry>
        </collision>
    </link>
    <link name="Leg12">
        <inertial>
            <origin xyz="0 0 0.6163443654568643" rpy="0 0 0"/>
            <mass value="1" />
            <inertia ixx="100" ixy="0" ixz="0" iyy="100" iyz="0" izz="100" />
        </inertial>
        <visual>
            <origin xyz="0 0 0.6163443654568643" rpy="0 0 0"/>
            <geometry>
                <box size="2.056107333669278 2.227394551992134 1.2326887309137287" />
            </geometry>
            <material name="Green">
                <color rgba="0 180.0 0.0 1.0"/>
            </material>
        </visual>
        <collision>
            <origin xyz="0 0 0.6163443654568643" rpy="0 0 0"/>
            <geometry>
                <box size="2.056107333669278 2.227394551992134 1.2326887309137287" />
            </geometry>
        </collision>
    </link>
    <link name="Leg13">
        <inertial>
            <origin xyz="0.7158963420035077 0 0" rpy="0 0 0"/>
            <mass value="1" />
            <inertia ixx="100" ixy="0" ixz="0" iyy="100" iyz="0" izz="100" />
        </inertial>
        <visual>
            <origin xyz="0.7158963420035077 0 0" rpy="0 0 0"/>
            <geometry>
                <box size="1.4317926840070154 2.9344391571865147 1.3497154633598878" />
            </geometry>
            <material name="Green">
                <color rgba="0 180.0 0.0 1.0"/>
            </material>
        </visual>
        <collision>
            <origin xyz="0.7158963420035077 0 0" rpy="0 0 0"/>
            <geometry>
                <box size="1.4317926840070154 2.9344391571865147 1.3497154633598878" />
            </geometry>
        </collision>
    </link>
    <link name="Leg14">
        <inertial>
            <origin xyz="1.3991308793364738 0 0" rpy="0 0 0"/>
            <mass value="1" />
            <inertia ixx="100" ixy="0" ixz="0" iyy="100" iyz="0" izz="100" />
        </inertial>
        <visual>
            <origin xyz="1.3991308793364738 0 0" rpy="0 0 0"/>
            <geometry>
                <box size="2.7982617586729477 1.5506845848074946 2.746915724240961" />
            </geometry>
            <material name="Green">
                <color rgba="0 180.0 0.0 1.0"/>
            </material>
        </visual>
        <collision>
            <origin xyz="1.3991308793364738 0 0" rpy="0 0 0"/>
            <geometry>
                <box size="2.7982617586729477 1.5506845848074946 2.746915724240961" />
            </geometry>
        </collision>
    </link>
    <link name="Leg15">
        <inertial>
            <origin xyz="0 0.7445815873119973 0" rpy="0 0 0"/>
            <mass value="1" />
            <inertia ixx="100" ixy="0" ixz="0" iyy="100" iyz="0" izz="100" />
        </inertial>
        <visual>
            <origin xyz="0 0.7445815873119973 0" rpy="0 0 0"/>
            <geometry>
                <box size="1.9171847832983453 1.4891631746239946 2.3752001363232447" />
            </geometry>
            <material name="Green">
                <color rgba="0 180.0 0.0 1.0"/>
            </material>
        </visual>
        <collision>
            <origin xyz="0 0.7445815873119973 0" rpy="0 0 0"/>
            <geometry>
                <box size="1.9171847832983453 1.4891631746239946 2.3752001363232447" />
            </geometry>
        </collision>
    </link>
    <link name="Leg16">
        <inertial>
            <origin xyz="0.5305724847881695 0 0" rpy="0 0 0"/>
            <mass value="1" />
            <inertia ixx="100" ixy="0" ixz="0" iyy="100" iyz="0" izz="100" />
        </inertial>
        <visual>
            <origin xyz="0.5305724847881695 0 0" rpy="0 0 0"/>
            <geometry>
                <box size="1.061144969576339 1.770195415961159 2.8852062621205783" />
            </geometry>
            <material name="Green">
                <color rgba="0 180.0 0.0 1.0"/>
            </material>
        </visual>
        <collision>
            <origin xyz="0.5305724847881695 0 0" rpy="0 0 0"/>
            <geometry>
                <box size="1.061144969576339 1.770195415961159 2.8852062621205783" />
            </geometry>
        </collision>
    </link>
    <link name="Leg17">
        <inertial>
            <origin xyz="0.7119276318571632 0 0" rpy="0 0 0"/>
            <mass value="1" />
            <inertia ixx="100" ixy="0" ixz="0" iyy="100" iyz="0" izz="100" />
        </inertial>
        <visual>
            <origin xyz="0.7119276318571632 0 0" rpy="0 0 0"/>
            <geometry>
                <box size="1.4238552637143265 2.4542510247077827 2.8571302843352235" />
            </geometry>
            <material name="Blue">
                <color rgba="0 1.0 1.0 1.0"/>
            </material>
        </visual>
        <collision>
            <origin xyz="0.7119276318571632 0 0" rpy="0 0 0"/>
            <geometry>
                <box size="1.4238552637143265 2.4542510247077827 2.8571302843352235" />
            </geometry>
        </collision>
    </link>
    <link name="Leg18">
        <inertial>
            <origin xyz="0 0 1.2012696548453934" rpy="0 0 0"/>
            <mass value="1" />
            <inertia ixx="100" ixy="0" ixz="0" iyy="100" iyz="0" izz="100" />
        </inertial>
        <visual>
            <origin xyz="0 0 1.2012696548453934" rpy="0 0 0"/>
            <geometry>
                <box size="2.870197900678879 1.5538092326485113 2.4025393096907868" />
            </geometry>
            <material name="Green">
                <color rgba="0 180.0 0.0 1.0"/>
            </material>
        </visual>
        <collision>
            <origin xyz="0 0 1.2012696548453934" rpy="0 0 0"/>
            <geometry>
                <box size="2.870197900678879 1.5538092326485113 2.4025393096907868" />
            </geometry>
        </collision>
    </link>
    <link name="Leg19">
        <inertial>
            <origin xyz="0 0 0.625712469324528" rpy="0 0 0"/>
            <mass value="1" />
            <inertia ixx="100" ixy="0" ixz="0" iyy="100" iyz="0" izz="100" />
        </inertial>
        <visual>
            <origin xyz="0 0 0.625712469324528" rpy="0 0 0"/>
            <geometry>
                <box size="1.7366806917751232 2.4514852750306977 1.251424938649056" />
            </geometry>
            <material name="Blue">
                <color rgba="0 1.0 1.0 1.0"/>
            </material>
        </visual>
        <collision>
            <origin xyz="0 0 0.625712469324528" rpy="0 0 0"/>
            <geometry>
                <box size="1.7366806917751232 2.4514852750306977 1.251424938649056" />
            </geometry>
        </collision>
    </link>
    <link name="Leg20">
        <inertial>
            <origin xyz="0 0 0.7343029248954054" rpy="0 0 0"/>
            <mass value="1" />
            <inertia ixx="100" ixy="0" ixz="0" iyy="100" iyz="0" izz="100" />
        </inertial>
        <visual>
            <origin xyz="0 0 0.7343029248954054" rpy="0 0 0"/>
            <geometry>
                <box size="1.1261689911795272 1.312787588386461 1.4686058497908108" />
            </geometry>
            <material name="Blue">
                <color rgba="0 1.0 1.0 1.0"/>
            </material>
        </visual>
        <collision>
            <origin xyz="0 0 0.7343029248954054" rpy="0 0 0"/>
            <geometry>
                <box size="1.1261689911795272 1.312787588386461 1.4686058497908108" />
            </geometry>
        </collision>
    </link>
    <link name="Leg21">
        <inertial>
            <origin xyz="0 0 0.9762496602395996" rpy="0 0 0"/>
            <mass value="1" />
            <inertia ixx="100" ixy="0" ixz="0" iyy="100" iyz="0" izz="100" />
        </inertial>
        <visual>
            <origin xyz="0 0 0.9762496602395996" rpy="0 0 0"/>
            <geometry>
                <box size="1.049216726095607 1.2155130687012803 1.9524993204791992" />
            </geometry>
            <material name="Green">
                <color rgba="0 180.0 0.0 1.0"/>
            </material>
        </visual>
        <collision>
            <origin xyz="0 0 0.9762496602395996" rpy="0 0 0"/>
            <geometry>
                <box size="1.049216726095607 1.2155130687012803 1.9524993204791992" />
            </geometry>
        </collision>
    </link>
    <link name="Leg22">
        <inertial>
            <origin xyz="0 0.7990920334233315 0" rpy="0 0 0"/>
            <mass value="1" />
            <inertia ixx="100" ixy="0" ixz="0" iyy="100" iyz="0" izz="100" />
        </inertial>
        <visual>
            <origin xyz="0 0.7990920334233315 0" rpy="0 0 0"/>
            <geometry>
                <box size="2.948903707247833 1.598184066846663 1.8184734746394131" />
            </geometry>
            <material name="Green">
                <color rgba="0 180.0 0.0 1.0"/>
            </material>
        </visual>
        <collision>
            <origin xyz="0 0.7990920334233315 0" rpy="0 0 0"/>
            <geometry>
                <box size="2.948903707247833 1.598184066846663 1.8184734746394131" />
            </geometry>
        </collision>
    </link>
    <link name="Leg23">
        <inertial>
            <origin xyz="0.7704240668005061 0 0" rpy="0 0 0"/>
            <mass value="1" />
            <inertia ixx="100" ixy="0" ixz="0" iyy="100" iyz="0" izz="100" />
        </inertial>
        <visual>
            <origin xyz="0.7704240668005061 0 0" rpy="0 0 0"/>
            <geometry>
                <box size="1.5408481336010122 2.8395479157998844 2.890642648966196" />
            </geometry>
            <material name="Green">
                <color rgba="0 180.0 0.0 1.0"/>
            </material>
        </visual>
        <collision>
            <origin xyz="0.7704240668005061 0 0" rpy="0 0 0"/>
            <geometry>
                <box size="1.5408481336010122 2.8395479157998844 2.890642648966196" />
            </geometry>
        </collision>
    </link>
    <link name="Leg24">
        <inertial>
            <origin xyz="0 1.0117702344791302 0" rpy="0 0 0"/>
            <mass value="1" />
            <inertia ixx="100" ixy="0" ixz="0" iyy="100" iyz="0" izz="100" />
        </inertial>
        <visual>
            <origin xyz="0 1.0117702344791302 0" rpy="0 0 0"/>
            <geometry>
                <box size="1.5964512189676094 2.0235404689582603 2.262308815299792" />
            </geometry>
            <material name="Green">
                <color rgba="0 180.0 0.0 1.0"/>
            </material>
        </visual>
        <collision>
            <origin xyz="0 1.0117702344791302 0" rpy="0 0 0"/>
            <geometry>
                <box size="1.5964512189676094 2.0235404689582603 2.262308815299792" />
            </geometry>
        </collision>
    </link>
    <link name="Leg25">
        <inertial>
            <origin xyz="0 1.2068260618559745 0" rpy="0 0 0"/>
            <mass value="1" />
            <inertia ixx="100" ixy="0" ixz="0" iyy="100" iyz="0" izz="100" />
        </inertial>
        <visual>
            <origin xyz="0 1.2068260618559745 0" rpy="0 0 0"/>
            <geometry>
                <box size="1.864102855591743 2.413652123711949 2.3721688544588995" />
            </geometry>
            <material name="Blue">
                <color rgba="0 1.0 1.0 1.0"/>
            </material>
        </visual>
        <collision>
            <origin xyz="0 1.2068260618559745 0" rpy="0 0 0"/>
            <geometry>
                <box size="1.864102855591743 2.413652123711949 2.3721688544588995" />
            </geometry>
        </collision>
    </link>
    <link name="Leg26">
        <inertial>
            <origin xyz="0 0.7350130236346876 0" rpy="0 0 0"/>
            <mass value="1" />
            <inertia ixx="100" ixy="0" ixz="0" iyy="100" iyz="0" izz="100" />
        </inertial>
        <visual>
            <origin xyz="0 0.7350130236346876 0" rpy="0 0 0"/>
            <geometry>
                <box size="1.9891781777925734 1.4700260472693751 1.0600937815585612" />
            </geometry>
            <material name="Green">
                <color rgba="0 180.0 0.0 1.0"/>
            </material>
        </visual>
        <collision>
            <origin xyz="0 0.7350130236346876 0" rpy="0 0 0"/>
            <geometry>
                <box size="1.9891781777925734 1.4700260472693751 1.0600937815585612" />
            </geometry>
        </collision>
    </link>
    <joint name="Torso_Leg1" type="revolute">
       <parent link="Torso"/>
       <child  link="Leg1"/>
       <origin rpy="0 0 0" xyz="0 0 2.963724326506912" />
     <axis xyz="1 0 0"/>
       <limit effort="0.0" lower="-3.14159" upper="3.14159" velocity="0.0"/>
    </joint>
    <joint name="Leg1_Leg2" type="revolute">
       <parent link="Leg1"/>
       <child  link="Leg2"/>
       <origin rpy="0 0 0" xyz="0 1.4721174774145358 0" />
     <axis xyz="1 0 0"/>
       <limit effort="0.0" lower="-3.14159" upper="3.14159" velocity="0.0"/>
    </joint>
    <joint name="Torso_Leg3" type="revolute">
       <parent link="Torso"/>
       <child  link="Leg3"/>
       <origin rpy="0 0 0" xyz="0 0.9679205363068074 0.8689705071797722" />
     <axis xyz="1 0 0"/>
       <limit effort="0.0" lower="-3.14159" upper="3.14159" velocity="0.0"/>
    </joint>
    <joint name="Leg2_Leg4" type="revolute">
       <parent link="Leg2"/>
       <child  link="Leg4"/>
       <origin rpy="0 0 0" xyz="0 2.385248278282295 0" />
     <axis xyz="1 0 0"/>
       <limit effort="0.0" lower="-3.14159" upper="3.14159" velocity="0.0"/>
    </joint>
    <joint name="Leg3_Leg5" type="revolute">
       <parent link="Leg3"/>
       <child  link="Leg5"/>
       <origin rpy="0 0 0" xyz="0 1.4999340962536978 0" />
     <axis xyz="1 0 0"/>
       <limit effort="0.0" lower="-3.14159" upper="3.14159" velocity="0.0"/>
    </joint>
    <joint name="Leg3_Leg6" type="revolute">
       <parent link="Leg3"/>
       <child  link="Leg6"/>
       <origin rpy="0 0 0" xyz="1.0148273149619507 1.4999340962536978 0" />
     <axis xyz="1 0 0"/>
       <limit effort="0.0" lower="-3.14159" upper="3.14159" velocity="0.0"/>
    </joint>
    <joint name="Leg5_Leg7" type="revolute">
       <parent link="Leg5"/>
       <child  link="Leg7"/>
       <origin rpy="0 0 0" xyz="1.3084307377428772 0 0" />
     <axis xyz="1 0 0"/>
       <limit effort="0.0" lower="-3.14159" upper="3.14159" velocity="0.0"/>
    </joint>
    <joint name="Leg7_Leg8" type="revolute">
       <parent link="Leg7"/>
       <child  link="Leg8"/>
       <origin rpy="0 0 0" xyz="2.499195974696938 0 0" />
     <axis xyz="1 0 0"/>
       <limit effort="0.0" lower="-3.14159" upper="3.14159" velocity="0.0"/>
    </joint>
    <joint name="Leg1_Leg9" type="revolute">
       <parent link="Leg1"/>
       <child  link="Leg9"/>
       <origin rpy="0 0 0" xyz="0 1.4721174774145358 1.2904601129911981" />
     <axis xyz="1 0 0"/>
       <limit effort="0.0" lower="-3.14159" upper="3.14159" velocity="0.0"/>
    </joint>
    <joint name="Leg1_Leg10" type="revolute">
       <parent link="Leg1"/>
       <child  link="Leg10"/>
       <origin rpy="0 0 0" xyz="1.4697022443744503 1.4721174774145358 1.2904601129911981" />
     <axis xyz="1 0 0"/>
       <limit effort="0.0" lower="-3.14159" upper="3.14159" velocity="0.0"/>
    </joint>
    <joint name="Leg9_Leg11" type="revolute">
       <parent link="Leg9"/>
       <child  link="Leg11"/>
       <origin rpy="0 0 0" xyz="2.5987919739775065 0 0" />
     <axis xyz="1 0 0"/>
       <limit effort="0.0" lower="-3.14159" upper="3.14159" velocity="0.0"/>
    </joint>
    <joint name="Leg10_Leg12" type="revolute">
       <parent link="Leg10"/>
       <child  link="Leg12"/>
       <origin rpy="0 0 0" xyz="1.300716110027473 0 0.7366949573530917" />
     <axis xyz="1 0 0"/>
       <limit effort="0.0" lower="-3.14159" upper="3.14159" velocity="0.0"/>
    </joint>
    <joint name="Leg10_Leg13" type="revolute">
       <parent link="Leg10"/>
       <child  link="Leg13"/>
       <origin rpy="0 0 0" xyz="2.601432220054946 0 0.7366949573530917" />
     <axis xyz="1 0 0"/>
       <limit effort="0.0" lower="-3.14159" upper="3.14159" velocity="0.0"/>
    </joint>
    <joint name="Leg11_Leg14" type="revolute">
       <parent link="Leg11"/>
       <child  link="Leg14"/>
       <origin rpy="0 0 0" xyz="1.028053666834639 0 0.6163443654568643" />
     <axis xyz="1 0 0"/>
       <limit effort="0.0" lower="-3.14159" upper="3.14159" velocity="0.0"/>
    </joint>
    <joint name="Leg12_Leg15" type="revolute">
       <parent link="Leg12"/>
       <child  link="Leg15"/>
       <origin rpy="0 0 0" xyz="0.7158963420035077 1.4672195785932574 0" />
     <axis xyz="1 0 0"/>
       <limit effort="0.0" lower="-3.14159" upper="3.14159" velocity="0.0"/>
    </joint>
    <joint name="Leg14_Leg16" type="revolute">
       <parent link="Leg14"/>
       <child  link="Leg16"/>
       <origin rpy="0 0 0" xyz="0.9585923916491726 0.7445815873119973 0" />
     <axis xyz="1 0 0"/>
       <limit effort="0.0" lower="-3.14159" upper="3.14159" velocity="0.0"/>
    </joint>
    <joint name="Leg12_Leg17" type="revolute">
       <parent link="Leg12"/>
       <child  link="Leg17"/>
       <origin rpy="0 0 0" xyz="1.4317926840070154 1.4672195785932574 0" />
     <axis xyz="1 0 0"/>
       <limit effort="0.0" lower="-3.14159" upper="3.14159" velocity="0.0"/>
    </joint>
    <joint name="Leg7_Leg18" type="revolute">
       <parent link="Leg7"/>
       <child  link="Leg18"/>
       <origin rpy="0 0 0" xyz="2.499195974696938 0 1.1711164335996382" />
     <axis xyz="1 0 0"/>
       <limit effort="0.0" lower="-3.14159" upper="3.14159" velocity="0.0"/>
    </joint>
    <joint name="Leg18_Leg19" type="revolute">
       <parent link="Leg18"/>
       <child  link="Leg19"/>
       <origin rpy="0 0 0" xyz="0 0 1.251424938649056" />
     <axis xyz="1 0 0"/>
       <limit effort="0.0" lower="-3.14159" upper="3.14159" velocity="0.0"/>
    </joint>
    <joint name="Leg8_Leg20" type="revolute">
       <parent link="Leg8"/>
       <child  link="Leg20"/>
       <origin rpy="0 0 0" xyz="0 0 1.794786899276178" />
     <axis xyz="1 0 0"/>
       <limit effort="0.0" lower="-3.14159" upper="3.14159" velocity="0.0"/>
    </joint>
    <joint name="Leg17_Leg21" type="revolute">
       <parent link="Leg17"/>
       <child  link="Leg21"/>
       <origin rpy="0 0 0" xyz="0 0 2.4025393096907868" />
     <axis xyz="1 0 0"/>
       <limit effort="0.0" lower="-3.14159" upper="3.14159" velocity="0.0"/>
    </joint>
    <joint name="Leg13_Leg22" type="revolute">
       <parent link="Leg13"/>
       <child  link="Leg22"/>
       <origin rpy="0 0 0" xyz="1.3991308793364738 0.7753422924037473 0" />
     <axis xyz="1 0 0"/>
       <limit effort="0.0" lower="-3.14159" upper="3.14159" velocity="0.0"/>
    </joint>
    <joint name="Leg4_Leg23" type="revolute">
       <parent link="Leg4"/>
       <child  link="Leg23"/>
       <origin rpy="0 0 0" xyz="0.6455670317675573 0.6812987282169123 0" />
     <axis xyz="1 0 0"/>
       <limit effort="0.0" lower="-3.14159" upper="3.14159" velocity="0.0"/>
    </joint>
    <joint name="Leg18_Leg24" type="revolute">
       <parent link="Leg18"/>
       <child  link="Leg24"/>
       <origin rpy="0 0 0" xyz="0 1.2257426375153488 1.251424938649056" />
     <axis xyz="1 0 0"/>
       <limit effort="0.0" lower="-3.14159" upper="3.14159" velocity="0.0"/>
    </joint>
    <joint name="Leg9_Leg25" type="revolute">
       <parent link="Leg9"/>
       <child  link="Leg25"/>
       <origin rpy="0 0 0" xyz="2.5987919739775065 0.6575201259110829 0" />
     <axis xyz="1 0 0"/>
       <limit effort="0.0" lower="-3.14159" upper="3.14159" velocity="0.0"/>
    </joint>
    <joint name="Leg6_Leg26" type="revolute">
       <parent link="Leg6"/>
       <child  link="Leg26"/>
       <origin rpy="0 0 0" xyz="0.5714673873683139 1.0685798149828072 0" />
     <axis xyz="1 0 0"/>
       <limit effort="0.0" lower="-3.14159" upper="3.14159" velocity="0.0"/>
    </joint>
</robot>