<robot name = "robot">
    <link name="Torso">
        <inertial>
            <origin xyz="0 0 0.7245604969157625" rpy="0 0 0"/>
            <mass value="1" />
            <inertia ixx="100" ixy="0" ixz="0" iyy="100" iyz="0" izz="100" />
        </inertial>
        <visual>
            <origin xyz="0 0 0.7245604969157625" rpy="0 0 0"/>
            <geometry>
                <box size="1.72682003794251 2.1121282658835865 1.449120993831525" />
            </geometry>
            <material name="Green">
                <color rgba="0 180.0 0.0 1.0"/>
            </material>
        </visual>
        <collision>
            <origin xyz="0 0 0.7245604969157625" rpy="0 0 0"/>
            <geometry>
                <box size="1.72682003794251 2.1121282658835865 1.449120993831525" />
            </geometry>
        </collision>
    </link>
    <link name="Leg1">
        <inertial>
            <origin xyz="0 0 0.5932091821507601" rpy="0 0 0"/>
            <mass value="1" />
            <inertia ixx="100" ixy="0" ixz="0" iyy="100" iyz="0" izz="100" />
        </inertial>
        <visual>
            <origin xyz="0 0 0.5932091821507601" rpy="0 0 0"/>
            <geometry>
                <box size="2.4611064171025143 2.7187515625565997 1.1864183643015203" />
            </geometry>
            <material name="Blue">
                <color rgba="0 1.0 1.0 1.0"/>
            </material>
        </visual>
        <collision>
            <origin xyz="0 0 0.5932091821507601" rpy="0 0 0"/>
            <geometry>
                <box size="2.4611064171025143 2.7187515625565997 1.1864183643015203" />
            </geometry>
        </collision>
    </link>
    <link name="Leg2">
        <inertial>
            <origin xyz="1.2465833257192929 0 0" rpy="0 0 0"/>
            <mass value="1" />
            <inertia ixx="100" ixy="0" ixz="0" iyy="100" iyz="0" izz="100" />
        </inertial>
        <visual>
            <origin xyz="1.2465833257192929 0 0" rpy="0 0 0"/>
            <geometry>
                <box size="2.4931666514385857 1.6762776324991584 2.35531387889125" />
            </geometry>
            <material name="Blue">
                <color rgba="0 1.0 1.0 1.0"/>
            </material>
        </visual>
        <collision>
            <origin xyz="1.2465833257192929 0 0" rpy="0 0 0"/>
            <geometry>
                <box size="2.4931666514385857 1.6762776324991584 2.35531387889125" />
            </geometry>
        </collision>
    </link>
    <link name="Leg3">
        <inertial>
            <origin xyz="0 0 1.0288925210588893" rpy="0 0 0"/>
            <mass value="1" />
            <inertia ixx="100" ixy="0" ixz="0" iyy="100" iyz="0" izz="100" />
        </inertial>
        <visual>
            <origin xyz="0 0 1.0288925210588893" rpy="0 0 0"/>
            <geometry>
                <box size="1.3047087846613499 2.6403952525650203 2.0577850421177786" />
            </geometry>
            <material name="Blue">
                <color rgba="0 1.0 1.0 1.0"/>
            </material>
        </visual>
        <collision>
            <origin xyz="0 0 1.0288925210588893" rpy="0 0 0"/>
            <geometry>
                <box size="1.3047087846613499 2.6403952525650203 2.0577850421177786" />
            </geometry>
        </collision>
    </link>
    <link name="Leg4">
        <inertial>
            <origin xyz="1.4731255376730612 0 0" rpy="0 0 0"/>
            <mass value="1" />
            <inertia ixx="100" ixy="0" ixz="0" iyy="100" iyz="0" izz="100" />
        </inertial>
        <visual>
            <origin xyz="1.4731255376730612 0 0" rpy="0 0 0"/>
            <geometry>
                <box size="2.9462510753461224 2.4349418789578867 2.245951811865" />
            </geometry>
            <material name="Blue">
                <color rgba="0 1.0 1.0 1.0"/>
            </material>
        </visual>
        <collision>
            <origin xyz="1.4731255376730612 0 0" rpy="0 0 0"/>
            <geometry>
                <box size="2.9462510753461224 2.4349418789578867 2.245951811865" />
            </geometry>
        </collision>
    </link>
    <link name="Leg5">
        <inertial>
            <origin xyz="0 1.327533854632918 0" rpy="0 0 0"/>
            <mass value="1" />
            <inertia ixx="100" ixy="0" ixz="0" iyy="100" iyz="0" izz="100" />
        </inertial>
        <visual>
            <origin xyz="0 1.327533854632918 0" rpy="0 0 0"/>
            <geometry>
                <box size="1.4475803539164291 2.655067709265836 2.4709743648867226" />
            </geometry>
            <material name="Blue">
                <color rgba="0 1.0 1.0 1.0"/>
            </material>
        </visual>
        <collision>
            <origin xyz="0 1.327533854632918 0" rpy="0 0 0"/>
            <geometry>
                <box size="1.4475803539164291 2.655067709265836 2.4709743648867226" />
            </geometry>
        </collision>
    </link>
    <link name="Leg6">
        <inertial>
            <origin xyz="0.8302938212609035 0 0" rpy="0 0 0"/>
            <mass value="1" />
            <inertia ixx="100" ixy="0" ixz="0" iyy="100" iyz="0" izz="100" />
        </inertial>
        <visual>
            <origin xyz="0.8302938212609035 0 0" rpy="0 0 0"/>
            <geometry>
                <box size="1.660587642521807 1.5074926312436379 2.2447053391239717" />
            </geometry>
            <material name="Green">
                <color rgba="0 180.0 0.0 1.0"/>
            </material>
        </visual>
        <collision>
            <origin xyz="0.8302938212609035 0 0" rpy="0 0 0"/>
            <geometry>
                <box size="1.660587642521807 1.5074926312436379 2.2447053391239717" />
            </geometry>
        </collision>
    </link>
    <link name="Leg7">
        <inertial>
            <origin xyz="0 0 1.0467685931853374" rpy="0 0 0"/>
            <mass value="1" />
            <inertia ixx="100" ixy="0" ixz="0" iyy="100" iyz="0" izz="100" />
        </inertial>
        <visual>
            <origin xyz="0 0 1.0467685931853374" rpy="0 0 0"/>
            <geometry>
                <box size="2.934987764024701 1.5977946528957296 2.093537186370675" />
            </geometry>
            <material name="Green">
                <color rgba="0 180.0 0.0 1.0"/>
            </material>
        </visual>
        <collision>
            <origin xyz="0 0 1.0467685931853374" rpy="0 0 0"/>
            <geometry>
                <box size="2.934987764024701 1.5977946528957296 2.093537186370675" />
            </geometry>
        </collision>
    </link>
    <link name="Leg8">
        <inertial>
            <origin xyz="0 1.3602734368448028 0" rpy="0 0 0"/>
            <mass value="1" />
            <inertia ixx="100" ixy="0" ixz="0" iyy="100" iyz="0" izz="100" />
        </inertial>
        <visual>
            <origin xyz="0 1.3602734368448028 0" rpy="0 0 0"/>
            <geometry>
                <box size="1.1067522996044956 2.7205468736896057 2.1433051154679132" />
            </geometry>
            <material name="Green">
                <color rgba="0 180.0 0.0 1.0"/>
            </material>
        </visual>
        <collision>
            <origin xyz="0 1.3602734368448028 0" rpy="0 0 0"/>
            <geometry>
                <box size="1.1067522996044956 2.7205468736896057 2.1433051154679132" />
            </geometry>
        </collision>
    </link>
    <joint name="Torso_Leg1" type="revolute">
       <parent link="Torso"/>
       <child  link="Leg1"/>
       <origin rpy="0 0 0" xyz="0 0 1.449120993831525" />
     <axis xyz="1 0 0"/>
       <limit effort="0.0" lower="-3.14159" upper="3.14159" velocity="0.0"/>
    </joint>
    <joint name="Leg1_Leg2" type="revolute">
       <parent link="Leg1"/>
       <child  link="Leg2"/>
       <origin rpy="0 0 0" xyz="1.2305532085512572 0 0.5932091821507601" />
     <axis xyz="1 0 0"/>
       <limit effort="0.0" lower="-3.14159" upper="3.14159" velocity="0.0"/>
    </joint>
    <joint name="Leg2_Leg3" type="revolute">
       <parent link="Leg2"/>
       <child  link="Leg3"/>
       <origin rpy="0 0 0" xyz="1.2465833257192929 0 1.177656939445625" />
     <axis xyz="1 0 0"/>
       <limit effort="0.0" lower="-3.14159" upper="3.14159" velocity="0.0"/>
    </joint>
    <joint name="Leg3_Leg4" type="revolute">
       <parent link="Leg3"/>
       <child  link="Leg4"/>
       <origin rpy="0 0 0" xyz="0.6523543923306749 0 1.0288925210588893" />
     <axis xyz="1 0 0"/>
       <limit effort="0.0" lower="-3.14159" upper="3.14159" velocity="0.0"/>
    </joint>
    <joint name="Leg4_Leg5" type="revolute">
       <parent link="Leg4"/>
       <child  link="Leg5"/>
       <origin rpy="0 0 0" xyz="1.4731255376730612 1.2174709394789434 0" />
     <axis xyz="1 0 0"/>
       <limit effort="0.0" lower="-3.14159" upper="3.14159" velocity="0.0"/>
    </joint>
    <joint name="Leg5_Leg6" type="revolute">
       <parent link="Leg5"/>
       <child  link="Leg6"/>
       <origin rpy="0 0 0" xyz="0.7237901769582146 1.327533854632918 0" />
     <axis xyz="1 0 0"/>
       <limit effort="0.0" lower="-3.14159" upper="3.14159" velocity="0.0"/>
    </joint>
    <joint name="Leg6_Leg7" type="revolute">
       <parent link="Leg6"/>
       <child  link="Leg7"/>
       <origin rpy="0 0 0" xyz="0.8302938212609035 0 1.1223526695619859" />
     <axis xyz="1 0 0"/>
       <limit effort="0.0" lower="-3.14159" upper="3.14159" velocity="0.0"/>
    </joint>
    <joint name="Leg7_Leg8" type="revolute">
       <parent link="Leg7"/>
       <child  link="Leg8"/>
       <origin rpy="0 0 0" xyz="0 0.7988973264478648 1.0467685931853374" />
     <axis xyz="1 0 0"/>
       <limit effort="0.0" lower="-3.14159" upper="3.14159" velocity="0.0"/>
    </joint>
</robot>