<robot name = "robot">
    <link name="Torso">
        <inertial>
            <origin xyz="0 0 0.6089925965296197" rpy="0 0 0"/>
            <mass value="1" />
            <inertia ixx="100" ixy="0" ixz="0" iyy="100" iyz="0" izz="100" />
        </inertial>
        <visual>
            <origin xyz="0 0 0.6089925965296197" rpy="0 0 0"/>
            <geometry>
                <box size="2.6052039313544326 2.19466555682674 1.2179851930592394" />
            </geometry>
            <material name="Green">
                <color rgba="0 180.0 0.0 1.0"/>
            </material>
        </visual>
        <collision>
            <origin xyz="0 0 0.6089925965296197" rpy="0 0 0"/>
            <geometry>
                <box size="2.6052039313544326 2.19466555682674 1.2179851930592394" />
            </geometry>
        </collision>
    </link>
    <link name="Leg1">
        <inertial>
            <origin xyz="1.4256790515368731 0 0" rpy="0 0 0"/>
            <mass value="1" />
            <inertia ixx="100" ixy="0" ixz="0" iyy="100" iyz="0" izz="100" />
        </inertial>
        <visual>
            <origin xyz="1.4256790515368731 0 0" rpy="0 0 0"/>
            <geometry>
                <box size="2.8513581030737463 1.6592218647829209 2.1281145369952728" />
            </geometry>
            <material name="Blue">
                <color rgba="0 1.0 1.0 1.0"/>
            </material>
        </visual>
        <collision>
            <origin xyz="1.4256790515368731 0 0" rpy="0 0 0"/>
            <geometry>
                <box size="2.8513581030737463 1.6592218647829209 2.1281145369952728" />
            </geometry>
        </collision>
    </link>
    <link name="Leg2">
        <inertial>
            <origin xyz="1.1846726220996577 0 0" rpy="0 0 0"/>
            <mass value="1" />
            <inertia ixx="100" ixy="0" ixz="0" iyy="100" iyz="0" izz="100" />
        </inertial>
        <visual>
            <origin xyz="1.1846726220996577 0 0" rpy="0 0 0"/>
            <geometry>
                <box size="2.3693452441993155 1.3515432664923839 2.835161861541438" />
            </geometry>
            <material name="Blue">
                <color rgba="0 1.0 1.0 1.0"/>
            </material>
        </visual>
        <collision>
            <origin xyz="1.1846726220996577 0 0" rpy="0 0 0"/>
            <geometry>
                <box size="2.3693452441993155 1.3515432664923839 2.835161861541438" />
            </geometry>
        </collision>
    </link>
    <link name="Leg3">
        <inertial>
            <origin xyz="0 0.5611246591415867 0" rpy="0 0 0"/>
            <mass value="1" />
            <inertia ixx="100" ixy="0" ixz="0" iyy="100" iyz="0" izz="100" />
        </inertial>
        <visual>
            <origin xyz="0 0.5611246591415867 0" rpy="0 0 0"/>
            <geometry>
                <box size="1.7911526137073266 1.1222493182831734 2.389677148904446" />
            </geometry>
            <material name="Green">
                <color rgba="0 180.0 0.0 1.0"/>
            </material>
        </visual>
        <collision>
            <origin xyz="0 0.5611246591415867 0" rpy="0 0 0"/>
            <geometry>
                <box size="1.7911526137073266 1.1222493182831734 2.389677148904446" />
            </geometry>
        </collision>
    </link>
    <link name="Leg4">
        <inertial>
            <origin xyz="1.2304245253415784 0 0" rpy="0 0 0"/>
            <mass value="1" />
            <inertia ixx="100" ixy="0" ixz="0" iyy="100" iyz="0" izz="100" />
        </inertial>
        <visual>
            <origin xyz="1.2304245253415784 0 0" rpy="0 0 0"/>
            <geometry>
                <box size="2.460849050683157 2.8752662814381162 1.3463095750035858" />
            </geometry>
            <material name="Blue">
                <color rgba="0 1.0 1.0 1.0"/>
            </material>
        </visual>
        <collision>
            <origin xyz="1.2304245253415784 0 0" rpy="0 0 0"/>
            <geometry>
                <box size="2.460849050683157 2.8752662814381162 1.3463095750035858" />
            </geometry>
        </collision>
    </link>
    <link name="Leg5">
        <inertial>
            <origin xyz="0 0.6858647819159289 0" rpy="0 0 0"/>
            <mass value="1" />
            <inertia ixx="100" ixy="0" ixz="0" iyy="100" iyz="0" izz="100" />
        </inertial>
        <visual>
            <origin xyz="0 0.6858647819159289 0" rpy="0 0 0"/>
            <geometry>
                <box size="1.5915165024744917 1.3717295638318578 2.020788551164177" />
            </geometry>
            <material name="Blue">
                <color rgba="0 1.0 1.0 1.0"/>
            </material>
        </visual>
        <collision>
            <origin xyz="0 0.6858647819159289 0" rpy="0 0 0"/>
            <geometry>
                <box size="1.5915165024744917 1.3717295638318578 2.020788551164177" />
            </geometry>
        </collision>
    </link>
    <link name="Leg6">
        <inertial>
            <origin xyz="0 1.2823371364297818 0" rpy="0 0 0"/>
            <mass value="1" />
            <inertia ixx="100" ixy="0" ixz="0" iyy="100" iyz="0" izz="100" />
        </inertial>
        <visual>
            <origin xyz="0 1.2823371364297818 0" rpy="0 0 0"/>
            <geometry>
                <box size="2.2126560183686066 2.5646742728595635 1.8153995222937227" />
            </geometry>
            <material name="Green">
                <color rgba="0 180.0 0.0 1.0"/>
            </material>
        </visual>
        <collision>
            <origin xyz="0 1.2823371364297818 0" rpy="0 0 0"/>
            <geometry>
                <box size="2.2126560183686066 2.5646742728595635 1.8153995222937227" />
            </geometry>
        </collision>
    </link>
    <link name="Leg7">
        <inertial>
            <origin xyz="1.4558295729660808 0 0" rpy="0 0 0"/>
            <mass value="1" />
            <inertia ixx="100" ixy="0" ixz="0" iyy="100" iyz="0" izz="100" />
        </inertial>
        <visual>
            <origin xyz="1.4558295729660808 0 0" rpy="0 0 0"/>
            <geometry>
                <box size="2.9116591459321617 1.8689444500055519 2.373835662516436" />
            </geometry>
            <material name="Green">
                <color rgba="0 180.0 0.0 1.0"/>
            </material>
        </visual>
        <collision>
            <origin xyz="1.4558295729660808 0 0" rpy="0 0 0"/>
            <geometry>
                <box size="2.9116591459321617 1.8689444500055519 2.373835662516436" />
            </geometry>
        </collision>
    </link>
    <link name="Leg8">
        <inertial>
            <origin xyz="1.1455474545325646 0 0" rpy="0 0 0"/>
            <mass value="1" />
            <inertia ixx="100" ixy="0" ixz="0" iyy="100" iyz="0" izz="100" />
        </inertial>
        <visual>
            <origin xyz="1.1455474545325646 0 0" rpy="0 0 0"/>
            <geometry>
                <box size="2.291094909065129 1.7334754405285133 2.166884738264731" />
            </geometry>
            <material name="Green">
                <color rgba="0 180.0 0.0 1.0"/>
            </material>
        </visual>
        <collision>
            <origin xyz="1.1455474545325646 0 0" rpy="0 0 0"/>
            <geometry>
                <box size="2.291094909065129 1.7334754405285133 2.166884738264731" />
            </geometry>
        </collision>
    </link>
    <link name="Leg9">
        <inertial>
            <origin xyz="1.1617494839611546 0 0" rpy="0 0 0"/>
            <mass value="1" />
            <inertia ixx="100" ixy="0" ixz="0" iyy="100" iyz="0" izz="100" />
        </inertial>
        <visual>
            <origin xyz="1.1617494839611546 0 0" rpy="0 0 0"/>
            <geometry>
                <box size="2.3234989679223093 1.9367071701269611 2.1407118684617563" />
            </geometry>
            <material name="Blue">
                <color rgba="0 1.0 1.0 1.0"/>
            </material>
        </visual>
        <collision>
            <origin xyz="1.1617494839611546 0 0" rpy="0 0 0"/>
            <geometry>
                <box size="2.3234989679223093 1.9367071701269611 2.1407118684617563" />
            </geometry>
        </collision>
    </link>
    <link name="Leg10">
        <inertial>
            <origin xyz="0.7859554861889109 0 0" rpy="0 0 0"/>
            <mass value="1" />
            <inertia ixx="100" ixy="0" ixz="0" iyy="100" iyz="0" izz="100" />
        </inertial>
        <visual>
            <origin xyz="0.7859554861889109 0 0" rpy="0 0 0"/>
            <geometry>
                <box size="1.5719109723778217 2.066820363940505 2.825263165098967" />
            </geometry>
            <material name="Blue">
                <color rgba="0 1.0 1.0 1.0"/>
            </material>
        </visual>
        <collision>
            <origin xyz="0.7859554861889109 0 0" rpy="0 0 0"/>
            <geometry>
                <box size="1.5719109723778217 2.066820363940505 2.825263165098967" />
            </geometry>
        </collision>
    </link>
    <link name="Leg11">
        <inertial>
            <origin xyz="0 0.8572784897329784 0" rpy="0 0 0"/>
            <mass value="1" />
            <inertia ixx="100" ixy="0" ixz="0" iyy="100" iyz="0" izz="100" />
        </inertial>
        <visual>
            <origin xyz="0 0.8572784897329784 0" rpy="0 0 0"/>
            <geometry>
                <box size="2.034454727091316 1.7145569794659568 1.7208857843106145" />
            </geometry>
            <material name="Green">
                <color rgba="0 180.0 0.0 1.0"/>
            </material>
        </visual>
        <collision>
            <origin xyz="0 0.8572784897329784 0" rpy="0 0 0"/>
            <geometry>
                <box size="2.034454727091316 1.7145569794659568 1.7208857843106145" />
            </geometry>
        </collision>
    </link>
    <link name="Leg12">
        <inertial>
            <origin xyz="1.0576408319832247 0 0" rpy="0 0 0"/>
            <mass value="1" />
            <inertia ixx="100" ixy="0" ixz="0" iyy="100" iyz="0" izz="100" />
        </inertial>
        <visual>
            <origin xyz="1.0576408319832247 0 0" rpy="0 0 0"/>
            <geometry>
                <box size="2.1152816639664493 2.798950365030098 1.5246659077866433" />
            </geometry>
            <material name="Green">
                <color rgba="0 180.0 0.0 1.0"/>
            </material>
        </visual>
        <collision>
            <origin xyz="1.0576408319832247 0 0" rpy="0 0 0"/>
            <geometry>
                <box size="2.1152816639664493 2.798950365030098 1.5246659077866433" />
            </geometry>
        </collision>
    </link>
    <link name="Leg13">
        <inertial>
            <origin xyz="0 0 0.7823725639125337" rpy="0 0 0"/>
            <mass value="1" />
            <inertia ixx="100" ixy="0" ixz="0" iyy="100" iyz="0" izz="100" />
        </inertial>
        <visual>
            <origin xyz="0 0 0.7823725639125337" rpy="0 0 0"/>
            <geometry>
                <box size="2.0806164429102347 2.465426129037609 1.5647451278250675" />
            </geometry>
            <material name="Green">
                <color rgba="0 180.0 0.0 1.0"/>
            </material>
        </visual>
        <collision>
            <origin xyz="0 0 0.7823725639125337" rpy="0 0 0"/>
            <geometry>
                <box size="2.0806164429102347 2.465426129037609 1.5647451278250675" />
            </geometry>
        </collision>
    </link>
    <link name="Leg14">
        <inertial>
            <origin xyz="0 0 1.2667918869998485" rpy="0 0 0"/>
            <mass value="1" />
            <inertia ixx="100" ixy="0" ixz="0" iyy="100" iyz="0" izz="100" />
        </inertial>
        <visual>
            <origin xyz="0 0 1.2667918869998485" rpy="0 0 0"/>
            <geometry>
                <box size="1.5848723517268992 2.720283051805274 2.533583773999697" />
            </geometry>
            <material name="Blue">
                <color rgba="0 1.0 1.0 1.0"/>
            </material>
        </visual>
        <collision>
            <origin xyz="0 0 1.2667918869998485" rpy="0 0 0"/>
            <geometry>
                <box size="1.5848723517268992 2.720283051805274 2.533583773999697" />
            </geometry>
        </collision>
    </link>
    <link name="Leg15">
        <inertial>
            <origin xyz="0 0 1.283376888993811" rpy="0 0 0"/>
            <mass value="1" />
            <inertia ixx="100" ixy="0" ixz="0" iyy="100" iyz="0" izz="100" />
        </inertial>
        <visual>
            <origin xyz="0 0 1.283376888993811" rpy="0 0 0"/>
            <geometry>
                <box size="2.0562455848595125 1.2478322977289364 2.566753777987622" />
            </geometry>
            <material name="Green">
                <color rgba="0 180.0 0.0 1.0"/>
            </material>
        </visual>
        <collision>
            <origin xyz="0 0 1.283376888993811" rpy="0 0 0"/>
            <geometry>
                <box size="2.0562455848595125 1.2478322977289364 2.566753777987622" />
            </geometry>
        </collision>
    </link>
    <link name="Leg16">
        <inertial>
            <origin xyz="0.8541434220967475 0 0" rpy="0 0 0"/>
            <mass value="1" />
            <inertia ixx="100" ixy="0" ixz="0" iyy="100" iyz="0" izz="100" />
        </inertial>
        <visual>
            <origin xyz="0.8541434220967475 0 0" rpy="0 0 0"/>
            <geometry>
                <box size="1.708286844193495 2.147343416993725 1.5839114065712985" />
            </geometry>
            <material name="Blue">
                <color rgba="0 1.0 1.0 1.0"/>
            </material>
        </visual>
        <collision>
            <origin xyz="0.8541434220967475 0 0" rpy="0 0 0"/>
            <geometry>
                <box size="1.708286844193495 2.147343416993725 1.5839114065712985" />
            </geometry>
        </collision>
    </link>
    <link name="Leg17">
        <inertial>
            <origin xyz="0 0 1.105613422345989" rpy="0 0 0"/>
            <mass value="1" />
            <inertia ixx="100" ixy="0" ixz="0" iyy="100" iyz="0" izz="100" />
        </inertial>
        <visual>
            <origin xyz="0 0 1.105613422345989" rpy="0 0 0"/>
            <geometry>
                <box size="2.596357276265163 1.8001112749717574 2.211226844691978" />
            </geometry>
            <material name="Blue">
                <color rgba="0 1.0 1.0 1.0"/>
            </material>
        </visual>
        <collision>
            <origin xyz="0 0 1.105613422345989" rpy="0 0 0"/>
            <geometry>
                <box size="2.596357276265163 1.8001112749717574 2.211226844691978" />
            </geometry>
        </collision>
    </link>
    <link name="Leg18">
        <inertial>
            <origin xyz="0.9880656949303923 0 0" rpy="0 0 0"/>
            <mass value="1" />
            <inertia ixx="100" ixy="0" ixz="0" iyy="100" iyz="0" izz="100" />
        </inertial>
        <visual>
            <origin xyz="0.9880656949303923 0 0" rpy="0 0 0"/>
            <geometry>
                <box size="1.9761313898607846 1.4009607922724177 1.9449642220178456" />
            </geometry>
            <material name="Green">
                <color rgba="0 180.0 0.0 1.0"/>
            </material>
        </visual>
        <collision>
            <origin xyz="0.9880656949303923 0 0" rpy="0 0 0"/>
            <geometry>
                <box size="1.9761313898607846 1.4009607922724177 1.9449642220178456" />
            </geometry>
        </collision>
    </link>
    <link name="Leg19">
        <inertial>
            <origin xyz="0.9651959727487927 0 0" rpy="0 0 0"/>
            <mass value="1" />
            <inertia ixx="100" ixy="0" ixz="0" iyy="100" iyz="0" izz="100" />
        </inertial>
        <visual>
            <origin xyz="0.9651959727487927 0 0" rpy="0 0 0"/>
            <geometry>
                <box size="1.9303919454975853 2.817124670518674 1.7260945893184758" />
            </geometry>
            <material name="Green">
                <color rgba="0 180.0 0.0 1.0"/>
            </material>
        </visual>
        <collision>
            <origin xyz="0.9651959727487927 0 0" rpy="0 0 0"/>
            <geometry>
                <box size="1.9303919454975853 2.817124670518674 1.7260945893184758" />
            </geometry>
        </collision>
    </link>
    <link name="Leg20">
        <inertial>
            <origin xyz="0 0.5748485390601253 0" rpy="0 0 0"/>
            <mass value="1" />
            <inertia ixx="100" ixy="0" ixz="0" iyy="100" iyz="0" izz="100" />
        </inertial>
        <visual>
            <origin xyz="0 0.5748485390601253 0" rpy="0 0 0"/>
            <geometry>
                <box size="2.055471098046805 1.1496970781202507 2.921109826816261" />
            </geometry>
            <material name="Green">
                <color rgba="0 180.0 0.0 1.0"/>
            </material>
        </visual>
        <collision>
            <origin xyz="0 0.5748485390601253 0" rpy="0 0 0"/>
            <geometry>
                <box size="2.055471098046805 1.1496970781202507 2.921109826816261" />
            </geometry>
        </collision>
    </link>
    <link name="Leg21">
        <inertial>
            <origin xyz="1.0373220111266623 0 0" rpy="0 0 0"/>
            <mass value="1" />
            <inertia ixx="100" ixy="0" ixz="0" iyy="100" iyz="0" izz="100" />
        </inertial>
        <visual>
            <origin xyz="1.0373220111266623 0 0" rpy="0 0 0"/>
            <geometry>
                <box size="2.0746440222533247 2.520201632046942 1.2631395427341128" />
            </geometry>
            <material name="Blue">
                <color rgba="0 1.0 1.0 1.0"/>
            </material>
        </visual>
        <collision>
            <origin xyz="1.0373220111266623 0 0" rpy="0 0 0"/>
            <geometry>
                <box size="2.0746440222533247 2.520201632046942 1.2631395427341128" />
            </geometry>
        </collision>
    </link>
    <link name="Leg22">
        <inertial>
            <origin xyz="1.0166961400738397 0 0" rpy="0 0 0"/>
            <mass value="1" />
            <inertia ixx="100" ixy="0" ixz="0" iyy="100" iyz="0" izz="100" />
        </inertial>
        <visual>
            <origin xyz="1.0166961400738397 0 0" rpy="0 0 0"/>
            <geometry>
                <box size="2.0333922801476794 2.516570665650831 1.961679857867914" />
            </geometry>
            <material name="Blue">
                <color rgba="0 1.0 1.0 1.0"/>
            </material>
        </visual>
        <collision>
            <origin xyz="1.0166961400738397 0 0" rpy="0 0 0"/>
            <geometry>
                <box size="2.0333922801476794 2.516570665650831 1.961679857867914" />
            </geometry>
        </collision>
    </link>
    <link name="Leg23">
        <inertial>
            <origin xyz="0 0 0.7030263513777576" rpy="0 0 0"/>
            <mass value="1" />
            <inertia ixx="100" ixy="0" ixz="0" iyy="100" iyz="0" izz="100" />
        </inertial>
        <visual>
            <origin xyz="0 0 0.7030263513777576" rpy="0 0 0"/>
            <geometry>
                <box size="1.148638828585222 1.649434119449738 1.4060527027555152" />
            </geometry>
            <material name="Green">
                <color rgba="0 180.0 0.0 1.0"/>
            </material>
        </visual>
        <collision>
            <origin xyz="0 0 0.7030263513777576" rpy="0 0 0"/>
            <geometry>
                <box size="1.148638828585222 1.649434119449738 1.4060527027555152" />
            </geometry>
        </collision>
    </link>
    <link name="Leg24">
        <inertial>
            <origin xyz="0 1.051737248707329 0" rpy="0 0 0"/>
            <mass value="1" />
            <inertia ixx="100" ixy="0" ixz="0" iyy="100" iyz="0" izz="100" />
        </inertial>
        <visual>
            <origin xyz="0 1.051737248707329 0" rpy="0 0 0"/>
            <geometry>
                <box size="2.0888814704623577 2.103474497414658 2.641289176853336" />
            </geometry>
            <material name="Blue">
                <color rgba="0 1.0 1.0 1.0"/>
            </material>
        </visual>
        <collision>
            <origin xyz="0 1.051737248707329 0" rpy="0 0 0"/>
            <geometry>
                <box size="2.0888814704623577 2.103474497414658 2.641289176853336" />
            </geometry>
        </collision>
    </link>
    <joint name="Torso_Leg1" type="revolute">
       <parent link="Torso"/>
       <child  link="Leg1"/>
       <origin rpy="0 0 0" xyz="1.3026019656772163 0 0.6089925965296197" />
     <axis xyz="1 0 0"/>
       <limit effort="0.0" lower="-3.14159" upper="3.14159" velocity="0.0"/>
    </joint>
    <joint name="Leg1_Leg2" type="revolute">
       <parent link="Leg1"/>
       <child  link="Leg2"/>
       <origin rpy="0 0 0" xyz="2.3693452441993155 0 0" />
     <axis xyz="1 0 0"/>
       <limit effort="0.0" lower="-3.14159" upper="3.14159" velocity="0.0"/>
    </joint>
    <joint name="Leg2_Leg3" type="revolute">
       <parent link="Leg2"/>
       <child  link="Leg3"/>
       <origin rpy="0 0 0" xyz="0 1.1222493182831734 0" />
     <axis xyz="1 0 0"/>
       <limit effort="0.0" lower="-3.14159" upper="3.14159" velocity="0.0"/>
    </joint>
    <joint name="Leg2_Leg4" type="revolute">
       <parent link="Leg2"/>
       <child  link="Leg4"/>
       <origin rpy="0 0 0" xyz="0.8955763068536633 1.1222493182831734 0" />
     <axis xyz="1 0 0"/>
       <limit effort="0.0" lower="-3.14159" upper="3.14159" velocity="0.0"/>
    </joint>
    <joint name="Torso_Leg5" type="revolute">
       <parent link="Torso"/>
       <child  link="Leg5"/>
       <origin rpy="0 0 0" xyz="1.4256790515368731 0.8296109323914604 0" />
     <axis xyz="1 0 0"/>
       <limit effort="0.0" lower="-3.14159" upper="3.14159" velocity="0.0"/>
    </joint>
    <joint name="Leg1_Leg6" type="revolute">
       <parent link="Leg1"/>
       <child  link="Leg6"/>
       <origin rpy="0 0 0" xyz="2.3693452441993155 0.6757716332461919 0" />
     <axis xyz="1 0 0"/>
       <limit effort="0.0" lower="-3.14159" upper="3.14159" velocity="0.0"/>
    </joint>
    <joint name="Leg3_Leg7" type="revolute">
       <parent link="Leg3"/>
       <child  link="Leg7"/>
       <origin rpy="0 0 0" xyz="2.460849050683157 0 0" />
     <axis xyz="1 0 0"/>
       <limit effort="0.0" lower="-3.14159" upper="3.14159" velocity="0.0"/>
    </joint>
    <joint name="Leg5_Leg8" type="revolute">
       <parent link="Leg5"/>
       <child  link="Leg8"/>
       <origin rpy="0 0 0" xyz="1.1063280091843033 1.2823371364297818 0" />
     <axis xyz="1 0 0"/>
       <limit effort="0.0" lower="-3.14159" upper="3.14159" velocity="0.0"/>
    </joint>
    <joint name="Leg8_Leg9" type="revolute">
       <parent link="Leg8"/>
       <child  link="Leg9"/>
       <origin rpy="0 0 0" xyz="2.3234989679223093 0 0" />
     <axis xyz="1 0 0"/>
       <limit effort="0.0" lower="-3.14159" upper="3.14159" velocity="0.0"/>
    </joint>
    <joint name="Leg7_Leg10" type="revolute">
       <parent link="Leg7"/>
       <child  link="Leg10"/>
       <origin rpy="0 0 0" xyz="2.291094909065129 0 0" />
     <axis xyz="1 0 0"/>
       <limit effort="0.0" lower="-3.14159" upper="3.14159" velocity="0.0"/>
    </joint>
    <joint name="Leg5_Leg11" type="revolute">
       <parent link="Leg5"/>
       <child  link="Leg11"/>
       <origin rpy="0 0 0" xyz="1.1063280091843033 2.5646742728595635 0" />
     <axis xyz="1 0 0"/>
       <limit effort="0.0" lower="-3.14159" upper="3.14159" velocity="0.0"/>
    </joint>
    <joint name="Leg9_Leg12" type="revolute">
       <parent link="Leg9"/>
       <child  link="Leg12"/>
       <origin rpy="0 0 0" xyz="1.5719109723778217 0 0" />
     <axis xyz="1 0 0"/>
       <limit effort="0.0" lower="-3.14159" upper="3.14159" velocity="0.0"/>
    </joint>
    <joint name="Torso_Leg13" type="revolute">
       <parent link="Torso"/>
       <child  link="Leg13"/>
       <origin rpy="0 0 0" xyz="1.4256790515368731 0.8296109323914604 1.0640572684976364" />
     <axis xyz="1 0 0"/>
       <limit effort="0.0" lower="-3.14159" upper="3.14159" velocity="0.0"/>
    </joint>
    <joint name="Leg13_Leg14" type="revolute">
       <parent link="Leg13"/>
       <child  link="Leg14"/>
       <origin rpy="0 0 0" xyz="0 0 2.533583773999697" />
     <axis xyz="1 0 0"/>
       <limit effort="0.0" lower="-3.14159" upper="3.14159" velocity="0.0"/>
    </joint>
    <joint name="Leg5_Leg15" type="revolute">
       <parent link="Leg5"/>
       <child  link="Leg15"/>
       <origin rpy="0 0 0" xyz="1.1063280091843033 2.5646742728595635 0.9076997611468614" />
     <axis xyz="1 0 0"/>
       <limit effort="0.0" lower="-3.14159" upper="3.14159" velocity="0.0"/>
    </joint>
    <joint name="Leg11_Leg16" type="revolute">
       <parent link="Leg11"/>
       <child  link="Leg16"/>
       <origin rpy="0 0 0" xyz="2.1152816639664493 0 0" />
     <axis xyz="1 0 0"/>
       <limit effort="0.0" lower="-3.14159" upper="3.14159" velocity="0.0"/>
    </joint>
    <joint name="Leg12_Leg17" type="revolute">
       <parent link="Leg12"/>
       <child  link="Leg17"/>
       <origin rpy="0 0 0" xyz="0 0 1.5647451278250675" />
     <axis xyz="1 0 0"/>
       <limit effort="0.0" lower="-3.14159" upper="3.14159" velocity="0.0"/>
    </joint>
    <joint name="Leg10_Leg18" type="revolute">
       <parent link="Leg10"/>
       <child  link="Leg18"/>
       <origin rpy="0 0 0" xyz="1.017227363545658 0.8572784897329784 0" />
     <axis xyz="1 0 0"/>
       <limit effort="0.0" lower="-3.14159" upper="3.14159" velocity="0.0"/>
    </joint>
    <joint name="Leg12_Leg19" type="revolute">
       <parent link="Leg12"/>
       <child  link="Leg19"/>
       <origin rpy="0 0 0" xyz="1.0403082214551174 0 1.5647451278250675" />
     <axis xyz="1 0 0"/>
       <limit effort="0.0" lower="-3.14159" upper="3.14159" velocity="0.0"/>
    </joint>
    <joint name="Leg16_Leg20" type="revolute">
       <parent link="Leg16"/>
       <child  link="Leg20"/>
       <origin rpy="0 0 0" xyz="0 0.9000556374858787 1.105613422345989" />
     <axis xyz="1 0 0"/>
       <limit effort="0.0" lower="-3.14159" upper="3.14159" velocity="0.0"/>
    </joint>
    <joint name="Leg20_Leg21" type="revolute">
       <parent link="Leg20"/>
       <child  link="Leg21"/>
       <origin rpy="0 0 0" xyz="2.0746440222533247 0 0" />
     <axis xyz="1 0 0"/>
       <limit effort="0.0" lower="-3.14159" upper="3.14159" velocity="0.0"/>
    </joint>
    <joint name="Leg15_Leg22" type="revolute">
       <parent link="Leg15"/>
       <child  link="Leg22"/>
       <origin rpy="0 0 0" xyz="1.708286844193495 0 0" />
     <axis xyz="1 0 0"/>
       <limit effort="0.0" lower="-3.14159" upper="3.14159" velocity="0.0"/>
    </joint>
    <joint name="Leg9_Leg23" type="revolute">
       <parent link="Leg9"/>
       <child  link="Leg23"/>
       <origin rpy="0 0 0" xyz="1.5719109723778217 0 1.4126315825494835" />
     <axis xyz="1 0 0"/>
       <limit effort="0.0" lower="-3.14159" upper="3.14159" velocity="0.0"/>
    </joint>
    <joint name="Leg20_Leg24" type="revolute">
       <parent link="Leg20"/>
       <child  link="Leg24"/>
       <origin rpy="0 0 0" xyz="2.0746440222533247 1.260100816023471 0" />
     <axis xyz="1 0 0"/>
       <limit effort="0.0" lower="-3.14159" upper="3.14159" velocity="0.0"/>
    </joint>
</robot>