<robot name = "robot">
    <link name="Torso">
        <inertial>
            <origin xyz="0 0 1.1867789843287269" rpy="0 0 0"/>
            <mass value="1" />
            <inertia ixx="100" ixy="0" ixz="0" iyy="100" iyz="0" izz="100" />
        </inertial>
        <visual>
            <origin xyz="0 0 1.1867789843287269" rpy="0 0 0"/>
            <geometry>
                <box size="1.7419689307138047 1.1547700332525388 2.3735579686574537" />
            </geometry>
            <material name="Green">
                <color rgba="0 180.0 0.0 1.0"/>
            </material>
        </visual>
        <collision>
            <origin xyz="0 0 1.1867789843287269" rpy="0 0 0"/>
            <geometry>
                <box size="1.7419689307138047 1.1547700332525388 2.3735579686574537" />
            </geometry>
        </collision>
    </link>
    <link name="Leg1">
        <inertial>
            <origin xyz="0 0 1.040889117026067" rpy="0 0 0"/>
            <mass value="1" />
            <inertia ixx="100" ixy="0" ixz="0" iyy="100" iyz="0" izz="100" />
        </inertial>
        <visual>
            <origin xyz="0 0 1.040889117026067" rpy="0 0 0"/>
            <geometry>
                <box size="1.1577966359069465 2.2378803387615647 2.081778234052134" />
            </geometry>
            <material name="Blue">
                <color rgba="0 1.0 1.0 1.0"/>
            </material>
        </visual>
        <collision>
            <origin xyz="0 0 1.040889117026067" rpy="0 0 0"/>
            <geometry>
                <box size="1.1577966359069465 2.2378803387615647 2.081778234052134" />
            </geometry>
        </collision>
    </link>
    <link name="Leg2">
        <inertial>
            <origin xyz="0 0.6826225266988829 0" rpy="0 0 0"/>
            <mass value="1" />
            <inertia ixx="100" ixy="0" ixz="0" iyy="100" iyz="0" izz="100" />
        </inertial>
        <visual>
            <origin xyz="0 0.6826225266988829 0" rpy="0 0 0"/>
            <geometry>
                <box size="1.7549272478681293 1.3652450533977658 2.15095599804365" />
            </geometry>
            <material name="Blue">
                <color rgba="0 1.0 1.0 1.0"/>
            </material>
        </visual>
        <collision>
            <origin xyz="0 0.6826225266988829 0" rpy="0 0 0"/>
            <geometry>
                <box size="1.7549272478681293 1.3652450533977658 2.15095599804365" />
            </geometry>
        </collision>
    </link>
    <link name="Leg3">
        <inertial>
            <origin xyz="0 1.1608967834314952 0" rpy="0 0 0"/>
            <mass value="1" />
            <inertia ixx="100" ixy="0" ixz="0" iyy="100" iyz="0" izz="100" />
        </inertial>
        <visual>
            <origin xyz="0 1.1608967834314952 0" rpy="0 0 0"/>
            <geometry>
                <box size="2.923735700690637 2.3217935668629903 2.4936939453546945" />
            </geometry>
            <material name="Green">
                <color rgba="0 180.0 0.0 1.0"/>
            </material>
        </visual>
        <collision>
            <origin xyz="0 1.1608967834314952 0" rpy="0 0 0"/>
            <geometry>
                <box size="2.923735700690637 2.3217935668629903 2.4936939453546945" />
            </geometry>
        </collision>
    </link>
    <link name="Leg4">
        <inertial>
            <origin xyz="1.0786812080456771 0 0" rpy="0 0 0"/>
            <mass value="1" />
            <inertia ixx="100" ixy="0" ixz="0" iyy="100" iyz="0" izz="100" />
        </inertial>
        <visual>
            <origin xyz="1.0786812080456771 0 0" rpy="0 0 0"/>
            <geometry>
                <box size="2.1573624160913543 1.3059790137876128 1.261721715809145" />
            </geometry>
            <material name="Blue">
                <color rgba="0 1.0 1.0 1.0"/>
            </material>
        </visual>
        <collision>
            <origin xyz="1.0786812080456771 0 0" rpy="0 0 0"/>
            <geometry>
                <box size="2.1573624160913543 1.3059790137876128 1.261721715809145" />
            </geometry>
        </collision>
    </link>
    <link name="Leg5">
        <inertial>
            <origin xyz="1.2702869017469185 0 0" rpy="0 0 0"/>
            <mass value="1" />
            <inertia ixx="100" ixy="0" ixz="0" iyy="100" iyz="0" izz="100" />
        </inertial>
        <visual>
            <origin xyz="1.2702869017469185 0 0" rpy="0 0 0"/>
            <geometry>
                <box size="2.540573803493837 1.0447488580689903 2.982723170692063" />
            </geometry>
            <material name="Blue">
                <color rgba="0 1.0 1.0 1.0"/>
            </material>
        </visual>
        <collision>
            <origin xyz="1.2702869017469185 0 0" rpy="0 0 0"/>
            <geometry>
                <box size="2.540573803493837 1.0447488580689903 2.982723170692063" />
            </geometry>
        </collision>
    </link>
    <link name="Leg6">
        <inertial>
            <origin xyz="0 0 1.1628348777391846" rpy="0 0 0"/>
            <mass value="1" />
            <inertia ixx="100" ixy="0" ixz="0" iyy="100" iyz="0" izz="100" />
        </inertial>
        <visual>
            <origin xyz="0 0 1.1628348777391846" rpy="0 0 0"/>
            <geometry>
                <box size="2.167781420321313 2.7280150577450875 2.325669755478369" />
            </geometry>
            <material name="Green">
                <color rgba="0 180.0 0.0 1.0"/>
            </material>
        </visual>
        <collision>
            <origin xyz="0 0 1.1628348777391846" rpy="0 0 0"/>
            <geometry>
                <box size="2.167781420321313 2.7280150577450875 2.325669755478369" />
            </geometry>
        </collision>
    </link>
    <link name="Leg7">
        <inertial>
            <origin xyz="0 0 1.4209303248140603" rpy="0 0 0"/>
            <mass value="1" />
            <inertia ixx="100" ixy="0" ixz="0" iyy="100" iyz="0" izz="100" />
        </inertial>
        <visual>
            <origin xyz="0 0 1.4209303248140603" rpy="0 0 0"/>
            <geometry>
                <box size="2.620945100231009 2.797861416797052 2.8418606496281207" />
            </geometry>
            <material name="Green">
                <color rgba="0 180.0 0.0 1.0"/>
            </material>
        </visual>
        <collision>
            <origin xyz="0 0 1.4209303248140603" rpy="0 0 0"/>
            <geometry>
                <box size="2.620945100231009 2.797861416797052 2.8418606496281207" />
            </geometry>
        </collision>
    </link>
    <link name="Leg8">
        <inertial>
            <origin xyz="0 0.8310207659482505 0" rpy="0 0 0"/>
            <mass value="1" />
            <inertia ixx="100" ixy="0" ixz="0" iyy="100" iyz="0" izz="100" />
        </inertial>
        <visual>
            <origin xyz="0 0.8310207659482505 0" rpy="0 0 0"/>
            <geometry>
                <box size="2.4578628140755763 1.662041531896501 1.2579131428311356" />
            </geometry>
            <material name="Blue">
                <color rgba="0 1.0 1.0 1.0"/>
            </material>
        </visual>
        <collision>
            <origin xyz="0 0.8310207659482505 0" rpy="0 0 0"/>
            <geometry>
                <box size="2.4578628140755763 1.662041531896501 1.2579131428311356" />
            </geometry>
        </collision>
    </link>
    <link name="Leg9">
        <inertial>
            <origin xyz="0 0.804483418722411 0" rpy="0 0 0"/>
            <mass value="1" />
            <inertia ixx="100" ixy="0" ixz="0" iyy="100" iyz="0" izz="100" />
        </inertial>
        <visual>
            <origin xyz="0 0.804483418722411 0" rpy="0 0 0"/>
            <geometry>
                <box size="1.740012136842408 1.608966837444822 2.643783599461967" />
            </geometry>
            <material name="Blue">
                <color rgba="0 1.0 1.0 1.0"/>
            </material>
        </visual>
        <collision>
            <origin xyz="0 0.804483418722411 0" rpy="0 0 0"/>
            <geometry>
                <box size="1.740012136842408 1.608966837444822 2.643783599461967" />
            </geometry>
        </collision>
    </link>
    <link name="Leg10">
        <inertial>
            <origin xyz="1.207499487381869 0 0" rpy="0 0 0"/>
            <mass value="1" />
            <inertia ixx="100" ixy="0" ixz="0" iyy="100" iyz="0" izz="100" />
        </inertial>
        <visual>
            <origin xyz="1.207499487381869 0 0" rpy="0 0 0"/>
            <geometry>
                <box size="2.414998974763738 1.4349598516902322 1.6717274702947738" />
            </geometry>
            <material name="Blue">
                <color rgba="0 1.0 1.0 1.0"/>
            </material>
        </visual>
        <collision>
            <origin xyz="1.207499487381869 0 0" rpy="0 0 0"/>
            <geometry>
                <box size="2.414998974763738 1.4349598516902322 1.6717274702947738" />
            </geometry>
        </collision>
    </link>
    <link name="Leg11">
        <inertial>
            <origin xyz="0 0.7961302465910035 0" rpy="0 0 0"/>
            <mass value="1" />
            <inertia ixx="100" ixy="0" ixz="0" iyy="100" iyz="0" izz="100" />
        </inertial>
        <visual>
            <origin xyz="0 0.7961302465910035 0" rpy="0 0 0"/>
            <geometry>
                <box size="2.1340577169242625 1.592260493182007 2.8723583493007383" />
            </geometry>
            <material name="Green">
                <color rgba="0 180.0 0.0 1.0"/>
            </material>
        </visual>
        <collision>
            <origin xyz="0 0.7961302465910035 0" rpy="0 0 0"/>
            <geometry>
                <box size="2.1340577169242625 1.592260493182007 2.8723583493007383" />
            </geometry>
        </collision>
    </link>
    <link name="Leg12">
        <inertial>
            <origin xyz="0 1.3974630437121336 0" rpy="0 0 0"/>
            <mass value="1" />
            <inertia ixx="100" ixy="0" ixz="0" iyy="100" iyz="0" izz="100" />
        </inertial>
        <visual>
            <origin xyz="0 1.3974630437121336 0" rpy="0 0 0"/>
            <geometry>
                <box size="2.0948183001642398 2.794926087424267 2.631103843956491" />
            </geometry>
            <material name="Blue">
                <color rgba="0 1.0 1.0 1.0"/>
            </material>
        </visual>
        <collision>
            <origin xyz="0 1.3974630437121336 0" rpy="0 0 0"/>
            <geometry>
                <box size="2.0948183001642398 2.794926087424267 2.631103843956491" />
            </geometry>
        </collision>
    </link>
    <link name="Leg13">
        <inertial>
            <origin xyz="0 1.3775503279539831 0" rpy="0 0 0"/>
            <mass value="1" />
            <inertia ixx="100" ixy="0" ixz="0" iyy="100" iyz="0" izz="100" />
        </inertial>
        <visual>
            <origin xyz="0 1.3775503279539831 0" rpy="0 0 0"/>
            <geometry>
                <box size="2.047554402199075 2.7551006559079663 2.0921783286508617" />
            </geometry>
            <material name="Blue">
                <color rgba="0 1.0 1.0 1.0"/>
            </material>
        </visual>
        <collision>
            <origin xyz="0 1.3775503279539831 0" rpy="0 0 0"/>
            <geometry>
                <box size="2.047554402199075 2.7551006559079663 2.0921783286508617" />
            </geometry>
        </collision>
    </link>
    <link name="Leg14">
        <inertial>
            <origin xyz="0.5286819227401371 0 0" rpy="0 0 0"/>
            <mass value="1" />
            <inertia ixx="100" ixy="0" ixz="0" iyy="100" iyz="0" izz="100" />
        </inertial>
        <visual>
            <origin xyz="0.5286819227401371 0 0" rpy="0 0 0"/>
            <geometry>
                <box size="1.0573638454802743 1.081456259370604 1.9316694542210604" />
            </geometry>
            <material name="Green">
                <color rgba="0 180.0 0.0 1.0"/>
            </material>
        </visual>
        <collision>
            <origin xyz="0.5286819227401371 0 0" rpy="0 0 0"/>
            <geometry>
                <box size="1.0573638454802743 1.081456259370604 1.9316694542210604" />
            </geometry>
        </collision>
    </link>
    <link name="Leg15">
        <inertial>
            <origin xyz="0 0.9691636991080488 0" rpy="0 0 0"/>
            <mass value="1" />
            <inertia ixx="100" ixy="0" ixz="0" iyy="100" iyz="0" izz="100" />
        </inertial>
        <visual>
            <origin xyz="0 0.9691636991080488 0" rpy="0 0 0"/>
            <geometry>
                <box size="2.3888128055856708 1.9383273982160976 1.306700813123318" />
            </geometry>
            <material name="Green">
                <color rgba="0 180.0 0.0 1.0"/>
            </material>
        </visual>
        <collision>
            <origin xyz="0 0.9691636991080488 0" rpy="0 0 0"/>
            <geometry>
                <box size="2.3888128055856708 1.9383273982160976 1.306700813123318" />
            </geometry>
        </collision>
    </link>
    <link name="Leg16">
        <inertial>
            <origin xyz="0.7239236205813211 0 0" rpy="0 0 0"/>
            <mass value="1" />
            <inertia ixx="100" ixy="0" ixz="0" iyy="100" iyz="0" izz="100" />
        </inertial>
        <visual>
            <origin xyz="0.7239236205813211 0 0" rpy="0 0 0"/>
            <geometry>
                <box size="1.4478472411626422 2.8334882329884845 1.5014891879561916" />
            </geometry>
            <material name="Blue">
                <color rgba="0 1.0 1.0 1.0"/>
            </material>
        </visual>
        <collision>
            <origin xyz="0.7239236205813211 0 0" rpy="0 0 0"/>
            <geometry>
                <box size="1.4478472411626422 2.8334882329884845 1.5014891879561916" />
            </geometry>
        </collision>
    </link>
    <link name="Leg17">
        <inertial>
            <origin xyz="0 1.155024054267336 0" rpy="0 0 0"/>
            <mass value="1" />
            <inertia ixx="100" ixy="0" ixz="0" iyy="100" iyz="0" izz="100" />
        </inertial>
        <visual>
            <origin xyz="0 1.155024054267336 0" rpy="0 0 0"/>
            <geometry>
                <box size="2.745425571357848 2.310048108534672 1.8188724134726537" />
            </geometry>
            <material name="Green">
                <color rgba="0 180.0 0.0 1.0"/>
            </material>
        </visual>
        <collision>
            <origin xyz="0 1.155024054267336 0" rpy="0 0 0"/>
            <geometry>
                <box size="2.745425571357848 2.310048108534672 1.8188724134726537" />
            </geometry>
        </collision>
    </link>
    <link name="Leg18">
        <inertial>
            <origin xyz="0 0 0.7934661730881324" rpy="0 0 0"/>
            <mass value="1" />
            <inertia ixx="100" ixy="0" ixz="0" iyy="100" iyz="0" izz="100" />
        </inertial>
        <visual>
            <origin xyz="0 0 0.7934661730881324" rpy="0 0 0"/>
            <geometry>
                <box size="1.3030400883049433 2.8976553873915005 1.5869323461762648" />
            </geometry>
            <material name="Green">
                <color rgba="0 180.0 0.0 1.0"/>
            </material>
        </visual>
        <collision>
            <origin xyz="0 0 0.7934661730881324" rpy="0 0 0"/>
            <geometry>
                <box size="1.3030400883049433 2.8976553873915005 1.5869323461762648" />
            </geometry>
        </collision>
    </link>
    <link name="Leg19">
        <inertial>
            <origin xyz="0 0 1.0800280044498236" rpy="0 0 0"/>
            <mass value="1" />
            <inertia ixx="100" ixy="0" ixz="0" iyy="100" iyz="0" izz="100" />
        </inertial>
        <visual>
            <origin xyz="0 0 1.0800280044498236" rpy="0 0 0"/>
            <geometry>
                <box size="2.5454026030373633 2.199772674060891 2.160056008899647" />
            </geometry>
            <material name="Green">
                <color rgba="0 180.0 0.0 1.0"/>
            </material>
        </visual>
        <collision>
            <origin xyz="0 0 1.0800280044498236" rpy="0 0 0"/>
            <geometry>
                <box size="2.5454026030373633 2.199772674060891 2.160056008899647" />
            </geometry>
        </collision>
    </link>
    <link name="Leg20">
        <inertial>
            <origin xyz="0 0 1.1098706568999925" rpy="0 0 0"/>
            <mass value="1" />
            <inertia ixx="100" ixy="0" ixz="0" iyy="100" iyz="0" izz="100" />
        </inertial>
        <visual>
            <origin xyz="0 0 1.1098706568999925" rpy="0 0 0"/>
            <geometry>
                <box size="2.287324961102742 2.389246206315632 2.219741313799985" />
            </geometry>
            <material name="Blue">
                <color rgba="0 1.0 1.0 1.0"/>
            </material>
        </visual>
        <collision>
            <origin xyz="0 0 1.1098706568999925" rpy="0 0 0"/>
            <geometry>
                <box size="2.287324961102742 2.389246206315632 2.219741313799985" />
            </geometry>
        </collision>
    </link>
    <link name="Leg21">
        <inertial>
            <origin xyz="0 1.0224273441853162 0" rpy="0 0 0"/>
            <mass value="1" />
            <inertia ixx="100" ixy="0" ixz="0" iyy="100" iyz="0" izz="100" />
        </inertial>
        <visual>
            <origin xyz="0 1.0224273441853162 0" rpy="0 0 0"/>
            <geometry>
                <box size="2.2916190797603586 2.0448546883706324 2.7321633826391443" />
            </geometry>
            <material name="Blue">
                <color rgba="0 1.0 1.0 1.0"/>
            </material>
        </visual>
        <collision>
            <origin xyz="0 1.0224273441853162 0" rpy="0 0 0"/>
            <geometry>
                <box size="2.2916190797603586 2.0448546883706324 2.7321633826391443" />
            </geometry>
        </collision>
    </link>
    <link name="Leg22">
        <inertial>
            <origin xyz="0 1.0393758832102353 0" rpy="0 0 0"/>
            <mass value="1" />
            <inertia ixx="100" ixy="0" ixz="0" iyy="100" iyz="0" izz="100" />
        </inertial>
        <visual>
            <origin xyz="0 1.0393758832102353 0" rpy="0 0 0"/>
            <geometry>
                <box size="2.312130266718006 2.0787517664204707 2.7965147626855806" />
            </geometry>
            <material name="Green">
                <color rgba="0 180.0 0.0 1.0"/>
            </material>
        </visual>
        <collision>
            <origin xyz="0 1.0393758832102353 0" rpy="0 0 0"/>
            <geometry>
                <box size="2.312130266718006 2.0787517664204707 2.7965147626855806" />
            </geometry>
        </collision>
    </link>
    <link name="Leg23">
        <inertial>
            <origin xyz="0 0 0.5308141659649173" rpy="0 0 0"/>
            <mass value="1" />
            <inertia ixx="100" ixy="0" ixz="0" iyy="100" iyz="0" izz="100" />
        </inertial>
        <visual>
            <origin xyz="0 0 0.5308141659649173" rpy="0 0 0"/>
            <geometry>
                <box size="1.7821732686419212 1.185577920913479 1.0616283319298345" />
            </geometry>
            <material name="Blue">
                <color rgba="0 1.0 1.0 1.0"/>
            </material>
        </visual>
        <collision>
            <origin xyz="0 0 0.5308141659649173" rpy="0 0 0"/>
            <geometry>
                <box size="1.7821732686419212 1.185577920913479 1.0616283319298345" />
            </geometry>
        </collision>
    </link>
    <link name="Leg24">
        <inertial>
            <origin xyz="1.335381308352396 0 0" rpy="0 0 0"/>
            <mass value="1" />
            <inertia ixx="100" ixy="0" ixz="0" iyy="100" iyz="0" izz="100" />
        </inertial>
        <visual>
            <origin xyz="1.335381308352396 0 0" rpy="0 0 0"/>
            <geometry>
                <box size="2.670762616704792 2.595025719827432 2.3189671703726527" />
            </geometry>
            <material name="Blue">
                <color rgba="0 1.0 1.0 1.0"/>
            </material>
        </visual>
        <collision>
            <origin xyz="1.335381308352396 0 0" rpy="0 0 0"/>
            <geometry>
                <box size="2.670762616704792 2.595025719827432 2.3189671703726527" />
            </geometry>
        </collision>
    </link>
    <link name="Leg25">
        <inertial>
            <origin xyz="0 0 1.2573564346299553" rpy="0 0 0"/>
            <mass value="1" />
            <inertia ixx="100" ixy="0" ixz="0" iyy="100" iyz="0" izz="100" />
        </inertial>
        <visual>
            <origin xyz="0 0 1.2573564346299553" rpy="0 0 0"/>
            <geometry>
                <box size="1.7989428259514488 2.3576309203569625 2.5147128692599106" />
            </geometry>
            <material name="Blue">
                <color rgba="0 1.0 1.0 1.0"/>
            </material>
        </visual>
        <collision>
            <origin xyz="0 0 1.2573564346299553" rpy="0 0 0"/>
            <geometry>
                <box size="1.7989428259514488 2.3576309203569625 2.5147128692599106" />
            </geometry>
        </collision>
    </link>
    <joint name="Torso_Leg1" type="revolute">
       <parent link="Torso"/>
       <child  link="Leg1"/>
       <origin rpy="0 0 0" xyz="0 0 2.3735579686574537" />
     <axis xyz="1 0 0"/>
       <limit effort="0.0" lower="-3.14159" upper="3.14159" velocity="0.0"/>
    </joint>
    <joint name="Torso_Leg2" type="revolute">
       <parent link="Torso"/>
       <child  link="Leg2"/>
       <origin rpy="0 0 0" xyz="0 1.1189401693807823 1.040889117026067" />
     <axis xyz="1 0 0"/>
       <limit effort="0.0" lower="-3.14159" upper="3.14159" velocity="0.0"/>
    </joint>
    <joint name="Leg1_Leg3" type="revolute">
       <parent link="Leg1"/>
       <child  link="Leg3"/>
       <origin rpy="0 0 0" xyz="0 1.3652450533977658 0" />
     <axis xyz="1 0 0"/>
       <limit effort="0.0" lower="-3.14159" upper="3.14159" velocity="0.0"/>
    </joint>
    <joint name="Leg3_Leg4" type="revolute">
       <parent link="Leg3"/>
       <child  link="Leg4"/>
       <origin rpy="0 0 0" xyz="2.1573624160913543 0 0" />
     <axis xyz="1 0 0"/>
       <limit effort="0.0" lower="-3.14159" upper="3.14159" velocity="0.0"/>
    </joint>
    <joint name="Leg4_Leg5" type="revolute">
       <parent link="Leg4"/>
       <child  link="Leg5"/>
       <origin rpy="0 0 0" xyz="2.540573803493837 0 0" />
     <axis xyz="1 0 0"/>
       <limit effort="0.0" lower="-3.14159" upper="3.14159" velocity="0.0"/>
    </joint>
    <joint name="Leg4_Leg6" type="revolute">
       <parent link="Leg4"/>
       <child  link="Leg6"/>
       <origin rpy="0 0 0" xyz="2.540573803493837 0 1.4913615853460316" />
     <axis xyz="1 0 0"/>
       <limit effort="0.0" lower="-3.14159" upper="3.14159" velocity="0.0"/>
    </joint>
    <joint name="Leg3_Leg7" type="revolute">
       <parent link="Leg3"/>
       <child  link="Leg7"/>
       <origin rpy="0 0 0" xyz="2.1573624160913543 0 0.6308608579045725" />
     <axis xyz="1 0 0"/>
       <limit effort="0.0" lower="-3.14159" upper="3.14159" velocity="0.0"/>
    </joint>
    <joint name="Leg7_Leg8" type="revolute">
       <parent link="Leg7"/>
       <child  link="Leg8"/>
       <origin rpy="0 0 0" xyz="0 1.662041531896501 0" />
     <axis xyz="1 0 0"/>
       <limit effort="0.0" lower="-3.14159" upper="3.14159" velocity="0.0"/>
    </joint>
    <joint name="Leg4_Leg9" type="revolute">
       <parent link="Leg4"/>
       <child  link="Leg9"/>
       <origin rpy="0 0 0" xyz="2.540573803493837 0.5223744290344952 1.4913615853460316" />
     <axis xyz="1 0 0"/>
       <limit effort="0.0" lower="-3.14159" upper="3.14159" velocity="0.0"/>
    </joint>
    <joint name="Leg1_Leg10" type="revolute">
       <parent link="Leg1"/>
       <child  link="Leg10"/>
       <origin rpy="0 0 0" xyz="0.8774636239340646 1.3652450533977658 0" />
     <axis xyz="1 0 0"/>
       <limit effort="0.0" lower="-3.14159" upper="3.14159" velocity="0.0"/>
    </joint>
    <joint name="Leg2_Leg11" type="revolute">
       <parent link="Leg2"/>
       <child  link="Leg11"/>
       <origin rpy="0 0 0" xyz="0 2.3217935668629903 0" />
     <axis xyz="1 0 0"/>
       <limit effort="0.0" lower="-3.14159" upper="3.14159" velocity="0.0"/>
    </joint>
    <joint name="Leg9_Leg12" type="revolute">
       <parent link="Leg9"/>
       <child  link="Leg12"/>
       <origin rpy="0 0 0" xyz="1.207499487381869 0.7174799258451161 0" />
     <axis xyz="1 0 0"/>
       <limit effort="0.0" lower="-3.14159" upper="3.14159" velocity="0.0"/>
    </joint>
    <joint name="Leg3_Leg13" type="revolute">
       <parent link="Leg3"/>
       <child  link="Leg13"/>
       <origin rpy="0 0 0" xyz="2.1573624160913543 0.6529895068938064 0.6308608579045725" />
     <axis xyz="1 0 0"/>
       <limit effort="0.0" lower="-3.14159" upper="3.14159" velocity="0.0"/>
    </joint>
    <joint name="Leg8_Leg14" type="revolute">
       <parent link="Leg8"/>
       <child  link="Leg14"/>
       <origin rpy="0 0 0" xyz="0.870006068421204 0.804483418722411 0" />
     <axis xyz="1 0 0"/>
       <limit effort="0.0" lower="-3.14159" upper="3.14159" velocity="0.0"/>
    </joint>
    <joint name="Leg13_Leg15" type="revolute">
       <parent link="Leg13"/>
       <child  link="Leg15"/>
       <origin rpy="0 0 0" xyz="0.5286819227401371 0.540728129685302 0" />
     <axis xyz="1 0 0"/>
       <limit effort="0.0" lower="-3.14159" upper="3.14159" velocity="0.0"/>
    </joint>
    <joint name="Leg5_Leg16" type="revolute">
       <parent link="Leg5"/>
       <child  link="Leg16"/>
       <origin rpy="0 0 0" xyz="1.0838907101606565 0 1.1628348777391846" />
     <axis xyz="1 0 0"/>
       <limit effort="0.0" lower="-3.14159" upper="3.14159" velocity="0.0"/>
    </joint>
    <joint name="Leg11_Leg17" type="revolute">
       <parent link="Leg11"/>
       <child  link="Leg17"/>
       <origin rpy="0 0 0" xyz="0 2.794926087424267 0" />
     <axis xyz="1 0 0"/>
       <limit effort="0.0" lower="-3.14159" upper="3.14159" velocity="0.0"/>
    </joint>
    <joint name="Leg9_Leg18" type="revolute">
       <parent link="Leg9"/>
       <child  link="Leg18"/>
       <origin rpy="0 0 0" xyz="1.207499487381869 0.7174799258451161 0.8358637351473869" />
     <axis xyz="1 0 0"/>
       <limit effort="0.0" lower="-3.14159" upper="3.14159" velocity="0.0"/>
    </joint>
    <joint name="Leg1_Leg19" type="revolute">
       <parent link="Leg1"/>
       <child  link="Leg19"/>
       <origin rpy="0 0 0" xyz="0.8774636239340646 1.3652450533977658 1.075477999021825" />
     <axis xyz="1 0 0"/>
       <limit effort="0.0" lower="-3.14159" upper="3.14159" velocity="0.0"/>
    </joint>
    <joint name="Leg15_Leg20" type="revolute">
       <parent link="Leg15"/>
       <child  link="Leg20"/>
       <origin rpy="0 0 0" xyz="0.7239236205813211 0 0.7507445939780958" />
     <axis xyz="1 0 0"/>
       <limit effort="0.0" lower="-3.14159" upper="3.14159" velocity="0.0"/>
    </joint>
    <joint name="Leg17_Leg21" type="revolute">
       <parent link="Leg17"/>
       <child  link="Leg21"/>
       <origin rpy="0 0 0" xyz="0 1.4488276936957503 0.7934661730881324" />
     <axis xyz="1 0 0"/>
       <limit effort="0.0" lower="-3.14159" upper="3.14159" velocity="0.0"/>
    </joint>
    <joint name="Leg18_Leg22" type="revolute">
       <parent link="Leg18"/>
       <child  link="Leg22"/>
       <origin rpy="0 0 0" xyz="0 1.0998863370304455 1.0800280044498236" />
     <axis xyz="1 0 0"/>
       <limit effort="0.0" lower="-3.14159" upper="3.14159" velocity="0.0"/>
    </joint>
    <joint name="Leg10_Leg23" type="revolute">
       <parent link="Leg10"/>
       <child  link="Leg23"/>
       <origin rpy="0 0 0" xyz="0 0.7961302465910035 1.4361791746503692" />
     <axis xyz="1 0 0"/>
       <limit effort="0.0" lower="-3.14159" upper="3.14159" velocity="0.0"/>
    </joint>
    <joint name="Leg21_Leg24" type="revolute">
       <parent link="Leg21"/>
       <child  link="Leg24"/>
       <origin rpy="0 0 0" xyz="1.156065133359003 1.0393758832102353 0" />
     <axis xyz="1 0 0"/>
       <limit effort="0.0" lower="-3.14159" upper="3.14159" velocity="0.0"/>
    </joint>
    <joint name="Leg2_Leg25" type="revolute">
       <parent link="Leg2"/>
       <child  link="Leg25"/>
       <origin rpy="0 0 0" xyz="0 2.3217935668629903 1.2468469726773472" />
     <axis xyz="1 0 0"/>
       <limit effort="0.0" lower="-3.14159" upper="3.14159" velocity="0.0"/>
    </joint>
</robot>