<robot name = "robot">
    <link name="Torso">
        <inertial>
            <origin xyz="0 0 1.267587467428451" rpy="0 0 0"/>
            <mass value="1" />
            <inertia ixx="100" ixy="0" ixz="0" iyy="100" iyz="0" izz="100" />
        </inertial>
        <visual>
            <origin xyz="0 0 1.267587467428451" rpy="0 0 0"/>
            <geometry>
                <box size="1.1626614392137544 2.252659778147896 2.535174934856902" />
            </geometry>
            <material name="Green">
                <color rgba="0 180.0 0.0 1.0"/>
            </material>
        </visual>
        <collision>
            <origin xyz="0 0 1.267587467428451" rpy="0 0 0"/>
            <geometry>
                <box size="1.1626614392137544 2.252659778147896 2.535174934856902" />
            </geometry>
        </collision>
    </link>
    <link name="Leg1">
        <inertial>
            <origin xyz="1.1560177073465272 0 0" rpy="0 0 0"/>
            <mass value="1" />
            <inertia ixx="100" ixy="0" ixz="0" iyy="100" iyz="0" izz="100" />
        </inertial>
        <visual>
            <origin xyz="1.1560177073465272 0 0" rpy="0 0 0"/>
            <geometry>
                <box size="2.3120354146930544 1.8820394385016 1.7500815972426762" />
            </geometry>
            <material name="Blue">
                <color rgba="0 1.0 1.0 1.0"/>
            </material>
        </visual>
        <collision>
            <origin xyz="1.1560177073465272 0 0" rpy="0 0 0"/>
            <geometry>
                <box size="2.3120354146930544 1.8820394385016 1.7500815972426762" />
            </geometry>
        </collision>
    </link>
    <link name="Leg2">
        <inertial>
            <origin xyz="0 0 0.6147795308929495" rpy="0 0 0"/>
            <mass value="1" />
            <inertia ixx="100" ixy="0" ixz="0" iyy="100" iyz="0" izz="100" />
        </inertial>
        <visual>
            <origin xyz="0 0 0.6147795308929495" rpy="0 0 0"/>
            <geometry>
                <box size="1.005247709871985 2.563218547741567 1.229559061785899" />
            </geometry>
            <material name="Blue">
                <color rgba="0 1.0 1.0 1.0"/>
            </material>
        </visual>
        <collision>
            <origin xyz="0 0 0.6147795308929495" rpy="0 0 0"/>
            <geometry>
                <box size="1.005247709871985 2.563218547741567 1.229559061785899" />
            </geometry>
        </collision>
    </link>
    <link name="Leg3">
        <inertial>
            <origin xyz="0 0 1.1740258459730382" rpy="0 0 0"/>
            <mass value="1" />
            <inertia ixx="100" ixy="0" ixz="0" iyy="100" iyz="0" izz="100" />
        </inertial>
        <visual>
            <origin xyz="0 0 1.1740258459730382" rpy="0 0 0"/>
            <geometry>
                <box size="1.7302538778623366 2.9973405192408795 2.3480516919460763" />
            </geometry>
            <material name="Green">
                <color rgba="0 180.0 0.0 1.0"/>
            </material>
        </visual>
        <collision>
            <origin xyz="0 0 1.1740258459730382" rpy="0 0 0"/>
            <geometry>
                <box size="1.7302538778623366 2.9973405192408795 2.3480516919460763" />
            </geometry>
        </collision>
    </link>
    <link name="Leg4">
        <inertial>
            <origin xyz="0 0 0.8803205985971375" rpy="0 0 0"/>
            <mass value="1" />
            <inertia ixx="100" ixy="0" ixz="0" iyy="100" iyz="0" izz="100" />
        </inertial>
        <visual>
            <origin xyz="0 0 0.8803205985971375" rpy="0 0 0"/>
            <geometry>
                <box size="2.618795667832658 1.2806013348333407 1.760641197194275" />
            </geometry>
            <material name="Blue">
                <color rgba="0 1.0 1.0 1.0"/>
            </material>
        </visual>
        <collision>
            <origin xyz="0 0 0.8803205985971375" rpy="0 0 0"/>
            <geometry>
                <box size="2.618795667832658 1.2806013348333407 1.760641197194275" />
            </geometry>
        </collision>
    </link>
    <link name="Leg5">
        <inertial>
            <origin xyz="0.8743750034796192 0 0" rpy="0 0 0"/>
            <mass value="1" />
            <inertia ixx="100" ixy="0" ixz="0" iyy="100" iyz="0" izz="100" />
        </inertial>
        <visual>
            <origin xyz="0.8743750034796192 0 0" rpy="0 0 0"/>
            <geometry>
                <box size="1.7487500069592383 2.759330101499341 1.0972204834508898" />
            </geometry>
            <material name="Blue">
                <color rgba="0 1.0 1.0 1.0"/>
            </material>
        </visual>
        <collision>
            <origin xyz="0.8743750034796192 0 0" rpy="0 0 0"/>
            <geometry>
                <box size="1.7487500069592383 2.759330101499341 1.0972204834508898" />
            </geometry>
        </collision>
    </link>
    <link name="Leg6">
        <inertial>
            <origin xyz="0.9195996104573525 0 0" rpy="0 0 0"/>
            <mass value="1" />
            <inertia ixx="100" ixy="0" ixz="0" iyy="100" iyz="0" izz="100" />
        </inertial>
        <visual>
            <origin xyz="0.9195996104573525 0 0" rpy="0 0 0"/>
            <geometry>
                <box size="1.839199220914705 1.1736870668962665 2.2616751556347925" />
            </geometry>
            <material name="Blue">
                <color rgba="0 1.0 1.0 1.0"/>
            </material>
        </visual>
        <collision>
            <origin xyz="0.9195996104573525 0 0" rpy="0 0 0"/>
            <geometry>
                <box size="1.839199220914705 1.1736870668962665 2.2616751556347925" />
            </geometry>
        </collision>
    </link>
    <link name="Leg7">
        <inertial>
            <origin xyz="0 0 1.1027153450936547" rpy="0 0 0"/>
            <mass value="1" />
            <inertia ixx="100" ixy="0" ixz="0" iyy="100" iyz="0" izz="100" />
        </inertial>
        <visual>
            <origin xyz="0 0 1.1027153450936547" rpy="0 0 0"/>
            <geometry>
                <box size="1.4489455274089071 1.2351947717836844 2.2054306901873093" />
            </geometry>
            <material name="Blue">
                <color rgba="0 1.0 1.0 1.0"/>
            </material>
        </visual>
        <collision>
            <origin xyz="0 0 1.1027153450936547" rpy="0 0 0"/>
            <geometry>
                <box size="1.4489455274089071 1.2351947717836844 2.2054306901873093" />
            </geometry>
        </collision>
    </link>
    <link name="Leg8">
        <inertial>
            <origin xyz="0 0.8908004310408556 0" rpy="0 0 0"/>
            <mass value="1" />
            <inertia ixx="100" ixy="0" ixz="0" iyy="100" iyz="0" izz="100" />
        </inertial>
        <visual>
            <origin xyz="0 0.8908004310408556 0" rpy="0 0 0"/>
            <geometry>
                <box size="1.2462194264553745 1.7816008620817112 1.6594091235242427" />
            </geometry>
            <material name="Blue">
                <color rgba="0 1.0 1.0 1.0"/>
            </material>
        </visual>
        <collision>
            <origin xyz="0 0.8908004310408556 0" rpy="0 0 0"/>
            <geometry>
                <box size="1.2462194264553745 1.7816008620817112 1.6594091235242427" />
            </geometry>
        </collision>
    </link>
    <link name="Leg9">
        <inertial>
            <origin xyz="0 0 0.9445092307680871" rpy="0 0 0"/>
            <mass value="1" />
            <inertia ixx="100" ixy="0" ixz="0" iyy="100" iyz="0" izz="100" />
        </inertial>
        <visual>
            <origin xyz="0 0 0.9445092307680871" rpy="0 0 0"/>
            <geometry>
                <box size="1.8717404054099853 2.0639230853159853 1.8890184615361743" />
            </geometry>
            <material name="Green">
                <color rgba="0 180.0 0.0 1.0"/>
            </material>
        </visual>
        <collision>
            <origin xyz="0 0 0.9445092307680871" rpy="0 0 0"/>
            <geometry>
                <box size="1.8717404054099853 2.0639230853159853 1.8890184615361743" />
            </geometry>
        </collision>
    </link>
    <link name="Leg10">
        <inertial>
            <origin xyz="0 0 0.9606076542730734" rpy="0 0 0"/>
            <mass value="1" />
            <inertia ixx="100" ixy="0" ixz="0" iyy="100" iyz="0" izz="100" />
        </inertial>
        <visual>
            <origin xyz="0 0 0.9606076542730734" rpy="0 0 0"/>
            <geometry>
                <box size="1.5954367130036484 2.4151486082978564 1.9212153085461467" />
            </geometry>
            <material name="Green">
                <color rgba="0 180.0 0.0 1.0"/>
            </material>
        </visual>
        <collision>
            <origin xyz="0 0 0.9606076542730734" rpy="0 0 0"/>
            <geometry>
                <box size="1.5954367130036484 2.4151486082978564 1.9212153085461467" />
            </geometry>
        </collision>
    </link>
    <link name="Leg11">
        <inertial>
            <origin xyz="1.1915647557433693 0 0" rpy="0 0 0"/>
            <mass value="1" />
            <inertia ixx="100" ixy="0" ixz="0" iyy="100" iyz="0" izz="100" />
        </inertial>
        <visual>
            <origin xyz="1.1915647557433693 0 0" rpy="0 0 0"/>
            <geometry>
                <box size="2.3831295114867386 1.974868290927736 1.3934837298420735" />
            </geometry>
            <material name="Green">
                <color rgba="0 180.0 0.0 1.0"/>
            </material>
        </visual>
        <collision>
            <origin xyz="1.1915647557433693 0 0" rpy="0 0 0"/>
            <geometry>
                <box size="2.3831295114867386 1.974868290927736 1.3934837298420735" />
            </geometry>
        </collision>
    </link>
    <link name="Leg12">
        <inertial>
            <origin xyz="1.4473096087021236 0 0" rpy="0 0 0"/>
            <mass value="1" />
            <inertia ixx="100" ixy="0" ixz="0" iyy="100" iyz="0" izz="100" />
        </inertial>
        <visual>
            <origin xyz="1.4473096087021236 0 0" rpy="0 0 0"/>
            <geometry>
                <box size="2.894619217404247 1.8300114201304976 2.5214632398479377" />
            </geometry>
            <material name="Green">
                <color rgba="0 180.0 0.0 1.0"/>
            </material>
        </visual>
        <collision>
            <origin xyz="1.4473096087021236 0 0" rpy="0 0 0"/>
            <geometry>
                <box size="2.894619217404247 1.8300114201304976 2.5214632398479377" />
            </geometry>
        </collision>
    </link>
    <link name="Leg13">
        <inertial>
            <origin xyz="1.0615700407261843 0 0" rpy="0 0 0"/>
            <mass value="1" />
            <inertia ixx="100" ixy="0" ixz="0" iyy="100" iyz="0" izz="100" />
        </inertial>
        <visual>
            <origin xyz="1.0615700407261843 0 0" rpy="0 0 0"/>
            <geometry>
                <box size="2.1231400814523687 1.3614650888827138 1.685092531277621" />
            </geometry>
            <material name="Blue">
                <color rgba="0 1.0 1.0 1.0"/>
            </material>
        </visual>
        <collision>
            <origin xyz="1.0615700407261843 0 0" rpy="0 0 0"/>
            <geometry>
                <box size="2.1231400814523687 1.3614650888827138 1.685092531277621" />
            </geometry>
        </collision>
    </link>
    <link name="Leg14">
        <inertial>
            <origin xyz="0 0.6208810099719372 0" rpy="0 0 0"/>
            <mass value="1" />
            <inertia ixx="100" ixy="0" ixz="0" iyy="100" iyz="0" izz="100" />
        </inertial>
        <visual>
            <origin xyz="0 0.6208810099719372 0" rpy="0 0 0"/>
            <geometry>
                <box size="1.353442310954969 1.2417620199438744 2.1829020436406124" />
            </geometry>
            <material name="Green">
                <color rgba="0 180.0 0.0 1.0"/>
            </material>
        </visual>
        <collision>
            <origin xyz="0 0.6208810099719372 0" rpy="0 0 0"/>
            <geometry>
                <box size="1.353442310954969 1.2417620199438744 2.1829020436406124" />
            </geometry>
        </collision>
    </link>
    <link name="Leg15">
        <inertial>
            <origin xyz="1.3100576449617232 0 0" rpy="0 0 0"/>
            <mass value="1" />
            <inertia ixx="100" ixy="0" ixz="0" iyy="100" iyz="0" izz="100" />
        </inertial>
        <visual>
            <origin xyz="1.3100576449617232 0 0" rpy="0 0 0"/>
            <geometry>
                <box size="2.6201152899234463 1.0299037372348134 2.758141882833576" />
            </geometry>
            <material name="Green">
                <color rgba="0 180.0 0.0 1.0"/>
            </material>
        </visual>
        <collision>
            <origin xyz="1.3100576449617232 0 0" rpy="0 0 0"/>
            <geometry>
                <box size="2.6201152899234463 1.0299037372348134 2.758141882833576" />
            </geometry>
        </collision>
    </link>
    <link name="Leg16">
        <inertial>
            <origin xyz="0 0 1.2441787481847846" rpy="0 0 0"/>
            <mass value="1" />
            <inertia ixx="100" ixy="0" ixz="0" iyy="100" iyz="0" izz="100" />
        </inertial>
        <visual>
            <origin xyz="0 0 1.2441787481847846" rpy="0 0 0"/>
            <geometry>
                <box size="1.8300220650363817 1.3777915369824607 2.488357496369569" />
            </geometry>
            <material name="Blue">
                <color rgba="0 1.0 1.0 1.0"/>
            </material>
        </visual>
        <collision>
            <origin xyz="0 0 1.2441787481847846" rpy="0 0 0"/>
            <geometry>
                <box size="1.8300220650363817 1.3777915369824607 2.488357496369569" />
            </geometry>
        </collision>
    </link>
    <link name="Leg17">
        <inertial>
            <origin xyz="0.5606975223868277 0 0" rpy="0 0 0"/>
            <mass value="1" />
            <inertia ixx="100" ixy="0" ixz="0" iyy="100" iyz="0" izz="100" />
        </inertial>
        <visual>
            <origin xyz="0.5606975223868277 0 0" rpy="0 0 0"/>
            <geometry>
                <box size="1.1213950447736554 1.258019708605795 1.1334960925379722" />
            </geometry>
            <material name="Green">
                <color rgba="0 180.0 0.0 1.0"/>
            </material>
        </visual>
        <collision>
            <origin xyz="0.5606975223868277 0 0" rpy="0 0 0"/>
            <geometry>
                <box size="1.1213950447736554 1.258019708605795 1.1334960925379722" />
            </geometry>
        </collision>
    </link>
    <link name="Leg18">
        <inertial>
            <origin xyz="0.7898185533480754 0 0" rpy="0 0 0"/>
            <mass value="1" />
            <inertia ixx="100" ixy="0" ixz="0" iyy="100" iyz="0" izz="100" />
        </inertial>
        <visual>
            <origin xyz="0.7898185533480754 0 0" rpy="0 0 0"/>
            <geometry>
                <box size="1.5796371066961508 1.1432405436369164 2.102871009399543" />
            </geometry>
            <material name="Blue">
                <color rgba="0 1.0 1.0 1.0"/>
            </material>
        </visual>
        <collision>
            <origin xyz="0.7898185533480754 0 0" rpy="0 0 0"/>
            <geometry>
                <box size="1.5796371066961508 1.1432405436369164 2.102871009399543" />
            </geometry>
        </collision>
    </link>
    <link name="Leg19">
        <inertial>
            <origin xyz="0 0.7333372272292438 0" rpy="0 0 0"/>
            <mass value="1" />
            <inertia ixx="100" ixy="0" ixz="0" iyy="100" iyz="0" izz="100" />
        </inertial>
        <visual>
            <origin xyz="0 0.7333372272292438 0" rpy="0 0 0"/>
            <geometry>
                <box size="2.813457154494332 1.4666744544584875 2.92291229742344" />
            </geometry>
            <material name="Green">
                <color rgba="0 180.0 0.0 1.0"/>
            </material>
        </visual>
        <collision>
            <origin xyz="0 0.7333372272292438 0" rpy="0 0 0"/>
            <geometry>
                <box size="2.813457154494332 1.4666744544584875 2.92291229742344" />
            </geometry>
        </collision>
    </link>
    <link name="Leg20">
        <inertial>
            <origin xyz="1.2629972062330763 0 0" rpy="0 0 0"/>
            <mass value="1" />
            <inertia ixx="100" ixy="0" ixz="0" iyy="100" iyz="0" izz="100" />
        </inertial>
        <visual>
            <origin xyz="1.2629972062330763 0 0" rpy="0 0 0"/>
            <geometry>
                <box size="2.5259944124661526 1.992364760303776 1.4778631238997517" />
            </geometry>
            <material name="Blue">
                <color rgba="0 1.0 1.0 1.0"/>
            </material>
        </visual>
        <collision>
            <origin xyz="1.2629972062330763 0 0" rpy="0 0 0"/>
            <geometry>
                <box size="2.5259944124661526 1.992364760303776 1.4778631238997517" />
            </geometry>
        </collision>
    </link>
    <link name="Leg21">
        <inertial>
            <origin xyz="0.6141160656644598 0 0" rpy="0 0 0"/>
            <mass value="1" />
            <inertia ixx="100" ixy="0" ixz="0" iyy="100" iyz="0" izz="100" />
        </inertial>
        <visual>
            <origin xyz="0.6141160656644598 0 0" rpy="0 0 0"/>
            <geometry>
                <box size="1.2282321313289195 1.1860527678640065 1.1799625076119584" />
            </geometry>
            <material name="Green">
                <color rgba="0 180.0 0.0 1.0"/>
            </material>
        </visual>
        <collision>
            <origin xyz="0.6141160656644598 0 0" rpy="0 0 0"/>
            <geometry>
                <box size="1.2282321313289195 1.1860527678640065 1.1799625076119584" />
            </geometry>
        </collision>
    </link>
    <link name="Leg22">
        <inertial>
            <origin xyz="0 0 1.137986632447842" rpy="0 0 0"/>
            <mass value="1" />
            <inertia ixx="100" ixy="0" ixz="0" iyy="100" iyz="0" izz="100" />
        </inertial>
        <visual>
            <origin xyz="0 0 1.137986632447842" rpy="0 0 0"/>
            <geometry>
                <box size="1.4060631199714984 2.6834204782435047 2.275973264895684" />
            </geometry>
            <material name="Green">
                <color rgba="0 180.0 0.0 1.0"/>
            </material>
        </visual>
        <collision>
            <origin xyz="0 0 1.137986632447842" rpy="0 0 0"/>
            <geometry>
                <box size="1.4060631199714984 2.6834204782435047 2.275973264895684" />
            </geometry>
        </collision>
    </link>
    <link name="Leg23">
        <inertial>
            <origin xyz="1.1340062824592083 0 0" rpy="0 0 0"/>
            <mass value="1" />
            <inertia ixx="100" ixy="0" ixz="0" iyy="100" iyz="0" izz="100" />
        </inertial>
        <visual>
            <origin xyz="1.1340062824592083 0 0" rpy="0 0 0"/>
            <geometry>
                <box size="2.2680125649184166 2.253684096615334 1.1324881493463943" />
            </geometry>
            <material name="Green">
                <color rgba="0 180.0 0.0 1.0"/>
            </material>
        </visual>
        <collision>
            <origin xyz="1.1340062824592083 0 0" rpy="0 0 0"/>
            <geometry>
                <box size="2.2680125649184166 2.253684096615334 1.1324881493463943" />
            </geometry>
        </collision>
    </link>
    <link name="Leg24">
        <inertial>
            <origin xyz="0 0.5623562012515076 0" rpy="0 0 0"/>
            <mass value="1" />
            <inertia ixx="100" ixy="0" ixz="0" iyy="100" iyz="0" izz="100" />
        </inertial>
        <visual>
            <origin xyz="0 0.5623562012515076 0" rpy="0 0 0"/>
            <geometry>
                <box size="2.008133549702782 1.1247124025030153 2.462262451029937" />
            </geometry>
            <material name="Blue">
                <color rgba="0 1.0 1.0 1.0"/>
            </material>
        </visual>
        <collision>
            <origin xyz="0 0.5623562012515076 0" rpy="0 0 0"/>
            <geometry>
                <box size="2.008133549702782 1.1247124025030153 2.462262451029937" />
            </geometry>
        </collision>
    </link>
    <link name="Leg25">
        <inertial>
            <origin xyz="0 0.9578948245648921 0" rpy="0 0 0"/>
            <mass value="1" />
            <inertia ixx="100" ixy="0" ixz="0" iyy="100" iyz="0" izz="100" />
        </inertial>
        <visual>
            <origin xyz="0 0.9578948245648921 0" rpy="0 0 0"/>
            <geometry>
                <box size="2.776684358848268 1.9157896491297841 2.209120900730502" />
            </geometry>
            <material name="Green">
                <color rgba="0 180.0 0.0 1.0"/>
            </material>
        </visual>
        <collision>
            <origin xyz="0 0.9578948245648921 0" rpy="0 0 0"/>
            <geometry>
                <box size="2.776684358848268 1.9157896491297841 2.209120900730502" />
            </geometry>
        </collision>
    </link>
    <joint name="Torso_Leg1" type="revolute">
       <parent link="Torso"/>
       <child  link="Leg1"/>
       <origin rpy="0 0 0" xyz="0.5813307196068772 0 1.267587467428451" />
     <axis xyz="1 0 0"/>
       <limit effort="0.0" lower="-3.14159" upper="3.14159" velocity="0.0"/>
    </joint>
    <joint name="Leg1_Leg2" type="revolute">
       <parent link="Leg1"/>
       <child  link="Leg2"/>
       <origin rpy="0 0 0" xyz="0 0 1.229559061785899" />
     <axis xyz="1 0 0"/>
       <limit effort="0.0" lower="-3.14159" upper="3.14159" velocity="0.0"/>
    </joint>
    <joint name="Torso_Leg3" type="revolute">
       <parent link="Torso"/>
       <child  link="Leg3"/>
       <origin rpy="0 0 0" xyz="1.1560177073465272 0 0.8750407986213381" />
     <axis xyz="1 0 0"/>
       <limit effort="0.0" lower="-3.14159" upper="3.14159" velocity="0.0"/>
    </joint>
    <joint name="Leg3_Leg4" type="revolute">
       <parent link="Leg3"/>
       <child  link="Leg4"/>
       <origin rpy="0 0 0" xyz="0 0 1.760641197194275" />
     <axis xyz="1 0 0"/>
       <limit effort="0.0" lower="-3.14159" upper="3.14159" velocity="0.0"/>
    </joint>
    <joint name="Leg4_Leg5" type="revolute">
       <parent link="Leg4"/>
       <child  link="Leg5"/>
       <origin rpy="0 0 0" xyz="1.7487500069592383 0 0" />
     <axis xyz="1 0 0"/>
       <limit effort="0.0" lower="-3.14159" upper="3.14159" velocity="0.0"/>
    </joint>
    <joint name="Leg5_Leg6" type="revolute">
       <parent link="Leg5"/>
       <child  link="Leg6"/>
       <origin rpy="0 0 0" xyz="1.839199220914705 0 0" />
     <axis xyz="1 0 0"/>
       <limit effort="0.0" lower="-3.14159" upper="3.14159" velocity="0.0"/>
    </joint>
    <joint name="Leg2_Leg7" type="revolute">
       <parent link="Leg2"/>
       <child  link="Leg7"/>
       <origin rpy="0 0 0" xyz="0 0 2.3480516919460763" />
     <axis xyz="1 0 0"/>
       <limit effort="0.0" lower="-3.14159" upper="3.14159" velocity="0.0"/>
    </joint>
    <joint name="Leg5_Leg8" type="revolute">
       <parent link="Leg5"/>
       <child  link="Leg8"/>
       <origin rpy="0 0 0" xyz="1.839199220914705 0.5868435334481332 0" />
     <axis xyz="1 0 0"/>
       <limit effort="0.0" lower="-3.14159" upper="3.14159" velocity="0.0"/>
    </joint>
    <joint name="Leg7_Leg9" type="revolute">
       <parent link="Leg7"/>
       <child  link="Leg9"/>
       <origin rpy="0 0 0" xyz="0 0.8908004310408556 0.8297045617621214" />
     <axis xyz="1 0 0"/>
       <limit effort="0.0" lower="-3.14159" upper="3.14159" velocity="0.0"/>
    </joint>
    <joint name="Leg6_Leg10" type="revolute">
       <parent link="Leg6"/>
       <child  link="Leg10"/>
       <origin rpy="0 0 0" xyz="0 0 2.2054306901873093" />
     <axis xyz="1 0 0"/>
       <limit effort="0.0" lower="-3.14159" upper="3.14159" velocity="0.0"/>
    </joint>
    <joint name="Leg9_Leg11" type="revolute">
       <parent link="Leg9"/>
       <child  link="Leg11"/>
       <origin rpy="0 0 0" xyz="0.7977183565018242 0 0.9606076542730734" />
     <axis xyz="1 0 0"/>
       <limit effort="0.0" lower="-3.14159" upper="3.14159" velocity="0.0"/>
    </joint>
    <joint name="Leg3_Leg12" type="revolute">
       <parent link="Leg3"/>
       <child  link="Leg12"/>
       <origin rpy="0 0 0" xyz="1.309397833916329 0 1.760641197194275" />
     <axis xyz="1 0 0"/>
       <limit effort="0.0" lower="-3.14159" upper="3.14159" velocity="0.0"/>
    </joint>
    <joint name="Leg2_Leg13" type="revolute">
       <parent link="Leg2"/>
       <child  link="Leg13"/>
       <origin rpy="0 0 0" xyz="0.8651269389311683 0 2.3480516919460763" />
     <axis xyz="1 0 0"/>
       <limit effort="0.0" lower="-3.14159" upper="3.14159" velocity="0.0"/>
    </joint>
    <joint name="Leg8_Leg14" type="revolute">
       <parent link="Leg8"/>
       <child  link="Leg14"/>
       <origin rpy="0 0 0" xyz="0 1.0319615426579927 0.9445092307680871" />
     <axis xyz="1 0 0"/>
       <limit effort="0.0" lower="-3.14159" upper="3.14159" velocity="0.0"/>
    </joint>
    <joint name="Leg13_Leg15" type="revolute">
       <parent link="Leg13"/>
       <child  link="Leg15"/>
       <origin rpy="0 0 0" xyz="0.6767211554774845 0.6208810099719372 0" />
     <axis xyz="1 0 0"/>
       <limit effort="0.0" lower="-3.14159" upper="3.14159" velocity="0.0"/>
    </joint>
    <joint name="Leg12_Leg16" type="revolute">
       <parent link="Leg12"/>
       <child  link="Leg16"/>
       <origin rpy="0 0 0" xyz="1.0615700407261843 0 0.8425462656388105" />
     <axis xyz="1 0 0"/>
       <limit effort="0.0" lower="-3.14159" upper="3.14159" velocity="0.0"/>
    </joint>
    <joint name="Leg12_Leg17" type="revolute">
       <parent link="Leg12"/>
       <child  link="Leg17"/>
       <origin rpy="0 0 0" xyz="2.1231400814523687 0 0.8425462656388105" />
     <axis xyz="1 0 0"/>
       <limit effort="0.0" lower="-3.14159" upper="3.14159" velocity="0.0"/>
    </joint>
    <joint name="Leg16_Leg18" type="revolute">
       <parent link="Leg16"/>
       <child  link="Leg18"/>
       <origin rpy="0 0 0" xyz="1.1213950447736554 0 0" />
     <axis xyz="1 0 0"/>
       <limit effort="0.0" lower="-3.14159" upper="3.14159" velocity="0.0"/>
    </joint>
    <joint name="Leg3_Leg19" type="revolute">
       <parent link="Leg3"/>
       <child  link="Leg19"/>
       <origin rpy="0 0 0" xyz="1.309397833916329 0.6403006674166704 1.760641197194275" />
     <axis xyz="1 0 0"/>
       <limit effort="0.0" lower="-3.14159" upper="3.14159" velocity="0.0"/>
    </joint>
    <joint name="Leg6_Leg20" type="revolute">
       <parent link="Leg6"/>
       <child  link="Leg20"/>
       <origin rpy="0 0 0" xyz="0.7244727637044536 0 2.2054306901873093" />
     <axis xyz="1 0 0"/>
       <limit effort="0.0" lower="-3.14159" upper="3.14159" velocity="0.0"/>
    </joint>
    <joint name="Leg20_Leg21" type="revolute">
       <parent link="Leg20"/>
       <child  link="Leg21"/>
       <origin rpy="0 0 0" xyz="1.2282321313289195 0 0" />
     <axis xyz="1 0 0"/>
       <limit effort="0.0" lower="-3.14159" upper="3.14159" velocity="0.0"/>
    </joint>
    <joint name="Leg8_Leg22" type="revolute">
       <parent link="Leg8"/>
       <child  link="Leg22"/>
       <origin rpy="0 0 0" xyz="0 1.0319615426579927 1.8890184615361743" />
     <axis xyz="1 0 0"/>
       <limit effort="0.0" lower="-3.14159" upper="3.14159" velocity="0.0"/>
    </joint>
    <joint name="Leg17_Leg23" type="revolute">
       <parent link="Leg17"/>
       <child  link="Leg23"/>
       <origin rpy="0 0 0" xyz="1.5796371066961508 0 0" />
     <axis xyz="1 0 0"/>
       <limit effort="0.0" lower="-3.14159" upper="3.14159" velocity="0.0"/>
    </joint>
    <joint name="Leg12_Leg24" type="revolute">
       <parent link="Leg12"/>
       <child  link="Leg24"/>
       <origin rpy="0 0 0" xyz="2.1231400814523687 0.6807325444413569 0.8425462656388105" />
     <axis xyz="1 0 0"/>
       <limit effort="0.0" lower="-3.14159" upper="3.14159" velocity="0.0"/>
    </joint>
    <joint name="Leg23_Leg25" type="revolute">
       <parent link="Leg23"/>
       <child  link="Leg25"/>
       <origin rpy="0 0 0" xyz="0 1.1247124025030153 0" />
     <axis xyz="1 0 0"/>
       <limit effort="0.0" lower="-3.14159" upper="3.14159" velocity="0.0"/>
    </joint>
</robot>