<robot name = "robot">
    <link name="Torso">
        <inertial>
            <origin xyz="0 0 1.3970434966147853" rpy="0 0 0"/>
            <mass value="1" />
            <inertia ixx="100" ixy="0" ixz="0" iyy="100" iyz="0" izz="100" />
        </inertial>
        <visual>
            <origin xyz="0 0 1.3970434966147853" rpy="0 0 0"/>
            <geometry>
                <box size="1.0593244561585458 1.588158294630396 2.7940869932295707" />
            </geometry>
            <material name="Green">
                <color rgba="0 180.0 0.0 1.0"/>
            </material>
        </visual>
        <collision>
            <origin xyz="0 0 1.3970434966147853" rpy="0 0 0"/>
            <geometry>
                <box size="1.0593244561585458 1.588158294630396 2.7940869932295707" />
            </geometry>
        </collision>
    </link>
    <link name="Leg1">
        <inertial>
            <origin xyz="0.9126345355763248 0 0" rpy="0 0 0"/>
            <mass value="1" />
            <inertia ixx="100" ixy="0" ixz="0" iyy="100" iyz="0" izz="100" />
        </inertial>
        <visual>
            <origin xyz="0.9126345355763248 0 0" rpy="0 0 0"/>
            <geometry>
                <box size="1.8252690711526496 1.6648847914132503 1.3539531450801403" />
            </geometry>
            <material name="Green">
                <color rgba="0 180.0 0.0 1.0"/>
            </material>
        </visual>
        <collision>
            <origin xyz="0.9126345355763248 0 0" rpy="0 0 0"/>
            <geometry>
                <box size="1.8252690711526496 1.6648847914132503 1.3539531450801403" />
            </geometry>
        </collision>
    </link>
    <link name="Leg2">
        <inertial>
            <origin xyz="0 0 0.7997263249919409" rpy="0 0 0"/>
            <mass value="1" />
            <inertia ixx="100" ixy="0" ixz="0" iyy="100" iyz="0" izz="100" />
        </inertial>
        <visual>
            <origin xyz="0 0 0.7997263249919409" rpy="0 0 0"/>
            <geometry>
                <box size="2.8335508959121825 1.0829751423490008 1.5994526499838817" />
            </geometry>
            <material name="Blue">
                <color rgba="0 1.0 1.0 1.0"/>
            </material>
        </visual>
        <collision>
            <origin xyz="0 0 0.7997263249919409" rpy="0 0 0"/>
            <geometry>
                <box size="2.8335508959121825 1.0829751423490008 1.5994526499838817" />
            </geometry>
        </collision>
    </link>
    <link name="Leg3">
        <inertial>
            <origin xyz="0.7191768955247004 0 0" rpy="0 0 0"/>
            <mass value="1" />
            <inertia ixx="100" ixy="0" ixz="0" iyy="100" iyz="0" izz="100" />
        </inertial>
        <visual>
            <origin xyz="0.7191768955247004 0 0" rpy="0 0 0"/>
            <geometry>
                <box size="1.4383537910494009 1.4271504640551427 1.0721562717035975" />
            </geometry>
            <material name="Green">
                <color rgba="0 180.0 0.0 1.0"/>
            </material>
        </visual>
        <collision>
            <origin xyz="0.7191768955247004 0 0" rpy="0 0 0"/>
            <geometry>
                <box size="1.4383537910494009 1.4271504640551427 1.0721562717035975" />
            </geometry>
        </collision>
    </link>
    <link name="Leg4">
        <inertial>
            <origin xyz="0.9914424785880854 0 0" rpy="0 0 0"/>
            <mass value="1" />
            <inertia ixx="100" ixy="0" ixz="0" iyy="100" iyz="0" izz="100" />
        </inertial>
        <visual>
            <origin xyz="0.9914424785880854 0 0" rpy="0 0 0"/>
            <geometry>
                <box size="1.9828849571761709 2.219828636888704 1.5152122578219254" />
            </geometry>
            <material name="Blue">
                <color rgba="0 1.0 1.0 1.0"/>
            </material>
        </visual>
        <collision>
            <origin xyz="0.9914424785880854 0 0" rpy="0 0 0"/>
            <geometry>
                <box size="1.9828849571761709 2.219828636888704 1.5152122578219254" />
            </geometry>
        </collision>
    </link>
    <link name="Leg5">
        <inertial>
            <origin xyz="0 0 1.2776216444134638" rpy="0 0 0"/>
            <mass value="1" />
            <inertia ixx="100" ixy="0" ixz="0" iyy="100" iyz="0" izz="100" />
        </inertial>
        <visual>
            <origin xyz="0 0 1.2776216444134638" rpy="0 0 0"/>
            <geometry>
                <box size="2.8803571634914995 2.274937037605935 2.5552432888269276" />
            </geometry>
            <material name="Blue">
                <color rgba="0 1.0 1.0 1.0"/>
            </material>
        </visual>
        <collision>
            <origin xyz="0 0 1.2776216444134638" rpy="0 0 0"/>
            <geometry>
                <box size="2.8803571634914995 2.274937037605935 2.5552432888269276" />
            </geometry>
        </collision>
    </link>
    <link name="Leg6">
        <inertial>
            <origin xyz="0 0 1.0142437642329925" rpy="0 0 0"/>
            <mass value="1" />
            <inertia ixx="100" ixy="0" ixz="0" iyy="100" iyz="0" izz="100" />
        </inertial>
        <visual>
            <origin xyz="0 0 1.0142437642329925" rpy="0 0 0"/>
            <geometry>
                <box size="2.6709346247983374 1.8299707814323252 2.028487528465985" />
            </geometry>
            <material name="Blue">
                <color rgba="0 1.0 1.0 1.0"/>
            </material>
        </visual>
        <collision>
            <origin xyz="0 0 1.0142437642329925" rpy="0 0 0"/>
            <geometry>
                <box size="2.6709346247983374 1.8299707814323252 2.028487528465985" />
            </geometry>
        </collision>
    </link>
    <link name="Leg7">
        <inertial>
            <origin xyz="0.7387954850007233 0 0" rpy="0 0 0"/>
            <mass value="1" />
            <inertia ixx="100" ixy="0" ixz="0" iyy="100" iyz="0" izz="100" />
        </inertial>
        <visual>
            <origin xyz="0.7387954850007233 0 0" rpy="0 0 0"/>
            <geometry>
                <box size="1.4775909700014467 1.4825271774511624 1.1181053048080494" />
            </geometry>
            <material name="Green">
                <color rgba="0 180.0 0.0 1.0"/>
            </material>
        </visual>
        <collision>
            <origin xyz="0.7387954850007233 0 0" rpy="0 0 0"/>
            <geometry>
                <box size="1.4775909700014467 1.4825271774511624 1.1181053048080494" />
            </geometry>
        </collision>
    </link>
    <link name="Leg8">
        <inertial>
            <origin xyz="0 0 0.921601772607776" rpy="0 0 0"/>
            <mass value="1" />
            <inertia ixx="100" ixy="0" ixz="0" iyy="100" iyz="0" izz="100" />
        </inertial>
        <visual>
            <origin xyz="0 0 0.921601772607776" rpy="0 0 0"/>
            <geometry>
                <box size="1.0649689662102064 2.312291976889055 1.843203545215552" />
            </geometry>
            <material name="Green">
                <color rgba="0 180.0 0.0 1.0"/>
            </material>
        </visual>
        <collision>
            <origin xyz="0 0 0.921601772607776" rpy="0 0 0"/>
            <geometry>
                <box size="1.0649689662102064 2.312291976889055 1.843203545215552" />
            </geometry>
        </collision>
    </link>
    <link name="Leg9">
        <inertial>
            <origin xyz="0 0.8028053037136862 0" rpy="0 0 0"/>
            <mass value="1" />
            <inertia ixx="100" ixy="0" ixz="0" iyy="100" iyz="0" izz="100" />
        </inertial>
        <visual>
            <origin xyz="0 0.8028053037136862 0" rpy="0 0 0"/>
            <geometry>
                <box size="2.395857526118358 1.6056106074273724 1.4423107117294656" />
            </geometry>
            <material name="Blue">
                <color rgba="0 1.0 1.0 1.0"/>
            </material>
        </visual>
        <collision>
            <origin xyz="0 0.8028053037136862 0" rpy="0 0 0"/>
            <geometry>
                <box size="2.395857526118358 1.6056106074273724 1.4423107117294656" />
            </geometry>
        </collision>
    </link>
    <link name="Leg10">
        <inertial>
            <origin xyz="0 0 0.6872098239776345" rpy="0 0 0"/>
            <mass value="1" />
            <inertia ixx="100" ixy="0" ixz="0" iyy="100" iyz="0" izz="100" />
        </inertial>
        <visual>
            <origin xyz="0 0 0.6872098239776345" rpy="0 0 0"/>
            <geometry>
                <box size="2.6389379878388786 1.7645563228106647 1.374419647955269" />
            </geometry>
            <material name="Green">
                <color rgba="0 180.0 0.0 1.0"/>
            </material>
        </visual>
        <collision>
            <origin xyz="0 0 0.6872098239776345" rpy="0 0 0"/>
            <geometry>
                <box size="2.6389379878388786 1.7645563228106647 1.374419647955269" />
            </geometry>
        </collision>
    </link>
    <link name="Leg11">
        <inertial>
            <origin xyz="0 0.8452847082315187 0" rpy="0 0 0"/>
            <mass value="1" />
            <inertia ixx="100" ixy="0" ixz="0" iyy="100" iyz="0" izz="100" />
        </inertial>
        <visual>
            <origin xyz="0 0.8452847082315187 0" rpy="0 0 0"/>
            <geometry>
                <box size="2.040411999802696 1.6905694164630374 1.9847318900511703" />
            </geometry>
            <material name="Blue">
                <color rgba="0 1.0 1.0 1.0"/>
            </material>
        </visual>
        <collision>
            <origin xyz="0 0.8452847082315187 0" rpy="0 0 0"/>
            <geometry>
                <box size="2.040411999802696 1.6905694164630374 1.9847318900511703" />
            </geometry>
        </collision>
    </link>
    <link name="Leg12">
        <inertial>
            <origin xyz="0 0 1.1295207704770065" rpy="0 0 0"/>
            <mass value="1" />
            <inertia ixx="100" ixy="0" ixz="0" iyy="100" iyz="0" izz="100" />
        </inertial>
        <visual>
            <origin xyz="0 0 1.1295207704770065" rpy="0 0 0"/>
            <geometry>
                <box size="2.119930679462062 1.2407495435891158 2.259041540954013" />
            </geometry>
            <material name="Blue">
                <color rgba="0 1.0 1.0 1.0"/>
            </material>
        </visual>
        <collision>
            <origin xyz="0 0 1.1295207704770065" rpy="0 0 0"/>
            <geometry>
                <box size="2.119930679462062 1.2407495435891158 2.259041540954013" />
            </geometry>
        </collision>
    </link>
    <link name="Leg13">
        <inertial>
            <origin xyz="0 1.1252774058983273 0" rpy="0 0 0"/>
            <mass value="1" />
            <inertia ixx="100" ixy="0" ixz="0" iyy="100" iyz="0" izz="100" />
        </inertial>
        <visual>
            <origin xyz="0 1.1252774058983273 0" rpy="0 0 0"/>
            <geometry>
                <box size="1.3978736795452407 2.2505548117966545 2.0244641026001178" />
            </geometry>
            <material name="Blue">
                <color rgba="0 1.0 1.0 1.0"/>
            </material>
        </visual>
        <collision>
            <origin xyz="0 1.1252774058983273 0" rpy="0 0 0"/>
            <geometry>
                <box size="1.3978736795452407 2.2505548117966545 2.0244641026001178" />
            </geometry>
        </collision>
    </link>
    <link name="Leg14">
        <inertial>
            <origin xyz="1.3152874058479096 0 0" rpy="0 0 0"/>
            <mass value="1" />
            <inertia ixx="100" ixy="0" ixz="0" iyy="100" iyz="0" izz="100" />
        </inertial>
        <visual>
            <origin xyz="1.3152874058479096 0 0" rpy="0 0 0"/>
            <geometry>
                <box size="2.630574811695819 2.526293583476358 2.2230101369723347" />
            </geometry>
            <material name="Blue">
                <color rgba="0 1.0 1.0 1.0"/>
            </material>
        </visual>
        <collision>
            <origin xyz="1.3152874058479096 0 0" rpy="0 0 0"/>
            <geometry>
                <box size="2.630574811695819 2.526293583476358 2.2230101369723347" />
            </geometry>
        </collision>
    </link>
    <link name="Leg15">
        <inertial>
            <origin xyz="0.9626080287951574 0 0" rpy="0 0 0"/>
            <mass value="1" />
            <inertia ixx="100" ixy="0" ixz="0" iyy="100" iyz="0" izz="100" />
        </inertial>
        <visual>
            <origin xyz="0.9626080287951574 0 0" rpy="0 0 0"/>
            <geometry>
                <box size="1.9252160575903148 2.5966543672335796 2.544632764358556" />
            </geometry>
            <material name="Green">
                <color rgba="0 180.0 0.0 1.0"/>
            </material>
        </visual>
        <collision>
            <origin xyz="0.9626080287951574 0 0" rpy="0 0 0"/>
            <geometry>
                <box size="1.9252160575903148 2.5966543672335796 2.544632764358556" />
            </geometry>
        </collision>
    </link>
    <link name="Leg16">
        <inertial>
            <origin xyz="0.7231604486184564 0 0" rpy="0 0 0"/>
            <mass value="1" />
            <inertia ixx="100" ixy="0" ixz="0" iyy="100" iyz="0" izz="100" />
        </inertial>
        <visual>
            <origin xyz="0.7231604486184564 0 0" rpy="0 0 0"/>
            <geometry>
                <box size="1.4463208972369128 1.8845451532963553 1.3546073514303745" />
            </geometry>
            <material name="Green">
                <color rgba="0 180.0 0.0 1.0"/>
            </material>
        </visual>
        <collision>
            <origin xyz="0.7231604486184564 0 0" rpy="0 0 0"/>
            <geometry>
                <box size="1.4463208972369128 1.8845451532963553 1.3546073514303745" />
            </geometry>
        </collision>
    </link>
    <link name="Leg17">
        <inertial>
            <origin xyz="0.8018411024829573 0 0" rpy="0 0 0"/>
            <mass value="1" />
            <inertia ixx="100" ixy="0" ixz="0" iyy="100" iyz="0" izz="100" />
        </inertial>
        <visual>
            <origin xyz="0.8018411024829573 0 0" rpy="0 0 0"/>
            <geometry>
                <box size="1.6036822049659145 2.1460252450807764 1.326122419222642" />
            </geometry>
            <material name="Blue">
                <color rgba="0 1.0 1.0 1.0"/>
            </material>
        </visual>
        <collision>
            <origin xyz="0.8018411024829573 0 0" rpy="0 0 0"/>
            <geometry>
                <box size="1.6036822049659145 2.1460252450807764 1.326122419222642" />
            </geometry>
        </collision>
    </link>
    <link name="Leg18">
        <inertial>
            <origin xyz="0 0 1.2131981950837196" rpy="0 0 0"/>
            <mass value="1" />
            <inertia ixx="100" ixy="0" ixz="0" iyy="100" iyz="0" izz="100" />
        </inertial>
        <visual>
            <origin xyz="0 0 1.2131981950837196" rpy="0 0 0"/>
            <geometry>
                <box size="2.1611514389462885 1.374889559322782 2.4263963901674392" />
            </geometry>
            <material name="Blue">
                <color rgba="0 1.0 1.0 1.0"/>
            </material>
        </visual>
        <collision>
            <origin xyz="0 0 1.2131981950837196" rpy="0 0 0"/>
            <geometry>
                <box size="2.1611514389462885 1.374889559322782 2.4263963901674392" />
            </geometry>
        </collision>
    </link>
    <link name="Leg19">
        <inertial>
            <origin xyz="1.2203612840432576 0 0" rpy="0 0 0"/>
            <mass value="1" />
            <inertia ixx="100" ixy="0" ixz="0" iyy="100" iyz="0" izz="100" />
        </inertial>
        <visual>
            <origin xyz="1.2203612840432576 0 0" rpy="0 0 0"/>
            <geometry>
                <box size="2.440722568086515 1.126751964790974 1.641921166283346" />
            </geometry>
            <material name="Green">
                <color rgba="0 180.0 0.0 1.0"/>
            </material>
        </visual>
        <collision>
            <origin xyz="1.2203612840432576 0 0" rpy="0 0 0"/>
            <geometry>
                <box size="2.440722568086515 1.126751964790974 1.641921166283346" />
            </geometry>
        </collision>
    </link>
    <link name="Leg20">
        <inertial>
            <origin xyz="0 0.832780207525376 0" rpy="0 0 0"/>
            <mass value="1" />
            <inertia ixx="100" ixy="0" ixz="0" iyy="100" iyz="0" izz="100" />
        </inertial>
        <visual>
            <origin xyz="0 0.832780207525376 0" rpy="0 0 0"/>
            <geometry>
                <box size="1.9989067570479035 1.665560415050752 2.956348749111156" />
            </geometry>
            <material name="Green">
                <color rgba="0 180.0 0.0 1.0"/>
            </material>
        </visual>
        <collision>
            <origin xyz="0 0.832780207525376 0" rpy="0 0 0"/>
            <geometry>
                <box size="1.9989067570479035 1.665560415050752 2.956348749111156" />
            </geometry>
        </collision>
    </link>
    <link name="Leg21">
        <inertial>
            <origin xyz="0 0 1.3950986213045526" rpy="0 0 0"/>
            <mass value="1" />
            <inertia ixx="100" ixy="0" ixz="0" iyy="100" iyz="0" izz="100" />
        </inertial>
        <visual>
            <origin xyz="0 0 1.3950986213045526" rpy="0 0 0"/>
            <geometry>
                <box size="1.687649869590057 2.857422281849825 2.7901972426091053" />
            </geometry>
            <material name="Green">
                <color rgba="0 180.0 0.0 1.0"/>
            </material>
        </visual>
        <collision>
            <origin xyz="0 0 1.3950986213045526" rpy="0 0 0"/>
            <geometry>
                <box size="1.687649869590057 2.857422281849825 2.7901972426091053" />
            </geometry>
        </collision>
    </link>
    <link name="Leg22">
        <inertial>
            <origin xyz="0 0 1.0722185809423397" rpy="0 0 0"/>
            <mass value="1" />
            <inertia ixx="100" ixy="0" ixz="0" iyy="100" iyz="0" izz="100" />
        </inertial>
        <visual>
            <origin xyz="0 0 1.0722185809423397" rpy="0 0 0"/>
            <geometry>
                <box size="2.9113170170160796 2.193867609726549 2.1444371618846794" />
            </geometry>
            <material name="Green">
                <color rgba="0 180.0 0.0 1.0"/>
            </material>
        </visual>
        <collision>
            <origin xyz="0 0 1.0722185809423397" rpy="0 0 0"/>
            <geometry>
                <box size="2.9113170170160796 2.193867609726549 2.1444371618846794" />
            </geometry>
        </collision>
    </link>
    <link name="Leg23">
        <inertial>
            <origin xyz="1.494322435026132 0 0" rpy="0 0 0"/>
            <mass value="1" />
            <inertia ixx="100" ixy="0" ixz="0" iyy="100" iyz="0" izz="100" />
        </inertial>
        <visual>
            <origin xyz="1.494322435026132 0 0" rpy="0 0 0"/>
            <geometry>
                <box size="2.988644870052264 2.6837756412282863 2.009032204283276" />
            </geometry>
            <material name="Blue">
                <color rgba="0 1.0 1.0 1.0"/>
            </material>
        </visual>
        <collision>
            <origin xyz="1.494322435026132 0 0" rpy="0 0 0"/>
            <geometry>
                <box size="2.988644870052264 2.6837756412282863 2.009032204283276" />
            </geometry>
        </collision>
    </link>
    <link name="Leg24">
        <inertial>
            <origin xyz="0.7983821689060632 0 0" rpy="0 0 0"/>
            <mass value="1" />
            <inertia ixx="100" ixy="0" ixz="0" iyy="100" iyz="0" izz="100" />
        </inertial>
        <visual>
            <origin xyz="0.7983821689060632 0 0" rpy="0 0 0"/>
            <geometry>
                <box size="1.5967643378121263 2.1024459040405863 2.710989730146857" />
            </geometry>
            <material name="Green">
                <color rgba="0 180.0 0.0 1.0"/>
            </material>
        </visual>
        <collision>
            <origin xyz="0.7983821689060632 0 0" rpy="0 0 0"/>
            <geometry>
                <box size="1.5967643378121263 2.1024459040405863 2.710989730146857" />
            </geometry>
        </collision>
    </link>
    <link name="Leg25">
        <inertial>
            <origin xyz="0 1.109652784818878 0" rpy="0 0 0"/>
            <mass value="1" />
            <inertia ixx="100" ixy="0" ixz="0" iyy="100" iyz="0" izz="100" />
        </inertial>
        <visual>
            <origin xyz="0 1.109652784818878 0" rpy="0 0 0"/>
            <geometry>
                <box size="2.9192376756451903 2.219305569637756 1.6023246869453427" />
            </geometry>
            <material name="Blue">
                <color rgba="0 1.0 1.0 1.0"/>
            </material>
        </visual>
        <collision>
            <origin xyz="0 1.109652784818878 0" rpy="0 0 0"/>
            <geometry>
                <box size="2.9192376756451903 2.219305569637756 1.6023246869453427" />
            </geometry>
        </collision>
    </link>
    <link name="Leg26">
        <inertial>
            <origin xyz="0 0 1.4632700412521238" rpy="0 0 0"/>
            <mass value="1" />
            <inertia ixx="100" ixy="0" ixz="0" iyy="100" iyz="0" izz="100" />
        </inertial>
        <visual>
            <origin xyz="0 0 1.4632700412521238" rpy="0 0 0"/>
            <geometry>
                <box size="2.7997135555917523 1.0892164145236203 2.9265400825042476" />
            </geometry>
            <material name="Blue">
                <color rgba="0 1.0 1.0 1.0"/>
            </material>
        </visual>
        <collision>
            <origin xyz="0 0 1.4632700412521238" rpy="0 0 0"/>
            <geometry>
                <box size="2.7997135555917523 1.0892164145236203 2.9265400825042476" />
            </geometry>
        </collision>
    </link>
    <link name="Leg27">
        <inertial>
            <origin xyz="0.9602199571606523 0 0" rpy="0 0 0"/>
            <mass value="1" />
            <inertia ixx="100" ixy="0" ixz="0" iyy="100" iyz="0" izz="100" />
        </inertial>
        <visual>
            <origin xyz="0.9602199571606523 0 0" rpy="0 0 0"/>
            <geometry>
                <box size="1.9204399143213047 1.485935039506674 2.8507960356966393" />
            </geometry>
            <material name="Green">
                <color rgba="0 180.0 0.0 1.0"/>
            </material>
        </visual>
        <collision>
            <origin xyz="0.9602199571606523 0 0" rpy="0 0 0"/>
            <geometry>
                <box size="1.9204399143213047 1.485935039506674 2.8507960356966393" />
            </geometry>
        </collision>
    </link>
    <joint name="Torso_Leg1" type="revolute">
       <parent link="Torso"/>
       <child  link="Leg1"/>
       <origin rpy="0 0 0" xyz="0.5296622280792729 0 1.3970434966147853" />
     <axis xyz="1 0 0"/>
       <limit effort="0.0" lower="-3.14159" upper="3.14159" velocity="0.0"/>
    </joint>
    <joint name="Torso_Leg2" type="revolute">
       <parent link="Torso"/>
       <child  link="Leg2"/>
       <origin rpy="0 0 0" xyz="0.9126345355763248 0 0.6769765725400702" />
     <axis xyz="1 0 0"/>
       <limit effort="0.0" lower="-3.14159" upper="3.14159" velocity="0.0"/>
    </joint>
    <joint name="Leg1_Leg3" type="revolute">
       <parent link="Leg1"/>
       <child  link="Leg3"/>
       <origin rpy="0 0 0" xyz="1.4167754479560912 0 0.7997263249919409" />
     <axis xyz="1 0 0"/>
       <limit effort="0.0" lower="-3.14159" upper="3.14159" velocity="0.0"/>
    </joint>
    <joint name="Leg2_Leg4" type="revolute">
       <parent link="Leg2"/>
       <child  link="Leg4"/>
       <origin rpy="0 0 0" xyz="1.4383537910494009 0 0" />
     <axis xyz="1 0 0"/>
       <limit effort="0.0" lower="-3.14159" upper="3.14159" velocity="0.0"/>
    </joint>
    <joint name="Leg3_Leg5" type="revolute">
       <parent link="Leg3"/>
       <child  link="Leg5"/>
       <origin rpy="0 0 0" xyz="0.9914424785880854 0 0.7576061289109627" />
     <axis xyz="1 0 0"/>
       <limit effort="0.0" lower="-3.14159" upper="3.14159" velocity="0.0"/>
    </joint>
    <joint name="Leg5_Leg6" type="revolute">
       <parent link="Leg5"/>
       <child  link="Leg6"/>
       <origin rpy="0 0 0" xyz="0 0 2.028487528465985" />
     <axis xyz="1 0 0"/>
       <limit effort="0.0" lower="-3.14159" upper="3.14159" velocity="0.0"/>
    </joint>
    <joint name="Leg3_Leg7" type="revolute">
       <parent link="Leg3"/>
       <child  link="Leg7"/>
       <origin rpy="0 0 0" xyz="1.9828849571761709 0 0.7576061289109627" />
     <axis xyz="1 0 0"/>
       <limit effort="0.0" lower="-3.14159" upper="3.14159" velocity="0.0"/>
    </joint>
    <joint name="Leg6_Leg8" type="revolute">
       <parent link="Leg6"/>
       <child  link="Leg8"/>
       <origin rpy="0 0 0" xyz="0.7387954850007233 0 0.5590526524040247" />
     <axis xyz="1 0 0"/>
       <limit effort="0.0" lower="-3.14159" upper="3.14159" velocity="0.0"/>
    </joint>
    <joint name="Leg8_Leg9" type="revolute">
       <parent link="Leg8"/>
       <child  link="Leg9"/>
       <origin rpy="0 0 0" xyz="0 1.6056106074273724 0" />
     <axis xyz="1 0 0"/>
       <limit effort="0.0" lower="-3.14159" upper="3.14159" velocity="0.0"/>
    </joint>
    <joint name="Leg4_Leg10" type="revolute">
       <parent link="Leg4"/>
       <child  link="Leg10"/>
       <origin rpy="0 0 0" xyz="0 0 2.5552432888269276" />
     <axis xyz="1 0 0"/>
       <limit effort="0.0" lower="-3.14159" upper="3.14159" velocity="0.0"/>
    </joint>
    <joint name="Leg10_Leg11" type="revolute">
       <parent link="Leg10"/>
       <child  link="Leg11"/>
       <origin rpy="0 0 0" xyz="0 1.6905694164630374 0" />
     <axis xyz="1 0 0"/>
       <limit effort="0.0" lower="-3.14159" upper="3.14159" velocity="0.0"/>
    </joint>
    <joint name="Leg1_Leg12" type="revolute">
       <parent link="Leg1"/>
       <child  link="Leg12"/>
       <origin rpy="0 0 0" xyz="1.4167754479560912 0 1.5994526499838817" />
     <axis xyz="1 0 0"/>
       <limit effort="0.0" lower="-3.14159" upper="3.14159" velocity="0.0"/>
    </joint>
    <joint name="Leg4_Leg13" type="revolute">
       <parent link="Leg4"/>
       <child  link="Leg13"/>
       <origin rpy="0 0 0" xyz="0 1.1374685188029674 2.5552432888269276" />
     <axis xyz="1 0 0"/>
       <limit effort="0.0" lower="-3.14159" upper="3.14159" velocity="0.0"/>
    </joint>
    <joint name="Leg7_Leg14" type="revolute">
       <parent link="Leg7"/>
       <child  link="Leg14"/>
       <origin rpy="0 0 0" xyz="0.5324844831051032 0 0.921601772607776" />
     <axis xyz="1 0 0"/>
       <limit effort="0.0" lower="-3.14159" upper="3.14159" velocity="0.0"/>
    </joint>
    <joint name="Leg13_Leg15" type="revolute">
       <parent link="Leg13"/>
       <child  link="Leg15"/>
       <origin rpy="0 0 0" xyz="2.630574811695819 0 0" />
     <axis xyz="1 0 0"/>
       <limit effort="0.0" lower="-3.14159" upper="3.14159" velocity="0.0"/>
    </joint>
    <joint name="Leg12_Leg16" type="revolute">
       <parent link="Leg12"/>
       <child  link="Leg16"/>
       <origin rpy="0 0 0" xyz="0.6989368397726203 1.1252774058983273 0" />
     <axis xyz="1 0 0"/>
       <limit effort="0.0" lower="-3.14159" upper="3.14159" velocity="0.0"/>
    </joint>
    <joint name="Leg14_Leg17" type="revolute">
       <parent link="Leg14"/>
       <child  link="Leg17"/>
       <origin rpy="0 0 0" xyz="1.9252160575903148 0 0" />
     <axis xyz="1 0 0"/>
       <limit effort="0.0" lower="-3.14159" upper="3.14159" velocity="0.0"/>
    </joint>
    <joint name="Leg10_Leg18" type="revolute">
       <parent link="Leg10"/>
       <child  link="Leg18"/>
       <origin rpy="0 0 0" xyz="0 1.6905694164630374 0.9923659450255852" />
     <axis xyz="1 0 0"/>
       <limit effort="0.0" lower="-3.14159" upper="3.14159" velocity="0.0"/>
    </joint>
    <joint name="Leg17_Leg19" type="revolute">
       <parent link="Leg17"/>
       <child  link="Leg19"/>
       <origin rpy="0 0 0" xyz="1.0805757194731442 0 1.2131981950837196" />
     <axis xyz="1 0 0"/>
       <limit effort="0.0" lower="-3.14159" upper="3.14159" velocity="0.0"/>
    </joint>
    <joint name="Leg5_Leg20" type="revolute">
       <parent link="Leg5"/>
       <child  link="Leg20"/>
       <origin rpy="0 0 0" xyz="0 0.9149853907161626 2.028487528465985" />
     <axis xyz="1 0 0"/>
       <limit effort="0.0" lower="-3.14159" upper="3.14159" velocity="0.0"/>
    </joint>
    <joint name="Leg8_Leg21" type="revolute">
       <parent link="Leg8"/>
       <child  link="Leg21"/>
       <origin rpy="0 0 0" xyz="0 1.6056106074273724 0.7211553558647328" />
     <axis xyz="1 0 0"/>
       <limit effort="0.0" lower="-3.14159" upper="3.14159" velocity="0.0"/>
    </joint>
    <joint name="Leg12_Leg22" type="revolute">
       <parent link="Leg12"/>
       <child  link="Leg22"/>
       <origin rpy="0 0 0" xyz="0.6989368397726203 1.1252774058983273 1.0122320513000589" />
     <axis xyz="1 0 0"/>
       <limit effort="0.0" lower="-3.14159" upper="3.14159" velocity="0.0"/>
    </joint>
    <joint name="Leg4_Leg23" type="revolute">
       <parent link="Leg4"/>
       <child  link="Leg23"/>
       <origin rpy="0 0 0" xyz="1.4401785817457498 1.1374685188029674 2.5552432888269276" />
     <axis xyz="1 0 0"/>
       <limit effort="0.0" lower="-3.14159" upper="3.14159" velocity="0.0"/>
    </joint>
    <joint name="Leg16_Leg24" type="revolute">
       <parent link="Leg16"/>
       <child  link="Leg24"/>
       <origin rpy="0 0 0" xyz="1.6036822049659145 0 0" />
     <axis xyz="1 0 0"/>
       <limit effort="0.0" lower="-3.14159" upper="3.14159" velocity="0.0"/>
    </joint>
    <joint name="Leg13_Leg25" type="revolute">
       <parent link="Leg13"/>
       <child  link="Leg25"/>
       <origin rpy="0 0 0" xyz="2.630574811695819 1.263146791738179 0" />
     <axis xyz="1 0 0"/>
       <limit effort="0.0" lower="-3.14159" upper="3.14159" velocity="0.0"/>
    </joint>
    <joint name="Leg16_Leg26" type="revolute">
       <parent link="Leg16"/>
       <child  link="Leg26"/>
       <origin rpy="0 0 0" xyz="1.6036822049659145 0 0.663061209611321" />
     <axis xyz="1 0 0"/>
       <limit effort="0.0" lower="-3.14159" upper="3.14159" velocity="0.0"/>
    </joint>
    <joint name="Leg5_Leg27" type="revolute">
       <parent link="Leg5"/>
       <child  link="Leg27"/>
       <origin rpy="0 0 0" xyz="1.3354673123991687 0.9149853907161626 2.028487528465985" />
     <axis xyz="1 0 0"/>
       <limit effort="0.0" lower="-3.14159" upper="3.14159" velocity="0.0"/>
    </joint>
</robot>