<robot name = "robot">
    <link name="Torso">
        <inertial>
            <origin xyz="0 0 1.0120402874571812" rpy="0 0 0"/>
            <mass value="1" />
            <inertia ixx="100" ixy="0" ixz="0" iyy="100" iyz="0" izz="100" />
        </inertial>
        <visual>
            <origin xyz="0 0 1.0120402874571812" rpy="0 0 0"/>
            <geometry>
                <box size="2.5818240173850233 1.6673400084363983 2.0240805749143624" />
            </geometry>
            <material name="Green">
                <color rgba="0 180.0 0.0 1.0"/>
            </material>
        </visual>
        <collision>
            <origin xyz="0 0 1.0120402874571812" rpy="0 0 0"/>
            <geometry>
                <box size="2.5818240173850233 1.6673400084363983 2.0240805749143624" />
            </geometry>
        </collision>
    </link>
    <link name="Leg1">
        <inertial>
            <origin xyz="0 0.9838280793959717 0" rpy="0 0 0"/>
            <mass value="1" />
            <inertia ixx="100" ixy="0" ixz="0" iyy="100" iyz="0" izz="100" />
        </inertial>
        <visual>
            <origin xyz="0 0.9838280793959717 0" rpy="0 0 0"/>
            <geometry>
                <box size="1.1319010492226829 1.9676561587919434 2.0828112625771356" />
            </geometry>
            <material name="Blue">
                <color rgba="0 1.0 1.0 1.0"/>
            </material>
        </visual>
        <collision>
            <origin xyz="0 0.9838280793959717 0" rpy="0 0 0"/>
            <geometry>
                <box size="1.1319010492226829 1.9676561587919434 2.0828112625771356" />
            </geometry>
        </collision>
    </link>
    <link name="Leg2">
        <inertial>
            <origin xyz="0 0.8304077113719363 0" rpy="0 0 0"/>
            <mass value="1" />
            <inertia ixx="100" ixy="0" ixz="0" iyy="100" iyz="0" izz="100" />
        </inertial>
        <visual>
            <origin xyz="0 0.8304077113719363 0" rpy="0 0 0"/>
            <geometry>
                <box size="1.4908542431312939 1.6608154227438725 2.68763094611299" />
            </geometry>
            <material name="Blue">
                <color rgba="0 1.0 1.0 1.0"/>
            </material>
        </visual>
        <collision>
            <origin xyz="0 0.8304077113719363 0" rpy="0 0 0"/>
            <geometry>
                <box size="1.4908542431312939 1.6608154227438725 2.68763094611299" />
            </geometry>
        </collision>
    </link>
    <link name="Leg3">
        <inertial>
            <origin xyz="0 0 0.9119206234957085" rpy="0 0 0"/>
            <mass value="1" />
            <inertia ixx="100" ixy="0" ixz="0" iyy="100" iyz="0" izz="100" />
        </inertial>
        <visual>
            <origin xyz="0 0 0.9119206234957085" rpy="0 0 0"/>
            <geometry>
                <box size="2.393345850167495 1.7425476942665117 1.823841246991417" />
            </geometry>
            <material name="Blue">
                <color rgba="0 1.0 1.0 1.0"/>
            </material>
        </visual>
        <collision>
            <origin xyz="0 0 0.9119206234957085" rpy="0 0 0"/>
            <geometry>
                <box size="2.393345850167495 1.7425476942665117 1.823841246991417" />
            </geometry>
        </collision>
    </link>
    <link name="Leg4">
        <inertial>
            <origin xyz="0 1.3230670622585985 0" rpy="0 0 0"/>
            <mass value="1" />
            <inertia ixx="100" ixy="0" ixz="0" iyy="100" iyz="0" izz="100" />
        </inertial>
        <visual>
            <origin xyz="0 1.3230670622585985 0" rpy="0 0 0"/>
            <geometry>
                <box size="1.8076760233827072 2.646134124517197 1.2761053097177433" />
            </geometry>
            <material name="Green">
                <color rgba="0 180.0 0.0 1.0"/>
            </material>
        </visual>
        <collision>
            <origin xyz="0 1.3230670622585985 0" rpy="0 0 0"/>
            <geometry>
                <box size="1.8076760233827072 2.646134124517197 1.2761053097177433" />
            </geometry>
        </collision>
    </link>
    <link name="Leg5">
        <inertial>
            <origin xyz="0 1.03205179340569 0" rpy="0 0 0"/>
            <mass value="1" />
            <inertia ixx="100" ixy="0" ixz="0" iyy="100" iyz="0" izz="100" />
        </inertial>
        <visual>
            <origin xyz="0 1.03205179340569 0" rpy="0 0 0"/>
            <geometry>
                <box size="1.1456466133621477 2.06410358681138 2.7625333458310966" />
            </geometry>
            <material name="Blue">
                <color rgba="0 1.0 1.0 1.0"/>
            </material>
        </visual>
        <collision>
            <origin xyz="0 1.03205179340569 0" rpy="0 0 0"/>
            <geometry>
                <box size="1.1456466133621477 2.06410358681138 2.7625333458310966" />
            </geometry>
        </collision>
    </link>
    <link name="Leg6">
        <inertial>
            <origin xyz="0 0.7145544289842071 0" rpy="0 0 0"/>
            <mass value="1" />
            <inertia ixx="100" ixy="0" ixz="0" iyy="100" iyz="0" izz="100" />
        </inertial>
        <visual>
            <origin xyz="0 0.7145544289842071 0" rpy="0 0 0"/>
            <geometry>
                <box size="2.9531199615676695 1.4291088579684141 1.4031627202763282" />
            </geometry>
            <material name="Blue">
                <color rgba="0 1.0 1.0 1.0"/>
            </material>
        </visual>
        <collision>
            <origin xyz="0 0.7145544289842071 0" rpy="0 0 0"/>
            <geometry>
                <box size="2.9531199615676695 1.4291088579684141 1.4031627202763282" />
            </geometry>
        </collision>
    </link>
    <link name="Leg7">
        <inertial>
            <origin xyz="1.4284684904632252 0 0" rpy="0 0 0"/>
            <mass value="1" />
            <inertia ixx="100" ixy="0" ixz="0" iyy="100" iyz="0" izz="100" />
        </inertial>
        <visual>
            <origin xyz="1.4284684904632252 0 0" rpy="0 0 0"/>
            <geometry>
                <box size="2.8569369809264504 1.7641445347771383 1.4188308113948769" />
            </geometry>
            <material name="Green">
                <color rgba="0 180.0 0.0 1.0"/>
            </material>
        </visual>
        <collision>
            <origin xyz="1.4284684904632252 0 0" rpy="0 0 0"/>
            <geometry>
                <box size="2.8569369809264504 1.7641445347771383 1.4188308113948769" />
            </geometry>
        </collision>
    </link>
    <link name="Leg8">
        <inertial>
            <origin xyz="0 0 1.3016297909045718" rpy="0 0 0"/>
            <mass value="1" />
            <inertia ixx="100" ixy="0" ixz="0" iyy="100" iyz="0" izz="100" />
        </inertial>
        <visual>
            <origin xyz="0 0 1.3016297909045718" rpy="0 0 0"/>
            <geometry>
                <box size="1.3829640103098586 2.9347143869622085 2.6032595818091435" />
            </geometry>
            <material name="Green">
                <color rgba="0 180.0 0.0 1.0"/>
            </material>
        </visual>
        <collision>
            <origin xyz="0 0 1.3016297909045718" rpy="0 0 0"/>
            <geometry>
                <box size="1.3829640103098586 2.9347143869622085 2.6032595818091435" />
            </geometry>
        </collision>
    </link>
    <link name="Leg9">
        <inertial>
            <origin xyz="1.2832287076984894 0 0" rpy="0 0 0"/>
            <mass value="1" />
            <inertia ixx="100" ixy="0" ixz="0" iyy="100" iyz="0" izz="100" />
        </inertial>
        <visual>
            <origin xyz="1.2832287076984894 0 0" rpy="0 0 0"/>
            <geometry>
                <box size="2.566457415396979 2.987657531451344 1.3810895143035047" />
            </geometry>
            <material name="Blue">
                <color rgba="0 1.0 1.0 1.0"/>
            </material>
        </visual>
        <collision>
            <origin xyz="1.2832287076984894 0 0" rpy="0 0 0"/>
            <geometry>
                <box size="2.566457415396979 2.987657531451344 1.3810895143035047" />
            </geometry>
        </collision>
    </link>
    <link name="Leg10">
        <inertial>
            <origin xyz="0 0 1.3811544596847858" rpy="0 0 0"/>
            <mass value="1" />
            <inertia ixx="100" ixy="0" ixz="0" iyy="100" iyz="0" izz="100" />
        </inertial>
        <visual>
            <origin xyz="0 0 1.3811544596847858" rpy="0 0 0"/>
            <geometry>
                <box size="1.3589472620503344 2.872881377598247 2.7623089193695716" />
            </geometry>
            <material name="Green">
                <color rgba="0 180.0 0.0 1.0"/>
            </material>
        </visual>
        <collision>
            <origin xyz="0 0 1.3811544596847858" rpy="0 0 0"/>
            <geometry>
                <box size="1.3589472620503344 2.872881377598247 2.7623089193695716" />
            </geometry>
        </collision>
    </link>
    <link name="Leg11">
        <inertial>
            <origin xyz="0.8539556080203572 0 0" rpy="0 0 0"/>
            <mass value="1" />
            <inertia ixx="100" ixy="0" ixz="0" iyy="100" iyz="0" izz="100" />
        </inertial>
        <visual>
            <origin xyz="0.8539556080203572 0 0" rpy="0 0 0"/>
            <geometry>
                <box size="1.7079112160407144 2.0952386692286202 2.862107986715414" />
            </geometry>
            <material name="Green">
                <color rgba="0 180.0 0.0 1.0"/>
            </material>
        </visual>
        <collision>
            <origin xyz="0.8539556080203572 0 0" rpy="0 0 0"/>
            <geometry>
                <box size="1.7079112160407144 2.0952386692286202 2.862107986715414" />
            </geometry>
        </collision>
    </link>
    <link name="Leg12">
        <inertial>
            <origin xyz="0.8232337660545045 0 0" rpy="0 0 0"/>
            <mass value="1" />
            <inertia ixx="100" ixy="0" ixz="0" iyy="100" iyz="0" izz="100" />
        </inertial>
        <visual>
            <origin xyz="0.8232337660545045 0 0" rpy="0 0 0"/>
            <geometry>
                <box size="1.646467532109009 2.4371689440869533 2.5743028202129823" />
            </geometry>
            <material name="Green">
                <color rgba="0 180.0 0.0 1.0"/>
            </material>
        </visual>
        <collision>
            <origin xyz="0.8232337660545045 0 0" rpy="0 0 0"/>
            <geometry>
                <box size="1.646467532109009 2.4371689440869533 2.5743028202129823" />
            </geometry>
        </collision>
    </link>
    <link name="Leg13">
        <inertial>
            <origin xyz="0 0 0.630710554801221" rpy="0 0 0"/>
            <mass value="1" />
            <inertia ixx="100" ixy="0" ixz="0" iyy="100" iyz="0" izz="100" />
        </inertial>
        <visual>
            <origin xyz="0 0 0.630710554801221" rpy="0 0 0"/>
            <geometry>
                <box size="1.3984566053259366 1.2389370917609002 1.261421109602442" />
            </geometry>
            <material name="Green">
                <color rgba="0 180.0 0.0 1.0"/>
            </material>
        </visual>
        <collision>
            <origin xyz="0 0 0.630710554801221" rpy="0 0 0"/>
            <geometry>
                <box size="1.3984566053259366 1.2389370917609002 1.261421109602442" />
            </geometry>
        </collision>
    </link>
    <link name="Leg14">
        <inertial>
            <origin xyz="0 0 1.4908719518671276" rpy="0 0 0"/>
            <mass value="1" />
            <inertia ixx="100" ixy="0" ixz="0" iyy="100" iyz="0" izz="100" />
        </inertial>
        <visual>
            <origin xyz="0 0 1.4908719518671276" rpy="0 0 0"/>
            <geometry>
                <box size="2.2341750268599583 1.9463025459625918 2.9817439037342552" />
            </geometry>
            <material name="Blue">
                <color rgba="0 1.0 1.0 1.0"/>
            </material>
        </visual>
        <collision>
            <origin xyz="0 0 1.4908719518671276" rpy="0 0 0"/>
            <geometry>
                <box size="2.2341750268599583 1.9463025459625918 2.9817439037342552" />
            </geometry>
        </collision>
    </link>
    <link name="Leg15">
        <inertial>
            <origin xyz="0.5075101414899589 0 0" rpy="0 0 0"/>
            <mass value="1" />
            <inertia ixx="100" ixy="0" ixz="0" iyy="100" iyz="0" izz="100" />
        </inertial>
        <visual>
            <origin xyz="0.5075101414899589 0 0" rpy="0 0 0"/>
            <geometry>
                <box size="1.0150202829799178 1.2795855524944635 2.4183738016033356" />
            </geometry>
            <material name="Green">
                <color rgba="0 180.0 0.0 1.0"/>
            </material>
        </visual>
        <collision>
            <origin xyz="0.5075101414899589 0 0" rpy="0 0 0"/>
            <geometry>
                <box size="1.0150202829799178 1.2795855524944635 2.4183738016033356" />
            </geometry>
        </collision>
    </link>
    <link name="Leg16">
        <inertial>
            <origin xyz="0.6906290857896278 0 0" rpy="0 0 0"/>
            <mass value="1" />
            <inertia ixx="100" ixy="0" ixz="0" iyy="100" iyz="0" izz="100" />
        </inertial>
        <visual>
            <origin xyz="0.6906290857896278 0 0" rpy="0 0 0"/>
            <geometry>
                <box size="1.3812581715792556 1.967842677635149 2.3522083022489317" />
            </geometry>
            <material name="Green">
                <color rgba="0 180.0 0.0 1.0"/>
            </material>
        </visual>
        <collision>
            <origin xyz="0.6906290857896278 0 0" rpy="0 0 0"/>
            <geometry>
                <box size="1.3812581715792556 1.967842677635149 2.3522083022489317" />
            </geometry>
        </collision>
    </link>
    <link name="Leg17">
        <inertial>
            <origin xyz="0 0.6954400619854594 0" rpy="0 0 0"/>
            <mass value="1" />
            <inertia ixx="100" ixy="0" ixz="0" iyy="100" iyz="0" izz="100" />
        </inertial>
        <visual>
            <origin xyz="0 0.6954400619854594 0" rpy="0 0 0"/>
            <geometry>
                <box size="2.4740635856618223 1.3908801239709188 1.4527563650390451" />
            </geometry>
            <material name="Blue">
                <color rgba="0 1.0 1.0 1.0"/>
            </material>
        </visual>
        <collision>
            <origin xyz="0 0.6954400619854594 0" rpy="0 0 0"/>
            <geometry>
                <box size="2.4740635856618223 1.3908801239709188 1.4527563650390451" />
            </geometry>
        </collision>
    </link>
    <link name="Leg18">
        <inertial>
            <origin xyz="0 0 0.8291649882654079" rpy="0 0 0"/>
            <mass value="1" />
            <inertia ixx="100" ixy="0" ixz="0" iyy="100" iyz="0" izz="100" />
        </inertial>
        <visual>
            <origin xyz="0 0 0.8291649882654079" rpy="0 0 0"/>
            <geometry>
                <box size="1.3484699386136845 2.9124552268053066 1.6583299765308157" />
            </geometry>
            <material name="Blue">
                <color rgba="0 1.0 1.0 1.0"/>
            </material>
        </visual>
        <collision>
            <origin xyz="0 0 0.8291649882654079" rpy="0 0 0"/>
            <geometry>
                <box size="1.3484699386136845 2.9124552268053066 1.6583299765308157" />
            </geometry>
        </collision>
    </link>
    <link name="Leg19">
        <inertial>
            <origin xyz="1.0785300307642594 0 0" rpy="0 0 0"/>
            <mass value="1" />
            <inertia ixx="100" ixy="0" ixz="0" iyy="100" iyz="0" izz="100" />
        </inertial>
        <visual>
            <origin xyz="1.0785300307642594 0 0" rpy="0 0 0"/>
            <geometry>
                <box size="2.1570600615285187 1.443423476603877 1.756656787629284" />
            </geometry>
            <material name="Blue">
                <color rgba="0 1.0 1.0 1.0"/>
            </material>
        </visual>
        <collision>
            <origin xyz="1.0785300307642594 0 0" rpy="0 0 0"/>
            <geometry>
                <box size="2.1570600615285187 1.443423476603877 1.756656787629284" />
            </geometry>
        </collision>
    </link>
    <link name="Leg20">
        <inertial>
            <origin xyz="0.9303233316668579 0 0" rpy="0 0 0"/>
            <mass value="1" />
            <inertia ixx="100" ixy="0" ixz="0" iyy="100" iyz="0" izz="100" />
        </inertial>
        <visual>
            <origin xyz="0.9303233316668579 0 0" rpy="0 0 0"/>
            <geometry>
                <box size="1.8606466633337158 2.559315271008633 2.3352385601164967" />
            </geometry>
            <material name="Blue">
                <color rgba="0 1.0 1.0 1.0"/>
            </material>
        </visual>
        <collision>
            <origin xyz="0.9303233316668579 0 0" rpy="0 0 0"/>
            <geometry>
                <box size="1.8606466633337158 2.559315271008633 2.3352385601164967" />
            </geometry>
        </collision>
    </link>
    <link name="Leg21">
        <inertial>
            <origin xyz="0 1.1094999442514633 0" rpy="0 0 0"/>
            <mass value="1" />
            <inertia ixx="100" ixy="0" ixz="0" iyy="100" iyz="0" izz="100" />
        </inertial>
        <visual>
            <origin xyz="0 1.1094999442514633 0" rpy="0 0 0"/>
            <geometry>
                <box size="2.6489479406239598 2.2189998885029265 1.228852166878235" />
            </geometry>
            <material name="Blue">
                <color rgba="0 1.0 1.0 1.0"/>
            </material>
        </visual>
        <collision>
            <origin xyz="0 1.1094999442514633 0" rpy="0 0 0"/>
            <geometry>
                <box size="2.6489479406239598 2.2189998885029265 1.228852166878235" />
            </geometry>
        </collision>
    </link>
    <link name="Leg22">
        <inertial>
            <origin xyz="0 1.418860673283615 0" rpy="0 0 0"/>
            <mass value="1" />
            <inertia ixx="100" ixy="0" ixz="0" iyy="100" iyz="0" izz="100" />
        </inertial>
        <visual>
            <origin xyz="0 1.418860673283615 0" rpy="0 0 0"/>
            <geometry>
                <box size="1.2451266126791405 2.83772134656723 2.0440197993706755" />
            </geometry>
            <material name="Blue">
                <color rgba="0 1.0 1.0 1.0"/>
            </material>
        </visual>
        <collision>
            <origin xyz="0 1.418860673283615 0" rpy="0 0 0"/>
            <geometry>
                <box size="1.2451266126791405 2.83772134656723 2.0440197993706755" />
            </geometry>
        </collision>
    </link>
    <link name="Leg23">
        <inertial>
            <origin xyz="0 1.0178304762854462 0" rpy="0 0 0"/>
            <mass value="1" />
            <inertia ixx="100" ixy="0" ixz="0" iyy="100" iyz="0" izz="100" />
        </inertial>
        <visual>
            <origin xyz="0 1.0178304762854462 0" rpy="0 0 0"/>
            <geometry>
                <box size="2.7562470956344525 2.0356609525708924 1.5508982762992718" />
            </geometry>
            <material name="Blue">
                <color rgba="0 1.0 1.0 1.0"/>
            </material>
        </visual>
        <collision>
            <origin xyz="0 1.0178304762854462 0" rpy="0 0 0"/>
            <geometry>
                <box size="2.7562470956344525 2.0356609525708924 1.5508982762992718" />
            </geometry>
        </collision>
    </link>
    <link name="Leg24">
        <inertial>
            <origin xyz="0 0 0.8577535539380403" rpy="0 0 0"/>
            <mass value="1" />
            <inertia ixx="100" ixy="0" ixz="0" iyy="100" iyz="0" izz="100" />
        </inertial>
        <visual>
            <origin xyz="0 0 0.8577535539380403" rpy="0 0 0"/>
            <geometry>
                <box size="1.8380514693683359 2.847085157913176 1.7155071078760806" />
            </geometry>
            <material name="Green">
                <color rgba="0 180.0 0.0 1.0"/>
            </material>
        </visual>
        <collision>
            <origin xyz="0 0 0.8577535539380403" rpy="0 0 0"/>
            <geometry>
                <box size="1.8380514693683359 2.847085157913176 1.7155071078760806" />
            </geometry>
        </collision>
    </link>
    <joint name="Torso_Leg1" type="revolute">
       <parent link="Torso"/>
       <child  link="Leg1"/>
       <origin rpy="0 0 0" xyz="0 0.8336700042181991 1.0120402874571812" />
     <axis xyz="1 0 0"/>
       <limit effort="0.0" lower="-3.14159" upper="3.14159" velocity="0.0"/>
    </joint>
    <joint name="Leg1_Leg2" type="revolute">
       <parent link="Leg1"/>
       <child  link="Leg2"/>
       <origin rpy="0 0 0" xyz="0 1.6608154227438725 0" />
     <axis xyz="1 0 0"/>
       <limit effort="0.0" lower="-3.14159" upper="3.14159" velocity="0.0"/>
    </joint>
    <joint name="Leg2_Leg3" type="revolute">
       <parent link="Leg2"/>
       <child  link="Leg3"/>
       <origin rpy="0 0 0" xyz="0 0 1.823841246991417" />
     <axis xyz="1 0 0"/>
       <limit effort="0.0" lower="-3.14159" upper="3.14159" velocity="0.0"/>
    </joint>
    <joint name="Leg2_Leg4" type="revolute">
       <parent link="Leg2"/>
       <child  link="Leg4"/>
       <origin rpy="0 0 0" xyz="0 0.8712738471332558 1.823841246991417" />
     <axis xyz="1 0 0"/>
       <limit effort="0.0" lower="-3.14159" upper="3.14159" velocity="0.0"/>
    </joint>
    <joint name="Leg4_Leg5" type="revolute">
       <parent link="Leg4"/>
       <child  link="Leg5"/>
       <origin rpy="0 0 0" xyz="0 2.06410358681138 0" />
     <axis xyz="1 0 0"/>
       <limit effort="0.0" lower="-3.14159" upper="3.14159" velocity="0.0"/>
    </joint>
    <joint name="Leg5_Leg6" type="revolute">
       <parent link="Leg5"/>
       <child  link="Leg6"/>
       <origin rpy="0 0 0" xyz="0 1.4291088579684141 0" />
     <axis xyz="1 0 0"/>
       <limit effort="0.0" lower="-3.14159" upper="3.14159" velocity="0.0"/>
    </joint>
    <joint name="Leg1_Leg7" type="revolute">
       <parent link="Leg1"/>
       <child  link="Leg7"/>
       <origin rpy="0 0 0" xyz="0.7454271215656469 1.6608154227438725 0" />
     <axis xyz="1 0 0"/>
       <limit effort="0.0" lower="-3.14159" upper="3.14159" velocity="0.0"/>
    </joint>
    <joint name="Leg6_Leg8" type="revolute">
       <parent link="Leg6"/>
       <child  link="Leg8"/>
       <origin rpy="0 0 0" xyz="1.4284684904632252 0 0.7094154056974384" />
     <axis xyz="1 0 0"/>
       <limit effort="0.0" lower="-3.14159" upper="3.14159" velocity="0.0"/>
    </joint>
    <joint name="Leg4_Leg9" type="revolute">
       <parent link="Leg4"/>
       <child  link="Leg9"/>
       <origin rpy="0 0 0" xyz="0.5728233066810738 2.06410358681138 0" />
     <axis xyz="1 0 0"/>
       <limit effort="0.0" lower="-3.14159" upper="3.14159" velocity="0.0"/>
    </joint>
    <joint name="Leg3_Leg10" type="revolute">
       <parent link="Leg3"/>
       <child  link="Leg10"/>
       <origin rpy="0 0 0" xyz="0 1.3230670622585985 0.6380526548588716" />
     <axis xyz="1 0 0"/>
       <limit effort="0.0" lower="-3.14159" upper="3.14159" velocity="0.0"/>
    </joint>
    <joint name="Leg9_Leg11" type="revolute">
       <parent link="Leg9"/>
       <child  link="Leg11"/>
       <origin rpy="0 0 0" xyz="0.6794736310251672 0 1.3811544596847858" />
     <axis xyz="1 0 0"/>
       <limit effort="0.0" lower="-3.14159" upper="3.14159" velocity="0.0"/>
    </joint>
    <joint name="Leg10_Leg12" type="revolute">
       <parent link="Leg10"/>
       <child  link="Leg12"/>
       <origin rpy="0 0 0" xyz="1.7079112160407144 0 0" />
     <axis xyz="1 0 0"/>
       <limit effort="0.0" lower="-3.14159" upper="3.14159" velocity="0.0"/>
    </joint>
    <joint name="Leg7_Leg13" type="revolute">
       <parent link="Leg7"/>
       <child  link="Leg13"/>
       <origin rpy="0 0 0" xyz="0 0 2.6032595818091435" />
     <axis xyz="1 0 0"/>
       <limit effort="0.0" lower="-3.14159" upper="3.14159" velocity="0.0"/>
    </joint>
    <joint name="Leg13_Leg14" type="revolute">
       <parent link="Leg13"/>
       <child  link="Leg14"/>
       <origin rpy="0 0 0" xyz="0 0 2.9817439037342552" />
     <axis xyz="1 0 0"/>
       <limit effort="0.0" lower="-3.14159" upper="3.14159" velocity="0.0"/>
    </joint>
    <joint name="Leg7_Leg15" type="revolute">
       <parent link="Leg7"/>
       <child  link="Leg15"/>
       <origin rpy="0 0 0" xyz="0.6914820051549293 0 2.6032595818091435" />
     <axis xyz="1 0 0"/>
       <limit effort="0.0" lower="-3.14159" upper="3.14159" velocity="0.0"/>
    </joint>
    <joint name="Leg13_Leg16" type="revolute">
       <parent link="Leg13"/>
       <child  link="Leg16"/>
       <origin rpy="0 0 0" xyz="1.1170875134299791 0 2.9817439037342552" />
     <axis xyz="1 0 0"/>
       <limit effort="0.0" lower="-3.14159" upper="3.14159" velocity="0.0"/>
    </joint>
    <joint name="Leg12_Leg17" type="revolute">
       <parent link="Leg12"/>
       <child  link="Leg17"/>
       <origin rpy="0 0 0" xyz="0 0.6194685458804501 0.630710554801221" />
     <axis xyz="1 0 0"/>
       <limit effort="0.0" lower="-3.14159" upper="3.14159" velocity="0.0"/>
    </joint>
    <joint name="Leg15_Leg18" type="revolute">
       <parent link="Leg15"/>
       <child  link="Leg18"/>
       <origin rpy="0 0 0" xyz="0.6906290857896278 0 1.1761041511244659" />
     <axis xyz="1 0 0"/>
       <limit effort="0.0" lower="-3.14159" upper="3.14159" velocity="0.0"/>
    </joint>
    <joint name="Leg16_Leg19" type="revolute">
       <parent link="Leg16"/>
       <child  link="Leg19"/>
       <origin rpy="0 0 0" xyz="1.2370317928309111 0.6954400619854594 0" />
     <axis xyz="1 0 0"/>
       <limit effort="0.0" lower="-3.14159" upper="3.14159" velocity="0.0"/>
    </joint>
    <joint name="Torso_Leg20" type="revolute">
       <parent link="Torso"/>
       <child  link="Leg20"/>
       <origin rpy="0 0 0" xyz="0.5659505246113414 0.9838280793959717 0" />
     <axis xyz="1 0 0"/>
       <limit effort="0.0" lower="-3.14159" upper="3.14159" velocity="0.0"/>
    </joint>
    <joint name="Leg10_Leg21" type="revolute">
       <parent link="Leg10"/>
       <child  link="Leg21"/>
       <origin rpy="0 0 0" xyz="1.7079112160407144 1.0476193346143101 0" />
     <axis xyz="1 0 0"/>
       <limit effort="0.0" lower="-3.14159" upper="3.14159" velocity="0.0"/>
    </joint>
    <joint name="Leg7_Leg22" type="revolute">
       <parent link="Leg7"/>
       <child  link="Leg22"/>
       <origin rpy="0 0 0" xyz="0.6914820051549293 1.4673571934811043 2.6032595818091435" />
     <axis xyz="1 0 0"/>
       <limit effort="0.0" lower="-3.14159" upper="3.14159" velocity="0.0"/>
    </joint>
    <joint name="Leg6_Leg23" type="revolute">
       <parent link="Leg6"/>
       <child  link="Leg23"/>
       <origin rpy="0 0 0" xyz="1.4284684904632252 0.8820722673885691 0.7094154056974384" />
     <axis xyz="1 0 0"/>
       <limit effort="0.0" lower="-3.14159" upper="3.14159" velocity="0.0"/>
    </joint>
    <joint name="Leg16_Leg24" type="revolute">
       <parent link="Leg16"/>
       <child  link="Leg24"/>
       <origin rpy="0 0 0" xyz="1.2370317928309111 0.6954400619854594 0.7263781825195226" />
     <axis xyz="1 0 0"/>
       <limit effort="0.0" lower="-3.14159" upper="3.14159" velocity="0.0"/>
    </joint>
</robot>