<robot name = "robot">
    <link name="Torso">
        <inertial>
            <origin xyz="0 0.9961243165706627 0.6326389996235633" rpy="0 0 0"/>
            <mass value="1" />
            <inertia ixx="100" ixy="0" ixz="0" iyy="100" iyz="0" izz="100" />
        </inertial>
        <visual>
            <origin xyz="0 0.9961243165706627 0.6326389996235633" rpy="0 0 0"/>
            <geometry>
                <box size="1.4951023638685719 1.9922486331413254 1.2652779992471266" />
            </geometry>
            <material name="Green">
                <color rgba="0 180.0 0.0 1.0"/>
            </material>
        </visual>
        <collision>
            <origin xyz="0 0.9961243165706627 0.6326389996235633" rpy="0 0 0"/>
            <geometry>
                <box size="1.4951023638685719 1.9922486331413254 1.2652779992471266" />
            </geometry>
        </collision>
    </link>
    <link name="Leg1">
        <inertial>
            <origin xyz="0.6467971178137076 0.7051997746470424 1.3992433500704369" rpy="0 0 0"/>
            <mass value="1" />
            <inertia ixx="100" ixy="0" ixz="0" iyy="100" iyz="0" izz="100" />
        </inertial>
        <visual>
            <origin xyz="0.6467971178137076 0.7051997746470424 1.3992433500704369" rpy="0 0 0"/>
            <geometry>
                <box size="1.2935942356274153 1.4103995492940848 2.7984867001408738" />
            </geometry>
            <material name="Blue">
                <color rgba="0 1.0 1.0 1.0"/>
            </material>
        </visual>
        <collision>
            <origin xyz="0.6467971178137076 0.7051997746470424 1.3992433500704369" rpy="0 0 0"/>
            <geometry>
                <box size="1.2935942356274153 1.4103995492940848 2.7984867001408738" />
            </geometry>
        </collision>
    </link>
    <link name="Leg2">
        <inertial>
            <origin xyz="0.7956675045030784 1.2945198830543232 1.327886777756135" rpy="0 0 0"/>
            <mass value="1" />
            <inertia ixx="100" ixy="0" ixz="0" iyy="100" iyz="0" izz="100" />
        </inertial>
        <visual>
            <origin xyz="0.7956675045030784 1.2945198830543232 1.327886777756135" rpy="0 0 0"/>
            <geometry>
                <box size="1.5913350090061569 1.2945198830543232 2.65577355551227" />
            </geometry>
            <material name="Blue">
                <color rgba="0 1.0 1.0 1.0"/>
            </material>
        </visual>
        <collision>
            <origin xyz="0.7956675045030784 1.2945198830543232 1.327886777756135" rpy="0 0 0"/>
            <geometry>
                <box size="1.5913350090061569 1.2945198830543232 2.65577355551227" />
            </geometry>
        </collision>
    </link>
    <link name="Leg3">
        <inertial>
            <origin xyz="1.421354348568046 1.0502732175863265 0" rpy="0 0 0"/>
            <mass value="1" />
            <inertia ixx="100" ixy="0" ixz="0" iyy="100" iyz="0" izz="100" />
        </inertial>
        <visual>
            <origin xyz="1.421354348568046 1.0502732175863265 0" rpy="0 0 0"/>
            <geometry>
                <box size="1.421354348568046 2.100546435172653 1.0995871375548232" />
            </geometry>
            <material name="Blue">
                <color rgba="0 1.0 1.0 1.0"/>
            </material>
        </visual>
        <collision>
            <origin xyz="1.421354348568046 1.0502732175863265 0" rpy="0 0 0"/>
            <geometry>
                <box size="1.421354348568046 2.100546435172653 1.0995871375548232" />
            </geometry>
        </collision>
    </link>
    <link name="Leg4">
        <inertial>
            <origin xyz="1.2859900057064522 0.9220679870744802 1.4515409930760232" rpy="0 0 0"/>
            <mass value="1" />
            <inertia ixx="100" ixy="0" ixz="0" iyy="100" iyz="0" izz="100" />
        </inertial>
        <visual>
            <origin xyz="1.2859900057064522 0.9220679870744802 1.4515409930760232" rpy="0 0 0"/>
            <geometry>
                <box size="2.5719800114129043 1.8441359741489605 2.9030819861520465" />
            </geometry>
            <material name="Blue">
                <color rgba="0 1.0 1.0 1.0"/>
            </material>
        </visual>
        <collision>
            <origin xyz="1.2859900057064522 0.9220679870744802 1.4515409930760232" rpy="0 0 0"/>
            <geometry>
                <box size="2.5719800114129043 1.8441359741489605 2.9030819861520465" />
            </geometry>
        </collision>
    </link>
    <link name="Leg5">
        <inertial>
            <origin xyz="1.3780171865598647 2.7688691865876 0" rpy="0 0 0"/>
            <mass value="1" />
            <inertia ixx="100" ixy="0" ixz="0" iyy="100" iyz="0" izz="100" />
        </inertial>
        <visual>
            <origin xyz="1.3780171865598647 2.7688691865876 0" rpy="0 0 0"/>
            <geometry>
                <box size="2.7560343731197294 2.7688691865876 1.3307905223470964" />
            </geometry>
            <material name="Blue">
                <color rgba="0 1.0 1.0 1.0"/>
            </material>
        </visual>
        <collision>
            <origin xyz="1.3780171865598647 2.7688691865876 0" rpy="0 0 0"/>
            <geometry>
                <box size="2.7560343731197294 2.7688691865876 1.3307905223470964" />
            </geometry>
        </collision>
    </link>
    <link name="Leg6">
        <inertial>
            <origin xyz="0.7201489057143988 0 0" rpy="0 0 0"/>
            <mass value="1" />
            <inertia ixx="100" ixy="0" ixz="0" iyy="100" iyz="0" izz="100" />
        </inertial>
        <visual>
            <origin xyz="0.7201489057143988 0 0" rpy="0 0 0"/>
            <geometry>
                <box size="1.4402978114287976 2.5920003326034444 1.7343470835621961" />
            </geometry>
            <material name="Blue">
                <color rgba="0 1.0 1.0 1.0"/>
            </material>
        </visual>
        <collision>
            <origin xyz="0.7201489057143988 0 0" rpy="0 0 0"/>
            <geometry>
                <box size="1.4402978114287976 2.5920003326034444 1.7343470835621961" />
            </geometry>
        </collision>
    </link>
    <link name="Leg7">
        <inertial>
            <origin xyz="0.505851228771382 0.8207306163505367 1.2047848602194307" rpy="0 0 0"/>
            <mass value="1" />
            <inertia ixx="100" ixy="0" ixz="0" iyy="100" iyz="0" izz="100" />
        </inertial>
        <visual>
            <origin xyz="0.505851228771382 0.8207306163505367 1.2047848602194307" rpy="0 0 0"/>
            <geometry>
                <box size="1.011702457542764 1.6414612327010734 2.4095697204388613" />
            </geometry>
            <material name="Blue">
                <color rgba="0 1.0 1.0 1.0"/>
            </material>
        </visual>
        <collision>
            <origin xyz="0.505851228771382 0.8207306163505367 1.2047848602194307" rpy="0 0 0"/>
            <geometry>
                <box size="1.011702457542764 1.6414612327010734 2.4095697204388613" />
            </geometry>
        </collision>
    </link>
    <link name="Leg8">
        <inertial>
            <origin xyz="0.5730464216555398 2.7314184962660164 0" rpy="0 0 0"/>
            <mass value="1" />
            <inertia ixx="100" ixy="0" ixz="0" iyy="100" iyz="0" izz="100" />
        </inertial>
        <visual>
            <origin xyz="0.5730464216555398 2.7314184962660164 0" rpy="0 0 0"/>
            <geometry>
                <box size="1.1460928433110795 2.7314184962660164 1.903504431097292" />
            </geometry>
            <material name="Blue">
                <color rgba="0 1.0 1.0 1.0"/>
            </material>
        </visual>
        <collision>
            <origin xyz="0.5730464216555398 2.7314184962660164 0" rpy="0 0 0"/>
            <geometry>
                <box size="1.1460928433110795 2.7314184962660164 1.903504431097292" />
            </geometry>
        </collision>
    </link>
    <link name="Leg9">
        <inertial>
            <origin xyz="1.2077129168809124 0 0" rpy="0 0 0"/>
            <mass value="1" />
            <inertia ixx="100" ixy="0" ixz="0" iyy="100" iyz="0" izz="100" />
        </inertial>
        <visual>
            <origin xyz="1.2077129168809124 0 0" rpy="0 0 0"/>
            <geometry>
                <box size="2.415425833761825 1.676953671741381 1.393172516816444" />
            </geometry>
            <material name="Blue">
                <color rgba="0 1.0 1.0 1.0"/>
            </material>
        </visual>
        <collision>
            <origin xyz="1.2077129168809124 0 0" rpy="0 0 0"/>
            <geometry>
                <box size="2.415425833761825 1.676953671741381 1.393172516816444" />
            </geometry>
        </collision>
    </link>
    <link name="Leg10">
        <inertial>
            <origin xyz="0.6100650399956979 0 0" rpy="0 0 0"/>
            <mass value="1" />
            <inertia ixx="100" ixy="0" ixz="0" iyy="100" iyz="0" izz="100" />
        </inertial>
        <visual>
            <origin xyz="0.6100650399956979 0 0" rpy="0 0 0"/>
            <geometry>
                <box size="1.2201300799913959 2.566356498135212 2.1981031369837494" />
            </geometry>
            <material name="Blue">
                <color rgba="0 1.0 1.0 1.0"/>
            </material>
        </visual>
        <collision>
            <origin xyz="0.6100650399956979 0 0" rpy="0 0 0"/>
            <geometry>
                <box size="1.2201300799913959 2.566356498135212 2.1981031369837494" />
            </geometry>
        </collision>
    </link>
    <link name="Leg11">
        <inertial>
            <origin xyz="0.7188498547244574 0 1.4914602270311224" rpy="0 0 0"/>
            <mass value="1" />
            <inertia ixx="100" ixy="0" ixz="0" iyy="100" iyz="0" izz="100" />
        </inertial>
        <visual>
            <origin xyz="0.7188498547244574 0 1.4914602270311224" rpy="0 0 0"/>
            <geometry>
                <box size="1.4376997094489148 1.7330102595702797 2.9829204540622447" />
            </geometry>
            <material name="Blue">
                <color rgba="0 1.0 1.0 1.0"/>
            </material>
        </visual>
        <collision>
            <origin xyz="0.7188498547244574 0 1.4914602270311224" rpy="0 0 0"/>
            <geometry>
                <box size="1.4376997094489148 1.7330102595702797 2.9829204540622447" />
            </geometry>
        </collision>
    </link>
    <link name="Leg12">
        <inertial>
            <origin xyz="0.6643419164074972 0.6123101189462261 0" rpy="0 0 0"/>
            <mass value="1" />
            <inertia ixx="100" ixy="0" ixz="0" iyy="100" iyz="0" izz="100" />
        </inertial>
        <visual>
            <origin xyz="0.6643419164074972 0.6123101189462261 0" rpy="0 0 0"/>
            <geometry>
                <box size="1.3286838328149944 1.2246202378924522 2.8492724632590734" />
            </geometry>
            <material name="Blue">
                <color rgba="0 1.0 1.0 1.0"/>
            </material>
        </visual>
        <collision>
            <origin xyz="0.6643419164074972 0.6123101189462261 0" rpy="0 0 0"/>
            <geometry>
                <box size="1.3286838328149944 1.2246202378924522 2.8492724632590734" />
            </geometry>
        </collision>
    </link>
    <link name="Leg13">
        <inertial>
            <origin xyz="0 1.0393628814976257 0" rpy="0 0 0"/>
            <mass value="1" />
            <inertia ixx="100" ixy="0" ixz="0" iyy="100" iyz="0" izz="100" />
        </inertial>
        <visual>
            <origin xyz="0 1.0393628814976257 0" rpy="0 0 0"/>
            <geometry>
                <box size="2.1959599534408127 2.0787257629952514 1.4700227877999483" />
            </geometry>
            <material name="Blue">
                <color rgba="0 1.0 1.0 1.0"/>
            </material>
        </visual>
        <collision>
            <origin xyz="0 1.0393628814976257 0" rpy="0 0 0"/>
            <geometry>
                <box size="2.1959599534408127 2.0787257629952514 1.4700227877999483" />
            </geometry>
        </collision>
    </link>
    <link name="Leg14">
        <inertial>
            <origin xyz="0.5130776485709335 0 0" rpy="0 0 0"/>
            <mass value="1" />
            <inertia ixx="100" ixy="0" ixz="0" iyy="100" iyz="0" izz="100" />
        </inertial>
        <visual>
            <origin xyz="0.5130776485709335 0 0" rpy="0 0 0"/>
            <geometry>
                <box size="1.026155297141867 1.2670156258885417 1.673052290746289" />
            </geometry>
            <material name="Blue">
                <color rgba="0 1.0 1.0 1.0"/>
            </material>
        </visual>
        <collision>
            <origin xyz="0.5130776485709335 0 0" rpy="0 0 0"/>
            <geometry>
                <box size="1.026155297141867 1.2670156258885417 1.673052290746289" />
            </geometry>
        </collision>
    </link>
    <link name="Leg15">
        <inertial>
            <origin xyz="0 2.362067887351016 0" rpy="0 0 0"/>
            <mass value="1" />
            <inertia ixx="100" ixy="0" ixz="0" iyy="100" iyz="0" izz="100" />
        </inertial>
        <visual>
            <origin xyz="0 2.362067887351016 0" rpy="0 0 0"/>
            <geometry>
                <box size="1.0393176838989078 2.362067887351016 2.104127636083928" />
            </geometry>
            <material name="Blue">
                <color rgba="0 1.0 1.0 1.0"/>
            </material>
        </visual>
        <collision>
            <origin xyz="0 2.362067887351016 0" rpy="0 0 0"/>
            <geometry>
                <box size="1.0393176838989078 2.362067887351016 2.104127636083928" />
            </geometry>
        </collision>
    </link>
    <link name="Leg16">
        <inertial>
            <origin xyz="1.0925128367188082 0 1.152570751091337" rpy="0 0 0"/>
            <mass value="1" />
            <inertia ixx="100" ixy="0" ixz="0" iyy="100" iyz="0" izz="100" />
        </inertial>
        <visual>
            <origin xyz="1.0925128367188082 0 1.152570751091337" rpy="0 0 0"/>
            <geometry>
                <box size="2.1850256734376163 1.7861746568742891 1.152570751091337" />
            </geometry>
            <material name="Blue">
                <color rgba="0 1.0 1.0 1.0"/>
            </material>
        </visual>
        <collision>
            <origin xyz="1.0925128367188082 0 1.152570751091337" rpy="0 0 0"/>
            <geometry>
                <box size="2.1850256734376163 1.7861746568742891 1.152570751091337" />
            </geometry>
        </collision>
    </link>
    <link name="Leg17">
        <inertial>
            <origin xyz="1.4499174361436586 0 0" rpy="0 0 0"/>
            <mass value="1" />
            <inertia ixx="100" ixy="0" ixz="0" iyy="100" iyz="0" izz="100" />
        </inertial>
        <visual>
            <origin xyz="1.4499174361436586 0 0" rpy="0 0 0"/>
            <geometry>
                <box size="2.8998348722873173 2.4509046256530462 2.063918196698649" />
            </geometry>
            <material name="Blue">
                <color rgba="0 1.0 1.0 1.0"/>
            </material>
        </visual>
        <collision>
            <origin xyz="1.4499174361436586 0 0" rpy="0 0 0"/>
            <geometry>
                <box size="2.8998348722873173 2.4509046256530462 2.063918196698649" />
            </geometry>
        </collision>
    </link>
    <link name="Leg18">
        <inertial>
            <origin xyz="1.363371594235268 0 0" rpy="0 0 0"/>
            <mass value="1" />
            <inertia ixx="100" ixy="0" ixz="0" iyy="100" iyz="0" izz="100" />
        </inertial>
        <visual>
            <origin xyz="1.363371594235268 0 0" rpy="0 0 0"/>
            <geometry>
                <box size="1.363371594235268 1.569707468048665 2.1508068089986736" />
            </geometry>
            <material name="Blue">
                <color rgba="0 1.0 1.0 1.0"/>
            </material>
        </visual>
        <collision>
            <origin xyz="1.363371594235268 0 0" rpy="0 0 0"/>
            <geometry>
                <box size="1.363371594235268 1.569707468048665 2.1508068089986736" />
            </geometry>
        </collision>
    </link>
    <link name="Leg19">
        <inertial>
            <origin xyz="0 0 2.9754859949898433" rpy="0 0 0"/>
            <mass value="1" />
            <inertia ixx="100" ixy="0" ixz="0" iyy="100" iyz="0" izz="100" />
        </inertial>
        <visual>
            <origin xyz="0 0 2.9754859949898433" rpy="0 0 0"/>
            <geometry>
                <box size="2.8917487990435995 2.0430365509589525 2.9754859949898433" />
            </geometry>
            <material name="Blue">
                <color rgba="0 1.0 1.0 1.0"/>
            </material>
        </visual>
        <collision>
            <origin xyz="0 0 2.9754859949898433" rpy="0 0 0"/>
            <geometry>
                <box size="2.8917487990435995 2.0430365509589525 2.9754859949898433" />
            </geometry>
        </collision>
    </link>
    <link name="Leg20">
        <inertial>
            <origin xyz="0 1.5764778625748925 0" rpy="0 0 0"/>
            <mass value="1" />
            <inertia ixx="100" ixy="0" ixz="0" iyy="100" iyz="0" izz="100" />
        </inertial>
        <visual>
            <origin xyz="0 1.5764778625748925 0" rpy="0 0 0"/>
            <geometry>
                <box size="2.2853614405683995 1.5764778625748925 1.5191287716860151" />
            </geometry>
            <material name="Blue">
                <color rgba="0 1.0 1.0 1.0"/>
            </material>
        </visual>
        <collision>
            <origin xyz="0 1.5764778625748925 0" rpy="0 0 0"/>
            <geometry>
                <box size="2.2853614405683995 1.5764778625748925 1.5191287716860151" />
            </geometry>
        </collision>
    </link>
    <link name="Leg21">
        <inertial>
            <origin xyz="0 1.3632162702077242 0.6827302473075455" rpy="0 0 0"/>
            <mass value="1" />
            <inertia ixx="100" ixy="0" ixz="0" iyy="100" iyz="0" izz="100" />
        </inertial>
        <visual>
            <origin xyz="0 1.3632162702077242 0.6827302473075455" rpy="0 0 0"/>
            <geometry>
                <box size="2.77733860001052 2.7264325404154484 1.365460494615091" />
            </geometry>
            <material name="Blue">
                <color rgba="0 1.0 1.0 1.0"/>
            </material>
        </visual>
        <collision>
            <origin xyz="0 1.3632162702077242 0.6827302473075455" rpy="0 0 0"/>
            <geometry>
                <box size="2.77733860001052 2.7264325404154484 1.365460494615091" />
            </geometry>
        </collision>
    </link>
    <link name="Leg22">
        <inertial>
            <origin xyz="0 0 1.1648519617145099" rpy="0 0 0"/>
            <mass value="1" />
            <inertia ixx="100" ixy="0" ixz="0" iyy="100" iyz="0" izz="100" />
        </inertial>
        <visual>
            <origin xyz="0 0 1.1648519617145099" rpy="0 0 0"/>
            <geometry>
                <box size="1.6905486783909986 1.061041702062829 2.3297039234290198" />
            </geometry>
            <material name="Blue">
                <color rgba="0 1.0 1.0 1.0"/>
            </material>
        </visual>
        <collision>
            <origin xyz="0 0 1.1648519617145099" rpy="0 0 0"/>
            <geometry>
                <box size="1.6905486783909986 1.061041702062829 2.3297039234290198" />
            </geometry>
        </collision>
    </link>
    <link name="Leg23">
        <inertial>
            <origin xyz="0 0 1.0059580114216735" rpy="0 0 0"/>
            <mass value="1" />
            <inertia ixx="100" ixy="0" ixz="0" iyy="100" iyz="0" izz="100" />
        </inertial>
        <visual>
            <origin xyz="0 0 1.0059580114216735" rpy="0 0 0"/>
            <geometry>
                <box size="2.275901364689754 2.718317454023645 2.011916022843347" />
            </geometry>
            <material name="Blue">
                <color rgba="0 1.0 1.0 1.0"/>
            </material>
        </visual>
        <collision>
            <origin xyz="0 0 1.0059580114216735" rpy="0 0 0"/>
            <geometry>
                <box size="2.275901364689754 2.718317454023645 2.011916022843347" />
            </geometry>
        </collision>
    </link>
    <link name="Leg24">
        <inertial>
            <origin xyz="0.6428036793444512 0 0" rpy="0 0 0"/>
            <mass value="1" />
            <inertia ixx="100" ixy="0" ixz="0" iyy="100" iyz="0" izz="100" />
        </inertial>
        <visual>
            <origin xyz="0.6428036793444512 0 0" rpy="0 0 0"/>
            <geometry>
                <box size="1.2856073586889023 2.0850118514385807 1.2733101899456258" />
            </geometry>
            <material name="Blue">
                <color rgba="0 1.0 1.0 1.0"/>
            </material>
        </visual>
        <collision>
            <origin xyz="0.6428036793444512 0 0" rpy="0 0 0"/>
            <geometry>
                <box size="1.2856073586889023 2.0850118514385807 1.2733101899456258" />
            </geometry>
        </collision>
    </link>
    <link name="Leg25">
        <inertial>
            <origin xyz="1.4089518408004504 0 0.7099710112126489" rpy="0 0 0"/>
            <mass value="1" />
            <inertia ixx="100" ixy="0" ixz="0" iyy="100" iyz="0" izz="100" />
        </inertial>
        <visual>
            <origin xyz="1.4089518408004504 0 0.7099710112126489" rpy="0 0 0"/>
            <geometry>
                <box size="2.817903681600901 1.4247502597244226 1.4199420224252979" />
            </geometry>
            <material name="Blue">
                <color rgba="0 1.0 1.0 1.0"/>
            </material>
        </visual>
        <collision>
            <origin xyz="1.4089518408004504 0 0.7099710112126489" rpy="0 0 0"/>
            <geometry>
                <box size="2.817903681600901 1.4247502597244226 1.4199420224252979" />
            </geometry>
        </collision>
    </link>
    <link name="Leg26">
        <inertial>
            <origin xyz="0 0 0.9997400490708113" rpy="0 0 0"/>
            <mass value="1" />
            <inertia ixx="100" ixy="0" ixz="0" iyy="100" iyz="0" izz="100" />
        </inertial>
        <visual>
            <origin xyz="0 0 0.9997400490708113" rpy="0 0 0"/>
            <geometry>
                <box size="1.5441157110325017 2.65915908592599 1.9994800981416225" />
            </geometry>
            <material name="Blue">
                <color rgba="0 1.0 1.0 1.0"/>
            </material>
        </visual>
        <collision>
            <origin xyz="0 0 0.9997400490708113" rpy="0 0 0"/>
            <geometry>
                <box size="1.5441157110325017 2.65915908592599 1.9994800981416225" />
            </geometry>
        </collision>
    </link>
    <link name="Leg27">
        <inertial>
            <origin xyz="0 0.8835181394235911 0" rpy="0 0 0"/>
            <mass value="1" />
            <inertia ixx="100" ixy="0" ixz="0" iyy="100" iyz="0" izz="100" />
        </inertial>
        <visual>
            <origin xyz="0 0.8835181394235911 0" rpy="0 0 0"/>
            <geometry>
                <box size="2.3050139227574267 1.7670362788471823 2.8091854519051402" />
            </geometry>
            <material name="Green">
                <color rgba="0 180.0 100.0 1.0"/>
            </material>
        </visual>
        <collision>
            <origin xyz="0 0.8835181394235911 0" rpy="0 0 0"/>
            <geometry>
                <box size="2.3050139227574267 1.7670362788471823 2.8091854519051402" />
            </geometry>
        </collision>
    </link>
    <joint name="Torso_Leg1" type="revolute">
       <parent link="Torso"/>
       <child  link="Leg1"/>
       <origin rpy="0 0 0" xyz="0 0.9961243165706627 0.6326389996235633" />
     <axis xyz="1 0 0"/>
       <limit effort="0.0" lower="-3.14159" upper="3.14159" velocity="0.0"/>
    </joint>
    <joint name="Leg1_Leg2" type="revolute">
       <parent link="Leg1"/>
       <child  link="Leg2"/>
       <origin rpy="0 0 0" xyz="0.7956675045030784 1.2945198830543232 1.327886777756135" />
     <axis xyz="1 0 0"/>
       <limit effort="0.0" lower="-3.14159" upper="3.14159" velocity="0.0"/>
    </joint>
    <joint name="Torso_Leg3" type="revolute">
       <parent link="Torso"/>
       <child  link="Leg3"/>
       <origin rpy="0 0 0" xyz="0.6467971178137076 0.7051997746470424 1.3992433500704369" />
     <axis xyz="1 0 0"/>
       <limit effort="0.0" lower="-3.14159" upper="3.14159" velocity="0.0"/>
    </joint>
    <joint name="Leg1_Leg4" type="revolute">
       <parent link="Leg1"/>
       <child  link="Leg4"/>
       <origin rpy="0 0 0" xyz="0.7956675045030784 1.2945198830543232 1.327886777756135" />
     <axis xyz="1 0 0"/>
       <limit effort="0.0" lower="-3.14159" upper="3.14159" velocity="0.0"/>
    </joint>
    <joint name="Leg2_Leg5" type="revolute">
       <parent link="Leg2"/>
       <child  link="Leg5"/>
       <origin rpy="0 0 0" xyz="1.421354348568046 1.0502732175863265 0" />
     <axis xyz="1 0 0"/>
       <limit effort="0.0" lower="-3.14159" upper="3.14159" velocity="0.0"/>
    </joint>
    <joint name="Leg4_Leg6" type="revolute">
       <parent link="Leg4"/>
       <child  link="Leg6"/>
       <origin rpy="0 0 0" xyz="1.3780171865598647 2.7688691865876 0" />
     <axis xyz="1 0 0"/>
       <limit effort="0.0" lower="-3.14159" upper="3.14159" velocity="0.0"/>
    </joint>
    <joint name="Leg3_Leg7" type="revolute">
       <parent link="Leg3"/>
       <child  link="Leg7"/>
       <origin rpy="0 0 0" xyz="1.2859900057064522 0.9220679870744802 1.4515409930760232" />
     <axis xyz="1 0 0"/>
       <limit effort="0.0" lower="-3.14159" upper="3.14159" velocity="0.0"/>
    </joint>
    <joint name="Leg7_Leg8" type="revolute">
       <parent link="Leg7"/>
       <child  link="Leg8"/>
       <origin rpy="0 0 0" xyz="0.5730464216555398 2.7314184962660164 0" />
     <axis xyz="1 0 0"/>
       <limit effort="0.0" lower="-3.14159" upper="3.14159" velocity="0.0"/>
    </joint>
    <joint name="Leg6_Leg9" type="revolute">
       <parent link="Leg6"/>
       <child  link="Leg9"/>
       <origin rpy="0 0 0" xyz="0.505851228771382 0.8207306163505367 1.2047848602194307" />
     <axis xyz="1 0 0"/>
       <limit effort="0.0" lower="-3.14159" upper="3.14159" velocity="0.0"/>
    </joint>
    <joint name="Leg2_Leg10" type="revolute">
       <parent link="Leg2"/>
       <child  link="Leg10"/>
       <origin rpy="0 0 0" xyz="1.421354348568046 1.0502732175863265 0" />
     <axis xyz="1 0 0"/>
       <limit effort="0.0" lower="-3.14159" upper="3.14159" velocity="0.0"/>
    </joint>
    <joint name="Torso_Leg11" type="revolute">
       <parent link="Torso"/>
       <child  link="Leg11"/>
       <origin rpy="0 0 0" xyz="0.6467971178137076 0.7051997746470424 1.3992433500704369" />
     <axis xyz="1 0 0"/>
       <limit effort="0.0" lower="-3.14159" upper="3.14159" velocity="0.0"/>
    </joint>
    <joint name="Leg7_Leg12" type="revolute">
       <parent link="Leg7"/>
       <child  link="Leg12"/>
       <origin rpy="0 0 0" xyz="0.5730464216555398 2.7314184962660164 0" />
     <axis xyz="1 0 0"/>
       <limit effort="0.0" lower="-3.14159" upper="3.14159" velocity="0.0"/>
    </joint>
    <joint name="Leg4_Leg13" type="revolute">
       <parent link="Leg4"/>
       <child  link="Leg13"/>
       <origin rpy="0 0 0" xyz="1.3780171865598647 2.7688691865876 0" />
     <axis xyz="1 0 0"/>
       <limit effort="0.0" lower="-3.14159" upper="3.14159" velocity="0.0"/>
    </joint>
    <joint name="Leg1_Leg14" type="revolute">
       <parent link="Leg1"/>
       <child  link="Leg14"/>
       <origin rpy="0 0 0" xyz="0.7956675045030784 1.2945198830543232 1.327886777756135" />
     <axis xyz="1 0 0"/>
       <limit effort="0.0" lower="-3.14159" upper="3.14159" velocity="0.0"/>
    </joint>
    <joint name="Leg11_Leg15" type="revolute">
       <parent link="Leg11"/>
       <child  link="Leg15"/>
       <origin rpy="0 0 0" xyz="0.6643419164074972 0.6123101189462261 0" />
     <axis xyz="1 0 0"/>
       <limit effort="0.0" lower="-3.14159" upper="3.14159" velocity="0.0"/>
    </joint>
    <joint name="Leg6_Leg16" type="revolute">
       <parent link="Leg6"/>
       <child  link="Leg16"/>
       <origin rpy="0 0 0" xyz="0.505851228771382 0.8207306163505367 1.2047848602194307" />
     <axis xyz="1 0 0"/>
       <limit effort="0.0" lower="-3.14159" upper="3.14159" velocity="0.0"/>
    </joint>
    <joint name="Leg15_Leg17" type="revolute">
       <parent link="Leg15"/>
       <child  link="Leg17"/>
       <origin rpy="0 0 0" xyz="1.0925128367188082 0 1.152570751091337" />
     <axis xyz="1 0 0"/>
       <limit effort="0.0" lower="-3.14159" upper="3.14159" velocity="0.0"/>
    </joint>
    <joint name="Leg3_Leg18" type="revolute">
       <parent link="Leg3"/>
       <child  link="Leg18"/>
       <origin rpy="0 0 0" xyz="1.2859900057064522 0.9220679870744802 1.4515409930760232" />
     <axis xyz="1 0 0"/>
       <limit effort="0.0" lower="-3.14159" upper="3.14159" velocity="0.0"/>
    </joint>
    <joint name="Leg15_Leg19" type="revolute">
       <parent link="Leg15"/>
       <child  link="Leg19"/>
       <origin rpy="0 0 0" xyz="1.0925128367188082 0 1.152570751091337" />
     <axis xyz="1 0 0"/>
       <limit effort="0.0" lower="-3.14159" upper="3.14159" velocity="0.0"/>
    </joint>
    <joint name="Leg14_Leg20" type="revolute">
       <parent link="Leg14"/>
       <child  link="Leg20"/>
       <origin rpy="0 0 0" xyz="0 2.362067887351016 0" />
     <axis xyz="1 0 0"/>
       <limit effort="0.0" lower="-3.14159" upper="3.14159" velocity="0.0"/>
    </joint>
    <joint name="Leg19_Leg21" type="revolute">
       <parent link="Leg19"/>
       <child  link="Leg21"/>
       <origin rpy="0 0 0" xyz="0 1.5764778625748925 0" />
     <axis xyz="1 0 0"/>
       <limit effort="0.0" lower="-3.14159" upper="3.14159" velocity="0.0"/>
    </joint>
    <joint name="Leg18_Leg22" type="revolute">
       <parent link="Leg18"/>
       <child  link="Leg22"/>
       <origin rpy="0 0 0" xyz="0 0 2.9754859949898433" />
     <axis xyz="1 0 0"/>
       <limit effort="0.0" lower="-3.14159" upper="3.14159" velocity="0.0"/>
    </joint>
    <joint name="Leg20_Leg23" type="revolute">
       <parent link="Leg20"/>
       <child  link="Leg23"/>
       <origin rpy="0 0 0" xyz="0 1.3632162702077242 0.6827302473075455" />
     <axis xyz="1 0 0"/>
       <limit effort="0.0" lower="-3.14159" upper="3.14159" velocity="0.0"/>
    </joint>
    <joint name="Leg17_Leg24" type="revolute">
       <parent link="Leg17"/>
       <child  link="Leg24"/>
       <origin rpy="0 0 0" xyz="1.363371594235268 0 0" />
     <axis xyz="1 0 0"/>
       <limit effort="0.0" lower="-3.14159" upper="3.14159" velocity="0.0"/>
    </joint>
    <joint name="Leg10_Leg25" type="revolute">
       <parent link="Leg10"/>
       <child  link="Leg25"/>
       <origin rpy="0 0 0" xyz="0.7188498547244574 0 1.4914602270311224" />
     <axis xyz="1 0 0"/>
       <limit effort="0.0" lower="-3.14159" upper="3.14159" velocity="0.0"/>
    </joint>
    <joint name="Leg24_Leg26" type="revolute">
       <parent link="Leg24"/>
       <child  link="Leg26"/>
       <origin rpy="0 0 0" xyz="1.4089518408004504 0 0.7099710112126489" />
     <axis xyz="1 0 0"/>
       <limit effort="0.0" lower="-3.14159" upper="3.14159" velocity="0.0"/>
    </joint>
    <joint name="Leg26_Leg27" type="revolute">
       <parent link="Leg26"/>
       <child  link="Leg26"/>
       <origin rpy="0 0 0" xyz="0 1.329579542962995 0.9997400490708113" />
     <axis xyz="1 0 0"/>
       <limit effort="0.0" lower="-3.14159" upper="3.14159" velocity="0.0"/>
    </joint>
</robot>