<robot name = "robot">
    <link name="Torso">
        <inertial>
            <origin xyz="0 0 1.397407698452366" rpy="0 0 0"/>
            <mass value="1" />
            <inertia ixx="100" ixy="0" ixz="0" iyy="100" iyz="0" izz="100" />
        </inertial>
        <visual>
            <origin xyz="0 0 1.397407698452366" rpy="0 0 0"/>
            <geometry>
                <box size="2.404764268447493 2.596954660107914 2.794815396904732" />
            </geometry>
            <material name="Green">
                <color rgba="0 180.0 0.0 1.0"/>
            </material>
        </visual>
        <collision>
            <origin xyz="0 0 1.397407698452366" rpy="0 0 0"/>
            <geometry>
                <box size="2.404764268447493 2.596954660107914 2.794815396904732" />
            </geometry>
        </collision>
    </link>
    <link name="Leg1">
        <inertial>
            <origin xyz="0.9191950398358623 0 0" rpy="0 0 0"/>
            <mass value="1" />
            <inertia ixx="100" ixy="0" ixz="0" iyy="100" iyz="0" izz="100" />
        </inertial>
        <visual>
            <origin xyz="0.9191950398358623 0 0" rpy="0 0 0"/>
            <geometry>
                <box size="1.8383900796717245 2.202245223620334 1.1432683236204808" />
            </geometry>
            <material name="Blue">
                <color rgba="0 1.0 1.0 1.0"/>
            </material>
        </visual>
        <collision>
            <origin xyz="0.9191950398358623 0 0" rpy="0 0 0"/>
            <geometry>
                <box size="1.8383900796717245 2.202245223620334 1.1432683236204808" />
            </geometry>
        </collision>
    </link>
    <link name="Leg2">
        <inertial>
            <origin xyz="0.6432909784817455 0 0" rpy="0 0 0"/>
            <mass value="1" />
            <inertia ixx="100" ixy="0" ixz="0" iyy="100" iyz="0" izz="100" />
        </inertial>
        <visual>
            <origin xyz="0.6432909784817455 0 0" rpy="0 0 0"/>
            <geometry>
                <box size="1.286581956963491 2.491366725503575 2.4942378094732223" />
            </geometry>
            <material name="Blue">
                <color rgba="0 1.0 1.0 1.0"/>
            </material>
        </visual>
        <collision>
            <origin xyz="0.6432909784817455 0 0" rpy="0 0 0"/>
            <geometry>
                <box size="1.286581956963491 2.491366725503575 2.4942378094732223" />
            </geometry>
        </collision>
    </link>
    <link name="Leg3">
        <inertial>
            <origin xyz="0 0 0.9764625184166162" rpy="0 0 0"/>
            <mass value="1" />
            <inertia ixx="100" ixy="0" ixz="0" iyy="100" iyz="0" izz="100" />
        </inertial>
        <visual>
            <origin xyz="0 0 0.9764625184166162" rpy="0 0 0"/>
            <geometry>
                <box size="2.886873062973298 2.2700146184597836 1.9529250368332325" />
            </geometry>
            <material name="Blue">
                <color rgba="0 1.0 1.0 1.0"/>
            </material>
        </visual>
        <collision>
            <origin xyz="0 0 0.9764625184166162" rpy="0 0 0"/>
            <geometry>
                <box size="2.886873062973298 2.2700146184597836 1.9529250368332325" />
            </geometry>
        </collision>
    </link>
    <link name="Leg4">
        <inertial>
            <origin xyz="0 0.5779214562400636 0" rpy="0 0 0"/>
            <mass value="1" />
            <inertia ixx="100" ixy="0" ixz="0" iyy="100" iyz="0" izz="100" />
        </inertial>
        <visual>
            <origin xyz="0 0.5779214562400636 0" rpy="0 0 0"/>
            <geometry>
                <box size="1.4545843789531419 1.1558429124801273 2.034645078801372" />
            </geometry>
            <material name="Green">
                <color rgba="0 180.0 0.0 1.0"/>
            </material>
        </visual>
        <collision>
            <origin xyz="0 0.5779214562400636 0" rpy="0 0 0"/>
            <geometry>
                <box size="1.4545843789531419 1.1558429124801273 2.034645078801372" />
            </geometry>
        </collision>
    </link>
    <link name="Leg5">
        <inertial>
            <origin xyz="0 1.3690234868318631 0" rpy="0 0 0"/>
            <mass value="1" />
            <inertia ixx="100" ixy="0" ixz="0" iyy="100" iyz="0" izz="100" />
        </inertial>
        <visual>
            <origin xyz="0 1.3690234868318631 0" rpy="0 0 0"/>
            <geometry>
                <box size="2.419393897355693 2.7380469736637263 2.5943977719589704" />
            </geometry>
            <material name="Green">
                <color rgba="0 180.0 0.0 1.0"/>
            </material>
        </visual>
        <collision>
            <origin xyz="0 1.3690234868318631 0" rpy="0 0 0"/>
            <geometry>
                <box size="2.419393897355693 2.7380469736637263 2.5943977719589704" />
            </geometry>
        </collision>
    </link>
    <link name="Leg6">
        <inertial>
            <origin xyz="0 1.4540707164697608 0" rpy="0 0 0"/>
            <mass value="1" />
            <inertia ixx="100" ixy="0" ixz="0" iyy="100" iyz="0" izz="100" />
        </inertial>
        <visual>
            <origin xyz="0 1.4540707164697608 0" rpy="0 0 0"/>
            <geometry>
                <box size="2.533965309051335 2.9081414329395217 1.2020795297078979" />
            </geometry>
            <material name="Green">
                <color rgba="0 180.0 0.0 1.0"/>
            </material>
        </visual>
        <collision>
            <origin xyz="0 1.4540707164697608 0" rpy="0 0 0"/>
            <geometry>
                <box size="2.533965309051335 2.9081414329395217 1.2020795297078979" />
            </geometry>
        </collision>
    </link>
    <link name="Leg7">
        <inertial>
            <origin xyz="0.5746446270037153 0 0" rpy="0 0 0"/>
            <mass value="1" />
            <inertia ixx="100" ixy="0" ixz="0" iyy="100" iyz="0" izz="100" />
        </inertial>
        <visual>
            <origin xyz="0.5746446270037153 0 0" rpy="0 0 0"/>
            <geometry>
                <box size="1.1492892540074306 2.3122353950790258 1.5930917142808316" />
            </geometry>
            <material name="Blue">
                <color rgba="0 1.0 1.0 1.0"/>
            </material>
        </visual>
        <collision>
            <origin xyz="0.5746446270037153 0 0" rpy="0 0 0"/>
            <geometry>
                <box size="1.1492892540074306 2.3122353950790258 1.5930917142808316" />
            </geometry>
        </collision>
    </link>
    <link name="Leg8">
        <inertial>
            <origin xyz="1.369727446110413 0 0" rpy="0 0 0"/>
            <mass value="1" />
            <inertia ixx="100" ixy="0" ixz="0" iyy="100" iyz="0" izz="100" />
        </inertial>
        <visual>
            <origin xyz="1.369727446110413 0 0" rpy="0 0 0"/>
            <geometry>
                <box size="2.739454892220826 2.6961617546828642 2.553515970783053" />
            </geometry>
            <material name="Blue">
                <color rgba="0 1.0 1.0 1.0"/>
            </material>
        </visual>
        <collision>
            <origin xyz="1.369727446110413 0 0" rpy="0 0 0"/>
            <geometry>
                <box size="2.739454892220826 2.6961617546828642 2.553515970783053" />
            </geometry>
        </collision>
    </link>
    <link name="Leg9">
        <inertial>
            <origin xyz="1.1253556142530123 0 0" rpy="0 0 0"/>
            <mass value="1" />
            <inertia ixx="100" ixy="0" ixz="0" iyy="100" iyz="0" izz="100" />
        </inertial>
        <visual>
            <origin xyz="1.1253556142530123 0 0" rpy="0 0 0"/>
            <geometry>
                <box size="2.2507112285060247 2.4963387592946122 1.4287809474795188" />
            </geometry>
            <material name="Blue">
                <color rgba="0 1.0 1.0 1.0"/>
            </material>
        </visual>
        <collision>
            <origin xyz="1.1253556142530123 0 0" rpy="0 0 0"/>
            <geometry>
                <box size="2.2507112285060247 2.4963387592946122 1.4287809474795188" />
            </geometry>
        </collision>
    </link>
    <link name="Leg10">
        <inertial>
            <origin xyz="0 1.158534569156576 0" rpy="0 0 0"/>
            <mass value="1" />
            <inertia ixx="100" ixy="0" ixz="0" iyy="100" iyz="0" izz="100" />
        </inertial>
        <visual>
            <origin xyz="0 1.158534569156576 0" rpy="0 0 0"/>
            <geometry>
                <box size="2.1114762446664557 2.317069138313152 1.512351197204536" />
            </geometry>
            <material name="Green">
                <color rgba="0 180.0 0.0 1.0"/>
            </material>
        </visual>
        <collision>
            <origin xyz="0 1.158534569156576 0" rpy="0 0 0"/>
            <geometry>
                <box size="2.1114762446664557 2.317069138313152 1.512351197204536" />
            </geometry>
        </collision>
    </link>
    <link name="Leg11">
        <inertial>
            <origin xyz="0 1.1578102585620598 0" rpy="0 0 0"/>
            <mass value="1" />
            <inertia ixx="100" ixy="0" ixz="0" iyy="100" iyz="0" izz="100" />
        </inertial>
        <visual>
            <origin xyz="0 1.1578102585620598 0" rpy="0 0 0"/>
            <geometry>
                <box size="1.1359497596545072 2.3156205171241195 2.9217643311648738" />
            </geometry>
            <material name="Blue">
                <color rgba="0 1.0 1.0 1.0"/>
            </material>
        </visual>
        <collision>
            <origin xyz="0 1.1578102585620598 0" rpy="0 0 0"/>
            <geometry>
                <box size="1.1359497596545072 2.3156205171241195 2.9217643311648738" />
            </geometry>
        </collision>
    </link>
    <link name="Leg12">
        <inertial>
            <origin xyz="0 0 0.7909633938761885" rpy="0 0 0"/>
            <mass value="1" />
            <inertia ixx="100" ixy="0" ixz="0" iyy="100" iyz="0" izz="100" />
        </inertial>
        <visual>
            <origin xyz="0 0 0.7909633938761885" rpy="0 0 0"/>
            <geometry>
                <box size="1.7372901518508337 1.3678083651157902 1.581926787752377" />
            </geometry>
            <material name="Green">
                <color rgba="0 180.0 0.0 1.0"/>
            </material>
        </visual>
        <collision>
            <origin xyz="0 0 0.7909633938761885" rpy="0 0 0"/>
            <geometry>
                <box size="1.7372901518508337 1.3678083651157902 1.581926787752377" />
            </geometry>
        </collision>
    </link>
    <link name="Leg13">
        <inertial>
            <origin xyz="0 0 0.7751101708126534" rpy="0 0 0"/>
            <mass value="1" />
            <inertia ixx="100" ixy="0" ixz="0" iyy="100" iyz="0" izz="100" />
        </inertial>
        <visual>
            <origin xyz="0 0 0.7751101708126534" rpy="0 0 0"/>
            <geometry>
                <box size="2.021843419039364 2.4064247153184857 1.5502203416253069" />
            </geometry>
            <material name="Green">
                <color rgba="0 180.0 0.0 1.0"/>
            </material>
        </visual>
        <collision>
            <origin xyz="0 0 0.7751101708126534" rpy="0 0 0"/>
            <geometry>
                <box size="2.021843419039364 2.4064247153184857 1.5502203416253069" />
            </geometry>
        </collision>
    </link>
    <link name="Leg14">
        <inertial>
            <origin xyz="1.2643996415349168 0 0" rpy="0 0 0"/>
            <mass value="1" />
            <inertia ixx="100" ixy="0" ixz="0" iyy="100" iyz="0" izz="100" />
        </inertial>
        <visual>
            <origin xyz="1.2643996415349168 0 0" rpy="0 0 0"/>
            <geometry>
                <box size="2.5287992830698336 2.685062683229505 1.3630299556875194" />
            </geometry>
            <material name="Green">
                <color rgba="0 180.0 0.0 1.0"/>
            </material>
        </visual>
        <collision>
            <origin xyz="1.2643996415349168 0 0" rpy="0 0 0"/>
            <geometry>
                <box size="2.5287992830698336 2.685062683229505 1.3630299556875194" />
            </geometry>
        </collision>
    </link>
    <link name="Leg15">
        <inertial>
            <origin xyz="0.8119681319987447 0 0" rpy="0 0 0"/>
            <mass value="1" />
            <inertia ixx="100" ixy="0" ixz="0" iyy="100" iyz="0" izz="100" />
        </inertial>
        <visual>
            <origin xyz="0.8119681319987447 0 0" rpy="0 0 0"/>
            <geometry>
                <box size="1.6239362639974895 1.0839982058201627 2.946784640704358" />
            </geometry>
            <material name="Green">
                <color rgba="0 180.0 0.0 1.0"/>
            </material>
        </visual>
        <collision>
            <origin xyz="0.8119681319987447 0 0" rpy="0 0 0"/>
            <geometry>
                <box size="1.6239362639974895 1.0839982058201627 2.946784640704358" />
            </geometry>
        </collision>
    </link>
    <link name="Leg16">
        <inertial>
            <origin xyz="0 1.3136011715041263 0" rpy="0 0 0"/>
            <mass value="1" />
            <inertia ixx="100" ixy="0" ixz="0" iyy="100" iyz="0" izz="100" />
        </inertial>
        <visual>
            <origin xyz="0 1.3136011715041263 0" rpy="0 0 0"/>
            <geometry>
                <box size="2.1592430468029047 2.6272023430082525 2.242720457078133" />
            </geometry>
            <material name="Blue">
                <color rgba="0 1.0 1.0 1.0"/>
            </material>
        </visual>
        <collision>
            <origin xyz="0 1.3136011715041263 0" rpy="0 0 0"/>
            <geometry>
                <box size="2.1592430468029047 2.6272023430082525 2.242720457078133" />
            </geometry>
        </collision>
    </link>
    <link name="Leg17">
        <inertial>
            <origin xyz="1.2657416254115135 0 0" rpy="0 0 0"/>
            <mass value="1" />
            <inertia ixx="100" ixy="0" ixz="0" iyy="100" iyz="0" izz="100" />
        </inertial>
        <visual>
            <origin xyz="1.2657416254115135 0 0" rpy="0 0 0"/>
            <geometry>
                <box size="2.531483250823027 2.18277489059271 2.9803956234447133" />
            </geometry>
            <material name="Blue">
                <color rgba="0 1.0 1.0 1.0"/>
            </material>
        </visual>
        <collision>
            <origin xyz="1.2657416254115135 0 0" rpy="0 0 0"/>
            <geometry>
                <box size="2.531483250823027 2.18277489059271 2.9803956234447133" />
            </geometry>
        </collision>
    </link>
    <link name="Leg18">
        <inertial>
            <origin xyz="0 0 1.1976675232187213" rpy="0 0 0"/>
            <mass value="1" />
            <inertia ixx="100" ixy="0" ixz="0" iyy="100" iyz="0" izz="100" />
        </inertial>
        <visual>
            <origin xyz="0 0 1.1976675232187213" rpy="0 0 0"/>
            <geometry>
                <box size="1.2922400862406507 1.67718850221924 2.3953350464374425" />
            </geometry>
            <material name="Green">
                <color rgba="0 180.0 0.0 1.0"/>
            </material>
        </visual>
        <collision>
            <origin xyz="0 0 1.1976675232187213" rpy="0 0 0"/>
            <geometry>
                <box size="1.2922400862406507 1.67718850221924 2.3953350464374425" />
            </geometry>
        </collision>
    </link>
    <link name="Leg19">
        <inertial>
            <origin xyz="0 0.678206227301836 0" rpy="0 0 0"/>
            <mass value="1" />
            <inertia ixx="100" ixy="0" ixz="0" iyy="100" iyz="0" izz="100" />
        </inertial>
        <visual>
            <origin xyz="0 0.678206227301836 0" rpy="0 0 0"/>
            <geometry>
                <box size="2.8347028051702763 1.356412454603672 1.0562042247864771" />
            </geometry>
            <material name="Green">
                <color rgba="0 180.0 0.0 1.0"/>
            </material>
        </visual>
        <collision>
            <origin xyz="0 0.678206227301836 0" rpy="0 0 0"/>
            <geometry>
                <box size="2.8347028051702763 1.356412454603672 1.0562042247864771" />
            </geometry>
        </collision>
    </link>
    <link name="Leg20">
        <inertial>
            <origin xyz="0 0 0.532241636130236" rpy="0 0 0"/>
            <mass value="1" />
            <inertia ixx="100" ixy="0" ixz="0" iyy="100" iyz="0" izz="100" />
        </inertial>
        <visual>
            <origin xyz="0 0 0.532241636130236" rpy="0 0 0"/>
            <geometry>
                <box size="2.475805167727147 1.926020562397622 1.064483272260472" />
            </geometry>
            <material name="Green">
                <color rgba="0 180.0 0.0 1.0"/>
            </material>
        </visual>
        <collision>
            <origin xyz="0 0 0.532241636130236" rpy="0 0 0"/>
            <geometry>
                <box size="2.475805167727147 1.926020562397622 1.064483272260472" />
            </geometry>
        </collision>
    </link>
    <link name="Leg21">
        <inertial>
            <origin xyz="1.074380897357691 0 0" rpy="0 0 0"/>
            <mass value="1" />
            <inertia ixx="100" ixy="0" ixz="0" iyy="100" iyz="0" izz="100" />
        </inertial>
        <visual>
            <origin xyz="1.074380897357691 0 0" rpy="0 0 0"/>
            <geometry>
                <box size="2.148761794715382 1.6942496541079408 2.134959642831416" />
            </geometry>
            <material name="Blue">
                <color rgba="0 1.0 1.0 1.0"/>
            </material>
        </visual>
        <collision>
            <origin xyz="1.074380897357691 0 0" rpy="0 0 0"/>
            <geometry>
                <box size="2.148761794715382 1.6942496541079408 2.134959642831416" />
            </geometry>
        </collision>
    </link>
    <link name="Leg22">
        <inertial>
            <origin xyz="1.440739416147879 0 0" rpy="0 0 0"/>
            <mass value="1" />
            <inertia ixx="100" ixy="0" ixz="0" iyy="100" iyz="0" izz="100" />
        </inertial>
        <visual>
            <origin xyz="1.440739416147879 0 0" rpy="0 0 0"/>
            <geometry>
                <box size="2.881478832295758 1.6374788018869781 1.916118819387374" />
            </geometry>
            <material name="Green">
                <color rgba="0 180.0 0.0 1.0"/>
            </material>
        </visual>
        <collision>
            <origin xyz="1.440739416147879 0 0" rpy="0 0 0"/>
            <geometry>
                <box size="2.881478832295758 1.6374788018869781 1.916118819387374" />
            </geometry>
        </collision>
    </link>
    <link name="Leg23">
        <inertial>
            <origin xyz="0 1.221758004521182 0" rpy="0 0 0"/>
            <mass value="1" />
            <inertia ixx="100" ixy="0" ixz="0" iyy="100" iyz="0" izz="100" />
        </inertial>
        <visual>
            <origin xyz="0 1.221758004521182 0" rpy="0 0 0"/>
            <geometry>
                <box size="1.3497833231217382 2.443516009042364 1.4009786352889035" />
            </geometry>
            <material name="Blue">
                <color rgba="0 1.0 1.0 1.0"/>
            </material>
        </visual>
        <collision>
            <origin xyz="0 1.221758004521182 0" rpy="0 0 0"/>
            <geometry>
                <box size="1.3497833231217382 2.443516009042364 1.4009786352889035" />
            </geometry>
        </collision>
    </link>
    <link name="Leg24">
        <inertial>
            <origin xyz="1.2963653209435244 0 0" rpy="0 0 0"/>
            <mass value="1" />
            <inertia ixx="100" ixy="0" ixz="0" iyy="100" iyz="0" izz="100" />
        </inertial>
        <visual>
            <origin xyz="1.2963653209435244 0 0" rpy="0 0 0"/>
            <geometry>
                <box size="2.592730641887049 1.0787307830460777 1.8795148051511434" />
            </geometry>
            <material name="Blue">
                <color rgba="0 1.0 1.0 1.0"/>
            </material>
        </visual>
        <collision>
            <origin xyz="1.2963653209435244 0 0" rpy="0 0 0"/>
            <geometry>
                <box size="2.592730641887049 1.0787307830460777 1.8795148051511434" />
            </geometry>
        </collision>
    </link>
    <link name="Leg25">
        <inertial>
            <origin xyz="1.3095314279886812 0 0" rpy="0 0 0"/>
            <mass value="1" />
            <inertia ixx="100" ixy="0" ixz="0" iyy="100" iyz="0" izz="100" />
        </inertial>
        <visual>
            <origin xyz="1.3095314279886812 0 0" rpy="0 0 0"/>
            <geometry>
                <box size="2.6190628559773623 1.7462285275902885 2.022016401684678" />
            </geometry>
            <material name="Blue">
                <color rgba="0 1.0 1.0 1.0"/>
            </material>
        </visual>
        <collision>
            <origin xyz="1.3095314279886812 0 0" rpy="0 0 0"/>
            <geometry>
                <box size="2.6190628559773623 1.7462285275902885 2.022016401684678" />
            </geometry>
        </collision>
    </link>
    <link name="Leg26">
        <inertial>
            <origin xyz="0 0 1.2885270104242736" rpy="0 0 0"/>
            <mass value="1" />
            <inertia ixx="100" ixy="0" ixz="0" iyy="100" iyz="0" izz="100" />
        </inertial>
        <visual>
            <origin xyz="0 0 1.2885270104242736" rpy="0 0 0"/>
            <geometry>
                <box size="1.961346142583445 1.9345434390925746 2.5770540208485473" />
            </geometry>
            <material name="Blue">
                <color rgba="0 1.0 1.0 1.0"/>
            </material>
        </visual>
        <collision>
            <origin xyz="0 0 1.2885270104242736" rpy="0 0 0"/>
            <geometry>
                <box size="1.961346142583445 1.9345434390925746 2.5770540208485473" />
            </geometry>
        </collision>
    </link>
    <link name="Leg27">
        <inertial>
            <origin xyz="1.3479184216859876 0 0" rpy="0 0 0"/>
            <mass value="1" />
            <inertia ixx="100" ixy="0" ixz="0" iyy="100" iyz="0" izz="100" />
        </inertial>
        <visual>
            <origin xyz="1.3479184216859876 0 0" rpy="0 0 0"/>
            <geometry>
                <box size="2.6958368433719753 2.7163703031318738 1.0840193528794533" />
            </geometry>
            <material name="Blue">
                <color rgba="0 1.0 1.0 1.0"/>
            </material>
        </visual>
        <collision>
            <origin xyz="1.3479184216859876 0 0" rpy="0 0 0"/>
            <geometry>
                <box size="2.6958368433719753 2.7163703031318738 1.0840193528794533" />
            </geometry>
        </collision>
    </link>
    <joint name="Torso_Leg1" type="revolute">
       <parent link="Torso"/>
       <child  link="Leg1"/>
       <origin rpy="0 0 0" xyz="1.2023821342237464 0 1.397407698452366" />
     <axis xyz="1 0 0"/>
       <limit effort="0.0" lower="-3.14159" upper="3.14159" velocity="0.0"/>
    </joint>
    <joint name="Leg1_Leg2" type="revolute">
       <parent link="Leg1"/>
       <child  link="Leg2"/>
       <origin rpy="0 0 0" xyz="1.286581956963491 0 0" />
     <axis xyz="1 0 0"/>
       <limit effort="0.0" lower="-3.14159" upper="3.14159" velocity="0.0"/>
    </joint>
    <joint name="Leg1_Leg3" type="revolute">
       <parent link="Leg1"/>
       <child  link="Leg3"/>
       <origin rpy="0 0 0" xyz="1.286581956963491 0 1.2471189047366111" />
     <axis xyz="1 0 0"/>
       <limit effort="0.0" lower="-3.14159" upper="3.14159" velocity="0.0"/>
    </joint>
    <joint name="Leg1_Leg4" type="revolute">
       <parent link="Leg1"/>
       <child  link="Leg4"/>
       <origin rpy="0 0 0" xyz="1.286581956963491 1.2456833627517876 1.2471189047366111" />
     <axis xyz="1 0 0"/>
       <limit effort="0.0" lower="-3.14159" upper="3.14159" velocity="0.0"/>
    </joint>
    <joint name="Torso_Leg5" type="revolute">
       <parent link="Torso"/>
       <child  link="Leg5"/>
       <origin rpy="0 0 0" xyz="0.9191950398358623 1.101122611810167 0" />
     <axis xyz="1 0 0"/>
       <limit effort="0.0" lower="-3.14159" upper="3.14159" velocity="0.0"/>
    </joint>
    <joint name="Leg3_Leg6" type="revolute">
       <parent link="Leg3"/>
       <child  link="Leg6"/>
       <origin rpy="0 0 0" xyz="0 1.1558429124801273 0" />
     <axis xyz="1 0 0"/>
       <limit effort="0.0" lower="-3.14159" upper="3.14159" velocity="0.0"/>
    </joint>
    <joint name="Leg5_Leg7" type="revolute">
       <parent link="Leg5"/>
       <child  link="Leg7"/>
       <origin rpy="0 0 0" xyz="1.2669826545256675 1.4540707164697608 0" />
     <axis xyz="1 0 0"/>
       <limit effort="0.0" lower="-3.14159" upper="3.14159" velocity="0.0"/>
    </joint>
    <joint name="Leg6_Leg8" type="revolute">
       <parent link="Leg6"/>
       <child  link="Leg8"/>
       <origin rpy="0 0 0" xyz="1.1492892540074306 0 0" />
     <axis xyz="1 0 0"/>
       <limit effort="0.0" lower="-3.14159" upper="3.14159" velocity="0.0"/>
    </joint>
    <joint name="Leg4_Leg9" type="revolute">
       <parent link="Leg4"/>
       <child  link="Leg9"/>
       <origin rpy="0 0 0" xyz="1.2096969486778466 1.3690234868318631 0" />
     <axis xyz="1 0 0"/>
       <limit effort="0.0" lower="-3.14159" upper="3.14159" velocity="0.0"/>
    </joint>
    <joint name="Leg6_Leg10" type="revolute">
       <parent link="Leg6"/>
       <child  link="Leg10"/>
       <origin rpy="0 0 0" xyz="1.1492892540074306 1.1561176975395129 0" />
     <axis xyz="1 0 0"/>
       <limit effort="0.0" lower="-3.14159" upper="3.14159" velocity="0.0"/>
    </joint>
    <joint name="Leg2_Leg11" type="revolute">
       <parent link="Leg2"/>
       <child  link="Leg11"/>
       <origin rpy="0 0 0" xyz="0 1.1350073092298918 0.9764625184166162" />
     <axis xyz="1 0 0"/>
       <limit effort="0.0" lower="-3.14159" upper="3.14159" velocity="0.0"/>
    </joint>
    <joint name="Leg6_Leg12" type="revolute">
       <parent link="Leg6"/>
       <child  link="Leg12"/>
       <origin rpy="0 0 0" xyz="1.1492892540074306 1.1561176975395129 0.7965458571404158" />
     <axis xyz="1 0 0"/>
       <limit effort="0.0" lower="-3.14159" upper="3.14159" velocity="0.0"/>
    </joint>
    <joint name="Leg10_Leg13" type="revolute">
       <parent link="Leg10"/>
       <child  link="Leg13"/>
       <origin rpy="0 0 0" xyz="0 1.1578102585620598 1.4608821655824369" />
     <axis xyz="1 0 0"/>
       <limit effort="0.0" lower="-3.14159" upper="3.14159" velocity="0.0"/>
    </joint>
    <joint name="Leg13_Leg14" type="revolute">
       <parent link="Leg13"/>
       <child  link="Leg14"/>
       <origin rpy="0 0 0" xyz="2.5287992830698336 0 0" />
     <axis xyz="1 0 0"/>
       <limit effort="0.0" lower="-3.14159" upper="3.14159" velocity="0.0"/>
    </joint>
    <joint name="Leg3_Leg15" type="revolute">
       <parent link="Leg3"/>
       <child  link="Leg15"/>
       <origin rpy="0 0 0" xyz="0.7272921894765709 1.1558429124801273 0" />
     <axis xyz="1 0 0"/>
       <limit effort="0.0" lower="-3.14159" upper="3.14159" velocity="0.0"/>
    </joint>
    <joint name="Leg14_Leg16" type="revolute">
       <parent link="Leg14"/>
       <child  link="Leg16"/>
       <origin rpy="0 0 0" xyz="0.8119681319987447 0.5419991029100814 0" />
     <axis xyz="1 0 0"/>
       <limit effort="0.0" lower="-3.14159" upper="3.14159" velocity="0.0"/>
    </joint>
    <joint name="Leg10_Leg17" type="revolute">
       <parent link="Leg10"/>
       <child  link="Leg17"/>
       <origin rpy="0 0 0" xyz="0.5679748798272536 1.1578102585620598 1.4608821655824369" />
     <axis xyz="1 0 0"/>
       <limit effort="0.0" lower="-3.14159" upper="3.14159" velocity="0.0"/>
    </joint>
    <joint name="Leg14_Leg18" type="revolute">
       <parent link="Leg14"/>
       <child  link="Leg18"/>
       <origin rpy="0 0 0" xyz="0.8119681319987447 0.5419991029100814 1.473392320352179" />
     <axis xyz="1 0 0"/>
       <limit effort="0.0" lower="-3.14159" upper="3.14159" velocity="0.0"/>
    </joint>
    <joint name="Leg11_Leg19" type="revolute">
       <parent link="Leg11"/>
       <child  link="Leg19"/>
       <origin rpy="0 0 0" xyz="0 0.6839041825578951 0.7909633938761885" />
     <axis xyz="1 0 0"/>
       <limit effort="0.0" lower="-3.14159" upper="3.14159" velocity="0.0"/>
    </joint>
    <joint name="Leg7_Leg20" type="revolute">
       <parent link="Leg7"/>
       <child  link="Leg20"/>
       <origin rpy="0 0 0" xyz="1.369727446110413 0 1.2767579853915265" />
     <axis xyz="1 0 0"/>
       <limit effort="0.0" lower="-3.14159" upper="3.14159" velocity="0.0"/>
    </joint>
    <joint name="Leg16_Leg21" type="revolute">
       <parent link="Leg16"/>
       <child  link="Leg21"/>
       <origin rpy="0 0 0" xyz="2.531483250823027 0 0" />
     <axis xyz="1 0 0"/>
       <limit effort="0.0" lower="-3.14159" upper="3.14159" velocity="0.0"/>
    </joint>
    <joint name="Leg11_Leg22" type="revolute">
       <parent link="Leg11"/>
       <child  link="Leg22"/>
       <origin rpy="0 0 0" xyz="0.8686450759254168 0.6839041825578951 0.7909633938761885" />
     <axis xyz="1 0 0"/>
       <limit effort="0.0" lower="-3.14159" upper="3.14159" velocity="0.0"/>
    </joint>
    <joint name="Leg18_Leg23" type="revolute">
       <parent link="Leg18"/>
       <child  link="Leg23"/>
       <origin rpy="0 0 0" xyz="0 1.356412454603672 0" />
     <axis xyz="1 0 0"/>
       <limit effort="0.0" lower="-3.14159" upper="3.14159" velocity="0.0"/>
    </joint>
    <joint name="Leg23_Leg24" type="revolute">
       <parent link="Leg23"/>
       <child  link="Leg24"/>
       <origin rpy="0 0 0" xyz="2.592730641887049 0 0" />
     <axis xyz="1 0 0"/>
       <limit effort="0.0" lower="-3.14159" upper="3.14159" velocity="0.0"/>
    </joint>
    <joint name="Leg19_Leg25" type="revolute">
       <parent link="Leg19"/>
       <child  link="Leg25"/>
       <origin rpy="0 0 0" xyz="1.2379025838635735 0 0.532241636130236" />
     <axis xyz="1 0 0"/>
       <limit effort="0.0" lower="-3.14159" upper="3.14159" velocity="0.0"/>
    </joint>
    <joint name="Leg5_Leg26" type="revolute">
       <parent link="Leg5"/>
       <child  link="Leg26"/>
       <origin rpy="0 0 0" xyz="1.2669826545256675 1.4540707164697608 0.6010397648539489" />
     <axis xyz="1 0 0"/>
       <limit effort="0.0" lower="-3.14159" upper="3.14159" velocity="0.0"/>
    </joint>
    <joint name="Leg14_Leg27" type="revolute">
       <parent link="Leg14"/>
       <child  link="Leg27"/>
       <origin rpy="0 0 0" xyz="1.6239362639974895 0.5419991029100814 1.473392320352179" />
     <axis xyz="1 0 0"/>
       <limit effort="0.0" lower="-3.14159" upper="3.14159" velocity="0.0"/>
    </joint>
</robot>