<robot name = "robot">
    <link name="Torso">
        <inertial>
            <origin xyz="0 0 1.2658818280718995" rpy="0 0 0"/>
            <mass value="1" />
            <inertia ixx="100" ixy="0" ixz="0" iyy="100" iyz="0" izz="100" />
        </inertial>
        <visual>
            <origin xyz="0 0 1.2658818280718995" rpy="0 0 0"/>
            <geometry>
                <box size="2.033933467510279 1.9176390842574738 2.531763656143799" />
            </geometry>
            <material name="Green">
                <color rgba="0 180.0 0.0 1.0"/>
            </material>
        </visual>
        <collision>
            <origin xyz="0 0 1.2658818280718995" rpy="0 0 0"/>
            <geometry>
                <box size="2.033933467510279 1.9176390842574738 2.531763656143799" />
            </geometry>
        </collision>
    </link>
    <link name="Leg1">
        <inertial>
            <origin xyz="1.149062053143544 0 0" rpy="0 0 0"/>
            <mass value="1" />
            <inertia ixx="100" ixy="0" ixz="0" iyy="100" iyz="0" izz="100" />
        </inertial>
        <visual>
            <origin xyz="1.149062053143544 0 0" rpy="0 0 0"/>
            <geometry>
                <box size="2.298124106287088 1.4417697969145038 2.7911691323779495" />
            </geometry>
            <material name="Blue">
                <color rgba="0 1.0 1.0 1.0"/>
            </material>
        </visual>
        <collision>
            <origin xyz="1.149062053143544 0 0" rpy="0 0 0"/>
            <geometry>
                <box size="2.298124106287088 1.4417697969145038 2.7911691323779495" />
            </geometry>
        </collision>
    </link>
    <link name="Leg2">
        <inertial>
            <origin xyz="0 0.9354931702679977 0" rpy="0 0 0"/>
            <mass value="1" />
            <inertia ixx="100" ixy="0" ixz="0" iyy="100" iyz="0" izz="100" />
        </inertial>
        <visual>
            <origin xyz="0 0.9354931702679977 0" rpy="0 0 0"/>
            <geometry>
                <box size="2.743985060164289 1.8709863405359954 1.4922613974838712" />
            </geometry>
            <material name="Blue">
                <color rgba="0 1.0 1.0 1.0"/>
            </material>
        </visual>
        <collision>
            <origin xyz="0 0.9354931702679977 0" rpy="0 0 0"/>
            <geometry>
                <box size="2.743985060164289 1.8709863405359954 1.4922613974838712" />
            </geometry>
        </collision>
    </link>
    <link name="Leg3">
        <inertial>
            <origin xyz="0 0 1.3160255693252783" rpy="0 0 0"/>
            <mass value="1" />
            <inertia ixx="100" ixy="0" ixz="0" iyy="100" iyz="0" izz="100" />
        </inertial>
        <visual>
            <origin xyz="0 0 1.3160255693252783" rpy="0 0 0"/>
            <geometry>
                <box size="1.2513407495483315 2.2591256252608485 2.6320511386505565" />
            </geometry>
            <material name="Blue">
                <color rgba="0 1.0 1.0 1.0"/>
            </material>
        </visual>
        <collision>
            <origin xyz="0 0 1.3160255693252783" rpy="0 0 0"/>
            <geometry>
                <box size="1.2513407495483315 2.2591256252608485 2.6320511386505565" />
            </geometry>
        </collision>
    </link>
    <link name="Leg4">
        <inertial>
            <origin xyz="0 0 0.6360171379176502" rpy="0 0 0"/>
            <mass value="1" />
            <inertia ixx="100" ixy="0" ixz="0" iyy="100" iyz="0" izz="100" />
        </inertial>
        <visual>
            <origin xyz="0 0 0.6360171379176502" rpy="0 0 0"/>
            <geometry>
                <box size="1.488880738761942 2.551898945927973 1.2720342758353005" />
            </geometry>
            <material name="Green">
                <color rgba="0 180.0 0.0 1.0"/>
            </material>
        </visual>
        <collision>
            <origin xyz="0 0 0.6360171379176502" rpy="0 0 0"/>
            <geometry>
                <box size="1.488880738761942 2.551898945927973 1.2720342758353005" />
            </geometry>
        </collision>
    </link>
    <link name="Leg5">
        <inertial>
            <origin xyz="0.6669778831390901 0 0" rpy="0 0 0"/>
            <mass value="1" />
            <inertia ixx="100" ixy="0" ixz="0" iyy="100" iyz="0" izz="100" />
        </inertial>
        <visual>
            <origin xyz="0.6669778831390901 0 0" rpy="0 0 0"/>
            <geometry>
                <box size="1.3339557662781802 1.077678853944953 1.2637857239263983" />
            </geometry>
            <material name="Green">
                <color rgba="0 180.0 0.0 1.0"/>
            </material>
        </visual>
        <collision>
            <origin xyz="0.6669778831390901 0 0" rpy="0 0 0"/>
            <geometry>
                <box size="1.3339557662781802 1.077678853944953 1.2637857239263983" />
            </geometry>
        </collision>
    </link>
    <link name="Leg6">
        <inertial>
            <origin xyz="1.4269944806007022 0 0" rpy="0 0 0"/>
            <mass value="1" />
            <inertia ixx="100" ixy="0" ixz="0" iyy="100" iyz="0" izz="100" />
        </inertial>
        <visual>
            <origin xyz="1.4269944806007022 0 0" rpy="0 0 0"/>
            <geometry>
                <box size="2.8539889612014044 2.457889040230513 2.394404320450701" />
            </geometry>
            <material name="Blue">
                <color rgba="0 1.0 1.0 1.0"/>
            </material>
        </visual>
        <collision>
            <origin xyz="1.4269944806007022 0 0" rpy="0 0 0"/>
            <geometry>
                <box size="2.8539889612014044 2.457889040230513 2.394404320450701" />
            </geometry>
        </collision>
    </link>
    <link name="Leg7">
        <inertial>
            <origin xyz="0 0.5573876140482988 0" rpy="0 0 0"/>
            <mass value="1" />
            <inertia ixx="100" ixy="0" ixz="0" iyy="100" iyz="0" izz="100" />
        </inertial>
        <visual>
            <origin xyz="0 0.5573876140482988 0" rpy="0 0 0"/>
            <geometry>
                <box size="2.4008115344464347 1.1147752280965977 1.9882470543329638" />
            </geometry>
            <material name="Green">
                <color rgba="0 180.0 0.0 1.0"/>
            </material>
        </visual>
        <collision>
            <origin xyz="0 0.5573876140482988 0" rpy="0 0 0"/>
            <geometry>
                <box size="2.4008115344464347 1.1147752280965977 1.9882470543329638" />
            </geometry>
        </collision>
    </link>
    <link name="Leg8">
        <inertial>
            <origin xyz="0 0 0.7816746778518188" rpy="0 0 0"/>
            <mass value="1" />
            <inertia ixx="100" ixy="0" ixz="0" iyy="100" iyz="0" izz="100" />
        </inertial>
        <visual>
            <origin xyz="0 0 0.7816746778518188" rpy="0 0 0"/>
            <geometry>
                <box size="2.758827234723319 1.2998403177876807 1.5633493557036375" />
            </geometry>
            <material name="Blue">
                <color rgba="0 1.0 1.0 1.0"/>
            </material>
        </visual>
        <collision>
            <origin xyz="0 0 0.7816746778518188" rpy="0 0 0"/>
            <geometry>
                <box size="2.758827234723319 1.2998403177876807 1.5633493557036375" />
            </geometry>
        </collision>
    </link>
    <link name="Leg9">
        <inertial>
            <origin xyz="0 1.3035242613243625 0" rpy="0 0 0"/>
            <mass value="1" />
            <inertia ixx="100" ixy="0" ixz="0" iyy="100" iyz="0" izz="100" />
        </inertial>
        <visual>
            <origin xyz="0 1.3035242613243625 0" rpy="0 0 0"/>
            <geometry>
                <box size="2.5837984874518236 2.607048522648725 1.6842983561733593" />
            </geometry>
            <material name="Blue">
                <color rgba="0 1.0 1.0 1.0"/>
            </material>
        </visual>
        <collision>
            <origin xyz="0 1.3035242613243625 0" rpy="0 0 0"/>
            <geometry>
                <box size="2.5837984874518236 2.607048522648725 1.6842983561733593" />
            </geometry>
        </collision>
    </link>
    <link name="Leg10">
        <inertial>
            <origin xyz="0 1.2819874844419736 0" rpy="0 0 0"/>
            <mass value="1" />
            <inertia ixx="100" ixy="0" ixz="0" iyy="100" iyz="0" izz="100" />
        </inertial>
        <visual>
            <origin xyz="0 1.2819874844419736 0" rpy="0 0 0"/>
            <geometry>
                <box size="1.1708750678058095 2.5639749688839473 2.710711116008314" />
            </geometry>
            <material name="Blue">
                <color rgba="0 1.0 1.0 1.0"/>
            </material>
        </visual>
        <collision>
            <origin xyz="0 1.2819874844419736 0" rpy="0 0 0"/>
            <geometry>
                <box size="1.1708750678058095 2.5639749688839473 2.710711116008314" />
            </geometry>
        </collision>
    </link>
    <link name="Leg11">
        <inertial>
            <origin xyz="0 0.6641296237932828 0" rpy="0 0 0"/>
            <mass value="1" />
            <inertia ixx="100" ixy="0" ixz="0" iyy="100" iyz="0" izz="100" />
        </inertial>
        <visual>
            <origin xyz="0 0.6641296237932828 0" rpy="0 0 0"/>
            <geometry>
                <box size="2.76605651586613 1.3282592475865656 1.9078853300958902" />
            </geometry>
            <material name="Green">
                <color rgba="0 180.0 0.0 1.0"/>
            </material>
        </visual>
        <collision>
            <origin xyz="0 0.6641296237932828 0" rpy="0 0 0"/>
            <geometry>
                <box size="2.76605651586613 1.3282592475865656 1.9078853300958902" />
            </geometry>
        </collision>
    </link>
    <link name="Leg12">
        <inertial>
            <origin xyz="0 0.9896791010840352 0" rpy="0 0 0"/>
            <mass value="1" />
            <inertia ixx="100" ixy="0" ixz="0" iyy="100" iyz="0" izz="100" />
        </inertial>
        <visual>
            <origin xyz="0 0.9896791010840352 0" rpy="0 0 0"/>
            <geometry>
                <box size="1.219642383210514 1.9793582021680705 2.237645054120777" />
            </geometry>
            <material name="Blue">
                <color rgba="0 1.0 1.0 1.0"/>
            </material>
        </visual>
        <collision>
            <origin xyz="0 0.9896791010840352 0" rpy="0 0 0"/>
            <geometry>
                <box size="1.219642383210514 1.9793582021680705 2.237645054120777" />
            </geometry>
        </collision>
    </link>
    <link name="Leg13">
        <inertial>
            <origin xyz="0.8911264338472626 0 0" rpy="0 0 0"/>
            <mass value="1" />
            <inertia ixx="100" ixy="0" ixz="0" iyy="100" iyz="0" izz="100" />
        </inertial>
        <visual>
            <origin xyz="0.8911264338472626 0 0" rpy="0 0 0"/>
            <geometry>
                <box size="1.7822528676945253 2.1786166038849437 1.239671403948414" />
            </geometry>
            <material name="Green">
                <color rgba="0 180.0 0.0 1.0"/>
            </material>
        </visual>
        <collision>
            <origin xyz="0.8911264338472626 0 0" rpy="0 0 0"/>
            <geometry>
                <box size="1.7822528676945253 2.1786166038849437 1.239671403948414" />
            </geometry>
        </collision>
    </link>
    <link name="Leg14">
        <inertial>
            <origin xyz="0 0 0.7693034695102204" rpy="0 0 0"/>
            <mass value="1" />
            <inertia ixx="100" ixy="0" ixz="0" iyy="100" iyz="0" izz="100" />
        </inertial>
        <visual>
            <origin xyz="0 0 0.7693034695102204" rpy="0 0 0"/>
            <geometry>
                <box size="2.180175454645411 2.870811942791356 1.5386069390204409" />
            </geometry>
            <material name="Green">
                <color rgba="0 180.0 0.0 1.0"/>
            </material>
        </visual>
        <collision>
            <origin xyz="0 0 0.7693034695102204" rpy="0 0 0"/>
            <geometry>
                <box size="2.180175454645411 2.870811942791356 1.5386069390204409" />
            </geometry>
        </collision>
    </link>
    <link name="Leg15">
        <inertial>
            <origin xyz="0.7555780886564541 0 0" rpy="0 0 0"/>
            <mass value="1" />
            <inertia ixx="100" ixy="0" ixz="0" iyy="100" iyz="0" izz="100" />
        </inertial>
        <visual>
            <origin xyz="0.7555780886564541 0 0" rpy="0 0 0"/>
            <geometry>
                <box size="1.5111561773129083 1.5400318218431663 2.325481594575579" />
            </geometry>
            <material name="Green">
                <color rgba="0 180.0 0.0 1.0"/>
            </material>
        </visual>
        <collision>
            <origin xyz="0.7555780886564541 0 0" rpy="0 0 0"/>
            <geometry>
                <box size="1.5111561773129083 1.5400318218431663 2.325481594575579" />
            </geometry>
        </collision>
    </link>
    <link name="Leg16">
        <inertial>
            <origin xyz="0 0 1.278284300776252" rpy="0 0 0"/>
            <mass value="1" />
            <inertia ixx="100" ixy="0" ixz="0" iyy="100" iyz="0" izz="100" />
        </inertial>
        <visual>
            <origin xyz="0 0 1.278284300776252" rpy="0 0 0"/>
            <geometry>
                <box size="1.4412558520493497 1.5279226711661344 2.556568601552504" />
            </geometry>
            <material name="Green">
                <color rgba="0 180.0 0.0 1.0"/>
            </material>
        </visual>
        <collision>
            <origin xyz="0 0 1.278284300776252" rpy="0 0 0"/>
            <geometry>
                <box size="1.4412558520493497 1.5279226711661344 2.556568601552504" />
            </geometry>
        </collision>
    </link>
    <link name="Leg17">
        <inertial>
            <origin xyz="0 0 0.6733542613361836" rpy="0 0 0"/>
            <mass value="1" />
            <inertia ixx="100" ixy="0" ixz="0" iyy="100" iyz="0" izz="100" />
        </inertial>
        <visual>
            <origin xyz="0 0 0.6733542613361836" rpy="0 0 0"/>
            <geometry>
                <box size="1.2557819802563583 1.4159756568251274 1.3467085226723672" />
            </geometry>
            <material name="Blue">
                <color rgba="0 1.0 1.0 1.0"/>
            </material>
        </visual>
        <collision>
            <origin xyz="0 0 0.6733542613361836" rpy="0 0 0"/>
            <geometry>
                <box size="1.2557819802563583 1.4159756568251274 1.3467085226723672" />
            </geometry>
        </collision>
    </link>
    <link name="Leg18">
        <inertial>
            <origin xyz="0 1.0579544125787157 0" rpy="0 0 0"/>
            <mass value="1" />
            <inertia ixx="100" ixy="0" ixz="0" iyy="100" iyz="0" izz="100" />
        </inertial>
        <visual>
            <origin xyz="0 1.0579544125787157 0" rpy="0 0 0"/>
            <geometry>
                <box size="1.7291603662374648 2.1159088251574314 2.482803814386441" />
            </geometry>
            <material name="Blue">
                <color rgba="0 1.0 1.0 1.0"/>
            </material>
        </visual>
        <collision>
            <origin xyz="0 1.0579544125787157 0" rpy="0 0 0"/>
            <geometry>
                <box size="1.7291603662374648 2.1159088251574314 2.482803814386441" />
            </geometry>
        </collision>
    </link>
    <link name="Leg19">
        <inertial>
            <origin xyz="0 0 1.405479410200647" rpy="0 0 0"/>
            <mass value="1" />
            <inertia ixx="100" ixy="0" ixz="0" iyy="100" iyz="0" izz="100" />
        </inertial>
        <visual>
            <origin xyz="0 0 1.405479410200647" rpy="0 0 0"/>
            <geometry>
                <box size="1.1894732321268395 2.863649721218005 2.810958820401294" />
            </geometry>
            <material name="Blue">
                <color rgba="0 1.0 1.0 1.0"/>
            </material>
        </visual>
        <collision>
            <origin xyz="0 0 1.405479410200647" rpy="0 0 0"/>
            <geometry>
                <box size="1.1894732321268395 2.863649721218005 2.810958820401294" />
            </geometry>
        </collision>
    </link>
    <link name="Leg20">
        <inertial>
            <origin xyz="0 0 1.0306116744029583" rpy="0 0 0"/>
            <mass value="1" />
            <inertia ixx="100" ixy="0" ixz="0" iyy="100" iyz="0" izz="100" />
        </inertial>
        <visual>
            <origin xyz="0 0 1.0306116744029583" rpy="0 0 0"/>
            <geometry>
                <box size="2.0756672010260084 1.7552181537443143 2.0612233488059166" />
            </geometry>
            <material name="Green">
                <color rgba="0 180.0 0.0 1.0"/>
            </material>
        </visual>
        <collision>
            <origin xyz="0 0 1.0306116744029583" rpy="0 0 0"/>
            <geometry>
                <box size="2.0756672010260084 1.7552181537443143 2.0612233488059166" />
            </geometry>
        </collision>
    </link>
    <link name="Leg21">
        <inertial>
            <origin xyz="0 0 1.4085121123556577" rpy="0 0 0"/>
            <mass value="1" />
            <inertia ixx="100" ixy="0" ixz="0" iyy="100" iyz="0" izz="100" />
        </inertial>
        <visual>
            <origin xyz="0 0 1.4085121123556577" rpy="0 0 0"/>
            <geometry>
                <box size="1.0361501194506977 1.239752034793008 2.8170242247113153" />
            </geometry>
            <material name="Blue">
                <color rgba="0 1.0 1.0 1.0"/>
            </material>
        </visual>
        <collision>
            <origin xyz="0 0 1.4085121123556577" rpy="0 0 0"/>
            <geometry>
                <box size="1.0361501194506977 1.239752034793008 2.8170242247113153" />
            </geometry>
        </collision>
    </link>
    <link name="Leg22">
        <inertial>
            <origin xyz="0 0 0.8695095237758173" rpy="0 0 0"/>
            <mass value="1" />
            <inertia ixx="100" ixy="0" ixz="0" iyy="100" iyz="0" izz="100" />
        </inertial>
        <visual>
            <origin xyz="0 0 0.8695095237758173" rpy="0 0 0"/>
            <geometry>
                <box size="2.3650541128517775 2.929369027949006 1.7390190475516345" />
            </geometry>
            <material name="Green">
                <color rgba="0 180.0 0.0 1.0"/>
            </material>
        </visual>
        <collision>
            <origin xyz="0 0 0.8695095237758173" rpy="0 0 0"/>
            <geometry>
                <box size="2.3650541128517775 2.929369027949006 1.7390190475516345" />
            </geometry>
        </collision>
    </link>
    <link name="Leg23">
        <inertial>
            <origin xyz="0.9889719966523997 0 0" rpy="0 0 0"/>
            <mass value="1" />
            <inertia ixx="100" ixy="0" ixz="0" iyy="100" iyz="0" izz="100" />
        </inertial>
        <visual>
            <origin xyz="0.9889719966523997 0 0" rpy="0 0 0"/>
            <geometry>
                <box size="1.9779439933047993 1.548112521697569 1.1804614202627726" />
            </geometry>
            <material name="Green">
                <color rgba="0 180.0 0.0 1.0"/>
            </material>
        </visual>
        <collision>
            <origin xyz="0.9889719966523997 0 0" rpy="0 0 0"/>
            <geometry>
                <box size="1.9779439933047993 1.548112521697569 1.1804614202627726" />
            </geometry>
        </collision>
    </link>
    <link name="Leg24">
        <inertial>
            <origin xyz="0 0 0.79372811157053" rpy="0 0 0"/>
            <mass value="1" />
            <inertia ixx="100" ixy="0" ixz="0" iyy="100" iyz="0" izz="100" />
        </inertial>
        <visual>
            <origin xyz="0 0 0.79372811157053" rpy="0 0 0"/>
            <geometry>
                <box size="2.4491214140404596 1.3149489359312239 1.58745622314106" />
            </geometry>
            <material name="Green">
                <color rgba="0 180.0 0.0 1.0"/>
            </material>
        </visual>
        <collision>
            <origin xyz="0 0 0.79372811157053" rpy="0 0 0"/>
            <geometry>
                <box size="2.4491214140404596 1.3149489359312239 1.58745622314106" />
            </geometry>
        </collision>
    </link>
    <link name="Leg25">
        <inertial>
            <origin xyz="0 1.0240163275580016 0" rpy="0 0 0"/>
            <mass value="1" />
            <inertia ixx="100" ixy="0" ixz="0" iyy="100" iyz="0" izz="100" />
        </inertial>
        <visual>
            <origin xyz="0 1.0240163275580016 0" rpy="0 0 0"/>
            <geometry>
                <box size="1.7549461605168717 2.0480326551160033 2.7159306451105145" />
            </geometry>
            <material name="Blue">
                <color rgba="0 1.0 1.0 1.0"/>
            </material>
        </visual>
        <collision>
            <origin xyz="0 1.0240163275580016 0" rpy="0 0 0"/>
            <geometry>
                <box size="1.7549461605168717 2.0480326551160033 2.7159306451105145" />
            </geometry>
        </collision>
    </link>
    <joint name="Torso_Leg1" type="revolute">
       <parent link="Torso"/>
       <child  link="Leg1"/>
       <origin rpy="0 0 0" xyz="1.0169667337551396 0 1.2658818280718995" />
     <axis xyz="1 0 0"/>
       <limit effort="0.0" lower="-3.14159" upper="3.14159" velocity="0.0"/>
    </joint>
    <joint name="Leg1_Leg2" type="revolute">
       <parent link="Leg1"/>
       <child  link="Leg2"/>
       <origin rpy="0 0 0" xyz="0 1.8709863405359954 0" />
     <axis xyz="1 0 0"/>
       <limit effort="0.0" lower="-3.14159" upper="3.14159" velocity="0.0"/>
    </joint>
    <joint name="Torso_Leg3" type="revolute">
       <parent link="Torso"/>
       <child  link="Leg3"/>
       <origin rpy="0 0 0" xyz="1.149062053143544 0 1.3955845661889748" />
     <axis xyz="1 0 0"/>
       <limit effort="0.0" lower="-3.14159" upper="3.14159" velocity="0.0"/>
    </joint>
    <joint name="Leg3_Leg4" type="revolute">
       <parent link="Leg3"/>
       <child  link="Leg4"/>
       <origin rpy="0 0 0" xyz="0 0 1.2720342758353005" />
     <axis xyz="1 0 0"/>
       <limit effort="0.0" lower="-3.14159" upper="3.14159" velocity="0.0"/>
    </joint>
    <joint name="Leg2_Leg5" type="revolute">
       <parent link="Leg2"/>
       <child  link="Leg5"/>
       <origin rpy="0 0 0" xyz="0.6256703747741658 0 1.3160255693252783" />
     <axis xyz="1 0 0"/>
       <limit effort="0.0" lower="-3.14159" upper="3.14159" velocity="0.0"/>
    </joint>
    <joint name="Leg5_Leg6" type="revolute">
       <parent link="Leg5"/>
       <child  link="Leg6"/>
       <origin rpy="0 0 0" xyz="2.8539889612014044 0 0" />
     <axis xyz="1 0 0"/>
       <limit effort="0.0" lower="-3.14159" upper="3.14159" velocity="0.0"/>
    </joint>
    <joint name="Leg2_Leg7" type="revolute">
       <parent link="Leg2"/>
       <child  link="Leg7"/>
       <origin rpy="0 0 0" xyz="0.6256703747741658 1.1295628126304242 1.3160255693252783" />
     <axis xyz="1 0 0"/>
       <limit effort="0.0" lower="-3.14159" upper="3.14159" velocity="0.0"/>
    </joint>
    <joint name="Leg2_Leg8" type="revolute">
       <parent link="Leg2"/>
       <child  link="Leg8"/>
       <origin rpy="0 0 0" xyz="0.6256703747741658 1.1295628126304242 2.6320511386505565" />
     <axis xyz="1 0 0"/>
       <limit effort="0.0" lower="-3.14159" upper="3.14159" velocity="0.0"/>
    </joint>
    <joint name="Torso_Leg9" type="revolute">
       <parent link="Torso"/>
       <child  link="Leg9"/>
       <origin rpy="0 0 0" xyz="1.149062053143544 0.7208848984572519 1.3955845661889748" />
     <axis xyz="1 0 0"/>
       <limit effort="0.0" lower="-3.14159" upper="3.14159" velocity="0.0"/>
    </joint>
    <joint name="Leg9_Leg10" type="revolute">
       <parent link="Leg9"/>
       <child  link="Leg10"/>
       <origin rpy="0 0 0" xyz="0 2.5639749688839473 0" />
     <axis xyz="1 0 0"/>
       <limit effort="0.0" lower="-3.14159" upper="3.14159" velocity="0.0"/>
    </joint>
    <joint name="Leg3_Leg11" type="revolute">
       <parent link="Leg3"/>
       <child  link="Leg11"/>
       <origin rpy="0 0 0" xyz="0 1.2759494729639864 1.2720342758353005" />
     <axis xyz="1 0 0"/>
       <limit effort="0.0" lower="-3.14159" upper="3.14159" velocity="0.0"/>
    </joint>
    <joint name="Leg4_Leg12" type="revolute">
       <parent link="Leg4"/>
       <child  link="Leg12"/>
       <origin rpy="0 0 0" xyz="0.6669778831390901 0.5388394269724766 0" />
     <axis xyz="1 0 0"/>
       <limit effort="0.0" lower="-3.14159" upper="3.14159" velocity="0.0"/>
    </joint>
    <joint name="Leg12_Leg13" type="revolute">
       <parent link="Leg12"/>
       <child  link="Leg13"/>
       <origin rpy="0 0 0" xyz="1.7822528676945253 0 0" />
     <axis xyz="1 0 0"/>
       <limit effort="0.0" lower="-3.14159" upper="3.14159" velocity="0.0"/>
    </joint>
    <joint name="Leg6_Leg14" type="revolute">
       <parent link="Leg6"/>
       <child  link="Leg14"/>
       <origin rpy="0 0 0" xyz="0 0.5573876140482988 0.9941235271664819" />
     <axis xyz="1 0 0"/>
       <limit effort="0.0" lower="-3.14159" upper="3.14159" velocity="0.0"/>
    </joint>
    <joint name="Leg10_Leg15" type="revolute">
       <parent link="Leg10"/>
       <child  link="Leg15"/>
       <origin rpy="0 0 0" xyz="1.383028257933065 0.6641296237932828 0" />
     <axis xyz="1 0 0"/>
       <limit effort="0.0" lower="-3.14159" upper="3.14159" velocity="0.0"/>
    </joint>
    <joint name="Leg4_Leg16" type="revolute">
       <parent link="Leg4"/>
       <child  link="Leg16"/>
       <origin rpy="0 0 0" xyz="0.6669778831390901 0.5388394269724766 0.6318928619631992" />
     <axis xyz="1 0 0"/>
       <limit effort="0.0" lower="-3.14159" upper="3.14159" velocity="0.0"/>
    </joint>
    <joint name="Leg16_Leg17" type="revolute">
       <parent link="Leg16"/>
       <child  link="Leg17"/>
       <origin rpy="0 0 0" xyz="0 0 1.3467085226723672" />
     <axis xyz="1 0 0"/>
       <limit effort="0.0" lower="-3.14159" upper="3.14159" velocity="0.0"/>
    </joint>
    <joint name="Leg6_Leg18" type="revolute">
       <parent link="Leg6"/>
       <child  link="Leg18"/>
       <origin rpy="0 0 0" xyz="0 1.1147752280965977 0.9941235271664819" />
     <axis xyz="1 0 0"/>
       <limit effort="0.0" lower="-3.14159" upper="3.14159" velocity="0.0"/>
    </joint>
    <joint name="Leg10_Leg19" type="revolute">
       <parent link="Leg10"/>
       <child  link="Leg19"/>
       <origin rpy="0 0 0" xyz="1.383028257933065 0.6641296237932828 0.9539426650479451" />
     <axis xyz="1 0 0"/>
       <limit effort="0.0" lower="-3.14159" upper="3.14159" velocity="0.0"/>
    </joint>
    <joint name="Leg5_Leg20" type="revolute">
       <parent link="Leg5"/>
       <child  link="Leg20"/>
       <origin rpy="0 0 0" xyz="2.8539889612014044 0 1.1972021602253504" />
     <axis xyz="1 0 0"/>
       <limit effort="0.0" lower="-3.14159" upper="3.14159" velocity="0.0"/>
    </joint>
    <joint name="Leg8_Leg21" type="revolute">
       <parent link="Leg8"/>
       <child  link="Leg21"/>
       <origin rpy="0 0 0" xyz="0 1.3035242613243625 0.8421491780866797" />
     <axis xyz="1 0 0"/>
       <limit effort="0.0" lower="-3.14159" upper="3.14159" velocity="0.0"/>
    </joint>
    <joint name="Leg13_Leg22" type="revolute">
       <parent link="Leg13"/>
       <child  link="Leg22"/>
       <origin rpy="0 0 0" xyz="0 0 1.5386069390204409" />
     <axis xyz="1 0 0"/>
       <limit effort="0.0" lower="-3.14159" upper="3.14159" velocity="0.0"/>
    </joint>
    <joint name="Leg16_Leg23" type="revolute">
       <parent link="Leg16"/>
       <child  link="Leg23"/>
       <origin rpy="0 0 0" xyz="0.6278909901281792 0 1.3467085226723672" />
     <axis xyz="1 0 0"/>
       <limit effort="0.0" lower="-3.14159" upper="3.14159" velocity="0.0"/>
    </joint>
    <joint name="Leg9_Leg24" type="revolute">
       <parent link="Leg9"/>
       <child  link="Leg24"/>
       <origin rpy="0 0 0" xyz="0 2.5639749688839473 1.355355558004157" />
     <axis xyz="1 0 0"/>
       <limit effort="0.0" lower="-3.14159" upper="3.14159" velocity="0.0"/>
    </joint>
    <joint name="Leg22_Leg25" type="revolute">
       <parent link="Leg22"/>
       <child  link="Leg25"/>
       <origin rpy="0 0 0" xyz="0.9889719966523997 0.7740562608487845 0" />
     <axis xyz="1 0 0"/>
       <limit effort="0.0" lower="-3.14159" upper="3.14159" velocity="0.0"/>
    </joint>
</robot>