<robot name = "robot">
    <link name="Torso">
        <inertial>
            <origin xyz="0 0 1.4380304522657656" rpy="0 0 0"/>
            <mass value="1" />
            <inertia ixx="100" ixy="0" ixz="0" iyy="100" iyz="0" izz="100" />
        </inertial>
        <visual>
            <origin xyz="0 0 1.4380304522657656" rpy="0 0 0"/>
            <geometry>
                <box size="1.747608297319078 2.297218880016268 2.8760609045315313" />
            </geometry>
            <material name="Green">
                <color rgba="0 180.0 0.0 1.0"/>
            </material>
        </visual>
        <collision>
            <origin xyz="0 0 1.4380304522657656" rpy="0 0 0"/>
            <geometry>
                <box size="1.747608297319078 2.297218880016268 2.8760609045315313" />
            </geometry>
        </collision>
    </link>
    <link name="Leg1">
        <inertial>
            <origin xyz="0 1.3194928021248644 0" rpy="0 0 0"/>
            <mass value="1" />
            <inertia ixx="100" ixy="0" ixz="0" iyy="100" iyz="0" izz="100" />
        </inertial>
        <visual>
            <origin xyz="0 1.3194928021248644 0" rpy="0 0 0"/>
            <geometry>
                <box size="2.5543542134423998 2.638985604249729 1.5546486383942537" />
            </geometry>
            <material name="Blue">
                <color rgba="0 1.0 1.0 1.0"/>
            </material>
        </visual>
        <collision>
            <origin xyz="0 1.3194928021248644 0" rpy="0 0 0"/>
            <geometry>
                <box size="2.5543542134423998 2.638985604249729 1.5546486383942537" />
            </geometry>
        </collision>
    </link>
    <link name="Leg2">
        <inertial>
            <origin xyz="0 0.5594165346404074 0" rpy="0 0 0"/>
            <mass value="1" />
            <inertia ixx="100" ixy="0" ixz="0" iyy="100" iyz="0" izz="100" />
        </inertial>
        <visual>
            <origin xyz="0 0.5594165346404074 0" rpy="0 0 0"/>
            <geometry>
                <box size="1.2975270505998417 1.1188330692808148 2.880661786933417" />
            </geometry>
            <material name="Green">
                <color rgba="0 180.0 0.0 1.0"/>
            </material>
        </visual>
        <collision>
            <origin xyz="0 0.5594165346404074 0" rpy="0 0 0"/>
            <geometry>
                <box size="1.2975270505998417 1.1188330692808148 2.880661786933417" />
            </geometry>
        </collision>
    </link>
    <link name="Leg3">
        <inertial>
            <origin xyz="1.2930773230858752 0 0" rpy="0 0 0"/>
            <mass value="1" />
            <inertia ixx="100" ixy="0" ixz="0" iyy="100" iyz="0" izz="100" />
        </inertial>
        <visual>
            <origin xyz="1.2930773230858752 0 0" rpy="0 0 0"/>
            <geometry>
                <box size="2.5861546461717504 1.718545566235428 2.7422564338537243" />
            </geometry>
            <material name="Green">
                <color rgba="0 180.0 0.0 1.0"/>
            </material>
        </visual>
        <collision>
            <origin xyz="1.2930773230858752 0 0" rpy="0 0 0"/>
            <geometry>
                <box size="2.5861546461717504 1.718545566235428 2.7422564338537243" />
            </geometry>
        </collision>
    </link>
    <link name="Leg4">
        <inertial>
            <origin xyz="0 0.5050517954958189 0" rpy="0 0 0"/>
            <mass value="1" />
            <inertia ixx="100" ixy="0" ixz="0" iyy="100" iyz="0" izz="100" />
        </inertial>
        <visual>
            <origin xyz="0 0.5050517954958189 0" rpy="0 0 0"/>
            <geometry>
                <box size="2.245579511721868 1.0101035909916378 1.5960683000642846" />
            </geometry>
            <material name="Green">
                <color rgba="0 180.0 0.0 1.0"/>
            </material>
        </visual>
        <collision>
            <origin xyz="0 0.5050517954958189 0" rpy="0 0 0"/>
            <geometry>
                <box size="2.245579511721868 1.0101035909916378 1.5960683000642846" />
            </geometry>
        </collision>
    </link>
    <link name="Leg5">
        <inertial>
            <origin xyz="1.2547645826317164 0 0" rpy="0 0 0"/>
            <mass value="1" />
            <inertia ixx="100" ixy="0" ixz="0" iyy="100" iyz="0" izz="100" />
        </inertial>
        <visual>
            <origin xyz="1.2547645826317164 0 0" rpy="0 0 0"/>
            <geometry>
                <box size="2.509529165263433 2.222692726409636 2.6598083177832486" />
            </geometry>
            <material name="Blue">
                <color rgba="0 1.0 1.0 1.0"/>
            </material>
        </visual>
        <collision>
            <origin xyz="1.2547645826317164 0 0" rpy="0 0 0"/>
            <geometry>
                <box size="2.509529165263433 2.222692726409636 2.6598083177832486" />
            </geometry>
        </collision>
    </link>
    <joint name="Torso_Leg1" type="revolute">
       <parent link="Torso"/>
       <child  link="Leg1"/>
       <origin rpy="0 0 0" xyz="0 1.148609440008134 1.4380304522657656" />
     <axis xyz="1 0 0"/>
       <limit effort="0.0" lower="-3.14159" upper="3.14159" velocity="0.0"/>
    </joint>
    <joint name="Leg1_Leg2" type="revolute">
       <parent link="Leg1"/>
       <child  link="Leg2"/>
       <origin rpy="0 0 0" xyz="0 1.1188330692808148 0" />
     <axis xyz="1 0 0"/>
       <limit effort="0.0" lower="-3.14159" upper="3.14159" velocity="0.0"/>
    </joint>
    <joint name="Torso_Leg3" type="revolute">
       <parent link="Torso"/>
       <child  link="Leg3"/>
       <origin rpy="0 0 0" xyz="1.2771771067211999 1.3194928021248644 0" />
     <axis xyz="1 0 0"/>
       <limit effort="0.0" lower="-3.14159" upper="3.14159" velocity="0.0"/>
    </joint>
    <joint name="Leg2_Leg4" type="revolute">
       <parent link="Leg2"/>
       <child  link="Leg4"/>
       <origin rpy="0 0 0" xyz="1.2930773230858752 0.859272783117714 0" />
     <axis xyz="1 0 0"/>
       <limit effort="0.0" lower="-3.14159" upper="3.14159" velocity="0.0"/>
    </joint>
    <joint name="Leg1_Leg5" type="revolute">
       <parent link="Leg1"/>
       <child  link="Leg5"/>
       <origin rpy="0 0 0" xyz="0.6487635252999209 1.1188330692808148 0" />
     <axis xyz="1 0 0"/>
       <limit effort="0.0" lower="-3.14159" upper="3.14159" velocity="0.0"/>
    </joint>
</robot>