<robot name = "robot">
    <link name="Torso">
        <inertial>
            <origin xyz="0 0 1.0958673781298431" rpy="0 0 0"/>
            <mass value="1" />
            <inertia ixx="100" ixy="0" ixz="0" iyy="100" iyz="0" izz="100" />
        </inertial>
        <visual>
            <origin xyz="0 0 1.0958673781298431" rpy="0 0 0"/>
            <geometry>
                <box size="1.4613989324013317 2.727988940559598 2.1917347562596863" />
            </geometry>
            <material name="Green">
                <color rgba="0 180.0 0.0 1.0"/>
            </material>
        </visual>
        <collision>
            <origin xyz="0 0 1.0958673781298431" rpy="0 0 0"/>
            <geometry>
                <box size="1.4613989324013317 2.727988940559598 2.1917347562596863" />
            </geometry>
        </collision>
    </link>
    <link name="Leg1">
        <inertial>
            <origin xyz="0.729755259059567 0 0" rpy="0 0 0"/>
            <mass value="1" />
            <inertia ixx="100" ixy="0" ixz="0" iyy="100" iyz="0" izz="100" />
        </inertial>
        <visual>
            <origin xyz="0.729755259059567 0 0" rpy="0 0 0"/>
            <geometry>
                <box size="1.459510518119134 1.8325926885064876 1.5814482974526571" />
            </geometry>
            <material name="Green">
                <color rgba="0 180.0 0.0 1.0"/>
            </material>
        </visual>
        <collision>
            <origin xyz="0.729755259059567 0 0" rpy="0 0 0"/>
            <geometry>
                <box size="1.459510518119134 1.8325926885064876 1.5814482974526571" />
            </geometry>
        </collision>
    </link>
    <link name="Leg2">
        <inertial>
            <origin xyz="1.3001692197651409 0 0" rpy="0 0 0"/>
            <mass value="1" />
            <inertia ixx="100" ixy="0" ixz="0" iyy="100" iyz="0" izz="100" />
        </inertial>
        <visual>
            <origin xyz="1.3001692197651409 0 0" rpy="0 0 0"/>
            <geometry>
                <box size="2.6003384395302818 1.259988377076496 1.8790241445987275" />
            </geometry>
            <material name="Blue">
                <color rgba="0 1.0 1.0 1.0"/>
            </material>
        </visual>
        <collision>
            <origin xyz="1.3001692197651409 0 0" rpy="0 0 0"/>
            <geometry>
                <box size="2.6003384395302818 1.259988377076496 1.8790241445987275" />
            </geometry>
        </collision>
    </link>
    <link name="Leg3">
        <inertial>
            <origin xyz="1.0328091143906837 0 0" rpy="0 0 0"/>
            <mass value="1" />
            <inertia ixx="100" ixy="0" ixz="0" iyy="100" iyz="0" izz="100" />
        </inertial>
        <visual>
            <origin xyz="1.0328091143906837 0 0" rpy="0 0 0"/>
            <geometry>
                <box size="2.0656182287813674 1.146317380655737 2.2063567068037204" />
            </geometry>
            <material name="Green">
                <color rgba="0 180.0 0.0 1.0"/>
            </material>
        </visual>
        <collision>
            <origin xyz="1.0328091143906837 0 0" rpy="0 0 0"/>
            <geometry>
                <box size="2.0656182287813674 1.146317380655737 2.2063567068037204" />
            </geometry>
        </collision>
    </link>
    <link name="Leg4">
        <inertial>
            <origin xyz="0 1.019213701856435 0" rpy="0 0 0"/>
            <mass value="1" />
            <inertia ixx="100" ixy="0" ixz="0" iyy="100" iyz="0" izz="100" />
        </inertial>
        <visual>
            <origin xyz="0 1.019213701856435 0" rpy="0 0 0"/>
            <geometry>
                <box size="2.4848909454738903 2.03842740371287 2.633721479352287" />
            </geometry>
            <material name="Green">
                <color rgba="0 180.0 0.0 1.0"/>
            </material>
        </visual>
        <collision>
            <origin xyz="0 1.019213701856435 0" rpy="0 0 0"/>
            <geometry>
                <box size="2.4848909454738903 2.03842740371287 2.633721479352287" />
            </geometry>
        </collision>
    </link>
    <link name="Leg5">
        <inertial>
            <origin xyz="0.6391301116851728 0 0" rpy="0 0 0"/>
            <mass value="1" />
            <inertia ixx="100" ixy="0" ixz="0" iyy="100" iyz="0" izz="100" />
        </inertial>
        <visual>
            <origin xyz="0.6391301116851728 0 0" rpy="0 0 0"/>
            <geometry>
                <box size="1.2782602233703455 2.4407215126764235 2.4936641754095468" />
            </geometry>
            <material name="Blue">
                <color rgba="0 1.0 1.0 1.0"/>
            </material>
        </visual>
        <collision>
            <origin xyz="0.6391301116851728 0 0" rpy="0 0 0"/>
            <geometry>
                <box size="1.2782602233703455 2.4407215126764235 2.4936641754095468" />
            </geometry>
        </collision>
    </link>
    <link name="Leg6">
        <inertial>
            <origin xyz="0.810495797911337 0 0" rpy="0 0 0"/>
            <mass value="1" />
            <inertia ixx="100" ixy="0" ixz="0" iyy="100" iyz="0" izz="100" />
        </inertial>
        <visual>
            <origin xyz="0.810495797911337 0 0" rpy="0 0 0"/>
            <geometry>
                <box size="1.620991595822674 1.222760935853038 2.3379856248617505" />
            </geometry>
            <material name="Blue">
                <color rgba="0 1.0 1.0 1.0"/>
            </material>
        </visual>
        <collision>
            <origin xyz="0.810495797911337 0 0" rpy="0 0 0"/>
            <geometry>
                <box size="1.620991595822674 1.222760935853038 2.3379856248617505" />
            </geometry>
        </collision>
    </link>
    <link name="Leg7">
        <inertial>
            <origin xyz="0 0.8002340829078916 0" rpy="0 0 0"/>
            <mass value="1" />
            <inertia ixx="100" ixy="0" ixz="0" iyy="100" iyz="0" izz="100" />
        </inertial>
        <visual>
            <origin xyz="0 0.8002340829078916 0" rpy="0 0 0"/>
            <geometry>
                <box size="1.637170160234869 1.600468165815783 2.3306422792674137" />
            </geometry>
            <material name="Green">
                <color rgba="0 180.0 0.0 1.0"/>
            </material>
        </visual>
        <collision>
            <origin xyz="0 0.8002340829078916 0" rpy="0 0 0"/>
            <geometry>
                <box size="1.637170160234869 1.600468165815783 2.3306422792674137" />
            </geometry>
        </collision>
    </link>
    <link name="Leg8">
        <inertial>
            <origin xyz="0 0.7189189698485101 0" rpy="0 0 0"/>
            <mass value="1" />
            <inertia ixx="100" ixy="0" ixz="0" iyy="100" iyz="0" izz="100" />
        </inertial>
        <visual>
            <origin xyz="0 0.7189189698485101 0" rpy="0 0 0"/>
            <geometry>
                <box size="1.229788473716363 1.4378379396970202 2.7021221492807497" />
            </geometry>
            <material name="Green">
                <color rgba="0 180.0 0.0 1.0"/>
            </material>
        </visual>
        <collision>
            <origin xyz="0 0.7189189698485101 0" rpy="0 0 0"/>
            <geometry>
                <box size="1.229788473716363 1.4378379396970202 2.7021221492807497" />
            </geometry>
        </collision>
    </link>
    <link name="Leg9">
        <inertial>
            <origin xyz="0.56015031301318 0 0" rpy="0 0 0"/>
            <mass value="1" />
            <inertia ixx="100" ixy="0" ixz="0" iyy="100" iyz="0" izz="100" />
        </inertial>
        <visual>
            <origin xyz="0.56015031301318 0 0" rpy="0 0 0"/>
            <geometry>
                <box size="1.12030062602636 2.6689858077216573 1.8217226950300336" />
            </geometry>
            <material name="Blue">
                <color rgba="0 1.0 1.0 1.0"/>
            </material>
        </visual>
        <collision>
            <origin xyz="0.56015031301318 0 0" rpy="0 0 0"/>
            <geometry>
                <box size="1.12030062602636 2.6689858077216573 1.8217226950300336" />
            </geometry>
        </collision>
    </link>
    <link name="Leg10">
        <inertial>
            <origin xyz="0 0 0.9275799443199965" rpy="0 0 0"/>
            <mass value="1" />
            <inertia ixx="100" ixy="0" ixz="0" iyy="100" iyz="0" izz="100" />
        </inertial>
        <visual>
            <origin xyz="0 0 0.9275799443199965" rpy="0 0 0"/>
            <geometry>
                <box size="2.01819230062339 2.6856344361446522 1.855159888639993" />
            </geometry>
            <material name="Green">
                <color rgba="0 180.0 0.0 1.0"/>
            </material>
        </visual>
        <collision>
            <origin xyz="0 0 0.9275799443199965" rpy="0 0 0"/>
            <geometry>
                <box size="2.01819230062339 2.6856344361446522 1.855159888639993" />
            </geometry>
        </collision>
    </link>
    <link name="Leg11">
        <inertial>
            <origin xyz="0.7249026788626933 0 0" rpy="0 0 0"/>
            <mass value="1" />
            <inertia ixx="100" ixy="0" ixz="0" iyy="100" iyz="0" izz="100" />
        </inertial>
        <visual>
            <origin xyz="0.7249026788626933 0 0" rpy="0 0 0"/>
            <geometry>
                <box size="1.4498053577253867 2.5495026116113033 2.0049985497932807" />
            </geometry>
            <material name="Blue">
                <color rgba="0 1.0 1.0 1.0"/>
            </material>
        </visual>
        <collision>
            <origin xyz="0.7249026788626933 0 0" rpy="0 0 0"/>
            <geometry>
                <box size="1.4498053577253867 2.5495026116113033 2.0049985497932807" />
            </geometry>
        </collision>
    </link>
    <link name="Leg12">
        <inertial>
            <origin xyz="0 0 0.9628215707474154" rpy="0 0 0"/>
            <mass value="1" />
            <inertia ixx="100" ixy="0" ixz="0" iyy="100" iyz="0" izz="100" />
        </inertial>
        <visual>
            <origin xyz="0 0 0.9628215707474154" rpy="0 0 0"/>
            <geometry>
                <box size="1.770897151980557 1.388900168155142 1.9256431414948307" />
            </geometry>
            <material name="Green">
                <color rgba="0 180.0 0.0 1.0"/>
            </material>
        </visual>
        <collision>
            <origin xyz="0 0 0.9628215707474154" rpy="0 0 0"/>
            <geometry>
                <box size="1.770897151980557 1.388900168155142 1.9256431414948307" />
            </geometry>
        </collision>
    </link>
    <link name="Leg13">
        <inertial>
            <origin xyz="0 0 1.3525554704298957" rpy="0 0 0"/>
            <mass value="1" />
            <inertia ixx="100" ixy="0" ixz="0" iyy="100" iyz="0" izz="100" />
        </inertial>
        <visual>
            <origin xyz="0 0 1.3525554704298957" rpy="0 0 0"/>
            <geometry>
                <box size="1.8486845654919202 2.706003827380858 2.7051109408597913" />
            </geometry>
            <material name="Blue">
                <color rgba="0 1.0 1.0 1.0"/>
            </material>
        </visual>
        <collision>
            <origin xyz="0 0 1.3525554704298957" rpy="0 0 0"/>
            <geometry>
                <box size="1.8486845654919202 2.706003827380858 2.7051109408597913" />
            </geometry>
        </collision>
    </link>
    <link name="Leg14">
        <inertial>
            <origin xyz="0 1.4778471903222963 0" rpy="0 0 0"/>
            <mass value="1" />
            <inertia ixx="100" ixy="0" ixz="0" iyy="100" iyz="0" izz="100" />
        </inertial>
        <visual>
            <origin xyz="0 1.4778471903222963 0" rpy="0 0 0"/>
            <geometry>
                <box size="1.170209436403532 2.9556943806445926 2.991002170029753" />
            </geometry>
            <material name="Green">
                <color rgba="0 180.0 0.0 1.0"/>
            </material>
        </visual>
        <collision>
            <origin xyz="0 1.4778471903222963 0" rpy="0 0 0"/>
            <geometry>
                <box size="1.170209436403532 2.9556943806445926 2.991002170029753" />
            </geometry>
        </collision>
    </link>
    <link name="Leg15">
        <inertial>
            <origin xyz="0.9421741388405434 0 0" rpy="0 0 0"/>
            <mass value="1" />
            <inertia ixx="100" ixy="0" ixz="0" iyy="100" iyz="0" izz="100" />
        </inertial>
        <visual>
            <origin xyz="0.9421741388405434 0 0" rpy="0 0 0"/>
            <geometry>
                <box size="1.8843482776810867 2.9041713633900192 2.1429301645704433" />
            </geometry>
            <material name="Green">
                <color rgba="0 180.0 0.0 1.0"/>
            </material>
        </visual>
        <collision>
            <origin xyz="0.9421741388405434 0 0" rpy="0 0 0"/>
            <geometry>
                <box size="1.8843482776810867 2.9041713633900192 2.1429301645704433" />
            </geometry>
        </collision>
    </link>
    <link name="Leg16">
        <inertial>
            <origin xyz="0 0 1.1879896686598035" rpy="0 0 0"/>
            <mass value="1" />
            <inertia ixx="100" ixy="0" ixz="0" iyy="100" iyz="0" izz="100" />
        </inertial>
        <visual>
            <origin xyz="0 0 1.1879896686598035" rpy="0 0 0"/>
            <geometry>
                <box size="1.6772277855057993 2.732704817721731 2.375979337319607" />
            </geometry>
            <material name="Blue">
                <color rgba="0 1.0 1.0 1.0"/>
            </material>
        </visual>
        <collision>
            <origin xyz="0 0 1.1879896686598035" rpy="0 0 0"/>
            <geometry>
                <box size="1.6772277855057993 2.732704817721731 2.375979337319607" />
            </geometry>
        </collision>
    </link>
    <link name="Leg17">
        <inertial>
            <origin xyz="1.3236070604335333 0 0" rpy="0 0 0"/>
            <mass value="1" />
            <inertia ixx="100" ixy="0" ixz="0" iyy="100" iyz="0" izz="100" />
        </inertial>
        <visual>
            <origin xyz="1.3236070604335333 0 0" rpy="0 0 0"/>
            <geometry>
                <box size="2.6472141208670665 2.2172510390676035 2.3598983937329905" />
            </geometry>
            <material name="Green">
                <color rgba="0 180.0 0.0 1.0"/>
            </material>
        </visual>
        <collision>
            <origin xyz="1.3236070604335333 0 0" rpy="0 0 0"/>
            <geometry>
                <box size="2.6472141208670665 2.2172510390676035 2.3598983937329905" />
            </geometry>
        </collision>
    </link>
    <link name="Leg18">
        <inertial>
            <origin xyz="0 0.6876600402601257 0" rpy="0 0 0"/>
            <mass value="1" />
            <inertia ixx="100" ixy="0" ixz="0" iyy="100" iyz="0" izz="100" />
        </inertial>
        <visual>
            <origin xyz="0 0.6876600402601257 0" rpy="0 0 0"/>
            <geometry>
                <box size="2.9067028598966087 1.3753200805202515 1.4272296551436547" />
            </geometry>
            <material name="Blue">
                <color rgba="0 1.0 1.0 1.0"/>
            </material>
        </visual>
        <collision>
            <origin xyz="0 0.6876600402601257 0" rpy="0 0 0"/>
            <geometry>
                <box size="2.9067028598966087 1.3753200805202515 1.4272296551436547" />
            </geometry>
        </collision>
    </link>
    <link name="Leg19">
        <inertial>
            <origin xyz="0 0 0.7636093765105273" rpy="0 0 0"/>
            <mass value="1" />
            <inertia ixx="100" ixy="0" ixz="0" iyy="100" iyz="0" izz="100" />
        </inertial>
        <visual>
            <origin xyz="0 0 0.7636093765105273" rpy="0 0 0"/>
            <geometry>
                <box size="2.571101127420162 1.1156780682718817 1.5272187530210546" />
            </geometry>
            <material name="Blue">
                <color rgba="0 1.0 1.0 1.0"/>
            </material>
        </visual>
        <collision>
            <origin xyz="0 0 0.7636093765105273" rpy="0 0 0"/>
            <geometry>
                <box size="2.571101127420162 1.1156780682718817 1.5272187530210546" />
            </geometry>
        </collision>
    </link>
    <link name="Leg20">
        <inertial>
            <origin xyz="0 0 1.1996050673443128" rpy="0 0 0"/>
            <mass value="1" />
            <inertia ixx="100" ixy="0" ixz="0" iyy="100" iyz="0" izz="100" />
        </inertial>
        <visual>
            <origin xyz="0 0 1.1996050673443128" rpy="0 0 0"/>
            <geometry>
                <box size="2.932294322103544 2.381794363060558 2.3992101346886257" />
            </geometry>
            <material name="Blue">
                <color rgba="0 1.0 1.0 1.0"/>
            </material>
        </visual>
        <collision>
            <origin xyz="0 0 1.1996050673443128" rpy="0 0 0"/>
            <geometry>
                <box size="2.932294322103544 2.381794363060558 2.3992101346886257" />
            </geometry>
        </collision>
    </link>
    <link name="Leg21">
        <inertial>
            <origin xyz="0 0.9804414400293519 0" rpy="0 0 0"/>
            <mass value="1" />
            <inertia ixx="100" ixy="0" ixz="0" iyy="100" iyz="0" izz="100" />
        </inertial>
        <visual>
            <origin xyz="0 0.9804414400293519 0" rpy="0 0 0"/>
            <geometry>
                <box size="1.2389143963380582 1.9608828800587037 2.5987638109578306" />
            </geometry>
            <material name="Blue">
                <color rgba="0 1.0 1.0 1.0"/>
            </material>
        </visual>
        <collision>
            <origin xyz="0 0.9804414400293519 0" rpy="0 0 0"/>
            <geometry>
                <box size="1.2389143963380582 1.9608828800587037 2.5987638109578306" />
            </geometry>
        </collision>
    </link>
    <link name="Leg22">
        <inertial>
            <origin xyz="0 0 0.7260778961228734" rpy="0 0 0"/>
            <mass value="1" />
            <inertia ixx="100" ixy="0" ixz="0" iyy="100" iyz="0" izz="100" />
        </inertial>
        <visual>
            <origin xyz="0 0 0.7260778961228734" rpy="0 0 0"/>
            <geometry>
                <box size="1.8903208069587651 2.9882282755616942 1.4521557922457469" />
            </geometry>
            <material name="Blue">
                <color rgba="0 1.0 1.0 1.0"/>
            </material>
        </visual>
        <collision>
            <origin xyz="0 0 0.7260778961228734" rpy="0 0 0"/>
            <geometry>
                <box size="1.8903208069587651 2.9882282755616942 1.4521557922457469" />
            </geometry>
        </collision>
    </link>
    <link name="Leg23">
        <inertial>
            <origin xyz="0 1.144409904261066 0" rpy="0 0 0"/>
            <mass value="1" />
            <inertia ixx="100" ixy="0" ixz="0" iyy="100" iyz="0" izz="100" />
        </inertial>
        <visual>
            <origin xyz="0 1.144409904261066 0" rpy="0 0 0"/>
            <geometry>
                <box size="1.707258313629486 2.288819808522132 2.3376074324105804" />
            </geometry>
            <material name="Green">
                <color rgba="0 180.0 0.0 1.0"/>
            </material>
        </visual>
        <collision>
            <origin xyz="0 1.144409904261066 0" rpy="0 0 0"/>
            <geometry>
                <box size="1.707258313629486 2.288819808522132 2.3376074324105804" />
            </geometry>
        </collision>
    </link>
    <link name="Leg24">
        <inertial>
            <origin xyz="0 0 0.8692603182014539" rpy="0 0 0"/>
            <mass value="1" />
            <inertia ixx="100" ixy="0" ixz="0" iyy="100" iyz="0" izz="100" />
        </inertial>
        <visual>
            <origin xyz="0 0 0.8692603182014539" rpy="0 0 0"/>
            <geometry>
                <box size="1.9393923239520674 2.1514105354224533 1.7385206364029078" />
            </geometry>
            <material name="Blue">
                <color rgba="0 1.0 1.0 1.0"/>
            </material>
        </visual>
        <collision>
            <origin xyz="0 0 0.8692603182014539" rpy="0 0 0"/>
            <geometry>
                <box size="1.9393923239520674 2.1514105354224533 1.7385206364029078" />
            </geometry>
        </collision>
    </link>
    <link name="Leg25">
        <inertial>
            <origin xyz="1.0374511406465299 0 0" rpy="0 0 0"/>
            <mass value="1" />
            <inertia ixx="100" ixy="0" ixz="0" iyy="100" iyz="0" izz="100" />
        </inertial>
        <visual>
            <origin xyz="1.0374511406465299 0 0" rpy="0 0 0"/>
            <geometry>
                <box size="2.0749022812930598 2.4202303400853467 1.0067876542532075" />
            </geometry>
            <material name="Blue">
                <color rgba="0 1.0 1.0 1.0"/>
            </material>
        </visual>
        <collision>
            <origin xyz="1.0374511406465299 0 0" rpy="0 0 0"/>
            <geometry>
                <box size="2.0749022812930598 2.4202303400853467 1.0067876542532075" />
            </geometry>
        </collision>
    </link>
    <link name="Leg26">
        <inertial>
            <origin xyz="0 0 0.6337228664431073" rpy="0 0 0"/>
            <mass value="1" />
            <inertia ixx="100" ixy="0" ixz="0" iyy="100" iyz="0" izz="100" />
        </inertial>
        <visual>
            <origin xyz="0 0 0.6337228664431073" rpy="0 0 0"/>
            <geometry>
                <box size="2.629994093993558 2.8166719174029797 1.2674457328862145" />
            </geometry>
            <material name="Blue">
                <color rgba="0 1.0 1.0 1.0"/>
            </material>
        </visual>
        <collision>
            <origin xyz="0 0 0.6337228664431073" rpy="0 0 0"/>
            <geometry>
                <box size="2.629994093993558 2.8166719174029797 1.2674457328862145" />
            </geometry>
        </collision>
    </link>
    <joint name="Torso_Leg1" type="revolute">
       <parent link="Torso"/>
       <child  link="Leg1"/>
       <origin rpy="0 0 0" xyz="0.7306994662006658 0 1.0958673781298431" />
     <axis xyz="1 0 0"/>
       <limit effort="0.0" lower="-3.14159" upper="3.14159" velocity="0.0"/>
    </joint>
    <joint name="Leg1_Leg2" type="revolute">
       <parent link="Leg1"/>
       <child  link="Leg2"/>
       <origin rpy="0 0 0" xyz="2.6003384395302818 0 0" />
     <axis xyz="1 0 0"/>
       <limit effort="0.0" lower="-3.14159" upper="3.14159" velocity="0.0"/>
    </joint>
    <joint name="Leg2_Leg3" type="revolute">
       <parent link="Leg2"/>
       <child  link="Leg3"/>
       <origin rpy="0 0 0" xyz="2.0656182287813674 0 0" />
     <axis xyz="1 0 0"/>
       <limit effort="0.0" lower="-3.14159" upper="3.14159" velocity="0.0"/>
    </joint>
    <joint name="Leg1_Leg4" type="revolute">
       <parent link="Leg1"/>
       <child  link="Leg4"/>
       <origin rpy="0 0 0" xyz="2.6003384395302818 0.629994188538248 0" />
     <axis xyz="1 0 0"/>
       <limit effort="0.0" lower="-3.14159" upper="3.14159" velocity="0.0"/>
    </joint>
    <joint name="Leg3_Leg5" type="revolute">
       <parent link="Leg3"/>
       <child  link="Leg5"/>
       <origin rpy="0 0 0" xyz="1.2424454727369452 1.019213701856435 0" />
     <axis xyz="1 0 0"/>
       <limit effort="0.0" lower="-3.14159" upper="3.14159" velocity="0.0"/>
    </joint>
    <joint name="Leg5_Leg6" type="revolute">
       <parent link="Leg5"/>
       <child  link="Leg6"/>
       <origin rpy="0 0 0" xyz="1.620991595822674 0 0" />
     <axis xyz="1 0 0"/>
       <limit effort="0.0" lower="-3.14159" upper="3.14159" velocity="0.0"/>
    </joint>
    <joint name="Torso_Leg7" type="revolute">
       <parent link="Torso"/>
       <child  link="Leg7"/>
       <origin rpy="0 0 0" xyz="0.729755259059567 0.9162963442532438 0" />
     <axis xyz="1 0 0"/>
       <limit effort="0.0" lower="-3.14159" upper="3.14159" velocity="0.0"/>
    </joint>
    <joint name="Leg5_Leg8" type="revolute">
       <parent link="Leg5"/>
       <child  link="Leg8"/>
       <origin rpy="0 0 0" xyz="1.620991595822674 0.611380467926519 0" />
     <axis xyz="1 0 0"/>
       <limit effort="0.0" lower="-3.14159" upper="3.14159" velocity="0.0"/>
    </joint>
    <joint name="Leg8_Leg9" type="revolute">
       <parent link="Leg8"/>
       <child  link="Leg9"/>
       <origin rpy="0 0 0" xyz="1.12030062602636 0 0" />
     <axis xyz="1 0 0"/>
       <limit effort="0.0" lower="-3.14159" upper="3.14159" velocity="0.0"/>
    </joint>
    <joint name="Leg1_Leg10" type="revolute">
       <parent link="Leg1"/>
       <child  link="Leg10"/>
       <origin rpy="0 0 0" xyz="2.6003384395302818 0.629994188538248 0.9395120722993637" />
     <axis xyz="1 0 0"/>
       <limit effort="0.0" lower="-3.14159" upper="3.14159" velocity="0.0"/>
    </joint>
    <joint name="Leg9_Leg11" type="revolute">
       <parent link="Leg9"/>
       <child  link="Leg11"/>
       <origin rpy="0 0 0" xyz="1.009096150311695 0 0.9275799443199965" />
     <axis xyz="1 0 0"/>
       <limit effort="0.0" lower="-3.14159" upper="3.14159" velocity="0.0"/>
    </joint>
    <joint name="Leg9_Leg12" type="revolute">
       <parent link="Leg9"/>
       <child  link="Leg12"/>
       <origin rpy="0 0 0" xyz="1.009096150311695 0 1.855159888639993" />
     <axis xyz="1 0 0"/>
       <limit effort="0.0" lower="-3.14159" upper="3.14159" velocity="0.0"/>
    </joint>
    <joint name="Leg4_Leg13" type="revolute">
       <parent link="Leg4"/>
       <child  link="Leg13"/>
       <origin rpy="0 0 0" xyz="0.6391301116851728 0 1.2468320877047734" />
     <axis xyz="1 0 0"/>
       <limit effort="0.0" lower="-3.14159" upper="3.14159" velocity="0.0"/>
    </joint>
    <joint name="Leg13_Leg14" type="revolute">
       <parent link="Leg13"/>
       <child  link="Leg14"/>
       <origin rpy="0 0 0" xyz="0 2.9556943806445926 0" />
     <axis xyz="1 0 0"/>
       <limit effort="0.0" lower="-3.14159" upper="3.14159" velocity="0.0"/>
    </joint>
    <joint name="Leg13_Leg15" type="revolute">
       <parent link="Leg13"/>
       <child  link="Leg15"/>
       <origin rpy="0 0 0" xyz="0.585104718201766 2.9556943806445926 0" />
     <axis xyz="1 0 0"/>
       <limit effort="0.0" lower="-3.14159" upper="3.14159" velocity="0.0"/>
    </joint>
    <joint name="Leg13_Leg16" type="revolute">
       <parent link="Leg13"/>
       <child  link="Leg16"/>
       <origin rpy="0 0 0" xyz="0.585104718201766 2.9556943806445926 1.4955010850148764" />
     <axis xyz="1 0 0"/>
       <limit effort="0.0" lower="-3.14159" upper="3.14159" velocity="0.0"/>
    </joint>
    <joint name="Leg15_Leg17" type="revolute">
       <parent link="Leg15"/>
       <child  link="Leg17"/>
       <origin rpy="0 0 0" xyz="0.8386138927528997 0 1.1879896686598035" />
     <axis xyz="1 0 0"/>
       <limit effort="0.0" lower="-3.14159" upper="3.14159" velocity="0.0"/>
    </joint>
    <joint name="Leg15_Leg18" type="revolute">
       <parent link="Leg15"/>
       <child  link="Leg18"/>
       <origin rpy="0 0 0" xyz="0.8386138927528997 1.3663524088608654 1.1879896686598035" />
     <axis xyz="1 0 0"/>
       <limit effort="0.0" lower="-3.14159" upper="3.14159" velocity="0.0"/>
    </joint>
    <joint name="Leg6_Leg19" type="revolute">
       <parent link="Leg6"/>
       <child  link="Leg19"/>
       <origin rpy="0 0 0" xyz="0 0.8002340829078916 1.1653211396337069" />
     <axis xyz="1 0 0"/>
       <limit effort="0.0" lower="-3.14159" upper="3.14159" velocity="0.0"/>
    </joint>
    <joint name="Leg18_Leg20" type="revolute">
       <parent link="Leg18"/>
       <child  link="Leg20"/>
       <origin rpy="0 0 0" xyz="0 0 1.5272187530210546" />
     <axis xyz="1 0 0"/>
       <limit effort="0.0" lower="-3.14159" upper="3.14159" velocity="0.0"/>
    </joint>
    <joint name="Leg16_Leg21" type="revolute">
       <parent link="Leg16"/>
       <child  link="Leg21"/>
       <origin rpy="0 0 0" xyz="1.3236070604335333 1.1086255195338017 0" />
     <axis xyz="1 0 0"/>
       <limit effort="0.0" lower="-3.14159" upper="3.14159" velocity="0.0"/>
    </joint>
    <joint name="Leg8_Leg22" type="revolute">
       <parent link="Leg8"/>
       <child  link="Leg22"/>
       <origin rpy="0 0 0" xyz="1.12030062602636 0 0.9108613475150168" />
     <axis xyz="1 0 0"/>
       <limit effort="0.0" lower="-3.14159" upper="3.14159" velocity="0.0"/>
    </joint>
    <joint name="Leg9_Leg23" type="revolute">
       <parent link="Leg9"/>
       <child  link="Leg23"/>
       <origin rpy="0 0 0" xyz="1.009096150311695 1.3428172180723261 1.855159888639993" />
     <axis xyz="1 0 0"/>
       <limit effort="0.0" lower="-3.14159" upper="3.14159" velocity="0.0"/>
    </joint>
    <joint name="Leg11_Leg24" type="revolute">
       <parent link="Leg11"/>
       <child  link="Leg24"/>
       <origin rpy="0 0 0" xyz="0 0 1.9256431414948307" />
     <axis xyz="1 0 0"/>
       <limit effort="0.0" lower="-3.14159" upper="3.14159" velocity="0.0"/>
    </joint>
    <joint name="Leg12_Leg25" type="revolute">
       <parent link="Leg12"/>
       <child  link="Leg25"/>
       <origin rpy="0 0 0" xyz="0.9243422827459601 0 1.3525554704298957" />
     <axis xyz="1 0 0"/>
       <limit effort="0.0" lower="-3.14159" upper="3.14159" velocity="0.0"/>
    </joint>
    <joint name="Leg22_Leg26" type="revolute">
       <parent link="Leg22"/>
       <child  link="Leg26"/>
       <origin rpy="0 0 0" xyz="0 1.144409904261066 1.1688037162052902" />
     <axis xyz="1 0 0"/>
       <limit effort="0.0" lower="-3.14159" upper="3.14159" velocity="0.0"/>
    </joint>
</robot>