<robot name = "robot">
    <link name="Torso">
        <inertial>
            <origin xyz="0 0 0.7253277199540609" rpy="0 0 0"/>
            <mass value="1" />
            <inertia ixx="100" ixy="0" ixz="0" iyy="100" iyz="0" izz="100" />
        </inertial>
        <visual>
            <origin xyz="0 0 0.7253277199540609" rpy="0 0 0"/>
            <geometry>
                <box size="2.726591562659938 1.0355448796741393 1.4506554399081217" />
            </geometry>
            <material name="Green">
                <color rgba="0 180.0 0.0 1.0"/>
            </material>
        </visual>
        <collision>
            <origin xyz="0 0 0.7253277199540609" rpy="0 0 0"/>
            <geometry>
                <box size="2.726591562659938 1.0355448796741393 1.4506554399081217" />
            </geometry>
        </collision>
    </link>
    <link name="Leg1">
        <inertial>
            <origin xyz="0 0 1.1907272840814522" rpy="0 0 0"/>
            <mass value="1" />
            <inertia ixx="100" ixy="0" ixz="0" iyy="100" iyz="0" izz="100" />
        </inertial>
        <visual>
            <origin xyz="0 0 1.1907272840814522" rpy="0 0 0"/>
            <geometry>
                <box size="1.314925983464604 1.0932844677340048 2.3814545681629045" />
            </geometry>
            <material name="Green">
                <color rgba="0 180.0 0.0 1.0"/>
            </material>
        </visual>
        <collision>
            <origin xyz="0 0 1.1907272840814522" rpy="0 0 0"/>
            <geometry>
                <box size="1.314925983464604 1.0932844677340048 2.3814545681629045" />
            </geometry>
        </collision>
    </link>
    <link name="Leg2">
        <inertial>
            <origin xyz="0 0.5378913253820834 0" rpy="0 0 0"/>
            <mass value="1" />
            <inertia ixx="100" ixy="0" ixz="0" iyy="100" iyz="0" izz="100" />
        </inertial>
        <visual>
            <origin xyz="0 0.5378913253820834 0" rpy="0 0 0"/>
            <geometry>
                <box size="2.520069896187505 1.0757826507641668 2.832989232310977" />
            </geometry>
            <material name="Green">
                <color rgba="0 180.0 0.0 1.0"/>
            </material>
        </visual>
        <collision>
            <origin xyz="0 0.5378913253820834 0" rpy="0 0 0"/>
            <geometry>
                <box size="2.520069896187505 1.0757826507641668 2.832989232310977" />
            </geometry>
        </collision>
    </link>
    <link name="Leg3">
        <inertial>
            <origin xyz="1.110280834103786 0 0" rpy="0 0 0"/>
            <mass value="1" />
            <inertia ixx="100" ixy="0" ixz="0" iyy="100" iyz="0" izz="100" />
        </inertial>
        <visual>
            <origin xyz="1.110280834103786 0 0" rpy="0 0 0"/>
            <geometry>
                <box size="2.220561668207572 1.7415532345764024 1.811710930233675" />
            </geometry>
            <material name="Blue">
                <color rgba="0 1.0 1.0 1.0"/>
            </material>
        </visual>
        <collision>
            <origin xyz="1.110280834103786 0 0" rpy="0 0 0"/>
            <geometry>
                <box size="2.220561668207572 1.7415532345764024 1.811710930233675" />
            </geometry>
        </collision>
    </link>
    <link name="Leg4">
        <inertial>
            <origin xyz="0 0 1.1404002942357523" rpy="0 0 0"/>
            <mass value="1" />
            <inertia ixx="100" ixy="0" ixz="0" iyy="100" iyz="0" izz="100" />
        </inertial>
        <visual>
            <origin xyz="0 0 1.1404002942357523" rpy="0 0 0"/>
            <geometry>
                <box size="2.7587833048837176 1.9300786767396179 2.2808005884715046" />
            </geometry>
            <material name="Green">
                <color rgba="0 180.0 0.0 1.0"/>
            </material>
        </visual>
        <collision>
            <origin xyz="0 0 1.1404002942357523" rpy="0 0 0"/>
            <geometry>
                <box size="2.7587833048837176 1.9300786767396179 2.2808005884715046" />
            </geometry>
        </collision>
    </link>
    <link name="Leg5">
        <inertial>
            <origin xyz="0 0 1.2395601121104804" rpy="0 0 0"/>
            <mass value="1" />
            <inertia ixx="100" ixy="0" ixz="0" iyy="100" iyz="0" izz="100" />
        </inertial>
        <visual>
            <origin xyz="0 0 1.2395601121104804" rpy="0 0 0"/>
            <geometry>
                <box size="2.370597901741896 2.0140771139033933 2.479120224220961" />
            </geometry>
            <material name="Blue">
                <color rgba="0 1.0 1.0 1.0"/>
            </material>
        </visual>
        <collision>
            <origin xyz="0 0 1.2395601121104804" rpy="0 0 0"/>
            <geometry>
                <box size="2.370597901741896 2.0140771139033933 2.479120224220961" />
            </geometry>
        </collision>
    </link>
    <link name="Leg6">
        <inertial>
            <origin xyz="0 0 0.9441403597015017" rpy="0 0 0"/>
            <mass value="1" />
            <inertia ixx="100" ixy="0" ixz="0" iyy="100" iyz="0" izz="100" />
        </inertial>
        <visual>
            <origin xyz="0 0 0.9441403597015017" rpy="0 0 0"/>
            <geometry>
                <box size="1.815128604880457 1.4047932656356859 1.8882807194030033" />
            </geometry>
            <material name="Green">
                <color rgba="0 180.0 0.0 1.0"/>
            </material>
        </visual>
        <collision>
            <origin xyz="0 0 0.9441403597015017" rpy="0 0 0"/>
            <geometry>
                <box size="1.815128604880457 1.4047932656356859 1.8882807194030033" />
            </geometry>
        </collision>
    </link>
    <link name="Leg7">
        <inertial>
            <origin xyz="0 0 0.5172587591212344" rpy="0 0 0"/>
            <mass value="1" />
            <inertia ixx="100" ixy="0" ixz="0" iyy="100" iyz="0" izz="100" />
        </inertial>
        <visual>
            <origin xyz="0 0 0.5172587591212344" rpy="0 0 0"/>
            <geometry>
                <box size="2.1036250535001075 1.8651065654349062 1.0345175182424688" />
            </geometry>
            <material name="Green">
                <color rgba="0 180.0 0.0 1.0"/>
            </material>
        </visual>
        <collision>
            <origin xyz="0 0 0.5172587591212344" rpy="0 0 0"/>
            <geometry>
                <box size="2.1036250535001075 1.8651065654349062 1.0345175182424688" />
            </geometry>
        </collision>
    </link>
    <link name="Leg8">
        <inertial>
            <origin xyz="0 0.5065106365679859 0" rpy="0 0 0"/>
            <mass value="1" />
            <inertia ixx="100" ixy="0" ixz="0" iyy="100" iyz="0" izz="100" />
        </inertial>
        <visual>
            <origin xyz="0 0.5065106365679859 0" rpy="0 0 0"/>
            <geometry>
                <box size="2.4958335449687685 1.0130212731359718 2.4340498457595166" />
            </geometry>
            <material name="Blue">
                <color rgba="0 1.0 1.0 1.0"/>
            </material>
        </visual>
        <collision>
            <origin xyz="0 0.5065106365679859 0" rpy="0 0 0"/>
            <geometry>
                <box size="2.4958335449687685 1.0130212731359718 2.4340498457595166" />
            </geometry>
        </collision>
    </link>
    <link name="Leg9">
        <inertial>
            <origin xyz="1.1846654983409248 0 0" rpy="0 0 0"/>
            <mass value="1" />
            <inertia ixx="100" ixy="0" ixz="0" iyy="100" iyz="0" izz="100" />
        </inertial>
        <visual>
            <origin xyz="1.1846654983409248 0 0" rpy="0 0 0"/>
            <geometry>
                <box size="2.3693309966818497 2.629789583649747 1.7683371573117497" />
            </geometry>
            <material name="Blue">
                <color rgba="0 1.0 1.0 1.0"/>
            </material>
        </visual>
        <collision>
            <origin xyz="1.1846654983409248 0 0" rpy="0 0 0"/>
            <geometry>
                <box size="2.3693309966818497 2.629789583649747 1.7683371573117497" />
            </geometry>
        </collision>
    </link>
    <link name="Leg10">
        <inertial>
            <origin xyz="0 0 0.7827005465555027" rpy="0 0 0"/>
            <mass value="1" />
            <inertia ixx="100" ixy="0" ixz="0" iyy="100" iyz="0" izz="100" />
        </inertial>
        <visual>
            <origin xyz="0 0 0.7827005465555027" rpy="0 0 0"/>
            <geometry>
                <box size="2.335814812016894 1.1363541283002425 1.5654010931110054" />
            </geometry>
            <material name="Green">
                <color rgba="0 180.0 0.0 1.0"/>
            </material>
        </visual>
        <collision>
            <origin xyz="0 0 0.7827005465555027" rpy="0 0 0"/>
            <geometry>
                <box size="2.335814812016894 1.1363541283002425 1.5654010931110054" />
            </geometry>
        </collision>
    </link>
    <link name="Leg11">
        <inertial>
            <origin xyz="0 1.3173811572733922 0" rpy="0 0 0"/>
            <mass value="1" />
            <inertia ixx="100" ixy="0" ixz="0" iyy="100" iyz="0" izz="100" />
        </inertial>
        <visual>
            <origin xyz="0 1.3173811572733922 0" rpy="0 0 0"/>
            <geometry>
                <box size="2.9865200140320614 2.6347623145467844 1.8674852585098922" />
            </geometry>
            <material name="Green">
                <color rgba="0 180.0 0.0 1.0"/>
            </material>
        </visual>
        <collision>
            <origin xyz="0 1.3173811572733922 0" rpy="0 0 0"/>
            <geometry>
                <box size="2.9865200140320614 2.6347623145467844 1.8674852585098922" />
            </geometry>
        </collision>
    </link>
    <link name="Leg12">
        <inertial>
            <origin xyz="0 0.669491029151656 0" rpy="0 0 0"/>
            <mass value="1" />
            <inertia ixx="100" ixy="0" ixz="0" iyy="100" iyz="0" izz="100" />
        </inertial>
        <visual>
            <origin xyz="0 0.669491029151656 0" rpy="0 0 0"/>
            <geometry>
                <box size="2.555464522735975 1.338982058303312 1.5576832534407679" />
            </geometry>
            <material name="Green">
                <color rgba="0 180.0 0.0 1.0"/>
            </material>
        </visual>
        <collision>
            <origin xyz="0 0.669491029151656 0" rpy="0 0 0"/>
            <geometry>
                <box size="2.555464522735975 1.338982058303312 1.5576832534407679" />
            </geometry>
        </collision>
    </link>
    <link name="Leg13">
        <inertial>
            <origin xyz="0 0 0.7299120304443101" rpy="0 0 0"/>
            <mass value="1" />
            <inertia ixx="100" ixy="0" ixz="0" iyy="100" iyz="0" izz="100" />
        </inertial>
        <visual>
            <origin xyz="0 0 0.7299120304443101" rpy="0 0 0"/>
            <geometry>
                <box size="1.2352222829165393 2.641041226543769 1.4598240608886202" />
            </geometry>
            <material name="Green">
                <color rgba="0 180.0 0.0 1.0"/>
            </material>
        </visual>
        <collision>
            <origin xyz="0 0 0.7299120304443101" rpy="0 0 0"/>
            <geometry>
                <box size="1.2352222829165393 2.641041226543769 1.4598240608886202" />
            </geometry>
        </collision>
    </link>
    <link name="Leg14">
        <inertial>
            <origin xyz="0 0 0.9616622518686984" rpy="0 0 0"/>
            <mass value="1" />
            <inertia ixx="100" ixy="0" ixz="0" iyy="100" iyz="0" izz="100" />
        </inertial>
        <visual>
            <origin xyz="0 0 0.9616622518686984" rpy="0 0 0"/>
            <geometry>
                <box size="2.0674706437309127 2.6513508160020205 1.9233245037373967" />
            </geometry>
            <material name="Green">
                <color rgba="0 180.0 0.0 1.0"/>
            </material>
        </visual>
        <collision>
            <origin xyz="0 0 0.9616622518686984" rpy="0 0 0"/>
            <geometry>
                <box size="2.0674706437309127 2.6513508160020205 1.9233245037373967" />
            </geometry>
        </collision>
    </link>
    <link name="Leg15">
        <inertial>
            <origin xyz="1.4176634094546179 0 0" rpy="0 0 0"/>
            <mass value="1" />
            <inertia ixx="100" ixy="0" ixz="0" iyy="100" iyz="0" izz="100" />
        </inertial>
        <visual>
            <origin xyz="1.4176634094546179 0 0" rpy="0 0 0"/>
            <geometry>
                <box size="2.8353268189092358 1.616705921569612 1.8778769804414501" />
            </geometry>
            <material name="Green">
                <color rgba="0 180.0 0.0 1.0"/>
            </material>
        </visual>
        <collision>
            <origin xyz="1.4176634094546179 0 0" rpy="0 0 0"/>
            <geometry>
                <box size="2.8353268189092358 1.616705921569612 1.8778769804414501" />
            </geometry>
        </collision>
    </link>
    <link name="Leg16">
        <inertial>
            <origin xyz="0.7742005230767459 0 0" rpy="0 0 0"/>
            <mass value="1" />
            <inertia ixx="100" ixy="0" ixz="0" iyy="100" iyz="0" izz="100" />
        </inertial>
        <visual>
            <origin xyz="0.7742005230767459 0 0" rpy="0 0 0"/>
            <geometry>
                <box size="1.5484010461534918 1.0613971789435468 1.061954526220446" />
            </geometry>
            <material name="Green">
                <color rgba="0 180.0 0.0 1.0"/>
            </material>
        </visual>
        <collision>
            <origin xyz="0.7742005230767459 0 0" rpy="0 0 0"/>
            <geometry>
                <box size="1.5484010461534918 1.0613971789435468 1.061954526220446" />
            </geometry>
        </collision>
    </link>
    <link name="Leg17">
        <inertial>
            <origin xyz="1.1587492152601895 0 0" rpy="0 0 0"/>
            <mass value="1" />
            <inertia ixx="100" ixy="0" ixz="0" iyy="100" iyz="0" izz="100" />
        </inertial>
        <visual>
            <origin xyz="1.1587492152601895 0 0" rpy="0 0 0"/>
            <geometry>
                <box size="2.317498430520379 1.413568488064656 1.1960354313412327" />
            </geometry>
            <material name="Blue">
                <color rgba="0 1.0 1.0 1.0"/>
            </material>
        </visual>
        <collision>
            <origin xyz="1.1587492152601895 0 0" rpy="0 0 0"/>
            <geometry>
                <box size="2.317498430520379 1.413568488064656 1.1960354313412327" />
            </geometry>
        </collision>
    </link>
    <link name="Leg18">
        <inertial>
            <origin xyz="0 1.1926299828922082 0" rpy="0 0 0"/>
            <mass value="1" />
            <inertia ixx="100" ixy="0" ixz="0" iyy="100" iyz="0" izz="100" />
        </inertial>
        <visual>
            <origin xyz="0 1.1926299828922082 0" rpy="0 0 0"/>
            <geometry>
                <box size="2.6484390503362434 2.3852599657844165 2.0632461406442157" />
            </geometry>
            <material name="Blue">
                <color rgba="0 1.0 1.0 1.0"/>
            </material>
        </visual>
        <collision>
            <origin xyz="0 1.1926299828922082 0" rpy="0 0 0"/>
            <geometry>
                <box size="2.6484390503362434 2.3852599657844165 2.0632461406442157" />
            </geometry>
        </collision>
    </link>
    <link name="Leg19">
        <inertial>
            <origin xyz="0 0.5867554676433115 0" rpy="0 0 0"/>
            <mass value="1" />
            <inertia ixx="100" ixy="0" ixz="0" iyy="100" iyz="0" izz="100" />
        </inertial>
        <visual>
            <origin xyz="0 0.5867554676433115 0" rpy="0 0 0"/>
            <geometry>
                <box size="1.143810450612909 1.173510935286623 2.306682626680164" />
            </geometry>
            <material name="Blue">
                <color rgba="0 1.0 1.0 1.0"/>
            </material>
        </visual>
        <collision>
            <origin xyz="0 0.5867554676433115 0" rpy="0 0 0"/>
            <geometry>
                <box size="1.143810450612909 1.173510935286623 2.306682626680164" />
            </geometry>
        </collision>
    </link>
    <link name="Leg20">
        <inertial>
            <origin xyz="0 0 0.6466973688798799" rpy="0 0 0"/>
            <mass value="1" />
            <inertia ixx="100" ixy="0" ixz="0" iyy="100" iyz="0" izz="100" />
        </inertial>
        <visual>
            <origin xyz="0 0 0.6466973688798799" rpy="0 0 0"/>
            <geometry>
                <box size="1.2219815129641718 2.9556532691210315 1.2933947377597599" />
            </geometry>
            <material name="Green">
                <color rgba="0 180.0 0.0 1.0"/>
            </material>
        </visual>
        <collision>
            <origin xyz="0 0 0.6466973688798799" rpy="0 0 0"/>
            <geometry>
                <box size="1.2219815129641718 2.9556532691210315 1.2933947377597599" />
            </geometry>
        </collision>
    </link>
    <link name="Leg21">
        <inertial>
            <origin xyz="0 0 0.9804243562591657" rpy="0 0 0"/>
            <mass value="1" />
            <inertia ixx="100" ixy="0" ixz="0" iyy="100" iyz="0" izz="100" />
        </inertial>
        <visual>
            <origin xyz="0 0 0.9804243562591657" rpy="0 0 0"/>
            <geometry>
                <box size="1.730588291700422 2.969176238978509 1.9608487125183314" />
            </geometry>
            <material name="Green">
                <color rgba="0 180.0 0.0 1.0"/>
            </material>
        </visual>
        <collision>
            <origin xyz="0 0 0.9804243562591657" rpy="0 0 0"/>
            <geometry>
                <box size="1.730588291700422 2.969176238978509 1.9608487125183314" />
            </geometry>
        </collision>
    </link>
    <link name="Leg22">
        <inertial>
            <origin xyz="0 0 0.7470515005949321" rpy="0 0 0"/>
            <mass value="1" />
            <inertia ixx="100" ixy="0" ixz="0" iyy="100" iyz="0" izz="100" />
        </inertial>
        <visual>
            <origin xyz="0 0 0.7470515005949321" rpy="0 0 0"/>
            <geometry>
                <box size="2.54703281932061 1.63876178498598 1.4941030011898642" />
            </geometry>
            <material name="Blue">
                <color rgba="0 1.0 1.0 1.0"/>
            </material>
        </visual>
        <collision>
            <origin xyz="0 0 0.7470515005949321" rpy="0 0 0"/>
            <geometry>
                <box size="2.54703281932061 1.63876178498598 1.4941030011898642" />
            </geometry>
        </collision>
    </link>
    <link name="Leg23">
        <inertial>
            <origin xyz="0 0.8336431466398991 0" rpy="0 0 0"/>
            <mass value="1" />
            <inertia ixx="100" ixy="0" ixz="0" iyy="100" iyz="0" izz="100" />
        </inertial>
        <visual>
            <origin xyz="0 0.8336431466398991 0" rpy="0 0 0"/>
            <geometry>
                <box size="1.8165362351010539 1.6672862932797983 2.0394723350789494" />
            </geometry>
            <material name="Blue">
                <color rgba="0 1.0 1.0 1.0"/>
            </material>
        </visual>
        <collision>
            <origin xyz="0 0.8336431466398991 0" rpy="0 0 0"/>
            <geometry>
                <box size="1.8165362351010539 1.6672862932797983 2.0394723350789494" />
            </geometry>
        </collision>
    </link>
    <link name="Leg24">
        <inertial>
            <origin xyz="0 1.0133044342372035 0" rpy="0 0 0"/>
            <mass value="1" />
            <inertia ixx="100" ixy="0" ixz="0" iyy="100" iyz="0" izz="100" />
        </inertial>
        <visual>
            <origin xyz="0 1.0133044342372035 0" rpy="0 0 0"/>
            <geometry>
                <box size="2.548085283516696 2.026608868474407 1.182415329411242" />
            </geometry>
            <material name="Green">
                <color rgba="0 180.0 0.0 1.0"/>
            </material>
        </visual>
        <collision>
            <origin xyz="0 1.0133044342372035 0" rpy="0 0 0"/>
            <geometry>
                <box size="2.548085283516696 2.026608868474407 1.182415329411242" />
            </geometry>
        </collision>
    </link>
    <link name="Leg25">
        <inertial>
            <origin xyz="0 1.205220009245712 0" rpy="0 0 0"/>
            <mass value="1" />
            <inertia ixx="100" ixy="0" ixz="0" iyy="100" iyz="0" izz="100" />
        </inertial>
        <visual>
            <origin xyz="0 1.205220009245712 0" rpy="0 0 0"/>
            <geometry>
                <box size="2.883727520591954 2.410440018491424 1.0191712379833635" />
            </geometry>
            <material name="Blue">
                <color rgba="0 1.0 1.0 1.0"/>
            </material>
        </visual>
        <collision>
            <origin xyz="0 1.205220009245712 0" rpy="0 0 0"/>
            <geometry>
                <box size="2.883727520591954 2.410440018491424 1.0191712379833635" />
            </geometry>
        </collision>
    </link>
    <joint name="Torso_Leg1" type="revolute">
       <parent link="Torso"/>
       <child  link="Leg1"/>
       <origin rpy="0 0 0" xyz="0 0 1.4506554399081217" />
     <axis xyz="1 0 0"/>
       <limit effort="0.0" lower="-3.14159" upper="3.14159" velocity="0.0"/>
    </joint>
    <joint name="Leg1_Leg2" type="revolute">
       <parent link="Leg1"/>
       <child  link="Leg2"/>
       <origin rpy="0 0 0" xyz="0 1.0757826507641668 0" />
     <axis xyz="1 0 0"/>
       <limit effort="0.0" lower="-3.14159" upper="3.14159" velocity="0.0"/>
    </joint>
    <joint name="Leg2_Leg3" type="revolute">
       <parent link="Leg2"/>
       <child  link="Leg3"/>
       <origin rpy="0 0 0" xyz="2.220561668207572 0 0" />
     <axis xyz="1 0 0"/>
       <limit effort="0.0" lower="-3.14159" upper="3.14159" velocity="0.0"/>
    </joint>
    <joint name="Leg2_Leg4" type="revolute">
       <parent link="Leg2"/>
       <child  link="Leg4"/>
       <origin rpy="0 0 0" xyz="2.220561668207572 0 0.9058554651168375" />
     <axis xyz="1 0 0"/>
       <limit effort="0.0" lower="-3.14159" upper="3.14159" velocity="0.0"/>
    </joint>
    <joint name="Leg1_Leg5" type="revolute">
       <parent link="Leg1"/>
       <child  link="Leg5"/>
       <origin rpy="0 0 0" xyz="0 1.0757826507641668 1.4164946161554886" />
     <axis xyz="1 0 0"/>
       <limit effort="0.0" lower="-3.14159" upper="3.14159" velocity="0.0"/>
    </joint>
    <joint name="Leg5_Leg6" type="revolute">
       <parent link="Leg5"/>
       <child  link="Leg6"/>
       <origin rpy="0 0 0" xyz="0 0 1.8882807194030033" />
     <axis xyz="1 0 0"/>
       <limit effort="0.0" lower="-3.14159" upper="3.14159" velocity="0.0"/>
    </joint>
    <joint name="Leg4_Leg7" type="revolute">
       <parent link="Leg4"/>
       <child  link="Leg7"/>
       <origin rpy="0 0 0" xyz="0 0 2.479120224220961" />
     <axis xyz="1 0 0"/>
       <limit effort="0.0" lower="-3.14159" upper="3.14159" velocity="0.0"/>
    </joint>
    <joint name="Leg3_Leg8" type="revolute">
       <parent link="Leg3"/>
       <child  link="Leg8"/>
       <origin rpy="0 0 0" xyz="0 0.9650393383698089 1.1404002942357523" />
     <axis xyz="1 0 0"/>
       <limit effort="0.0" lower="-3.14159" upper="3.14159" velocity="0.0"/>
    </joint>
    <joint name="Leg6_Leg9" type="revolute">
       <parent link="Leg6"/>
       <child  link="Leg9"/>
       <origin rpy="0 0 0" xyz="1.0518125267500538 0 0.5172587591212344" />
     <axis xyz="1 0 0"/>
       <limit effort="0.0" lower="-3.14159" upper="3.14159" velocity="0.0"/>
    </joint>
    <joint name="Leg6_Leg10" type="revolute">
       <parent link="Leg6"/>
       <child  link="Leg10"/>
       <origin rpy="0 0 0" xyz="1.0518125267500538 0 1.0345175182424688" />
     <axis xyz="1 0 0"/>
       <limit effort="0.0" lower="-3.14159" upper="3.14159" velocity="0.0"/>
    </joint>
    <joint name="Leg8_Leg11" type="revolute">
       <parent link="Leg8"/>
       <child  link="Leg11"/>
       <origin rpy="0 0 0" xyz="1.1846654983409248 1.3148947918248735 0" />
     <axis xyz="1 0 0"/>
       <limit effort="0.0" lower="-3.14159" upper="3.14159" velocity="0.0"/>
    </joint>
    <joint name="Torso_Leg12" type="revolute">
       <parent link="Torso"/>
       <child  link="Leg12"/>
       <origin rpy="0 0 0" xyz="0 0.5466422338670024 1.1907272840814522" />
     <axis xyz="1 0 0"/>
       <limit effort="0.0" lower="-3.14159" upper="3.14159" velocity="0.0"/>
    </joint>
    <joint name="Leg3_Leg13" type="revolute">
       <parent link="Leg3"/>
       <child  link="Leg13"/>
       <origin rpy="0 0 0" xyz="0 0.9650393383698089 2.2808005884715046" />
     <axis xyz="1 0 0"/>
       <limit effort="0.0" lower="-3.14159" upper="3.14159" velocity="0.0"/>
    </joint>
    <joint name="Leg8_Leg14" type="revolute">
       <parent link="Leg8"/>
       <child  link="Leg14"/>
       <origin rpy="0 0 0" xyz="1.1846654983409248 1.3148947918248735 0.8841685786558748" />
     <axis xyz="1 0 0"/>
       <limit effort="0.0" lower="-3.14159" upper="3.14159" velocity="0.0"/>
    </joint>
    <joint name="Leg1_Leg15" type="revolute">
       <parent link="Leg1"/>
       <child  link="Leg15"/>
       <origin rpy="0 0 0" xyz="1.2600349480937525 1.0757826507641668 1.4164946161554886" />
     <axis xyz="1 0 0"/>
       <limit effort="0.0" lower="-3.14159" upper="3.14159" velocity="0.0"/>
    </joint>
    <joint name="Leg7_Leg16" type="revolute">
       <parent link="Leg7"/>
       <child  link="Leg16"/>
       <origin rpy="0 0 0" xyz="1.2479167724843843 0.5065106365679859 0" />
     <axis xyz="1 0 0"/>
       <limit effort="0.0" lower="-3.14159" upper="3.14159" velocity="0.0"/>
    </joint>
    <joint name="Torso_Leg17" type="revolute">
       <parent link="Torso"/>
       <child  link="Leg17"/>
       <origin rpy="0 0 0" xyz="0.657462991732302 0.5466422338670024 1.1907272840814522" />
     <axis xyz="1 0 0"/>
       <limit effort="0.0" lower="-3.14159" upper="3.14159" velocity="0.0"/>
    </joint>
    <joint name="Leg2_Leg18" type="revolute">
       <parent link="Leg2"/>
       <child  link="Leg18"/>
       <origin rpy="0 0 0" xyz="2.220561668207572 0.8707766172882012 0.9058554651168375" />
     <axis xyz="1 0 0"/>
       <limit effort="0.0" lower="-3.14159" upper="3.14159" velocity="0.0"/>
    </joint>
    <joint name="Leg16_Leg19" type="revolute">
       <parent link="Leg16"/>
       <child  link="Leg19"/>
       <origin rpy="0 0 0" xyz="1.1587492152601895 0.706784244032328 0" />
     <axis xyz="1 0 0"/>
       <limit effort="0.0" lower="-3.14159" upper="3.14159" velocity="0.0"/>
    </joint>
    <joint name="Leg13_Leg20" type="revolute">
       <parent link="Leg13"/>
       <child  link="Leg20"/>
       <origin rpy="0 0 0" xyz="0 0 1.9233245037373967" />
     <axis xyz="1 0 0"/>
       <limit effort="0.0" lower="-3.14159" upper="3.14159" velocity="0.0"/>
    </joint>
    <joint name="Leg9_Leg21" type="revolute">
       <parent link="Leg9"/>
       <child  link="Leg21"/>
       <origin rpy="0 0 0" xyz="0 0 1.5654010931110054" />
     <axis xyz="1 0 0"/>
       <limit effort="0.0" lower="-3.14159" upper="3.14159" velocity="0.0"/>
    </joint>
    <joint name="Leg15_Leg22" type="revolute">
       <parent link="Leg15"/>
       <child  link="Leg22"/>
       <origin rpy="0 0 0" xyz="0.7742005230767459 0 0.530977263110223" />
     <axis xyz="1 0 0"/>
       <limit effort="0.0" lower="-3.14159" upper="3.14159" velocity="0.0"/>
    </joint>
    <joint name="Leg7_Leg23" type="revolute">
       <parent link="Leg7"/>
       <child  link="Leg23"/>
       <origin rpy="0 0 0" xyz="1.2479167724843843 1.0130212731359718 0" />
     <axis xyz="1 0 0"/>
       <limit effort="0.0" lower="-3.14159" upper="3.14159" velocity="0.0"/>
    </joint>
    <joint name="Leg19_Leg24" type="revolute">
       <parent link="Leg19"/>
       <child  link="Leg24"/>
       <origin rpy="0 0 0" xyz="0 1.4778266345605158 0.6466973688798799" />
     <axis xyz="1 0 0"/>
       <limit effort="0.0" lower="-3.14159" upper="3.14159" velocity="0.0"/>
    </joint>
    <joint name="Leg23_Leg25" type="revolute">
       <parent link="Leg23"/>
       <child  link="Leg25"/>
       <origin rpy="0 0 0" xyz="0 2.026608868474407 0" />
     <axis xyz="1 0 0"/>
       <limit effort="0.0" lower="-3.14159" upper="3.14159" velocity="0.0"/>
    </joint>
</robot>