<robot name = "robot">
    <link name="Torso">
        <inertial>
            <origin xyz="0 0 0.7135287731432332" rpy="0 0 0"/>
            <mass value="1" />
            <inertia ixx="100" ixy="0" ixz="0" iyy="100" iyz="0" izz="100" />
        </inertial>
        <visual>
            <origin xyz="0 0 0.7135287731432332" rpy="0 0 0"/>
            <geometry>
                <box size="2.8955630135486006 2.3372293623005724 1.4270575462864663" />
            </geometry>
            <material name="Green">
                <color rgba="0 180.0 0.0 1.0"/>
            </material>
        </visual>
        <collision>
            <origin xyz="0 0 0.7135287731432332" rpy="0 0 0"/>
            <geometry>
                <box size="2.8955630135486006 2.3372293623005724 1.4270575462864663" />
            </geometry>
        </collision>
    </link>
    <link name="Leg1">
        <inertial>
            <origin xyz="0 0.5149594145567076 0" rpy="0 0 0"/>
            <mass value="1" />
            <inertia ixx="100" ixy="0" ixz="0" iyy="100" iyz="0" izz="100" />
        </inertial>
        <visual>
            <origin xyz="0 0.5149594145567076 0" rpy="0 0 0"/>
            <geometry>
                <box size="1.6281226191654687 1.0299188291134151 1.8514036711801167" />
            </geometry>
            <material name="Green">
                <color rgba="0 180.0 0.0 1.0"/>
            </material>
        </visual>
        <collision>
            <origin xyz="0 0.5149594145567076 0" rpy="0 0 0"/>
            <geometry>
                <box size="1.6281226191654687 1.0299188291134151 1.8514036711801167" />
            </geometry>
        </collision>
    </link>
    <link name="Leg2">
        <inertial>
            <origin xyz="1.3815324476360367 0 0" rpy="0 0 0"/>
            <mass value="1" />
            <inertia ixx="100" ixy="0" ixz="0" iyy="100" iyz="0" izz="100" />
        </inertial>
        <visual>
            <origin xyz="1.3815324476360367 0 0" rpy="0 0 0"/>
            <geometry>
                <box size="2.7630648952720733 2.552088861651977 1.5317462639285306" />
            </geometry>
            <material name="Green">
                <color rgba="0 180.0 0.0 1.0"/>
            </material>
        </visual>
        <collision>
            <origin xyz="1.3815324476360367 0 0" rpy="0 0 0"/>
            <geometry>
                <box size="2.7630648952720733 2.552088861651977 1.5317462639285306" />
            </geometry>
        </collision>
    </link>
    <link name="Leg3">
        <inertial>
            <origin xyz="0 0 0.7374029564150473" rpy="0 0 0"/>
            <mass value="1" />
            <inertia ixx="100" ixy="0" ixz="0" iyy="100" iyz="0" izz="100" />
        </inertial>
        <visual>
            <origin xyz="0 0 0.7374029564150473" rpy="0 0 0"/>
            <geometry>
                <box size="2.338909023842113 2.639073709726918 1.4748059128300945" />
            </geometry>
            <material name="Blue">
                <color rgba="0 1.0 1.0 1.0"/>
            </material>
        </visual>
        <collision>
            <origin xyz="0 0 0.7374029564150473" rpy="0 0 0"/>
            <geometry>
                <box size="2.338909023842113 2.639073709726918 1.4748059128300945" />
            </geometry>
        </collision>
    </link>
    <link name="Leg4">
        <inertial>
            <origin xyz="1.0819497665239455 0 0" rpy="0 0 0"/>
            <mass value="1" />
            <inertia ixx="100" ixy="0" ixz="0" iyy="100" iyz="0" izz="100" />
        </inertial>
        <visual>
            <origin xyz="1.0819497665239455 0 0" rpy="0 0 0"/>
            <geometry>
                <box size="2.163899533047891 2.0178662281196296 2.6312317299163417" />
            </geometry>
            <material name="Blue">
                <color rgba="0 1.0 1.0 1.0"/>
            </material>
        </visual>
        <collision>
            <origin xyz="1.0819497665239455 0 0" rpy="0 0 0"/>
            <geometry>
                <box size="2.163899533047891 2.0178662281196296 2.6312317299163417" />
            </geometry>
        </collision>
    </link>
    <link name="Leg5">
        <inertial>
            <origin xyz="0.8323915840961097 0 0" rpy="0 0 0"/>
            <mass value="1" />
            <inertia ixx="100" ixy="0" ixz="0" iyy="100" iyz="0" izz="100" />
        </inertial>
        <visual>
            <origin xyz="0.8323915840961097 0 0" rpy="0 0 0"/>
            <geometry>
                <box size="1.6647831681922194 2.8906321175154224 2.049571567626569" />
            </geometry>
            <material name="Blue">
                <color rgba="0 1.0 1.0 1.0"/>
            </material>
        </visual>
        <collision>
            <origin xyz="0.8323915840961097 0 0" rpy="0 0 0"/>
            <geometry>
                <box size="1.6647831681922194 2.8906321175154224 2.049571567626569" />
            </geometry>
        </collision>
    </link>
    <link name="Leg6">
        <inertial>
            <origin xyz="1.2309304580307807 0 0" rpy="0 0 0"/>
            <mass value="1" />
            <inertia ixx="100" ixy="0" ixz="0" iyy="100" iyz="0" izz="100" />
        </inertial>
        <visual>
            <origin xyz="1.2309304580307807 0 0" rpy="0 0 0"/>
            <geometry>
                <box size="2.4618609160615614 1.4965039277752918 2.0478979846576584" />
            </geometry>
            <material name="Blue">
                <color rgba="0 1.0 1.0 1.0"/>
            </material>
        </visual>
        <collision>
            <origin xyz="1.2309304580307807 0 0" rpy="0 0 0"/>
            <geometry>
                <box size="2.4618609160615614 1.4965039277752918 2.0478979846576584" />
            </geometry>
        </collision>
    </link>
    <link name="Leg7">
        <inertial>
            <origin xyz="0 0.6116720829165659 0" rpy="0 0 0"/>
            <mass value="1" />
            <inertia ixx="100" ixy="0" ixz="0" iyy="100" iyz="0" izz="100" />
        </inertial>
        <visual>
            <origin xyz="0 0.6116720829165659 0" rpy="0 0 0"/>
            <geometry>
                <box size="1.39158705697327 1.2233441658331319 2.3322238006056875" />
            </geometry>
            <material name="Blue">
                <color rgba="0 1.0 1.0 1.0"/>
            </material>
        </visual>
        <collision>
            <origin xyz="0 0.6116720829165659 0" rpy="0 0 0"/>
            <geometry>
                <box size="1.39158705697327 1.2233441658331319 2.3322238006056875" />
            </geometry>
        </collision>
    </link>
    <link name="Leg8">
        <inertial>
            <origin xyz="0.9130592778272624 0 0" rpy="0 0 0"/>
            <mass value="1" />
            <inertia ixx="100" ixy="0" ixz="0" iyy="100" iyz="0" izz="100" />
        </inertial>
        <visual>
            <origin xyz="0.9130592778272624 0 0" rpy="0 0 0"/>
            <geometry>
                <box size="1.8261185556545247 1.300844928048683 1.3659768366936107" />
            </geometry>
            <material name="Blue">
                <color rgba="0 1.0 1.0 1.0"/>
            </material>
        </visual>
        <collision>
            <origin xyz="0.9130592778272624 0 0" rpy="0 0 0"/>
            <geometry>
                <box size="1.8261185556545247 1.300844928048683 1.3659768366936107" />
            </geometry>
        </collision>
    </link>
    <link name="Leg9">
        <inertial>
            <origin xyz="0 1.4686505497005693 0" rpy="0 0 0"/>
            <mass value="1" />
            <inertia ixx="100" ixy="0" ixz="0" iyy="100" iyz="0" izz="100" />
        </inertial>
        <visual>
            <origin xyz="0 1.4686505497005693 0" rpy="0 0 0"/>
            <geometry>
                <box size="1.3394384442052896 2.9373010994011386 1.34607464860825" />
            </geometry>
            <material name="Blue">
                <color rgba="0 1.0 1.0 1.0"/>
            </material>
        </visual>
        <collision>
            <origin xyz="0 1.4686505497005693 0" rpy="0 0 0"/>
            <geometry>
                <box size="1.3394384442052896 2.9373010994011386 1.34607464860825" />
            </geometry>
        </collision>
    </link>
    <link name="Leg10">
        <inertial>
            <origin xyz="0 1.450588838503879 0" rpy="0 0 0"/>
            <mass value="1" />
            <inertia ixx="100" ixy="0" ixz="0" iyy="100" iyz="0" izz="100" />
        </inertial>
        <visual>
            <origin xyz="0 1.450588838503879 0" rpy="0 0 0"/>
            <geometry>
                <box size="1.239062276256647 2.901177677007758 2.7079744213809054" />
            </geometry>
            <material name="Blue">
                <color rgba="0 1.0 1.0 1.0"/>
            </material>
        </visual>
        <collision>
            <origin xyz="0 1.450588838503879 0" rpy="0 0 0"/>
            <geometry>
                <box size="1.239062276256647 2.901177677007758 2.7079744213809054" />
            </geometry>
        </collision>
    </link>
    <link name="Leg11">
        <inertial>
            <origin xyz="0 1.0320314448414623 0" rpy="0 0 0"/>
            <mass value="1" />
            <inertia ixx="100" ixy="0" ixz="0" iyy="100" iyz="0" izz="100" />
        </inertial>
        <visual>
            <origin xyz="0 1.0320314448414623 0" rpy="0 0 0"/>
            <geometry>
                <box size="1.587102493800181 2.0640628896829245 1.72880079852801" />
            </geometry>
            <material name="Green">
                <color rgba="0 180.0 0.0 1.0"/>
            </material>
        </visual>
        <collision>
            <origin xyz="0 1.0320314448414623 0" rpy="0 0 0"/>
            <geometry>
                <box size="1.587102493800181 2.0640628896829245 1.72880079852801" />
            </geometry>
        </collision>
    </link>
    <link name="Leg12">
        <inertial>
            <origin xyz="0 0 1.4551185943943938" rpy="0 0 0"/>
            <mass value="1" />
            <inertia ixx="100" ixy="0" ixz="0" iyy="100" iyz="0" izz="100" />
        </inertial>
        <visual>
            <origin xyz="0 0 1.4551185943943938" rpy="0 0 0"/>
            <geometry>
                <box size="1.5366824733207889 1.5450453126193877 2.9102371887887877" />
            </geometry>
            <material name="Blue">
                <color rgba="0 1.0 1.0 1.0"/>
            </material>
        </visual>
        <collision>
            <origin xyz="0 0 1.4551185943943938" rpy="0 0 0"/>
            <geometry>
                <box size="1.5366824733207889 1.5450453126193877 2.9102371887887877" />
            </geometry>
        </collision>
    </link>
    <link name="Leg13">
        <inertial>
            <origin xyz="0 1.386480800952555 0" rpy="0 0 0"/>
            <mass value="1" />
            <inertia ixx="100" ixy="0" ixz="0" iyy="100" iyz="0" izz="100" />
        </inertial>
        <visual>
            <origin xyz="0 1.386480800952555 0" rpy="0 0 0"/>
            <geometry>
                <box size="2.8537303411539003 2.77296160190511 2.176049271411328" />
            </geometry>
            <material name="Blue">
                <color rgba="0 1.0 1.0 1.0"/>
            </material>
        </visual>
        <collision>
            <origin xyz="0 1.386480800952555 0" rpy="0 0 0"/>
            <geometry>
                <box size="2.8537303411539003 2.77296160190511 2.176049271411328" />
            </geometry>
        </collision>
    </link>
    <link name="Leg14">
        <inertial>
            <origin xyz="1.4835817039212937 0 0" rpy="0 0 0"/>
            <mass value="1" />
            <inertia ixx="100" ixy="0" ixz="0" iyy="100" iyz="0" izz="100" />
        </inertial>
        <visual>
            <origin xyz="1.4835817039212937 0 0" rpy="0 0 0"/>
            <geometry>
                <box size="2.9671634078425875 1.7761699576204473 1.658959785460137" />
            </geometry>
            <material name="Blue">
                <color rgba="0 1.0 1.0 1.0"/>
            </material>
        </visual>
        <collision>
            <origin xyz="1.4835817039212937 0 0" rpy="0 0 0"/>
            <geometry>
                <box size="2.9671634078425875 1.7761699576204473 1.658959785460137" />
            </geometry>
        </collision>
    </link>
    <link name="Leg15">
        <inertial>
            <origin xyz="0 0.9567177842692385 0" rpy="0 0 0"/>
            <mass value="1" />
            <inertia ixx="100" ixy="0" ixz="0" iyy="100" iyz="0" izz="100" />
        </inertial>
        <visual>
            <origin xyz="0 0.9567177842692385 0" rpy="0 0 0"/>
            <geometry>
                <box size="1.074389986929767 1.913435568538477 2.1775524550898715" />
            </geometry>
            <material name="Green">
                <color rgba="0 180.0 0.0 1.0"/>
            </material>
        </visual>
        <collision>
            <origin xyz="0 0.9567177842692385 0" rpy="0 0 0"/>
            <geometry>
                <box size="1.074389986929767 1.913435568538477 2.1775524550898715" />
            </geometry>
        </collision>
    </link>
    <link name="Leg16">
        <inertial>
            <origin xyz="0 0 0.6592801862433234" rpy="0 0 0"/>
            <mass value="1" />
            <inertia ixx="100" ixy="0" ixz="0" iyy="100" iyz="0" izz="100" />
        </inertial>
        <visual>
            <origin xyz="0 0 0.6592801862433234" rpy="0 0 0"/>
            <geometry>
                <box size="1.4760068676086124 2.9385456064846016 1.3185603724866468" />
            </geometry>
            <material name="Green">
                <color rgba="0 180.0 0.0 1.0"/>
            </material>
        </visual>
        <collision>
            <origin xyz="0 0 0.6592801862433234" rpy="0 0 0"/>
            <geometry>
                <box size="1.4760068676086124 2.9385456064846016 1.3185603724866468" />
            </geometry>
        </collision>
    </link>
    <link name="Leg17">
        <inertial>
            <origin xyz="0 0 1.1517081302698773" rpy="0 0 0"/>
            <mass value="1" />
            <inertia ixx="100" ixy="0" ixz="0" iyy="100" iyz="0" izz="100" />
        </inertial>
        <visual>
            <origin xyz="0 0 1.1517081302698773" rpy="0 0 0"/>
            <geometry>
                <box size="1.138769953824161 1.9830023577204814 2.3034162605397546" />
            </geometry>
            <material name="Blue">
                <color rgba="0 1.0 1.0 1.0"/>
            </material>
        </visual>
        <collision>
            <origin xyz="0 0 1.1517081302698773" rpy="0 0 0"/>
            <geometry>
                <box size="1.138769953824161 1.9830023577204814 2.3034162605397546" />
            </geometry>
        </collision>
    </link>
    <link name="Leg18">
        <inertial>
            <origin xyz="0 0.9434277207029388 0" rpy="0 0 0"/>
            <mass value="1" />
            <inertia ixx="100" ixy="0" ixz="0" iyy="100" iyz="0" izz="100" />
        </inertial>
        <visual>
            <origin xyz="0 0.9434277207029388 0" rpy="0 0 0"/>
            <geometry>
                <box size="2.3618192884941527 1.8868554414058776 1.6202198872365738" />
            </geometry>
            <material name="Blue">
                <color rgba="0 1.0 1.0 1.0"/>
            </material>
        </visual>
        <collision>
            <origin xyz="0 0.9434277207029388 0" rpy="0 0 0"/>
            <geometry>
                <box size="2.3618192884941527 1.8868554414058776 1.6202198872365738" />
            </geometry>
        </collision>
    </link>
    <link name="Leg19">
        <inertial>
            <origin xyz="0 0.6972160806948909 0" rpy="0 0 0"/>
            <mass value="1" />
            <inertia ixx="100" ixy="0" ixz="0" iyy="100" iyz="0" izz="100" />
        </inertial>
        <visual>
            <origin xyz="0 0.6972160806948909 0" rpy="0 0 0"/>
            <geometry>
                <box size="2.869566788569875 1.3944321613897819 2.337742229596001" />
            </geometry>
            <material name="Blue">
                <color rgba="0 1.0 1.0 1.0"/>
            </material>
        </visual>
        <collision>
            <origin xyz="0 0.6972160806948909 0" rpy="0 0 0"/>
            <geometry>
                <box size="2.869566788569875 1.3944321613897819 2.337742229596001" />
            </geometry>
        </collision>
    </link>
    <link name="Leg20">
        <inertial>
            <origin xyz="0 0 0.7483540562923588" rpy="0 0 0"/>
            <mass value="1" />
            <inertia ixx="100" ixy="0" ixz="0" iyy="100" iyz="0" izz="100" />
        </inertial>
        <visual>
            <origin xyz="0 0 0.7483540562923588" rpy="0 0 0"/>
            <geometry>
                <box size="1.8976844274332267 2.4375633175984546 1.4967081125847177" />
            </geometry>
            <material name="Blue">
                <color rgba="0 1.0 1.0 1.0"/>
            </material>
        </visual>
        <collision>
            <origin xyz="0 0 0.7483540562923588" rpy="0 0 0"/>
            <geometry>
                <box size="1.8976844274332267 2.4375633175984546 1.4967081125847177" />
            </geometry>
        </collision>
    </link>
    <link name="Leg21">
        <inertial>
            <origin xyz="0 0 0.8293740701268336" rpy="0 0 0"/>
            <mass value="1" />
            <inertia ixx="100" ixy="0" ixz="0" iyy="100" iyz="0" izz="100" />
        </inertial>
        <visual>
            <origin xyz="0 0 0.8293740701268336" rpy="0 0 0"/>
            <geometry>
                <box size="1.3752340937781449 2.144574317099008 1.6587481402536672" />
            </geometry>
            <material name="Green">
                <color rgba="0 180.0 0.0 1.0"/>
            </material>
        </visual>
        <collision>
            <origin xyz="0 0 0.8293740701268336" rpy="0 0 0"/>
            <geometry>
                <box size="1.3752340937781449 2.144574317099008 1.6587481402536672" />
            </geometry>
        </collision>
    </link>
    <link name="Leg22">
        <inertial>
            <origin xyz="1.1616425539931459 0 0" rpy="0 0 0"/>
            <mass value="1" />
            <inertia ixx="100" ixy="0" ixz="0" iyy="100" iyz="0" izz="100" />
        </inertial>
        <visual>
            <origin xyz="1.1616425539931459 0 0" rpy="0 0 0"/>
            <geometry>
                <box size="2.3232851079862917 2.877922247442727 2.272723366897468" />
            </geometry>
            <material name="Blue">
                <color rgba="0 1.0 1.0 1.0"/>
            </material>
        </visual>
        <collision>
            <origin xyz="1.1616425539931459 0 0" rpy="0 0 0"/>
            <geometry>
                <box size="2.3232851079862917 2.877922247442727 2.272723366897468" />
            </geometry>
        </collision>
    </link>
    <link name="Leg23">
        <inertial>
            <origin xyz="0 0 0.8699666222965579" rpy="0 0 0"/>
            <mass value="1" />
            <inertia ixx="100" ixy="0" ixz="0" iyy="100" iyz="0" izz="100" />
        </inertial>
        <visual>
            <origin xyz="0 0 0.8699666222965579" rpy="0 0 0"/>
            <geometry>
                <box size="1.232058339377198 2.187890362723664 1.7399332445931157" />
            </geometry>
            <material name="Blue">
                <color rgba="0 1.0 1.0 1.0"/>
            </material>
        </visual>
        <collision>
            <origin xyz="0 0 0.8699666222965579" rpy="0 0 0"/>
            <geometry>
                <box size="1.232058339377198 2.187890362723664 1.7399332445931157" />
            </geometry>
        </collision>
    </link>
    <link name="Leg24">
        <inertial>
            <origin xyz="0 0.6766314506055037 0" rpy="0 0 0"/>
            <mass value="1" />
            <inertia ixx="100" ixy="0" ixz="0" iyy="100" iyz="0" izz="100" />
        </inertial>
        <visual>
            <origin xyz="0 0.6766314506055037 0" rpy="0 0 0"/>
            <geometry>
                <box size="2.563643145091782 1.3532629012110073 2.195085451907786" />
            </geometry>
            <material name="Green">
                <color rgba="0 180.0 0.0 1.0"/>
            </material>
        </visual>
        <collision>
            <origin xyz="0 0.6766314506055037 0" rpy="0 0 0"/>
            <geometry>
                <box size="2.563643145091782 1.3532629012110073 2.195085451907786" />
            </geometry>
        </collision>
    </link>
    <link name="Leg25">
        <inertial>
            <origin xyz="0.5550418551965596 0 0" rpy="0 0 0"/>
            <mass value="1" />
            <inertia ixx="100" ixy="0" ixz="0" iyy="100" iyz="0" izz="100" />
        </inertial>
        <visual>
            <origin xyz="0.5550418551965596 0 0" rpy="0 0 0"/>
            <geometry>
                <box size="1.1100837103931191 2.562788561294702 2.4172383252953358" />
            </geometry>
            <material name="Blue">
                <color rgba="0 1.0 1.0 1.0"/>
            </material>
        </visual>
        <collision>
            <origin xyz="0.5550418551965596 0 0" rpy="0 0 0"/>
            <geometry>
                <box size="1.1100837103931191 2.562788561294702 2.4172383252953358" />
            </geometry>
        </collision>
    </link>
    <link name="Leg26">
        <inertial>
            <origin xyz="0.8185677880904122 0 0" rpy="0 0 0"/>
            <mass value="1" />
            <inertia ixx="100" ixy="0" ixz="0" iyy="100" iyz="0" izz="100" />
        </inertial>
        <visual>
            <origin xyz="0.8185677880904122 0 0" rpy="0 0 0"/>
            <geometry>
                <box size="1.6371355761808244 2.5990400636859095 2.9936161233597804" />
            </geometry>
            <material name="Green">
                <color rgba="0 180.0 0.0 1.0"/>
            </material>
        </visual>
        <collision>
            <origin xyz="0.8185677880904122 0 0" rpy="0 0 0"/>
            <geometry>
                <box size="1.6371355761808244 2.5990400636859095 2.9936161233597804" />
            </geometry>
        </collision>
    </link>
    <joint name="Torso_Leg1" type="revolute">
       <parent link="Torso"/>
       <child  link="Leg1"/>
       <origin rpy="0 0 0" xyz="0 1.1686146811502862 0.7135287731432332" />
     <axis xyz="1 0 0"/>
       <limit effort="0.0" lower="-3.14159" upper="3.14159" velocity="0.0"/>
    </joint>
    <joint name="Torso_Leg2" type="revolute">
       <parent link="Torso"/>
       <child  link="Leg2"/>
       <origin rpy="0 0 0" xyz="0.8140613095827344 0.5149594145567076 0" />
     <axis xyz="1 0 0"/>
       <limit effort="0.0" lower="-3.14159" upper="3.14159" velocity="0.0"/>
    </joint>
    <joint name="Leg1_Leg3" type="revolute">
       <parent link="Leg1"/>
       <child  link="Leg3"/>
       <origin rpy="0 0 0" xyz="1.3815324476360367 0 0.7658731319642653" />
     <axis xyz="1 0 0"/>
       <limit effort="0.0" lower="-3.14159" upper="3.14159" velocity="0.0"/>
    </joint>
    <joint name="Leg1_Leg4" type="revolute">
       <parent link="Leg1"/>
       <child  link="Leg4"/>
       <origin rpy="0 0 0" xyz="2.7630648952720733 0 0.7658731319642653" />
     <axis xyz="1 0 0"/>
       <limit effort="0.0" lower="-3.14159" upper="3.14159" velocity="0.0"/>
    </joint>
    <joint name="Leg3_Leg5" type="revolute">
       <parent link="Leg3"/>
       <child  link="Leg5"/>
       <origin rpy="0 0 0" xyz="2.163899533047891 0 0" />
     <axis xyz="1 0 0"/>
       <limit effort="0.0" lower="-3.14159" upper="3.14159" velocity="0.0"/>
    </joint>
    <joint name="Leg2_Leg6" type="revolute">
       <parent link="Leg2"/>
       <child  link="Leg6"/>
       <origin rpy="0 0 0" xyz="1.1694545119210564 0 0.7374029564150473" />
     <axis xyz="1 0 0"/>
       <limit effort="0.0" lower="-3.14159" upper="3.14159" velocity="0.0"/>
    </joint>
    <joint name="Leg3_Leg7" type="revolute">
       <parent link="Leg3"/>
       <child  link="Leg7"/>
       <origin rpy="0 0 0" xyz="2.163899533047891 1.0089331140598148 0" />
     <axis xyz="1 0 0"/>
       <limit effort="0.0" lower="-3.14159" upper="3.14159" velocity="0.0"/>
    </joint>
    <joint name="Leg6_Leg8" type="revolute">
       <parent link="Leg6"/>
       <child  link="Leg8"/>
       <origin rpy="0 0 0" xyz="0.695793528486635 0.6116720829165659 0" />
     <axis xyz="1 0 0"/>
       <limit effort="0.0" lower="-3.14159" upper="3.14159" velocity="0.0"/>
    </joint>
    <joint name="Leg1_Leg9" type="revolute">
       <parent link="Leg1"/>
       <child  link="Leg9"/>
       <origin rpy="0 0 0" xyz="2.7630648952720733 1.2760444308259884 0.7658731319642653" />
     <axis xyz="1 0 0"/>
       <limit effort="0.0" lower="-3.14159" upper="3.14159" velocity="0.0"/>
    </joint>
    <joint name="Leg4_Leg10" type="revolute">
       <parent link="Leg4"/>
       <child  link="Leg10"/>
       <origin rpy="0 0 0" xyz="0.8323915840961097 1.4453160587577112 0" />
     <axis xyz="1 0 0"/>
       <limit effort="0.0" lower="-3.14159" upper="3.14159" velocity="0.0"/>
    </joint>
    <joint name="Leg7_Leg11" type="revolute">
       <parent link="Leg7"/>
       <child  link="Leg11"/>
       <origin rpy="0 0 0" xyz="0.9130592778272624 0.6504224640243415 0" />
     <axis xyz="1 0 0"/>
       <limit effort="0.0" lower="-3.14159" upper="3.14159" velocity="0.0"/>
    </joint>
    <joint name="Leg2_Leg12" type="revolute">
       <parent link="Leg2"/>
       <child  link="Leg12"/>
       <origin rpy="0 0 0" xyz="1.1694545119210564 0 1.4748059128300945" />
     <axis xyz="1 0 0"/>
       <limit effort="0.0" lower="-3.14159" upper="3.14159" velocity="0.0"/>
    </joint>
    <joint name="Leg10_Leg13" type="revolute">
       <parent link="Leg10"/>
       <child  link="Leg13"/>
       <origin rpy="0 0 0" xyz="0 2.0640628896829245 0" />
     <axis xyz="1 0 0"/>
       <limit effort="0.0" lower="-3.14159" upper="3.14159" velocity="0.0"/>
    </joint>
    <joint name="Leg9_Leg14" type="revolute">
       <parent link="Leg9"/>
       <child  link="Leg14"/>
       <origin rpy="0 0 0" xyz="0.6195311381283235 1.450588838503879 0" />
     <axis xyz="1 0 0"/>
       <limit effort="0.0" lower="-3.14159" upper="3.14159" velocity="0.0"/>
    </joint>
    <joint name="Leg9_Leg15" type="revolute">
       <parent link="Leg9"/>
       <child  link="Leg15"/>
       <origin rpy="0 0 0" xyz="0.6195311381283235 2.901177677007758 0" />
     <axis xyz="1 0 0"/>
       <limit effort="0.0" lower="-3.14159" upper="3.14159" velocity="0.0"/>
    </joint>
    <joint name="Leg7_Leg16" type="revolute">
       <parent link="Leg7"/>
       <child  link="Leg16"/>
       <origin rpy="0 0 0" xyz="0.9130592778272624 0.6504224640243415 0.6829884183468053" />
     <axis xyz="1 0 0"/>
       <limit effort="0.0" lower="-3.14159" upper="3.14159" velocity="0.0"/>
    </joint>
    <joint name="Leg9_Leg17" type="revolute">
       <parent link="Leg9"/>
       <child  link="Leg17"/>
       <origin rpy="0 0 0" xyz="0.6195311381283235 2.901177677007758 1.3539872106904527" />
     <axis xyz="1 0 0"/>
       <limit effort="0.0" lower="-3.14159" upper="3.14159" velocity="0.0"/>
    </joint>
    <joint name="Leg12_Leg18" type="revolute">
       <parent link="Leg12"/>
       <child  link="Leg18"/>
       <origin rpy="0 0 0" xyz="0 2.77296160190511 0" />
     <axis xyz="1 0 0"/>
       <limit effort="0.0" lower="-3.14159" upper="3.14159" velocity="0.0"/>
    </joint>
    <joint name="Leg14_Leg19" type="revolute">
       <parent link="Leg14"/>
       <child  link="Leg19"/>
       <origin rpy="0 0 0" xyz="0 1.913435568538477 0" />
     <axis xyz="1 0 0"/>
       <limit effort="0.0" lower="-3.14159" upper="3.14159" velocity="0.0"/>
    </joint>
    <joint name="Leg3_Leg20" type="revolute">
       <parent link="Leg3"/>
       <child  link="Leg20"/>
       <origin rpy="0 0 0" xyz="2.163899533047891 1.0089331140598148 1.3156158649581708" />
     <axis xyz="1 0 0"/>
       <limit effort="0.0" lower="-3.14159" upper="3.14159" velocity="0.0"/>
    </joint>
    <joint name="Leg20_Leg21" type="revolute">
       <parent link="Leg20"/>
       <child  link="Leg21"/>
       <origin rpy="0 0 0" xyz="0 0 1.6587481402536672" />
     <axis xyz="1 0 0"/>
       <limit effort="0.0" lower="-3.14159" upper="3.14159" velocity="0.0"/>
    </joint>
    <joint name="Leg19_Leg22" type="revolute">
       <parent link="Leg19"/>
       <child  link="Leg22"/>
       <origin rpy="0 0 0" xyz="0.9488422137166134 0 0.7483540562923588" />
     <axis xyz="1 0 0"/>
       <limit effort="0.0" lower="-3.14159" upper="3.14159" velocity="0.0"/>
    </joint>
    <joint name="Leg18_Leg23" type="revolute">
       <parent link="Leg18"/>
       <child  link="Leg23"/>
       <origin rpy="0 0 0" xyz="0 0.6972160806948909 1.1688711147980004" />
     <axis xyz="1 0 0"/>
       <limit effort="0.0" lower="-3.14159" upper="3.14159" velocity="0.0"/>
    </joint>
    <joint name="Leg20_Leg24" type="revolute">
       <parent link="Leg20"/>
       <child  link="Leg24"/>
       <origin rpy="0 0 0" xyz="0 1.072287158549504 1.6587481402536672" />
     <axis xyz="1 0 0"/>
       <limit effort="0.0" lower="-3.14159" upper="3.14159" velocity="0.0"/>
    </joint>
    <joint name="Leg13_Leg25" type="revolute">
       <parent link="Leg13"/>
       <child  link="Leg25"/>
       <origin rpy="0 0 0" xyz="2.9671634078425875 0 0" />
     <axis xyz="1 0 0"/>
       <limit effort="0.0" lower="-3.14159" upper="3.14159" velocity="0.0"/>
    </joint>
    <joint name="Leg8_Leg26" type="revolute">
       <parent link="Leg8"/>
       <child  link="Leg26"/>
       <origin rpy="0 0 0" xyz="0.6697192221026448 1.4686505497005693 0" />
     <axis xyz="1 0 0"/>
       <limit effort="0.0" lower="-3.14159" upper="3.14159" velocity="0.0"/>
    </joint>
</robot>