<robot name = "robot">
    <link name="Torso">
        <inertial>
            <origin xyz="0 0 0.6188606425860481" rpy="0 0 0"/>
            <mass value="1" />
            <inertia ixx="100" ixy="0" ixz="0" iyy="100" iyz="0" izz="100" />
        </inertial>
        <visual>
            <origin xyz="0 0 0.6188606425860481" rpy="0 0 0"/>
            <geometry>
                <box size="1.1282652205230463 2.374792754627035 1.2377212851720962" />
            </geometry>
            <material name="Green">
                <color rgba="0 180.0 0.0 1.0"/>
            </material>
        </visual>
        <collision>
            <origin xyz="0 0 0.6188606425860481" rpy="0 0 0"/>
            <geometry>
                <box size="1.1282652205230463 2.374792754627035 1.2377212851720962" />
            </geometry>
        </collision>
    </link>
    <link name="Leg1">
        <inertial>
            <origin xyz="1.0759042799881615 0 0" rpy="0 0 0"/>
            <mass value="1" />
            <inertia ixx="100" ixy="0" ixz="0" iyy="100" iyz="0" izz="100" />
        </inertial>
        <visual>
            <origin xyz="1.0759042799881615 0 0" rpy="0 0 0"/>
            <geometry>
                <box size="2.151808559976323 1.9191231838271774 2.3299169964946014" />
            </geometry>
            <material name="Green">
                <color rgba="0 180.0 0.0 1.0"/>
            </material>
        </visual>
        <collision>
            <origin xyz="1.0759042799881615 0 0" rpy="0 0 0"/>
            <geometry>
                <box size="2.151808559976323 1.9191231838271774 2.3299169964946014" />
            </geometry>
        </collision>
    </link>
    <link name="Leg2">
        <inertial>
            <origin xyz="0 1.1292520987362957 0" rpy="0 0 0"/>
            <mass value="1" />
            <inertia ixx="100" ixy="0" ixz="0" iyy="100" iyz="0" izz="100" />
        </inertial>
        <visual>
            <origin xyz="0 1.1292520987362957 0" rpy="0 0 0"/>
            <geometry>
                <box size="1.4740688344763495 2.2585041974725915 2.0241421547146783" />
            </geometry>
            <material name="Green">
                <color rgba="0 180.0 0.0 1.0"/>
            </material>
        </visual>
        <collision>
            <origin xyz="0 1.1292520987362957 0" rpy="0 0 0"/>
            <geometry>
                <box size="1.4740688344763495 2.2585041974725915 2.0241421547146783" />
            </geometry>
        </collision>
    </link>
    <link name="Leg3">
        <inertial>
            <origin xyz="0 1.3281247255723074 0" rpy="0 0 0"/>
            <mass value="1" />
            <inertia ixx="100" ixy="0" ixz="0" iyy="100" iyz="0" izz="100" />
        </inertial>
        <visual>
            <origin xyz="0 1.3281247255723074 0" rpy="0 0 0"/>
            <geometry>
                <box size="1.6651850825084338 2.656249451144615 1.356061685688199" />
            </geometry>
            <material name="Green">
                <color rgba="0 180.0 0.0 1.0"/>
            </material>
        </visual>
        <collision>
            <origin xyz="0 1.3281247255723074 0" rpy="0 0 0"/>
            <geometry>
                <box size="1.6651850825084338 2.656249451144615 1.356061685688199" />
            </geometry>
        </collision>
    </link>
    <link name="Leg4">
        <inertial>
            <origin xyz="0.7043924540953056 0 0" rpy="0 0 0"/>
            <mass value="1" />
            <inertia ixx="100" ixy="0" ixz="0" iyy="100" iyz="0" izz="100" />
        </inertial>
        <visual>
            <origin xyz="0.7043924540953056 0 0" rpy="0 0 0"/>
            <geometry>
                <box size="1.4087849081906112 2.61350813739927 1.7026584112312013" />
            </geometry>
            <material name="Green">
                <color rgba="0 180.0 0.0 1.0"/>
            </material>
        </visual>
        <collision>
            <origin xyz="0.7043924540953056 0 0" rpy="0 0 0"/>
            <geometry>
                <box size="1.4087849081906112 2.61350813739927 1.7026584112312013" />
            </geometry>
        </collision>
    </link>
    <link name="Leg5">
        <inertial>
            <origin xyz="0 0 1.1021512256021844" rpy="0 0 0"/>
            <mass value="1" />
            <inertia ixx="100" ixy="0" ixz="0" iyy="100" iyz="0" izz="100" />
        </inertial>
        <visual>
            <origin xyz="0 0 1.1021512256021844" rpy="0 0 0"/>
            <geometry>
                <box size="1.2984040069205198 1.9801251692175343 2.2043024512043687" />
            </geometry>
            <material name="Blue">
                <color rgba="0 1.0 1.0 1.0"/>
            </material>
        </visual>
        <collision>
            <origin xyz="0 0 1.1021512256021844" rpy="0 0 0"/>
            <geometry>
                <box size="1.2984040069205198 1.9801251692175343 2.2043024512043687" />
            </geometry>
        </collision>
    </link>
    <link name="Leg6">
        <inertial>
            <origin xyz="1.3866948094229623 0 0" rpy="0 0 0"/>
            <mass value="1" />
            <inertia ixx="100" ixy="0" ixz="0" iyy="100" iyz="0" izz="100" />
        </inertial>
        <visual>
            <origin xyz="1.3866948094229623 0 0" rpy="0 0 0"/>
            <geometry>
                <box size="2.7733896188459246 1.203053467689666 1.7282742264439075" />
            </geometry>
            <material name="Green">
                <color rgba="0 180.0 0.0 1.0"/>
            </material>
        </visual>
        <collision>
            <origin xyz="1.3866948094229623 0 0" rpy="0 0 0"/>
            <geometry>
                <box size="2.7733896188459246 1.203053467689666 1.7282742264439075" />
            </geometry>
        </collision>
    </link>
    <link name="Leg7">
        <inertial>
            <origin xyz="0 1.2950644514178782 0" rpy="0 0 0"/>
            <mass value="1" />
            <inertia ixx="100" ixy="0" ixz="0" iyy="100" iyz="0" izz="100" />
        </inertial>
        <visual>
            <origin xyz="0 1.2950644514178782 0" rpy="0 0 0"/>
            <geometry>
                <box size="2.8134578371918173 2.5901289028357564 1.654725122686048" />
            </geometry>
            <material name="Blue">
                <color rgba="0 1.0 1.0 1.0"/>
            </material>
        </visual>
        <collision>
            <origin xyz="0 1.2950644514178782 0" rpy="0 0 0"/>
            <geometry>
                <box size="2.8134578371918173 2.5901289028357564 1.654725122686048" />
            </geometry>
        </collision>
    </link>
    <link name="Leg8">
        <inertial>
            <origin xyz="0.735724641938732 0 0" rpy="0 0 0"/>
            <mass value="1" />
            <inertia ixx="100" ixy="0" ixz="0" iyy="100" iyz="0" izz="100" />
        </inertial>
        <visual>
            <origin xyz="0.735724641938732 0 0" rpy="0 0 0"/>
            <geometry>
                <box size="1.471449283877464 1.350116509104955 1.3961912099914005" />
            </geometry>
            <material name="Blue">
                <color rgba="0 1.0 1.0 1.0"/>
            </material>
        </visual>
        <collision>
            <origin xyz="0.735724641938732 0 0" rpy="0 0 0"/>
            <geometry>
                <box size="1.471449283877464 1.350116509104955 1.3961912099914005" />
            </geometry>
        </collision>
    </link>
    <link name="Leg9">
        <inertial>
            <origin xyz="0 0 0.5977103295998973" rpy="0 0 0"/>
            <mass value="1" />
            <inertia ixx="100" ixy="0" ixz="0" iyy="100" iyz="0" izz="100" />
        </inertial>
        <visual>
            <origin xyz="0 0 0.5977103295998973" rpy="0 0 0"/>
            <geometry>
                <box size="2.8623594948088296 2.6978261056650332 1.1954206591997947" />
            </geometry>
            <material name="Blue">
                <color rgba="0 1.0 1.0 1.0"/>
            </material>
        </visual>
        <collision>
            <origin xyz="0 0 0.5977103295998973" rpy="0 0 0"/>
            <geometry>
                <box size="2.8623594948088296 2.6978261056650332 1.1954206591997947" />
            </geometry>
        </collision>
    </link>
    <link name="Leg10">
        <inertial>
            <origin xyz="0 0 0.8285505089017751" rpy="0 0 0"/>
            <mass value="1" />
            <inertia ixx="100" ixy="0" ixz="0" iyy="100" iyz="0" izz="100" />
        </inertial>
        <visual>
            <origin xyz="0 0 0.8285505089017751" rpy="0 0 0"/>
            <geometry>
                <box size="2.4232952588586163 1.7470302795336163 1.6571010178035501" />
            </geometry>
            <material name="Blue">
                <color rgba="0 1.0 1.0 1.0"/>
            </material>
        </visual>
        <collision>
            <origin xyz="0 0 0.8285505089017751" rpy="0 0 0"/>
            <geometry>
                <box size="2.4232952588586163 1.7470302795336163 1.6571010178035501" />
            </geometry>
        </collision>
    </link>
    <link name="Leg11">
        <inertial>
            <origin xyz="1.1778704747501327 0 0" rpy="0 0 0"/>
            <mass value="1" />
            <inertia ixx="100" ixy="0" ixz="0" iyy="100" iyz="0" izz="100" />
        </inertial>
        <visual>
            <origin xyz="1.1778704747501327 0 0" rpy="0 0 0"/>
            <geometry>
                <box size="2.3557409495002655 2.0579367230879875 2.8694798998100053" />
            </geometry>
            <material name="Blue">
                <color rgba="0 1.0 1.0 1.0"/>
            </material>
        </visual>
        <collision>
            <origin xyz="1.1778704747501327 0 0" rpy="0 0 0"/>
            <geometry>
                <box size="2.3557409495002655 2.0579367230879875 2.8694798998100053" />
            </geometry>
        </collision>
    </link>
    <link name="Leg12">
        <inertial>
            <origin xyz="0.8653941376226557 0 0" rpy="0 0 0"/>
            <mass value="1" />
            <inertia ixx="100" ixy="0" ixz="0" iyy="100" iyz="0" izz="100" />
        </inertial>
        <visual>
            <origin xyz="0.8653941376226557 0 0" rpy="0 0 0"/>
            <geometry>
                <box size="1.7307882752453114 2.8448559330650425 2.3539166679936616" />
            </geometry>
            <material name="Green">
                <color rgba="0 180.0 0.0 1.0"/>
            </material>
        </visual>
        <collision>
            <origin xyz="0.8653941376226557 0 0" rpy="0 0 0"/>
            <geometry>
                <box size="1.7307882752453114 2.8448559330650425 2.3539166679936616" />
            </geometry>
        </collision>
    </link>
    <link name="Leg13">
        <inertial>
            <origin xyz="0 0.5817194743729047 0" rpy="0 0 0"/>
            <mass value="1" />
            <inertia ixx="100" ixy="0" ixz="0" iyy="100" iyz="0" izz="100" />
        </inertial>
        <visual>
            <origin xyz="0 0.5817194743729047 0" rpy="0 0 0"/>
            <geometry>
                <box size="2.3713932676408964 1.1634389487458094 1.7983320568314964" />
            </geometry>
            <material name="Blue">
                <color rgba="0 1.0 1.0 1.0"/>
            </material>
        </visual>
        <collision>
            <origin xyz="0 0.5817194743729047 0" rpy="0 0 0"/>
            <geometry>
                <box size="2.3713932676408964 1.1634389487458094 1.7983320568314964" />
            </geometry>
        </collision>
    </link>
    <link name="Leg14">
        <inertial>
            <origin xyz="0.6472716922506374 0 0" rpy="0 0 0"/>
            <mass value="1" />
            <inertia ixx="100" ixy="0" ixz="0" iyy="100" iyz="0" izz="100" />
        </inertial>
        <visual>
            <origin xyz="0.6472716922506374 0 0" rpy="0 0 0"/>
            <geometry>
                <box size="1.2945433845012748 1.6511223174253005 2.6183527457633735" />
            </geometry>
            <material name="Blue">
                <color rgba="0 1.0 1.0 1.0"/>
            </material>
        </visual>
        <collision>
            <origin xyz="0.6472716922506374 0 0" rpy="0 0 0"/>
            <geometry>
                <box size="1.2945433845012748 1.6511223174253005 2.6183527457633735" />
            </geometry>
        </collision>
    </link>
    <link name="Leg15">
        <inertial>
            <origin xyz="0 0.5133586508378954 0" rpy="0 0 0"/>
            <mass value="1" />
            <inertia ixx="100" ixy="0" ixz="0" iyy="100" iyz="0" izz="100" />
        </inertial>
        <visual>
            <origin xyz="0 0.5133586508378954 0" rpy="0 0 0"/>
            <geometry>
                <box size="2.2104350459657276 1.026717301675791 2.5485349396248638" />
            </geometry>
            <material name="Blue">
                <color rgba="0 1.0 1.0 1.0"/>
            </material>
        </visual>
        <collision>
            <origin xyz="0 0.5133586508378954 0" rpy="0 0 0"/>
            <geometry>
                <box size="2.2104350459657276 1.026717301675791 2.5485349396248638" />
            </geometry>
        </collision>
    </link>
    <link name="Leg16">
        <inertial>
            <origin xyz="0 1.0477491378101582 0" rpy="0 0 0"/>
            <mass value="1" />
            <inertia ixx="100" ixy="0" ixz="0" iyy="100" iyz="0" izz="100" />
        </inertial>
        <visual>
            <origin xyz="0 1.0477491378101582 0" rpy="0 0 0"/>
            <geometry>
                <box size="2.841005996512604 2.0954982756203164 1.8101507994911246" />
            </geometry>
            <material name="Green">
                <color rgba="0 180.0 0.0 1.0"/>
            </material>
        </visual>
        <collision>
            <origin xyz="0 1.0477491378101582 0" rpy="0 0 0"/>
            <geometry>
                <box size="2.841005996512604 2.0954982756203164 1.8101507994911246" />
            </geometry>
        </collision>
    </link>
    <link name="Leg17">
        <inertial>
            <origin xyz="0 0 1.256338520307327" rpy="0 0 0"/>
            <mass value="1" />
            <inertia ixx="100" ixy="0" ixz="0" iyy="100" iyz="0" izz="100" />
        </inertial>
        <visual>
            <origin xyz="0 0 1.256338520307327" rpy="0 0 0"/>
            <geometry>
                <box size="1.971243953406047 1.7442410615860082 2.512677040614654" />
            </geometry>
            <material name="Green">
                <color rgba="0 180.0 0.0 1.0"/>
            </material>
        </visual>
        <collision>
            <origin xyz="0 0 1.256338520307327" rpy="0 0 0"/>
            <geometry>
                <box size="1.971243953406047 1.7442410615860082 2.512677040614654" />
            </geometry>
        </collision>
    </link>
    <link name="Leg18">
        <inertial>
            <origin xyz="1.1968887871551506 0 0" rpy="0 0 0"/>
            <mass value="1" />
            <inertia ixx="100" ixy="0" ixz="0" iyy="100" iyz="0" izz="100" />
        </inertial>
        <visual>
            <origin xyz="1.1968887871551506 0 0" rpy="0 0 0"/>
            <geometry>
                <box size="2.393777574310301 2.0560854931090526 1.091621832941818" />
            </geometry>
            <material name="Green">
                <color rgba="0 180.0 0.0 1.0"/>
            </material>
        </visual>
        <collision>
            <origin xyz="1.1968887871551506 0 0" rpy="0 0 0"/>
            <geometry>
                <box size="2.393777574310301 2.0560854931090526 1.091621832941818" />
            </geometry>
        </collision>
    </link>
    <link name="Leg19">
        <inertial>
            <origin xyz="0 0 0.7235370413258396" rpy="0 0 0"/>
            <mass value="1" />
            <inertia ixx="100" ixy="0" ixz="0" iyy="100" iyz="0" izz="100" />
        </inertial>
        <visual>
            <origin xyz="0 0 0.7235370413258396" rpy="0 0 0"/>
            <geometry>
                <box size="1.7661392919080248 1.1444420367245776 1.4470740826516792" />
            </geometry>
            <material name="Blue">
                <color rgba="0 1.0 1.0 1.0"/>
            </material>
        </visual>
        <collision>
            <origin xyz="0 0 0.7235370413258396" rpy="0 0 0"/>
            <geometry>
                <box size="1.7661392919080248 1.1444420367245776 1.4470740826516792" />
            </geometry>
        </collision>
    </link>
    <link name="Leg20">
        <inertial>
            <origin xyz="0 0 1.2843748974444447" rpy="0 0 0"/>
            <mass value="1" />
            <inertia ixx="100" ixy="0" ixz="0" iyy="100" iyz="0" izz="100" />
        </inertial>
        <visual>
            <origin xyz="0 0 1.2843748974444447" rpy="0 0 0"/>
            <geometry>
                <box size="2.083933768338708 1.5723060806037392 2.5687497948888893" />
            </geometry>
            <material name="Blue">
                <color rgba="0 1.0 1.0 1.0"/>
            </material>
        </visual>
        <collision>
            <origin xyz="0 0 1.2843748974444447" rpy="0 0 0"/>
            <geometry>
                <box size="2.083933768338708 1.5723060806037392 2.5687497948888893" />
            </geometry>
        </collision>
    </link>
    <link name="Leg21">
        <inertial>
            <origin xyz="0 0.9098603195171008 0" rpy="0 0 0"/>
            <mass value="1" />
            <inertia ixx="100" ixy="0" ixz="0" iyy="100" iyz="0" izz="100" />
        </inertial>
        <visual>
            <origin xyz="0 0.9098603195171008 0" rpy="0 0 0"/>
            <geometry>
                <box size="2.1350326264245183 1.8197206390342016 2.9006367218839717" />
            </geometry>
            <material name="Green">
                <color rgba="0 180.0 0.0 1.0"/>
            </material>
        </visual>
        <collision>
            <origin xyz="0 0.9098603195171008 0" rpy="0 0 0"/>
            <geometry>
                <box size="2.1350326264245183 1.8197206390342016 2.9006367218839717" />
            </geometry>
        </collision>
    </link>
    <link name="Leg22">
        <inertial>
            <origin xyz="1.3228785305757509 0 0" rpy="0 0 0"/>
            <mass value="1" />
            <inertia ixx="100" ixy="0" ixz="0" iyy="100" iyz="0" izz="100" />
        </inertial>
        <visual>
            <origin xyz="1.3228785305757509 0 0" rpy="0 0 0"/>
            <geometry>
                <box size="2.6457570611515018 1.5504268654439113 1.3932008479855071" />
            </geometry>
            <material name="Green">
                <color rgba="0 180.0 0.0 1.0"/>
            </material>
        </visual>
        <collision>
            <origin xyz="1.3228785305757509 0 0" rpy="0 0 0"/>
            <geometry>
                <box size="2.6457570611515018 1.5504268654439113 1.3932008479855071" />
            </geometry>
        </collision>
    </link>
    <link name="Leg23">
        <inertial>
            <origin xyz="0 0.7536727900314503 0" rpy="0 0 0"/>
            <mass value="1" />
            <inertia ixx="100" ixy="0" ixz="0" iyy="100" iyz="0" izz="100" />
        </inertial>
        <visual>
            <origin xyz="0 0.7536727900314503 0" rpy="0 0 0"/>
            <geometry>
                <box size="1.2310295726805704 1.5073455800629005 2.672505812165811" />
            </geometry>
            <material name="Green">
                <color rgba="0 180.0 0.0 1.0"/>
            </material>
        </visual>
        <collision>
            <origin xyz="0 0.7536727900314503 0" rpy="0 0 0"/>
            <geometry>
                <box size="1.2310295726805704 1.5073455800629005 2.672505812165811" />
            </geometry>
        </collision>
    </link>
    <link name="Leg24">
        <inertial>
            <origin xyz="0 0.8705549611596597 0" rpy="0 0 0"/>
            <mass value="1" />
            <inertia ixx="100" ixy="0" ixz="0" iyy="100" iyz="0" izz="100" />
        </inertial>
        <visual>
            <origin xyz="0 0.8705549611596597 0" rpy="0 0 0"/>
            <geometry>
                <box size="2.5711278113598204 1.7411099223193194 2.3056661369458515" />
            </geometry>
            <material name="Blue">
                <color rgba="0 1.0 1.0 1.0"/>
            </material>
        </visual>
        <collision>
            <origin xyz="0 0.8705549611596597 0" rpy="0 0 0"/>
            <geometry>
                <box size="2.5711278113598204 1.7411099223193194 2.3056661369458515" />
            </geometry>
        </collision>
    </link>
    <link name="Leg25">
        <inertial>
            <origin xyz="0 0.5823205488764306 0" rpy="0 0 0"/>
            <mass value="1" />
            <inertia ixx="100" ixy="0" ixz="0" iyy="100" iyz="0" izz="100" />
        </inertial>
        <visual>
            <origin xyz="0 0.5823205488764306 0" rpy="0 0 0"/>
            <geometry>
                <box size="2.952056817144878 1.1646410977528612 1.9619955767668524" />
            </geometry>
            <material name="Green">
                <color rgba="0 180.0 0.0 1.0"/>
            </material>
        </visual>
        <collision>
            <origin xyz="0 0.5823205488764306 0" rpy="0 0 0"/>
            <geometry>
                <box size="2.952056817144878 1.1646410977528612 1.9619955767668524" />
            </geometry>
        </collision>
    </link>
    <link name="Leg26">
        <inertial>
            <origin xyz="0 0 1.0318555811989323" rpy="0 0 0"/>
            <mass value="1" />
            <inertia ixx="100" ixy="0" ixz="0" iyy="100" iyz="0" izz="100" />
        </inertial>
        <visual>
            <origin xyz="0 0 1.0318555811989323" rpy="0 0 0"/>
            <geometry>
                <box size="2.0187925404163582 2.7385490048863534 2.0637111623978646" />
            </geometry>
            <material name="Green">
                <color rgba="0 180.0 0.0 1.0"/>
            </material>
        </visual>
        <collision>
            <origin xyz="0 0 1.0318555811989323" rpy="0 0 0"/>
            <geometry>
                <box size="2.0187925404163582 2.7385490048863534 2.0637111623978646" />
            </geometry>
        </collision>
    </link>
    <link name="Leg27">
        <inertial>
            <origin xyz="1.0835216345763543 0 0" rpy="0 0 0"/>
            <mass value="1" />
            <inertia ixx="100" ixy="0" ixz="0" iyy="100" iyz="0" izz="100" />
        </inertial>
        <visual>
            <origin xyz="1.0835216345763543 0 0" rpy="0 0 0"/>
            <geometry>
                <box size="2.1670432691527086 1.6755342887310143 2.4835118930489175" />
            </geometry>
            <material name="Green">
                <color rgba="0 180.0 0.0 1.0"/>
            </material>
        </visual>
        <collision>
            <origin xyz="1.0835216345763543 0 0" rpy="0 0 0"/>
            <geometry>
                <box size="2.1670432691527086 1.6755342887310143 2.4835118930489175" />
            </geometry>
        </collision>
    </link>
    <link name="Leg28">
        <inertial>
            <origin xyz="0 0 1.448624113724292" rpy="0 0 0"/>
            <mass value="1" />
            <inertia ixx="100" ixy="0" ixz="0" iyy="100" iyz="0" izz="100" />
        </inertial>
        <visual>
            <origin xyz="0 0 1.448624113724292" rpy="0 0 0"/>
            <geometry>
                <box size="2.1754979531489003 2.3259660412297283 2.897248227448584" />
            </geometry>
            <material name="Green">
                <color rgba="0 180.0 0.0 1.0"/>
            </material>
        </visual>
        <collision>
            <origin xyz="0 0 1.448624113724292" rpy="0 0 0"/>
            <geometry>
                <box size="2.1754979531489003 2.3259660412297283 2.897248227448584" />
            </geometry>
        </collision>
    </link>
    <joint name="Torso_Leg1" type="revolute">
       <parent link="Torso"/>
       <child  link="Leg1"/>
       <origin rpy="0 0 0" xyz="0.5641326102615232 0 0.6188606425860481" />
     <axis xyz="1 0 0"/>
       <limit effort="0.0" lower="-3.14159" upper="3.14159" velocity="0.0"/>
    </joint>
    <joint name="Torso_Leg2" type="revolute">
       <parent link="Torso"/>
       <child  link="Leg2"/>
       <origin rpy="0 0 0" xyz="1.0759042799881615 0.9595615919135887 0" />
     <axis xyz="1 0 0"/>
       <limit effort="0.0" lower="-3.14159" upper="3.14159" velocity="0.0"/>
    </joint>
    <joint name="Leg1_Leg3" type="revolute">
       <parent link="Leg1"/>
       <child  link="Leg3"/>
       <origin rpy="0 0 0" xyz="0 2.2585041974725915 0" />
     <axis xyz="1 0 0"/>
       <limit effort="0.0" lower="-3.14159" upper="3.14159" velocity="0.0"/>
    </joint>
    <joint name="Leg1_Leg4" type="revolute">
       <parent link="Leg1"/>
       <child  link="Leg4"/>
       <origin rpy="0 0 0" xyz="0.7370344172381748 2.2585041974725915 0" />
     <axis xyz="1 0 0"/>
       <limit effort="0.0" lower="-3.14159" upper="3.14159" velocity="0.0"/>
    </joint>
    <joint name="Torso_Leg5" type="revolute">
       <parent link="Torso"/>
       <child  link="Leg5"/>
       <origin rpy="0 0 0" xyz="1.0759042799881615 0.9595615919135887 1.1649584982473007" />
     <axis xyz="1 0 0"/>
       <limit effort="0.0" lower="-3.14159" upper="3.14159" velocity="0.0"/>
    </joint>
    <joint name="Leg3_Leg6" type="revolute">
       <parent link="Leg3"/>
       <child  link="Leg6"/>
       <origin rpy="0 0 0" xyz="1.4087849081906112 0 0" />
     <axis xyz="1 0 0"/>
       <limit effort="0.0" lower="-3.14159" upper="3.14159" velocity="0.0"/>
    </joint>
    <joint name="Leg2_Leg7" type="revolute">
       <parent link="Leg2"/>
       <child  link="Leg7"/>
       <origin rpy="0 0 0" xyz="0 2.656249451144615 0" />
     <axis xyz="1 0 0"/>
       <limit effort="0.0" lower="-3.14159" upper="3.14159" velocity="0.0"/>
    </joint>
    <joint name="Leg5_Leg8" type="revolute">
       <parent link="Leg5"/>
       <child  link="Leg8"/>
       <origin rpy="0 0 0" xyz="2.7733896188459246 0 0" />
     <axis xyz="1 0 0"/>
       <limit effort="0.0" lower="-3.14159" upper="3.14159" velocity="0.0"/>
    </joint>
    <joint name="Leg5_Leg9" type="revolute">
       <parent link="Leg5"/>
       <child  link="Leg9"/>
       <origin rpy="0 0 0" xyz="2.7733896188459246 0 0.8641371132219537" />
     <axis xyz="1 0 0"/>
       <limit effort="0.0" lower="-3.14159" upper="3.14159" velocity="0.0"/>
    </joint>
    <joint name="Leg9_Leg10" type="revolute">
       <parent link="Leg9"/>
       <child  link="Leg10"/>
       <origin rpy="0 0 0" xyz="0 0 1.6571010178035501" />
     <axis xyz="1 0 0"/>
       <limit effort="0.0" lower="-3.14159" upper="3.14159" velocity="0.0"/>
    </joint>
    <joint name="Leg2_Leg11" type="revolute">
       <parent link="Leg2"/>
       <child  link="Leg11"/>
       <origin rpy="0 0 0" xyz="0.8325925412542169 2.656249451144615 0" />
     <axis xyz="1 0 0"/>
       <limit effort="0.0" lower="-3.14159" upper="3.14159" velocity="0.0"/>
    </joint>
    <joint name="Leg8_Leg12" type="revolute">
       <parent link="Leg8"/>
       <child  link="Leg12"/>
       <origin rpy="0 0 0" xyz="1.4311797474044148 0 0.5977103295998973" />
     <axis xyz="1 0 0"/>
       <limit effort="0.0" lower="-3.14159" upper="3.14159" velocity="0.0"/>
    </joint>
    <joint name="Leg12_Leg13" type="revolute">
       <parent link="Leg12"/>
       <child  link="Leg13"/>
       <origin rpy="0 0 0" xyz="0 1.1634389487458094 0" />
     <axis xyz="1 0 0"/>
       <limit effort="0.0" lower="-3.14159" upper="3.14159" velocity="0.0"/>
    </joint>
    <joint name="Leg12_Leg14" type="revolute">
       <parent link="Leg12"/>
       <child  link="Leg14"/>
       <origin rpy="0 0 0" xyz="1.1856966338204482 1.1634389487458094 0" />
     <axis xyz="1 0 0"/>
       <limit effort="0.0" lower="-3.14159" upper="3.14159" velocity="0.0"/>
    </joint>
    <joint name="Leg3_Leg15" type="revolute">
       <parent link="Leg3"/>
       <child  link="Leg15"/>
       <origin rpy="0 0 0" xyz="1.4087849081906112 1.306754068699635 0" />
     <axis xyz="1 0 0"/>
       <limit effort="0.0" lower="-3.14159" upper="3.14159" velocity="0.0"/>
    </joint>
    <joint name="Leg15_Leg16" type="revolute">
       <parent link="Leg15"/>
       <child  link="Leg16"/>
       <origin rpy="0 0 0" xyz="0 2.0954982756203164 0" />
     <axis xyz="1 0 0"/>
       <limit effort="0.0" lower="-3.14159" upper="3.14159" velocity="0.0"/>
    </joint>
    <joint name="Leg6_Leg17" type="revolute">
       <parent link="Leg6"/>
       <child  link="Leg17"/>
       <origin rpy="0 0 0" xyz="0 1.2950644514178782 0.827362561343024" />
     <axis xyz="1 0 0"/>
       <limit effort="0.0" lower="-3.14159" upper="3.14159" velocity="0.0"/>
    </joint>
    <joint name="Leg13_Leg18" type="revolute">
       <parent link="Leg13"/>
       <child  link="Leg18"/>
       <origin rpy="0 0 0" xyz="1.2945433845012748 0 0" />
     <axis xyz="1 0 0"/>
       <limit effort="0.0" lower="-3.14159" upper="3.14159" velocity="0.0"/>
    </joint>
    <joint name="Leg4_Leg19" type="revolute">
       <parent link="Leg4"/>
       <child  link="Leg19"/>
       <origin rpy="0 0 0" xyz="0 0 2.2043024512043687" />
     <axis xyz="1 0 0"/>
       <limit effort="0.0" lower="-3.14159" upper="3.14159" velocity="0.0"/>
    </joint>
    <joint name="Leg19_Leg20" type="revolute">
       <parent link="Leg19"/>
       <child  link="Leg20"/>
       <origin rpy="0 0 0" xyz="0 0 2.5687497948888893" />
     <axis xyz="1 0 0"/>
       <limit effort="0.0" lower="-3.14159" upper="3.14159" velocity="0.0"/>
    </joint>
    <joint name="Leg5_Leg21" type="revolute">
       <parent link="Leg5"/>
       <child  link="Leg21"/>
       <origin rpy="0 0 0" xyz="2.7733896188459246 0.601526733844833 0.8641371132219537" />
     <axis xyz="1 0 0"/>
       <limit effort="0.0" lower="-3.14159" upper="3.14159" velocity="0.0"/>
    </joint>
    <joint name="Leg6_Leg22" type="revolute">
       <parent link="Leg6"/>
       <child  link="Leg22"/>
       <origin rpy="0 0 0" xyz="1.4067289185959087 1.2950644514178782 0.827362561343024" />
     <axis xyz="1 0 0"/>
       <limit effort="0.0" lower="-3.14159" upper="3.14159" velocity="0.0"/>
    </joint>
    <joint name="Leg6_Leg23" type="revolute">
       <parent link="Leg6"/>
       <child  link="Leg23"/>
       <origin rpy="0 0 0" xyz="1.4067289185959087 2.5901289028357564 0.827362561343024" />
     <axis xyz="1 0 0"/>
       <limit effort="0.0" lower="-3.14159" upper="3.14159" velocity="0.0"/>
    </joint>
    <joint name="Leg16_Leg24" type="revolute">
       <parent link="Leg16"/>
       <child  link="Leg24"/>
       <origin rpy="0 0 0" xyz="0 0.8721205307930041 1.256338520307327" />
     <axis xyz="1 0 0"/>
       <limit effort="0.0" lower="-3.14159" upper="3.14159" velocity="0.0"/>
    </joint>
    <joint name="Leg18_Leg25" type="revolute">
       <parent link="Leg18"/>
       <child  link="Leg25"/>
       <origin rpy="0 0 0" xyz="0 0.5722210183622888 0.7235370413258396" />
     <axis xyz="1 0 0"/>
       <limit effort="0.0" lower="-3.14159" upper="3.14159" velocity="0.0"/>
    </joint>
    <joint name="Leg16_Leg26" type="revolute">
       <parent link="Leg16"/>
       <child  link="Leg26"/>
       <origin rpy="0 0 0" xyz="0 0.8721205307930041 2.512677040614654" />
     <axis xyz="1 0 0"/>
       <limit effort="0.0" lower="-3.14159" upper="3.14159" velocity="0.0"/>
    </joint>
    <joint name="Leg10_Leg27" type="revolute">
       <parent link="Leg10"/>
       <child  link="Leg27"/>
       <origin rpy="0 0 0" xyz="2.3557409495002655 0 0" />
     <axis xyz="1 0 0"/>
       <limit effort="0.0" lower="-3.14159" upper="3.14159" velocity="0.0"/>
    </joint>
    <joint name="Leg13_Leg28" type="revolute">
       <parent link="Leg13"/>
       <child  link="Leg28"/>
       <origin rpy="0 0 0" xyz="1.2945433845012748 0 1.3091763728816868" />
     <axis xyz="1 0 0"/>
       <limit effort="0.0" lower="-3.14159" upper="3.14159" velocity="0.0"/>
    </joint>
</robot>