<robot name = "robot">
    <link name="Torso">
        <inertial>
            <origin xyz="0 0 1.4821497646370707" rpy="0 0 0"/>
            <mass value="1" />
            <inertia ixx="100" ixy="0" ixz="0" iyy="100" iyz="0" izz="100" />
        </inertial>
        <visual>
            <origin xyz="0 0 1.4821497646370707" rpy="0 0 0"/>
            <geometry>
                <box size="2.32587227337323 1.4897381149858204 2.9642995292741414" />
            </geometry>
            <material name="Green">
                <color rgba="0 180.0 0.0 1.0"/>
            </material>
        </visual>
        <collision>
            <origin xyz="0 0 1.4821497646370707" rpy="0 0 0"/>
            <geometry>
                <box size="2.32587227337323 1.4897381149858204 2.9642995292741414" />
            </geometry>
        </collision>
    </link>
    <link name="Leg1">
        <inertial>
            <origin xyz="1.1491038962078404 0 0" rpy="0 0 0"/>
            <mass value="1" />
            <inertia ixx="100" ixy="0" ixz="0" iyy="100" iyz="0" izz="100" />
        </inertial>
        <visual>
            <origin xyz="1.1491038962078404 0 0" rpy="0 0 0"/>
            <geometry>
                <box size="2.2982077924156807 2.213422393834805 2.679776192101956" />
            </geometry>
            <material name="Green">
                <color rgba="0 180.0 0.0 1.0"/>
            </material>
        </visual>
        <collision>
            <origin xyz="1.1491038962078404 0 0" rpy="0 0 0"/>
            <geometry>
                <box size="2.2982077924156807 2.213422393834805 2.679776192101956" />
            </geometry>
        </collision>
    </link>
    <link name="Leg2">
        <inertial>
            <origin xyz="0 0 0.6435109737491421" rpy="0 0 0"/>
            <mass value="1" />
            <inertia ixx="100" ixy="0" ixz="0" iyy="100" iyz="0" izz="100" />
        </inertial>
        <visual>
            <origin xyz="0 0 0.6435109737491421" rpy="0 0 0"/>
            <geometry>
                <box size="1.534951025657549 1.033405885998204 1.2870219474982842" />
            </geometry>
            <material name="Blue">
                <color rgba="0 1.0 1.0 1.0"/>
            </material>
        </visual>
        <collision>
            <origin xyz="0 0 0.6435109737491421" rpy="0 0 0"/>
            <geometry>
                <box size="1.534951025657549 1.033405885998204 1.2870219474982842" />
            </geometry>
        </collision>
    </link>
    <link name="Leg3">
        <inertial>
            <origin xyz="0.7365751468302285 0 0" rpy="0 0 0"/>
            <mass value="1" />
            <inertia ixx="100" ixy="0" ixz="0" iyy="100" iyz="0" izz="100" />
        </inertial>
        <visual>
            <origin xyz="0.7365751468302285 0 0" rpy="0 0 0"/>
            <geometry>
                <box size="1.473150293660457 2.522836218182489 1.296036239240459" />
            </geometry>
            <material name="Blue">
                <color rgba="0 1.0 1.0 1.0"/>
            </material>
        </visual>
        <collision>
            <origin xyz="0.7365751468302285 0 0" rpy="0 0 0"/>
            <geometry>
                <box size="1.473150293660457 2.522836218182489 1.296036239240459" />
            </geometry>
        </collision>
    </link>
    <link name="Leg4">
        <inertial>
            <origin xyz="0 0 0.6733292719645755" rpy="0 0 0"/>
            <mass value="1" />
            <inertia ixx="100" ixy="0" ixz="0" iyy="100" iyz="0" izz="100" />
        </inertial>
        <visual>
            <origin xyz="0 0 0.6733292719645755" rpy="0 0 0"/>
            <geometry>
                <box size="1.1162344056571039 2.0470514145260674 1.346658543929151" />
            </geometry>
            <material name="Blue">
                <color rgba="0 1.0 1.0 1.0"/>
            </material>
        </visual>
        <collision>
            <origin xyz="0 0 0.6733292719645755" rpy="0 0 0"/>
            <geometry>
                <box size="1.1162344056571039 2.0470514145260674 1.346658543929151" />
            </geometry>
        </collision>
    </link>
    <link name="Leg5">
        <inertial>
            <origin xyz="0 0 1.1477528113772189" rpy="0 0 0"/>
            <mass value="1" />
            <inertia ixx="100" ixy="0" ixz="0" iyy="100" iyz="0" izz="100" />
        </inertial>
        <visual>
            <origin xyz="0 0 1.1477528113772189" rpy="0 0 0"/>
            <geometry>
                <box size="1.8826477834441804 2.101221724481473 2.2955056227544377" />
            </geometry>
            <material name="Blue">
                <color rgba="0 1.0 1.0 1.0"/>
            </material>
        </visual>
        <collision>
            <origin xyz="0 0 1.1477528113772189" rpy="0 0 0"/>
            <geometry>
                <box size="1.8826477834441804 2.101221724481473 2.2955056227544377" />
            </geometry>
        </collision>
    </link>
    <link name="Leg6">
        <inertial>
            <origin xyz="1.1255513959679653 0 0" rpy="0 0 0"/>
            <mass value="1" />
            <inertia ixx="100" ixy="0" ixz="0" iyy="100" iyz="0" izz="100" />
        </inertial>
        <visual>
            <origin xyz="1.1255513959679653 0 0" rpy="0 0 0"/>
            <geometry>
                <box size="2.2511027919359305 1.9273826981451796 2.584168510674458" />
            </geometry>
            <material name="Green">
                <color rgba="0 180.0 0.0 1.0"/>
            </material>
        </visual>
        <collision>
            <origin xyz="1.1255513959679653 0 0" rpy="0 0 0"/>
            <geometry>
                <box size="2.2511027919359305 1.9273826981451796 2.584168510674458" />
            </geometry>
        </collision>
    </link>
    <link name="Leg7">
        <inertial>
            <origin xyz="0.6928656840814589 0 0" rpy="0 0 0"/>
            <mass value="1" />
            <inertia ixx="100" ixy="0" ixz="0" iyy="100" iyz="0" izz="100" />
        </inertial>
        <visual>
            <origin xyz="0.6928656840814589 0 0" rpy="0 0 0"/>
            <geometry>
                <box size="1.3857313681629178 1.104912249058489 1.0657623147117545" />
            </geometry>
            <material name="Green">
                <color rgba="0 180.0 0.0 1.0"/>
            </material>
        </visual>
        <collision>
            <origin xyz="0.6928656840814589 0 0" rpy="0 0 0"/>
            <geometry>
                <box size="1.3857313681629178 1.104912249058489 1.0657623147117545" />
            </geometry>
        </collision>
    </link>
    <link name="Leg8">
        <inertial>
            <origin xyz="0 0 1.2658644006993713" rpy="0 0 0"/>
            <mass value="1" />
            <inertia ixx="100" ixy="0" ixz="0" iyy="100" iyz="0" izz="100" />
        </inertial>
        <visual>
            <origin xyz="0 0 1.2658644006993713" rpy="0 0 0"/>
            <geometry>
                <box size="1.501074514076752 1.0149862273908423 2.5317288013987427" />
            </geometry>
            <material name="Blue">
                <color rgba="0 1.0 1.0 1.0"/>
            </material>
        </visual>
        <collision>
            <origin xyz="0 0 1.2658644006993713" rpy="0 0 0"/>
            <geometry>
                <box size="1.501074514076752 1.0149862273908423 2.5317288013987427" />
            </geometry>
        </collision>
    </link>
    <link name="Leg9">
        <inertial>
            <origin xyz="0 0 1.411467369116631" rpy="0 0 0"/>
            <mass value="1" />
            <inertia ixx="100" ixy="0" ixz="0" iyy="100" iyz="0" izz="100" />
        </inertial>
        <visual>
            <origin xyz="0 0 1.411467369116631" rpy="0 0 0"/>
            <geometry>
                <box size="2.5959021294446987 1.1471042867360224 2.822934738233262" />
            </geometry>
            <material name="Blue">
                <color rgba="0 1.0 1.0 1.0"/>
            </material>
        </visual>
        <collision>
            <origin xyz="0 0 1.411467369116631" rpy="0 0 0"/>
            <geometry>
                <box size="2.5959021294446987 1.1471042867360224 2.822934738233262" />
            </geometry>
        </collision>
    </link>
    <link name="Leg10">
        <inertial>
            <origin xyz="0 0 0.5829996158496089" rpy="0 0 0"/>
            <mass value="1" />
            <inertia ixx="100" ixy="0" ixz="0" iyy="100" iyz="0" izz="100" />
        </inertial>
        <visual>
            <origin xyz="0 0 0.5829996158496089" rpy="0 0 0"/>
            <geometry>
                <box size="2.0018097633905882 2.2101619892023088 1.1659992316992178" />
            </geometry>
            <material name="Green">
                <color rgba="0 180.0 0.0 1.0"/>
            </material>
        </visual>
        <collision>
            <origin xyz="0 0 0.5829996158496089" rpy="0 0 0"/>
            <geometry>
                <box size="2.0018097633905882 2.2101619892023088 1.1659992316992178" />
            </geometry>
        </collision>
    </link>
    <link name="Leg11">
        <inertial>
            <origin xyz="0 1.1987929480257642 0" rpy="0 0 0"/>
            <mass value="1" />
            <inertia ixx="100" ixy="0" ixz="0" iyy="100" iyz="0" izz="100" />
        </inertial>
        <visual>
            <origin xyz="0 1.1987929480257642 0" rpy="0 0 0"/>
            <geometry>
                <box size="2.4596540439750285 2.3975858960515284 2.116499206864302" />
            </geometry>
            <material name="Green">
                <color rgba="0 180.0 0.0 1.0"/>
            </material>
        </visual>
        <collision>
            <origin xyz="0 1.1987929480257642 0" rpy="0 0 0"/>
            <geometry>
                <box size="2.4596540439750285 2.3975858960515284 2.116499206864302" />
            </geometry>
        </collision>
    </link>
    <link name="Leg12">
        <inertial>
            <origin xyz="0 1.48606097792308 0" rpy="0 0 0"/>
            <mass value="1" />
            <inertia ixx="100" ixy="0" ixz="0" iyy="100" iyz="0" izz="100" />
        </inertial>
        <visual>
            <origin xyz="0 1.48606097792308 0" rpy="0 0 0"/>
            <geometry>
                <box size="2.5495929706667386 2.97212195584616 2.469397146873595" />
            </geometry>
            <material name="Green">
                <color rgba="0 180.0 0.0 1.0"/>
            </material>
        </visual>
        <collision>
            <origin xyz="0 1.48606097792308 0" rpy="0 0 0"/>
            <geometry>
                <box size="2.5495929706667386 2.97212195584616 2.469397146873595" />
            </geometry>
        </collision>
    </link>
    <link name="Leg13">
        <inertial>
            <origin xyz="0 0 0.9448860554195285" rpy="0 0 0"/>
            <mass value="1" />
            <inertia ixx="100" ixy="0" ixz="0" iyy="100" iyz="0" izz="100" />
        </inertial>
        <visual>
            <origin xyz="0 0 0.9448860554195285" rpy="0 0 0"/>
            <geometry>
                <box size="1.6113507741643742 2.0405569291920127 1.889772110839057" />
            </geometry>
            <material name="Green">
                <color rgba="0 180.0 0.0 1.0"/>
            </material>
        </visual>
        <collision>
            <origin xyz="0 0 0.9448860554195285" rpy="0 0 0"/>
            <geometry>
                <box size="1.6113507741643742 2.0405569291920127 1.889772110839057" />
            </geometry>
        </collision>
    </link>
    <link name="Leg14">
        <inertial>
            <origin xyz="0 1.2332759098607329 0" rpy="0 0 0"/>
            <mass value="1" />
            <inertia ixx="100" ixy="0" ixz="0" iyy="100" iyz="0" izz="100" />
        </inertial>
        <visual>
            <origin xyz="0 1.2332759098607329 0" rpy="0 0 0"/>
            <geometry>
                <box size="1.263354711015529 2.4665518197214658 1.077015580141895" />
            </geometry>
            <material name="Blue">
                <color rgba="0 1.0 1.0 1.0"/>
            </material>
        </visual>
        <collision>
            <origin xyz="0 1.2332759098607329 0" rpy="0 0 0"/>
            <geometry>
                <box size="1.263354711015529 2.4665518197214658 1.077015580141895" />
            </geometry>
        </collision>
    </link>
    <link name="Leg15">
        <inertial>
            <origin xyz="0.7713326693990383 0 0" rpy="0 0 0"/>
            <mass value="1" />
            <inertia ixx="100" ixy="0" ixz="0" iyy="100" iyz="0" izz="100" />
        </inertial>
        <visual>
            <origin xyz="0.7713326693990383 0 0" rpy="0 0 0"/>
            <geometry>
                <box size="1.5426653387980767 2.8508821816744 2.9902376746365533" />
            </geometry>
            <material name="Green">
                <color rgba="0 180.0 0.0 1.0"/>
            </material>
        </visual>
        <collision>
            <origin xyz="0.7713326693990383 0 0" rpy="0 0 0"/>
            <geometry>
                <box size="1.5426653387980767 2.8508821816744 2.9902376746365533" />
            </geometry>
        </collision>
    </link>
    <link name="Leg16">
        <inertial>
            <origin xyz="0 0.7541406606721545 0" rpy="0 0 0"/>
            <mass value="1" />
            <inertia ixx="100" ixy="0" ixz="0" iyy="100" iyz="0" izz="100" />
        </inertial>
        <visual>
            <origin xyz="0 0.7541406606721545 0" rpy="0 0 0"/>
            <geometry>
                <box size="2.315797569588444 1.508281321344309 1.3438428520614374" />
            </geometry>
            <material name="Blue">
                <color rgba="0 1.0 1.0 1.0"/>
            </material>
        </visual>
        <collision>
            <origin xyz="0 0.7541406606721545 0" rpy="0 0 0"/>
            <geometry>
                <box size="2.315797569588444 1.508281321344309 1.3438428520614374" />
            </geometry>
        </collision>
    </link>
    <link name="Leg17">
        <inertial>
            <origin xyz="1.4223284727800465 0 0" rpy="0 0 0"/>
            <mass value="1" />
            <inertia ixx="100" ixy="0" ixz="0" iyy="100" iyz="0" izz="100" />
        </inertial>
        <visual>
            <origin xyz="1.4223284727800465 0 0" rpy="0 0 0"/>
            <geometry>
                <box size="2.844656945560093 2.33433489145572 2.262479977439494" />
            </geometry>
            <material name="Blue">
                <color rgba="0 1.0 1.0 1.0"/>
            </material>
        </visual>
        <collision>
            <origin xyz="1.4223284727800465 0 0" rpy="0 0 0"/>
            <geometry>
                <box size="2.844656945560093 2.33433489145572 2.262479977439494" />
            </geometry>
        </collision>
    </link>
    <link name="Leg18">
        <inertial>
            <origin xyz="0.5289830874048663 0 0" rpy="0 0 0"/>
            <mass value="1" />
            <inertia ixx="100" ixy="0" ixz="0" iyy="100" iyz="0" izz="100" />
        </inertial>
        <visual>
            <origin xyz="0.5289830874048663 0 0" rpy="0 0 0"/>
            <geometry>
                <box size="1.0579661748097327 2.1113295639901013 2.813269139242282" />
            </geometry>
            <material name="Green">
                <color rgba="0 180.0 0.0 1.0"/>
            </material>
        </visual>
        <collision>
            <origin xyz="0.5289830874048663 0 0" rpy="0 0 0"/>
            <geometry>
                <box size="1.0579661748097327 2.1113295639901013 2.813269139242282" />
            </geometry>
        </collision>
    </link>
    <link name="Leg19">
        <inertial>
            <origin xyz="0 0.787711333114138 0" rpy="0 0 0"/>
            <mass value="1" />
            <inertia ixx="100" ixy="0" ixz="0" iyy="100" iyz="0" izz="100" />
        </inertial>
        <visual>
            <origin xyz="0 0.787711333114138 0" rpy="0 0 0"/>
            <geometry>
                <box size="2.9686281246999506 1.575422666228276 1.3648090612713226" />
            </geometry>
            <material name="Green">
                <color rgba="0 180.0 0.0 1.0"/>
            </material>
        </visual>
        <collision>
            <origin xyz="0 0.787711333114138 0" rpy="0 0 0"/>
            <geometry>
                <box size="2.9686281246999506 1.575422666228276 1.3648090612713226" />
            </geometry>
        </collision>
    </link>
    <link name="Leg20">
        <inertial>
            <origin xyz="0.6560489757354194 0 0" rpy="0 0 0"/>
            <mass value="1" />
            <inertia ixx="100" ixy="0" ixz="0" iyy="100" iyz="0" izz="100" />
        </inertial>
        <visual>
            <origin xyz="0.6560489757354194 0 0" rpy="0 0 0"/>
            <geometry>
                <box size="1.3120979514708389 2.41208617805054 2.769358082182153" />
            </geometry>
            <material name="Blue">
                <color rgba="0 1.0 1.0 1.0"/>
            </material>
        </visual>
        <collision>
            <origin xyz="0.6560489757354194 0 0" rpy="0 0 0"/>
            <geometry>
                <box size="1.3120979514708389 2.41208617805054 2.769358082182153" />
            </geometry>
        </collision>
    </link>
    <link name="Leg21">
        <inertial>
            <origin xyz="0 0 1.418005208679933" rpy="0 0 0"/>
            <mass value="1" />
            <inertia ixx="100" ixy="0" ixz="0" iyy="100" iyz="0" izz="100" />
        </inertial>
        <visual>
            <origin xyz="0 0 1.418005208679933" rpy="0 0 0"/>
            <geometry>
                <box size="2.0524555276042897 1.916073156178337 2.836010417359866" />
            </geometry>
            <material name="Green">
                <color rgba="0 180.0 0.0 1.0"/>
            </material>
        </visual>
        <collision>
            <origin xyz="0 0 1.418005208679933" rpy="0 0 0"/>
            <geometry>
                <box size="2.0524555276042897 1.916073156178337 2.836010417359866" />
            </geometry>
        </collision>
    </link>
    <link name="Leg22">
        <inertial>
            <origin xyz="1.399855790352715 0 0" rpy="0 0 0"/>
            <mass value="1" />
            <inertia ixx="100" ixy="0" ixz="0" iyy="100" iyz="0" izz="100" />
        </inertial>
        <visual>
            <origin xyz="1.399855790352715 0 0" rpy="0 0 0"/>
            <geometry>
                <box size="2.79971158070543 1.172070040100572 2.6250093735948536" />
            </geometry>
            <material name="Green">
                <color rgba="0 180.0 0.0 1.0"/>
            </material>
        </visual>
        <collision>
            <origin xyz="1.399855790352715 0 0" rpy="0 0 0"/>
            <geometry>
                <box size="2.79971158070543 1.172070040100572 2.6250093735948536" />
            </geometry>
        </collision>
    </link>
    <link name="Leg23">
        <inertial>
            <origin xyz="0.7317084636523367 0 0" rpy="0 0 0"/>
            <mass value="1" />
            <inertia ixx="100" ixy="0" ixz="0" iyy="100" iyz="0" izz="100" />
        </inertial>
        <visual>
            <origin xyz="0.7317084636523367 0 0" rpy="0 0 0"/>
            <geometry>
                <box size="1.4634169273046733 1.9926888103696032 2.9068954059993386" />
            </geometry>
            <material name="Blue">
                <color rgba="0 1.0 1.0 1.0"/>
            </material>
        </visual>
        <collision>
            <origin xyz="0.7317084636523367 0 0" rpy="0 0 0"/>
            <geometry>
                <box size="1.4634169273046733 1.9926888103696032 2.9068954059993386" />
            </geometry>
        </collision>
    </link>
    <link name="Leg24">
        <inertial>
            <origin xyz="0.6568460116336605 0 0" rpy="0 0 0"/>
            <mass value="1" />
            <inertia ixx="100" ixy="0" ixz="0" iyy="100" iyz="0" izz="100" />
        </inertial>
        <visual>
            <origin xyz="0.6568460116336605 0 0" rpy="0 0 0"/>
            <geometry>
                <box size="1.313692023267321 1.165938909139202 1.1290332427674559" />
            </geometry>
            <material name="Green">
                <color rgba="0 180.0 0.0 1.0"/>
            </material>
        </visual>
        <collision>
            <origin xyz="0.6568460116336605 0 0" rpy="0 0 0"/>
            <geometry>
                <box size="1.313692023267321 1.165938909139202 1.1290332427674559" />
            </geometry>
        </collision>
    </link>
    <link name="Leg25">
        <inertial>
            <origin xyz="0 1.3110745310367027 0" rpy="0 0 0"/>
            <mass value="1" />
            <inertia ixx="100" ixy="0" ixz="0" iyy="100" iyz="0" izz="100" />
        </inertial>
        <visual>
            <origin xyz="0 1.3110745310367027 0" rpy="0 0 0"/>
            <geometry>
                <box size="2.03343194119375 2.6221490620734054 1.1803480474873191" />
            </geometry>
            <material name="Green">
                <color rgba="0 180.0 0.0 1.0"/>
            </material>
        </visual>
        <collision>
            <origin xyz="0 1.3110745310367027 0" rpy="0 0 0"/>
            <geometry>
                <box size="2.03343194119375 2.6221490620734054 1.1803480474873191" />
            </geometry>
        </collision>
    </link>
    <link name="Leg26">
        <inertial>
            <origin xyz="0 0 1.0067791940817634" rpy="0 0 0"/>
            <mass value="1" />
            <inertia ixx="100" ixy="0" ixz="0" iyy="100" iyz="0" izz="100" />
        </inertial>
        <visual>
            <origin xyz="0 0 1.0067791940817634" rpy="0 0 0"/>
            <geometry>
                <box size="1.5615599791236958 2.8408835446563825 2.013558388163527" />
            </geometry>
            <material name="Green">
                <color rgba="0 180.0 0.0 1.0"/>
            </material>
        </visual>
        <collision>
            <origin xyz="0 0 1.0067791940817634" rpy="0 0 0"/>
            <geometry>
                <box size="1.5615599791236958 2.8408835446563825 2.013558388163527" />
            </geometry>
        </collision>
    </link>
    <link name="Leg27">
        <inertial>
            <origin xyz="0 1.2343514131314433 0" rpy="0 0 0"/>
            <mass value="1" />
            <inertia ixx="100" ixy="0" ixz="0" iyy="100" iyz="0" izz="100" />
        </inertial>
        <visual>
            <origin xyz="0 1.2343514131314433 0" rpy="0 0 0"/>
            <geometry>
                <box size="2.8115469127357806 2.4687028262628865 2.561836396902997" />
            </geometry>
            <material name="Green">
                <color rgba="0 180.0 0.0 1.0"/>
            </material>
        </visual>
        <collision>
            <origin xyz="0 1.2343514131314433 0" rpy="0 0 0"/>
            <geometry>
                <box size="2.8115469127357806 2.4687028262628865 2.561836396902997" />
            </geometry>
        </collision>
    </link>
    <joint name="Torso_Leg1" type="revolute">
       <parent link="Torso"/>
       <child  link="Leg1"/>
       <origin rpy="0 0 0" xyz="1.162936136686615 0 1.4821497646370707" />
     <axis xyz="1 0 0"/>
       <limit effort="0.0" lower="-3.14159" upper="3.14159" velocity="0.0"/>
    </joint>
    <joint name="Leg1_Leg2" type="revolute">
       <parent link="Leg1"/>
       <child  link="Leg2"/>
       <origin rpy="0 0 0" xyz="0 0 1.2870219474982842" />
     <axis xyz="1 0 0"/>
       <limit effort="0.0" lower="-3.14159" upper="3.14159" velocity="0.0"/>
    </joint>
    <joint name="Leg2_Leg3" type="revolute">
       <parent link="Leg2"/>
       <child  link="Leg3"/>
       <origin rpy="0 0 0" xyz="1.473150293660457 0 0" />
     <axis xyz="1 0 0"/>
       <limit effort="0.0" lower="-3.14159" upper="3.14159" velocity="0.0"/>
    </joint>
    <joint name="Leg2_Leg4" type="revolute">
       <parent link="Leg2"/>
       <child  link="Leg4"/>
       <origin rpy="0 0 0" xyz="1.473150293660457 0 0.6480181196202295" />
     <axis xyz="1 0 0"/>
       <limit effort="0.0" lower="-3.14159" upper="3.14159" velocity="0.0"/>
    </joint>
    <joint name="Torso_Leg5" type="revolute">
       <parent link="Torso"/>
       <child  link="Leg5"/>
       <origin rpy="0 0 0" xyz="1.1491038962078404 0 1.339888096050978" />
     <axis xyz="1 0 0"/>
       <limit effort="0.0" lower="-3.14159" upper="3.14159" velocity="0.0"/>
    </joint>
    <joint name="Leg4_Leg6" type="revolute">
       <parent link="Leg4"/>
       <child  link="Leg6"/>
       <origin rpy="0 0 0" xyz="0.9413238917220902 0 1.1477528113772189" />
     <axis xyz="1 0 0"/>
       <limit effort="0.0" lower="-3.14159" upper="3.14159" velocity="0.0"/>
    </joint>
    <joint name="Leg1_Leg7" type="revolute">
       <parent link="Leg1"/>
       <child  link="Leg7"/>
       <origin rpy="0 0 0" xyz="0.7674755128287745 0 1.2870219474982842" />
     <axis xyz="1 0 0"/>
       <limit effort="0.0" lower="-3.14159" upper="3.14159" velocity="0.0"/>
    </joint>
    <joint name="Leg5_Leg8" type="revolute">
       <parent link="Leg5"/>
       <child  link="Leg8"/>
       <origin rpy="0 0 0" xyz="1.1255513959679653 0 1.292084255337229" />
     <axis xyz="1 0 0"/>
       <limit effort="0.0" lower="-3.14159" upper="3.14159" velocity="0.0"/>
    </joint>
    <joint name="Leg3_Leg9" type="revolute">
       <parent link="Leg3"/>
       <child  link="Leg9"/>
       <origin rpy="0 0 0" xyz="0 0 1.346658543929151" />
     <axis xyz="1 0 0"/>
       <limit effort="0.0" lower="-3.14159" upper="3.14159" velocity="0.0"/>
    </joint>
    <joint name="Leg7_Leg10" type="revolute">
       <parent link="Leg7"/>
       <child  link="Leg10"/>
       <origin rpy="0 0 0" xyz="0 0 2.5317288013987427" />
     <axis xyz="1 0 0"/>
       <limit effort="0.0" lower="-3.14159" upper="3.14159" velocity="0.0"/>
    </joint>
    <joint name="Leg5_Leg11" type="revolute">
       <parent link="Leg5"/>
       <child  link="Leg11"/>
       <origin rpy="0 0 0" xyz="1.1255513959679653 0.9636913490725898 1.292084255337229" />
     <axis xyz="1 0 0"/>
       <limit effort="0.0" lower="-3.14159" upper="3.14159" velocity="0.0"/>
    </joint>
    <joint name="Leg2_Leg12" type="revolute">
       <parent link="Leg2"/>
       <child  link="Leg12"/>
       <origin rpy="0 0 0" xyz="1.473150293660457 1.2614181090912444 0.6480181196202295" />
     <axis xyz="1 0 0"/>
       <limit effort="0.0" lower="-3.14159" upper="3.14159" velocity="0.0"/>
    </joint>
    <joint name="Leg4_Leg13" type="revolute">
       <parent link="Leg4"/>
       <child  link="Leg13"/>
       <origin rpy="0 0 0" xyz="0.9413238917220902 0 2.2955056227544377" />
     <axis xyz="1 0 0"/>
       <limit effort="0.0" lower="-3.14159" upper="3.14159" velocity="0.0"/>
    </joint>
    <joint name="Torso_Leg14" type="revolute">
       <parent link="Torso"/>
       <child  link="Leg14"/>
       <origin rpy="0 0 0" xyz="1.1491038962078404 1.1067111969174026 1.339888096050978" />
     <axis xyz="1 0 0"/>
       <limit effort="0.0" lower="-3.14159" upper="3.14159" velocity="0.0"/>
    </joint>
    <joint name="Leg9_Leg15" type="revolute">
       <parent link="Leg9"/>
       <child  link="Leg15"/>
       <origin rpy="0 0 0" xyz="1.0009048816952941 0 0.5829996158496089" />
     <axis xyz="1 0 0"/>
       <limit effort="0.0" lower="-3.14159" upper="3.14159" velocity="0.0"/>
    </joint>
    <joint name="Leg10_Leg16" type="revolute">
       <parent link="Leg10"/>
       <child  link="Leg16"/>
       <origin rpy="0 0 0" xyz="0 2.3975858960515284 0" />
     <axis xyz="1 0 0"/>
       <limit effort="0.0" lower="-3.14159" upper="3.14159" velocity="0.0"/>
    </joint>
    <joint name="Leg15_Leg17" type="revolute">
       <parent link="Leg15"/>
       <child  link="Leg17"/>
       <origin rpy="0 0 0" xyz="1.157898784794222 0.7541406606721545 0" />
     <axis xyz="1 0 0"/>
       <limit effort="0.0" lower="-3.14159" upper="3.14159" velocity="0.0"/>
    </joint>
    <joint name="Leg8_Leg18" type="revolute">
       <parent link="Leg8"/>
       <child  link="Leg18"/>
       <origin rpy="0 0 0" xyz="1.2979510647223493 0 1.411467369116631" />
     <axis xyz="1 0 0"/>
       <limit effort="0.0" lower="-3.14159" upper="3.14159" velocity="0.0"/>
    </joint>
    <joint name="Leg17_Leg19" type="revolute">
       <parent link="Leg17"/>
       <child  link="Leg19"/>
       <origin rpy="0 0 0" xyz="0.5289830874048663 1.0556647819950506 0" />
     <axis xyz="1 0 0"/>
       <limit effort="0.0" lower="-3.14159" upper="3.14159" velocity="0.0"/>
    </joint>
    <joint name="Leg6_Leg20" type="revolute">
       <parent link="Leg6"/>
       <child  link="Leg20"/>
       <origin rpy="0 0 0" xyz="1.3857313681629178 0 0" />
     <axis xyz="1 0 0"/>
       <limit effort="0.0" lower="-3.14159" upper="3.14159" velocity="0.0"/>
    </joint>
    <joint name="Leg8_Leg21" type="revolute">
       <parent link="Leg8"/>
       <child  link="Leg21"/>
       <origin rpy="0 0 0" xyz="1.2979510647223493 0 2.822934738233262" />
     <axis xyz="1 0 0"/>
       <limit effort="0.0" lower="-3.14159" upper="3.14159" velocity="0.0"/>
    </joint>
    <joint name="Leg18_Leg22" type="revolute">
       <parent link="Leg18"/>
       <child  link="Leg22"/>
       <origin rpy="0 0 0" xyz="1.4843140623499753 0.787711333114138 0" />
     <axis xyz="1 0 0"/>
       <limit effort="0.0" lower="-3.14159" upper="3.14159" velocity="0.0"/>
    </joint>
    <joint name="Leg21_Leg23" type="revolute">
       <parent link="Leg21"/>
       <child  link="Leg23"/>
       <origin rpy="0 0 0" xyz="2.79971158070543 0 0" />
     <axis xyz="1 0 0"/>
       <limit effort="0.0" lower="-3.14159" upper="3.14159" velocity="0.0"/>
    </joint>
    <joint name="Leg14_Leg24" type="revolute">
       <parent link="Leg14"/>
       <child  link="Leg24"/>
       <origin rpy="0 0 0" xyz="1.5426653387980767 0 0" />
     <axis xyz="1 0 0"/>
       <limit effort="0.0" lower="-3.14159" upper="3.14159" velocity="0.0"/>
    </joint>
    <joint name="Leg8_Leg25" type="revolute">
       <parent link="Leg8"/>
       <child  link="Leg25"/>
       <origin rpy="0 0 0" xyz="1.2979510647223493 0.5735521433680112 2.822934738233262" />
     <axis xyz="1 0 0"/>
       <limit effort="0.0" lower="-3.14159" upper="3.14159" velocity="0.0"/>
    </joint>
    <joint name="Leg11_Leg26" type="revolute">
       <parent link="Leg11"/>
       <child  link="Leg26"/>
       <origin rpy="0 0 0" xyz="0 1.48606097792308 1.2346985734367975" />
     <axis xyz="1 0 0"/>
       <limit effort="0.0" lower="-3.14159" upper="3.14159" velocity="0.0"/>
    </joint>
    <joint name="Leg1_Leg27" type="revolute">
       <parent link="Leg1"/>
       <child  link="Leg27"/>
       <origin rpy="0 0 0" xyz="0.7674755128287745 0.516702942999102 1.2870219474982842" />
     <axis xyz="1 0 0"/>
       <limit effort="0.0" lower="-3.14159" upper="3.14159" velocity="0.0"/>
    </joint>
</robot>