<robot name = "robot">
    <link name="Torso">
        <inertial>
            <origin xyz="0 0 0.6685880935999942" rpy="0 0 0"/>
            <mass value="1" />
            <inertia ixx="100" ixy="0" ixz="0" iyy="100" iyz="0" izz="100" />
        </inertial>
        <visual>
            <origin xyz="0 0 0.6685880935999942" rpy="0 0 0"/>
            <geometry>
                <box size="2.4940218510085748 2.5013979510121076 1.3371761871999883" />
            </geometry>
            <material name="Green">
                <color rgba="0 180.0 0.0 1.0"/>
            </material>
        </visual>
        <collision>
            <origin xyz="0 0 0.6685880935999942" rpy="0 0 0"/>
            <geometry>
                <box size="2.4940218510085748 2.5013979510121076 1.3371761871999883" />
            </geometry>
        </collision>
    </link>
    <link name="Leg1">
        <inertial>
            <origin xyz="0.7320199417734823 0 0" rpy="0 0 0"/>
            <mass value="1" />
            <inertia ixx="100" ixy="0" ixz="0" iyy="100" iyz="0" izz="100" />
        </inertial>
        <visual>
            <origin xyz="0.7320199417734823 0 0" rpy="0 0 0"/>
            <geometry>
                <box size="1.4640398835469646 1.2734554157067852 2.652392976913478" />
            </geometry>
            <material name="Blue">
                <color rgba="0 1.0 1.0 1.0"/>
            </material>
        </visual>
        <collision>
            <origin xyz="0.7320199417734823 0 0" rpy="0 0 0"/>
            <geometry>
                <box size="1.4640398835469646 1.2734554157067852 2.652392976913478" />
            </geometry>
        </collision>
    </link>
    <link name="Leg2">
        <inertial>
            <origin xyz="0 0 0.8963254976890531" rpy="0 0 0"/>
            <mass value="1" />
            <inertia ixx="100" ixy="0" ixz="0" iyy="100" iyz="0" izz="100" />
        </inertial>
        <visual>
            <origin xyz="0 0 0.8963254976890531" rpy="0 0 0"/>
            <geometry>
                <box size="2.634241680180374 1.5693737520753215 1.7926509953781062" />
            </geometry>
            <material name="Green">
                <color rgba="0 180.0 0.0 1.0"/>
            </material>
        </visual>
        <collision>
            <origin xyz="0 0 0.8963254976890531" rpy="0 0 0"/>
            <geometry>
                <box size="2.634241680180374 1.5693737520753215 1.7926509953781062" />
            </geometry>
        </collision>
    </link>
    <link name="Leg3">
        <inertial>
            <origin xyz="0 0 1.1518165489689367" rpy="0 0 0"/>
            <mass value="1" />
            <inertia ixx="100" ixy="0" ixz="0" iyy="100" iyz="0" izz="100" />
        </inertial>
        <visual>
            <origin xyz="0 0 1.1518165489689367" rpy="0 0 0"/>
            <geometry>
                <box size="1.1903567789358003 1.7263952758734233 2.3036330979378734" />
            </geometry>
            <material name="Green">
                <color rgba="0 180.0 0.0 1.0"/>
            </material>
        </visual>
        <collision>
            <origin xyz="0 0 1.1518165489689367" rpy="0 0 0"/>
            <geometry>
                <box size="1.1903567789358003 1.7263952758734233 2.3036330979378734" />
            </geometry>
        </collision>
    </link>
    <link name="Leg4">
        <inertial>
            <origin xyz="1.2862858430193937 0 0" rpy="0 0 0"/>
            <mass value="1" />
            <inertia ixx="100" ixy="0" ixz="0" iyy="100" iyz="0" izz="100" />
        </inertial>
        <visual>
            <origin xyz="1.2862858430193937 0 0" rpy="0 0 0"/>
            <geometry>
                <box size="2.5725716860387875 1.7184208607862763 2.624967931482752" />
            </geometry>
            <material name="Green">
                <color rgba="0 180.0 0.0 1.0"/>
            </material>
        </visual>
        <collision>
            <origin xyz="1.2862858430193937 0 0" rpy="0 0 0"/>
            <geometry>
                <box size="2.5725716860387875 1.7184208607862763 2.624967931482752" />
            </geometry>
        </collision>
    </link>
    <link name="Leg5">
        <inertial>
            <origin xyz="0 0 0.5775651785909772" rpy="0 0 0"/>
            <mass value="1" />
            <inertia ixx="100" ixy="0" ixz="0" iyy="100" iyz="0" izz="100" />
        </inertial>
        <visual>
            <origin xyz="0 0 0.5775651785909772" rpy="0 0 0"/>
            <geometry>
                <box size="1.579512408872867 2.6275973870432683 1.1551303571819544" />
            </geometry>
            <material name="Green">
                <color rgba="0 180.0 0.0 1.0"/>
            </material>
        </visual>
        <collision>
            <origin xyz="0 0 0.5775651785909772" rpy="0 0 0"/>
            <geometry>
                <box size="1.579512408872867 2.6275973870432683 1.1551303571819544" />
            </geometry>
        </collision>
    </link>
    <link name="Leg6">
        <inertial>
            <origin xyz="0.8451592353706977 0 0" rpy="0 0 0"/>
            <mass value="1" />
            <inertia ixx="100" ixy="0" ixz="0" iyy="100" iyz="0" izz="100" />
        </inertial>
        <visual>
            <origin xyz="0.8451592353706977 0 0" rpy="0 0 0"/>
            <geometry>
                <box size="1.6903184707413954 2.850963043706016 1.1389570576749455" />
            </geometry>
            <material name="Green">
                <color rgba="0 180.0 0.0 1.0"/>
            </material>
        </visual>
        <collision>
            <origin xyz="0.8451592353706977 0 0" rpy="0 0 0"/>
            <geometry>
                <box size="1.6903184707413954 2.850963043706016 1.1389570576749455" />
            </geometry>
        </collision>
    </link>
    <link name="Leg7">
        <inertial>
            <origin xyz="0 1.1479255638826071 0" rpy="0 0 0"/>
            <mass value="1" />
            <inertia ixx="100" ixy="0" ixz="0" iyy="100" iyz="0" izz="100" />
        </inertial>
        <visual>
            <origin xyz="0 1.1479255638826071 0" rpy="0 0 0"/>
            <geometry>
                <box size="2.1426460647176353 2.2958511277652143 2.512196174352768" />
            </geometry>
            <material name="Blue">
                <color rgba="0 1.0 1.0 1.0"/>
            </material>
        </visual>
        <collision>
            <origin xyz="0 1.1479255638826071 0" rpy="0 0 0"/>
            <geometry>
                <box size="2.1426460647176353 2.2958511277652143 2.512196174352768" />
            </geometry>
        </collision>
    </link>
    <link name="Leg8">
        <inertial>
            <origin xyz="0 0 1.0389542630262616" rpy="0 0 0"/>
            <mass value="1" />
            <inertia ixx="100" ixy="0" ixz="0" iyy="100" iyz="0" izz="100" />
        </inertial>
        <visual>
            <origin xyz="0 0 1.0389542630262616" rpy="0 0 0"/>
            <geometry>
                <box size="1.027823322678144 1.132356148296222 2.077908526052523" />
            </geometry>
            <material name="Blue">
                <color rgba="0 1.0 1.0 1.0"/>
            </material>
        </visual>
        <collision>
            <origin xyz="0 0 1.0389542630262616" rpy="0 0 0"/>
            <geometry>
                <box size="1.027823322678144 1.132356148296222 2.077908526052523" />
            </geometry>
        </collision>
    </link>
    <link name="Leg9">
        <inertial>
            <origin xyz="1.3139269214912168 0 0" rpy="0 0 0"/>
            <mass value="1" />
            <inertia ixx="100" ixy="0" ixz="0" iyy="100" iyz="0" izz="100" />
        </inertial>
        <visual>
            <origin xyz="1.3139269214912168 0 0" rpy="0 0 0"/>
            <geometry>
                <box size="2.6278538429824336 2.970598673422896 1.4649810187641408" />
            </geometry>
            <material name="Green">
                <color rgba="0 180.0 0.0 1.0"/>
            </material>
        </visual>
        <collision>
            <origin xyz="1.3139269214912168 0 0" rpy="0 0 0"/>
            <geometry>
                <box size="2.6278538429824336 2.970598673422896 1.4649810187641408" />
            </geometry>
        </collision>
    </link>
    <link name="Leg10">
        <inertial>
            <origin xyz="1.2332597223857267 0 0" rpy="0 0 0"/>
            <mass value="1" />
            <inertia ixx="100" ixy="0" ixz="0" iyy="100" iyz="0" izz="100" />
        </inertial>
        <visual>
            <origin xyz="1.2332597223857267 0 0" rpy="0 0 0"/>
            <geometry>
                <box size="2.4665194447714534 1.4977223805157847 1.81059159227725" />
            </geometry>
            <material name="Blue">
                <color rgba="0 1.0 1.0 1.0"/>
            </material>
        </visual>
        <collision>
            <origin xyz="1.2332597223857267 0 0" rpy="0 0 0"/>
            <geometry>
                <box size="2.4665194447714534 1.4977223805157847 1.81059159227725" />
            </geometry>
        </collision>
    </link>
    <link name="Leg11">
        <inertial>
            <origin xyz="0.8060911307170713 0 0" rpy="0 0 0"/>
            <mass value="1" />
            <inertia ixx="100" ixy="0" ixz="0" iyy="100" iyz="0" izz="100" />
        </inertial>
        <visual>
            <origin xyz="0.8060911307170713 0 0" rpy="0 0 0"/>
            <geometry>
                <box size="1.6121822614341426 2.818202133808633 1.6258995437598895" />
            </geometry>
            <material name="Green">
                <color rgba="0 180.0 0.0 1.0"/>
            </material>
        </visual>
        <collision>
            <origin xyz="0.8060911307170713 0 0" rpy="0 0 0"/>
            <geometry>
                <box size="1.6121822614341426 2.818202133808633 1.6258995437598895" />
            </geometry>
        </collision>
    </link>
    <link name="Leg12">
        <inertial>
            <origin xyz="0.5177945540641443 0 0" rpy="0 0 0"/>
            <mass value="1" />
            <inertia ixx="100" ixy="0" ixz="0" iyy="100" iyz="0" izz="100" />
        </inertial>
        <visual>
            <origin xyz="0.5177945540641443 0 0" rpy="0 0 0"/>
            <geometry>
                <box size="1.0355891081282886 1.4104877633409105 1.8563375383156786" />
            </geometry>
            <material name="Blue">
                <color rgba="0 1.0 1.0 1.0"/>
            </material>
        </visual>
        <collision>
            <origin xyz="0.5177945540641443 0 0" rpy="0 0 0"/>
            <geometry>
                <box size="1.0355891081282886 1.4104877633409105 1.8563375383156786" />
            </geometry>
        </collision>
    </link>
    <link name="Leg13">
        <inertial>
            <origin xyz="0 1.4975778183236308 0" rpy="0 0 0"/>
            <mass value="1" />
            <inertia ixx="100" ixy="0" ixz="0" iyy="100" iyz="0" izz="100" />
        </inertial>
        <visual>
            <origin xyz="0 1.4975778183236308 0" rpy="0 0 0"/>
            <geometry>
                <box size="2.358553749930022 2.9951556366472616 1.6028762510863932" />
            </geometry>
            <material name="Blue">
                <color rgba="0 1.0 1.0 1.0"/>
            </material>
        </visual>
        <collision>
            <origin xyz="0 1.4975778183236308 0" rpy="0 0 0"/>
            <geometry>
                <box size="2.358553749930022 2.9951556366472616 1.6028762510863932" />
            </geometry>
        </collision>
    </link>
    <link name="Leg14">
        <inertial>
            <origin xyz="0 0 0.5219332100581611" rpy="0 0 0"/>
            <mass value="1" />
            <inertia ixx="100" ixy="0" ixz="0" iyy="100" iyz="0" izz="100" />
        </inertial>
        <visual>
            <origin xyz="0 0 0.5219332100581611" rpy="0 0 0"/>
            <geometry>
                <box size="1.1782321254871746 2.6159202373562946 1.0438664201163221" />
            </geometry>
            <material name="Blue">
                <color rgba="0 1.0 1.0 1.0"/>
            </material>
        </visual>
        <collision>
            <origin xyz="0 0 0.5219332100581611" rpy="0 0 0"/>
            <geometry>
                <box size="1.1782321254871746 2.6159202373562946 1.0438664201163221" />
            </geometry>
        </collision>
    </link>
    <link name="Leg15">
        <inertial>
            <origin xyz="1.1141311676484726 0 0" rpy="0 0 0"/>
            <mass value="1" />
            <inertia ixx="100" ixy="0" ixz="0" iyy="100" iyz="0" izz="100" />
        </inertial>
        <visual>
            <origin xyz="1.1141311676484726 0 0" rpy="0 0 0"/>
            <geometry>
                <box size="2.2282623352969453 1.8321054990749 2.9656746508621596" />
            </geometry>
            <material name="Blue">
                <color rgba="0 1.0 1.0 1.0"/>
            </material>
        </visual>
        <collision>
            <origin xyz="1.1141311676484726 0 0" rpy="0 0 0"/>
            <geometry>
                <box size="2.2282623352969453 1.8321054990749 2.9656746508621596" />
            </geometry>
        </collision>
    </link>
    <link name="Leg16">
        <inertial>
            <origin xyz="0 1.1842436420465918 0" rpy="0 0 0"/>
            <mass value="1" />
            <inertia ixx="100" ixy="0" ixz="0" iyy="100" iyz="0" izz="100" />
        </inertial>
        <visual>
            <origin xyz="0 1.1842436420465918 0" rpy="0 0 0"/>
            <geometry>
                <box size="2.636294357029816 2.3684872840931837 2.592591714330559" />
            </geometry>
            <material name="Green">
                <color rgba="0 180.0 0.0 1.0"/>
            </material>
        </visual>
        <collision>
            <origin xyz="0 1.1842436420465918 0" rpy="0 0 0"/>
            <geometry>
                <box size="2.636294357029816 2.3684872840931837 2.592591714330559" />
            </geometry>
        </collision>
    </link>
    <link name="Leg17">
        <inertial>
            <origin xyz="0 0 1.2978845901211042" rpy="0 0 0"/>
            <mass value="1" />
            <inertia ixx="100" ixy="0" ixz="0" iyy="100" iyz="0" izz="100" />
        </inertial>
        <visual>
            <origin xyz="0 0 1.2978845901211042" rpy="0 0 0"/>
            <geometry>
                <box size="2.658488278266258 2.6959318917269695 2.5957691802422085" />
            </geometry>
            <material name="Green">
                <color rgba="0 180.0 0.0 1.0"/>
            </material>
        </visual>
        <collision>
            <origin xyz="0 0 1.2978845901211042" rpy="0 0 0"/>
            <geometry>
                <box size="2.658488278266258 2.6959318917269695 2.5957691802422085" />
            </geometry>
        </collision>
    </link>
    <link name="Leg18">
        <inertial>
            <origin xyz="1.1350534618154513 0 0" rpy="0 0 0"/>
            <mass value="1" />
            <inertia ixx="100" ixy="0" ixz="0" iyy="100" iyz="0" izz="100" />
        </inertial>
        <visual>
            <origin xyz="1.1350534618154513 0 0" rpy="0 0 0"/>
            <geometry>
                <box size="2.2701069236309026 2.808964528770349 1.8557947490144278" />
            </geometry>
            <material name="Blue">
                <color rgba="0 1.0 1.0 1.0"/>
            </material>
        </visual>
        <collision>
            <origin xyz="1.1350534618154513 0 0" rpy="0 0 0"/>
            <geometry>
                <box size="2.2701069236309026 2.808964528770349 1.8557947490144278" />
            </geometry>
        </collision>
    </link>
    <link name="Leg19">
        <inertial>
            <origin xyz="0 1.0473051252977177 0" rpy="0 0 0"/>
            <mass value="1" />
            <inertia ixx="100" ixy="0" ixz="0" iyy="100" iyz="0" izz="100" />
        </inertial>
        <visual>
            <origin xyz="0 1.0473051252977177 0" rpy="0 0 0"/>
            <geometry>
                <box size="2.9947203003755907 2.0946102505954354 2.689482694209528" />
            </geometry>
            <material name="Blue">
                <color rgba="0 1.0 1.0 1.0"/>
            </material>
        </visual>
        <collision>
            <origin xyz="0 1.0473051252977177 0" rpy="0 0 0"/>
            <geometry>
                <box size="2.9947203003755907 2.0946102505954354 2.689482694209528" />
            </geometry>
        </collision>
    </link>
    <link name="Leg20">
        <inertial>
            <origin xyz="1.2228143627786014 0 0" rpy="0 0 0"/>
            <mass value="1" />
            <inertia ixx="100" ixy="0" ixz="0" iyy="100" iyz="0" izz="100" />
        </inertial>
        <visual>
            <origin xyz="1.2228143627786014 0 0" rpy="0 0 0"/>
            <geometry>
                <box size="2.445628725557203 2.228896860897351 1.4615690720417338" />
            </geometry>
            <material name="Blue">
                <color rgba="0 1.0 1.0 1.0"/>
            </material>
        </visual>
        <collision>
            <origin xyz="1.2228143627786014 0 0" rpy="0 0 0"/>
            <geometry>
                <box size="2.445628725557203 2.228896860897351 1.4615690720417338" />
            </geometry>
        </collision>
    </link>
    <link name="Leg21">
        <inertial>
            <origin xyz="0 1.3284412982010525 0" rpy="0 0 0"/>
            <mass value="1" />
            <inertia ixx="100" ixy="0" ixz="0" iyy="100" iyz="0" izz="100" />
        </inertial>
        <visual>
            <origin xyz="0 1.3284412982010525 0" rpy="0 0 0"/>
            <geometry>
                <box size="1.582472182901508 2.656882596402105 2.1722317270877634" />
            </geometry>
            <material name="Blue">
                <color rgba="0 1.0 1.0 1.0"/>
            </material>
        </visual>
        <collision>
            <origin xyz="0 1.3284412982010525 0" rpy="0 0 0"/>
            <geometry>
                <box size="1.582472182901508 2.656882596402105 2.1722317270877634" />
            </geometry>
        </collision>
    </link>
    <link name="Leg22">
        <inertial>
            <origin xyz="0 0 1.3812344191706272" rpy="0 0 0"/>
            <mass value="1" />
            <inertia ixx="100" ixy="0" ixz="0" iyy="100" iyz="0" izz="100" />
        </inertial>
        <visual>
            <origin xyz="0 0 1.3812344191706272" rpy="0 0 0"/>
            <geometry>
                <box size="1.3562630416098624 1.247192940439299 2.7624688383412543" />
            </geometry>
            <material name="Green">
                <color rgba="0 180.0 0.0 1.0"/>
            </material>
        </visual>
        <collision>
            <origin xyz="0 0 1.3812344191706272" rpy="0 0 0"/>
            <geometry>
                <box size="1.3562630416098624 1.247192940439299 2.7624688383412543" />
            </geometry>
        </collision>
    </link>
    <link name="Leg23">
        <inertial>
            <origin xyz="0 1.015985587836382 0" rpy="0 0 0"/>
            <mass value="1" />
            <inertia ixx="100" ixy="0" ixz="0" iyy="100" iyz="0" izz="100" />
        </inertial>
        <visual>
            <origin xyz="0 1.015985587836382 0" rpy="0 0 0"/>
            <geometry>
                <box size="1.673272609495669 2.031971175672764 1.4338923950755784" />
            </geometry>
            <material name="Blue">
                <color rgba="0 1.0 1.0 1.0"/>
            </material>
        </visual>
        <collision>
            <origin xyz="0 1.015985587836382 0" rpy="0 0 0"/>
            <geometry>
                <box size="1.673272609495669 2.031971175672764 1.4338923950755784" />
            </geometry>
        </collision>
    </link>
    <link name="Leg24">
        <inertial>
            <origin xyz="0 0 1.2698954254753096" rpy="0 0 0"/>
            <mass value="1" />
            <inertia ixx="100" ixy="0" ixz="0" iyy="100" iyz="0" izz="100" />
        </inertial>
        <visual>
            <origin xyz="0 0 1.2698954254753096" rpy="0 0 0"/>
            <geometry>
                <box size="1.3650088816456913 1.416478626121166 2.5397908509506193" />
            </geometry>
            <material name="Blue">
                <color rgba="0 1.0 1.0 1.0"/>
            </material>
        </visual>
        <collision>
            <origin xyz="0 0 1.2698954254753096" rpy="0 0 0"/>
            <geometry>
                <box size="1.3650088816456913 1.416478626121166 2.5397908509506193" />
            </geometry>
        </collision>
    </link>
    <link name="Leg25">
        <inertial>
            <origin xyz="0 0 1.1789078272337308" rpy="0 0 0"/>
            <mass value="1" />
            <inertia ixx="100" ixy="0" ixz="0" iyy="100" iyz="0" izz="100" />
        </inertial>
        <visual>
            <origin xyz="0 0 1.1789078272337308" rpy="0 0 0"/>
            <geometry>
                <box size="1.5567234132419516 1.1374600578326575 2.3578156544674616" />
            </geometry>
            <material name="Blue">
                <color rgba="0 1.0 1.0 1.0"/>
            </material>
        </visual>
        <collision>
            <origin xyz="0 0 1.1789078272337308" rpy="0 0 0"/>
            <geometry>
                <box size="1.5567234132419516 1.1374600578326575 2.3578156544674616" />
            </geometry>
        </collision>
    </link>
    <link name="Leg26">
        <inertial>
            <origin xyz="0.6336980121960799 0 0" rpy="0 0 0"/>
            <mass value="1" />
            <inertia ixx="100" ixy="0" ixz="0" iyy="100" iyz="0" izz="100" />
        </inertial>
        <visual>
            <origin xyz="0.6336980121960799 0 0" rpy="0 0 0"/>
            <geometry>
                <box size="1.2673960243921598 2.93331849596234 1.4699459845881753" />
            </geometry>
            <material name="Blue">
                <color rgba="0 1.0 1.0 1.0"/>
            </material>
        </visual>
        <collision>
            <origin xyz="0.6336980121960799 0 0" rpy="0 0 0"/>
            <geometry>
                <box size="1.2673960243921598 2.93331849596234 1.4699459845881753" />
            </geometry>
        </collision>
    </link>
    <joint name="Torso_Leg1" type="revolute">
       <parent link="Torso"/>
       <child  link="Leg1"/>
       <origin rpy="0 0 0" xyz="1.2470109255042874 0 0.6685880935999942" />
     <axis xyz="1 0 0"/>
       <limit effort="0.0" lower="-3.14159" upper="3.14159" velocity="0.0"/>
    </joint>
    <joint name="Leg1_Leg2" type="revolute">
       <parent link="Leg1"/>
       <child  link="Leg2"/>
       <origin rpy="0 0 0" xyz="0 0 1.7926509953781062" />
     <axis xyz="1 0 0"/>
       <limit effort="0.0" lower="-3.14159" upper="3.14159" velocity="0.0"/>
    </joint>
    <joint name="Torso_Leg3" type="revolute">
       <parent link="Torso"/>
       <child  link="Leg3"/>
       <origin rpy="0 0 0" xyz="0.7320199417734823 0 1.326196488456739" />
     <axis xyz="1 0 0"/>
       <limit effort="0.0" lower="-3.14159" upper="3.14159" velocity="0.0"/>
    </joint>
    <joint name="Leg3_Leg4" type="revolute">
       <parent link="Leg3"/>
       <child  link="Leg4"/>
       <origin rpy="0 0 0" xyz="2.5725716860387875 0 0" />
     <axis xyz="1 0 0"/>
       <limit effort="0.0" lower="-3.14159" upper="3.14159" velocity="0.0"/>
    </joint>
    <joint name="Leg3_Leg5" type="revolute">
       <parent link="Leg3"/>
       <child  link="Leg5"/>
       <origin rpy="0 0 0" xyz="2.5725716860387875 0 1.312483965741376" />
     <axis xyz="1 0 0"/>
       <limit effort="0.0" lower="-3.14159" upper="3.14159" velocity="0.0"/>
    </joint>
    <joint name="Leg1_Leg6" type="revolute">
       <parent link="Leg1"/>
       <child  link="Leg6"/>
       <origin rpy="0 0 0" xyz="1.317120840090187 0 1.7926509953781062" />
     <axis xyz="1 0 0"/>
       <limit effort="0.0" lower="-3.14159" upper="3.14159" velocity="0.0"/>
    </joint>
    <joint name="Leg3_Leg7" type="revolute">
       <parent link="Leg3"/>
       <child  link="Leg7"/>
       <origin rpy="0 0 0" xyz="2.5725716860387875 0.8592104303931382 1.312483965741376" />
     <axis xyz="1 0 0"/>
       <limit effort="0.0" lower="-3.14159" upper="3.14159" velocity="0.0"/>
    </joint>
    <joint name="Leg2_Leg8" type="revolute">
       <parent link="Leg2"/>
       <child  link="Leg8"/>
       <origin rpy="0 0 0" xyz="0 0 2.3036330979378734" />
     <axis xyz="1 0 0"/>
       <limit effort="0.0" lower="-3.14159" upper="3.14159" velocity="0.0"/>
    </joint>
    <joint name="Leg7_Leg9" type="revolute">
       <parent link="Leg7"/>
       <child  link="Leg9"/>
       <origin rpy="0 0 0" xyz="0.513911661339072 0 1.0389542630262616" />
     <axis xyz="1 0 0"/>
       <limit effort="0.0" lower="-3.14159" upper="3.14159" velocity="0.0"/>
    </joint>
    <joint name="Leg4_Leg10" type="revolute">
       <parent link="Leg4"/>
       <child  link="Leg10"/>
       <origin rpy="0 0 0" xyz="0.7897562044364335 0 0.5775651785909772" />
     <axis xyz="1 0 0"/>
       <limit effort="0.0" lower="-3.14159" upper="3.14159" velocity="0.0"/>
    </joint>
    <joint name="Leg9_Leg11" type="revolute">
       <parent link="Leg9"/>
       <child  link="Leg11"/>
       <origin rpy="0 0 0" xyz="2.4665194447714534 0 0" />
     <axis xyz="1 0 0"/>
       <limit effort="0.0" lower="-3.14159" upper="3.14159" velocity="0.0"/>
    </joint>
    <joint name="Leg10_Leg12" type="revolute">
       <parent link="Leg10"/>
       <child  link="Leg12"/>
       <origin rpy="0 0 0" xyz="1.6121822614341426 0 0" />
     <axis xyz="1 0 0"/>
       <limit effort="0.0" lower="-3.14159" upper="3.14159" velocity="0.0"/>
    </joint>
    <joint name="Torso_Leg13" type="revolute">
       <parent link="Torso"/>
       <child  link="Leg13"/>
       <origin rpy="0 0 0" xyz="0.7320199417734823 0.6367277078533926 1.326196488456739" />
     <axis xyz="1 0 0"/>
       <limit effort="0.0" lower="-3.14159" upper="3.14159" velocity="0.0"/>
    </joint>
    <joint name="Leg8_Leg14" type="revolute">
       <parent link="Leg8"/>
       <child  link="Leg14"/>
       <origin rpy="0 0 0" xyz="1.3139269214912168 0 0.7324905093820704" />
     <axis xyz="1 0 0"/>
       <limit effort="0.0" lower="-3.14159" upper="3.14159" velocity="0.0"/>
    </joint>
    <joint name="Leg14_Leg15" type="revolute">
       <parent link="Leg14"/>
       <child  link="Leg15"/>
       <origin rpy="0 0 0" xyz="2.2282623352969453 0 0" />
     <axis xyz="1 0 0"/>
       <limit effort="0.0" lower="-3.14159" upper="3.14159" velocity="0.0"/>
    </joint>
    <joint name="Leg9_Leg16" type="revolute">
       <parent link="Leg9"/>
       <child  link="Leg16"/>
       <origin rpy="0 0 0" xyz="2.4665194447714534 0.7488611902578923 0" />
     <axis xyz="1 0 0"/>
       <limit effort="0.0" lower="-3.14159" upper="3.14159" velocity="0.0"/>
    </joint>
    <joint name="Leg10_Leg17" type="revolute">
       <parent link="Leg10"/>
       <child  link="Leg17"/>
       <origin rpy="0 0 0" xyz="1.6121822614341426 0 0.8129497718799448" />
     <axis xyz="1 0 0"/>
       <limit effort="0.0" lower="-3.14159" upper="3.14159" velocity="0.0"/>
    </joint>
    <joint name="Leg11_Leg18" type="revolute">
       <parent link="Leg11"/>
       <child  link="Leg18"/>
       <origin rpy="0 0 0" xyz="1.0355891081282886 0 0" />
     <axis xyz="1 0 0"/>
       <limit effort="0.0" lower="-3.14159" upper="3.14159" velocity="0.0"/>
    </joint>
    <joint name="Leg6_Leg19" type="revolute">
       <parent link="Leg6"/>
       <child  link="Leg19"/>
       <origin rpy="0 0 0" xyz="0 2.2958511277652143 0" />
     <axis xyz="1 0 0"/>
       <limit effort="0.0" lower="-3.14159" upper="3.14159" velocity="0.0"/>
    </joint>
    <joint name="Leg17_Leg20" type="revolute">
       <parent link="Leg17"/>
       <child  link="Leg20"/>
       <origin rpy="0 0 0" xyz="2.2701069236309026 0 0" />
     <axis xyz="1 0 0"/>
       <limit effort="0.0" lower="-3.14159" upper="3.14159" velocity="0.0"/>
    </joint>
    <joint name="Leg20_Leg21" type="revolute">
       <parent link="Leg20"/>
       <child  link="Leg21"/>
       <origin rpy="0 0 0" xyz="0 2.656882596402105 0" />
     <axis xyz="1 0 0"/>
       <limit effort="0.0" lower="-3.14159" upper="3.14159" velocity="0.0"/>
    </joint>
    <joint name="Leg21_Leg22" type="revolute">
       <parent link="Leg21"/>
       <child  link="Leg22"/>
       <origin rpy="0 0 0" xyz="0 0 2.7624688383412543" />
     <axis xyz="1 0 0"/>
       <limit effort="0.0" lower="-3.14159" upper="3.14159" velocity="0.0"/>
    </joint>
    <joint name="Leg12_Leg23" type="revolute">
       <parent link="Leg12"/>
       <child  link="Leg23"/>
       <origin rpy="0 0 0" xyz="0 2.9951556366472616 0" />
     <axis xyz="1 0 0"/>
       <limit effort="0.0" lower="-3.14159" upper="3.14159" velocity="0.0"/>
    </joint>
    <joint name="Leg20_Leg24" type="revolute">
       <parent link="Leg20"/>
       <child  link="Leg24"/>
       <origin rpy="0 0 0" xyz="0 2.656882596402105 1.0861158635438817" />
     <axis xyz="1 0 0"/>
       <limit effort="0.0" lower="-3.14159" upper="3.14159" velocity="0.0"/>
    </joint>
    <joint name="Leg14_Leg25" type="revolute">
       <parent link="Leg14"/>
       <child  link="Leg25"/>
       <origin rpy="0 0 0" xyz="2.2282623352969453 0 1.4828373254310798" />
     <axis xyz="1 0 0"/>
       <limit effort="0.0" lower="-3.14159" upper="3.14159" velocity="0.0"/>
    </joint>
    <joint name="Leg12_Leg26" type="revolute">
       <parent link="Leg12"/>
       <child  link="Leg26"/>
       <origin rpy="0 0 0" xyz="1.179276874965011 2.9951556366472616 0" />
     <axis xyz="1 0 0"/>
       <limit effort="0.0" lower="-3.14159" upper="3.14159" velocity="0.0"/>
    </joint>
</robot>