<robot name = "robot">
    <link name="Torso">
        <inertial>
            <origin xyz="0 0 0.7596492924036515" rpy="0 0 0"/>
            <mass value="1" />
            <inertia ixx="100" ixy="0" ixz="0" iyy="100" iyz="0" izz="100" />
        </inertial>
        <visual>
            <origin xyz="0 0 0.7596492924036515" rpy="0 0 0"/>
            <geometry>
                <box size="2.9778133941088045 1.406270724264768 1.519298584807303" />
            </geometry>
            <material name="Green">
                <color rgba="0 180.0 0.0 1.0"/>
            </material>
        </visual>
        <collision>
            <origin xyz="0 0 0.7596492924036515" rpy="0 0 0"/>
            <geometry>
                <box size="2.9778133941088045 1.406270724264768 1.519298584807303" />
            </geometry>
        </collision>
    </link>
    <link name="Leg1">
        <inertial>
            <origin xyz="0 0.7234149459514363 0" rpy="0 0 0"/>
            <mass value="1" />
            <inertia ixx="100" ixy="0" ixz="0" iyy="100" iyz="0" izz="100" />
        </inertial>
        <visual>
            <origin xyz="0 0.7234149459514363 0" rpy="0 0 0"/>
            <geometry>
                <box size="1.757780406347092 1.4468298919028726 2.3385099423782707" />
            </geometry>
            <material name="Blue">
                <color rgba="0 1.0 1.0 1.0"/>
            </material>
        </visual>
        <collision>
            <origin xyz="0 0.7234149459514363 0" rpy="0 0 0"/>
            <geometry>
                <box size="1.757780406347092 1.4468298919028726 2.3385099423782707" />
            </geometry>
        </collision>
    </link>
    <link name="Leg2">
        <inertial>
            <origin xyz="0 0 1.0988867940012244" rpy="0 0 0"/>
            <mass value="1" />
            <inertia ixx="100" ixy="0" ixz="0" iyy="100" iyz="0" izz="100" />
        </inertial>
        <visual>
            <origin xyz="0 0 1.0988867940012244" rpy="0 0 0"/>
            <geometry>
                <box size="2.96783738495501 1.1808196284947587 2.1977735880024487" />
            </geometry>
            <material name="Blue">
                <color rgba="0 1.0 1.0 1.0"/>
            </material>
        </visual>
        <collision>
            <origin xyz="0 0 1.0988867940012244" rpy="0 0 0"/>
            <geometry>
                <box size="2.96783738495501 1.1808196284947587 2.1977735880024487" />
            </geometry>
        </collision>
    </link>
    <link name="Leg3">
        <inertial>
            <origin xyz="0 1.2662759344470849 0" rpy="0 0 0"/>
            <mass value="1" />
            <inertia ixx="100" ixy="0" ixz="0" iyy="100" iyz="0" izz="100" />
        </inertial>
        <visual>
            <origin xyz="0 1.2662759344470849 0" rpy="0 0 0"/>
            <geometry>
                <box size="2.6570690407351667 2.5325518688941697 1.567988708170405" />
            </geometry>
            <material name="Blue">
                <color rgba="0 1.0 1.0 1.0"/>
            </material>
        </visual>
        <collision>
            <origin xyz="0 1.2662759344470849 0" rpy="0 0 0"/>
            <geometry>
                <box size="2.6570690407351667 2.5325518688941697 1.567988708170405" />
            </geometry>
        </collision>
    </link>
    <link name="Leg4">
        <inertial>
            <origin xyz="0 0 1.0543067980776297" rpy="0 0 0"/>
            <mass value="1" />
            <inertia ixx="100" ixy="0" ixz="0" iyy="100" iyz="0" izz="100" />
        </inertial>
        <visual>
            <origin xyz="0 0 1.0543067980776297" rpy="0 0 0"/>
            <geometry>
                <box size="1.9219604410533713 2.9387505655398973 2.1086135961552595" />
            </geometry>
            <material name="Blue">
                <color rgba="0 1.0 1.0 1.0"/>
            </material>
        </visual>
        <collision>
            <origin xyz="0 0 1.0543067980776297" rpy="0 0 0"/>
            <geometry>
                <box size="1.9219604410533713 2.9387505655398973 2.1086135961552595" />
            </geometry>
        </collision>
    </link>
    <link name="Leg5">
        <inertial>
            <origin xyz="0 0.5525556711232065 0" rpy="0 0 0"/>
            <mass value="1" />
            <inertia ixx="100" ixy="0" ixz="0" iyy="100" iyz="0" izz="100" />
        </inertial>
        <visual>
            <origin xyz="0 0.5525556711232065 0" rpy="0 0 0"/>
            <geometry>
                <box size="2.9611561323820075 1.105111342246413 2.329575785822901" />
            </geometry>
            <material name="Green">
                <color rgba="0 180.0 0.0 1.0"/>
            </material>
        </visual>
        <collision>
            <origin xyz="0 0.5525556711232065 0" rpy="0 0 0"/>
            <geometry>
                <box size="2.9611561323820075 1.105111342246413 2.329575785822901" />
            </geometry>
        </collision>
    </link>
    <link name="Leg6">
        <inertial>
            <origin xyz="0 0.7377646692558221 0" rpy="0 0 0"/>
            <mass value="1" />
            <inertia ixx="100" ixy="0" ixz="0" iyy="100" iyz="0" izz="100" />
        </inertial>
        <visual>
            <origin xyz="0 0.7377646692558221 0" rpy="0 0 0"/>
            <geometry>
                <box size="2.9335570058504614 1.4755293385116441 2.5900321267838824" />
            </geometry>
            <material name="Blue">
                <color rgba="0 1.0 1.0 1.0"/>
            </material>
        </visual>
        <collision>
            <origin xyz="0 0.7377646692558221 0" rpy="0 0 0"/>
            <geometry>
                <box size="2.9335570058504614 1.4755293385116441 2.5900321267838824" />
            </geometry>
        </collision>
    </link>
    <link name="Leg7">
        <inertial>
            <origin xyz="0 1.213650789617668 0" rpy="0 0 0"/>
            <mass value="1" />
            <inertia ixx="100" ixy="0" ixz="0" iyy="100" iyz="0" izz="100" />
        </inertial>
        <visual>
            <origin xyz="0 1.213650789617668 0" rpy="0 0 0"/>
            <geometry>
                <box size="2.504515692941511 2.427301579235336 1.7126731240458701" />
            </geometry>
            <material name="Blue">
                <color rgba="0 1.0 1.0 1.0"/>
            </material>
        </visual>
        <collision>
            <origin xyz="0 1.213650789617668 0" rpy="0 0 0"/>
            <geometry>
                <box size="2.504515692941511 2.427301579235336 1.7126731240458701" />
            </geometry>
        </collision>
    </link>
    <link name="Leg8">
        <inertial>
            <origin xyz="0 0.7434508873940856 0" rpy="0 0 0"/>
            <mass value="1" />
            <inertia ixx="100" ixy="0" ixz="0" iyy="100" iyz="0" izz="100" />
        </inertial>
        <visual>
            <origin xyz="0 0.7434508873940856 0" rpy="0 0 0"/>
            <geometry>
                <box size="1.1549843736857626 1.4869017747881712 1.8171793928007538" />
            </geometry>
            <material name="Blue">
                <color rgba="0 1.0 1.0 1.0"/>
            </material>
        </visual>
        <collision>
            <origin xyz="0 0.7434508873940856 0" rpy="0 0 0"/>
            <geometry>
                <box size="1.1549843736857626 1.4869017747881712 1.8171793928007538" />
            </geometry>
        </collision>
    </link>
    <link name="Leg9">
        <inertial>
            <origin xyz="0.6869443722897786 0 0" rpy="0 0 0"/>
            <mass value="1" />
            <inertia ixx="100" ixy="0" ixz="0" iyy="100" iyz="0" izz="100" />
        </inertial>
        <visual>
            <origin xyz="0.6869443722897786 0 0" rpy="0 0 0"/>
            <geometry>
                <box size="1.3738887445795571 1.9292804554346514 2.2716887241150934" />
            </geometry>
            <material name="Green">
                <color rgba="0 180.0 0.0 1.0"/>
            </material>
        </visual>
        <collision>
            <origin xyz="0.6869443722897786 0 0" rpy="0 0 0"/>
            <geometry>
                <box size="1.3738887445795571 1.9292804554346514 2.2716887241150934" />
            </geometry>
        </collision>
    </link>
    <link name="Leg10">
        <inertial>
            <origin xyz="0 0.5479938503416913 0" rpy="0 0 0"/>
            <mass value="1" />
            <inertia ixx="100" ixy="0" ixz="0" iyy="100" iyz="0" izz="100" />
        </inertial>
        <visual>
            <origin xyz="0 0.5479938503416913 0" rpy="0 0 0"/>
            <geometry>
                <box size="2.640731961746684 1.0959877006833827 1.26827631914795" />
            </geometry>
            <material name="Blue">
                <color rgba="0 1.0 1.0 1.0"/>
            </material>
        </visual>
        <collision>
            <origin xyz="0 0.5479938503416913 0" rpy="0 0 0"/>
            <geometry>
                <box size="2.640731961746684 1.0959877006833827 1.26827631914795" />
            </geometry>
        </collision>
    </link>
    <link name="Leg11">
        <inertial>
            <origin xyz="0 0.7631922720921732 0" rpy="0 0 0"/>
            <mass value="1" />
            <inertia ixx="100" ixy="0" ixz="0" iyy="100" iyz="0" izz="100" />
        </inertial>
        <visual>
            <origin xyz="0 0.7631922720921732 0" rpy="0 0 0"/>
            <geometry>
                <box size="2.303501749648757 1.5263845441843464 2.6322232378901314" />
            </geometry>
            <material name="Green">
                <color rgba="0 180.0 0.0 1.0"/>
            </material>
        </visual>
        <collision>
            <origin xyz="0 0.7631922720921732 0" rpy="0 0 0"/>
            <geometry>
                <box size="2.303501749648757 1.5263845441843464 2.6322232378901314" />
            </geometry>
        </collision>
    </link>
    <link name="Leg12">
        <inertial>
            <origin xyz="0 1.4805470960492078 0" rpy="0 0 0"/>
            <mass value="1" />
            <inertia ixx="100" ixy="0" ixz="0" iyy="100" iyz="0" izz="100" />
        </inertial>
        <visual>
            <origin xyz="0 1.4805470960492078 0" rpy="0 0 0"/>
            <geometry>
                <box size="2.562679411207564 2.9610941920984155 1.4919067434295386" />
            </geometry>
            <material name="Blue">
                <color rgba="0 1.0 1.0 1.0"/>
            </material>
        </visual>
        <collision>
            <origin xyz="0 1.4805470960492078 0" rpy="0 0 0"/>
            <geometry>
                <box size="2.562679411207564 2.9610941920984155 1.4919067434295386" />
            </geometry>
        </collision>
    </link>
    <link name="Leg13">
        <inertial>
            <origin xyz="1.3899933213691678 0 0" rpy="0 0 0"/>
            <mass value="1" />
            <inertia ixx="100" ixy="0" ixz="0" iyy="100" iyz="0" izz="100" />
        </inertial>
        <visual>
            <origin xyz="1.3899933213691678 0 0" rpy="0 0 0"/>
            <geometry>
                <box size="2.7799866427383355 2.516942486746048 1.4446598149089898" />
            </geometry>
            <material name="Green">
                <color rgba="0 180.0 0.0 1.0"/>
            </material>
        </visual>
        <collision>
            <origin xyz="1.3899933213691678 0 0" rpy="0 0 0"/>
            <geometry>
                <box size="2.7799866427383355 2.516942486746048 1.4446598149089898" />
            </geometry>
        </collision>
    </link>
    <link name="Leg14">
        <inertial>
            <origin xyz="0 0 1.1914405349675377" rpy="0 0 0"/>
            <mass value="1" />
            <inertia ixx="100" ixy="0" ixz="0" iyy="100" iyz="0" izz="100" />
        </inertial>
        <visual>
            <origin xyz="0 0 1.1914405349675377" rpy="0 0 0"/>
            <geometry>
                <box size="1.6449613662576281 2.35724537233133 2.3828810699350753" />
            </geometry>
            <material name="Green">
                <color rgba="0 180.0 0.0 1.0"/>
            </material>
        </visual>
        <collision>
            <origin xyz="0 0 1.1914405349675377" rpy="0 0 0"/>
            <geometry>
                <box size="1.6449613662576281 2.35724537233133 2.3828810699350753" />
            </geometry>
        </collision>
    </link>
    <link name="Leg15">
        <inertial>
            <origin xyz="0.65751309754393 0 0" rpy="0 0 0"/>
            <mass value="1" />
            <inertia ixx="100" ixy="0" ixz="0" iyy="100" iyz="0" izz="100" />
        </inertial>
        <visual>
            <origin xyz="0.65751309754393 0 0" rpy="0 0 0"/>
            <geometry>
                <box size="1.31502619508786 2.917322005868014 2.565504100511801" />
            </geometry>
            <material name="Blue">
                <color rgba="0 1.0 1.0 1.0"/>
            </material>
        </visual>
        <collision>
            <origin xyz="0.65751309754393 0 0" rpy="0 0 0"/>
            <geometry>
                <box size="1.31502619508786 2.917322005868014 2.565504100511801" />
            </geometry>
        </collision>
    </link>
    <link name="Leg16">
        <inertial>
            <origin xyz="0 0.8784043912029077 0" rpy="0 0 0"/>
            <mass value="1" />
            <inertia ixx="100" ixy="0" ixz="0" iyy="100" iyz="0" izz="100" />
        </inertial>
        <visual>
            <origin xyz="0 0.8784043912029077 0" rpy="0 0 0"/>
            <geometry>
                <box size="2.8672388584078323 1.7568087824058154 2.0655696592392614" />
            </geometry>
            <material name="Blue">
                <color rgba="0 1.0 1.0 1.0"/>
            </material>
        </visual>
        <collision>
            <origin xyz="0 0.8784043912029077 0" rpy="0 0 0"/>
            <geometry>
                <box size="2.8672388584078323 1.7568087824058154 2.0655696592392614" />
            </geometry>
        </collision>
    </link>
    <link name="Leg17">
        <inertial>
            <origin xyz="0 0.5457935883178017 0" rpy="0 0 0"/>
            <mass value="1" />
            <inertia ixx="100" ixy="0" ixz="0" iyy="100" iyz="0" izz="100" />
        </inertial>
        <visual>
            <origin xyz="0 0.5457935883178017 0" rpy="0 0 0"/>
            <geometry>
                <box size="1.6187236653954102 1.0915871766356033 2.141326065631474" />
            </geometry>
            <material name="Blue">
                <color rgba="0 1.0 1.0 1.0"/>
            </material>
        </visual>
        <collision>
            <origin xyz="0 0.5457935883178017 0" rpy="0 0 0"/>
            <geometry>
                <box size="1.6187236653954102 1.0915871766356033 2.141326065631474" />
            </geometry>
        </collision>
    </link>
    <link name="Leg18">
        <inertial>
            <origin xyz="0 0.6450491795067886 0" rpy="0 0 0"/>
            <mass value="1" />
            <inertia ixx="100" ixy="0" ixz="0" iyy="100" iyz="0" izz="100" />
        </inertial>
        <visual>
            <origin xyz="0 0.6450491795067886 0" rpy="0 0 0"/>
            <geometry>
                <box size="2.036089621103427 1.2900983590135773 1.9956965804133815" />
            </geometry>
            <material name="Green">
                <color rgba="0 180.0 0.0 1.0"/>
            </material>
        </visual>
        <collision>
            <origin xyz="0 0.6450491795067886 0" rpy="0 0 0"/>
            <geometry>
                <box size="2.036089621103427 1.2900983590135773 1.9956965804133815" />
            </geometry>
        </collision>
    </link>
    <link name="Leg19">
        <inertial>
            <origin xyz="0.692240256538203 0 0" rpy="0 0 0"/>
            <mass value="1" />
            <inertia ixx="100" ixy="0" ixz="0" iyy="100" iyz="0" izz="100" />
        </inertial>
        <visual>
            <origin xyz="0.692240256538203 0 0" rpy="0 0 0"/>
            <geometry>
                <box size="1.384480513076406 1.092201676835669 2.067639736192615" />
            </geometry>
            <material name="Green">
                <color rgba="0 180.0 0.0 1.0"/>
            </material>
        </visual>
        <collision>
            <origin xyz="0.692240256538203 0 0" rpy="0 0 0"/>
            <geometry>
                <box size="1.384480513076406 1.092201676835669 2.067639736192615" />
            </geometry>
        </collision>
    </link>
    <link name="Leg20">
        <inertial>
            <origin xyz="1.1149759698766266 0 0" rpy="0 0 0"/>
            <mass value="1" />
            <inertia ixx="100" ixy="0" ixz="0" iyy="100" iyz="0" izz="100" />
        </inertial>
        <visual>
            <origin xyz="1.1149759698766266 0 0" rpy="0 0 0"/>
            <geometry>
                <box size="2.2299519397532532 1.2873721464671013 1.3207863115422132" />
            </geometry>
            <material name="Blue">
                <color rgba="0 1.0 1.0 1.0"/>
            </material>
        </visual>
        <collision>
            <origin xyz="1.1149759698766266 0 0" rpy="0 0 0"/>
            <geometry>
                <box size="2.2299519397532532 1.2873721464671013 1.3207863115422132" />
            </geometry>
        </collision>
    </link>
    <link name="Leg21">
        <inertial>
            <origin xyz="0 0 0.571560864817643" rpy="0 0 0"/>
            <mass value="1" />
            <inertia ixx="100" ixy="0" ixz="0" iyy="100" iyz="0" izz="100" />
        </inertial>
        <visual>
            <origin xyz="0 0 0.571560864817643" rpy="0 0 0"/>
            <geometry>
                <box size="2.0799928783183486 1.5717779043772109 1.143121729635286" />
            </geometry>
            <material name="Blue">
                <color rgba="0 1.0 1.0 1.0"/>
            </material>
        </visual>
        <collision>
            <origin xyz="0 0 0.571560864817643" rpy="0 0 0"/>
            <geometry>
                <box size="2.0799928783183486 1.5717779043772109 1.143121729635286" />
            </geometry>
        </collision>
    </link>
    <link name="Leg22">
        <inertial>
            <origin xyz="0 0.8430641112221986 0" rpy="0 0 0"/>
            <mass value="1" />
            <inertia ixx="100" ixy="0" ixz="0" iyy="100" iyz="0" izz="100" />
        </inertial>
        <visual>
            <origin xyz="0 0.8430641112221986 0" rpy="0 0 0"/>
            <geometry>
                <box size="2.4789074507950666 1.6861282224443972 2.5506288940188853" />
            </geometry>
            <material name="Blue">
                <color rgba="0 1.0 1.0 1.0"/>
            </material>
        </visual>
        <collision>
            <origin xyz="0 0.8430641112221986 0" rpy="0 0 0"/>
            <geometry>
                <box size="2.4789074507950666 1.6861282224443972 2.5506288940188853" />
            </geometry>
        </collision>
    </link>
    <link name="Leg23">
        <inertial>
            <origin xyz="0 0 0.5408536160010938" rpy="0 0 0"/>
            <mass value="1" />
            <inertia ixx="100" ixy="0" ixz="0" iyy="100" iyz="0" izz="100" />
        </inertial>
        <visual>
            <origin xyz="0 0 0.5408536160010938" rpy="0 0 0"/>
            <geometry>
                <box size="2.600211996474588 1.994442050363954 1.0817072320021877" />
            </geometry>
            <material name="Green">
                <color rgba="0 180.0 0.0 1.0"/>
            </material>
        </visual>
        <collision>
            <origin xyz="0 0 0.5408536160010938" rpy="0 0 0"/>
            <geometry>
                <box size="2.600211996474588 1.994442050363954 1.0817072320021877" />
            </geometry>
        </collision>
    </link>
    <link name="Leg24">
        <inertial>
            <origin xyz="0 0 0.6816639097162641" rpy="0 0 0"/>
            <mass value="1" />
            <inertia ixx="100" ixy="0" ixz="0" iyy="100" iyz="0" izz="100" />
        </inertial>
        <visual>
            <origin xyz="0 0 0.6816639097162641" rpy="0 0 0"/>
            <geometry>
                <box size="1.8089720833538743 2.9871432420839135 1.3633278194325282" />
            </geometry>
            <material name="Blue">
                <color rgba="0 1.0 1.0 1.0"/>
            </material>
        </visual>
        <collision>
            <origin xyz="0 0 0.6816639097162641" rpy="0 0 0"/>
            <geometry>
                <box size="1.8089720833538743 2.9871432420839135 1.3633278194325282" />
            </geometry>
        </collision>
    </link>
    <link name="Leg25">
        <inertial>
            <origin xyz="0 0 0.917116636571089" rpy="0 0 0"/>
            <mass value="1" />
            <inertia ixx="100" ixy="0" ixz="0" iyy="100" iyz="0" izz="100" />
        </inertial>
        <visual>
            <origin xyz="0 0 0.917116636571089" rpy="0 0 0"/>
            <geometry>
                <box size="1.6146147685894492 1.5410395899101657 1.834233273142178" />
            </geometry>
            <material name="Green">
                <color rgba="0 180.0 0.0 1.0"/>
            </material>
        </visual>
        <collision>
            <origin xyz="0 0 0.917116636571089" rpy="0 0 0"/>
            <geometry>
                <box size="1.6146147685894492 1.5410395899101657 1.834233273142178" />
            </geometry>
        </collision>
    </link>
    <link name="Leg26">
        <inertial>
            <origin xyz="0 1.3037070961512427 0" rpy="0 0 0"/>
            <mass value="1" />
            <inertia ixx="100" ixy="0" ixz="0" iyy="100" iyz="0" izz="100" />
        </inertial>
        <visual>
            <origin xyz="0 1.3037070961512427 0" rpy="0 0 0"/>
            <geometry>
                <box size="2.2084746895788294 2.6074141923024854 1.770091440799497" />
            </geometry>
            <material name="Blue">
                <color rgba="0 1.0 1.0 1.0"/>
            </material>
        </visual>
        <collision>
            <origin xyz="0 1.3037070961512427 0" rpy="0 0 0"/>
            <geometry>
                <box size="2.2084746895788294 2.6074141923024854 1.770091440799497" />
            </geometry>
        </collision>
    </link>
    <link name="Leg27">
        <inertial>
            <origin xyz="0 0 0.5629585266631606" rpy="0 0 0"/>
            <mass value="1" />
            <inertia ixx="100" ixy="0" ixz="0" iyy="100" iyz="0" izz="100" />
        </inertial>
        <visual>
            <origin xyz="0 0 0.5629585266631606" rpy="0 0 0"/>
            <geometry>
                <box size="1.4502663065678159 2.692903047873231 1.1259170533263212" />
            </geometry>
            <material name="Green">
                <color rgba="0 180.0 0.0 1.0"/>
            </material>
        </visual>
        <collision>
            <origin xyz="0 0 0.5629585266631606" rpy="0 0 0"/>
            <geometry>
                <box size="1.4502663065678159 2.692903047873231 1.1259170533263212" />
            </geometry>
        </collision>
    </link>
    <joint name="Torso_Leg1" type="revolute">
       <parent link="Torso"/>
       <child  link="Leg1"/>
       <origin rpy="0 0 0" xyz="0 0.703135362132384 0.7596492924036515" />
     <axis xyz="1 0 0"/>
       <limit effort="0.0" lower="-3.14159" upper="3.14159" velocity="0.0"/>
    </joint>
    <joint name="Leg1_Leg2" type="revolute">
       <parent link="Leg1"/>
       <child  link="Leg2"/>
       <origin rpy="0 0 0" xyz="0 0 2.1977735880024487" />
     <axis xyz="1 0 0"/>
       <limit effort="0.0" lower="-3.14159" upper="3.14159" velocity="0.0"/>
    </joint>
    <joint name="Leg1_Leg3" type="revolute">
       <parent link="Leg1"/>
       <child  link="Leg3"/>
       <origin rpy="0 0 0" xyz="0 0.5904098142473794 2.1977735880024487" />
     <axis xyz="1 0 0"/>
       <limit effort="0.0" lower="-3.14159" upper="3.14159" velocity="0.0"/>
    </joint>
    <joint name="Leg3_Leg4" type="revolute">
       <parent link="Leg3"/>
       <child  link="Leg4"/>
       <origin rpy="0 0 0" xyz="0 0 2.1086135961552595" />
     <axis xyz="1 0 0"/>
       <limit effort="0.0" lower="-3.14159" upper="3.14159" velocity="0.0"/>
    </joint>
    <joint name="Leg3_Leg5" type="revolute">
       <parent link="Leg3"/>
       <child  link="Leg5"/>
       <origin rpy="0 0 0" xyz="0 1.4693752827699487 2.1086135961552595" />
     <axis xyz="1 0 0"/>
       <limit effort="0.0" lower="-3.14159" upper="3.14159" velocity="0.0"/>
    </joint>
    <joint name="Leg2_Leg6" type="revolute">
       <parent link="Leg2"/>
       <child  link="Leg6"/>
       <origin rpy="0 0 0" xyz="0 2.5325518688941697 0" />
     <axis xyz="1 0 0"/>
       <limit effort="0.0" lower="-3.14159" upper="3.14159" velocity="0.0"/>
    </joint>
    <joint name="Leg6_Leg7" type="revolute">
       <parent link="Leg6"/>
       <child  link="Leg7"/>
       <origin rpy="0 0 0" xyz="0 2.427301579235336 0" />
     <axis xyz="1 0 0"/>
       <limit effort="0.0" lower="-3.14159" upper="3.14159" velocity="0.0"/>
    </joint>
    <joint name="Leg5_Leg8" type="revolute">
       <parent link="Leg5"/>
       <child  link="Leg8"/>
       <origin rpy="0 0 0" xyz="0 1.4755293385116441 0" />
     <axis xyz="1 0 0"/>
       <limit effort="0.0" lower="-3.14159" upper="3.14159" velocity="0.0"/>
    </joint>
    <joint name="Leg4_Leg9" type="revolute">
       <parent link="Leg4"/>
       <child  link="Leg9"/>
       <origin rpy="0 0 0" xyz="1.4805780661910037 0.5525556711232065 0" />
     <axis xyz="1 0 0"/>
       <limit effort="0.0" lower="-3.14159" upper="3.14159" velocity="0.0"/>
    </joint>
    <joint name="Leg7_Leg10" type="revolute">
       <parent link="Leg7"/>
       <child  link="Leg10"/>
       <origin rpy="0 0 0" xyz="0 1.4869017747881712 0" />
     <axis xyz="1 0 0"/>
       <limit effort="0.0" lower="-3.14159" upper="3.14159" velocity="0.0"/>
    </joint>
    <joint name="Leg8_Leg11" type="revolute">
       <parent link="Leg8"/>
       <child  link="Leg11"/>
       <origin rpy="0 0 0" xyz="0.6869443722897786 0.9646402277173257 0" />
     <axis xyz="1 0 0"/>
       <limit effort="0.0" lower="-3.14159" upper="3.14159" velocity="0.0"/>
    </joint>
    <joint name="Leg11_Leg12" type="revolute">
       <parent link="Leg11"/>
       <child  link="Leg12"/>
       <origin rpy="0 0 0" xyz="0 2.9610941920984155 0" />
     <axis xyz="1 0 0"/>
       <limit effort="0.0" lower="-3.14159" upper="3.14159" velocity="0.0"/>
    </joint>
    <joint name="Leg9_Leg13" type="revolute">
       <parent link="Leg9"/>
       <child  link="Leg13"/>
       <origin rpy="0 0 0" xyz="1.320365980873342 0.5479938503416913 0" />
     <axis xyz="1 0 0"/>
       <limit effort="0.0" lower="-3.14159" upper="3.14159" velocity="0.0"/>
    </joint>
    <joint name="Leg13_Leg14" type="revolute">
       <parent link="Leg13"/>
       <child  link="Leg14"/>
       <origin rpy="0 0 0" xyz="0 0 2.3828810699350753" />
     <axis xyz="1 0 0"/>
       <limit effort="0.0" lower="-3.14159" upper="3.14159" velocity="0.0"/>
    </joint>
    <joint name="Leg3_Leg15" type="revolute">
       <parent link="Leg3"/>
       <child  link="Leg15"/>
       <origin rpy="0 0 0" xyz="0.9609802205266856 1.4693752827699487 2.1086135961552595" />
     <axis xyz="1 0 0"/>
       <limit effort="0.0" lower="-3.14159" upper="3.14159" velocity="0.0"/>
    </joint>
    <joint name="Leg12_Leg16" type="revolute">
       <parent link="Leg12"/>
       <child  link="Leg16"/>
       <origin rpy="0 0 0" xyz="1.3899933213691678 1.258471243373024 0" />
     <axis xyz="1 0 0"/>
       <limit effort="0.0" lower="-3.14159" upper="3.14159" velocity="0.0"/>
    </joint>
    <joint name="Leg10_Leg17" type="revolute">
       <parent link="Leg10"/>
       <child  link="Leg17"/>
       <origin rpy="0 0 0" xyz="0 1.5263845441843464 0" />
     <axis xyz="1 0 0"/>
       <limit effort="0.0" lower="-3.14159" upper="3.14159" velocity="0.0"/>
    </joint>
    <joint name="Leg17_Leg18" type="revolute">
       <parent link="Leg17"/>
       <child  link="Leg18"/>
       <origin rpy="0 0 0" xyz="0 1.2900983590135773 0" />
     <axis xyz="1 0 0"/>
       <limit effort="0.0" lower="-3.14159" upper="3.14159" velocity="0.0"/>
    </joint>
    <joint name="Leg16_Leg19" type="revolute">
       <parent link="Leg16"/>
       <child  link="Leg19"/>
       <origin rpy="0 0 0" xyz="0.8093618326977051 0.5457935883178017 0" />
     <axis xyz="1 0 0"/>
       <limit effort="0.0" lower="-3.14159" upper="3.14159" velocity="0.0"/>
    </joint>
    <joint name="Leg2_Leg20" type="revolute">
       <parent link="Leg2"/>
       <child  link="Leg20"/>
       <origin rpy="0 0 0" xyz="1.3285345203675833 2.5325518688941697 0" />
     <axis xyz="1 0 0"/>
       <limit effort="0.0" lower="-3.14159" upper="3.14159" velocity="0.0"/>
    </joint>
    <joint name="Leg7_Leg21" type="revolute">
       <parent link="Leg7"/>
       <child  link="Leg21"/>
       <origin rpy="0 0 0" xyz="0 1.4869017747881712 0.9085896964003769" />
     <axis xyz="1 0 0"/>
       <limit effort="0.0" lower="-3.14159" upper="3.14159" velocity="0.0"/>
    </joint>
    <joint name="Leg15_Leg22" type="revolute">
       <parent link="Leg15"/>
       <child  link="Leg22"/>
       <origin rpy="0 0 0" xyz="0 1.7568087824058154 0" />
     <axis xyz="1 0 0"/>
       <limit effort="0.0" lower="-3.14159" upper="3.14159" velocity="0.0"/>
    </joint>
    <joint name="Leg14_Leg23" type="revolute">
       <parent link="Leg14"/>
       <child  link="Leg23"/>
       <origin rpy="0 0 0" xyz="0.65751309754393 0 1.2827520502559004" />
     <axis xyz="1 0 0"/>
       <limit effort="0.0" lower="-3.14159" upper="3.14159" velocity="0.0"/>
    </joint>
    <joint name="Leg23_Leg24" type="revolute">
       <parent link="Leg23"/>
       <child  link="Leg24"/>
       <origin rpy="0 0 0" xyz="0 0 1.3633278194325282" />
     <axis xyz="1 0 0"/>
       <limit effort="0.0" lower="-3.14159" upper="3.14159" velocity="0.0"/>
    </joint>
    <joint name="Leg15_Leg25" type="revolute">
       <parent link="Leg15"/>
       <child  link="Leg25"/>
       <origin rpy="0 0 0" xyz="0 1.7568087824058154 1.0327848296196307" />
     <axis xyz="1 0 0"/>
       <limit effort="0.0" lower="-3.14159" upper="3.14159" velocity="0.0"/>
    </joint>
    <joint name="Leg24_Leg26" type="revolute">
       <parent link="Leg24"/>
       <child  link="Leg26"/>
       <origin rpy="0 0 0" xyz="0 0.7705197949550828 0.917116636571089" />
     <axis xyz="1 0 0"/>
       <limit effort="0.0" lower="-3.14159" upper="3.14159" velocity="0.0"/>
    </joint>
    <joint name="Leg25_Leg27" type="revolute">
       <parent link="Leg25"/>
       <child  link="Leg27"/>
       <origin rpy="0 0 0" xyz="0 1.3037070961512427 0.8850457203997485" />
     <axis xyz="1 0 0"/>
       <limit effort="0.0" lower="-3.14159" upper="3.14159" velocity="0.0"/>
    </joint>
</robot>