<robot name = "robot">
    <link name="Torso">
        <inertial>
            <origin xyz="0 0 1.191905851077252" rpy="0 0 0"/>
            <mass value="1" />
            <inertia ixx="100" ixy="0" ixz="0" iyy="100" iyz="0" izz="100" />
        </inertial>
        <visual>
            <origin xyz="0 0 1.191905851077252" rpy="0 0 0"/>
            <geometry>
                <box size="1.544918884154025 2.4754568355947457 2.383811702154504" />
            </geometry>
            <material name="Green">
                <color rgba="0 180.0 0.0 1.0"/>
            </material>
        </visual>
        <collision>
            <origin xyz="0 0 1.191905851077252" rpy="0 0 0"/>
            <geometry>
                <box size="1.544918884154025 2.4754568355947457 2.383811702154504" />
            </geometry>
        </collision>
    </link>
    <link name="Leg1">
        <inertial>
            <origin xyz="0 1.4707320282834573 0" rpy="0 0 0"/>
            <mass value="1" />
            <inertia ixx="100" ixy="0" ixz="0" iyy="100" iyz="0" izz="100" />
        </inertial>
        <visual>
            <origin xyz="0 1.4707320282834573 0" rpy="0 0 0"/>
            <geometry>
                <box size="1.5293757015972451 2.9414640565669146 2.5964150247167748" />
            </geometry>
            <material name="Blue">
                <color rgba="0 1.0 1.0 1.0"/>
            </material>
        </visual>
        <collision>
            <origin xyz="0 1.4707320282834573 0" rpy="0 0 0"/>
            <geometry>
                <box size="1.5293757015972451 2.9414640565669146 2.5964150247167748" />
            </geometry>
        </collision>
    </link>
    <link name="Leg2">
        <inertial>
            <origin xyz="0 0 0.8586909648983808" rpy="0 0 0"/>
            <mass value="1" />
            <inertia ixx="100" ixy="0" ixz="0" iyy="100" iyz="0" izz="100" />
        </inertial>
        <visual>
            <origin xyz="0 0 0.8586909648983808" rpy="0 0 0"/>
            <geometry>
                <box size="2.988030667373967 2.0088932619995257 1.7173819297967616" />
            </geometry>
            <material name="Green">
                <color rgba="0 180.0 0.0 1.0"/>
            </material>
        </visual>
        <collision>
            <origin xyz="0 0 0.8586909648983808" rpy="0 0 0"/>
            <geometry>
                <box size="2.988030667373967 2.0088932619995257 1.7173819297967616" />
            </geometry>
        </collision>
    </link>
    <link name="Leg3">
        <inertial>
            <origin xyz="0 0 0.7714059186618992" rpy="0 0 0"/>
            <mass value="1" />
            <inertia ixx="100" ixy="0" ixz="0" iyy="100" iyz="0" izz="100" />
        </inertial>
        <visual>
            <origin xyz="0 0 0.7714059186618992" rpy="0 0 0"/>
            <geometry>
                <box size="1.219379691436976 1.4576560888988077 1.5428118373237985" />
            </geometry>
            <material name="Blue">
                <color rgba="0 1.0 1.0 1.0"/>
            </material>
        </visual>
        <collision>
            <origin xyz="0 0 0.7714059186618992" rpy="0 0 0"/>
            <geometry>
                <box size="1.219379691436976 1.4576560888988077 1.5428118373237985" />
            </geometry>
        </collision>
    </link>
    <link name="Leg4">
        <inertial>
            <origin xyz="0 0 0.6792705722293118" rpy="0 0 0"/>
            <mass value="1" />
            <inertia ixx="100" ixy="0" ixz="0" iyy="100" iyz="0" izz="100" />
        </inertial>
        <visual>
            <origin xyz="0 0 0.6792705722293118" rpy="0 0 0"/>
            <geometry>
                <box size="1.4663263142257819 1.0193961093997297 1.3585411444586235" />
            </geometry>
            <material name="Blue">
                <color rgba="0 1.0 1.0 1.0"/>
            </material>
        </visual>
        <collision>
            <origin xyz="0 0 0.6792705722293118" rpy="0 0 0"/>
            <geometry>
                <box size="1.4663263142257819 1.0193961093997297 1.3585411444586235" />
            </geometry>
        </collision>
    </link>
    <link name="Leg5">
        <inertial>
            <origin xyz="1.4653597226993031 0 0" rpy="0 0 0"/>
            <mass value="1" />
            <inertia ixx="100" ixy="0" ixz="0" iyy="100" iyz="0" izz="100" />
        </inertial>
        <visual>
            <origin xyz="1.4653597226993031 0 0" rpy="0 0 0"/>
            <geometry>
                <box size="2.9307194453986063 1.7001051359067842 1.508290242642587" />
            </geometry>
            <material name="Blue">
                <color rgba="0 1.0 1.0 1.0"/>
            </material>
        </visual>
        <collision>
            <origin xyz="1.4653597226993031 0 0" rpy="0 0 0"/>
            <geometry>
                <box size="2.9307194453986063 1.7001051359067842 1.508290242642587" />
            </geometry>
        </collision>
    </link>
    <link name="Leg6">
        <inertial>
            <origin xyz="0.6458671692469823 0 0" rpy="0 0 0"/>
            <mass value="1" />
            <inertia ixx="100" ixy="0" ixz="0" iyy="100" iyz="0" izz="100" />
        </inertial>
        <visual>
            <origin xyz="0.6458671692469823 0 0" rpy="0 0 0"/>
            <geometry>
                <box size="1.2917343384939646 1.972978599448023 1.5986394824218724" />
            </geometry>
            <material name="Green">
                <color rgba="0 180.0 0.0 1.0"/>
            </material>
        </visual>
        <collision>
            <origin xyz="0.6458671692469823 0 0" rpy="0 0 0"/>
            <geometry>
                <box size="1.2917343384939646 1.972978599448023 1.5986394824218724" />
            </geometry>
        </collision>
    </link>
    <link name="Leg7">
        <inertial>
            <origin xyz="0 0 1.4314773390903248" rpy="0 0 0"/>
            <mass value="1" />
            <inertia ixx="100" ixy="0" ixz="0" iyy="100" iyz="0" izz="100" />
        </inertial>
        <visual>
            <origin xyz="0 0 1.4314773390903248" rpy="0 0 0"/>
            <geometry>
                <box size="2.128728285652818 1.3029858076028118 2.8629546781806496" />
            </geometry>
            <material name="Blue">
                <color rgba="0 1.0 1.0 1.0"/>
            </material>
        </visual>
        <collision>
            <origin xyz="0 0 1.4314773390903248" rpy="0 0 0"/>
            <geometry>
                <box size="2.128728285652818 1.3029858076028118 2.8629546781806496" />
            </geometry>
        </collision>
    </link>
    <link name="Leg8">
        <inertial>
            <origin xyz="0 0.8048004644304767 0" rpy="0 0 0"/>
            <mass value="1" />
            <inertia ixx="100" ixy="0" ixz="0" iyy="100" iyz="0" izz="100" />
        </inertial>
        <visual>
            <origin xyz="0 0.8048004644304767 0" rpy="0 0 0"/>
            <geometry>
                <box size="2.932285018297894 1.6096009288609534 1.2432848617925698" />
            </geometry>
            <material name="Green">
                <color rgba="0 180.0 0.0 1.0"/>
            </material>
        </visual>
        <collision>
            <origin xyz="0 0.8048004644304767 0" rpy="0 0 0"/>
            <geometry>
                <box size="2.932285018297894 1.6096009288609534 1.2432848617925698" />
            </geometry>
        </collision>
    </link>
    <link name="Leg9">
        <inertial>
            <origin xyz="1.2207931546571502 0 0" rpy="0 0 0"/>
            <mass value="1" />
            <inertia ixx="100" ixy="0" ixz="0" iyy="100" iyz="0" izz="100" />
        </inertial>
        <visual>
            <origin xyz="1.2207931546571502 0 0" rpy="0 0 0"/>
            <geometry>
                <box size="2.4415863093143004 1.757249645882564 1.7952084571539249" />
            </geometry>
            <material name="Green">
                <color rgba="0 180.0 0.0 1.0"/>
            </material>
        </visual>
        <collision>
            <origin xyz="1.2207931546571502 0 0" rpy="0 0 0"/>
            <geometry>
                <box size="2.4415863093143004 1.757249645882564 1.7952084571539249" />
            </geometry>
        </collision>
    </link>
    <link name="Leg10">
        <inertial>
            <origin xyz="0 0.6786082967352834 0" rpy="0 0 0"/>
            <mass value="1" />
            <inertia ixx="100" ixy="0" ixz="0" iyy="100" iyz="0" izz="100" />
        </inertial>
        <visual>
            <origin xyz="0 0.6786082967352834 0" rpy="0 0 0"/>
            <geometry>
                <box size="2.9731905927258673 1.357216593470567 2.4321880336557724" />
            </geometry>
            <material name="Blue">
                <color rgba="0 1.0 1.0 1.0"/>
            </material>
        </visual>
        <collision>
            <origin xyz="0 0.6786082967352834 0" rpy="0 0 0"/>
            <geometry>
                <box size="2.9731905927258673 1.357216593470567 2.4321880336557724" />
            </geometry>
        </collision>
    </link>
    <link name="Leg11">
        <inertial>
            <origin xyz="1.1603457318628225 0 0" rpy="0 0 0"/>
            <mass value="1" />
            <inertia ixx="100" ixy="0" ixz="0" iyy="100" iyz="0" izz="100" />
        </inertial>
        <visual>
            <origin xyz="1.1603457318628225 0 0" rpy="0 0 0"/>
            <geometry>
                <box size="2.320691463725645 2.0042506538875897 1.6044535615903406" />
            </geometry>
            <material name="Green">
                <color rgba="0 180.0 0.0 1.0"/>
            </material>
        </visual>
        <collision>
            <origin xyz="1.1603457318628225 0 0" rpy="0 0 0"/>
            <geometry>
                <box size="2.320691463725645 2.0042506538875897 1.6044535615903406" />
            </geometry>
        </collision>
    </link>
    <link name="Leg12">
        <inertial>
            <origin xyz="0 0 0.8895623464001027" rpy="0 0 0"/>
            <mass value="1" />
            <inertia ixx="100" ixy="0" ixz="0" iyy="100" iyz="0" izz="100" />
        </inertial>
        <visual>
            <origin xyz="0 0 0.8895623464001027" rpy="0 0 0"/>
            <geometry>
                <box size="1.466892901932193 1.269962215668997 1.7791246928002054" />
            </geometry>
            <material name="Green">
                <color rgba="0 180.0 0.0 1.0"/>
            </material>
        </visual>
        <collision>
            <origin xyz="0 0 0.8895623464001027" rpy="0 0 0"/>
            <geometry>
                <box size="1.466892901932193 1.269962215668997 1.7791246928002054" />
            </geometry>
        </collision>
    </link>
    <link name="Leg13">
        <inertial>
            <origin xyz="0 0 1.4340046316301063" rpy="0 0 0"/>
            <mass value="1" />
            <inertia ixx="100" ixy="0" ixz="0" iyy="100" iyz="0" izz="100" />
        </inertial>
        <visual>
            <origin xyz="0 0 1.4340046316301063" rpy="0 0 0"/>
            <geometry>
                <box size="1.8305393920822521 1.1976544992129046 2.8680092632602125" />
            </geometry>
            <material name="Green">
                <color rgba="0 180.0 0.0 1.0"/>
            </material>
        </visual>
        <collision>
            <origin xyz="0 0 1.4340046316301063" rpy="0 0 0"/>
            <geometry>
                <box size="1.8305393920822521 1.1976544992129046 2.8680092632602125" />
            </geometry>
        </collision>
    </link>
    <link name="Leg14">
        <inertial>
            <origin xyz="0 0.891486974434288 0" rpy="0 0 0"/>
            <mass value="1" />
            <inertia ixx="100" ixy="0" ixz="0" iyy="100" iyz="0" izz="100" />
        </inertial>
        <visual>
            <origin xyz="0 0.891486974434288 0" rpy="0 0 0"/>
            <geometry>
                <box size="1.3179540071773093 1.782973948868576 1.7671380227200273" />
            </geometry>
            <material name="Blue">
                <color rgba="0 1.0 1.0 1.0"/>
            </material>
        </visual>
        <collision>
            <origin xyz="0 0.891486974434288 0" rpy="0 0 0"/>
            <geometry>
                <box size="1.3179540071773093 1.782973948868576 1.7671380227200273" />
            </geometry>
        </collision>
    </link>
    <link name="Leg15">
        <inertial>
            <origin xyz="0.9657392665337496 0 0" rpy="0 0 0"/>
            <mass value="1" />
            <inertia ixx="100" ixy="0" ixz="0" iyy="100" iyz="0" izz="100" />
        </inertial>
        <visual>
            <origin xyz="0.9657392665337496 0 0" rpy="0 0 0"/>
            <geometry>
                <box size="1.9314785330674993 2.808158186817177 1.042652417245422" />
            </geometry>
            <material name="Blue">
                <color rgba="0 1.0 1.0 1.0"/>
            </material>
        </visual>
        <collision>
            <origin xyz="0.9657392665337496 0 0" rpy="0 0 0"/>
            <geometry>
                <box size="1.9314785330674993 2.808158186817177 1.042652417245422" />
            </geometry>
        </collision>
    </link>
    <link name="Leg16">
        <inertial>
            <origin xyz="0 1.4258958057857893 0" rpy="0 0 0"/>
            <mass value="1" />
            <inertia ixx="100" ixy="0" ixz="0" iyy="100" iyz="0" izz="100" />
        </inertial>
        <visual>
            <origin xyz="0 1.4258958057857893 0" rpy="0 0 0"/>
            <geometry>
                <box size="2.515133747956779 2.8517916115715787 2.9737031057902636" />
            </geometry>
            <material name="Green">
                <color rgba="0 180.0 0.0 1.0"/>
            </material>
        </visual>
        <collision>
            <origin xyz="0 1.4258958057857893 0" rpy="0 0 0"/>
            <geometry>
                <box size="2.515133747956779 2.8517916115715787 2.9737031057902636" />
            </geometry>
        </collision>
    </link>
    <link name="Leg17">
        <inertial>
            <origin xyz="0 1.4721861959033724 0" rpy="0 0 0"/>
            <mass value="1" />
            <inertia ixx="100" ixy="0" ixz="0" iyy="100" iyz="0" izz="100" />
        </inertial>
        <visual>
            <origin xyz="0 1.4721861959033724 0" rpy="0 0 0"/>
            <geometry>
                <box size="1.605714813147078 2.944372391806745 2.914468339966593" />
            </geometry>
            <material name="Green">
                <color rgba="0 180.0 0.0 1.0"/>
            </material>
        </visual>
        <collision>
            <origin xyz="0 1.4721861959033724 0" rpy="0 0 0"/>
            <geometry>
                <box size="1.605714813147078 2.944372391806745 2.914468339966593" />
            </geometry>
        </collision>
    </link>
    <link name="Leg18">
        <inertial>
            <origin xyz="0 0 1.478952832865458" rpy="0 0 0"/>
            <mass value="1" />
            <inertia ixx="100" ixy="0" ixz="0" iyy="100" iyz="0" izz="100" />
        </inertial>
        <visual>
            <origin xyz="0 0 1.478952832865458" rpy="0 0 0"/>
            <geometry>
                <box size="1.9570430812754254 2.933107165001379 2.957905665730916" />
            </geometry>
            <material name="Green">
                <color rgba="0 180.0 0.0 1.0"/>
            </material>
        </visual>
        <collision>
            <origin xyz="0 0 1.478952832865458" rpy="0 0 0"/>
            <geometry>
                <box size="1.9570430812754254 2.933107165001379 2.957905665730916" />
            </geometry>
        </collision>
    </link>
    <link name="Leg19">
        <inertial>
            <origin xyz="0 0.8086093648615733 0" rpy="0 0 0"/>
            <mass value="1" />
            <inertia ixx="100" ixy="0" ixz="0" iyy="100" iyz="0" izz="100" />
        </inertial>
        <visual>
            <origin xyz="0 0.8086093648615733 0" rpy="0 0 0"/>
            <geometry>
                <box size="1.2934312605016767 1.6172187297231466 2.1086108591505988" />
            </geometry>
            <material name="Green">
                <color rgba="0 180.0 0.0 1.0"/>
            </material>
        </visual>
        <collision>
            <origin xyz="0 0.8086093648615733 0" rpy="0 0 0"/>
            <geometry>
                <box size="1.2934312605016767 1.6172187297231466 2.1086108591505988" />
            </geometry>
        </collision>
    </link>
    <link name="Leg20">
        <inertial>
            <origin xyz="0 1.4550495260471772 0" rpy="0 0 0"/>
            <mass value="1" />
            <inertia ixx="100" ixy="0" ixz="0" iyy="100" iyz="0" izz="100" />
        </inertial>
        <visual>
            <origin xyz="0 1.4550495260471772 0" rpy="0 0 0"/>
            <geometry>
                <box size="1.696114774191684 2.9100990520943544 2.9946006961691696" />
            </geometry>
            <material name="Green">
                <color rgba="0 180.0 0.0 1.0"/>
            </material>
        </visual>
        <collision>
            <origin xyz="0 1.4550495260471772 0" rpy="0 0 0"/>
            <geometry>
                <box size="1.696114774191684 2.9100990520943544 2.9946006961691696" />
            </geometry>
        </collision>
    </link>
    <link name="Leg21">
        <inertial>
            <origin xyz="0 0 1.1233678731069672" rpy="0 0 0"/>
            <mass value="1" />
            <inertia ixx="100" ixy="0" ixz="0" iyy="100" iyz="0" izz="100" />
        </inertial>
        <visual>
            <origin xyz="0 0 1.1233678731069672" rpy="0 0 0"/>
            <geometry>
                <box size="1.982668965934039 2.551974710056774 2.2467357462139343" />
            </geometry>
            <material name="Blue">
                <color rgba="0 1.0 1.0 1.0"/>
            </material>
        </visual>
        <collision>
            <origin xyz="0 0 1.1233678731069672" rpy="0 0 0"/>
            <geometry>
                <box size="1.982668965934039 2.551974710056774 2.2467357462139343" />
            </geometry>
        </collision>
    </link>
    <link name="Leg22">
        <inertial>
            <origin xyz="0 0.9155302526829947 0" rpy="0 0 0"/>
            <mass value="1" />
            <inertia ixx="100" ixy="0" ixz="0" iyy="100" iyz="0" izz="100" />
        </inertial>
        <visual>
            <origin xyz="0 0.9155302526829947 0" rpy="0 0 0"/>
            <geometry>
                <box size="1.7117307802494695 1.8310605053659894 1.0288239294704784" />
            </geometry>
            <material name="Green">
                <color rgba="0 180.0 0.0 1.0"/>
            </material>
        </visual>
        <collision>
            <origin xyz="0 0.9155302526829947 0" rpy="0 0 0"/>
            <geometry>
                <box size="1.7117307802494695 1.8310605053659894 1.0288239294704784" />
            </geometry>
        </collision>
    </link>
    <link name="Leg23">
        <inertial>
            <origin xyz="0 0.7898361143048324 0" rpy="0 0 0"/>
            <mass value="1" />
            <inertia ixx="100" ixy="0" ixz="0" iyy="100" iyz="0" izz="100" />
        </inertial>
        <visual>
            <origin xyz="0 0.7898361143048324 0" rpy="0 0 0"/>
            <geometry>
                <box size="1.0446837784294873 1.5796722286096647 2.03186229051984" />
            </geometry>
            <material name="Blue">
                <color rgba="0 1.0 1.0 1.0"/>
            </material>
        </visual>
        <collision>
            <origin xyz="0 0.7898361143048324 0" rpy="0 0 0"/>
            <geometry>
                <box size="1.0446837784294873 1.5796722286096647 2.03186229051984" />
            </geometry>
        </collision>
    </link>
    <link name="Leg24">
        <inertial>
            <origin xyz="1.3369190826885804 0 0" rpy="0 0 0"/>
            <mass value="1" />
            <inertia ixx="100" ixy="0" ixz="0" iyy="100" iyz="0" izz="100" />
        </inertial>
        <visual>
            <origin xyz="1.3369190826885804 0 0" rpy="0 0 0"/>
            <geometry>
                <box size="2.673838165377161 1.5412565012579373 1.368128793750324" />
            </geometry>
            <material name="Blue">
                <color rgba="0 1.0 1.0 1.0"/>
            </material>
        </visual>
        <collision>
            <origin xyz="1.3369190826885804 0 0" rpy="0 0 0"/>
            <geometry>
                <box size="2.673838165377161 1.5412565012579373 1.368128793750324" />
            </geometry>
        </collision>
    </link>
    <link name="Leg25">
        <inertial>
            <origin xyz="0 0.5907931698630011 0" rpy="0 0 0"/>
            <mass value="1" />
            <inertia ixx="100" ixy="0" ixz="0" iyy="100" iyz="0" izz="100" />
        </inertial>
        <visual>
            <origin xyz="0 0.5907931698630011 0" rpy="0 0 0"/>
            <geometry>
                <box size="2.675500625336164 1.1815863397260022 1.7601285820386434" />
            </geometry>
            <material name="Blue">
                <color rgba="0 1.0 1.0 1.0"/>
            </material>
        </visual>
        <collision>
            <origin xyz="0 0.5907931698630011 0" rpy="0 0 0"/>
            <geometry>
                <box size="2.675500625336164 1.1815863397260022 1.7601285820386434" />
            </geometry>
        </collision>
    </link>
    <link name="Leg26">
        <inertial>
            <origin xyz="0 1.0961243023137923 0" rpy="0 0 0"/>
            <mass value="1" />
            <inertia ixx="100" ixy="0" ixz="0" iyy="100" iyz="0" izz="100" />
        </inertial>
        <visual>
            <origin xyz="0 1.0961243023137923 0" rpy="0 0 0"/>
            <geometry>
                <box size="1.4430993020160228 2.1922486046275846 1.0689502684642278" />
            </geometry>
            <material name="Blue">
                <color rgba="0 1.0 1.0 1.0"/>
            </material>
        </visual>
        <collision>
            <origin xyz="0 1.0961243023137923 0" rpy="0 0 0"/>
            <geometry>
                <box size="1.4430993020160228 2.1922486046275846 1.0689502684642278" />
            </geometry>
        </collision>
    </link>
    <link name="Leg27">
        <inertial>
            <origin xyz="0 1.0693345874988616 0" rpy="0 0 0"/>
            <mass value="1" />
            <inertia ixx="100" ixy="0" ixz="0" iyy="100" iyz="0" izz="100" />
        </inertial>
        <visual>
            <origin xyz="0 1.0693345874988616 0" rpy="0 0 0"/>
            <geometry>
                <box size="1.5407278197701482 2.138669174997723 1.563429403760532" />
            </geometry>
            <material name="Blue">
                <color rgba="0 1.0 1.0 1.0"/>
            </material>
        </visual>
        <collision>
            <origin xyz="0 1.0693345874988616 0" rpy="0 0 0"/>
            <geometry>
                <box size="1.5407278197701482 2.138669174997723 1.563429403760532" />
            </geometry>
        </collision>
    </link>
    <joint name="Torso_Leg1" type="revolute">
       <parent link="Torso"/>
       <child  link="Leg1"/>
       <origin rpy="0 0 0" xyz="0 1.2377284177973729 1.191905851077252" />
     <axis xyz="1 0 0"/>
       <limit effort="0.0" lower="-3.14159" upper="3.14159" velocity="0.0"/>
    </joint>
    <joint name="Leg1_Leg2" type="revolute">
       <parent link="Leg1"/>
       <child  link="Leg2"/>
       <origin rpy="0 0 0" xyz="0 0 1.7173819297967616" />
     <axis xyz="1 0 0"/>
       <limit effort="0.0" lower="-3.14159" upper="3.14159" velocity="0.0"/>
    </joint>
    <joint name="Torso_Leg3" type="revolute">
       <parent link="Torso"/>
       <child  link="Leg3"/>
       <origin rpy="0 0 0" xyz="0 1.4707320282834573 1.2982075123583874" />
     <axis xyz="1 0 0"/>
       <limit effort="0.0" lower="-3.14159" upper="3.14159" velocity="0.0"/>
    </joint>
    <joint name="Leg2_Leg4" type="revolute">
       <parent link="Leg2"/>
       <child  link="Leg4"/>
       <origin rpy="0 0 0" xyz="0 0 1.5428118373237985" />
     <axis xyz="1 0 0"/>
       <limit effort="0.0" lower="-3.14159" upper="3.14159" velocity="0.0"/>
    </joint>
    <joint name="Leg2_Leg5" type="revolute">
       <parent link="Leg2"/>
       <child  link="Leg5"/>
       <origin rpy="0 0 0" xyz="0.609689845718488 0 1.5428118373237985" />
     <axis xyz="1 0 0"/>
       <limit effort="0.0" lower="-3.14159" upper="3.14159" velocity="0.0"/>
    </joint>
    <joint name="Leg3_Leg6" type="revolute">
       <parent link="Leg3"/>
       <child  link="Leg6"/>
       <origin rpy="0 0 0" xyz="0.7331631571128909 0 0.6792705722293118" />
     <axis xyz="1 0 0"/>
       <limit effort="0.0" lower="-3.14159" upper="3.14159" velocity="0.0"/>
    </joint>
    <joint name="Leg4_Leg7" type="revolute">
       <parent link="Leg4"/>
       <child  link="Leg7"/>
       <origin rpy="0 0 0" xyz="1.4653597226993031 0 0.7541451213212935" />
     <axis xyz="1 0 0"/>
       <limit effort="0.0" lower="-3.14159" upper="3.14159" velocity="0.0"/>
    </joint>
    <joint name="Leg5_Leg8" type="revolute">
       <parent link="Leg5"/>
       <child  link="Leg8"/>
       <origin rpy="0 0 0" xyz="0.6458671692469823 0.9864892997240114 0" />
     <axis xyz="1 0 0"/>
       <limit effort="0.0" lower="-3.14159" upper="3.14159" velocity="0.0"/>
    </joint>
    <joint name="Leg1_Leg9" type="revolute">
       <parent link="Leg1"/>
       <child  link="Leg9"/>
       <origin rpy="0 0 0" xyz="1.4940153336869835 0 1.7173819297967616" />
     <axis xyz="1 0 0"/>
       <limit effort="0.0" lower="-3.14159" upper="3.14159" velocity="0.0"/>
    </joint>
    <joint name="Leg9_Leg10" type="revolute">
       <parent link="Leg9"/>
       <child  link="Leg10"/>
       <origin rpy="0 0 0" xyz="0 1.357216593470567 0" />
     <axis xyz="1 0 0"/>
       <limit effort="0.0" lower="-3.14159" upper="3.14159" velocity="0.0"/>
    </joint>
    <joint name="Leg7_Leg11" type="revolute">
       <parent link="Leg7"/>
       <child  link="Leg11"/>
       <origin rpy="0 0 0" xyz="1.466142509148947 0.8048004644304767 0" />
     <axis xyz="1 0 0"/>
       <limit effort="0.0" lower="-3.14159" upper="3.14159" velocity="0.0"/>
    </joint>
    <joint name="Leg3_Leg12" type="revolute">
       <parent link="Leg3"/>
       <child  link="Leg12"/>
       <origin rpy="0 0 0" xyz="0.7331631571128909 0 1.3585411444586235" />
     <axis xyz="1 0 0"/>
       <limit effort="0.0" lower="-3.14159" upper="3.14159" velocity="0.0"/>
    </joint>
    <joint name="Leg11_Leg13" type="revolute">
       <parent link="Leg11"/>
       <child  link="Leg13"/>
       <origin rpy="0 0 0" xyz="0 0 1.7791246928002054" />
     <axis xyz="1 0 0"/>
       <limit effort="0.0" lower="-3.14159" upper="3.14159" velocity="0.0"/>
    </joint>
    <joint name="Leg8_Leg14" type="revolute">
       <parent link="Leg8"/>
       <child  link="Leg14"/>
       <origin rpy="0 0 0" xyz="1.2207931546571502 0.878624822941282 0" />
     <axis xyz="1 0 0"/>
       <limit effort="0.0" lower="-3.14159" upper="3.14159" velocity="0.0"/>
    </joint>
    <joint name="Leg9_Leg15" type="revolute">
       <parent link="Leg9"/>
       <child  link="Leg15"/>
       <origin rpy="0 0 0" xyz="1.4865952963629336 1.357216593470567 0" />
     <axis xyz="1 0 0"/>
       <limit effort="0.0" lower="-3.14159" upper="3.14159" velocity="0.0"/>
    </joint>
    <joint name="Leg7_Leg16" type="revolute">
       <parent link="Leg7"/>
       <child  link="Leg16"/>
       <origin rpy="0 0 0" xyz="1.466142509148947 1.6096009288609534 0" />
     <axis xyz="1 0 0"/>
       <limit effort="0.0" lower="-3.14159" upper="3.14159" velocity="0.0"/>
    </joint>
    <joint name="Leg1_Leg17" type="revolute">
       <parent link="Leg1"/>
       <child  link="Leg17"/>
       <origin rpy="0 0 0" xyz="1.4940153336869835 1.0044466309997628 1.7173819297967616" />
     <axis xyz="1 0 0"/>
       <limit effort="0.0" lower="-3.14159" upper="3.14159" velocity="0.0"/>
    </joint>
    <joint name="Leg16_Leg18" type="revolute">
       <parent link="Leg16"/>
       <child  link="Leg18"/>
       <origin rpy="0 0 0" xyz="0 1.4721861959033724 1.4572341699832965" />
     <axis xyz="1 0 0"/>
       <limit effort="0.0" lower="-3.14159" upper="3.14159" velocity="0.0"/>
    </joint>
    <joint name="Leg3_Leg19" type="revolute">
       <parent link="Leg3"/>
       <child  link="Leg19"/>
       <origin rpy="0 0 0" xyz="0.7331631571128909 0.5096980546998648 1.3585411444586235" />
     <axis xyz="1 0 0"/>
       <limit effort="0.0" lower="-3.14159" upper="3.14159" velocity="0.0"/>
    </joint>
    <joint name="Leg6_Leg20" type="revolute">
       <parent link="Leg6"/>
       <child  link="Leg20"/>
       <origin rpy="0 0 0" xyz="0 0.6514929038014059 1.4314773390903248" />
     <axis xyz="1 0 0"/>
       <limit effort="0.0" lower="-3.14159" upper="3.14159" velocity="0.0"/>
    </joint>
    <joint name="Leg10_Leg21" type="revolute">
       <parent link="Leg10"/>
       <child  link="Leg21"/>
       <origin rpy="0 0 0" xyz="1.1603457318628225 0 0.8022267807951703" />
     <axis xyz="1 0 0"/>
       <limit effort="0.0" lower="-3.14159" upper="3.14159" velocity="0.0"/>
    </joint>
    <joint name="Leg13_Leg22" type="revolute">
       <parent link="Leg13"/>
       <child  link="Leg22"/>
       <origin rpy="0 0 0" xyz="0 1.782973948868576 0" />
     <axis xyz="1 0 0"/>
       <limit effort="0.0" lower="-3.14159" upper="3.14159" velocity="0.0"/>
    </joint>
    <joint name="Leg4_Leg23" type="revolute">
       <parent link="Leg4"/>
       <child  link="Leg23"/>
       <origin rpy="0 0 0" xyz="1.4653597226993031 0.8500525679533921 0.7541451213212935" />
     <axis xyz="1 0 0"/>
       <limit effort="0.0" lower="-3.14159" upper="3.14159" velocity="0.0"/>
    </joint>
    <joint name="Leg5_Leg24" type="revolute">
       <parent link="Leg5"/>
       <child  link="Leg24"/>
       <origin rpy="0 0 0" xyz="1.2917343384939646 0.9864892997240114 0" />
     <axis xyz="1 0 0"/>
       <limit effort="0.0" lower="-3.14159" upper="3.14159" velocity="0.0"/>
    </joint>
    <joint name="Leg19_Leg25" type="revolute">
       <parent link="Leg19"/>
       <child  link="Leg25"/>
       <origin rpy="0 0 0" xyz="0 2.9100990520943544 0" />
     <axis xyz="1 0 0"/>
       <limit effort="0.0" lower="-3.14159" upper="3.14159" velocity="0.0"/>
    </joint>
    <joint name="Leg16_Leg26" type="revolute">
       <parent link="Leg16"/>
       <child  link="Leg26"/>
       <origin rpy="0 0 0" xyz="0 2.944372391806745 1.4572341699832965" />
     <axis xyz="1 0 0"/>
       <limit effort="0.0" lower="-3.14159" upper="3.14159" velocity="0.0"/>
    </joint>
    <joint name="Leg17_Leg27" type="revolute">
       <parent link="Leg17"/>
       <child  link="Leg27"/>
       <origin rpy="0 0 0" xyz="0 1.4665535825006895 1.478952832865458" />
     <axis xyz="1 0 0"/>
       <limit effort="0.0" lower="-3.14159" upper="3.14159" velocity="0.0"/>
    </joint>
</robot>