<robot name = "robot">
    <link name="Torso">
        <inertial>
            <origin xyz="0 0 1.293937163325129" rpy="0 0 0"/>
            <mass value="1" />
            <inertia ixx="100" ixy="0" ixz="0" iyy="100" iyz="0" izz="100" />
        </inertial>
        <visual>
            <origin xyz="0 0 1.293937163325129" rpy="0 0 0"/>
            <geometry>
                <box size="2.181257379259259 1.256366241720463 2.587874326650258" />
            </geometry>
            <material name="Green">
                <color rgba="0 180.0 0.0 1.0"/>
            </material>
        </visual>
        <collision>
            <origin xyz="0 0 1.293937163325129" rpy="0 0 0"/>
            <geometry>
                <box size="2.181257379259259 1.256366241720463 2.587874326650258" />
            </geometry>
        </collision>
    </link>
    <link name="Leg1">
        <inertial>
            <origin xyz="1.0850444545907207 0 0" rpy="0 0 0"/>
            <mass value="1" />
            <inertia ixx="100" ixy="0" ixz="0" iyy="100" iyz="0" izz="100" />
        </inertial>
        <visual>
            <origin xyz="1.0850444545907207 0 0" rpy="0 0 0"/>
            <geometry>
                <box size="2.1700889091814415 1.504504769874672 2.544600038141659" />
            </geometry>
            <material name="Blue">
                <color rgba="0 1.0 1.0 1.0"/>
            </material>
        </visual>
        <collision>
            <origin xyz="1.0850444545907207 0 0" rpy="0 0 0"/>
            <geometry>
                <box size="2.1700889091814415 1.504504769874672 2.544600038141659" />
            </geometry>
        </collision>
    </link>
    <link name="Leg2">
        <inertial>
            <origin xyz="0 0 1.203747930546565" rpy="0 0 0"/>
            <mass value="1" />
            <inertia ixx="100" ixy="0" ixz="0" iyy="100" iyz="0" izz="100" />
        </inertial>
        <visual>
            <origin xyz="0 0 1.203747930546565" rpy="0 0 0"/>
            <geometry>
                <box size="2.8994347034369365 1.3222782814833827 2.40749586109313" />
            </geometry>
            <material name="Green">
                <color rgba="0 180.0 0.0 1.0"/>
            </material>
        </visual>
        <collision>
            <origin xyz="0 0 1.203747930546565" rpy="0 0 0"/>
            <geometry>
                <box size="2.8994347034369365 1.3222782814833827 2.40749586109313" />
            </geometry>
        </collision>
    </link>
    <link name="Leg3">
        <inertial>
            <origin xyz="0 0 1.2908257656034112" rpy="0 0 0"/>
            <mass value="1" />
            <inertia ixx="100" ixy="0" ixz="0" iyy="100" iyz="0" izz="100" />
        </inertial>
        <visual>
            <origin xyz="0 0 1.2908257656034112" rpy="0 0 0"/>
            <geometry>
                <box size="2.7966080191080174 1.5840997328107824 2.5816515312068224" />
            </geometry>
            <material name="Green">
                <color rgba="0 180.0 0.0 1.0"/>
            </material>
        </visual>
        <collision>
            <origin xyz="0 0 1.2908257656034112" rpy="0 0 0"/>
            <geometry>
                <box size="2.7966080191080174 1.5840997328107824 2.5816515312068224" />
            </geometry>
        </collision>
    </link>
    <link name="Leg4">
        <inertial>
            <origin xyz="0 0.8986207896693732 0" rpy="0 0 0"/>
            <mass value="1" />
            <inertia ixx="100" ixy="0" ixz="0" iyy="100" iyz="0" izz="100" />
        </inertial>
        <visual>
            <origin xyz="0 0.8986207896693732 0" rpy="0 0 0"/>
            <geometry>
                <box size="2.873216494577364 1.7972415793387464 2.189659998191786" />
            </geometry>
            <material name="Green">
                <color rgba="0 180.0 0.0 1.0"/>
            </material>
        </visual>
        <collision>
            <origin xyz="0 0.8986207896693732 0" rpy="0 0 0"/>
            <geometry>
                <box size="2.873216494577364 1.7972415793387464 2.189659998191786" />
            </geometry>
        </collision>
    </link>
    <link name="Leg5">
        <inertial>
            <origin xyz="0 0.832795903851213 0" rpy="0 0 0"/>
            <mass value="1" />
            <inertia ixx="100" ixy="0" ixz="0" iyy="100" iyz="0" izz="100" />
        </inertial>
        <visual>
            <origin xyz="0 0.832795903851213 0" rpy="0 0 0"/>
            <geometry>
                <box size="2.437124600511268 1.665591807702426 2.510177433979598" />
            </geometry>
            <material name="Green">
                <color rgba="0 180.0 0.0 1.0"/>
            </material>
        </visual>
        <collision>
            <origin xyz="0 0.832795903851213 0" rpy="0 0 0"/>
            <geometry>
                <box size="2.437124600511268 1.665591807702426 2.510177433979598" />
            </geometry>
        </collision>
    </link>
    <link name="Leg6">
        <inertial>
            <origin xyz="0 0 0.7463011174957618" rpy="0 0 0"/>
            <mass value="1" />
            <inertia ixx="100" ixy="0" ixz="0" iyy="100" iyz="0" izz="100" />
        </inertial>
        <visual>
            <origin xyz="0 0 0.7463011174957618" rpy="0 0 0"/>
            <geometry>
                <box size="1.7777440058781033 1.1654044348870485 1.4926022349915236" />
            </geometry>
            <material name="Green">
                <color rgba="0 180.0 0.0 1.0"/>
            </material>
        </visual>
        <collision>
            <origin xyz="0 0 0.7463011174957618" rpy="0 0 0"/>
            <geometry>
                <box size="1.7777440058781033 1.1654044348870485 1.4926022349915236" />
            </geometry>
        </collision>
    </link>
    <link name="Leg7">
        <inertial>
            <origin xyz="0.6264702311130529 0 0" rpy="0 0 0"/>
            <mass value="1" />
            <inertia ixx="100" ixy="0" ixz="0" iyy="100" iyz="0" izz="100" />
        </inertial>
        <visual>
            <origin xyz="0.6264702311130529 0 0" rpy="0 0 0"/>
            <geometry>
                <box size="1.2529404622261058 2.1684761663855983 1.3163358731298358" />
            </geometry>
            <material name="Blue">
                <color rgba="0 1.0 1.0 1.0"/>
            </material>
        </visual>
        <collision>
            <origin xyz="0.6264702311130529 0 0" rpy="0 0 0"/>
            <geometry>
                <box size="1.2529404622261058 2.1684761663855983 1.3163358731298358" />
            </geometry>
        </collision>
    </link>
    <link name="Leg8">
        <inertial>
            <origin xyz="0 0 0.5967871380045005" rpy="0 0 0"/>
            <mass value="1" />
            <inertia ixx="100" ixy="0" ixz="0" iyy="100" iyz="0" izz="100" />
        </inertial>
        <visual>
            <origin xyz="0 0 0.5967871380045005" rpy="0 0 0"/>
            <geometry>
                <box size="1.862533428369782 2.0196256848951473 1.193574276009001" />
            </geometry>
            <material name="Blue">
                <color rgba="0 1.0 1.0 1.0"/>
            </material>
        </visual>
        <collision>
            <origin xyz="0 0 0.5967871380045005" rpy="0 0 0"/>
            <geometry>
                <box size="1.862533428369782 2.0196256848951473 1.193574276009001" />
            </geometry>
        </collision>
    </link>
    <link name="Leg9">
        <inertial>
            <origin xyz="1.0143437424312682 0 0" rpy="0 0 0"/>
            <mass value="1" />
            <inertia ixx="100" ixy="0" ixz="0" iyy="100" iyz="0" izz="100" />
        </inertial>
        <visual>
            <origin xyz="1.0143437424312682 0 0" rpy="0 0 0"/>
            <geometry>
                <box size="2.0286874848625365 1.918965715723481 1.1752432497203904" />
            </geometry>
            <material name="Blue">
                <color rgba="0 1.0 1.0 1.0"/>
            </material>
        </visual>
        <collision>
            <origin xyz="1.0143437424312682 0 0" rpy="0 0 0"/>
            <geometry>
                <box size="2.0286874848625365 1.918965715723481 1.1752432497203904" />
            </geometry>
        </collision>
    </link>
    <link name="Leg10">
        <inertial>
            <origin xyz="0.8416198770110082 0 0" rpy="0 0 0"/>
            <mass value="1" />
            <inertia ixx="100" ixy="0" ixz="0" iyy="100" iyz="0" izz="100" />
        </inertial>
        <visual>
            <origin xyz="0.8416198770110082 0 0" rpy="0 0 0"/>
            <geometry>
                <box size="1.6832397540220163 2.8067687321111032 1.8969401822683285" />
            </geometry>
            <material name="Blue">
                <color rgba="0 1.0 1.0 1.0"/>
            </material>
        </visual>
        <collision>
            <origin xyz="0.8416198770110082 0 0" rpy="0 0 0"/>
            <geometry>
                <box size="1.6832397540220163 2.8067687321111032 1.8969401822683285" />
            </geometry>
        </collision>
    </link>
    <link name="Leg11">
        <inertial>
            <origin xyz="0 0 0.5744337941925544" rpy="0 0 0"/>
            <mass value="1" />
            <inertia ixx="100" ixy="0" ixz="0" iyy="100" iyz="0" izz="100" />
        </inertial>
        <visual>
            <origin xyz="0 0 0.5744337941925544" rpy="0 0 0"/>
            <geometry>
                <box size="1.3250575179969368 1.0811992166812672 1.1488675883851087" />
            </geometry>
            <material name="Blue">
                <color rgba="0 1.0 1.0 1.0"/>
            </material>
        </visual>
        <collision>
            <origin xyz="0 0 0.5744337941925544" rpy="0 0 0"/>
            <geometry>
                <box size="1.3250575179969368 1.0811992166812672 1.1488675883851087" />
            </geometry>
        </collision>
    </link>
    <link name="Leg12">
        <inertial>
            <origin xyz="0 1.4112172260901334 0" rpy="0 0 0"/>
            <mass value="1" />
            <inertia ixx="100" ixy="0" ixz="0" iyy="100" iyz="0" izz="100" />
        </inertial>
        <visual>
            <origin xyz="0 1.4112172260901334 0" rpy="0 0 0"/>
            <geometry>
                <box size="1.7679225123560847 2.822434452180267 1.0523361655809618" />
            </geometry>
            <material name="Blue">
                <color rgba="0 1.0 1.0 1.0"/>
            </material>
        </visual>
        <collision>
            <origin xyz="0 1.4112172260901334 0" rpy="0 0 0"/>
            <geometry>
                <box size="1.7679225123560847 2.822434452180267 1.0523361655809618" />
            </geometry>
        </collision>
    </link>
    <link name="Leg13">
        <inertial>
            <origin xyz="0 0 1.1884937199050012" rpy="0 0 0"/>
            <mass value="1" />
            <inertia ixx="100" ixy="0" ixz="0" iyy="100" iyz="0" izz="100" />
        </inertial>
        <visual>
            <origin xyz="0 0 1.1884937199050012" rpy="0 0 0"/>
            <geometry>
                <box size="1.1590132200354417 2.050348800895498 2.3769874398100024" />
            </geometry>
            <material name="Blue">
                <color rgba="0 1.0 1.0 1.0"/>
            </material>
        </visual>
        <collision>
            <origin xyz="0 0 1.1884937199050012" rpy="0 0 0"/>
            <geometry>
                <box size="1.1590132200354417 2.050348800895498 2.3769874398100024" />
            </geometry>
        </collision>
    </link>
    <link name="Leg14">
        <inertial>
            <origin xyz="1.0041722048990078 0 0" rpy="0 0 0"/>
            <mass value="1" />
            <inertia ixx="100" ixy="0" ixz="0" iyy="100" iyz="0" izz="100" />
        </inertial>
        <visual>
            <origin xyz="1.0041722048990078 0 0" rpy="0 0 0"/>
            <geometry>
                <box size="2.0083444097980157 1.0532802786264936 2.2107272572331613" />
            </geometry>
            <material name="Blue">
                <color rgba="0 1.0 1.0 1.0"/>
            </material>
        </visual>
        <collision>
            <origin xyz="1.0041722048990078 0 0" rpy="0 0 0"/>
            <geometry>
                <box size="2.0083444097980157 1.0532802786264936 2.2107272572331613" />
            </geometry>
        </collision>
    </link>
    <link name="Leg15">
        <inertial>
            <origin xyz="0 0 1.1164312931208875" rpy="0 0 0"/>
            <mass value="1" />
            <inertia ixx="100" ixy="0" ixz="0" iyy="100" iyz="0" izz="100" />
        </inertial>
        <visual>
            <origin xyz="0 0 1.1164312931208875" rpy="0 0 0"/>
            <geometry>
                <box size="2.275312114897952 1.3621093273777112 2.232862586241775" />
            </geometry>
            <material name="Green">
                <color rgba="0 180.0 0.0 1.0"/>
            </material>
        </visual>
        <collision>
            <origin xyz="0 0 1.1164312931208875" rpy="0 0 0"/>
            <geometry>
                <box size="2.275312114897952 1.3621093273777112 2.232862586241775" />
            </geometry>
        </collision>
    </link>
    <link name="Leg16">
        <inertial>
            <origin xyz="0 0 1.0677355651169167" rpy="0 0 0"/>
            <mass value="1" />
            <inertia ixx="100" ixy="0" ixz="0" iyy="100" iyz="0" izz="100" />
        </inertial>
        <visual>
            <origin xyz="0 0 1.0677355651169167" rpy="0 0 0"/>
            <geometry>
                <box size="1.0802654036815547 2.9631091375956062 2.1354711302338334" />
            </geometry>
            <material name="Green">
                <color rgba="0 180.0 0.0 1.0"/>
            </material>
        </visual>
        <collision>
            <origin xyz="0 0 1.0677355651169167" rpy="0 0 0"/>
            <geometry>
                <box size="1.0802654036815547 2.9631091375956062 2.1354711302338334" />
            </geometry>
        </collision>
    </link>
    <link name="Leg17">
        <inertial>
            <origin xyz="0 1.066168436296763 0" rpy="0 0 0"/>
            <mass value="1" />
            <inertia ixx="100" ixy="0" ixz="0" iyy="100" iyz="0" izz="100" />
        </inertial>
        <visual>
            <origin xyz="0 1.066168436296763 0" rpy="0 0 0"/>
            <geometry>
                <box size="2.038007790484191 2.132336872593526 2.4939538851574614" />
            </geometry>
            <material name="Green">
                <color rgba="0 180.0 0.0 1.0"/>
            </material>
        </visual>
        <collision>
            <origin xyz="0 1.066168436296763 0" rpy="0 0 0"/>
            <geometry>
                <box size="2.038007790484191 2.132336872593526 2.4939538851574614" />
            </geometry>
        </collision>
    </link>
    <link name="Leg18">
        <inertial>
            <origin xyz="0 0 0.5406462412664611" rpy="0 0 0"/>
            <mass value="1" />
            <inertia ixx="100" ixy="0" ixz="0" iyy="100" iyz="0" izz="100" />
        </inertial>
        <visual>
            <origin xyz="0 0 0.5406462412664611" rpy="0 0 0"/>
            <geometry>
                <box size="2.9434984076484434 1.4811367373608486 1.0812924825329222" />
            </geometry>
            <material name="Blue">
                <color rgba="0 1.0 1.0 1.0"/>
            </material>
        </visual>
        <collision>
            <origin xyz="0 0 0.5406462412664611" rpy="0 0 0"/>
            <geometry>
                <box size="2.9434984076484434 1.4811367373608486 1.0812924825329222" />
            </geometry>
        </collision>
    </link>
    <link name="Leg19">
        <inertial>
            <origin xyz="0 1.3969402439252092 0" rpy="0 0 0"/>
            <mass value="1" />
            <inertia ixx="100" ixy="0" ixz="0" iyy="100" iyz="0" izz="100" />
        </inertial>
        <visual>
            <origin xyz="0 1.3969402439252092 0" rpy="0 0 0"/>
            <geometry>
                <box size="2.1055403695458565 2.7938804878504184 2.881610255567307" />
            </geometry>
            <material name="Green">
                <color rgba="0 180.0 0.0 1.0"/>
            </material>
        </visual>
        <collision>
            <origin xyz="0 1.3969402439252092 0" rpy="0 0 0"/>
            <geometry>
                <box size="2.1055403695458565 2.7938804878504184 2.881610255567307" />
            </geometry>
        </collision>
    </link>
    <link name="Leg20">
        <inertial>
            <origin xyz="0.9950699893762519 0 0" rpy="0 0 0"/>
            <mass value="1" />
            <inertia ixx="100" ixy="0" ixz="0" iyy="100" iyz="0" izz="100" />
        </inertial>
        <visual>
            <origin xyz="0.9950699893762519 0 0" rpy="0 0 0"/>
            <geometry>
                <box size="1.9901399787525038 1.6836825642042437 2.8159088281394657" />
            </geometry>
            <material name="Green">
                <color rgba="0 180.0 0.0 1.0"/>
            </material>
        </visual>
        <collision>
            <origin xyz="0.9950699893762519 0 0" rpy="0 0 0"/>
            <geometry>
                <box size="1.9901399787525038 1.6836825642042437 2.8159088281394657" />
            </geometry>
        </collision>
    </link>
    <link name="Leg21">
        <inertial>
            <origin xyz="0 1.0408088006641603 0" rpy="0 0 0"/>
            <mass value="1" />
            <inertia ixx="100" ixy="0" ixz="0" iyy="100" iyz="0" izz="100" />
        </inertial>
        <visual>
            <origin xyz="0 1.0408088006641603 0" rpy="0 0 0"/>
            <geometry>
                <box size="1.9623010413883444 2.0816176013283205 2.895354039672321" />
            </geometry>
            <material name="Green">
                <color rgba="0 180.0 0.0 1.0"/>
            </material>
        </visual>
        <collision>
            <origin xyz="0 1.0408088006641603 0" rpy="0 0 0"/>
            <geometry>
                <box size="1.9623010413883444 2.0816176013283205 2.895354039672321" />
            </geometry>
        </collision>
    </link>
    <link name="Leg22">
        <inertial>
            <origin xyz="0.8164426653929354 0 0" rpy="0 0 0"/>
            <mass value="1" />
            <inertia ixx="100" ixy="0" ixz="0" iyy="100" iyz="0" izz="100" />
        </inertial>
        <visual>
            <origin xyz="0.8164426653929354 0 0" rpy="0 0 0"/>
            <geometry>
                <box size="1.6328853307858708 2.720334015367472 2.753306952298312" />
            </geometry>
            <material name="Blue">
                <color rgba="0 1.0 1.0 1.0"/>
            </material>
        </visual>
        <collision>
            <origin xyz="0.8164426653929354 0 0" rpy="0 0 0"/>
            <geometry>
                <box size="1.6328853307858708 2.720334015367472 2.753306952298312" />
            </geometry>
        </collision>
    </link>
    <link name="Leg23">
        <inertial>
            <origin xyz="0 0 0.8144117888948127" rpy="0 0 0"/>
            <mass value="1" />
            <inertia ixx="100" ixy="0" ixz="0" iyy="100" iyz="0" izz="100" />
        </inertial>
        <visual>
            <origin xyz="0 0 0.8144117888948127" rpy="0 0 0"/>
            <geometry>
                <box size="1.013786321880775 1.7391302134836297 1.6288235777896254" />
            </geometry>
            <material name="Green">
                <color rgba="0 180.0 0.0 1.0"/>
            </material>
        </visual>
        <collision>
            <origin xyz="0 0 0.8144117888948127" rpy="0 0 0"/>
            <geometry>
                <box size="1.013786321880775 1.7391302134836297 1.6288235777896254" />
            </geometry>
        </collision>
    </link>
    <link name="Leg24">
        <inertial>
            <origin xyz="0 0.5755957255520391 0" rpy="0 0 0"/>
            <mass value="1" />
            <inertia ixx="100" ixy="0" ixz="0" iyy="100" iyz="0" izz="100" />
        </inertial>
        <visual>
            <origin xyz="0 0.5755957255520391 0" rpy="0 0 0"/>
            <geometry>
                <box size="2.214526569354078 1.1511914511040782 1.6234899893404804" />
            </geometry>
            <material name="Green">
                <color rgba="0 180.0 0.0 1.0"/>
            </material>
        </visual>
        <collision>
            <origin xyz="0 0.5755957255520391 0" rpy="0 0 0"/>
            <geometry>
                <box size="2.214526569354078 1.1511914511040782 1.6234899893404804" />
            </geometry>
        </collision>
    </link>
    <link name="Leg25">
        <inertial>
            <origin xyz="0.6716838544865948 0 0" rpy="0 0 0"/>
            <mass value="1" />
            <inertia ixx="100" ixy="0" ixz="0" iyy="100" iyz="0" izz="100" />
        </inertial>
        <visual>
            <origin xyz="0.6716838544865948 0 0" rpy="0 0 0"/>
            <geometry>
                <box size="1.3433677089731897 1.8809187025307816 1.6230281567441842" />
            </geometry>
            <material name="Blue">
                <color rgba="0 1.0 1.0 1.0"/>
            </material>
        </visual>
        <collision>
            <origin xyz="0.6716838544865948 0 0" rpy="0 0 0"/>
            <geometry>
                <box size="1.3433677089731897 1.8809187025307816 1.6230281567441842" />
            </geometry>
        </collision>
    </link>
    <link name="Leg26">
        <inertial>
            <origin xyz="0 1.3040431008711433 0" rpy="0 0 0"/>
            <mass value="1" />
            <inertia ixx="100" ixy="0" ixz="0" iyy="100" iyz="0" izz="100" />
        </inertial>
        <visual>
            <origin xyz="0 1.3040431008711433 0" rpy="0 0 0"/>
            <geometry>
                <box size="2.335014702130416 2.6080862017422866 1.284440813496805" />
            </geometry>
            <material name="Green">
                <color rgba="0 180.0 0.0 1.0"/>
            </material>
        </visual>
        <collision>
            <origin xyz="0 1.3040431008711433 0" rpy="0 0 0"/>
            <geometry>
                <box size="2.335014702130416 2.6080862017422866 1.284440813496805" />
            </geometry>
        </collision>
    </link>
    <link name="Leg27">
        <inertial>
            <origin xyz="0 0 1.2154975058874142" rpy="0 0 0"/>
            <mass value="1" />
            <inertia ixx="100" ixy="0" ixz="0" iyy="100" iyz="0" izz="100" />
        </inertial>
        <visual>
            <origin xyz="0 0 1.2154975058874142" rpy="0 0 0"/>
            <geometry>
                <box size="1.6629831257241277 1.9719225135357654 2.4309950117748285" />
            </geometry>
            <material name="Green">
                <color rgba="0 180.0 0.0 1.0"/>
            </material>
        </visual>
        <collision>
            <origin xyz="0 0 1.2154975058874142" rpy="0 0 0"/>
            <geometry>
                <box size="1.6629831257241277 1.9719225135357654 2.4309950117748285" />
            </geometry>
        </collision>
    </link>
    <joint name="Torso_Leg1" type="revolute">
       <parent link="Torso"/>
       <child  link="Leg1"/>
       <origin rpy="0 0 0" xyz="1.0906286896296296 0 1.293937163325129" />
     <axis xyz="1 0 0"/>
       <limit effort="0.0" lower="-3.14159" upper="3.14159" velocity="0.0"/>
    </joint>
    <joint name="Leg1_Leg2" type="revolute">
       <parent link="Leg1"/>
       <child  link="Leg2"/>
       <origin rpy="0 0 0" xyz="0 0 2.40749586109313" />
     <axis xyz="1 0 0"/>
       <limit effort="0.0" lower="-3.14159" upper="3.14159" velocity="0.0"/>
    </joint>
    <joint name="Torso_Leg3" type="revolute">
       <parent link="Torso"/>
       <child  link="Leg3"/>
       <origin rpy="0 0 0" xyz="1.0850444545907207 0 1.2723000190708296" />
     <axis xyz="1 0 0"/>
       <limit effort="0.0" lower="-3.14159" upper="3.14159" velocity="0.0"/>
    </joint>
    <joint name="Leg3_Leg4" type="revolute">
       <parent link="Leg3"/>
       <child  link="Leg4"/>
       <origin rpy="0 0 0" xyz="0 1.7972415793387464 0" />
     <axis xyz="1 0 0"/>
       <limit effort="0.0" lower="-3.14159" upper="3.14159" velocity="0.0"/>
    </joint>
    <joint name="Leg2_Leg5" type="revolute">
       <parent link="Leg2"/>
       <child  link="Leg5"/>
       <origin rpy="0 0 0" xyz="0 0.7920498664053912 1.2908257656034112" />
     <axis xyz="1 0 0"/>
       <limit effort="0.0" lower="-3.14159" upper="3.14159" velocity="0.0"/>
    </joint>
    <joint name="Leg2_Leg6" type="revolute">
       <parent link="Leg2"/>
       <child  link="Leg6"/>
       <origin rpy="0 0 0" xyz="0 0.7920498664053912 2.5816515312068224" />
     <axis xyz="1 0 0"/>
       <limit effort="0.0" lower="-3.14159" upper="3.14159" velocity="0.0"/>
    </joint>
    <joint name="Leg3_Leg7" type="revolute">
       <parent link="Leg3"/>
       <child  link="Leg7"/>
       <origin rpy="0 0 0" xyz="1.436608247288682 1.7972415793387464 0" />
     <axis xyz="1 0 0"/>
       <limit effort="0.0" lower="-3.14159" upper="3.14159" velocity="0.0"/>
    </joint>
    <joint name="Leg4_Leg8" type="revolute">
       <parent link="Leg4"/>
       <child  link="Leg8"/>
       <origin rpy="0 0 0" xyz="0 0.832795903851213 1.255088716989799" />
     <axis xyz="1 0 0"/>
       <limit effort="0.0" lower="-3.14159" upper="3.14159" velocity="0.0"/>
    </joint>
    <joint name="Leg4_Leg9" type="revolute">
       <parent link="Leg4"/>
       <child  link="Leg9"/>
       <origin rpy="0 0 0" xyz="1.218562300255634 0.832795903851213 1.255088716989799" />
     <axis xyz="1 0 0"/>
       <limit effort="0.0" lower="-3.14159" upper="3.14159" velocity="0.0"/>
    </joint>
    <joint name="Leg2_Leg10" type="revolute">
       <parent link="Leg2"/>
       <child  link="Leg10"/>
       <origin rpy="0 0 0" xyz="1.3983040095540087 0.7920498664053912 2.5816515312068224" />
     <axis xyz="1 0 0"/>
       <limit effort="0.0" lower="-3.14159" upper="3.14159" velocity="0.0"/>
    </joint>
    <joint name="Leg9_Leg11" type="revolute">
       <parent link="Leg9"/>
       <child  link="Leg11"/>
       <origin rpy="0 0 0" xyz="0.8416198770110082 0 0.9484700911341643" />
     <axis xyz="1 0 0"/>
       <limit effort="0.0" lower="-3.14159" upper="3.14159" velocity="0.0"/>
    </joint>
    <joint name="Leg11_Leg12" type="revolute">
       <parent link="Leg11"/>
       <child  link="Leg12"/>
       <origin rpy="0 0 0" xyz="0 2.822434452180267 0" />
     <axis xyz="1 0 0"/>
       <limit effort="0.0" lower="-3.14159" upper="3.14159" velocity="0.0"/>
    </joint>
    <joint name="Leg7_Leg13" type="revolute">
       <parent link="Leg7"/>
       <child  link="Leg13"/>
       <origin rpy="0 0 0" xyz="0 0 1.193574276009001" />
     <axis xyz="1 0 0"/>
       <limit effort="0.0" lower="-3.14159" upper="3.14159" velocity="0.0"/>
    </joint>
    <joint name="Leg13_Leg14" type="revolute">
       <parent link="Leg13"/>
       <child  link="Leg14"/>
       <origin rpy="0 0 0" xyz="2.0083444097980157 0 0" />
     <axis xyz="1 0 0"/>
       <limit effort="0.0" lower="-3.14159" upper="3.14159" velocity="0.0"/>
    </joint>
    <joint name="Leg13_Leg15" type="revolute">
       <parent link="Leg13"/>
       <child  link="Leg15"/>
       <origin rpy="0 0 0" xyz="2.0083444097980157 0 1.1053636286165807" />
     <axis xyz="1 0 0"/>
       <limit effort="0.0" lower="-3.14159" upper="3.14159" velocity="0.0"/>
    </joint>
    <joint name="Leg3_Leg16" type="revolute">
       <parent link="Leg3"/>
       <child  link="Leg16"/>
       <origin rpy="0 0 0" xyz="1.436608247288682 1.7972415793387464 1.094829999095893" />
     <axis xyz="1 0 0"/>
       <limit effort="0.0" lower="-3.14159" upper="3.14159" velocity="0.0"/>
    </joint>
    <joint name="Leg5_Leg17" type="revolute">
       <parent link="Leg5"/>
       <child  link="Leg17"/>
       <origin rpy="0 0 0" xyz="0 0.5827022174435242 0.7463011174957618" />
     <axis xyz="1 0 0"/>
       <limit effort="0.0" lower="-3.14159" upper="3.14159" velocity="0.0"/>
    </joint>
    <joint name="Leg8_Leg18" type="revolute">
       <parent link="Leg8"/>
       <child  link="Leg18"/>
       <origin rpy="0 0 0" xyz="1.0143437424312682 0 0.5876216248601952" />
     <axis xyz="1 0 0"/>
       <limit effort="0.0" lower="-3.14159" upper="3.14159" velocity="0.0"/>
    </joint>
    <joint name="Leg17_Leg19" type="revolute">
       <parent link="Leg17"/>
       <child  link="Leg19"/>
       <origin rpy="0 0 0" xyz="0 0.7405683686804243 0.5406462412664611" />
     <axis xyz="1 0 0"/>
       <limit effort="0.0" lower="-3.14159" upper="3.14159" velocity="0.0"/>
    </joint>
    <joint name="Leg11_Leg20" type="revolute">
       <parent link="Leg11"/>
       <child  link="Leg20"/>
       <origin rpy="0 0 0" xyz="0.8839612561780423 2.822434452180267 0" />
     <axis xyz="1 0 0"/>
       <limit effort="0.0" lower="-3.14159" upper="3.14159" velocity="0.0"/>
    </joint>
    <joint name="Leg8_Leg21" type="revolute">
       <parent link="Leg8"/>
       <child  link="Leg21"/>
       <origin rpy="0 0 0" xyz="1.0143437424312682 0.9594828578617405 0.5876216248601952" />
     <axis xyz="1 0 0"/>
       <limit effort="0.0" lower="-3.14159" upper="3.14159" velocity="0.0"/>
    </joint>
    <joint name="Leg20_Leg22" type="revolute">
       <parent link="Leg20"/>
       <child  link="Leg22"/>
       <origin rpy="0 0 0" xyz="0.9811505206941722 1.0408088006641603 0" />
     <axis xyz="1 0 0"/>
       <limit effort="0.0" lower="-3.14159" upper="3.14159" velocity="0.0"/>
    </joint>
    <joint name="Leg19_Leg23" type="revolute">
       <parent link="Leg19"/>
       <child  link="Leg23"/>
       <origin rpy="0 0 0" xyz="0.9950699893762519 0 1.4079544140697329" />
     <axis xyz="1 0 0"/>
       <limit effort="0.0" lower="-3.14159" upper="3.14159" velocity="0.0"/>
    </joint>
    <joint name="Leg22_Leg24" type="revolute">
       <parent link="Leg22"/>
       <child  link="Leg24"/>
       <origin rpy="0 0 0" xyz="0 0.8695651067418149 0.8144117888948127" />
     <axis xyz="1 0 0"/>
       <limit effort="0.0" lower="-3.14159" upper="3.14159" velocity="0.0"/>
    </joint>
    <joint name="Leg14_Leg25" type="revolute">
       <parent link="Leg14"/>
       <child  link="Leg25"/>
       <origin rpy="0 0 0" xyz="1.137656057448976 0 1.1164312931208875" />
     <axis xyz="1 0 0"/>
       <limit effort="0.0" lower="-3.14159" upper="3.14159" velocity="0.0"/>
    </joint>
    <joint name="Leg7_Leg26" type="revolute">
       <parent link="Leg7"/>
       <child  link="Leg26"/>
       <origin rpy="0 0 0" xyz="0 1.0098128424475736 1.193574276009001" />
     <axis xyz="1 0 0"/>
       <limit effort="0.0" lower="-3.14159" upper="3.14159" velocity="0.0"/>
    </joint>
    <joint name="Leg18_Leg27" type="revolute">
       <parent link="Leg18"/>
       <child  link="Leg27"/>
       <origin rpy="0 0 0" xyz="0 1.3969402439252092 1.4408051277836535" />
     <axis xyz="1 0 0"/>
       <limit effort="0.0" lower="-3.14159" upper="3.14159" velocity="0.0"/>
    </joint>
</robot>