<robot name = "robot">
    <link name="Torso">
        <inertial>
            <origin xyz="0 0.6045867454262728 0.5000716225324188" rpy="0 0 0"/>
            <mass value="1" />
            <inertia ixx="100" ixy="0" ixz="0" iyy="100" iyz="0" izz="100" />
        </inertial>
        <visual>
            <origin xyz="0 0.6045867454262728 0.5000716225324188" rpy="0 0 0"/>
            <geometry>
                <box size="2.194355312998802 1.2091734908525456 1.0001432450648375" />
            </geometry>
            <material name="Green">
                <color rgba="0 180.0 0.0 1.0"/>
            </material>
        </visual>
        <collision>
            <origin xyz="0 0.6045867454262728 0.5000716225324188" rpy="0 0 0"/>
            <geometry>
                <box size="2.194355312998802 1.2091734908525456 1.0001432450648375" />
            </geometry>
        </collision>
    </link>
    <link name="Leg1">
        <inertial>
            <origin xyz="0.9220051057922886 1.256524777770641 0" rpy="0 0 0"/>
            <mass value="1" />
            <inertia ixx="100" ixy="0" ixz="0" iyy="100" iyz="0" izz="100" />
        </inertial>
        <visual>
            <origin xyz="0.9220051057922886 1.256524777770641 0" rpy="0 0 0"/>
            <geometry>
                <box size="1.8440102115845771 2.513049555541282 1.3176902103743058" />
            </geometry>
            <material name="Blue">
                <color rgba="0 1.0 1.0 1.0"/>
            </material>
        </visual>
        <collision>
            <origin xyz="0.9220051057922886 1.256524777770641 0" rpy="0 0 0"/>
            <geometry>
                <box size="1.8440102115845771 2.513049555541282 1.3176902103743058" />
            </geometry>
        </collision>
    </link>
    <link name="Leg2">
        <inertial>
            <origin xyz="2.863628502816508 0.8973629599641022 1.0271726649369484" rpy="0 0 0"/>
            <mass value="1" />
            <inertia ixx="100" ixy="0" ixz="0" iyy="100" iyz="0" izz="100" />
        </inertial>
        <visual>
            <origin xyz="2.863628502816508 0.8973629599641022 1.0271726649369484" rpy="0 0 0"/>
            <geometry>
                <box size="2.863628502816508 1.7947259199282044 2.0543453298738967" />
            </geometry>
            <material name="Blue">
                <color rgba="0 1.0 1.0 1.0"/>
            </material>
        </visual>
        <collision>
            <origin xyz="2.863628502816508 0.8973629599641022 1.0271726649369484" rpy="0 0 0"/>
            <geometry>
                <box size="2.863628502816508 1.7947259199282044 2.0543453298738967" />
            </geometry>
        </collision>
    </link>
    <link name="Leg3">
        <inertial>
            <origin xyz="1.2273435173091416 1.3059216445400736 1.5434598522980107" rpy="0 0 0"/>
            <mass value="1" />
            <inertia ixx="100" ixy="0" ixz="0" iyy="100" iyz="0" izz="100" />
        </inertial>
        <visual>
            <origin xyz="1.2273435173091416 1.3059216445400736 1.5434598522980107" rpy="0 0 0"/>
            <geometry>
                <box size="2.454687034618283 2.6118432890801473 1.5434598522980107" />
            </geometry>
            <material name="Blue">
                <color rgba="0 1.0 1.0 1.0"/>
            </material>
        </visual>
        <collision>
            <origin xyz="1.2273435173091416 1.3059216445400736 1.5434598522980107" rpy="0 0 0"/>
            <geometry>
                <box size="2.454687034618283 2.6118432890801473 1.5434598522980107" />
            </geometry>
        </collision>
    </link>
    <link name="Leg4">
        <inertial>
            <origin xyz="2.23053855751853 0.8736924738009557 0" rpy="0 0 0"/>
            <mass value="1" />
            <inertia ixx="100" ixy="0" ixz="0" iyy="100" iyz="0" izz="100" />
        </inertial>
        <visual>
            <origin xyz="2.23053855751853 0.8736924738009557 0" rpy="0 0 0"/>
            <geometry>
                <box size="2.23053855751853 1.7473849476019114 2.2544052718871406" />
            </geometry>
            <material name="Blue">
                <color rgba="0 1.0 1.0 1.0"/>
            </material>
        </visual>
        <collision>
            <origin xyz="2.23053855751853 0.8736924738009557 0" rpy="0 0 0"/>
            <geometry>
                <box size="2.23053855751853 1.7473849476019114 2.2544052718871406" />
            </geometry>
        </collision>
    </link>
    <link name="Leg5">
        <inertial>
            <origin xyz="0.5271132149271602 0.5883352935719638 1.6515466408218116" rpy="0 0 0"/>
            <mass value="1" />
            <inertia ixx="100" ixy="0" ixz="0" iyy="100" iyz="0" izz="100" />
        </inertial>
        <visual>
            <origin xyz="0.5271132149271602 0.5883352935719638 1.6515466408218116" rpy="0 0 0"/>
            <geometry>
                <box size="1.0542264298543205 1.1766705871439276 1.6515466408218116" />
            </geometry>
            <material name="Blue">
                <color rgba="0 1.0 1.0 1.0"/>
            </material>
        </visual>
        <collision>
            <origin xyz="0.5271132149271602 0.5883352935719638 1.6515466408218116" rpy="0 0 0"/>
            <geometry>
                <box size="1.0542264298543205 1.1766705871439276 1.6515466408218116" />
            </geometry>
        </collision>
    </link>
    <link name="Leg6">
        <inertial>
            <origin xyz="0.5387685330636345 1.9229453943162993 0.5538740190184536" rpy="0 0 0"/>
            <mass value="1" />
            <inertia ixx="100" ixy="0" ixz="0" iyy="100" iyz="0" izz="100" />
        </inertial>
        <visual>
            <origin xyz="0.5387685330636345 1.9229453943162993 0.5538740190184536" rpy="0 0 0"/>
            <geometry>
                <box size="1.077537066127269 1.9229453943162993 1.1077480380369071" />
            </geometry>
            <material name="Blue">
                <color rgba="0 1.0 1.0 1.0"/>
            </material>
        </visual>
        <collision>
            <origin xyz="0.5387685330636345 1.9229453943162993 0.5538740190184536" rpy="0 0 0"/>
            <geometry>
                <box size="1.077537066127269 1.9229453943162993 1.1077480380369071" />
            </geometry>
        </collision>
    </link>
    <link name="Leg7">
        <inertial>
            <origin xyz="0.5901122385709173 0.7166643389241238 0" rpy="0 0 0"/>
            <mass value="1" />
            <inertia ixx="100" ixy="0" ixz="0" iyy="100" iyz="0" izz="100" />
        </inertial>
        <visual>
            <origin xyz="0.5901122385709173 0.7166643389241238 0" rpy="0 0 0"/>
            <geometry>
                <box size="1.1802244771418346 1.4333286778482477 2.3357150462485583" />
            </geometry>
            <material name="Blue">
                <color rgba="0 1.0 1.0 1.0"/>
            </material>
        </visual>
        <collision>
            <origin xyz="0.5901122385709173 0.7166643389241238 0" rpy="0 0 0"/>
            <geometry>
                <box size="1.1802244771418346 1.4333286778482477 2.3357150462485583" />
            </geometry>
        </collision>
    </link>
    <link name="Leg8">
        <inertial>
            <origin xyz="0.9433001164798441 0 0" rpy="0 0 0"/>
            <mass value="1" />
            <inertia ixx="100" ixy="0" ixz="0" iyy="100" iyz="0" izz="100" />
        </inertial>
        <visual>
            <origin xyz="0.9433001164798441 0 0" rpy="0 0 0"/>
            <geometry>
                <box size="1.8866002329596883 1.292208186980353 1.614260769831778" />
            </geometry>
            <material name="Blue">
                <color rgba="0 1.0 1.0 1.0"/>
            </material>
        </visual>
        <collision>
            <origin xyz="0.9433001164798441 0 0" rpy="0 0 0"/>
            <geometry>
                <box size="1.8866002329596883 1.292208186980353 1.614260769831778" />
            </geometry>
        </collision>
    </link>
    <link name="Leg9">
        <inertial>
            <origin xyz="0 1.4234866055993374 1.373555669167179" rpy="0 0 0"/>
            <mass value="1" />
            <inertia ixx="100" ixy="0" ixz="0" iyy="100" iyz="0" izz="100" />
        </inertial>
        <visual>
            <origin xyz="0 1.4234866055993374 1.373555669167179" rpy="0 0 0"/>
            <geometry>
                <box size="1.3386708474048021 2.8469732111986747 2.747111338334358" />
            </geometry>
            <material name="Blue">
                <color rgba="0 1.0 1.0 1.0"/>
            </material>
        </visual>
        <collision>
            <origin xyz="0 1.4234866055993374 1.373555669167179" rpy="0 0 0"/>
            <geometry>
                <box size="1.3386708474048021 2.8469732111986747 2.747111338334358" />
            </geometry>
        </collision>
    </link>
    <link name="Leg10">
        <inertial>
            <origin xyz="1.4489468181916725 0 0.5444836508668386" rpy="0 0 0"/>
            <mass value="1" />
            <inertia ixx="100" ixy="0" ixz="0" iyy="100" iyz="0" izz="100" />
        </inertial>
        <visual>
            <origin xyz="1.4489468181916725 0 0.5444836508668386" rpy="0 0 0"/>
            <geometry>
                <box size="2.897893636383345 2.854716851628658 1.0889673017336772" />
            </geometry>
            <material name="Blue">
                <color rgba="0 1.0 1.0 1.0"/>
            </material>
        </visual>
        <collision>
            <origin xyz="1.4489468181916725 0 0.5444836508668386" rpy="0 0 0"/>
            <geometry>
                <box size="2.897893636383345 2.854716851628658 1.0889673017336772" />
            </geometry>
        </collision>
    </link>
    <link name="Leg11">
        <inertial>
            <origin xyz="0 1.255650057704888 0" rpy="0 0 0"/>
            <mass value="1" />
            <inertia ixx="100" ixy="0" ixz="0" iyy="100" iyz="0" izz="100" />
        </inertial>
        <visual>
            <origin xyz="0 1.255650057704888 0" rpy="0 0 0"/>
            <geometry>
                <box size="2.136525568186385 2.511300115409776 2.4125581558654803" />
            </geometry>
            <material name="Blue">
                <color rgba="0 1.0 1.0 1.0"/>
            </material>
        </visual>
        <collision>
            <origin xyz="0 1.255650057704888 0" rpy="0 0 0"/>
            <geometry>
                <box size="2.136525568186385 2.511300115409776 2.4125581558654803" />
            </geometry>
        </collision>
    </link>
    <link name="Leg12">
        <inertial>
            <origin xyz="1.4644035000432274 0 0" rpy="0 0 0"/>
            <mass value="1" />
            <inertia ixx="100" ixy="0" ixz="0" iyy="100" iyz="0" izz="100" />
        </inertial>
        <visual>
            <origin xyz="1.4644035000432274 0 0" rpy="0 0 0"/>
            <geometry>
                <box size="2.928807000086455 2.6883461640508752 2.0259459829239646" />
            </geometry>
            <material name="Blue">
                <color rgba="0 1.0 1.0 1.0"/>
            </material>
        </visual>
        <collision>
            <origin xyz="1.4644035000432274 0 0" rpy="0 0 0"/>
            <geometry>
                <box size="2.928807000086455 2.6883461640508752 2.0259459829239646" />
            </geometry>
        </collision>
    </link>
    <link name="Leg13">
        <inertial>
            <origin xyz="1.4274754490465558 0 0.5852623527137842" rpy="0 0 0"/>
            <mass value="1" />
            <inertia ixx="100" ixy="0" ixz="0" iyy="100" iyz="0" izz="100" />
        </inertial>
        <visual>
            <origin xyz="1.4274754490465558 0 0.5852623527137842" rpy="0 0 0"/>
            <geometry>
                <box size="2.8549508980931115 1.0605219912809312 1.1705247054275685" />
            </geometry>
            <material name="Blue">
                <color rgba="0 1.0 1.0 1.0"/>
            </material>
        </visual>
        <collision>
            <origin xyz="1.4274754490465558 0 0.5852623527137842" rpy="0 0 0"/>
            <geometry>
                <box size="2.8549508980931115 1.0605219912809312 1.1705247054275685" />
            </geometry>
        </collision>
    </link>
    <link name="Leg14">
        <inertial>
            <origin xyz="0 0.6213750862217214 0" rpy="0 0 0"/>
            <mass value="1" />
            <inertia ixx="100" ixy="0" ixz="0" iyy="100" iyz="0" izz="100" />
        </inertial>
        <visual>
            <origin xyz="0 0.6213750862217214 0" rpy="0 0 0"/>
            <geometry>
                <box size="1.5129792296444478 1.2427501724434429 2.0275715128593292" />
            </geometry>
            <material name="Blue">
                <color rgba="0 1.0 1.0 1.0"/>
            </material>
        </visual>
        <collision>
            <origin xyz="0 0.6213750862217214 0" rpy="0 0 0"/>
            <geometry>
                <box size="1.5129792296444478 1.2427501724434429 2.0275715128593292" />
            </geometry>
        </collision>
    </link>
    <link name="Leg15">
        <inertial>
            <origin xyz="0 1.0199804541515596 0" rpy="0 0 0"/>
            <mass value="1" />
            <inertia ixx="100" ixy="0" ixz="0" iyy="100" iyz="0" izz="100" />
        </inertial>
        <visual>
            <origin xyz="0 1.0199804541515596 0" rpy="0 0 0"/>
            <geometry>
                <box size="1.5038757347839622 1.0199804541515596 1.739357866597731" />
            </geometry>
            <material name="Blue">
                <color rgba="0 1.0 1.0 1.0"/>
            </material>
        </visual>
        <collision>
            <origin xyz="0 1.0199804541515596 0" rpy="0 0 0"/>
            <geometry>
                <box size="1.5038757347839622 1.0199804541515596 1.739357866597731" />
            </geometry>
        </collision>
    </link>
    <link name="Leg16">
        <inertial>
            <origin xyz="1.462297046850035 0 0" rpy="0 0 0"/>
            <mass value="1" />
            <inertia ixx="100" ixy="0" ixz="0" iyy="100" iyz="0" izz="100" />
        </inertial>
        <visual>
            <origin xyz="1.462297046850035 0 0" rpy="0 0 0"/>
            <geometry>
                <box size="2.92459409370007 2.9600142617420957 1.9321060288530152" />
            </geometry>
            <material name="Blue">
                <color rgba="0 1.0 1.0 1.0"/>
            </material>
        </visual>
        <collision>
            <origin xyz="1.462297046850035 0 0" rpy="0 0 0"/>
            <geometry>
                <box size="2.92459409370007 2.9600142617420957 1.9321060288530152" />
            </geometry>
        </collision>
    </link>
    <link name="Leg17">
        <inertial>
            <origin xyz="0 1.185579713898325 1.3389909026927673" rpy="0 0 0"/>
            <mass value="1" />
            <inertia ixx="100" ixy="0" ixz="0" iyy="100" iyz="0" izz="100" />
        </inertial>
        <visual>
            <origin xyz="0 1.185579713898325 1.3389909026927673" rpy="0 0 0"/>
            <geometry>
                <box size="1.811038615612102 2.37115942779665 2.6779818053855347" />
            </geometry>
            <material name="Blue">
                <color rgba="0 1.0 1.0 1.0"/>
            </material>
        </visual>
        <collision>
            <origin xyz="0 1.185579713898325 1.3389909026927673" rpy="0 0 0"/>
            <geometry>
                <box size="1.811038615612102 2.37115942779665 2.6779818053855347" />
            </geometry>
        </collision>
    </link>
    <link name="Leg18">
        <inertial>
            <origin xyz="1.265145220349153 0 0" rpy="0 0 0"/>
            <mass value="1" />
            <inertia ixx="100" ixy="0" ixz="0" iyy="100" iyz="0" izz="100" />
        </inertial>
        <visual>
            <origin xyz="1.265145220349153 0 0" rpy="0 0 0"/>
            <geometry>
                <box size="2.530290440698306 1.5220662114104242 1.1627726840501713" />
            </geometry>
            <material name="Blue">
                <color rgba="0 1.0 1.0 1.0"/>
            </material>
        </visual>
        <collision>
            <origin xyz="1.265145220349153 0 0" rpy="0 0 0"/>
            <geometry>
                <box size="2.530290440698306 1.5220662114104242 1.1627726840501713" />
            </geometry>
        </collision>
    </link>
    <link name="Leg19">
        <inertial>
            <origin xyz="0 1.0116721898518162 0" rpy="0 0 0"/>
            <mass value="1" />
            <inertia ixx="100" ixy="0" ixz="0" iyy="100" iyz="0" izz="100" />
        </inertial>
        <visual>
            <origin xyz="0 1.0116721898518162 0" rpy="0 0 0"/>
            <geometry>
                <box size="2.3127409902780065 1.0116721898518162 2.3588408257806104" />
            </geometry>
            <material name="Blue">
                <color rgba="0 1.0 1.0 1.0"/>
            </material>
        </visual>
        <collision>
            <origin xyz="0 1.0116721898518162 0" rpy="0 0 0"/>
            <geometry>
                <box size="2.3127409902780065 1.0116721898518162 2.3588408257806104" />
            </geometry>
        </collision>
    </link>
    <link name="Leg20">
        <inertial>
            <origin xyz="0 0.6491741653401907 0.5099153519743185" rpy="0 0 0"/>
            <mass value="1" />
            <inertia ixx="100" ixy="0" ixz="0" iyy="100" iyz="0" izz="100" />
        </inertial>
        <visual>
            <origin xyz="0 0.6491741653401907 0.5099153519743185" rpy="0 0 0"/>
            <geometry>
                <box size="1.5071623308077418 1.2983483306803814 1.019830703948637" />
            </geometry>
            <material name="Blue">
                <color rgba="0 1.0 1.0 1.0"/>
            </material>
        </visual>
        <collision>
            <origin xyz="0 0.6491741653401907 0.5099153519743185" rpy="0 0 0"/>
            <geometry>
                <box size="1.5071623308077418 1.2983483306803814 1.019830703948637" />
            </geometry>
        </collision>
    </link>
    <link name="Leg21">
        <inertial>
            <origin xyz="0 0 0.5068881229204301" rpy="0 0 0"/>
            <mass value="1" />
            <inertia ixx="100" ixy="0" ixz="0" iyy="100" iyz="0" izz="100" />
        </inertial>
        <visual>
            <origin xyz="0 0 0.5068881229204301" rpy="0 0 0"/>
            <geometry>
                <box size="2.6742052201215722 1.091193707130152 1.0137762458408601" />
            </geometry>
            <material name="Blue">
                <color rgba="0 1.0 1.0 1.0"/>
            </material>
        </visual>
        <collision>
            <origin xyz="0 0 0.5068881229204301" rpy="0 0 0"/>
            <geometry>
                <box size="2.6742052201215722 1.091193707130152 1.0137762458408601" />
            </geometry>
        </collision>
    </link>
    <link name="Leg22">
        <inertial>
            <origin xyz="0 0 1.2130559380973203" rpy="0 0 0"/>
            <mass value="1" />
            <inertia ixx="100" ixy="0" ixz="0" iyy="100" iyz="0" izz="100" />
        </inertial>
        <visual>
            <origin xyz="0 0 1.2130559380973203" rpy="0 0 0"/>
            <geometry>
                <box size="2.994897582197109 2.1455981539800106 2.4261118761946405" />
            </geometry>
            <material name="Blue">
                <color rgba="0 1.0 1.0 1.0"/>
            </material>
        </visual>
        <collision>
            <origin xyz="0 0 1.2130559380973203" rpy="0 0 0"/>
            <geometry>
                <box size="2.994897582197109 2.1455981539800106 2.4261118761946405" />
            </geometry>
        </collision>
    </link>
    <link name="Leg23">
        <inertial>
            <origin xyz="0.6411510535936243 0 0" rpy="0 0 0"/>
            <mass value="1" />
            <inertia ixx="100" ixy="0" ixz="0" iyy="100" iyz="0" izz="100" />
        </inertial>
        <visual>
            <origin xyz="0.6411510535936243 0 0" rpy="0 0 0"/>
            <geometry>
                <box size="1.2823021071872487 1.8942204920355925 1.7689267826964323" />
            </geometry>
            <material name="Blue">
                <color rgba="0 1.0 1.0 1.0"/>
            </material>
        </visual>
        <collision>
            <origin xyz="0.6411510535936243 0 0" rpy="0 0 0"/>
            <geometry>
                <box size="1.2823021071872487 1.8942204920355925 1.7689267826964323" />
            </geometry>
        </collision>
    </link>
    <link name="Leg24">
        <inertial>
            <origin xyz="0 0 0.9120157319225699" rpy="0 0 0"/>
            <mass value="1" />
            <inertia ixx="100" ixy="0" ixz="0" iyy="100" iyz="0" izz="100" />
        </inertial>
        <visual>
            <origin xyz="0 0 0.9120157319225699" rpy="0 0 0"/>
            <geometry>
                <box size="2.6828594807058455 2.6999586629905465 1.8240314638451398" />
            </geometry>
            <material name="Blue">
                <color rgba="0 1.0 1.0 1.0"/>
            </material>
        </visual>
        <collision>
            <origin xyz="0 0 0.9120157319225699" rpy="0 0 0"/>
            <geometry>
                <box size="2.6828594807058455 2.6999586629905465 1.8240314638451398" />
            </geometry>
        </collision>
    </link>
    <link name="Leg25">
        <inertial>
            <origin xyz="0 1.1077799780979993 0" rpy="0 0 0"/>
            <mass value="1" />
            <inertia ixx="100" ixy="0" ixz="0" iyy="100" iyz="0" izz="100" />
        </inertial>
        <visual>
            <origin xyz="0 1.1077799780979993 0" rpy="0 0 0"/>
            <geometry>
                <box size="1.9090568728436326 2.2155599561959987 1.2913630269382774" />
            </geometry>
            <material name="Green">
                <color rgba="0 180.0 100.0 1.0"/>
            </material>
        </visual>
        <collision>
            <origin xyz="0 1.1077799780979993 0" rpy="0 0 0"/>
            <geometry>
                <box size="1.9090568728436326 2.2155599561959987 1.2913630269382774" />
            </geometry>
        </collision>
    </link>
    <joint name="Torso_Leg1" type="revolute">
       <parent link="Torso"/>
       <child  link="Leg1"/>
       <origin rpy="0 0 0" xyz="0 0.6045867454262728 0.5000716225324188" />
     <axis xyz="1 0 0"/>
       <limit effort="0.0" lower="-3.14159" upper="3.14159" velocity="0.0"/>
    </joint>
    <joint name="Torso_Leg2" type="revolute">
       <parent link="Torso"/>
       <child  link="Leg2"/>
       <origin rpy="0 0 0" xyz="0.9220051057922886 1.256524777770641 0" />
     <axis xyz="1 0 0"/>
       <limit effort="0.0" lower="-3.14159" upper="3.14159" velocity="0.0"/>
    </joint>
    <joint name="Leg2_Leg3" type="revolute">
       <parent link="Leg2"/>
       <child  link="Leg3"/>
       <origin rpy="0 0 0" xyz="1.2273435173091416 1.3059216445400736 1.5434598522980107" />
     <axis xyz="1 0 0"/>
       <limit effort="0.0" lower="-3.14159" upper="3.14159" velocity="0.0"/>
    </joint>
    <joint name="Leg3_Leg4" type="revolute">
       <parent link="Leg3"/>
       <child  link="Leg4"/>
       <origin rpy="0 0 0" xyz="2.23053855751853 0.8736924738009557 0" />
     <axis xyz="1 0 0"/>
       <limit effort="0.0" lower="-3.14159" upper="3.14159" velocity="0.0"/>
    </joint>
    <joint name="Leg1_Leg5" type="revolute">
       <parent link="Leg1"/>
       <child  link="Leg5"/>
       <origin rpy="0 0 0" xyz="2.863628502816508 0.8973629599641022 1.0271726649369484" />
     <axis xyz="1 0 0"/>
       <limit effort="0.0" lower="-3.14159" upper="3.14159" velocity="0.0"/>
    </joint>
    <joint name="Leg4_Leg6" type="revolute">
       <parent link="Leg4"/>
       <child  link="Leg6"/>
       <origin rpy="0 0 0" xyz="0.5271132149271602 0.5883352935719638 1.6515466408218116" />
     <axis xyz="1 0 0"/>
       <limit effort="0.0" lower="-3.14159" upper="3.14159" velocity="0.0"/>
    </joint>
    <joint name="Leg5_Leg7" type="revolute">
       <parent link="Leg5"/>
       <child  link="Leg7"/>
       <origin rpy="0 0 0" xyz="0.5387685330636345 1.9229453943162993 0.5538740190184536" />
     <axis xyz="1 0 0"/>
       <limit effort="0.0" lower="-3.14159" upper="3.14159" velocity="0.0"/>
    </joint>
    <joint name="Leg4_Leg8" type="revolute">
       <parent link="Leg4"/>
       <child  link="Leg8"/>
       <origin rpy="0 0 0" xyz="0.5271132149271602 0.5883352935719638 1.6515466408218116" />
     <axis xyz="1 0 0"/>
       <limit effort="0.0" lower="-3.14159" upper="3.14159" velocity="0.0"/>
    </joint>
    <joint name="Leg4_Leg9" type="revolute">
       <parent link="Leg4"/>
       <child  link="Leg9"/>
       <origin rpy="0 0 0" xyz="0.5271132149271602 0.5883352935719638 1.6515466408218116" />
     <axis xyz="1 0 0"/>
       <limit effort="0.0" lower="-3.14159" upper="3.14159" velocity="0.0"/>
    </joint>
    <joint name="Leg5_Leg10" type="revolute">
       <parent link="Leg5"/>
       <child  link="Leg10"/>
       <origin rpy="0 0 0" xyz="0.5387685330636345 1.9229453943162993 0.5538740190184536" />
     <axis xyz="1 0 0"/>
       <limit effort="0.0" lower="-3.14159" upper="3.14159" velocity="0.0"/>
    </joint>
    <joint name="Leg2_Leg11" type="revolute">
       <parent link="Leg2"/>
       <child  link="Leg11"/>
       <origin rpy="0 0 0" xyz="1.2273435173091416 1.3059216445400736 1.5434598522980107" />
     <axis xyz="1 0 0"/>
       <limit effort="0.0" lower="-3.14159" upper="3.14159" velocity="0.0"/>
    </joint>
    <joint name="Leg6_Leg12" type="revolute">
       <parent link="Leg6"/>
       <child  link="Leg12"/>
       <origin rpy="0 0 0" xyz="0.5901122385709173 0.7166643389241238 0" />
     <axis xyz="1 0 0"/>
       <limit effort="0.0" lower="-3.14159" upper="3.14159" velocity="0.0"/>
    </joint>
    <joint name="Leg9_Leg13" type="revolute">
       <parent link="Leg9"/>
       <child  link="Leg13"/>
       <origin rpy="0 0 0" xyz="1.4489468181916725 0 0.5444836508668386" />
     <axis xyz="1 0 0"/>
       <limit effort="0.0" lower="-3.14159" upper="3.14159" velocity="0.0"/>
    </joint>
    <joint name="Leg1_Leg14" type="revolute">
       <parent link="Leg1"/>
       <child  link="Leg14"/>
       <origin rpy="0 0 0" xyz="2.863628502816508 0.8973629599641022 1.0271726649369484" />
     <axis xyz="1 0 0"/>
       <limit effort="0.0" lower="-3.14159" upper="3.14159" velocity="0.0"/>
    </joint>
    <joint name="Leg3_Leg15" type="revolute">
       <parent link="Leg3"/>
       <child  link="Leg15"/>
       <origin rpy="0 0 0" xyz="2.23053855751853 0.8736924738009557 0" />
     <axis xyz="1 0 0"/>
       <limit effort="0.0" lower="-3.14159" upper="3.14159" velocity="0.0"/>
    </joint>
    <joint name="Leg12_Leg16" type="revolute">
       <parent link="Leg12"/>
       <child  link="Leg16"/>
       <origin rpy="0 0 0" xyz="1.4274754490465558 0 0.5852623527137842" />
     <axis xyz="1 0 0"/>
       <limit effort="0.0" lower="-3.14159" upper="3.14159" velocity="0.0"/>
    </joint>
    <joint name="Leg14_Leg17" type="revolute">
       <parent link="Leg14"/>
       <child  link="Leg17"/>
       <origin rpy="0 0 0" xyz="0 1.0199804541515596 0" />
     <axis xyz="1 0 0"/>
       <limit effort="0.0" lower="-3.14159" upper="3.14159" velocity="0.0"/>
    </joint>
    <joint name="Leg1_Leg18" type="revolute">
       <parent link="Leg1"/>
       <child  link="Leg18"/>
       <origin rpy="0 0 0" xyz="2.863628502816508 0.8973629599641022 1.0271726649369484" />
     <axis xyz="1 0 0"/>
       <limit effort="0.0" lower="-3.14159" upper="3.14159" velocity="0.0"/>
    </joint>
    <joint name="Leg18_Leg19" type="revolute">
       <parent link="Leg18"/>
       <child  link="Leg19"/>
       <origin rpy="0 0 0" xyz="0 1.0116721898518162 0" />
     <axis xyz="1 0 0"/>
       <limit effort="0.0" lower="-3.14159" upper="3.14159" velocity="0.0"/>
    </joint>
    <joint name="Leg8_Leg20" type="revolute">
       <parent link="Leg8"/>
       <child  link="Leg20"/>
       <origin rpy="0 0 0" xyz="0 1.4234866055993374 1.373555669167179" />
     <axis xyz="1 0 0"/>
       <limit effort="0.0" lower="-3.14159" upper="3.14159" velocity="0.0"/>
    </joint>
    <joint name="Leg16_Leg21" type="revolute">
       <parent link="Leg16"/>
       <child  link="Leg21"/>
       <origin rpy="0 0 0" xyz="0 1.185579713898325 1.3389909026927673" />
     <axis xyz="1 0 0"/>
       <limit effort="0.0" lower="-3.14159" upper="3.14159" velocity="0.0"/>
    </joint>
    <joint name="Leg5_Leg22" type="revolute">
       <parent link="Leg5"/>
       <child  link="Leg22"/>
       <origin rpy="0 0 0" xyz="0.5387685330636345 1.9229453943162993 0.5538740190184536" />
     <axis xyz="1 0 0"/>
       <limit effort="0.0" lower="-3.14159" upper="3.14159" velocity="0.0"/>
    </joint>
    <joint name="Leg2_Leg23" type="revolute">
       <parent link="Leg2"/>
       <child  link="Leg23"/>
       <origin rpy="0 0 0" xyz="1.2273435173091416 1.3059216445400736 1.5434598522980107" />
     <axis xyz="1 0 0"/>
       <limit effort="0.0" lower="-3.14159" upper="3.14159" velocity="0.0"/>
    </joint>
    <joint name="Leg19_Leg24" type="revolute">
       <parent link="Leg19"/>
       <child  link="Leg24"/>
       <origin rpy="0 0 0" xyz="0 0.6491741653401907 0.5099153519743185" />
     <axis xyz="1 0 0"/>
       <limit effort="0.0" lower="-3.14159" upper="3.14159" velocity="0.0"/>
    </joint>
    <joint name="Leg24_Leg25" type="revolute">
       <parent link="Leg24"/>
       <child  link="Leg24"/>
       <origin rpy="0 0 0" xyz="0 1.3499793314952733 0.9120157319225699" />
     <axis xyz="1 0 0"/>
       <limit effort="0.0" lower="-3.14159" upper="3.14159" velocity="0.0"/>
    </joint>
</robot>