<robot name = "robot">
    <link name="Torso">
        <inertial>
            <origin xyz="0 0 1.2759158382078803" rpy="0 0 0"/>
            <mass value="1" />
            <inertia ixx="100" ixy="0" ixz="0" iyy="100" iyz="0" izz="100" />
        </inertial>
        <visual>
            <origin xyz="0 0 1.2759158382078803" rpy="0 0 0"/>
            <geometry>
                <box size="1.8720768652223665 1.456616770941623 2.5518316764157607" />
            </geometry>
            <material name="Green">
                <color rgba="0 180.0 0.0 1.0"/>
            </material>
        </visual>
        <collision>
            <origin xyz="0 0 1.2759158382078803" rpy="0 0 0"/>
            <geometry>
                <box size="1.8720768652223665 1.456616770941623 2.5518316764157607" />
            </geometry>
        </collision>
    </link>
    <link name="Leg1">
        <inertial>
            <origin xyz="1.4106566990118041 0 0" rpy="0 0 0"/>
            <mass value="1" />
            <inertia ixx="100" ixy="0" ixz="0" iyy="100" iyz="0" izz="100" />
        </inertial>
        <visual>
            <origin xyz="1.4106566990118041 0 0" rpy="0 0 0"/>
            <geometry>
                <box size="2.8213133980236083 2.8525673086672736 2.212746444944237" />
            </geometry>
            <material name="Green">
                <color rgba="0 180.0 0.0 1.0"/>
            </material>
        </visual>
        <collision>
            <origin xyz="1.4106566990118041 0 0" rpy="0 0 0"/>
            <geometry>
                <box size="2.8213133980236083 2.8525673086672736 2.212746444944237" />
            </geometry>
        </collision>
    </link>
    <link name="Leg2">
        <inertial>
            <origin xyz="1.1675217315496622 0 0" rpy="0 0 0"/>
            <mass value="1" />
            <inertia ixx="100" ixy="0" ixz="0" iyy="100" iyz="0" izz="100" />
        </inertial>
        <visual>
            <origin xyz="1.1675217315496622 0 0" rpy="0 0 0"/>
            <geometry>
                <box size="2.3350434630993244 1.613756414004985 2.3197328121018472" />
            </geometry>
            <material name="Green">
                <color rgba="0 180.0 0.0 1.0"/>
            </material>
        </visual>
        <collision>
            <origin xyz="1.1675217315496622 0 0" rpy="0 0 0"/>
            <geometry>
                <box size="2.3350434630993244 1.613756414004985 2.3197328121018472" />
            </geometry>
        </collision>
    </link>
    <link name="Leg3">
        <inertial>
            <origin xyz="0 0 0.5340675208636183" rpy="0 0 0"/>
            <mass value="1" />
            <inertia ixx="100" ixy="0" ixz="0" iyy="100" iyz="0" izz="100" />
        </inertial>
        <visual>
            <origin xyz="0 0 0.5340675208636183" rpy="0 0 0"/>
            <geometry>
                <box size="2.314038269423388 1.2738004230428048 1.0681350417272366" />
            </geometry>
            <material name="Blue">
                <color rgba="0 1.0 1.0 1.0"/>
            </material>
        </visual>
        <collision>
            <origin xyz="0 0 0.5340675208636183" rpy="0 0 0"/>
            <geometry>
                <box size="2.314038269423388 1.2738004230428048 1.0681350417272366" />
            </geometry>
        </collision>
    </link>
    <link name="Leg4">
        <inertial>
            <origin xyz="1.1017041199406798 0 0" rpy="0 0 0"/>
            <mass value="1" />
            <inertia ixx="100" ixy="0" ixz="0" iyy="100" iyz="0" izz="100" />
        </inertial>
        <visual>
            <origin xyz="1.1017041199406798 0 0" rpy="0 0 0"/>
            <geometry>
                <box size="2.2034082398813597 1.5862471822536395 1.9251200693184107" />
            </geometry>
            <material name="Green">
                <color rgba="0 180.0 0.0 1.0"/>
            </material>
        </visual>
        <collision>
            <origin xyz="1.1017041199406798 0 0" rpy="0 0 0"/>
            <geometry>
                <box size="2.2034082398813597 1.5862471822536395 1.9251200693184107" />
            </geometry>
        </collision>
    </link>
    <link name="Leg5">
        <inertial>
            <origin xyz="0 0.5333252944122913 0" rpy="0 0 0"/>
            <mass value="1" />
            <inertia ixx="100" ixy="0" ixz="0" iyy="100" iyz="0" izz="100" />
        </inertial>
        <visual>
            <origin xyz="0 0.5333252944122913 0" rpy="0 0 0"/>
            <geometry>
                <box size="2.2374945227653003 1.0666505888245825 2.1703238956354127" />
            </geometry>
            <material name="Blue">
                <color rgba="0 1.0 1.0 1.0"/>
            </material>
        </visual>
        <collision>
            <origin xyz="0 0.5333252944122913 0" rpy="0 0 0"/>
            <geometry>
                <box size="2.2374945227653003 1.0666505888245825 2.1703238956354127" />
            </geometry>
        </collision>
    </link>
    <link name="Leg6">
        <inertial>
            <origin xyz="1.14598426457674 0 0" rpy="0 0 0"/>
            <mass value="1" />
            <inertia ixx="100" ixy="0" ixz="0" iyy="100" iyz="0" izz="100" />
        </inertial>
        <visual>
            <origin xyz="1.14598426457674 0 0" rpy="0 0 0"/>
            <geometry>
                <box size="2.29196852915348 2.706202030615903 2.5739473912936397" />
            </geometry>
            <material name="Blue">
                <color rgba="0 1.0 1.0 1.0"/>
            </material>
        </visual>
        <collision>
            <origin xyz="1.14598426457674 0 0" rpy="0 0 0"/>
            <geometry>
                <box size="2.29196852915348 2.706202030615903 2.5739473912936397" />
            </geometry>
        </collision>
    </link>
    <link name="Leg7">
        <inertial>
            <origin xyz="0 1.3194922045402226 0" rpy="0 0 0"/>
            <mass value="1" />
            <inertia ixx="100" ixy="0" ixz="0" iyy="100" iyz="0" izz="100" />
        </inertial>
        <visual>
            <origin xyz="0 1.3194922045402226 0" rpy="0 0 0"/>
            <geometry>
                <box size="1.4424233606816996 2.6389844090804453 1.730611366724436" />
            </geometry>
            <material name="Green">
                <color rgba="0 180.0 0.0 1.0"/>
            </material>
        </visual>
        <collision>
            <origin xyz="0 1.3194922045402226 0" rpy="0 0 0"/>
            <geometry>
                <box size="1.4424233606816996 2.6389844090804453 1.730611366724436" />
            </geometry>
        </collision>
    </link>
    <link name="Leg8">
        <inertial>
            <origin xyz="0.8296825892788116 0 0" rpy="0 0 0"/>
            <mass value="1" />
            <inertia ixx="100" ixy="0" ixz="0" iyy="100" iyz="0" izz="100" />
        </inertial>
        <visual>
            <origin xyz="0.8296825892788116 0 0" rpy="0 0 0"/>
            <geometry>
                <box size="1.659365178557623 2.7348848554014236 1.3872797141257234" />
            </geometry>
            <material name="Blue">
                <color rgba="0 1.0 1.0 1.0"/>
            </material>
        </visual>
        <collision>
            <origin xyz="0.8296825892788116 0 0" rpy="0 0 0"/>
            <geometry>
                <box size="1.659365178557623 2.7348848554014236 1.3872797141257234" />
            </geometry>
        </collision>
    </link>
    <link name="Leg9">
        <inertial>
            <origin xyz="0 0 0.634094389241172" rpy="0 0 0"/>
            <mass value="1" />
            <inertia ixx="100" ixy="0" ixz="0" iyy="100" iyz="0" izz="100" />
        </inertial>
        <visual>
            <origin xyz="0 0 0.634094389241172" rpy="0 0 0"/>
            <geometry>
                <box size="1.3858463932216387 1.507624853114147 1.268188778482344" />
            </geometry>
            <material name="Green">
                <color rgba="0 180.0 0.0 1.0"/>
            </material>
        </visual>
        <collision>
            <origin xyz="0 0 0.634094389241172" rpy="0 0 0"/>
            <geometry>
                <box size="1.3858463932216387 1.507624853114147 1.268188778482344" />
            </geometry>
        </collision>
    </link>
    <link name="Leg10">
        <inertial>
            <origin xyz="0 0.5747049733279792 0" rpy="0 0 0"/>
            <mass value="1" />
            <inertia ixx="100" ixy="0" ixz="0" iyy="100" iyz="0" izz="100" />
        </inertial>
        <visual>
            <origin xyz="0 0.5747049733279792 0" rpy="0 0 0"/>
            <geometry>
                <box size="1.126212023261134 1.1494099466559584 2.6576040077659187" />
            </geometry>
            <material name="Green">
                <color rgba="0 180.0 0.0 1.0"/>
            </material>
        </visual>
        <collision>
            <origin xyz="0 0.5747049733279792 0" rpy="0 0 0"/>
            <geometry>
                <box size="1.126212023261134 1.1494099466559584 2.6576040077659187" />
            </geometry>
        </collision>
    </link>
    <link name="Leg11">
        <inertial>
            <origin xyz="0.7195387308905263 0 0" rpy="0 0 0"/>
            <mass value="1" />
            <inertia ixx="100" ixy="0" ixz="0" iyy="100" iyz="0" izz="100" />
        </inertial>
        <visual>
            <origin xyz="0.7195387308905263 0 0" rpy="0 0 0"/>
            <geometry>
                <box size="1.4390774617810527 1.4269412816589415 1.0794755805506948" />
            </geometry>
            <material name="Green">
                <color rgba="0 180.0 0.0 1.0"/>
            </material>
        </visual>
        <collision>
            <origin xyz="0.7195387308905263 0 0" rpy="0 0 0"/>
            <geometry>
                <box size="1.4390774617810527 1.4269412816589415 1.0794755805506948" />
            </geometry>
        </collision>
    </link>
    <link name="Leg12">
        <inertial>
            <origin xyz="0 0 0.7286985632926112" rpy="0 0 0"/>
            <mass value="1" />
            <inertia ixx="100" ixy="0" ixz="0" iyy="100" iyz="0" izz="100" />
        </inertial>
        <visual>
            <origin xyz="0 0 0.7286985632926112" rpy="0 0 0"/>
            <geometry>
                <box size="2.3606673091398296 1.4237138395611035 1.4573971265852224" />
            </geometry>
            <material name="Blue">
                <color rgba="0 1.0 1.0 1.0"/>
            </material>
        </visual>
        <collision>
            <origin xyz="0 0 0.7286985632926112" rpy="0 0 0"/>
            <geometry>
                <box size="2.3606673091398296 1.4237138395611035 1.4573971265852224" />
            </geometry>
        </collision>
    </link>
    <link name="Leg13">
        <inertial>
            <origin xyz="0 1.0450350585058081 0" rpy="0 0 0"/>
            <mass value="1" />
            <inertia ixx="100" ixy="0" ixz="0" iyy="100" iyz="0" izz="100" />
        </inertial>
        <visual>
            <origin xyz="0 1.0450350585058081 0" rpy="0 0 0"/>
            <geometry>
                <box size="1.5205343667676714 2.0900701170116163 1.923000521406385" />
            </geometry>
            <material name="Blue">
                <color rgba="0 1.0 1.0 1.0"/>
            </material>
        </visual>
        <collision>
            <origin xyz="0 1.0450350585058081 0" rpy="0 0 0"/>
            <geometry>
                <box size="1.5205343667676714 2.0900701170116163 1.923000521406385" />
            </geometry>
        </collision>
    </link>
    <link name="Leg14">
        <inertial>
            <origin xyz="0 0 0.9652572425262317" rpy="0 0 0"/>
            <mass value="1" />
            <inertia ixx="100" ixy="0" ixz="0" iyy="100" iyz="0" izz="100" />
        </inertial>
        <visual>
            <origin xyz="0 0 0.9652572425262317" rpy="0 0 0"/>
            <geometry>
                <box size="1.6503320427922683 2.461916037854383 1.9305144850524634" />
            </geometry>
            <material name="Green">
                <color rgba="0 180.0 0.0 1.0"/>
            </material>
        </visual>
        <collision>
            <origin xyz="0 0 0.9652572425262317" rpy="0 0 0"/>
            <geometry>
                <box size="1.6503320427922683 2.461916037854383 1.9305144850524634" />
            </geometry>
        </collision>
    </link>
    <link name="Leg15">
        <inertial>
            <origin xyz="0 0.8045804984866105 0" rpy="0 0 0"/>
            <mass value="1" />
            <inertia ixx="100" ixy="0" ixz="0" iyy="100" iyz="0" izz="100" />
        </inertial>
        <visual>
            <origin xyz="0 0.8045804984866105 0" rpy="0 0 0"/>
            <geometry>
                <box size="1.5359192676344842 1.609160996973221 1.517881470826903" />
            </geometry>
            <material name="Blue">
                <color rgba="0 1.0 1.0 1.0"/>
            </material>
        </visual>
        <collision>
            <origin xyz="0 0.8045804984866105 0" rpy="0 0 0"/>
            <geometry>
                <box size="1.5359192676344842 1.609160996973221 1.517881470826903" />
            </geometry>
        </collision>
    </link>
    <link name="Leg16">
        <inertial>
            <origin xyz="1.0721031517594939 0 0" rpy="0 0 0"/>
            <mass value="1" />
            <inertia ixx="100" ixy="0" ixz="0" iyy="100" iyz="0" izz="100" />
        </inertial>
        <visual>
            <origin xyz="1.0721031517594939 0 0" rpy="0 0 0"/>
            <geometry>
                <box size="2.1442063035189878 1.7555266686914048 1.8820713542016245" />
            </geometry>
            <material name="Green">
                <color rgba="0 180.0 0.0 1.0"/>
            </material>
        </visual>
        <collision>
            <origin xyz="1.0721031517594939 0 0" rpy="0 0 0"/>
            <geometry>
                <box size="2.1442063035189878 1.7555266686914048 1.8820713542016245" />
            </geometry>
        </collision>
    </link>
    <link name="Leg17">
        <inertial>
            <origin xyz="0.9232185061514796 0 0" rpy="0 0 0"/>
            <mass value="1" />
            <inertia ixx="100" ixy="0" ixz="0" iyy="100" iyz="0" izz="100" />
        </inertial>
        <visual>
            <origin xyz="0.9232185061514796 0 0" rpy="0 0 0"/>
            <geometry>
                <box size="1.8464370123029592 2.8898326902762816 1.0936274996954458" />
            </geometry>
            <material name="Blue">
                <color rgba="0 1.0 1.0 1.0"/>
            </material>
        </visual>
        <collision>
            <origin xyz="0.9232185061514796 0 0" rpy="0 0 0"/>
            <geometry>
                <box size="1.8464370123029592 2.8898326902762816 1.0936274996954458" />
            </geometry>
        </collision>
    </link>
    <link name="Leg18">
        <inertial>
            <origin xyz="0 0 0.7092697191173963" rpy="0 0 0"/>
            <mass value="1" />
            <inertia ixx="100" ixy="0" ixz="0" iyy="100" iyz="0" izz="100" />
        </inertial>
        <visual>
            <origin xyz="0 0 0.7092697191173963" rpy="0 0 0"/>
            <geometry>
                <box size="1.068926122138926 2.046280828273898 1.4185394382347927" />
            </geometry>
            <material name="Green">
                <color rgba="0 180.0 0.0 1.0"/>
            </material>
        </visual>
        <collision>
            <origin xyz="0 0 0.7092697191173963" rpy="0 0 0"/>
            <geometry>
                <box size="1.068926122138926 2.046280828273898 1.4185394382347927" />
            </geometry>
        </collision>
    </link>
    <link name="Leg19">
        <inertial>
            <origin xyz="0 0.7014993731240703 0" rpy="0 0 0"/>
            <mass value="1" />
            <inertia ixx="100" ixy="0" ixz="0" iyy="100" iyz="0" izz="100" />
        </inertial>
        <visual>
            <origin xyz="0 0.7014993731240703 0" rpy="0 0 0"/>
            <geometry>
                <box size="1.7105235088703146 1.4029987462481406 2.6783410948311173" />
            </geometry>
            <material name="Blue">
                <color rgba="0 1.0 1.0 1.0"/>
            </material>
        </visual>
        <collision>
            <origin xyz="0 0.7014993731240703 0" rpy="0 0 0"/>
            <geometry>
                <box size="1.7105235088703146 1.4029987462481406 2.6783410948311173" />
            </geometry>
        </collision>
    </link>
    <link name="Leg20">
        <inertial>
            <origin xyz="0 1.287950486592726 0" rpy="0 0 0"/>
            <mass value="1" />
            <inertia ixx="100" ixy="0" ixz="0" iyy="100" iyz="0" izz="100" />
        </inertial>
        <visual>
            <origin xyz="0 1.287950486592726 0" rpy="0 0 0"/>
            <geometry>
                <box size="1.838033189674885 2.575900973185452 2.17115511390657" />
            </geometry>
            <material name="Blue">
                <color rgba="0 1.0 1.0 1.0"/>
            </material>
        </visual>
        <collision>
            <origin xyz="0 1.287950486592726 0" rpy="0 0 0"/>
            <geometry>
                <box size="1.838033189674885 2.575900973185452 2.17115511390657" />
            </geometry>
        </collision>
    </link>
    <link name="Leg21">
        <inertial>
            <origin xyz="0 0 1.4588794534631448" rpy="0 0 0"/>
            <mass value="1" />
            <inertia ixx="100" ixy="0" ixz="0" iyy="100" iyz="0" izz="100" />
        </inertial>
        <visual>
            <origin xyz="0 0 1.4588794534631448" rpy="0 0 0"/>
            <geometry>
                <box size="1.8287184023910557 1.0956999071977092 2.9177589069262897" />
            </geometry>
            <material name="Blue">
                <color rgba="0 1.0 1.0 1.0"/>
            </material>
        </visual>
        <collision>
            <origin xyz="0 0 1.4588794534631448" rpy="0 0 0"/>
            <geometry>
                <box size="1.8287184023910557 1.0956999071977092 2.9177589069262897" />
            </geometry>
        </collision>
    </link>
    <link name="Leg22">
        <inertial>
            <origin xyz="0.6418269755518659 0 0" rpy="0 0 0"/>
            <mass value="1" />
            <inertia ixx="100" ixy="0" ixz="0" iyy="100" iyz="0" izz="100" />
        </inertial>
        <visual>
            <origin xyz="0.6418269755518659 0 0" rpy="0 0 0"/>
            <geometry>
                <box size="1.2836539511037317 2.593408697307308 2.0568963753708385" />
            </geometry>
            <material name="Green">
                <color rgba="0 180.0 0.0 1.0"/>
            </material>
        </visual>
        <collision>
            <origin xyz="0.6418269755518659 0 0" rpy="0 0 0"/>
            <geometry>
                <box size="1.2836539511037317 2.593408697307308 2.0568963753708385" />
            </geometry>
        </collision>
    </link>
    <link name="Leg23">
        <inertial>
            <origin xyz="0.7022340679566925 0 0" rpy="0 0 0"/>
            <mass value="1" />
            <inertia ixx="100" ixy="0" ixz="0" iyy="100" iyz="0" izz="100" />
        </inertial>
        <visual>
            <origin xyz="0.7022340679566925 0 0" rpy="0 0 0"/>
            <geometry>
                <box size="1.404468135913385 1.4345709440998773 2.9710359064635163" />
            </geometry>
            <material name="Blue">
                <color rgba="0 1.0 1.0 1.0"/>
            </material>
        </visual>
        <collision>
            <origin xyz="0.7022340679566925 0 0" rpy="0 0 0"/>
            <geometry>
                <box size="1.404468135913385 1.4345709440998773 2.9710359064635163" />
            </geometry>
        </collision>
    </link>
    <link name="Leg24">
        <inertial>
            <origin xyz="1.0246315388317129 0 0" rpy="0 0 0"/>
            <mass value="1" />
            <inertia ixx="100" ixy="0" ixz="0" iyy="100" iyz="0" izz="100" />
        </inertial>
        <visual>
            <origin xyz="1.0246315388317129 0 0" rpy="0 0 0"/>
            <geometry>
                <box size="2.0492630776634257 2.45764632171171 1.5307280772588518" />
            </geometry>
            <material name="Green">
                <color rgba="0 180.0 0.0 1.0"/>
            </material>
        </visual>
        <collision>
            <origin xyz="1.0246315388317129 0 0" rpy="0 0 0"/>
            <geometry>
                <box size="2.0492630776634257 2.45764632171171 1.5307280772588518" />
            </geometry>
        </collision>
    </link>
    <link name="Leg25">
        <inertial>
            <origin xyz="0 1.2800942073117412 0" rpy="0 0 0"/>
            <mass value="1" />
            <inertia ixx="100" ixy="0" ixz="0" iyy="100" iyz="0" izz="100" />
        </inertial>
        <visual>
            <origin xyz="0 1.2800942073117412 0" rpy="0 0 0"/>
            <geometry>
                <box size="2.253730776803673 2.5601884146234823 1.172887743478018" />
            </geometry>
            <material name="Blue">
                <color rgba="0 1.0 1.0 1.0"/>
            </material>
        </visual>
        <collision>
            <origin xyz="0 1.2800942073117412 0" rpy="0 0 0"/>
            <geometry>
                <box size="2.253730776803673 2.5601884146234823 1.172887743478018" />
            </geometry>
        </collision>
    </link>
    <link name="Leg26">
        <inertial>
            <origin xyz="0 1.1880646559385473 0" rpy="0 0 0"/>
            <mass value="1" />
            <inertia ixx="100" ixy="0" ixz="0" iyy="100" iyz="0" izz="100" />
        </inertial>
        <visual>
            <origin xyz="0 1.1880646559385473 0" rpy="0 0 0"/>
            <geometry>
                <box size="2.3981263826230816 2.3761293118770945 2.8854204858135732" />
            </geometry>
            <material name="Blue">
                <color rgba="0 1.0 1.0 1.0"/>
            </material>
        </visual>
        <collision>
            <origin xyz="0 1.1880646559385473 0" rpy="0 0 0"/>
            <geometry>
                <box size="2.3981263826230816 2.3761293118770945 2.8854204858135732" />
            </geometry>
        </collision>
    </link>
    <joint name="Torso_Leg1" type="revolute">
       <parent link="Torso"/>
       <child  link="Leg1"/>
       <origin rpy="0 0 0" xyz="0.9360384326111832 0 1.2759158382078803" />
     <axis xyz="1 0 0"/>
       <limit effort="0.0" lower="-3.14159" upper="3.14159" velocity="0.0"/>
    </joint>
    <joint name="Leg1_Leg2" type="revolute">
       <parent link="Leg1"/>
       <child  link="Leg2"/>
       <origin rpy="0 0 0" xyz="2.3350434630993244 0 0" />
     <axis xyz="1 0 0"/>
       <limit effort="0.0" lower="-3.14159" upper="3.14159" velocity="0.0"/>
    </joint>
    <joint name="Leg1_Leg3" type="revolute">
       <parent link="Leg1"/>
       <child  link="Leg3"/>
       <origin rpy="0 0 0" xyz="2.3350434630993244 0 1.1598664060509236" />
     <axis xyz="1 0 0"/>
       <limit effort="0.0" lower="-3.14159" upper="3.14159" velocity="0.0"/>
    </joint>
    <joint name="Leg3_Leg4" type="revolute">
       <parent link="Leg3"/>
       <child  link="Leg4"/>
       <origin rpy="0 0 0" xyz="2.2034082398813597 0 0" />
     <axis xyz="1 0 0"/>
       <limit effort="0.0" lower="-3.14159" upper="3.14159" velocity="0.0"/>
    </joint>
    <joint name="Torso_Leg5" type="revolute">
       <parent link="Torso"/>
       <child  link="Leg5"/>
       <origin rpy="0 0 0" xyz="1.4106566990118041 1.4262836543336368 0" />
     <axis xyz="1 0 0"/>
       <limit effort="0.0" lower="-3.14159" upper="3.14159" velocity="0.0"/>
    </joint>
    <joint name="Leg5_Leg6" type="revolute">
       <parent link="Leg5"/>
       <child  link="Leg6"/>
       <origin rpy="0 0 0" xyz="2.29196852915348 0 0" />
     <axis xyz="1 0 0"/>
       <limit effort="0.0" lower="-3.14159" upper="3.14159" velocity="0.0"/>
    </joint>
    <joint name="Leg1_Leg7" type="revolute">
       <parent link="Leg1"/>
       <child  link="Leg7"/>
       <origin rpy="0 0 0" xyz="2.3350434630993244 0.8068782070024925 1.1598664060509236" />
     <axis xyz="1 0 0"/>
       <limit effort="0.0" lower="-3.14159" upper="3.14159" velocity="0.0"/>
    </joint>
    <joint name="Leg7_Leg8" type="revolute">
       <parent link="Leg7"/>
       <child  link="Leg8"/>
       <origin rpy="0 0 0" xyz="1.659365178557623 0 0" />
     <axis xyz="1 0 0"/>
       <limit effort="0.0" lower="-3.14159" upper="3.14159" velocity="0.0"/>
    </joint>
    <joint name="Leg2_Leg9" type="revolute">
       <parent link="Leg2"/>
       <child  link="Leg9"/>
       <origin rpy="0 0 0" xyz="0 0 1.0681350417272366" />
     <axis xyz="1 0 0"/>
       <limit effort="0.0" lower="-3.14159" upper="3.14159" velocity="0.0"/>
    </joint>
    <joint name="Leg5_Leg10" type="revolute">
       <parent link="Leg5"/>
       <child  link="Leg10"/>
       <origin rpy="0 0 0" xyz="2.29196852915348 1.3531010153079515 0" />
     <axis xyz="1 0 0"/>
       <limit effort="0.0" lower="-3.14159" upper="3.14159" velocity="0.0"/>
    </joint>
    <joint name="Leg10_Leg11" type="revolute">
       <parent link="Leg10"/>
       <child  link="Leg11"/>
       <origin rpy="0 0 0" xyz="1.4390774617810527 0 0" />
     <axis xyz="1 0 0"/>
       <limit effort="0.0" lower="-3.14159" upper="3.14159" velocity="0.0"/>
    </joint>
    <joint name="Leg8_Leg12" type="revolute">
       <parent link="Leg8"/>
       <child  link="Leg12"/>
       <origin rpy="0 0 0" xyz="0 0 1.268188778482344" />
     <axis xyz="1 0 0"/>
       <limit effort="0.0" lower="-3.14159" upper="3.14159" velocity="0.0"/>
    </joint>
    <joint name="Leg2_Leg13" type="revolute">
       <parent link="Leg2"/>
       <child  link="Leg13"/>
       <origin rpy="0 0 0" xyz="0 0.6369002115214024 1.0681350417272366" />
     <axis xyz="1 0 0"/>
       <limit effort="0.0" lower="-3.14159" upper="3.14159" velocity="0.0"/>
    </joint>
    <joint name="Leg7_Leg14" type="revolute">
       <parent link="Leg7"/>
       <child  link="Leg14"/>
       <origin rpy="0 0 0" xyz="1.659365178557623 0 0.6936398570628617" />
     <axis xyz="1 0 0"/>
       <limit effort="0.0" lower="-3.14159" upper="3.14159" velocity="0.0"/>
    </joint>
    <joint name="Leg6_Leg15" type="revolute">
       <parent link="Leg6"/>
       <child  link="Leg15"/>
       <origin rpy="0 0 0" xyz="0 2.6389844090804453 0" />
     <axis xyz="1 0 0"/>
       <limit effort="0.0" lower="-3.14159" upper="3.14159" velocity="0.0"/>
    </joint>
    <joint name="Leg9_Leg16" type="revolute">
       <parent link="Leg9"/>
       <child  link="Leg16"/>
       <origin rpy="0 0 0" xyz="0.563106011630567 0.5747049733279792 0" />
     <axis xyz="1 0 0"/>
       <limit effort="0.0" lower="-3.14159" upper="3.14159" velocity="0.0"/>
    </joint>
    <joint name="Leg11_Leg17" type="revolute">
       <parent link="Leg11"/>
       <child  link="Leg17"/>
       <origin rpy="0 0 0" xyz="1.1803336545699148 0 0.7286985632926112" />
     <axis xyz="1 0 0"/>
       <limit effort="0.0" lower="-3.14159" upper="3.14159" velocity="0.0"/>
    </joint>
    <joint name="Leg3_Leg18" type="revolute">
       <parent link="Leg3"/>
       <child  link="Leg18"/>
       <origin rpy="0 0 0" xyz="2.2034082398813597 0 0.9625600346592054" />
     <axis xyz="1 0 0"/>
       <limit effort="0.0" lower="-3.14159" upper="3.14159" velocity="0.0"/>
    </joint>
    <joint name="Leg8_Leg19" type="revolute">
       <parent link="Leg8"/>
       <child  link="Leg19"/>
       <origin rpy="0 0 0" xyz="0 0.7538124265570735 1.268188778482344" />
     <axis xyz="1 0 0"/>
       <limit effort="0.0" lower="-3.14159" upper="3.14159" velocity="0.0"/>
    </joint>
    <joint name="Leg13_Leg20" type="revolute">
       <parent link="Leg13"/>
       <child  link="Leg20"/>
       <origin rpy="0 0 0" xyz="0 1.2309580189271916 0.9652572425262317" />
     <axis xyz="1 0 0"/>
       <limit effort="0.0" lower="-3.14159" upper="3.14159" velocity="0.0"/>
    </joint>
    <joint name="Leg19_Leg21" type="revolute">
       <parent link="Leg19"/>
       <child  link="Leg21"/>
       <origin rpy="0 0 0" xyz="0 1.287950486592726 1.085577556953285" />
     <axis xyz="1 0 0"/>
       <limit effort="0.0" lower="-3.14159" upper="3.14159" velocity="0.0"/>
    </joint>
    <joint name="Leg6_Leg22" type="revolute">
       <parent link="Leg6"/>
       <child  link="Leg22"/>
       <origin rpy="0 0 0" xyz="0.7212116803408498 2.6389844090804453 0" />
     <axis xyz="1 0 0"/>
       <limit effort="0.0" lower="-3.14159" upper="3.14159" velocity="0.0"/>
    </joint>
    <joint name="Leg8_Leg23" type="revolute">
       <parent link="Leg8"/>
       <child  link="Leg23"/>
       <origin rpy="0 0 0" xyz="0.6929231966108194 0.7538124265570735 1.268188778482344" />
     <axis xyz="1 0 0"/>
       <limit effort="0.0" lower="-3.14159" upper="3.14159" velocity="0.0"/>
    </joint>
    <joint name="Leg12_Leg24" type="revolute">
       <parent link="Leg12"/>
       <child  link="Leg24"/>
       <origin rpy="0 0 0" xyz="0.7602671833838357 1.0450350585058081 0" />
     <axis xyz="1 0 0"/>
       <limit effort="0.0" lower="-3.14159" upper="3.14159" velocity="0.0"/>
    </joint>
    <joint name="Leg11_Leg25" type="revolute">
       <parent link="Leg11"/>
       <child  link="Leg25"/>
       <origin rpy="0 0 0" xyz="1.1803336545699148 0.7118569197805518 0.7286985632926112" />
     <axis xyz="1 0 0"/>
       <limit effort="0.0" lower="-3.14159" upper="3.14159" velocity="0.0"/>
    </joint>
    <joint name="Leg25_Leg26" type="revolute">
       <parent link="Leg25"/>
       <child  link="Leg26"/>
       <origin rpy="0 0 0" xyz="0 2.3761293118770945 0" />
     <axis xyz="1 0 0"/>
       <limit effort="0.0" lower="-3.14159" upper="3.14159" velocity="0.0"/>
    </joint>
</robot>