<robot name = "robot">
    <link name="Torso">
        <inertial>
            <origin xyz="0 0 1.2041292020981371" rpy="0 0 0"/>
            <mass value="1" />
            <inertia ixx="100" ixy="0" ixz="0" iyy="100" iyz="0" izz="100" />
        </inertial>
        <visual>
            <origin xyz="0 0 1.2041292020981371" rpy="0 0 0"/>
            <geometry>
                <box size="2.1172304941767948 1.1347533608479792 2.4082584041962742" />
            </geometry>
            <material name="Green">
                <color rgba="0 180.0 0.0 1.0"/>
            </material>
        </visual>
        <collision>
            <origin xyz="0 0 1.2041292020981371" rpy="0 0 0"/>
            <geometry>
                <box size="2.1172304941767948 1.1347533608479792 2.4082584041962742" />
            </geometry>
        </collision>
    </link>
    <link name="Leg1">
        <inertial>
            <origin xyz="0 0.7468652803211788 0" rpy="0 0 0"/>
            <mass value="1" />
            <inertia ixx="100" ixy="0" ixz="0" iyy="100" iyz="0" izz="100" />
        </inertial>
        <visual>
            <origin xyz="0 0.7468652803211788 0" rpy="0 0 0"/>
            <geometry>
                <box size="2.90283576967163 1.4937305606423577 1.6999882084678817" />
            </geometry>
            <material name="Blue">
                <color rgba="0 1.0 1.0 1.0"/>
            </material>
        </visual>
        <collision>
            <origin xyz="0 0.7468652803211788 0" rpy="0 0 0"/>
            <geometry>
                <box size="2.90283576967163 1.4937305606423577 1.6999882084678817" />
            </geometry>
        </collision>
    </link>
    <link name="Leg2">
        <inertial>
            <origin xyz="0.7906673070228332 0 0" rpy="0 0 0"/>
            <mass value="1" />
            <inertia ixx="100" ixy="0" ixz="0" iyy="100" iyz="0" izz="100" />
        </inertial>
        <visual>
            <origin xyz="0.7906673070228332 0 0" rpy="0 0 0"/>
            <geometry>
                <box size="1.5813346140456663 2.471060253142805 2.962117417259936" />
            </geometry>
            <material name="Green">
                <color rgba="0 180.0 0.0 1.0"/>
            </material>
        </visual>
        <collision>
            <origin xyz="0.7906673070228332 0 0" rpy="0 0 0"/>
            <geometry>
                <box size="1.5813346140456663 2.471060253142805 2.962117417259936" />
            </geometry>
        </collision>
    </link>
    <link name="Leg3">
        <inertial>
            <origin xyz="0.8340140413093708 0 0" rpy="0 0 0"/>
            <mass value="1" />
            <inertia ixx="100" ixy="0" ixz="0" iyy="100" iyz="0" izz="100" />
        </inertial>
        <visual>
            <origin xyz="0.8340140413093708 0 0" rpy="0 0 0"/>
            <geometry>
                <box size="1.6680280826187417 2.3271292576958107 2.4625674383030196" />
            </geometry>
            <material name="Blue">
                <color rgba="0 1.0 1.0 1.0"/>
            </material>
        </visual>
        <collision>
            <origin xyz="0.8340140413093708 0 0" rpy="0 0 0"/>
            <geometry>
                <box size="1.6680280826187417 2.3271292576958107 2.4625674383030196" />
            </geometry>
        </collision>
    </link>
    <link name="Leg4">
        <inertial>
            <origin xyz="0 0 0.7209908153417246" rpy="0 0 0"/>
            <mass value="1" />
            <inertia ixx="100" ixy="0" ixz="0" iyy="100" iyz="0" izz="100" />
        </inertial>
        <visual>
            <origin xyz="0 0 0.7209908153417246" rpy="0 0 0"/>
            <geometry>
                <box size="2.700593743384902 2.238306280609459 1.4419816306834492" />
            </geometry>
            <material name="Green">
                <color rgba="0 180.0 0.0 1.0"/>
            </material>
        </visual>
        <collision>
            <origin xyz="0 0 0.7209908153417246" rpy="0 0 0"/>
            <geometry>
                <box size="2.700593743384902 2.238306280609459 1.4419816306834492" />
            </geometry>
        </collision>
    </link>
    <link name="Leg5">
        <inertial>
            <origin xyz="0 1.1239372400608092 0" rpy="0 0 0"/>
            <mass value="1" />
            <inertia ixx="100" ixy="0" ixz="0" iyy="100" iyz="0" izz="100" />
        </inertial>
        <visual>
            <origin xyz="0 1.1239372400608092 0" rpy="0 0 0"/>
            <geometry>
                <box size="1.1552888806037764 2.2478744801216184 2.7626469318996665" />
            </geometry>
            <material name="Green">
                <color rgba="0 180.0 0.0 1.0"/>
            </material>
        </visual>
        <collision>
            <origin xyz="0 1.1239372400608092 0" rpy="0 0 0"/>
            <geometry>
                <box size="1.1552888806037764 2.2478744801216184 2.7626469318996665" />
            </geometry>
        </collision>
    </link>
    <link name="Leg6">
        <inertial>
            <origin xyz="0.8032335220799001 0 0" rpy="0 0 0"/>
            <mass value="1" />
            <inertia ixx="100" ixy="0" ixz="0" iyy="100" iyz="0" izz="100" />
        </inertial>
        <visual>
            <origin xyz="0.8032335220799001 0 0" rpy="0 0 0"/>
            <geometry>
                <box size="1.6064670441598001 2.024893839428906 2.425735710262206" />
            </geometry>
            <material name="Green">
                <color rgba="0 180.0 0.0 1.0"/>
            </material>
        </visual>
        <collision>
            <origin xyz="0.8032335220799001 0 0" rpy="0 0 0"/>
            <geometry>
                <box size="1.6064670441598001 2.024893839428906 2.425735710262206" />
            </geometry>
        </collision>
    </link>
    <link name="Leg7">
        <inertial>
            <origin xyz="0 0.6904015321852145 0" rpy="0 0 0"/>
            <mass value="1" />
            <inertia ixx="100" ixy="0" ixz="0" iyy="100" iyz="0" izz="100" />
        </inertial>
        <visual>
            <origin xyz="0 0.6904015321852145 0" rpy="0 0 0"/>
            <geometry>
                <box size="1.8149108403751746 1.380803064370429 2.2995607532671536" />
            </geometry>
            <material name="Blue">
                <color rgba="0 1.0 1.0 1.0"/>
            </material>
        </visual>
        <collision>
            <origin xyz="0 0.6904015321852145 0" rpy="0 0 0"/>
            <geometry>
                <box size="1.8149108403751746 1.380803064370429 2.2995607532671536" />
            </geometry>
        </collision>
    </link>
    <link name="Leg8">
        <inertial>
            <origin xyz="0.7792692516063753 0 0" rpy="0 0 0"/>
            <mass value="1" />
            <inertia ixx="100" ixy="0" ixz="0" iyy="100" iyz="0" izz="100" />
        </inertial>
        <visual>
            <origin xyz="0.7792692516063753 0 0" rpy="0 0 0"/>
            <geometry>
                <box size="1.5585385032127506 1.0959571795824274 1.4479698354806103" />
            </geometry>
            <material name="Green">
                <color rgba="0 180.0 0.0 1.0"/>
            </material>
        </visual>
        <collision>
            <origin xyz="0.7792692516063753 0 0" rpy="0 0 0"/>
            <geometry>
                <box size="1.5585385032127506 1.0959571795824274 1.4479698354806103" />
            </geometry>
        </collision>
    </link>
    <link name="Leg9">
        <inertial>
            <origin xyz="1.3806374730550086 0 0" rpy="0 0 0"/>
            <mass value="1" />
            <inertia ixx="100" ixy="0" ixz="0" iyy="100" iyz="0" izz="100" />
        </inertial>
        <visual>
            <origin xyz="1.3806374730550086 0 0" rpy="0 0 0"/>
            <geometry>
                <box size="2.7612749461100172 1.6341708290488903 2.1589784192747867" />
            </geometry>
            <material name="Green">
                <color rgba="0 180.0 0.0 1.0"/>
            </material>
        </visual>
        <collision>
            <origin xyz="1.3806374730550086 0 0" rpy="0 0 0"/>
            <geometry>
                <box size="2.7612749461100172 1.6341708290488903 2.1589784192747867" />
            </geometry>
        </collision>
    </link>
    <link name="Leg10">
        <inertial>
            <origin xyz="1.2925101120398819 0 0" rpy="0 0 0"/>
            <mass value="1" />
            <inertia ixx="100" ixy="0" ixz="0" iyy="100" iyz="0" izz="100" />
        </inertial>
        <visual>
            <origin xyz="1.2925101120398819 0 0" rpy="0 0 0"/>
            <geometry>
                <box size="2.5850202240797637 1.1305515002668443 1.5029877046574172" />
            </geometry>
            <material name="Green">
                <color rgba="0 180.0 0.0 1.0"/>
            </material>
        </visual>
        <collision>
            <origin xyz="1.2925101120398819 0 0" rpy="0 0 0"/>
            <geometry>
                <box size="2.5850202240797637 1.1305515002668443 1.5029877046574172" />
            </geometry>
        </collision>
    </link>
    <link name="Leg11">
        <inertial>
            <origin xyz="0.7075830096857229 0 0" rpy="0 0 0"/>
            <mass value="1" />
            <inertia ixx="100" ixy="0" ixz="0" iyy="100" iyz="0" izz="100" />
        </inertial>
        <visual>
            <origin xyz="0.7075830096857229 0 0" rpy="0 0 0"/>
            <geometry>
                <box size="1.4151660193714457 2.139105855418667 1.7339636814615882" />
            </geometry>
            <material name="Green">
                <color rgba="0 180.0 0.0 1.0"/>
            </material>
        </visual>
        <collision>
            <origin xyz="0.7075830096857229 0 0" rpy="0 0 0"/>
            <geometry>
                <box size="1.4151660193714457 2.139105855418667 1.7339636814615882" />
            </geometry>
        </collision>
    </link>
    <link name="Leg12">
        <inertial>
            <origin xyz="0 0.7599548698259826 0" rpy="0 0 0"/>
            <mass value="1" />
            <inertia ixx="100" ixy="0" ixz="0" iyy="100" iyz="0" izz="100" />
        </inertial>
        <visual>
            <origin xyz="0 0.7599548698259826 0" rpy="0 0 0"/>
            <geometry>
                <box size="1.385578913149796 1.5199097396519652 2.7124183895092355" />
            </geometry>
            <material name="Blue">
                <color rgba="0 1.0 1.0 1.0"/>
            </material>
        </visual>
        <collision>
            <origin xyz="0 0.7599548698259826 0" rpy="0 0 0"/>
            <geometry>
                <box size="1.385578913149796 1.5199097396519652 2.7124183895092355" />
            </geometry>
        </collision>
    </link>
    <link name="Leg13">
        <inertial>
            <origin xyz="0 0.8180092253549016 0" rpy="0 0 0"/>
            <mass value="1" />
            <inertia ixx="100" ixy="0" ixz="0" iyy="100" iyz="0" izz="100" />
        </inertial>
        <visual>
            <origin xyz="0 0.8180092253549016 0" rpy="0 0 0"/>
            <geometry>
                <box size="1.8574961861282433 1.6360184507098032 1.8551767406469368" />
            </geometry>
            <material name="Green">
                <color rgba="0 180.0 0.0 1.0"/>
            </material>
        </visual>
        <collision>
            <origin xyz="0 0.8180092253549016 0" rpy="0 0 0"/>
            <geometry>
                <box size="1.8574961861282433 1.6360184507098032 1.8551767406469368" />
            </geometry>
        </collision>
    </link>
    <link name="Leg14">
        <inertial>
            <origin xyz="0.5492682838147958 0 0" rpy="0 0 0"/>
            <mass value="1" />
            <inertia ixx="100" ixy="0" ixz="0" iyy="100" iyz="0" izz="100" />
        </inertial>
        <visual>
            <origin xyz="0.5492682838147958 0 0" rpy="0 0 0"/>
            <geometry>
                <box size="1.0985365676295915 2.783790968844206 1.4462679843564625" />
            </geometry>
            <material name="Green">
                <color rgba="0 180.0 0.0 1.0"/>
            </material>
        </visual>
        <collision>
            <origin xyz="0.5492682838147958 0 0" rpy="0 0 0"/>
            <geometry>
                <box size="1.0985365676295915 2.783790968844206 1.4462679843564625" />
            </geometry>
        </collision>
    </link>
    <link name="Leg15">
        <inertial>
            <origin xyz="1.3681188572443193 0 0" rpy="0 0 0"/>
            <mass value="1" />
            <inertia ixx="100" ixy="0" ixz="0" iyy="100" iyz="0" izz="100" />
        </inertial>
        <visual>
            <origin xyz="1.3681188572443193 0 0" rpy="0 0 0"/>
            <geometry>
                <box size="2.7362377144886385 2.4193761993990446 2.0468403201715284" />
            </geometry>
            <material name="Blue">
                <color rgba="0 1.0 1.0 1.0"/>
            </material>
        </visual>
        <collision>
            <origin xyz="1.3681188572443193 0 0" rpy="0 0 0"/>
            <geometry>
                <box size="2.7362377144886385 2.4193761993990446 2.0468403201715284" />
            </geometry>
        </collision>
    </link>
    <link name="Leg16">
        <inertial>
            <origin xyz="1.2649635798347638 0 0" rpy="0 0 0"/>
            <mass value="1" />
            <inertia ixx="100" ixy="0" ixz="0" iyy="100" iyz="0" izz="100" />
        </inertial>
        <visual>
            <origin xyz="1.2649635798347638 0 0" rpy="0 0 0"/>
            <geometry>
                <box size="2.5299271596695276 2.4277167485015836 2.5208076409755193" />
            </geometry>
            <material name="Blue">
                <color rgba="0 1.0 1.0 1.0"/>
            </material>
        </visual>
        <collision>
            <origin xyz="1.2649635798347638 0 0" rpy="0 0 0"/>
            <geometry>
                <box size="2.5299271596695276 2.4277167485015836 2.5208076409755193" />
            </geometry>
        </collision>
    </link>
    <link name="Leg17">
        <inertial>
            <origin xyz="0 0 0.9650633318482125" rpy="0 0 0"/>
            <mass value="1" />
            <inertia ixx="100" ixy="0" ixz="0" iyy="100" iyz="0" izz="100" />
        </inertial>
        <visual>
            <origin xyz="0 0 0.9650633318482125" rpy="0 0 0"/>
            <geometry>
                <box size="1.233174700136054 1.1350648028677641 1.930126663696425" />
            </geometry>
            <material name="Blue">
                <color rgba="0 1.0 1.0 1.0"/>
            </material>
        </visual>
        <collision>
            <origin xyz="0 0 0.9650633318482125" rpy="0 0 0"/>
            <geometry>
                <box size="1.233174700136054 1.1350648028677641 1.930126663696425" />
            </geometry>
        </collision>
    </link>
    <link name="Leg18">
        <inertial>
            <origin xyz="0 0.565342243739708 0" rpy="0 0 0"/>
            <mass value="1" />
            <inertia ixx="100" ixy="0" ixz="0" iyy="100" iyz="0" izz="100" />
        </inertial>
        <visual>
            <origin xyz="0 0.565342243739708 0" rpy="0 0 0"/>
            <geometry>
                <box size="2.98093354802376 1.130684487479416 1.5789208199720521" />
            </geometry>
            <material name="Blue">
                <color rgba="0 1.0 1.0 1.0"/>
            </material>
        </visual>
        <collision>
            <origin xyz="0 0.565342243739708 0" rpy="0 0 0"/>
            <geometry>
                <box size="2.98093354802376 1.130684487479416 1.5789208199720521" />
            </geometry>
        </collision>
    </link>
    <link name="Leg19">
        <inertial>
            <origin xyz="1.0870764721388713 0 0" rpy="0 0 0"/>
            <mass value="1" />
            <inertia ixx="100" ixy="0" ixz="0" iyy="100" iyz="0" izz="100" />
        </inertial>
        <visual>
            <origin xyz="1.0870764721388713 0 0" rpy="0 0 0"/>
            <geometry>
                <box size="2.1741529442777425 1.965256735220511 2.2145367349082465" />
            </geometry>
            <material name="Blue">
                <color rgba="0 1.0 1.0 1.0"/>
            </material>
        </visual>
        <collision>
            <origin xyz="1.0870764721388713 0 0" rpy="0 0 0"/>
            <geometry>
                <box size="2.1741529442777425 1.965256735220511 2.2145367349082465" />
            </geometry>
        </collision>
    </link>
    <link name="Leg20">
        <inertial>
            <origin xyz="1.4578901871938779 0 0" rpy="0 0 0"/>
            <mass value="1" />
            <inertia ixx="100" ixy="0" ixz="0" iyy="100" iyz="0" izz="100" />
        </inertial>
        <visual>
            <origin xyz="1.4578901871938779 0 0" rpy="0 0 0"/>
            <geometry>
                <box size="2.9157803743877557 1.6578200496770679 1.209326365934281" />
            </geometry>
            <material name="Blue">
                <color rgba="0 1.0 1.0 1.0"/>
            </material>
        </visual>
        <collision>
            <origin xyz="1.4578901871938779 0 0" rpy="0 0 0"/>
            <geometry>
                <box size="2.9157803743877557 1.6578200496770679 1.209326365934281" />
            </geometry>
        </collision>
    </link>
    <link name="Leg21">
        <inertial>
            <origin xyz="0 0.613020574565354 0" rpy="0 0 0"/>
            <mass value="1" />
            <inertia ixx="100" ixy="0" ixz="0" iyy="100" iyz="0" izz="100" />
        </inertial>
        <visual>
            <origin xyz="0 0.613020574565354 0" rpy="0 0 0"/>
            <geometry>
                <box size="2.3997803982435855 1.226041149130708 2.426101614474857" />
            </geometry>
            <material name="Blue">
                <color rgba="0 1.0 1.0 1.0"/>
            </material>
        </visual>
        <collision>
            <origin xyz="0 0.613020574565354 0" rpy="0 0 0"/>
            <geometry>
                <box size="2.3997803982435855 1.226041149130708 2.426101614474857" />
            </geometry>
        </collision>
    </link>
    <link name="Leg22">
        <inertial>
            <origin xyz="0.7928117746684527 0 0" rpy="0 0 0"/>
            <mass value="1" />
            <inertia ixx="100" ixy="0" ixz="0" iyy="100" iyz="0" izz="100" />
        </inertial>
        <visual>
            <origin xyz="0.7928117746684527 0 0" rpy="0 0 0"/>
            <geometry>
                <box size="1.5856235493369053 1.4759645201146143 2.0873233175273844" />
            </geometry>
            <material name="Blue">
                <color rgba="0 1.0 1.0 1.0"/>
            </material>
        </visual>
        <collision>
            <origin xyz="0.7928117746684527 0 0" rpy="0 0 0"/>
            <geometry>
                <box size="1.5856235493369053 1.4759645201146143 2.0873233175273844" />
            </geometry>
        </collision>
    </link>
    <link name="Leg23">
        <inertial>
            <origin xyz="0.6455258954764136 0 0" rpy="0 0 0"/>
            <mass value="1" />
            <inertia ixx="100" ixy="0" ixz="0" iyy="100" iyz="0" izz="100" />
        </inertial>
        <visual>
            <origin xyz="0.6455258954764136 0 0" rpy="0 0 0"/>
            <geometry>
                <box size="1.2910517909528272 1.2277126830649978 1.634344638849152" />
            </geometry>
            <material name="Blue">
                <color rgba="0 1.0 1.0 1.0"/>
            </material>
        </visual>
        <collision>
            <origin xyz="0.6455258954764136 0 0" rpy="0 0 0"/>
            <geometry>
                <box size="1.2910517909528272 1.2277126830649978 1.634344638849152" />
            </geometry>
        </collision>
    </link>
    <link name="Leg24">
        <inertial>
            <origin xyz="0 0.8106506556010328 0" rpy="0 0 0"/>
            <mass value="1" />
            <inertia ixx="100" ixy="0" ixz="0" iyy="100" iyz="0" izz="100" />
        </inertial>
        <visual>
            <origin xyz="0 0.8106506556010328 0" rpy="0 0 0"/>
            <geometry>
                <box size="1.5030258707461956 1.6213013112020656 2.936118069008449" />
            </geometry>
            <material name="Green">
                <color rgba="0 180.0 0.0 1.0"/>
            </material>
        </visual>
        <collision>
            <origin xyz="0 0.8106506556010328 0" rpy="0 0 0"/>
            <geometry>
                <box size="1.5030258707461956 1.6213013112020656 2.936118069008449" />
            </geometry>
        </collision>
    </link>
    <link name="Leg25">
        <inertial>
            <origin xyz="1.3959370475923372 0 0" rpy="0 0 0"/>
            <mass value="1" />
            <inertia ixx="100" ixy="0" ixz="0" iyy="100" iyz="0" izz="100" />
        </inertial>
        <visual>
            <origin xyz="1.3959370475923372 0 0" rpy="0 0 0"/>
            <geometry>
                <box size="2.7918740951846743 2.4242978124149905 2.9191458025446577" />
            </geometry>
            <material name="Blue">
                <color rgba="0 1.0 1.0 1.0"/>
            </material>
        </visual>
        <collision>
            <origin xyz="1.3959370475923372 0 0" rpy="0 0 0"/>
            <geometry>
                <box size="2.7918740951846743 2.4242978124149905 2.9191458025446577" />
            </geometry>
        </collision>
    </link>
    <joint name="Torso_Leg1" type="revolute">
       <parent link="Torso"/>
       <child  link="Leg1"/>
       <origin rpy="0 0 0" xyz="0 0.5673766804239896 1.2041292020981371" />
     <axis xyz="1 0 0"/>
       <limit effort="0.0" lower="-3.14159" upper="3.14159" velocity="0.0"/>
    </joint>
    <joint name="Torso_Leg2" type="revolute">
       <parent link="Torso"/>
       <child  link="Leg2"/>
       <origin rpy="0 0 0" xyz="1.451417884835815 0.7468652803211788 0" />
     <axis xyz="1 0 0"/>
       <limit effort="0.0" lower="-3.14159" upper="3.14159" velocity="0.0"/>
    </joint>
    <joint name="Leg2_Leg3" type="revolute">
       <parent link="Leg2"/>
       <child  link="Leg3"/>
       <origin rpy="0 0 0" xyz="1.6680280826187417 0 0" />
     <axis xyz="1 0 0"/>
       <limit effort="0.0" lower="-3.14159" upper="3.14159" velocity="0.0"/>
    </joint>
    <joint name="Leg3_Leg4" type="revolute">
       <parent link="Leg3"/>
       <child  link="Leg4"/>
       <origin rpy="0 0 0" xyz="0 0 1.4419816306834492" />
     <axis xyz="1 0 0"/>
       <limit effort="0.0" lower="-3.14159" upper="3.14159" velocity="0.0"/>
    </joint>
    <joint name="Leg3_Leg5" type="revolute">
       <parent link="Leg3"/>
       <child  link="Leg5"/>
       <origin rpy="0 0 0" xyz="0 1.1191531403047295 1.4419816306834492" />
     <axis xyz="1 0 0"/>
       <limit effort="0.0" lower="-3.14159" upper="3.14159" velocity="0.0"/>
    </joint>
    <joint name="Leg3_Leg6" type="revolute">
       <parent link="Leg3"/>
       <child  link="Leg6"/>
       <origin rpy="0 0 0" xyz="1.350296871692451 1.1191531403047295 1.4419816306834492" />
     <axis xyz="1 0 0"/>
       <limit effort="0.0" lower="-3.14159" upper="3.14159" velocity="0.0"/>
    </joint>
    <joint name="Leg2_Leg7" type="revolute">
       <parent link="Leg2"/>
       <child  link="Leg7"/>
       <origin rpy="0 0 0" xyz="1.6680280826187417 1.1635646288479053 0" />
     <axis xyz="1 0 0"/>
       <limit effort="0.0" lower="-3.14159" upper="3.14159" velocity="0.0"/>
    </joint>
    <joint name="Leg1_Leg8" type="revolute">
       <parent link="Leg1"/>
       <child  link="Leg8"/>
       <origin rpy="0 0 0" xyz="1.5813346140456663 0 0" />
     <axis xyz="1 0 0"/>
       <limit effort="0.0" lower="-3.14159" upper="3.14159" velocity="0.0"/>
    </joint>
    <joint name="Leg6_Leg9" type="revolute">
       <parent link="Leg6"/>
       <child  link="Leg9"/>
       <origin rpy="0 0 0" xyz="0.9074554201875873 0.6904015321852145 0" />
     <axis xyz="1 0 0"/>
       <limit effort="0.0" lower="-3.14159" upper="3.14159" velocity="0.0"/>
    </joint>
    <joint name="Leg5_Leg10" type="revolute">
       <parent link="Leg5"/>
       <child  link="Leg10"/>
       <origin rpy="0 0 0" xyz="1.6064670441598001 0 0" />
     <axis xyz="1 0 0"/>
       <limit effort="0.0" lower="-3.14159" upper="3.14159" velocity="0.0"/>
    </joint>
    <joint name="Leg8_Leg11" type="revolute">
       <parent link="Leg8"/>
       <child  link="Leg11"/>
       <origin rpy="0 0 0" xyz="2.7612749461100172 0 0" />
     <axis xyz="1 0 0"/>
       <limit effort="0.0" lower="-3.14159" upper="3.14159" velocity="0.0"/>
    </joint>
    <joint name="Leg1_Leg12" type="revolute">
       <parent link="Leg1"/>
       <child  link="Leg12"/>
       <origin rpy="0 0 0" xyz="1.5813346140456663 1.2355301265714025 0" />
     <axis xyz="1 0 0"/>
       <limit effort="0.0" lower="-3.14159" upper="3.14159" velocity="0.0"/>
    </joint>
    <joint name="Leg6_Leg13" type="revolute">
       <parent link="Leg6"/>
       <child  link="Leg13"/>
       <origin rpy="0 0 0" xyz="0.9074554201875873 1.380803064370429 0" />
     <axis xyz="1 0 0"/>
       <limit effort="0.0" lower="-3.14159" upper="3.14159" velocity="0.0"/>
    </joint>
    <joint name="Leg10_Leg14" type="revolute">
       <parent link="Leg10"/>
       <child  link="Leg14"/>
       <origin rpy="0 0 0" xyz="1.4151660193714457 0 0" />
     <axis xyz="1 0 0"/>
       <limit effort="0.0" lower="-3.14159" upper="3.14159" velocity="0.0"/>
    </joint>
    <joint name="Leg7_Leg15" type="revolute">
       <parent link="Leg7"/>
       <child  link="Leg15"/>
       <origin rpy="0 0 0" xyz="1.5585385032127506 0 0" />
     <axis xyz="1 0 0"/>
       <limit effort="0.0" lower="-3.14159" upper="3.14159" velocity="0.0"/>
    </joint>
    <joint name="Leg14_Leg16" type="revolute">
       <parent link="Leg14"/>
       <child  link="Leg16"/>
       <origin rpy="0 0 0" xyz="2.7362377144886385 0 0" />
     <axis xyz="1 0 0"/>
       <limit effort="0.0" lower="-3.14159" upper="3.14159" velocity="0.0"/>
    </joint>
    <joint name="Leg16_Leg17" type="revolute">
       <parent link="Leg16"/>
       <child  link="Leg17"/>
       <origin rpy="0 0 0" xyz="0 0 1.930126663696425" />
     <axis xyz="1 0 0"/>
       <limit effort="0.0" lower="-3.14159" upper="3.14159" velocity="0.0"/>
    </joint>
    <joint name="Leg5_Leg18" type="revolute">
       <parent link="Leg5"/>
       <child  link="Leg18"/>
       <origin rpy="0 0 0" xyz="1.6064670441598001 1.012446919714453 0" />
     <axis xyz="1 0 0"/>
       <limit effort="0.0" lower="-3.14159" upper="3.14159" velocity="0.0"/>
    </joint>
    <joint name="Leg15_Leg19" type="revolute">
       <parent link="Leg15"/>
       <child  link="Leg19"/>
       <origin rpy="0 0 0" xyz="2.5299271596695276 0 0" />
     <axis xyz="1 0 0"/>
       <limit effort="0.0" lower="-3.14159" upper="3.14159" velocity="0.0"/>
    </joint>
    <joint name="Leg19_Leg20" type="revolute">
       <parent link="Leg19"/>
       <child  link="Leg20"/>
       <origin rpy="0 0 0" xyz="2.9157803743877557 0 0" />
     <axis xyz="1 0 0"/>
       <limit effort="0.0" lower="-3.14159" upper="3.14159" velocity="0.0"/>
    </joint>
    <joint name="Leg15_Leg21" type="revolute">
       <parent link="Leg15"/>
       <child  link="Leg21"/>
       <origin rpy="0 0 0" xyz="2.5299271596695276 1.2138583742507918 0" />
     <axis xyz="1 0 0"/>
       <limit effort="0.0" lower="-3.14159" upper="3.14159" velocity="0.0"/>
    </joint>
    <joint name="Leg4_Leg22" type="revolute">
       <parent link="Leg4"/>
       <child  link="Leg22"/>
       <origin rpy="0 0 0" xyz="0.5776444403018882 1.1239372400608092 0" />
     <axis xyz="1 0 0"/>
       <limit effort="0.0" lower="-3.14159" upper="3.14159" velocity="0.0"/>
    </joint>
    <joint name="Leg12_Leg23" type="revolute">
       <parent link="Leg12"/>
       <child  link="Leg23"/>
       <origin rpy="0 0 0" xyz="0.9287480930641216 0.8180092253549016 0" />
     <axis xyz="1 0 0"/>
       <limit effort="0.0" lower="-3.14159" upper="3.14159" velocity="0.0"/>
    </joint>
    <joint name="Leg9_Leg24" type="revolute">
       <parent link="Leg9"/>
       <child  link="Leg24"/>
       <origin rpy="0 0 0" xyz="1.2925101120398819 0.5652757501334221 0" />
     <axis xyz="1 0 0"/>
       <limit effort="0.0" lower="-3.14159" upper="3.14159" velocity="0.0"/>
    </joint>
    <joint name="Leg11_Leg25" type="revolute">
       <parent link="Leg11"/>
       <child  link="Leg25"/>
       <origin rpy="0 0 0" xyz="0.692789456574898 0.7599548698259826 0" />
     <axis xyz="1 0 0"/>
       <limit effort="0.0" lower="-3.14159" upper="3.14159" velocity="0.0"/>
    </joint>
</robot>