<robot name = "robot">
    <link name="Torso">
        <inertial>
            <origin xyz="0 0 1.1338451307865667" rpy="0 0 0"/>
            <mass value="1" />
            <inertia ixx="100" ixy="0" ixz="0" iyy="100" iyz="0" izz="100" />
        </inertial>
        <visual>
            <origin xyz="0 0 1.1338451307865667" rpy="0 0 0"/>
            <geometry>
                <box size="1.2650258282292066 1.6378781003316045 2.2676902615731334" />
            </geometry>
            <material name="Green">
                <color rgba="0 180.0 0.0 1.0"/>
            </material>
        </visual>
        <collision>
            <origin xyz="0 0 1.1338451307865667" rpy="0 0 0"/>
            <geometry>
                <box size="1.2650258282292066 1.6378781003316045 2.2676902615731334" />
            </geometry>
        </collision>
    </link>
    <link name="Leg1">
        <inertial>
            <origin xyz="0 0 1.2237956253176554" rpy="0 0 0"/>
            <mass value="1" />
            <inertia ixx="100" ixy="0" ixz="0" iyy="100" iyz="0" izz="100" />
        </inertial>
        <visual>
            <origin xyz="0 0 1.2237956253176554" rpy="0 0 0"/>
            <geometry>
                <box size="2.695405833993786 1.3827877969010285 2.447591250635311" />
            </geometry>
            <material name="Green">
                <color rgba="0 180.0 0.0 1.0"/>
            </material>
        </visual>
        <collision>
            <origin xyz="0 0 1.2237956253176554" rpy="0 0 0"/>
            <geometry>
                <box size="2.695405833993786 1.3827877969010285 2.447591250635311" />
            </geometry>
        </collision>
    </link>
    <link name="Leg2">
        <inertial>
            <origin xyz="0.7813408280966262 0 0" rpy="0 0 0"/>
            <mass value="1" />
            <inertia ixx="100" ixy="0" ixz="0" iyy="100" iyz="0" izz="100" />
        </inertial>
        <visual>
            <origin xyz="0.7813408280966262 0 0" rpy="0 0 0"/>
            <geometry>
                <box size="1.5626816561932524 1.5531820499631508 2.8290946289844214" />
            </geometry>
            <material name="Blue">
                <color rgba="0 1.0 1.0 1.0"/>
            </material>
        </visual>
        <collision>
            <origin xyz="0.7813408280966262 0 0" rpy="0 0 0"/>
            <geometry>
                <box size="1.5626816561932524 1.5531820499631508 2.8290946289844214" />
            </geometry>
        </collision>
    </link>
    <link name="Leg3">
        <inertial>
            <origin xyz="0 0 0.7886557115458425" rpy="0 0 0"/>
            <mass value="1" />
            <inertia ixx="100" ixy="0" ixz="0" iyy="100" iyz="0" izz="100" />
        </inertial>
        <visual>
            <origin xyz="0 0 0.7886557115458425" rpy="0 0 0"/>
            <geometry>
                <box size="2.093107649272789 2.9793824419712593 1.577311423091685" />
            </geometry>
            <material name="Blue">
                <color rgba="0 1.0 1.0 1.0"/>
            </material>
        </visual>
        <collision>
            <origin xyz="0 0 0.7886557115458425" rpy="0 0 0"/>
            <geometry>
                <box size="2.093107649272789 2.9793824419712593 1.577311423091685" />
            </geometry>
        </collision>
    </link>
    <link name="Leg4">
        <inertial>
            <origin xyz="0 0.6412281969818567 0" rpy="0 0 0"/>
            <mass value="1" />
            <inertia ixx="100" ixy="0" ixz="0" iyy="100" iyz="0" izz="100" />
        </inertial>
        <visual>
            <origin xyz="0 0.6412281969818567 0" rpy="0 0 0"/>
            <geometry>
                <box size="2.9950122910171686 1.2824563939637135 1.4848470175340516" />
            </geometry>
            <material name="Green">
                <color rgba="0 180.0 0.0 1.0"/>
            </material>
        </visual>
        <collision>
            <origin xyz="0 0.6412281969818567 0" rpy="0 0 0"/>
            <geometry>
                <box size="2.9950122910171686 1.2824563939637135 1.4848470175340516" />
            </geometry>
        </collision>
    </link>
    <link name="Leg5">
        <inertial>
            <origin xyz="0 0.7467725256904553 0" rpy="0 0 0"/>
            <mass value="1" />
            <inertia ixx="100" ixy="0" ixz="0" iyy="100" iyz="0" izz="100" />
        </inertial>
        <visual>
            <origin xyz="0 0.7467725256904553 0" rpy="0 0 0"/>
            <geometry>
                <box size="2.3850605125897753 1.4935450513809105 2.026736241335384" />
            </geometry>
            <material name="Green">
                <color rgba="0 180.0 0.0 1.0"/>
            </material>
        </visual>
        <collision>
            <origin xyz="0 0.7467725256904553 0" rpy="0 0 0"/>
            <geometry>
                <box size="2.3850605125897753 1.4935450513809105 2.026736241335384" />
            </geometry>
        </collision>
    </link>
    <link name="Leg6">
        <inertial>
            <origin xyz="0.6791158432055685 0 0" rpy="0 0 0"/>
            <mass value="1" />
            <inertia ixx="100" ixy="0" ixz="0" iyy="100" iyz="0" izz="100" />
        </inertial>
        <visual>
            <origin xyz="0.6791158432055685 0 0" rpy="0 0 0"/>
            <geometry>
                <box size="1.358231686411137 1.4123042111065613 2.010817031838587" />
            </geometry>
            <material name="Blue">
                <color rgba="0 1.0 1.0 1.0"/>
            </material>
        </visual>
        <collision>
            <origin xyz="0.6791158432055685 0 0" rpy="0 0 0"/>
            <geometry>
                <box size="1.358231686411137 1.4123042111065613 2.010817031838587" />
            </geometry>
        </collision>
    </link>
    <link name="Leg7">
        <inertial>
            <origin xyz="0 0.7939355385150059 0" rpy="0 0 0"/>
            <mass value="1" />
            <inertia ixx="100" ixy="0" ixz="0" iyy="100" iyz="0" izz="100" />
        </inertial>
        <visual>
            <origin xyz="0 0.7939355385150059 0" rpy="0 0 0"/>
            <geometry>
                <box size="1.260890604439454 1.5878710770300117 2.392572130448915" />
            </geometry>
            <material name="Blue">
                <color rgba="0 1.0 1.0 1.0"/>
            </material>
        </visual>
        <collision>
            <origin xyz="0 0.7939355385150059 0" rpy="0 0 0"/>
            <geometry>
                <box size="1.260890604439454 1.5878710770300117 2.392572130448915" />
            </geometry>
        </collision>
    </link>
    <link name="Leg8">
        <inertial>
            <origin xyz="1.2335328134699064 0 0" rpy="0 0 0"/>
            <mass value="1" />
            <inertia ixx="100" ixy="0" ixz="0" iyy="100" iyz="0" izz="100" />
        </inertial>
        <visual>
            <origin xyz="1.2335328134699064 0 0" rpy="0 0 0"/>
            <geometry>
                <box size="2.467065626939813 1.642068538242263 1.1581139212325704" />
            </geometry>
            <material name="Blue">
                <color rgba="0 1.0 1.0 1.0"/>
            </material>
        </visual>
        <collision>
            <origin xyz="1.2335328134699064 0 0" rpy="0 0 0"/>
            <geometry>
                <box size="2.467065626939813 1.642068538242263 1.1581139212325704" />
            </geometry>
        </collision>
    </link>
    <link name="Leg9">
        <inertial>
            <origin xyz="0.673516835237019 0 0" rpy="0 0 0"/>
            <mass value="1" />
            <inertia ixx="100" ixy="0" ixz="0" iyy="100" iyz="0" izz="100" />
        </inertial>
        <visual>
            <origin xyz="0.673516835237019 0 0" rpy="0 0 0"/>
            <geometry>
                <box size="1.347033670474038 1.5229459825237355 1.7778573487523246" />
            </geometry>
            <material name="Blue">
                <color rgba="0 1.0 1.0 1.0"/>
            </material>
        </visual>
        <collision>
            <origin xyz="0.673516835237019 0 0" rpy="0 0 0"/>
            <geometry>
                <box size="1.347033670474038 1.5229459825237355 1.7778573487523246" />
            </geometry>
        </collision>
    </link>
    <link name="Leg10">
        <inertial>
            <origin xyz="0 0 1.009040719996057" rpy="0 0 0"/>
            <mass value="1" />
            <inertia ixx="100" ixy="0" ixz="0" iyy="100" iyz="0" izz="100" />
        </inertial>
        <visual>
            <origin xyz="0 0 1.009040719996057" rpy="0 0 0"/>
            <geometry>
                <box size="2.71610670024012 2.0007600113599424 2.018081439992114" />
            </geometry>
            <material name="Green">
                <color rgba="0 180.0 0.0 1.0"/>
            </material>
        </visual>
        <collision>
            <origin xyz="0 0 1.009040719996057" rpy="0 0 0"/>
            <geometry>
                <box size="2.71610670024012 2.0007600113599424 2.018081439992114" />
            </geometry>
        </collision>
    </link>
    <link name="Leg11">
        <inertial>
            <origin xyz="0.5428049166053386 0 0" rpy="0 0 0"/>
            <mass value="1" />
            <inertia ixx="100" ixy="0" ixz="0" iyy="100" iyz="0" izz="100" />
        </inertial>
        <visual>
            <origin xyz="0.5428049166053386 0 0" rpy="0 0 0"/>
            <geometry>
                <box size="1.0856098332106772 2.745395008497354 1.9396949009825593" />
            </geometry>
            <material name="Blue">
                <color rgba="0 1.0 1.0 1.0"/>
            </material>
        </visual>
        <collision>
            <origin xyz="0.5428049166053386 0 0" rpy="0 0 0"/>
            <geometry>
                <box size="1.0856098332106772 2.745395008497354 1.9396949009825593" />
            </geometry>
        </collision>
    </link>
    <link name="Leg12">
        <inertial>
            <origin xyz="1.26141228132109 0 0" rpy="0 0 0"/>
            <mass value="1" />
            <inertia ixx="100" ixy="0" ixz="0" iyy="100" iyz="0" izz="100" />
        </inertial>
        <visual>
            <origin xyz="1.26141228132109 0 0" rpy="0 0 0"/>
            <geometry>
                <box size="2.52282456264218 1.2387172773010984 2.852248559417419" />
            </geometry>
            <material name="Green">
                <color rgba="0 180.0 0.0 1.0"/>
            </material>
        </visual>
        <collision>
            <origin xyz="1.26141228132109 0 0" rpy="0 0 0"/>
            <geometry>
                <box size="2.52282456264218 1.2387172773010984 2.852248559417419" />
            </geometry>
        </collision>
    </link>
    <link name="Leg13">
        <inertial>
            <origin xyz="1.4799809300849693 0 0" rpy="0 0 0"/>
            <mass value="1" />
            <inertia ixx="100" ixy="0" ixz="0" iyy="100" iyz="0" izz="100" />
        </inertial>
        <visual>
            <origin xyz="1.4799809300849693 0 0" rpy="0 0 0"/>
            <geometry>
                <box size="2.9599618601699387 2.175802736292735 2.396136199111453" />
            </geometry>
            <material name="Green">
                <color rgba="0 180.0 0.0 1.0"/>
            </material>
        </visual>
        <collision>
            <origin xyz="1.4799809300849693 0 0" rpy="0 0 0"/>
            <geometry>
                <box size="2.9599618601699387 2.175802736292735 2.396136199111453" />
            </geometry>
        </collision>
    </link>
    <link name="Leg14">
        <inertial>
            <origin xyz="0 0.8507352844467274 0" rpy="0 0 0"/>
            <mass value="1" />
            <inertia ixx="100" ixy="0" ixz="0" iyy="100" iyz="0" izz="100" />
        </inertial>
        <visual>
            <origin xyz="0 0.8507352844467274 0" rpy="0 0 0"/>
            <geometry>
                <box size="2.865209817580757 1.7014705688934548 1.4261741440215616" />
            </geometry>
            <material name="Blue">
                <color rgba="0 1.0 1.0 1.0"/>
            </material>
        </visual>
        <collision>
            <origin xyz="0 0.8507352844467274 0" rpy="0 0 0"/>
            <geometry>
                <box size="2.865209817580757 1.7014705688934548 1.4261741440215616" />
            </geometry>
        </collision>
    </link>
    <link name="Leg15">
        <inertial>
            <origin xyz="0 0 1.173337031309286" rpy="0 0 0"/>
            <mass value="1" />
            <inertia ixx="100" ixy="0" ixz="0" iyy="100" iyz="0" izz="100" />
        </inertial>
        <visual>
            <origin xyz="0 0 1.173337031309286" rpy="0 0 0"/>
            <geometry>
                <box size="1.3415324233363772 2.5775225650409794 2.346674062618572" />
            </geometry>
            <material name="Blue">
                <color rgba="0 1.0 1.0 1.0"/>
            </material>
        </visual>
        <collision>
            <origin xyz="0 0 1.173337031309286" rpy="0 0 0"/>
            <geometry>
                <box size="1.3415324233363772 2.5775225650409794 2.346674062618572" />
            </geometry>
        </collision>
    </link>
    <link name="Leg16">
        <inertial>
            <origin xyz="0.866906566747508 0 0" rpy="0 0 0"/>
            <mass value="1" />
            <inertia ixx="100" ixy="0" ixz="0" iyy="100" iyz="0" izz="100" />
        </inertial>
        <visual>
            <origin xyz="0.866906566747508 0 0" rpy="0 0 0"/>
            <geometry>
                <box size="1.733813133495016 2.764462602443144 1.5228866092441073" />
            </geometry>
            <material name="Blue">
                <color rgba="0 1.0 1.0 1.0"/>
            </material>
        </visual>
        <collision>
            <origin xyz="0.866906566747508 0 0" rpy="0 0 0"/>
            <geometry>
                <box size="1.733813133495016 2.764462602443144 1.5228866092441073" />
            </geometry>
        </collision>
    </link>
    <link name="Leg17">
        <inertial>
            <origin xyz="0 0 1.46968827144192" rpy="0 0 0"/>
            <mass value="1" />
            <inertia ixx="100" ixy="0" ixz="0" iyy="100" iyz="0" izz="100" />
        </inertial>
        <visual>
            <origin xyz="0 0 1.46968827144192" rpy="0 0 0"/>
            <geometry>
                <box size="2.1689407943296137 2.897150023219206 2.93937654288384" />
            </geometry>
            <material name="Green">
                <color rgba="0 180.0 0.0 1.0"/>
            </material>
        </visual>
        <collision>
            <origin xyz="0 0 1.46968827144192" rpy="0 0 0"/>
            <geometry>
                <box size="2.1689407943296137 2.897150023219206 2.93937654288384" />
            </geometry>
        </collision>
    </link>
    <link name="Leg18">
        <inertial>
            <origin xyz="1.2646424778208842 0 0" rpy="0 0 0"/>
            <mass value="1" />
            <inertia ixx="100" ixy="0" ixz="0" iyy="100" iyz="0" izz="100" />
        </inertial>
        <visual>
            <origin xyz="1.2646424778208842 0 0" rpy="0 0 0"/>
            <geometry>
                <box size="2.5292849556417685 1.8629250339079981 2.7569879318055266" />
            </geometry>
            <material name="Green">
                <color rgba="0 180.0 0.0 1.0"/>
            </material>
        </visual>
        <collision>
            <origin xyz="1.2646424778208842 0 0" rpy="0 0 0"/>
            <geometry>
                <box size="2.5292849556417685 1.8629250339079981 2.7569879318055266" />
            </geometry>
        </collision>
    </link>
    <link name="Leg19">
        <inertial>
            <origin xyz="0 0 1.0421065666872127" rpy="0 0 0"/>
            <mass value="1" />
            <inertia ixx="100" ixy="0" ixz="0" iyy="100" iyz="0" izz="100" />
        </inertial>
        <visual>
            <origin xyz="0 0 1.0421065666872127" rpy="0 0 0"/>
            <geometry>
                <box size="2.9882664839459028 1.4483021850871485 2.0842131333744254" />
            </geometry>
            <material name="Blue">
                <color rgba="0 1.0 1.0 1.0"/>
            </material>
        </visual>
        <collision>
            <origin xyz="0 0 1.0421065666872127" rpy="0 0 0"/>
            <geometry>
                <box size="2.9882664839459028 1.4483021850871485 2.0842131333744254" />
            </geometry>
        </collision>
    </link>
    <link name="Leg20">
        <inertial>
            <origin xyz="0.7763527274735039 0 0" rpy="0 0 0"/>
            <mass value="1" />
            <inertia ixx="100" ixy="0" ixz="0" iyy="100" iyz="0" izz="100" />
        </inertial>
        <visual>
            <origin xyz="0.7763527274735039 0 0" rpy="0 0 0"/>
            <geometry>
                <box size="1.5527054549470078 2.5779443522873633 1.0367424795201428" />
            </geometry>
            <material name="Green">
                <color rgba="0 180.0 0.0 1.0"/>
            </material>
        </visual>
        <collision>
            <origin xyz="0.7763527274735039 0 0" rpy="0 0 0"/>
            <geometry>
                <box size="1.5527054549470078 2.5779443522873633 1.0367424795201428" />
            </geometry>
        </collision>
    </link>
    <link name="Leg21">
        <inertial>
            <origin xyz="0 0 1.330967008620331" rpy="0 0 0"/>
            <mass value="1" />
            <inertia ixx="100" ixy="0" ixz="0" iyy="100" iyz="0" izz="100" />
        </inertial>
        <visual>
            <origin xyz="0 0 1.330967008620331" rpy="0 0 0"/>
            <geometry>
                <box size="1.99913167202856 2.334199012525919 2.661934017240662" />
            </geometry>
            <material name="Blue">
                <color rgba="0 1.0 1.0 1.0"/>
            </material>
        </visual>
        <collision>
            <origin xyz="0 0 1.330967008620331" rpy="0 0 0"/>
            <geometry>
                <box size="1.99913167202856 2.334199012525919 2.661934017240662" />
            </geometry>
        </collision>
    </link>
    <link name="Leg22">
        <inertial>
            <origin xyz="0 0.8969626527076435 0" rpy="0 0 0"/>
            <mass value="1" />
            <inertia ixx="100" ixy="0" ixz="0" iyy="100" iyz="0" izz="100" />
        </inertial>
        <visual>
            <origin xyz="0 0.8969626527076435 0" rpy="0 0 0"/>
            <geometry>
                <box size="2.3123709376646904 1.793925305415287 2.480161798807279" />
            </geometry>
            <material name="Green">
                <color rgba="0 180.0 0.0 1.0"/>
            </material>
        </visual>
        <collision>
            <origin xyz="0 0.8969626527076435 0" rpy="0 0 0"/>
            <geometry>
                <box size="2.3123709376646904 1.793925305415287 2.480161798807279" />
            </geometry>
        </collision>
    </link>
    <link name="Leg23">
        <inertial>
            <origin xyz="1.1893089421012408 0 0" rpy="0 0 0"/>
            <mass value="1" />
            <inertia ixx="100" ixy="0" ixz="0" iyy="100" iyz="0" izz="100" />
        </inertial>
        <visual>
            <origin xyz="1.1893089421012408 0 0" rpy="0 0 0"/>
            <geometry>
                <box size="2.3786178842024817 2.794911436036725 1.1184784851106355" />
            </geometry>
            <material name="Green">
                <color rgba="0 180.0 0.0 1.0"/>
            </material>
        </visual>
        <collision>
            <origin xyz="1.1893089421012408 0 0" rpy="0 0 0"/>
            <geometry>
                <box size="2.3786178842024817 2.794911436036725 1.1184784851106355" />
            </geometry>
        </collision>
    </link>
    <link name="Leg24">
        <inertial>
            <origin xyz="0 0 1.0209403900529956" rpy="0 0 0"/>
            <mass value="1" />
            <inertia ixx="100" ixy="0" ixz="0" iyy="100" iyz="0" izz="100" />
        </inertial>
        <visual>
            <origin xyz="0 0 1.0209403900529956" rpy="0 0 0"/>
            <geometry>
                <box size="2.8522984622403396 2.8366552289031084 2.0418807801059913" />
            </geometry>
            <material name="Green">
                <color rgba="0 180.0 0.0 1.0"/>
            </material>
        </visual>
        <collision>
            <origin xyz="0 0 1.0209403900529956" rpy="0 0 0"/>
            <geometry>
                <box size="2.8522984622403396 2.8366552289031084 2.0418807801059913" />
            </geometry>
        </collision>
    </link>
    <joint name="Torso_Leg1" type="revolute">
       <parent link="Torso"/>
       <child  link="Leg1"/>
       <origin rpy="0 0 0" xyz="0 0 2.2676902615731334" />
     <axis xyz="1 0 0"/>
       <limit effort="0.0" lower="-3.14159" upper="3.14159" velocity="0.0"/>
    </joint>
    <joint name="Leg1_Leg2" type="revolute">
       <parent link="Leg1"/>
       <child  link="Leg2"/>
       <origin rpy="0 0 0" xyz="1.5626816561932524 0 0" />
     <axis xyz="1 0 0"/>
       <limit effort="0.0" lower="-3.14159" upper="3.14159" velocity="0.0"/>
    </joint>
    <joint name="Leg2_Leg3" type="revolute">
       <parent link="Leg2"/>
       <child  link="Leg3"/>
       <origin rpy="0 0 0" xyz="0 0 1.577311423091685" />
     <axis xyz="1 0 0"/>
       <limit effort="0.0" lower="-3.14159" upper="3.14159" velocity="0.0"/>
    </joint>
    <joint name="Leg1_Leg4" type="revolute">
       <parent link="Leg1"/>
       <child  link="Leg4"/>
       <origin rpy="0 0 0" xyz="1.5626816561932524 0.7765910249815754 0" />
     <axis xyz="1 0 0"/>
       <limit effort="0.0" lower="-3.14159" upper="3.14159" velocity="0.0"/>
    </joint>
    <joint name="Leg3_Leg5" type="revolute">
       <parent link="Leg3"/>
       <child  link="Leg5"/>
       <origin rpy="0 0 0" xyz="0 1.2824563939637135 0" />
     <axis xyz="1 0 0"/>
       <limit effort="0.0" lower="-3.14159" upper="3.14159" velocity="0.0"/>
    </joint>
    <joint name="Leg4_Leg6" type="revolute">
       <parent link="Leg4"/>
       <child  link="Leg6"/>
       <origin rpy="0 0 0" xyz="1.1925302562948876 0.7467725256904553 0" />
     <axis xyz="1 0 0"/>
       <limit effort="0.0" lower="-3.14159" upper="3.14159" velocity="0.0"/>
    </joint>
    <joint name="Leg4_Leg7" type="revolute">
       <parent link="Leg4"/>
       <child  link="Leg7"/>
       <origin rpy="0 0 0" xyz="1.1925302562948876 1.4935450513809105 0" />
     <axis xyz="1 0 0"/>
       <limit effort="0.0" lower="-3.14159" upper="3.14159" velocity="0.0"/>
    </joint>
    <joint name="Leg6_Leg8" type="revolute">
       <parent link="Leg6"/>
       <child  link="Leg8"/>
       <origin rpy="0 0 0" xyz="0.630445302219727 0.7939355385150059 0" />
     <axis xyz="1 0 0"/>
       <limit effort="0.0" lower="-3.14159" upper="3.14159" velocity="0.0"/>
    </joint>
    <joint name="Leg3_Leg9" type="revolute">
       <parent link="Leg3"/>
       <child  link="Leg9"/>
       <origin rpy="0 0 0" xyz="1.4975061455085843 1.2824563939637135 0" />
     <axis xyz="1 0 0"/>
       <limit effort="0.0" lower="-3.14159" upper="3.14159" velocity="0.0"/>
    </joint>
    <joint name="Leg7_Leg10" type="revolute">
       <parent link="Leg7"/>
       <child  link="Leg10"/>
       <origin rpy="0 0 0" xyz="1.2335328134699064 0 0.5790569606162852" />
     <axis xyz="1 0 0"/>
       <limit effort="0.0" lower="-3.14159" upper="3.14159" velocity="0.0"/>
    </joint>
    <joint name="Leg2_Leg11" type="revolute">
       <parent link="Leg2"/>
       <child  link="Leg11"/>
       <origin rpy="0 0 0" xyz="1.0465538246363946 0 1.577311423091685" />
     <axis xyz="1 0 0"/>
       <limit effort="0.0" lower="-3.14159" upper="3.14159" velocity="0.0"/>
    </joint>
    <joint name="Leg8_Leg12" type="revolute">
       <parent link="Leg8"/>
       <child  link="Leg12"/>
       <origin rpy="0 0 0" xyz="1.347033670474038 0 0" />
     <axis xyz="1 0 0"/>
       <limit effort="0.0" lower="-3.14159" upper="3.14159" velocity="0.0"/>
    </joint>
    <joint name="Torso_Leg13" type="revolute">
       <parent link="Torso"/>
       <child  link="Leg13"/>
       <origin rpy="0 0 0" xyz="1.347702916996893 0 1.2237956253176554" />
     <axis xyz="1 0 0"/>
       <limit effort="0.0" lower="-3.14159" upper="3.14159" velocity="0.0"/>
    </joint>
    <joint name="Leg13_Leg14" type="revolute">
       <parent link="Leg13"/>
       <child  link="Leg14"/>
       <origin rpy="0 0 0" xyz="0 1.7014705688934548 0" />
     <axis xyz="1 0 0"/>
       <limit effort="0.0" lower="-3.14159" upper="3.14159" velocity="0.0"/>
    </joint>
    <joint name="Leg13_Leg15" type="revolute">
       <parent link="Leg13"/>
       <child  link="Leg15"/>
       <origin rpy="0 0 0" xyz="0 1.7014705688934548 0.7130870720107808" />
     <axis xyz="1 0 0"/>
       <limit effort="0.0" lower="-3.14159" upper="3.14159" velocity="0.0"/>
    </joint>
    <joint name="Leg5_Leg16" type="revolute">
       <parent link="Leg5"/>
       <child  link="Leg16"/>
       <origin rpy="0 0 0" xyz="1.358231686411137 0 0" />
     <axis xyz="1 0 0"/>
       <limit effort="0.0" lower="-3.14159" upper="3.14159" velocity="0.0"/>
    </joint>
    <joint name="Leg12_Leg17" type="revolute">
       <parent link="Leg12"/>
       <child  link="Leg17"/>
       <origin rpy="0 0 0" xyz="1.4799809300849693 0 1.1980680995557265" />
     <axis xyz="1 0 0"/>
       <limit effort="0.0" lower="-3.14159" upper="3.14159" velocity="0.0"/>
    </joint>
    <joint name="Leg7_Leg18" type="revolute">
       <parent link="Leg7"/>
       <child  link="Leg18"/>
       <origin rpy="0 0 0" xyz="2.467065626939813 0 0.5790569606162852" />
     <axis xyz="1 0 0"/>
       <limit effort="0.0" lower="-3.14159" upper="3.14159" velocity="0.0"/>
    </joint>
    <joint name="Leg10_Leg19" type="revolute">
       <parent link="Leg10"/>
       <child  link="Leg19"/>
       <origin rpy="0 0 0" xyz="0.5428049166053386 0 0.9698474504912796" />
     <axis xyz="1 0 0"/>
       <limit effort="0.0" lower="-3.14159" upper="3.14159" velocity="0.0"/>
    </joint>
    <joint name="Leg10_Leg20" type="revolute">
       <parent link="Leg10"/>
       <child  link="Leg20"/>
       <origin rpy="0 0 0" xyz="1.0856098332106772 0 0.9698474504912796" />
     <axis xyz="1 0 0"/>
       <limit effort="0.0" lower="-3.14159" upper="3.14159" velocity="0.0"/>
    </joint>
    <joint name="Leg9_Leg21" type="revolute">
       <parent link="Leg9"/>
       <child  link="Leg21"/>
       <origin rpy="0 0 0" xyz="0 0 2.018081439992114" />
     <axis xyz="1 0 0"/>
       <limit effort="0.0" lower="-3.14159" upper="3.14159" velocity="0.0"/>
    </joint>
    <joint name="Torso_Leg22" type="revolute">
       <parent link="Torso"/>
       <child  link="Leg22"/>
       <origin rpy="0 0 0" xyz="1.347702916996893 0.6913938984505142 1.2237956253176554" />
     <axis xyz="1 0 0"/>
       <limit effort="0.0" lower="-3.14159" upper="3.14159" velocity="0.0"/>
    </joint>
    <joint name="Leg9_Leg23" type="revolute">
       <parent link="Leg9"/>
       <child  link="Leg23"/>
       <origin rpy="0 0 0" xyz="1.35805335012006 0 2.018081439992114" />
     <axis xyz="1 0 0"/>
       <limit effort="0.0" lower="-3.14159" upper="3.14159" velocity="0.0"/>
    </joint>
    <joint name="Leg14_Leg24" type="revolute">
       <parent link="Leg14"/>
       <child  link="Leg24"/>
       <origin rpy="0 0 0" xyz="0 0 2.346674062618572" />
     <axis xyz="1 0 0"/>
       <limit effort="0.0" lower="-3.14159" upper="3.14159" velocity="0.0"/>
    </joint>
</robot>