<robot name = "robot">
    <link name="Torso">
        <inertial>
            <origin xyz="0 0 1.0977785026514244" rpy="0 0 0"/>
            <mass value="1" />
            <inertia ixx="100" ixy="0" ixz="0" iyy="100" iyz="0" izz="100" />
        </inertial>
        <visual>
            <origin xyz="0 0 1.0977785026514244" rpy="0 0 0"/>
            <geometry>
                <box size="2.6339140509559704 1.9910455980415775 2.195557005302849" />
            </geometry>
            <material name="Green">
                <color rgba="0 180.0 0.0 1.0"/>
            </material>
        </visual>
        <collision>
            <origin xyz="0 0 1.0977785026514244" rpy="0 0 0"/>
            <geometry>
                <box size="2.6339140509559704 1.9910455980415775 2.195557005302849" />
            </geometry>
        </collision>
    </link>
    <link name="Leg1">
        <inertial>
            <origin xyz="0 1.2897719935446887 0" rpy="0 0 0"/>
            <mass value="1" />
            <inertia ixx="100" ixy="0" ixz="0" iyy="100" iyz="0" izz="100" />
        </inertial>
        <visual>
            <origin xyz="0 1.2897719935446887 0" rpy="0 0 0"/>
            <geometry>
                <box size="2.7444349254364693 2.5795439870893775 1.6562091402631276" />
            </geometry>
            <material name="Blue">
                <color rgba="0 1.0 1.0 1.0"/>
            </material>
        </visual>
        <collision>
            <origin xyz="0 1.2897719935446887 0" rpy="0 0 0"/>
            <geometry>
                <box size="2.7444349254364693 2.5795439870893775 1.6562091402631276" />
            </geometry>
        </collision>
    </link>
    <link name="Leg2">
        <inertial>
            <origin xyz="1.3908182759725602 0 0" rpy="0 0 0"/>
            <mass value="1" />
            <inertia ixx="100" ixy="0" ixz="0" iyy="100" iyz="0" izz="100" />
        </inertial>
        <visual>
            <origin xyz="1.3908182759725602 0 0" rpy="0 0 0"/>
            <geometry>
                <box size="2.7816365519451205 1.0412756483432029 2.8676161566318727" />
            </geometry>
            <material name="Blue">
                <color rgba="0 1.0 1.0 1.0"/>
            </material>
        </visual>
        <collision>
            <origin xyz="1.3908182759725602 0 0" rpy="0 0 0"/>
            <geometry>
                <box size="2.7816365519451205 1.0412756483432029 2.8676161566318727" />
            </geometry>
        </collision>
    </link>
    <link name="Leg3">
        <inertial>
            <origin xyz="0 0 1.3480310352498686" rpy="0 0 0"/>
            <mass value="1" />
            <inertia ixx="100" ixy="0" ixz="0" iyy="100" iyz="0" izz="100" />
        </inertial>
        <visual>
            <origin xyz="0 0 1.3480310352498686" rpy="0 0 0"/>
            <geometry>
                <box size="1.744807609623373 2.775006667092734 2.696062070499737" />
            </geometry>
            <material name="Green">
                <color rgba="0 180.0 0.0 1.0"/>
            </material>
        </visual>
        <collision>
            <origin xyz="0 0 1.3480310352498686" rpy="0 0 0"/>
            <geometry>
                <box size="1.744807609623373 2.775006667092734 2.696062070499737" />
            </geometry>
        </collision>
    </link>
    <link name="Leg4">
        <inertial>
            <origin xyz="1.2240104207686717 0 0" rpy="0 0 0"/>
            <mass value="1" />
            <inertia ixx="100" ixy="0" ixz="0" iyy="100" iyz="0" izz="100" />
        </inertial>
        <visual>
            <origin xyz="1.2240104207686717 0 0" rpy="0 0 0"/>
            <geometry>
                <box size="2.4480208415373435 1.2093394260640544 1.4673224646044012" />
            </geometry>
            <material name="Blue">
                <color rgba="0 1.0 1.0 1.0"/>
            </material>
        </visual>
        <collision>
            <origin xyz="1.2240104207686717 0 0" rpy="0 0 0"/>
            <geometry>
                <box size="2.4480208415373435 1.2093394260640544 1.4673224646044012" />
            </geometry>
        </collision>
    </link>
    <link name="Leg5">
        <inertial>
            <origin xyz="0.6535204828245325 0 0" rpy="0 0 0"/>
            <mass value="1" />
            <inertia ixx="100" ixy="0" ixz="0" iyy="100" iyz="0" izz="100" />
        </inertial>
        <visual>
            <origin xyz="0.6535204828245325 0 0" rpy="0 0 0"/>
            <geometry>
                <box size="1.307040965649065 2.1485095340188995 1.5839788534046564" />
            </geometry>
            <material name="Blue">
                <color rgba="0 1.0 1.0 1.0"/>
            </material>
        </visual>
        <collision>
            <origin xyz="0.6535204828245325 0 0" rpy="0 0 0"/>
            <geometry>
                <box size="1.307040965649065 2.1485095340188995 1.5839788534046564" />
            </geometry>
        </collision>
    </link>
    <link name="Leg6">
        <inertial>
            <origin xyz="0 0 1.0953712853627349" rpy="0 0 0"/>
            <mass value="1" />
            <inertia ixx="100" ixy="0" ixz="0" iyy="100" iyz="0" izz="100" />
        </inertial>
        <visual>
            <origin xyz="0 0 1.0953712853627349" rpy="0 0 0"/>
            <geometry>
                <box size="1.8014039674536333 2.4907939123908713 2.1907425707254697" />
            </geometry>
            <material name="Blue">
                <color rgba="0 1.0 1.0 1.0"/>
            </material>
        </visual>
        <collision>
            <origin xyz="0 0 1.0953712853627349" rpy="0 0 0"/>
            <geometry>
                <box size="1.8014039674536333 2.4907939123908713 2.1907425707254697" />
            </geometry>
        </collision>
    </link>
    <link name="Leg7">
        <inertial>
            <origin xyz="0 0.6114592898640946 0" rpy="0 0 0"/>
            <mass value="1" />
            <inertia ixx="100" ixy="0" ixz="0" iyy="100" iyz="0" izz="100" />
        </inertial>
        <visual>
            <origin xyz="0 0.6114592898640946 0" rpy="0 0 0"/>
            <geometry>
                <box size="1.420247199691663 1.2229185797281892 1.9680707029302549" />
            </geometry>
            <material name="Green">
                <color rgba="0 180.0 0.0 1.0"/>
            </material>
        </visual>
        <collision>
            <origin xyz="0 0.6114592898640946 0" rpy="0 0 0"/>
            <geometry>
                <box size="1.420247199691663 1.2229185797281892 1.9680707029302549" />
            </geometry>
        </collision>
    </link>
    <link name="Leg8">
        <inertial>
            <origin xyz="0 1.4414472582606033 0" rpy="0 0 0"/>
            <mass value="1" />
            <inertia ixx="100" ixy="0" ixz="0" iyy="100" iyz="0" izz="100" />
        </inertial>
        <visual>
            <origin xyz="0 1.4414472582606033 0" rpy="0 0 0"/>
            <geometry>
                <box size="1.016188852413604 2.8828945165212065 2.7520575739584725" />
            </geometry>
            <material name="Green">
                <color rgba="0 180.0 0.0 1.0"/>
            </material>
        </visual>
        <collision>
            <origin xyz="0 1.4414472582606033 0" rpy="0 0 0"/>
            <geometry>
                <box size="1.016188852413604 2.8828945165212065 2.7520575739584725" />
            </geometry>
        </collision>
    </link>
    <link name="Leg9">
        <inertial>
            <origin xyz="1.0155436700135958 0 0" rpy="0 0 0"/>
            <mass value="1" />
            <inertia ixx="100" ixy="0" ixz="0" iyy="100" iyz="0" izz="100" />
        </inertial>
        <visual>
            <origin xyz="1.0155436700135958 0 0" rpy="0 0 0"/>
            <geometry>
                <box size="2.0310873400271916 1.8894288774548638 2.998920405242224" />
            </geometry>
            <material name="Blue">
                <color rgba="0 1.0 1.0 1.0"/>
            </material>
        </visual>
        <collision>
            <origin xyz="1.0155436700135958 0 0" rpy="0 0 0"/>
            <geometry>
                <box size="2.0310873400271916 1.8894288774548638 2.998920405242224" />
            </geometry>
        </collision>
    </link>
    <link name="Leg10">
        <inertial>
            <origin xyz="0 0 0.8180759815453594" rpy="0 0 0"/>
            <mass value="1" />
            <inertia ixx="100" ixy="0" ixz="0" iyy="100" iyz="0" izz="100" />
        </inertial>
        <visual>
            <origin xyz="0 0 0.8180759815453594" rpy="0 0 0"/>
            <geometry>
                <box size="1.2341849702361316 2.8849186203385244 1.6361519630907189" />
            </geometry>
            <material name="Green">
                <color rgba="0 180.0 0.0 1.0"/>
            </material>
        </visual>
        <collision>
            <origin xyz="0 0 0.8180759815453594" rpy="0 0 0"/>
            <geometry>
                <box size="1.2341849702361316 2.8849186203385244 1.6361519630907189" />
            </geometry>
        </collision>
    </link>
    <link name="Leg11">
        <inertial>
            <origin xyz="0 0 0.7922579966038357" rpy="0 0 0"/>
            <mass value="1" />
            <inertia ixx="100" ixy="0" ixz="0" iyy="100" iyz="0" izz="100" />
        </inertial>
        <visual>
            <origin xyz="0 0 0.7922579966038357" rpy="0 0 0"/>
            <geometry>
                <box size="2.338091124029928 2.706920680191015 1.5845159932076713" />
            </geometry>
            <material name="Green">
                <color rgba="0 180.0 0.0 1.0"/>
            </material>
        </visual>
        <collision>
            <origin xyz="0 0 0.7922579966038357" rpy="0 0 0"/>
            <geometry>
                <box size="2.338091124029928 2.706920680191015 1.5845159932076713" />
            </geometry>
        </collision>
    </link>
    <link name="Leg12">
        <inertial>
            <origin xyz="0 0 0.6604923420716867" rpy="0 0 0"/>
            <mass value="1" />
            <inertia ixx="100" ixy="0" ixz="0" iyy="100" iyz="0" izz="100" />
        </inertial>
        <visual>
            <origin xyz="0 0 0.6604923420716867" rpy="0 0 0"/>
            <geometry>
                <box size="2.8813383525391636 1.953986919887429 1.3209846841433734" />
            </geometry>
            <material name="Blue">
                <color rgba="0 1.0 1.0 1.0"/>
            </material>
        </visual>
        <collision>
            <origin xyz="0 0 0.6604923420716867" rpy="0 0 0"/>
            <geometry>
                <box size="2.8813383525391636 1.953986919887429 1.3209846841433734" />
            </geometry>
        </collision>
    </link>
    <link name="Leg13">
        <inertial>
            <origin xyz="0 0 1.1434976923801827" rpy="0 0 0"/>
            <mass value="1" />
            <inertia ixx="100" ixy="0" ixz="0" iyy="100" iyz="0" izz="100" />
        </inertial>
        <visual>
            <origin xyz="0 0 1.1434976923801827" rpy="0 0 0"/>
            <geometry>
                <box size="2.939968357402262 1.4922531596662607 2.2869953847603655" />
            </geometry>
            <material name="Blue">
                <color rgba="0 1.0 1.0 1.0"/>
            </material>
        </visual>
        <collision>
            <origin xyz="0 0 1.1434976923801827" rpy="0 0 0"/>
            <geometry>
                <box size="2.939968357402262 1.4922531596662607 2.2869953847603655" />
            </geometry>
        </collision>
    </link>
    <link name="Leg14">
        <inertial>
            <origin xyz="0 0 1.1268483512096679" rpy="0 0 0"/>
            <mass value="1" />
            <inertia ixx="100" ixy="0" ixz="0" iyy="100" iyz="0" izz="100" />
        </inertial>
        <visual>
            <origin xyz="0 0 1.1268483512096679" rpy="0 0 0"/>
            <geometry>
                <box size="2.4653820453089814 1.8251912793625056 2.2536967024193357" />
            </geometry>
            <material name="Green">
                <color rgba="0 180.0 0.0 1.0"/>
            </material>
        </visual>
        <collision>
            <origin xyz="0 0 1.1268483512096679" rpy="0 0 0"/>
            <geometry>
                <box size="2.4653820453089814 1.8251912793625056 2.2536967024193357" />
            </geometry>
        </collision>
    </link>
    <link name="Leg15">
        <inertial>
            <origin xyz="0 0 1.300918697521812" rpy="0 0 0"/>
            <mass value="1" />
            <inertia ixx="100" ixy="0" ixz="0" iyy="100" iyz="0" izz="100" />
        </inertial>
        <visual>
            <origin xyz="0 0 1.300918697521812" rpy="0 0 0"/>
            <geometry>
                <box size="1.038877072189307 2.092931962940675 2.601837395043624" />
            </geometry>
            <material name="Green">
                <color rgba="0 180.0 0.0 1.0"/>
            </material>
        </visual>
        <collision>
            <origin xyz="0 0 1.300918697521812" rpy="0 0 0"/>
            <geometry>
                <box size="1.038877072189307 2.092931962940675 2.601837395043624" />
            </geometry>
        </collision>
    </link>
    <link name="Leg16">
        <inertial>
            <origin xyz="0 0 0.9758767971916092" rpy="0 0 0"/>
            <mass value="1" />
            <inertia ixx="100" ixy="0" ixz="0" iyy="100" iyz="0" izz="100" />
        </inertial>
        <visual>
            <origin xyz="0 0 0.9758767971916092" rpy="0 0 0"/>
            <geometry>
                <box size="1.9476285325593767 2.1018287056844116 1.9517535943832185" />
            </geometry>
            <material name="Green">
                <color rgba="0 180.0 0.0 1.0"/>
            </material>
        </visual>
        <collision>
            <origin xyz="0 0 0.9758767971916092" rpy="0 0 0"/>
            <geometry>
                <box size="1.9476285325593767 2.1018287056844116 1.9517535943832185" />
            </geometry>
        </collision>
    </link>
    <link name="Leg17">
        <inertial>
            <origin xyz="0 1.22750967875904 0" rpy="0 0 0"/>
            <mass value="1" />
            <inertia ixx="100" ixy="0" ixz="0" iyy="100" iyz="0" izz="100" />
        </inertial>
        <visual>
            <origin xyz="0 1.22750967875904 0" rpy="0 0 0"/>
            <geometry>
                <box size="1.310127387056667 2.45501935751808 1.776788511885682" />
            </geometry>
            <material name="Green">
                <color rgba="0 180.0 0.0 1.0"/>
            </material>
        </visual>
        <collision>
            <origin xyz="0 1.22750967875904 0" rpy="0 0 0"/>
            <geometry>
                <box size="1.310127387056667 2.45501935751808 1.776788511885682" />
            </geometry>
        </collision>
    </link>
    <link name="Leg18">
        <inertial>
            <origin xyz="0.6123958418744302 0 0" rpy="0 0 0"/>
            <mass value="1" />
            <inertia ixx="100" ixy="0" ixz="0" iyy="100" iyz="0" izz="100" />
        </inertial>
        <visual>
            <origin xyz="0.6123958418744302 0 0" rpy="0 0 0"/>
            <geometry>
                <box size="1.2247916837488604 2.284763305311226 1.4171864325268666" />
            </geometry>
            <material name="Green">
                <color rgba="0 180.0 0.0 1.0"/>
            </material>
        </visual>
        <collision>
            <origin xyz="0.6123958418744302 0 0" rpy="0 0 0"/>
            <geometry>
                <box size="1.2247916837488604 2.284763305311226 1.4171864325268666" />
            </geometry>
        </collision>
    </link>
    <link name="Leg19">
        <inertial>
            <origin xyz="0 0 1.378789362186164" rpy="0 0 0"/>
            <mass value="1" />
            <inertia ixx="100" ixy="0" ixz="0" iyy="100" iyz="0" izz="100" />
        </inertial>
        <visual>
            <origin xyz="0 0 1.378789362186164" rpy="0 0 0"/>
            <geometry>
                <box size="1.333340359312982 2.111361572501346 2.757578724372328" />
            </geometry>
            <material name="Green">
                <color rgba="0 180.0 0.0 1.0"/>
            </material>
        </visual>
        <collision>
            <origin xyz="0 0 1.378789362186164" rpy="0 0 0"/>
            <geometry>
                <box size="1.333340359312982 2.111361572501346 2.757578724372328" />
            </geometry>
        </collision>
    </link>
    <link name="Leg20">
        <inertial>
            <origin xyz="0.630852343629521 0 0" rpy="0 0 0"/>
            <mass value="1" />
            <inertia ixx="100" ixy="0" ixz="0" iyy="100" iyz="0" izz="100" />
        </inertial>
        <visual>
            <origin xyz="0.630852343629521 0 0" rpy="0 0 0"/>
            <geometry>
                <box size="1.261704687259042 2.9460739653705246 2.1242562403907677" />
            </geometry>
            <material name="Blue">
                <color rgba="0 1.0 1.0 1.0"/>
            </material>
        </visual>
        <collision>
            <origin xyz="0.630852343629521 0 0" rpy="0 0 0"/>
            <geometry>
                <box size="1.261704687259042 2.9460739653705246 2.1242562403907677" />
            </geometry>
        </collision>
    </link>
    <link name="Leg21">
        <inertial>
            <origin xyz="0 0 1.2658374395283984" rpy="0 0 0"/>
            <mass value="1" />
            <inertia ixx="100" ixy="0" ixz="0" iyy="100" iyz="0" izz="100" />
        </inertial>
        <visual>
            <origin xyz="0 0 1.2658374395283984" rpy="0 0 0"/>
            <geometry>
                <box size="1.6151377007066865 1.1705870809733083 2.531674879056797" />
            </geometry>
            <material name="Blue">
                <color rgba="0 1.0 1.0 1.0"/>
            </material>
        </visual>
        <collision>
            <origin xyz="0 0 1.2658374395283984" rpy="0 0 0"/>
            <geometry>
                <box size="1.6151377007066865 1.1705870809733083 2.531674879056797" />
            </geometry>
        </collision>
    </link>
    <link name="Leg22">
        <inertial>
            <origin xyz="0 1.3575781588121085 0" rpy="0 0 0"/>
            <mass value="1" />
            <inertia ixx="100" ixy="0" ixz="0" iyy="100" iyz="0" izz="100" />
        </inertial>
        <visual>
            <origin xyz="0 1.3575781588121085 0" rpy="0 0 0"/>
            <geometry>
                <box size="2.4053053809417273 2.715156317624217 2.4100763225306054" />
            </geometry>
            <material name="Blue">
                <color rgba="0 1.0 1.0 1.0"/>
            </material>
        </visual>
        <collision>
            <origin xyz="0 1.3575781588121085 0" rpy="0 0 0"/>
            <geometry>
                <box size="2.4053053809417273 2.715156317624217 2.4100763225306054" />
            </geometry>
        </collision>
    </link>
    <link name="Leg23">
        <inertial>
            <origin xyz="0 0 1.289030771979585" rpy="0 0 0"/>
            <mass value="1" />
            <inertia ixx="100" ixy="0" ixz="0" iyy="100" iyz="0" izz="100" />
        </inertial>
        <visual>
            <origin xyz="0 0 1.289030771979585" rpy="0 0 0"/>
            <geometry>
                <box size="2.8721728554837407 1.5797971105612463 2.57806154395917" />
            </geometry>
            <material name="Blue">
                <color rgba="0 1.0 1.0 1.0"/>
            </material>
        </visual>
        <collision>
            <origin xyz="0 0 1.289030771979585" rpy="0 0 0"/>
            <geometry>
                <box size="2.8721728554837407 1.5797971105612463 2.57806154395917" />
            </geometry>
        </collision>
    </link>
    <link name="Leg24">
        <inertial>
            <origin xyz="0 0.7128331018142695 0" rpy="0 0 0"/>
            <mass value="1" />
            <inertia ixx="100" ixy="0" ixz="0" iyy="100" iyz="0" izz="100" />
        </inertial>
        <visual>
            <origin xyz="0 0.7128331018142695 0" rpy="0 0 0"/>
            <geometry>
                <box size="1.9886862002424226 1.425666203628539 2.8145017982975467" />
            </geometry>
            <material name="Blue">
                <color rgba="0 1.0 1.0 1.0"/>
            </material>
        </visual>
        <collision>
            <origin xyz="0 0.7128331018142695 0" rpy="0 0 0"/>
            <geometry>
                <box size="1.9886862002424226 1.425666203628539 2.8145017982975467" />
            </geometry>
        </collision>
    </link>
    <joint name="Torso_Leg1" type="revolute">
       <parent link="Torso"/>
       <child  link="Leg1"/>
       <origin rpy="0 0 0" xyz="0 0.9955227990207888 1.0977785026514244" />
     <axis xyz="1 0 0"/>
       <limit effort="0.0" lower="-3.14159" upper="3.14159" velocity="0.0"/>
    </joint>
    <joint name="Torso_Leg2" type="revolute">
       <parent link="Torso"/>
       <child  link="Leg2"/>
       <origin rpy="0 0 0" xyz="1.3722174627182346 1.2897719935446887 0" />
     <axis xyz="1 0 0"/>
       <limit effort="0.0" lower="-3.14159" upper="3.14159" velocity="0.0"/>
    </joint>
    <joint name="Leg1_Leg3" type="revolute">
       <parent link="Leg1"/>
       <child  link="Leg3"/>
       <origin rpy="0 0 0" xyz="1.3908182759725602 0 1.4338080783159364" />
     <axis xyz="1 0 0"/>
       <limit effort="0.0" lower="-3.14159" upper="3.14159" velocity="0.0"/>
    </joint>
    <joint name="Leg2_Leg4" type="revolute">
       <parent link="Leg2"/>
       <child  link="Leg4"/>
       <origin rpy="0 0 0" xyz="0.8724038048116864 0 1.3480310352498686" />
     <axis xyz="1 0 0"/>
       <limit effort="0.0" lower="-3.14159" upper="3.14159" velocity="0.0"/>
    </joint>
    <joint name="Leg3_Leg5" type="revolute">
       <parent link="Leg3"/>
       <child  link="Leg5"/>
       <origin rpy="0 0 0" xyz="2.4480208415373435 0 0" />
     <axis xyz="1 0 0"/>
       <limit effort="0.0" lower="-3.14159" upper="3.14159" velocity="0.0"/>
    </joint>
    <joint name="Torso_Leg6" type="revolute">
       <parent link="Torso"/>
       <child  link="Leg6"/>
       <origin rpy="0 0 0" xyz="1.3722174627182346 1.2897719935446887 0.8281045701315638" />
     <axis xyz="1 0 0"/>
       <limit effort="0.0" lower="-3.14159" upper="3.14159" velocity="0.0"/>
    </joint>
    <joint name="Leg6_Leg7" type="revolute">
       <parent link="Leg6"/>
       <child  link="Leg7"/>
       <origin rpy="0 0 0" xyz="0 1.2229185797281892 0" />
     <axis xyz="1 0 0"/>
       <limit effort="0.0" lower="-3.14159" upper="3.14159" velocity="0.0"/>
    </joint>
    <joint name="Leg5_Leg8" type="revolute">
       <parent link="Leg5"/>
       <child  link="Leg8"/>
       <origin rpy="0 0 0" xyz="0 1.2453969561954357 1.0953712853627349" />
     <axis xyz="1 0 0"/>
       <limit effort="0.0" lower="-3.14159" upper="3.14159" velocity="0.0"/>
    </joint>
    <joint name="Leg4_Leg9" type="revolute">
       <parent link="Leg4"/>
       <child  link="Leg9"/>
       <origin rpy="0 0 0" xyz="1.307040965649065 0 0" />
     <axis xyz="1 0 0"/>
       <limit effort="0.0" lower="-3.14159" upper="3.14159" velocity="0.0"/>
    </joint>
    <joint name="Leg3_Leg10" type="revolute">
       <parent link="Leg3"/>
       <child  link="Leg10"/>
       <origin rpy="0 0 0" xyz="2.4480208415373435 0 0.7336612323022006" />
     <axis xyz="1 0 0"/>
       <limit effort="0.0" lower="-3.14159" upper="3.14159" velocity="0.0"/>
    </joint>
    <joint name="Leg6_Leg11" type="revolute">
       <parent link="Leg6"/>
       <child  link="Leg11"/>
       <origin rpy="0 0 0" xyz="0 1.2229185797281892 0.9840353514651274" />
     <axis xyz="1 0 0"/>
       <limit effort="0.0" lower="-3.14159" upper="3.14159" velocity="0.0"/>
    </joint>
    <joint name="Leg11_Leg12" type="revolute">
       <parent link="Leg11"/>
       <child  link="Leg12"/>
       <origin rpy="0 0 0" xyz="0 0 1.3209846841433734" />
     <axis xyz="1 0 0"/>
       <limit effort="0.0" lower="-3.14159" upper="3.14159" velocity="0.0"/>
    </joint>
    <joint name="Leg5_Leg13" type="revolute">
       <parent link="Leg5"/>
       <child  link="Leg13"/>
       <origin rpy="0 0 0" xyz="0 1.2453969561954357 2.1907425707254697" />
     <axis xyz="1 0 0"/>
       <limit effort="0.0" lower="-3.14159" upper="3.14159" velocity="0.0"/>
    </joint>
    <joint name="Leg8_Leg14" type="revolute">
       <parent link="Leg8"/>
       <child  link="Leg14"/>
       <origin rpy="0 0 0" xyz="1.0155436700135958 0 1.499460202621112" />
     <axis xyz="1 0 0"/>
       <limit effort="0.0" lower="-3.14159" upper="3.14159" velocity="0.0"/>
    </joint>
    <joint name="Leg7_Leg15" type="revolute">
       <parent link="Leg7"/>
       <child  link="Leg15"/>
       <origin rpy="0 0 0" xyz="0 1.4414472582606033 1.3760287869792363" />
     <axis xyz="1 0 0"/>
       <limit effort="0.0" lower="-3.14159" upper="3.14159" velocity="0.0"/>
    </joint>
    <joint name="Leg4_Leg16" type="revolute">
       <parent link="Leg4"/>
       <child  link="Leg16"/>
       <origin rpy="0 0 0" xyz="1.307040965649065 0 0.7919894267023282" />
     <axis xyz="1 0 0"/>
       <limit effort="0.0" lower="-3.14159" upper="3.14159" velocity="0.0"/>
    </joint>
    <joint name="Leg12_Leg17" type="revolute">
       <parent link="Leg12"/>
       <child  link="Leg17"/>
       <origin rpy="0 0 0" xyz="0 0.7461265798331304 1.1434976923801827" />
     <axis xyz="1 0 0"/>
       <limit effort="0.0" lower="-3.14159" upper="3.14159" velocity="0.0"/>
    </joint>
    <joint name="Leg1_Leg18" type="revolute">
       <parent link="Leg1"/>
       <child  link="Leg18"/>
       <origin rpy="0 0 0" xyz="2.7816365519451205 0 1.4338080783159364" />
     <axis xyz="1 0 0"/>
       <limit effort="0.0" lower="-3.14159" upper="3.14159" velocity="0.0"/>
    </joint>
    <joint name="Leg9_Leg19" type="revolute">
       <parent link="Leg9"/>
       <child  link="Leg19"/>
       <origin rpy="0 0 0" xyz="0 0 1.6361519630907189" />
     <axis xyz="1 0 0"/>
       <limit effort="0.0" lower="-3.14159" upper="3.14159" velocity="0.0"/>
    </joint>
    <joint name="Leg13_Leg20" type="revolute">
       <parent link="Leg13"/>
       <child  link="Leg20"/>
       <origin rpy="0 0 0" xyz="1.2326910226544907 0 1.1268483512096679" />
     <axis xyz="1 0 0"/>
       <limit effort="0.0" lower="-3.14159" upper="3.14159" velocity="0.0"/>
    </joint>
    <joint name="Leg17_Leg21" type="revolute">
       <parent link="Leg17"/>
       <child  link="Leg21"/>
       <origin rpy="0 0 0" xyz="0.6123958418744302 0 0.7085932162634333" />
     <axis xyz="1 0 0"/>
       <limit effort="0.0" lower="-3.14159" upper="3.14159" velocity="0.0"/>
    </joint>
    <joint name="Leg3_Leg22" type="revolute">
       <parent link="Leg3"/>
       <child  link="Leg22"/>
       <origin rpy="0 0 0" xyz="2.4480208415373435 0.6046697130320272 0.7336612323022006" />
     <axis xyz="1 0 0"/>
       <limit effort="0.0" lower="-3.14159" upper="3.14159" velocity="0.0"/>
    </joint>
    <joint name="Leg15_Leg23" type="revolute">
       <parent link="Leg15"/>
       <child  link="Leg23"/>
       <origin rpy="0 0 0" xyz="0 0 1.9517535943832185" />
     <axis xyz="1 0 0"/>
       <limit effort="0.0" lower="-3.14159" upper="3.14159" velocity="0.0"/>
    </joint>
    <joint name="Leg21_Leg24" type="revolute">
       <parent link="Leg21"/>
       <child  link="Leg24"/>
       <origin rpy="0 0 0" xyz="0 2.715156317624217 0" />
     <axis xyz="1 0 0"/>
       <limit effort="0.0" lower="-3.14159" upper="3.14159" velocity="0.0"/>
    </joint>
</robot>