<robot name = "robot">
    <link name="Torso">
        <inertial>
            <origin xyz="0 0 1.052470642744404" rpy="0 0 0"/>
            <mass value="1" />
            <inertia ixx="100" ixy="0" ixz="0" iyy="100" iyz="0" izz="100" />
        </inertial>
        <visual>
            <origin xyz="0 0 1.052470642744404" rpy="0 0 0"/>
            <geometry>
                <box size="2.87785287863879 1.9665183825103438 2.104941285488808" />
            </geometry>
            <material name="Green">
                <color rgba="0 180.0 0.0 1.0"/>
            </material>
        </visual>
        <collision>
            <origin xyz="0 0 1.052470642744404" rpy="0 0 0"/>
            <geometry>
                <box size="2.87785287863879 1.9665183825103438 2.104941285488808" />
            </geometry>
        </collision>
    </link>
    <link name="Leg1">
        <inertial>
            <origin xyz="1.3575843457707237 0 0" rpy="0 0 0"/>
            <mass value="1" />
            <inertia ixx="100" ixy="0" ixz="0" iyy="100" iyz="0" izz="100" />
        </inertial>
        <visual>
            <origin xyz="1.3575843457707237 0 0" rpy="0 0 0"/>
            <geometry>
                <box size="2.7151686915414475 1.4840036667188923 1.4147556094456" />
            </geometry>
            <material name="Green">
                <color rgba="0 180.0 0.0 1.0"/>
            </material>
        </visual>
        <collision>
            <origin xyz="1.3575843457707237 0 0" rpy="0 0 0"/>
            <geometry>
                <box size="2.7151686915414475 1.4840036667188923 1.4147556094456" />
            </geometry>
        </collision>
    </link>
    <link name="Leg2">
        <inertial>
            <origin xyz="0 0 1.0423614332484408" rpy="0 0 0"/>
            <mass value="1" />
            <inertia ixx="100" ixy="0" ixz="0" iyy="100" iyz="0" izz="100" />
        </inertial>
        <visual>
            <origin xyz="0 0 1.0423614332484408" rpy="0 0 0"/>
            <geometry>
                <box size="2.7365512711869364 1.2979607402524258 2.0847228664968815" />
            </geometry>
            <material name="Green">
                <color rgba="0 180.0 0.0 1.0"/>
            </material>
        </visual>
        <collision>
            <origin xyz="0 0 1.0423614332484408" rpy="0 0 0"/>
            <geometry>
                <box size="2.7365512711869364 1.2979607402524258 2.0847228664968815" />
            </geometry>
        </collision>
    </link>
    <link name="Leg3">
        <inertial>
            <origin xyz="0 0 0.8959685938581939" rpy="0 0 0"/>
            <mass value="1" />
            <inertia ixx="100" ixy="0" ixz="0" iyy="100" iyz="0" izz="100" />
        </inertial>
        <visual>
            <origin xyz="0 0 0.8959685938581939" rpy="0 0 0"/>
            <geometry>
                <box size="1.6031578808874665 2.928260580051313 1.7919371877163879" />
            </geometry>
            <material name="Green">
                <color rgba="0 180.0 0.0 1.0"/>
            </material>
        </visual>
        <collision>
            <origin xyz="0 0 0.8959685938581939" rpy="0 0 0"/>
            <geometry>
                <box size="1.6031578808874665 2.928260580051313 1.7919371877163879" />
            </geometry>
        </collision>
    </link>
    <link name="Leg4">
        <inertial>
            <origin xyz="0 0 0.7718658770055147" rpy="0 0 0"/>
            <mass value="1" />
            <inertia ixx="100" ixy="0" ixz="0" iyy="100" iyz="0" izz="100" />
        </inertial>
        <visual>
            <origin xyz="0 0 0.7718658770055147" rpy="0 0 0"/>
            <geometry>
                <box size="1.604506318043106 1.7881110129033795 1.5437317540110294" />
            </geometry>
            <material name="Green">
                <color rgba="0 180.0 0.0 1.0"/>
            </material>
        </visual>
        <collision>
            <origin xyz="0 0 0.7718658770055147" rpy="0 0 0"/>
            <geometry>
                <box size="1.604506318043106 1.7881110129033795 1.5437317540110294" />
            </geometry>
        </collision>
    </link>
    <link name="Leg5">
        <inertial>
            <origin xyz="0.7756583500548497 0 0" rpy="0 0 0"/>
            <mass value="1" />
            <inertia ixx="100" ixy="0" ixz="0" iyy="100" iyz="0" izz="100" />
        </inertial>
        <visual>
            <origin xyz="0.7756583500548497 0 0" rpy="0 0 0"/>
            <geometry>
                <box size="1.5513167001096995 1.859831014482653 1.8256962413390265" />
            </geometry>
            <material name="Green">
                <color rgba="0 180.0 0.0 1.0"/>
            </material>
        </visual>
        <collision>
            <origin xyz="0.7756583500548497 0 0" rpy="0 0 0"/>
            <geometry>
                <box size="1.5513167001096995 1.859831014482653 1.8256962413390265" />
            </geometry>
        </collision>
    </link>
    <link name="Leg6">
        <inertial>
            <origin xyz="0.5476324104991905 0 0" rpy="0 0 0"/>
            <mass value="1" />
            <inertia ixx="100" ixy="0" ixz="0" iyy="100" iyz="0" izz="100" />
        </inertial>
        <visual>
            <origin xyz="0.5476324104991905 0 0" rpy="0 0 0"/>
            <geometry>
                <box size="1.095264820998381 2.819321439528758 2.2720036665370777" />
            </geometry>
            <material name="Green">
                <color rgba="0 180.0 0.0 1.0"/>
            </material>
        </visual>
        <collision>
            <origin xyz="0.5476324104991905 0 0" rpy="0 0 0"/>
            <geometry>
                <box size="1.095264820998381 2.819321439528758 2.2720036665370777" />
            </geometry>
        </collision>
    </link>
    <link name="Leg7">
        <inertial>
            <origin xyz="1.0443130005301575 0 0" rpy="0 0 0"/>
            <mass value="1" />
            <inertia ixx="100" ixy="0" ixz="0" iyy="100" iyz="0" izz="100" />
        </inertial>
        <visual>
            <origin xyz="1.0443130005301575 0 0" rpy="0 0 0"/>
            <geometry>
                <box size="2.088626001060315 1.8976041462681308 1.6969823608024708" />
            </geometry>
            <material name="Blue">
                <color rgba="0 1.0 1.0 1.0"/>
            </material>
        </visual>
        <collision>
            <origin xyz="1.0443130005301575 0 0" rpy="0 0 0"/>
            <geometry>
                <box size="2.088626001060315 1.8976041462681308 1.6969823608024708" />
            </geometry>
        </collision>
    </link>
    <link name="Leg8">
        <inertial>
            <origin xyz="0 1.2770674756763456 0" rpy="0 0 0"/>
            <mass value="1" />
            <inertia ixx="100" ixy="0" ixz="0" iyy="100" iyz="0" izz="100" />
        </inertial>
        <visual>
            <origin xyz="0 1.2770674756763456 0" rpy="0 0 0"/>
            <geometry>
                <box size="2.284677950974249 2.554134951352691 2.1461103621648787" />
            </geometry>
            <material name="Green">
                <color rgba="0 180.0 0.0 1.0"/>
            </material>
        </visual>
        <collision>
            <origin xyz="0 1.2770674756763456 0" rpy="0 0 0"/>
            <geometry>
                <box size="2.284677950974249 2.554134951352691 2.1461103621648787" />
            </geometry>
        </collision>
    </link>
    <link name="Leg9">
        <inertial>
            <origin xyz="0 1.2463196541871855 0" rpy="0 0 0"/>
            <mass value="1" />
            <inertia ixx="100" ixy="0" ixz="0" iyy="100" iyz="0" izz="100" />
        </inertial>
        <visual>
            <origin xyz="0 1.2463196541871855 0" rpy="0 0 0"/>
            <geometry>
                <box size="1.7757616374538374 2.492639308374371 2.248279666648104" />
            </geometry>
            <material name="Green">
                <color rgba="0 180.0 0.0 1.0"/>
            </material>
        </visual>
        <collision>
            <origin xyz="0 1.2463196541871855 0" rpy="0 0 0"/>
            <geometry>
                <box size="1.7757616374538374 2.492639308374371 2.248279666648104" />
            </geometry>
        </collision>
    </link>
    <link name="Leg10">
        <inertial>
            <origin xyz="0 1.205877868363153 0" rpy="0 0 0"/>
            <mass value="1" />
            <inertia ixx="100" ixy="0" ixz="0" iyy="100" iyz="0" izz="100" />
        </inertial>
        <visual>
            <origin xyz="0 1.205877868363153 0" rpy="0 0 0"/>
            <geometry>
                <box size="2.3653449042942394 2.411755736726306 1.1899310048139244" />
            </geometry>
            <material name="Green">
                <color rgba="0 180.0 0.0 1.0"/>
            </material>
        </visual>
        <collision>
            <origin xyz="0 1.205877868363153 0" rpy="0 0 0"/>
            <geometry>
                <box size="2.3653449042942394 2.411755736726306 1.1899310048139244" />
            </geometry>
        </collision>
    </link>
    <link name="Leg11">
        <inertial>
            <origin xyz="0 0 1.2121660763736524" rpy="0 0 0"/>
            <mass value="1" />
            <inertia ixx="100" ixy="0" ixz="0" iyy="100" iyz="0" izz="100" />
        </inertial>
        <visual>
            <origin xyz="0 0 1.2121660763736524" rpy="0 0 0"/>
            <geometry>
                <box size="1.625701193838041 2.3958968992961354 2.4243321527473047" />
            </geometry>
            <material name="Blue">
                <color rgba="0 1.0 1.0 1.0"/>
            </material>
        </visual>
        <collision>
            <origin xyz="0 0 1.2121660763736524" rpy="0 0 0"/>
            <geometry>
                <box size="1.625701193838041 2.3958968992961354 2.4243321527473047" />
            </geometry>
        </collision>
    </link>
    <link name="Leg12">
        <inertial>
            <origin xyz="0 0 0.8124139877280124" rpy="0 0 0"/>
            <mass value="1" />
            <inertia ixx="100" ixy="0" ixz="0" iyy="100" iyz="0" izz="100" />
        </inertial>
        <visual>
            <origin xyz="0 0 0.8124139877280124" rpy="0 0 0"/>
            <geometry>
                <box size="1.5020523597637365 2.824278209371591 1.6248279754560249" />
            </geometry>
            <material name="Green">
                <color rgba="0 180.0 0.0 1.0"/>
            </material>
        </visual>
        <collision>
            <origin xyz="0 0 0.8124139877280124" rpy="0 0 0"/>
            <geometry>
                <box size="1.5020523597637365 2.824278209371591 1.6248279754560249" />
            </geometry>
        </collision>
    </link>
    <link name="Leg13">
        <inertial>
            <origin xyz="0 0 1.1051593929420038" rpy="0 0 0"/>
            <mass value="1" />
            <inertia ixx="100" ixy="0" ixz="0" iyy="100" iyz="0" izz="100" />
        </inertial>
        <visual>
            <origin xyz="0 0 1.1051593929420038" rpy="0 0 0"/>
            <geometry>
                <box size="2.0369140831954513 1.3164187056973355 2.2103187858840077" />
            </geometry>
            <material name="Blue">
                <color rgba="0 1.0 1.0 1.0"/>
            </material>
        </visual>
        <collision>
            <origin xyz="0 0 1.1051593929420038" rpy="0 0 0"/>
            <geometry>
                <box size="2.0369140831954513 1.3164187056973355 2.2103187858840077" />
            </geometry>
        </collision>
    </link>
    <link name="Leg14">
        <inertial>
            <origin xyz="0 0.7800008316103113 0" rpy="0 0 0"/>
            <mass value="1" />
            <inertia ixx="100" ixy="0" ixz="0" iyy="100" iyz="0" izz="100" />
        </inertial>
        <visual>
            <origin xyz="0 0.7800008316103113 0" rpy="0 0 0"/>
            <geometry>
                <box size="2.926083728762362 1.5600016632206226 1.8138378238239028" />
            </geometry>
            <material name="Green">
                <color rgba="0 180.0 0.0 1.0"/>
            </material>
        </visual>
        <collision>
            <origin xyz="0 0.7800008316103113 0" rpy="0 0 0"/>
            <geometry>
                <box size="2.926083728762362 1.5600016632206226 1.8138378238239028" />
            </geometry>
        </collision>
    </link>
    <link name="Leg15">
        <inertial>
            <origin xyz="1.4545772659843967 0 0" rpy="0 0 0"/>
            <mass value="1" />
            <inertia ixx="100" ixy="0" ixz="0" iyy="100" iyz="0" izz="100" />
        </inertial>
        <visual>
            <origin xyz="1.4545772659843967 0 0" rpy="0 0 0"/>
            <geometry>
                <box size="2.9091545319687935 2.427309654085451 1.8134651531606536" />
            </geometry>
            <material name="Green">
                <color rgba="0 180.0 0.0 1.0"/>
            </material>
        </visual>
        <collision>
            <origin xyz="1.4545772659843967 0 0" rpy="0 0 0"/>
            <geometry>
                <box size="2.9091545319687935 2.427309654085451 1.8134651531606536" />
            </geometry>
        </collision>
    </link>
    <link name="Leg16">
        <inertial>
            <origin xyz="0 0 1.0440138131881718" rpy="0 0 0"/>
            <mass value="1" />
            <inertia ixx="100" ixy="0" ixz="0" iyy="100" iyz="0" izz="100" />
        </inertial>
        <visual>
            <origin xyz="0 0 1.0440138131881718" rpy="0 0 0"/>
            <geometry>
                <box size="2.6297141144485194 1.6660807620868623 2.0880276263763435" />
            </geometry>
            <material name="Blue">
                <color rgba="0 1.0 1.0 1.0"/>
            </material>
        </visual>
        <collision>
            <origin xyz="0 0 1.0440138131881718" rpy="0 0 0"/>
            <geometry>
                <box size="2.6297141144485194 1.6660807620868623 2.0880276263763435" />
            </geometry>
        </collision>
    </link>
    <link name="Leg17">
        <inertial>
            <origin xyz="0 0 1.3252700074750692" rpy="0 0 0"/>
            <mass value="1" />
            <inertia ixx="100" ixy="0" ixz="0" iyy="100" iyz="0" izz="100" />
        </inertial>
        <visual>
            <origin xyz="0 0 1.3252700074750692" rpy="0 0 0"/>
            <geometry>
                <box size="1.5087813667144174 2.3741580917369736 2.6505400149501384" />
            </geometry>
            <material name="Green">
                <color rgba="0 180.0 0.0 1.0"/>
            </material>
        </visual>
        <collision>
            <origin xyz="0 0 1.3252700074750692" rpy="0 0 0"/>
            <geometry>
                <box size="1.5087813667144174 2.3741580917369736 2.6505400149501384" />
            </geometry>
        </collision>
    </link>
    <link name="Leg18">
        <inertial>
            <origin xyz="0.7280164304385082 0 0" rpy="0 0 0"/>
            <mass value="1" />
            <inertia ixx="100" ixy="0" ixz="0" iyy="100" iyz="0" izz="100" />
        </inertial>
        <visual>
            <origin xyz="0.7280164304385082 0 0" rpy="0 0 0"/>
            <geometry>
                <box size="1.4560328608770163 1.0865530628036708 1.104451390646063" />
            </geometry>
            <material name="Blue">
                <color rgba="0 1.0 1.0 1.0"/>
            </material>
        </visual>
        <collision>
            <origin xyz="0.7280164304385082 0 0" rpy="0 0 0"/>
            <geometry>
                <box size="1.4560328608770163 1.0865530628036708 1.104451390646063" />
            </geometry>
        </collision>
    </link>
    <link name="Leg19">
        <inertial>
            <origin xyz="0 1.2910463940099186 0" rpy="0 0 0"/>
            <mass value="1" />
            <inertia ixx="100" ixy="0" ixz="0" iyy="100" iyz="0" izz="100" />
        </inertial>
        <visual>
            <origin xyz="0 1.2910463940099186 0" rpy="0 0 0"/>
            <geometry>
                <box size="1.0054929693291237 2.582092788019837 2.009017833042801" />
            </geometry>
            <material name="Blue">
                <color rgba="0 1.0 1.0 1.0"/>
            </material>
        </visual>
        <collision>
            <origin xyz="0 1.2910463940099186 0" rpy="0 0 0"/>
            <geometry>
                <box size="1.0054929693291237 2.582092788019837 2.009017833042801" />
            </geometry>
        </collision>
    </link>
    <link name="Leg20">
        <inertial>
            <origin xyz="0 0 0.9058726655350477" rpy="0 0 0"/>
            <mass value="1" />
            <inertia ixx="100" ixy="0" ixz="0" iyy="100" iyz="0" izz="100" />
        </inertial>
        <visual>
            <origin xyz="0 0 0.9058726655350477" rpy="0 0 0"/>
            <geometry>
                <box size="2.5063917059501435 2.1201395067104043 1.8117453310700955" />
            </geometry>
            <material name="Blue">
                <color rgba="0 1.0 1.0 1.0"/>
            </material>
        </visual>
        <collision>
            <origin xyz="0 0 0.9058726655350477" rpy="0 0 0"/>
            <geometry>
                <box size="2.5063917059501435 2.1201395067104043 1.8117453310700955" />
            </geometry>
        </collision>
    </link>
    <link name="Leg21">
        <inertial>
            <origin xyz="0.967238808263259 0 0" rpy="0 0 0"/>
            <mass value="1" />
            <inertia ixx="100" ixy="0" ixz="0" iyy="100" iyz="0" izz="100" />
        </inertial>
        <visual>
            <origin xyz="0.967238808263259 0 0" rpy="0 0 0"/>
            <geometry>
                <box size="1.934477616526518 2.844717325971833 2.593577627202294" />
            </geometry>
            <material name="Green">
                <color rgba="0 180.0 0.0 1.0"/>
            </material>
        </visual>
        <collision>
            <origin xyz="0.967238808263259 0 0" rpy="0 0 0"/>
            <geometry>
                <box size="1.934477616526518 2.844717325971833 2.593577627202294" />
            </geometry>
        </collision>
    </link>
    <link name="Leg22">
        <inertial>
            <origin xyz="0 0 0.6331976146542925" rpy="0 0 0"/>
            <mass value="1" />
            <inertia ixx="100" ixy="0" ixz="0" iyy="100" iyz="0" izz="100" />
        </inertial>
        <visual>
            <origin xyz="0 0 0.6331976146542925" rpy="0 0 0"/>
            <geometry>
                <box size="1.6173865840194448 1.5039500149589686 1.266395229308585" />
            </geometry>
            <material name="Green">
                <color rgba="0 180.0 0.0 1.0"/>
            </material>
        </visual>
        <collision>
            <origin xyz="0 0 0.6331976146542925" rpy="0 0 0"/>
            <geometry>
                <box size="1.6173865840194448 1.5039500149589686 1.266395229308585" />
            </geometry>
        </collision>
    </link>
    <link name="Leg23">
        <inertial>
            <origin xyz="0 0.9222429236559604 0" rpy="0 0 0"/>
            <mass value="1" />
            <inertia ixx="100" ixy="0" ixz="0" iyy="100" iyz="0" izz="100" />
        </inertial>
        <visual>
            <origin xyz="0 0.9222429236559604 0" rpy="0 0 0"/>
            <geometry>
                <box size="1.2214220902732957 1.8444858473119208 2.681500207222536" />
            </geometry>
            <material name="Green">
                <color rgba="0 180.0 0.0 1.0"/>
            </material>
        </visual>
        <collision>
            <origin xyz="0 0.9222429236559604 0" rpy="0 0 0"/>
            <geometry>
                <box size="1.2214220902732957 1.8444858473119208 2.681500207222536" />
            </geometry>
        </collision>
    </link>
    <link name="Leg24">
        <inertial>
            <origin xyz="0 0 0.8458700684199884" rpy="0 0 0"/>
            <mass value="1" />
            <inertia ixx="100" ixy="0" ixz="0" iyy="100" iyz="0" izz="100" />
        </inertial>
        <visual>
            <origin xyz="0 0 0.8458700684199884" rpy="0 0 0"/>
            <geometry>
                <box size="1.8103076935380193 1.3842808234748307 1.6917401368399767" />
            </geometry>
            <material name="Blue">
                <color rgba="0 1.0 1.0 1.0"/>
            </material>
        </visual>
        <collision>
            <origin xyz="0 0 0.8458700684199884" rpy="0 0 0"/>
            <geometry>
                <box size="1.8103076935380193 1.3842808234748307 1.6917401368399767" />
            </geometry>
        </collision>
    </link>
    <link name="Leg25">
        <inertial>
            <origin xyz="0.5918583722139457 0 0" rpy="0 0 0"/>
            <mass value="1" />
            <inertia ixx="100" ixy="0" ixz="0" iyy="100" iyz="0" izz="100" />
        </inertial>
        <visual>
            <origin xyz="0.5918583722139457 0 0" rpy="0 0 0"/>
            <geometry>
                <box size="1.1837167444278913 1.5208568004680096 2.0012625391048005" />
            </geometry>
            <material name="Green">
                <color rgba="0 180.0 0.0 1.0"/>
            </material>
        </visual>
        <collision>
            <origin xyz="0.5918583722139457 0 0" rpy="0 0 0"/>
            <geometry>
                <box size="1.1837167444278913 1.5208568004680096 2.0012625391048005" />
            </geometry>
        </collision>
    </link>
    <link name="Leg26">
        <inertial>
            <origin xyz="0 1.4557567564428329 0" rpy="0 0 0"/>
            <mass value="1" />
            <inertia ixx="100" ixy="0" ixz="0" iyy="100" iyz="0" izz="100" />
        </inertial>
        <visual>
            <origin xyz="0 1.4557567564428329 0" rpy="0 0 0"/>
            <geometry>
                <box size="2.895821427585418 2.9115135128856657 2.4136833947332867" />
            </geometry>
            <material name="Blue">
                <color rgba="0 1.0 1.0 1.0"/>
            </material>
        </visual>
        <collision>
            <origin xyz="0 1.4557567564428329 0" rpy="0 0 0"/>
            <geometry>
                <box size="2.895821427585418 2.9115135128856657 2.4136833947332867" />
            </geometry>
        </collision>
    </link>
    <joint name="Torso_Leg1" type="revolute">
       <parent link="Torso"/>
       <child  link="Leg1"/>
       <origin rpy="0 0 0" xyz="1.438926439319395 0 1.052470642744404" />
     <axis xyz="1 0 0"/>
       <limit effort="0.0" lower="-3.14159" upper="3.14159" velocity="0.0"/>
    </joint>
    <joint name="Torso_Leg2" type="revolute">
       <parent link="Torso"/>
       <child  link="Leg2"/>
       <origin rpy="0 0 0" xyz="1.3575843457707237 0 0.7073778047228" />
     <axis xyz="1 0 0"/>
       <limit effort="0.0" lower="-3.14159" upper="3.14159" velocity="0.0"/>
    </joint>
    <joint name="Leg2_Leg3" type="revolute">
       <parent link="Leg2"/>
       <child  link="Leg3"/>
       <origin rpy="0 0 0" xyz="0 0 1.7919371877163879" />
     <axis xyz="1 0 0"/>
       <limit effort="0.0" lower="-3.14159" upper="3.14159" velocity="0.0"/>
    </joint>
    <joint name="Leg3_Leg4" type="revolute">
       <parent link="Leg3"/>
       <child  link="Leg4"/>
       <origin rpy="0 0 0" xyz="0 0 1.5437317540110294" />
     <axis xyz="1 0 0"/>
       <limit effort="0.0" lower="-3.14159" upper="3.14159" velocity="0.0"/>
    </joint>
    <joint name="Leg4_Leg5" type="revolute">
       <parent link="Leg4"/>
       <child  link="Leg5"/>
       <origin rpy="0 0 0" xyz="1.5513167001096995 0 0" />
     <axis xyz="1 0 0"/>
       <limit effort="0.0" lower="-3.14159" upper="3.14159" velocity="0.0"/>
    </joint>
    <joint name="Leg3_Leg6" type="revolute">
       <parent link="Leg3"/>
       <child  link="Leg6"/>
       <origin rpy="0 0 0" xyz="0.802253159021553 0 1.5437317540110294" />
     <axis xyz="1 0 0"/>
       <limit effort="0.0" lower="-3.14159" upper="3.14159" velocity="0.0"/>
    </joint>
    <joint name="Leg5_Leg7" type="revolute">
       <parent link="Leg5"/>
       <child  link="Leg7"/>
       <origin rpy="0 0 0" xyz="1.095264820998381 0 0" />
     <axis xyz="1 0 0"/>
       <limit effort="0.0" lower="-3.14159" upper="3.14159" velocity="0.0"/>
    </joint>
    <joint name="Leg6_Leg8" type="revolute">
       <parent link="Leg6"/>
       <child  link="Leg8"/>
       <origin rpy="0 0 0" xyz="1.0443130005301575 0.9488020731340654 0" />
     <axis xyz="1 0 0"/>
       <limit effort="0.0" lower="-3.14159" upper="3.14159" velocity="0.0"/>
    </joint>
    <joint name="Leg2_Leg9" type="revolute">
       <parent link="Leg2"/>
       <child  link="Leg9"/>
       <origin rpy="0 0 0" xyz="0 1.4641302900256565 1.7919371877163879" />
     <axis xyz="1 0 0"/>
       <limit effort="0.0" lower="-3.14159" upper="3.14159" velocity="0.0"/>
    </joint>
    <joint name="Torso_Leg10" type="revolute">
       <parent link="Torso"/>
       <child  link="Leg10"/>
       <origin rpy="0 0 0" xyz="1.3575843457707237 0.7420018333594461 0.7073778047228" />
     <axis xyz="1 0 0"/>
       <limit effort="0.0" lower="-3.14159" upper="3.14159" velocity="0.0"/>
    </joint>
    <joint name="Leg7_Leg11" type="revolute">
       <parent link="Leg7"/>
       <child  link="Leg11"/>
       <origin rpy="0 0 0" xyz="0 1.2770674756763456 1.0730551810824394" />
     <axis xyz="1 0 0"/>
       <limit effort="0.0" lower="-3.14159" upper="3.14159" velocity="0.0"/>
    </joint>
    <joint name="Leg6_Leg12" type="revolute">
       <parent link="Leg6"/>
       <child  link="Leg12"/>
       <origin rpy="0 0 0" xyz="1.0443130005301575 0.9488020731340654 0.8484911804012354" />
     <axis xyz="1 0 0"/>
       <limit effort="0.0" lower="-3.14159" upper="3.14159" velocity="0.0"/>
    </joint>
    <joint name="Leg11_Leg13" type="revolute">
       <parent link="Leg11"/>
       <child  link="Leg13"/>
       <origin rpy="0 0 0" xyz="0 0 1.6248279754560249" />
     <axis xyz="1 0 0"/>
       <limit effort="0.0" lower="-3.14159" upper="3.14159" velocity="0.0"/>
    </joint>
    <joint name="Leg7_Leg14" type="revolute">
       <parent link="Leg7"/>
       <child  link="Leg14"/>
       <origin rpy="0 0 0" xyz="0 2.554134951352691 1.0730551810824394" />
     <axis xyz="1 0 0"/>
       <limit effort="0.0" lower="-3.14159" upper="3.14159" velocity="0.0"/>
    </joint>
    <joint name="Leg12_Leg15" type="revolute">
       <parent link="Leg12"/>
       <child  link="Leg15"/>
       <origin rpy="0 0 0" xyz="1.0184570415977257 0 1.1051593929420038" />
     <axis xyz="1 0 0"/>
       <limit effort="0.0" lower="-3.14159" upper="3.14159" velocity="0.0"/>
    </joint>
    <joint name="Leg4_Leg16" type="revolute">
       <parent link="Leg4"/>
       <child  link="Leg16"/>
       <origin rpy="0 0 0" xyz="1.5513167001096995 0 0.9128481206695133" />
     <axis xyz="1 0 0"/>
       <limit effort="0.0" lower="-3.14159" upper="3.14159" velocity="0.0"/>
    </joint>
    <joint name="Leg13_Leg17" type="revolute">
       <parent link="Leg13"/>
       <child  link="Leg17"/>
       <origin rpy="0 0 0" xyz="0 0.7800008316103113 0.9069189119119514" />
     <axis xyz="1 0 0"/>
       <limit effort="0.0" lower="-3.14159" upper="3.14159" velocity="0.0"/>
    </joint>
    <joint name="Leg2_Leg18" type="revolute">
       <parent link="Leg2"/>
       <child  link="Leg18"/>
       <origin rpy="0 0 0" xyz="0.8015789404437332 1.4641302900256565 1.7919371877163879" />
     <axis xyz="1 0 0"/>
       <limit effort="0.0" lower="-3.14159" upper="3.14159" velocity="0.0"/>
    </joint>
    <joint name="Leg18_Leg19" type="revolute">
       <parent link="Leg18"/>
       <child  link="Leg19"/>
       <origin rpy="0 0 0" xyz="0 2.582092788019837 0" />
     <axis xyz="1 0 0"/>
       <limit effort="0.0" lower="-3.14159" upper="3.14159" velocity="0.0"/>
    </joint>
    <joint name="Leg12_Leg20" type="revolute">
       <parent link="Leg12"/>
       <child  link="Leg20"/>
       <origin rpy="0 0 0" xyz="1.0184570415977257 0 2.2103187858840077" />
     <axis xyz="1 0 0"/>
       <limit effort="0.0" lower="-3.14159" upper="3.14159" velocity="0.0"/>
    </joint>
    <joint name="Leg7_Leg21" type="revolute">
       <parent link="Leg7"/>
       <child  link="Leg21"/>
       <origin rpy="0 0 0" xyz="1.1423389754871245 2.554134951352691 1.0730551810824394" />
     <axis xyz="1 0 0"/>
       <limit effort="0.0" lower="-3.14159" upper="3.14159" velocity="0.0"/>
    </joint>
    <joint name="Leg10_Leg22" type="revolute">
       <parent link="Leg10"/>
       <child  link="Leg22"/>
       <origin rpy="0 0 0" xyz="0 0 2.4243321527473047" />
     <axis xyz="1 0 0"/>
       <limit effort="0.0" lower="-3.14159" upper="3.14159" velocity="0.0"/>
    </joint>
    <joint name="Leg8_Leg23" type="revolute">
       <parent link="Leg8"/>
       <child  link="Leg23"/>
       <origin rpy="0 0 0" xyz="0 2.492639308374371 0" />
     <axis xyz="1 0 0"/>
       <limit effort="0.0" lower="-3.14159" upper="3.14159" velocity="0.0"/>
    </joint>
    <joint name="Leg18_Leg24" type="revolute">
       <parent link="Leg18"/>
       <child  link="Leg24"/>
       <origin rpy="0 0 0" xyz="0 2.582092788019837 1.0045089165214005" />
     <axis xyz="1 0 0"/>
       <limit effort="0.0" lower="-3.14159" upper="3.14159" velocity="0.0"/>
    </joint>
    <joint name="Leg1_Leg25" type="revolute">
       <parent link="Leg1"/>
       <child  link="Leg25"/>
       <origin rpy="0 0 0" xyz="1.3682756355934682 0 1.0423614332484408" />
     <axis xyz="1 0 0"/>
       <limit effort="0.0" lower="-3.14159" upper="3.14159" velocity="0.0"/>
    </joint>
    <joint name="Leg13_Leg26" type="revolute">
       <parent link="Leg13"/>
       <child  link="Leg26"/>
       <origin rpy="0 0 0" xyz="0 1.5600016632206226 0.9069189119119514" />
     <axis xyz="1 0 0"/>
       <limit effort="0.0" lower="-3.14159" upper="3.14159" velocity="0.0"/>
    </joint>
</robot>