<robot name = "robot">
    <link name="Torso">
        <inertial>
            <origin xyz="0 0 1.4286457825688808" rpy="0 0 0"/>
            <mass value="1" />
            <inertia ixx="100" ixy="0" ixz="0" iyy="100" iyz="0" izz="100" />
        </inertial>
        <visual>
            <origin xyz="0 0 1.4286457825688808" rpy="0 0 0"/>
            <geometry>
                <box size="1.4139237255535415 1.2379126515026069 2.8572915651377615" />
            </geometry>
            <material name="Green">
                <color rgba="0 180.0 0.0 1.0"/>
            </material>
        </visual>
        <collision>
            <origin xyz="0 0 1.4286457825688808" rpy="0 0 0"/>
            <geometry>
                <box size="1.4139237255535415 1.2379126515026069 2.8572915651377615" />
            </geometry>
        </collision>
    </link>
    <link name="Leg1">
        <inertial>
            <origin xyz="0 0.5533776462784132 0" rpy="0 0 0"/>
            <mass value="1" />
            <inertia ixx="100" ixy="0" ixz="0" iyy="100" iyz="0" izz="100" />
        </inertial>
        <visual>
            <origin xyz="0 0.5533776462784132 0" rpy="0 0 0"/>
            <geometry>
                <box size="1.3549594037825006 1.1067552925568265 2.8308728085621944" />
            </geometry>
            <material name="Green">
                <color rgba="0 180.0 0.0 1.0"/>
            </material>
        </visual>
        <collision>
            <origin xyz="0 0.5533776462784132 0" rpy="0 0 0"/>
            <geometry>
                <box size="1.3549594037825006 1.1067552925568265 2.8308728085621944" />
            </geometry>
        </collision>
    </link>
    <link name="Leg2">
        <inertial>
            <origin xyz="1.0654723602058804 0 0" rpy="0 0 0"/>
            <mass value="1" />
            <inertia ixx="100" ixy="0" ixz="0" iyy="100" iyz="0" izz="100" />
        </inertial>
        <visual>
            <origin xyz="1.0654723602058804 0 0" rpy="0 0 0"/>
            <geometry>
                <box size="2.130944720411761 1.9199151079809764 1.2891989680401674" />
            </geometry>
            <material name="Blue">
                <color rgba="0 1.0 1.0 1.0"/>
            </material>
        </visual>
        <collision>
            <origin xyz="1.0654723602058804 0 0" rpy="0 0 0"/>
            <geometry>
                <box size="2.130944720411761 1.9199151079809764 1.2891989680401674" />
            </geometry>
        </collision>
    </link>
    <link name="Leg3">
        <inertial>
            <origin xyz="0 0 0.5477078483697355" rpy="0 0 0"/>
            <mass value="1" />
            <inertia ixx="100" ixy="0" ixz="0" iyy="100" iyz="0" izz="100" />
        </inertial>
        <visual>
            <origin xyz="0 0 0.5477078483697355" rpy="0 0 0"/>
            <geometry>
                <box size="2.9036243735093588 2.899451514086379 1.095415696739471" />
            </geometry>
            <material name="Green">
                <color rgba="0 180.0 0.0 1.0"/>
            </material>
        </visual>
        <collision>
            <origin xyz="0 0 0.5477078483697355" rpy="0 0 0"/>
            <geometry>
                <box size="2.9036243735093588 2.899451514086379 1.095415696739471" />
            </geometry>
        </collision>
    </link>
    <link name="Leg4">
        <inertial>
            <origin xyz="0 0.6470641368189237 0" rpy="0 0 0"/>
            <mass value="1" />
            <inertia ixx="100" ixy="0" ixz="0" iyy="100" iyz="0" izz="100" />
        </inertial>
        <visual>
            <origin xyz="0 0.6470641368189237 0" rpy="0 0 0"/>
            <geometry>
                <box size="1.0187150532186133 1.2941282736378474 1.1452403639019504" />
            </geometry>
            <material name="Green">
                <color rgba="0 180.0 0.0 1.0"/>
            </material>
        </visual>
        <collision>
            <origin xyz="0 0.6470641368189237 0" rpy="0 0 0"/>
            <geometry>
                <box size="1.0187150532186133 1.2941282736378474 1.1452403639019504" />
            </geometry>
        </collision>
    </link>
    <link name="Leg5">
        <inertial>
            <origin xyz="0 0.7244950253230005 0" rpy="0 0 0"/>
            <mass value="1" />
            <inertia ixx="100" ixy="0" ixz="0" iyy="100" iyz="0" izz="100" />
        </inertial>
        <visual>
            <origin xyz="0 0.7244950253230005 0" rpy="0 0 0"/>
            <geometry>
                <box size="2.6419274939019193 1.448990050646001 1.014046151876032" />
            </geometry>
            <material name="Green">
                <color rgba="0 180.0 0.0 1.0"/>
            </material>
        </visual>
        <collision>
            <origin xyz="0 0.7244950253230005 0" rpy="0 0 0"/>
            <geometry>
                <box size="2.6419274939019193 1.448990050646001 1.014046151876032" />
            </geometry>
        </collision>
    </link>
    <link name="Leg6">
        <inertial>
            <origin xyz="1.0539383518752254 0 0" rpy="0 0 0"/>
            <mass value="1" />
            <inertia ixx="100" ixy="0" ixz="0" iyy="100" iyz="0" izz="100" />
        </inertial>
        <visual>
            <origin xyz="1.0539383518752254 0 0" rpy="0 0 0"/>
            <geometry>
                <box size="2.107876703750451 2.817767643796225 1.2758290266298171" />
            </geometry>
            <material name="Green">
                <color rgba="0 180.0 0.0 1.0"/>
            </material>
        </visual>
        <collision>
            <origin xyz="1.0539383518752254 0 0" rpy="0 0 0"/>
            <geometry>
                <box size="2.107876703750451 2.817767643796225 1.2758290266298171" />
            </geometry>
        </collision>
    </link>
    <link name="Leg7">
        <inertial>
            <origin xyz="0 0 1.1802349372036973" rpy="0 0 0"/>
            <mass value="1" />
            <inertia ixx="100" ixy="0" ixz="0" iyy="100" iyz="0" izz="100" />
        </inertial>
        <visual>
            <origin xyz="0 0 1.1802349372036973" rpy="0 0 0"/>
            <geometry>
                <box size="2.7158935071255943 2.384804416665417 2.3604698744073946" />
            </geometry>
            <material name="Green">
                <color rgba="0 180.0 0.0 1.0"/>
            </material>
        </visual>
        <collision>
            <origin xyz="0 0 1.1802349372036973" rpy="0 0 0"/>
            <geometry>
                <box size="2.7158935071255943 2.384804416665417 2.3604698744073946" />
            </geometry>
        </collision>
    </link>
    <link name="Leg8">
        <inertial>
            <origin xyz="0 1.3804546696830242 0" rpy="0 0 0"/>
            <mass value="1" />
            <inertia ixx="100" ixy="0" ixz="0" iyy="100" iyz="0" izz="100" />
        </inertial>
        <visual>
            <origin xyz="0 1.3804546696830242 0" rpy="0 0 0"/>
            <geometry>
                <box size="2.578568354074931 2.7609093393660484 2.141182989580523" />
            </geometry>
            <material name="Blue">
                <color rgba="0 1.0 1.0 1.0"/>
            </material>
        </visual>
        <collision>
            <origin xyz="0 1.3804546696830242 0" rpy="0 0 0"/>
            <geometry>
                <box size="2.578568354074931 2.7609093393660484 2.141182989580523" />
            </geometry>
        </collision>
    </link>
    <link name="Leg9">
        <inertial>
            <origin xyz="0 0.6653294080767724 0" rpy="0 0 0"/>
            <mass value="1" />
            <inertia ixx="100" ixy="0" ixz="0" iyy="100" iyz="0" izz="100" />
        </inertial>
        <visual>
            <origin xyz="0 0.6653294080767724 0" rpy="0 0 0"/>
            <geometry>
                <box size="1.0615770597366672 1.3306588161535449 1.621130078538423" />
            </geometry>
            <material name="Blue">
                <color rgba="0 1.0 1.0 1.0"/>
            </material>
        </visual>
        <collision>
            <origin xyz="0 0.6653294080767724 0" rpy="0 0 0"/>
            <geometry>
                <box size="1.0615770597366672 1.3306588161535449 1.621130078538423" />
            </geometry>
        </collision>
    </link>
    <link name="Leg10">
        <inertial>
            <origin xyz="0.6118227018150313 0 0" rpy="0 0 0"/>
            <mass value="1" />
            <inertia ixx="100" ixy="0" ixz="0" iyy="100" iyz="0" izz="100" />
        </inertial>
        <visual>
            <origin xyz="0.6118227018150313 0 0" rpy="0 0 0"/>
            <geometry>
                <box size="1.2236454036300626 2.3409449728112404 1.0154340638511568" />
            </geometry>
            <material name="Blue">
                <color rgba="0 1.0 1.0 1.0"/>
            </material>
        </visual>
        <collision>
            <origin xyz="0.6118227018150313 0 0" rpy="0 0 0"/>
            <geometry>
                <box size="1.2236454036300626 2.3409449728112404 1.0154340638511568" />
            </geometry>
        </collision>
    </link>
    <link name="Leg11">
        <inertial>
            <origin xyz="0.992968044684967 0 0" rpy="0 0 0"/>
            <mass value="1" />
            <inertia ixx="100" ixy="0" ixz="0" iyy="100" iyz="0" izz="100" />
        </inertial>
        <visual>
            <origin xyz="0.992968044684967 0 0" rpy="0 0 0"/>
            <geometry>
                <box size="1.985936089369934 2.475341201022329 2.1434876150658333" />
            </geometry>
            <material name="Green">
                <color rgba="0 180.0 0.0 1.0"/>
            </material>
        </visual>
        <collision>
            <origin xyz="0.992968044684967 0 0" rpy="0 0 0"/>
            <geometry>
                <box size="1.985936089369934 2.475341201022329 2.1434876150658333" />
            </geometry>
        </collision>
    </link>
    <link name="Leg12">
        <inertial>
            <origin xyz="0 0 1.2168741073923817" rpy="0 0 0"/>
            <mass value="1" />
            <inertia ixx="100" ixy="0" ixz="0" iyy="100" iyz="0" izz="100" />
        </inertial>
        <visual>
            <origin xyz="0 0 1.2168741073923817" rpy="0 0 0"/>
            <geometry>
                <box size="2.1327189955940193 2.150160928173582 2.4337482147847633" />
            </geometry>
            <material name="Blue">
                <color rgba="0 1.0 1.0 1.0"/>
            </material>
        </visual>
        <collision>
            <origin xyz="0 0 1.2168741073923817" rpy="0 0 0"/>
            <geometry>
                <box size="2.1327189955940193 2.150160928173582 2.4337482147847633" />
            </geometry>
        </collision>
    </link>
    <link name="Leg13">
        <inertial>
            <origin xyz="0 0.5081958454477972 0" rpy="0 0 0"/>
            <mass value="1" />
            <inertia ixx="100" ixy="0" ixz="0" iyy="100" iyz="0" izz="100" />
        </inertial>
        <visual>
            <origin xyz="0 0.5081958454477972 0" rpy="0 0 0"/>
            <geometry>
                <box size="1.2618455306216063 1.0163916908955943 1.274366264719003" />
            </geometry>
            <material name="Green">
                <color rgba="0 180.0 0.0 1.0"/>
            </material>
        </visual>
        <collision>
            <origin xyz="0 0.5081958454477972 0" rpy="0 0 0"/>
            <geometry>
                <box size="1.2618455306216063 1.0163916908955943 1.274366264719003" />
            </geometry>
        </collision>
    </link>
    <link name="Leg14">
        <inertial>
            <origin xyz="0 1.3307517839277747 0" rpy="0 0 0"/>
            <mass value="1" />
            <inertia ixx="100" ixy="0" ixz="0" iyy="100" iyz="0" izz="100" />
        </inertial>
        <visual>
            <origin xyz="0 1.3307517839277747 0" rpy="0 0 0"/>
            <geometry>
                <box size="1.7193378510799826 2.6615035678555494 1.1692553761368203" />
            </geometry>
            <material name="Blue">
                <color rgba="0 1.0 1.0 1.0"/>
            </material>
        </visual>
        <collision>
            <origin xyz="0 1.3307517839277747 0" rpy="0 0 0"/>
            <geometry>
                <box size="1.7193378510799826 2.6615035678555494 1.1692553761368203" />
            </geometry>
        </collision>
    </link>
    <link name="Leg15">
        <inertial>
            <origin xyz="1.0138264577573084 0 0" rpy="0 0 0"/>
            <mass value="1" />
            <inertia ixx="100" ixy="0" ixz="0" iyy="100" iyz="0" izz="100" />
        </inertial>
        <visual>
            <origin xyz="1.0138264577573084 0 0" rpy="0 0 0"/>
            <geometry>
                <box size="2.027652915514617 2.422758974930845 2.7733502062720783" />
            </geometry>
            <material name="Green">
                <color rgba="0 180.0 0.0 1.0"/>
            </material>
        </visual>
        <collision>
            <origin xyz="1.0138264577573084 0 0" rpy="0 0 0"/>
            <geometry>
                <box size="2.027652915514617 2.422758974930845 2.7733502062720783" />
            </geometry>
        </collision>
    </link>
    <link name="Leg16">
        <inertial>
            <origin xyz="0 0.7686431420285279 0" rpy="0 0 0"/>
            <mass value="1" />
            <inertia ixx="100" ixy="0" ixz="0" iyy="100" iyz="0" izz="100" />
        </inertial>
        <visual>
            <origin xyz="0 0.7686431420285279 0" rpy="0 0 0"/>
            <geometry>
                <box size="1.8892637115455568 1.5372862840570558 1.5471387560241885" />
            </geometry>
            <material name="Blue">
                <color rgba="0 1.0 1.0 1.0"/>
            </material>
        </visual>
        <collision>
            <origin xyz="0 0.7686431420285279 0" rpy="0 0 0"/>
            <geometry>
                <box size="1.8892637115455568 1.5372862840570558 1.5471387560241885" />
            </geometry>
        </collision>
    </link>
    <link name="Leg17">
        <inertial>
            <origin xyz="0 0.8989938854334869 0" rpy="0 0 0"/>
            <mass value="1" />
            <inertia ixx="100" ixy="0" ixz="0" iyy="100" iyz="0" izz="100" />
        </inertial>
        <visual>
            <origin xyz="0 0.8989938854334869 0" rpy="0 0 0"/>
            <geometry>
                <box size="1.9580435054164407 1.7979877708669738 1.7475106919431516" />
            </geometry>
            <material name="Green">
                <color rgba="0 180.0 0.0 1.0"/>
            </material>
        </visual>
        <collision>
            <origin xyz="0 0.8989938854334869 0" rpy="0 0 0"/>
            <geometry>
                <box size="1.9580435054164407 1.7979877708669738 1.7475106919431516" />
            </geometry>
        </collision>
    </link>
    <link name="Leg18">
        <inertial>
            <origin xyz="0 0 0.8934856447581159" rpy="0 0 0"/>
            <mass value="1" />
            <inertia ixx="100" ixy="0" ixz="0" iyy="100" iyz="0" izz="100" />
        </inertial>
        <visual>
            <origin xyz="0 0 0.8934856447581159" rpy="0 0 0"/>
            <geometry>
                <box size="2.791229804001663 1.6233376298996274 1.7869712895162317" />
            </geometry>
            <material name="Green">
                <color rgba="0 180.0 0.0 1.0"/>
            </material>
        </visual>
        <collision>
            <origin xyz="0 0 0.8934856447581159" rpy="0 0 0"/>
            <geometry>
                <box size="2.791229804001663 1.6233376298996274 1.7869712895162317" />
            </geometry>
        </collision>
    </link>
    <link name="Leg19">
        <inertial>
            <origin xyz="0 0 0.7689972070941631" rpy="0 0 0"/>
            <mass value="1" />
            <inertia ixx="100" ixy="0" ixz="0" iyy="100" iyz="0" izz="100" />
        </inertial>
        <visual>
            <origin xyz="0 0 0.7689972070941631" rpy="0 0 0"/>
            <geometry>
                <box size="1.2781501775277864 2.722052294818545 1.5379944141883262" />
            </geometry>
            <material name="Green">
                <color rgba="0 180.0 0.0 1.0"/>
            </material>
        </visual>
        <collision>
            <origin xyz="0 0 0.7689972070941631" rpy="0 0 0"/>
            <geometry>
                <box size="1.2781501775277864 2.722052294818545 1.5379944141883262" />
            </geometry>
        </collision>
    </link>
    <link name="Leg20">
        <inertial>
            <origin xyz="1.081355601664117 0 0" rpy="0 0 0"/>
            <mass value="1" />
            <inertia ixx="100" ixy="0" ixz="0" iyy="100" iyz="0" izz="100" />
        </inertial>
        <visual>
            <origin xyz="1.081355601664117 0 0" rpy="0 0 0"/>
            <geometry>
                <box size="2.162711203328234 1.0144623108854167 2.55771692494145" />
            </geometry>
            <material name="Green">
                <color rgba="0 180.0 0.0 1.0"/>
            </material>
        </visual>
        <collision>
            <origin xyz="1.081355601664117 0 0" rpy="0 0 0"/>
            <geometry>
                <box size="2.162711203328234 1.0144623108854167 2.55771692494145" />
            </geometry>
        </collision>
    </link>
    <link name="Leg21">
        <inertial>
            <origin xyz="0.8823513629705007 0 0" rpy="0 0 0"/>
            <mass value="1" />
            <inertia ixx="100" ixy="0" ixz="0" iyy="100" iyz="0" izz="100" />
        </inertial>
        <visual>
            <origin xyz="0.8823513629705007 0 0" rpy="0 0 0"/>
            <geometry>
                <box size="1.7647027259410013 2.1098645154534914 2.7203165985808355" />
            </geometry>
            <material name="Green">
                <color rgba="0 180.0 0.0 1.0"/>
            </material>
        </visual>
        <collision>
            <origin xyz="0.8823513629705007 0 0" rpy="0 0 0"/>
            <geometry>
                <box size="1.7647027259410013 2.1098645154534914 2.7203165985808355" />
            </geometry>
        </collision>
    </link>
    <link name="Leg22">
        <inertial>
            <origin xyz="0 0 1.1805195414924214" rpy="0 0 0"/>
            <mass value="1" />
            <inertia ixx="100" ixy="0" ixz="0" iyy="100" iyz="0" izz="100" />
        </inertial>
        <visual>
            <origin xyz="0 0 1.1805195414924214" rpy="0 0 0"/>
            <geometry>
                <box size="1.311024160893692 2.6829084568264987 2.361039082984843" />
            </geometry>
            <material name="Blue">
                <color rgba="0 1.0 1.0 1.0"/>
            </material>
        </visual>
        <collision>
            <origin xyz="0 0 1.1805195414924214" rpy="0 0 0"/>
            <geometry>
                <box size="1.311024160893692 2.6829084568264987 2.361039082984843" />
            </geometry>
        </collision>
    </link>
    <link name="Leg23">
        <inertial>
            <origin xyz="0 0.8951720564712031 0" rpy="0 0 0"/>
            <mass value="1" />
            <inertia ixx="100" ixy="0" ixz="0" iyy="100" iyz="0" izz="100" />
        </inertial>
        <visual>
            <origin xyz="0 0.8951720564712031 0" rpy="0 0 0"/>
            <geometry>
                <box size="1.0858169143643104 1.7903441129424063 2.5809110702360862" />
            </geometry>
            <material name="Blue">
                <color rgba="0 1.0 1.0 1.0"/>
            </material>
        </visual>
        <collision>
            <origin xyz="0 0.8951720564712031 0" rpy="0 0 0"/>
            <geometry>
                <box size="1.0858169143643104 1.7903441129424063 2.5809110702360862" />
            </geometry>
        </collision>
    </link>
    <link name="Leg24">
        <inertial>
            <origin xyz="0 1.2647129292181891 0" rpy="0 0 0"/>
            <mass value="1" />
            <inertia ixx="100" ixy="0" ixz="0" iyy="100" iyz="0" izz="100" />
        </inertial>
        <visual>
            <origin xyz="0 1.2647129292181891 0" rpy="0 0 0"/>
            <geometry>
                <box size="1.7511524816447956 2.5294258584363782 1.2581751656313618" />
            </geometry>
            <material name="Blue">
                <color rgba="0 1.0 1.0 1.0"/>
            </material>
        </visual>
        <collision>
            <origin xyz="0 1.2647129292181891 0" rpy="0 0 0"/>
            <geometry>
                <box size="1.7511524816447956 2.5294258584363782 1.2581751656313618" />
            </geometry>
        </collision>
    </link>
    <link name="Leg25">
        <inertial>
            <origin xyz="0 1.0227110813881504 0" rpy="0 0 0"/>
            <mass value="1" />
            <inertia ixx="100" ixy="0" ixz="0" iyy="100" iyz="0" izz="100" />
        </inertial>
        <visual>
            <origin xyz="0 1.0227110813881504 0" rpy="0 0 0"/>
            <geometry>
                <box size="2.206960096074582 2.0454221627763007 1.003653193471673" />
            </geometry>
            <material name="Blue">
                <color rgba="0 1.0 1.0 1.0"/>
            </material>
        </visual>
        <collision>
            <origin xyz="0 1.0227110813881504 0" rpy="0 0 0"/>
            <geometry>
                <box size="2.206960096074582 2.0454221627763007 1.003653193471673" />
            </geometry>
        </collision>
    </link>
    <link name="Leg26">
        <inertial>
            <origin xyz="0 0 0.6840224830252539" rpy="0 0 0"/>
            <mass value="1" />
            <inertia ixx="100" ixy="0" ixz="0" iyy="100" iyz="0" izz="100" />
        </inertial>
        <visual>
            <origin xyz="0 0 0.6840224830252539" rpy="0 0 0"/>
            <geometry>
                <box size="2.5348020398816633 2.1869400593857646 1.3680449660505078" />
            </geometry>
            <material name="Blue">
                <color rgba="0 1.0 1.0 1.0"/>
            </material>
        </visual>
        <collision>
            <origin xyz="0 0 0.6840224830252539" rpy="0 0 0"/>
            <geometry>
                <box size="2.5348020398816633 2.1869400593857646 1.3680449660505078" />
            </geometry>
        </collision>
    </link>
    <link name="Leg27">
        <inertial>
            <origin xyz="1.3028498815694929 0 0" rpy="0 0 0"/>
            <mass value="1" />
            <inertia ixx="100" ixy="0" ixz="0" iyy="100" iyz="0" izz="100" />
        </inertial>
        <visual>
            <origin xyz="1.3028498815694929 0 0" rpy="0 0 0"/>
            <geometry>
                <box size="2.6056997631389858 1.1532022374884665 2.7088217883073176" />
            </geometry>
            <material name="Green">
                <color rgba="0 180.0 0.0 1.0"/>
            </material>
        </visual>
        <collision>
            <origin xyz="1.3028498815694929 0 0" rpy="0 0 0"/>
            <geometry>
                <box size="2.6056997631389858 1.1532022374884665 2.7088217883073176" />
            </geometry>
        </collision>
    </link>
    <link name="Leg28">
        <inertial>
            <origin xyz="1.2531974600851505 0 0" rpy="0 0 0"/>
            <mass value="1" />
            <inertia ixx="100" ixy="0" ixz="0" iyy="100" iyz="0" izz="100" />
        </inertial>
        <visual>
            <origin xyz="1.2531974600851505 0 0" rpy="0 0 0"/>
            <geometry>
                <box size="2.506394920170301 2.110262867238432 1.8475555196278322" />
            </geometry>
            <material name="Green">
                <color rgba="0 180.0 0.0 1.0"/>
            </material>
        </visual>
        <collision>
            <origin xyz="1.2531974600851505 0 0" rpy="0 0 0"/>
            <geometry>
                <box size="2.506394920170301 2.110262867238432 1.8475555196278322" />
            </geometry>
        </collision>
    </link>
    <link name="Leg29">
        <inertial>
            <origin xyz="0.9234808748492066 0 0" rpy="0 0 0"/>
            <mass value="1" />
            <inertia ixx="100" ixy="0" ixz="0" iyy="100" iyz="0" izz="100" />
        </inertial>
        <visual>
            <origin xyz="0.9234808748492066 0 0" rpy="0 0 0"/>
            <geometry>
                <box size="1.8469617496984132 2.9133486448930297 2.563948330807841" />
            </geometry>
            <material name="Green">
                <color rgba="0 180.0 0.0 1.0"/>
            </material>
        </visual>
        <collision>
            <origin xyz="0.9234808748492066 0 0" rpy="0 0 0"/>
            <geometry>
                <box size="1.8469617496984132 2.9133486448930297 2.563948330807841" />
            </geometry>
        </collision>
    </link>
    <joint name="Torso_Leg1" type="revolute">
       <parent link="Torso"/>
       <child  link="Leg1"/>
       <origin rpy="0 0 0" xyz="0 0.6189563257513034 1.4286457825688808" />
     <axis xyz="1 0 0"/>
       <limit effort="0.0" lower="-3.14159" upper="3.14159" velocity="0.0"/>
    </joint>
    <joint name="Leg1_Leg2" type="revolute">
       <parent link="Leg1"/>
       <child  link="Leg2"/>
       <origin rpy="0 0 0" xyz="2.130944720411761 0 0" />
     <axis xyz="1 0 0"/>
       <limit effort="0.0" lower="-3.14159" upper="3.14159" velocity="0.0"/>
    </joint>
    <joint name="Torso_Leg3" type="revolute">
       <parent link="Torso"/>
       <child  link="Leg3"/>
       <origin rpy="0 0 0" xyz="0 0.5533776462784132 1.4154364042810972" />
     <axis xyz="1 0 0"/>
       <limit effort="0.0" lower="-3.14159" upper="3.14159" velocity="0.0"/>
    </joint>
    <joint name="Leg2_Leg4" type="revolute">
       <parent link="Leg2"/>
       <child  link="Leg4"/>
       <origin rpy="0 0 0" xyz="0 1.4497257570431894 0.5477078483697355" />
     <axis xyz="1 0 0"/>
       <limit effort="0.0" lower="-3.14159" upper="3.14159" velocity="0.0"/>
    </joint>
    <joint name="Leg4_Leg5" type="revolute">
       <parent link="Leg4"/>
       <child  link="Leg5"/>
       <origin rpy="0 0 0" xyz="0 1.448990050646001 0" />
     <axis xyz="1 0 0"/>
       <limit effort="0.0" lower="-3.14159" upper="3.14159" velocity="0.0"/>
    </joint>
    <joint name="Leg5_Leg6" type="revolute">
       <parent link="Leg5"/>
       <child  link="Leg6"/>
       <origin rpy="0 0 0" xyz="2.107876703750451 0 0" />
     <axis xyz="1 0 0"/>
       <limit effort="0.0" lower="-3.14159" upper="3.14159" velocity="0.0"/>
    </joint>
    <joint name="Leg1_Leg7" type="revolute">
       <parent link="Leg1"/>
       <child  link="Leg7"/>
       <origin rpy="0 0 0" xyz="2.130944720411761 0 0.6445994840200837" />
     <axis xyz="1 0 0"/>
       <limit effort="0.0" lower="-3.14159" upper="3.14159" velocity="0.0"/>
    </joint>
    <joint name="Leg7_Leg8" type="revolute">
       <parent link="Leg7"/>
       <child  link="Leg8"/>
       <origin rpy="0 0 0" xyz="0 2.7609093393660484 0" />
     <axis xyz="1 0 0"/>
       <limit effort="0.0" lower="-3.14159" upper="3.14159" velocity="0.0"/>
    </joint>
    <joint name="Leg8_Leg9" type="revolute">
       <parent link="Leg8"/>
       <child  link="Leg9"/>
       <origin rpy="0 0 0" xyz="0 1.3306588161535449 0" />
     <axis xyz="1 0 0"/>
       <limit effort="0.0" lower="-3.14159" upper="3.14159" velocity="0.0"/>
    </joint>
    <joint name="Leg7_Leg10" type="revolute">
       <parent link="Leg7"/>
       <child  link="Leg10"/>
       <origin rpy="0 0 0" xyz="1.2892841770374655 2.7609093393660484 0" />
     <axis xyz="1 0 0"/>
       <limit effort="0.0" lower="-3.14159" upper="3.14159" velocity="0.0"/>
    </joint>
    <joint name="Leg6_Leg11" type="revolute">
       <parent link="Leg6"/>
       <child  link="Leg11"/>
       <origin rpy="0 0 0" xyz="1.3579467535627971 0 1.1802349372036973" />
     <axis xyz="1 0 0"/>
       <limit effort="0.0" lower="-3.14159" upper="3.14159" velocity="0.0"/>
    </joint>
    <joint name="Leg2_Leg12" type="revolute">
       <parent link="Leg2"/>
       <child  link="Leg12"/>
       <origin rpy="0 0 0" xyz="0 1.4497257570431894 1.095415696739471" />
     <axis xyz="1 0 0"/>
       <limit effort="0.0" lower="-3.14159" upper="3.14159" velocity="0.0"/>
    </joint>
    <joint name="Leg12_Leg13" type="revolute">
       <parent link="Leg12"/>
       <child  link="Leg13"/>
       <origin rpy="0 0 0" xyz="0 1.0163916908955943 0" />
     <axis xyz="1 0 0"/>
       <limit effort="0.0" lower="-3.14159" upper="3.14159" velocity="0.0"/>
    </joint>
    <joint name="Leg5_Leg14" type="revolute">
       <parent link="Leg5"/>
       <child  link="Leg14"/>
       <origin rpy="0 0 0" xyz="2.107876703750451 1.4088838218981126 0" />
     <axis xyz="1 0 0"/>
       <limit effort="0.0" lower="-3.14159" upper="3.14159" velocity="0.0"/>
    </joint>
    <joint name="Leg11_Leg15" type="revolute">
       <parent link="Leg11"/>
       <child  link="Leg15"/>
       <origin rpy="0 0 0" xyz="1.0663594977970097 0 1.2168741073923817" />
     <axis xyz="1 0 0"/>
       <limit effort="0.0" lower="-3.14159" upper="3.14159" velocity="0.0"/>
    </joint>
    <joint name="Leg10_Leg16" type="revolute">
       <parent link="Leg10"/>
       <child  link="Leg16"/>
       <origin rpy="0 0 0" xyz="0.992968044684967 1.2376706005111644 0" />
     <axis xyz="1 0 0"/>
       <limit effort="0.0" lower="-3.14159" upper="3.14159" velocity="0.0"/>
    </joint>
    <joint name="Leg13_Leg17" type="revolute">
       <parent link="Leg13"/>
       <child  link="Leg17"/>
       <origin rpy="0 0 0" xyz="0 2.6615035678555494 0" />
     <axis xyz="1 0 0"/>
       <limit effort="0.0" lower="-3.14159" upper="3.14159" velocity="0.0"/>
    </joint>
    <joint name="Leg5_Leg18" type="revolute">
       <parent link="Leg5"/>
       <child  link="Leg18"/>
       <origin rpy="0 0 0" xyz="2.107876703750451 1.4088838218981126 0.6379145133149086" />
     <axis xyz="1 0 0"/>
       <limit effort="0.0" lower="-3.14159" upper="3.14159" velocity="0.0"/>
    </joint>
    <joint name="Leg13_Leg19" type="revolute">
       <parent link="Leg13"/>
       <child  link="Leg19"/>
       <origin rpy="0 0 0" xyz="0 2.6615035678555494 0.5846276880684101" />
     <axis xyz="1 0 0"/>
       <limit effort="0.0" lower="-3.14159" upper="3.14159" velocity="0.0"/>
    </joint>
    <joint name="Leg18_Leg20" type="revolute">
       <parent link="Leg18"/>
       <child  link="Leg20"/>
       <origin rpy="0 0 0" xyz="0.6390750887638932 0 0.7689972070941631" />
     <axis xyz="1 0 0"/>
       <limit effort="0.0" lower="-3.14159" upper="3.14159" velocity="0.0"/>
    </joint>
    <joint name="Leg2_Leg21" type="revolute">
       <parent link="Leg2"/>
       <child  link="Leg21"/>
       <origin rpy="0 0 0" xyz="1.4518121867546794 1.4497257570431894 1.095415696739471" />
     <axis xyz="1 0 0"/>
       <limit effort="0.0" lower="-3.14159" upper="3.14159" velocity="0.0"/>
    </joint>
    <joint name="Leg19_Leg22" type="revolute">
       <parent link="Leg19"/>
       <child  link="Leg22"/>
       <origin rpy="0 0 0" xyz="1.081355601664117 0 1.278858462470725" />
     <axis xyz="1 0 0"/>
       <limit effort="0.0" lower="-3.14159" upper="3.14159" velocity="0.0"/>
    </joint>
    <joint name="Leg6_Leg23" type="revolute">
       <parent link="Leg6"/>
       <child  link="Leg23"/>
       <origin rpy="0 0 0" xyz="1.3579467535627971 1.1924022083327086 1.1802349372036973" />
     <axis xyz="1 0 0"/>
       <limit effort="0.0" lower="-3.14159" upper="3.14159" velocity="0.0"/>
    </joint>
    <joint name="Leg9_Leg24" type="revolute">
       <parent link="Leg9"/>
       <child  link="Leg24"/>
       <origin rpy="0 0 0" xyz="0.6118227018150313 1.1704724864056202 0" />
     <axis xyz="1 0 0"/>
       <limit effort="0.0" lower="-3.14159" upper="3.14159" velocity="0.0"/>
    </joint>
    <joint name="Leg19_Leg25" type="revolute">
       <parent link="Leg19"/>
       <child  link="Leg25"/>
       <origin rpy="0 0 0" xyz="1.081355601664117 0.5072311554427084 1.278858462470725" />
     <axis xyz="1 0 0"/>
       <limit effort="0.0" lower="-3.14159" upper="3.14159" velocity="0.0"/>
    </joint>
    <joint name="Leg23_Leg26" type="revolute">
       <parent link="Leg23"/>
       <child  link="Leg26"/>
       <origin rpy="0 0 0" xyz="0 1.2647129292181891 0.6290875828156809" />
     <axis xyz="1 0 0"/>
       <limit effort="0.0" lower="-3.14159" upper="3.14159" velocity="0.0"/>
    </joint>
    <joint name="Leg21_Leg27" type="revolute">
       <parent link="Leg21"/>
       <child  link="Leg27"/>
       <origin rpy="0 0 0" xyz="0.655512080446846 0 1.1805195414924214" />
     <axis xyz="1 0 0"/>
       <limit effort="0.0" lower="-3.14159" upper="3.14159" velocity="0.0"/>
    </joint>
    <joint name="Leg17_Leg28" type="revolute">
       <parent link="Leg17"/>
       <child  link="Leg28"/>
       <origin rpy="0 0 0" xyz="1.3956149020008315 0 0.8934856447581159" />
     <axis xyz="1 0 0"/>
       <limit effort="0.0" lower="-3.14159" upper="3.14159" velocity="0.0"/>
    </joint>
    <joint name="Leg19_Leg29" type="revolute">
       <parent link="Leg19"/>
       <child  link="Leg29"/>
       <origin rpy="0 0 0" xyz="2.162711203328234 0.5072311554427084 1.278858462470725" />
     <axis xyz="1 0 0"/>
       <limit effort="0.0" lower="-3.14159" upper="3.14159" velocity="0.0"/>
    </joint>
</robot>