<robot name = "robot">
    <link name="Torso">
        <inertial>
            <origin xyz="0 0 0.9384491636503877" rpy="0 0 0"/>
            <mass value="1" />
            <inertia ixx="100" ixy="0" ixz="0" iyy="100" iyz="0" izz="100" />
        </inertial>
        <visual>
            <origin xyz="0 0 0.9384491636503877" rpy="0 0 0"/>
            <geometry>
                <box size="2.988989021834985 1.176947527297308 1.8768983273007753" />
            </geometry>
            <material name="Green">
                <color rgba="0 180.0 0.0 1.0"/>
            </material>
        </visual>
        <collision>
            <origin xyz="0 0 0.9384491636503877" rpy="0 0 0"/>
            <geometry>
                <box size="2.988989021834985 1.176947527297308 1.8768983273007753" />
            </geometry>
        </collision>
    </link>
    <link name="Leg1">
        <inertial>
            <origin xyz="0 0 0.7653865402113703" rpy="0 0 0"/>
            <mass value="1" />
            <inertia ixx="100" ixy="0" ixz="0" iyy="100" iyz="0" izz="100" />
        </inertial>
        <visual>
            <origin xyz="0 0 0.7653865402113703" rpy="0 0 0"/>
            <geometry>
                <box size="1.8023442011179043 2.1829024456091517 1.5307730804227406" />
            </geometry>
            <material name="Green">
                <color rgba="0 180.0 0.0 1.0"/>
            </material>
        </visual>
        <collision>
            <origin xyz="0 0 0.7653865402113703" rpy="0 0 0"/>
            <geometry>
                <box size="1.8023442011179043 2.1829024456091517 1.5307730804227406" />
            </geometry>
        </collision>
    </link>
    <link name="Leg2">
        <inertial>
            <origin xyz="0.6577587577777525 0 0" rpy="0 0 0"/>
            <mass value="1" />
            <inertia ixx="100" ixy="0" ixz="0" iyy="100" iyz="0" izz="100" />
        </inertial>
        <visual>
            <origin xyz="0.6577587577777525 0 0" rpy="0 0 0"/>
            <geometry>
                <box size="1.315517515555505 1.8260529219960475 2.7357710111820337" />
            </geometry>
            <material name="Green">
                <color rgba="0 180.0 0.0 1.0"/>
            </material>
        </visual>
        <collision>
            <origin xyz="0.6577587577777525 0 0" rpy="0 0 0"/>
            <geometry>
                <box size="1.315517515555505 1.8260529219960475 2.7357710111820337" />
            </geometry>
        </collision>
    </link>
    <link name="Leg3">
        <inertial>
            <origin xyz="0.5803375623412654 0 0" rpy="0 0 0"/>
            <mass value="1" />
            <inertia ixx="100" ixy="0" ixz="0" iyy="100" iyz="0" izz="100" />
        </inertial>
        <visual>
            <origin xyz="0.5803375623412654 0 0" rpy="0 0 0"/>
            <geometry>
                <box size="1.1606751246825309 1.72538843143666 2.3069961996069406" />
            </geometry>
            <material name="Green">
                <color rgba="0 180.0 0.0 1.0"/>
            </material>
        </visual>
        <collision>
            <origin xyz="0.5803375623412654 0 0" rpy="0 0 0"/>
            <geometry>
                <box size="1.1606751246825309 1.72538843143666 2.3069961996069406" />
            </geometry>
        </collision>
    </link>
    <link name="Leg4">
        <inertial>
            <origin xyz="0 1.225020319092876 0" rpy="0 0 0"/>
            <mass value="1" />
            <inertia ixx="100" ixy="0" ixz="0" iyy="100" iyz="0" izz="100" />
        </inertial>
        <visual>
            <origin xyz="0 1.225020319092876 0" rpy="0 0 0"/>
            <geometry>
                <box size="2.7107623709575757 2.450040638185752 1.2287445533668784" />
            </geometry>
            <material name="Blue">
                <color rgba="0 1.0 1.0 1.0"/>
            </material>
        </visual>
        <collision>
            <origin xyz="0 1.225020319092876 0" rpy="0 0 0"/>
            <geometry>
                <box size="2.7107623709575757 2.450040638185752 1.2287445533668784" />
            </geometry>
        </collision>
    </link>
    <link name="Leg5">
        <inertial>
            <origin xyz="1.4721658357458152 0 0" rpy="0 0 0"/>
            <mass value="1" />
            <inertia ixx="100" ixy="0" ixz="0" iyy="100" iyz="0" izz="100" />
        </inertial>
        <visual>
            <origin xyz="1.4721658357458152 0 0" rpy="0 0 0"/>
            <geometry>
                <box size="2.9443316714916303 1.6347377610060139 2.589781274313096" />
            </geometry>
            <material name="Green">
                <color rgba="0 180.0 0.0 1.0"/>
            </material>
        </visual>
        <collision>
            <origin xyz="1.4721658357458152 0 0" rpy="0 0 0"/>
            <geometry>
                <box size="2.9443316714916303 1.6347377610060139 2.589781274313096" />
            </geometry>
        </collision>
    </link>
    <link name="Leg6">
        <inertial>
            <origin xyz="0 0 1.337697410895264" rpy="0 0 0"/>
            <mass value="1" />
            <inertia ixx="100" ixy="0" ixz="0" iyy="100" iyz="0" izz="100" />
        </inertial>
        <visual>
            <origin xyz="0 0 1.337697410895264" rpy="0 0 0"/>
            <geometry>
                <box size="1.6293715909803077 2.9675734845522577 2.675394821790528" />
            </geometry>
            <material name="Blue">
                <color rgba="0 1.0 1.0 1.0"/>
            </material>
        </visual>
        <collision>
            <origin xyz="0 0 1.337697410895264" rpy="0 0 0"/>
            <geometry>
                <box size="1.6293715909803077 2.9675734845522577 2.675394821790528" />
            </geometry>
        </collision>
    </link>
    <link name="Leg7">
        <inertial>
            <origin xyz="1.0158103347887042 0 0" rpy="0 0 0"/>
            <mass value="1" />
            <inertia ixx="100" ixy="0" ixz="0" iyy="100" iyz="0" izz="100" />
        </inertial>
        <visual>
            <origin xyz="1.0158103347887042 0 0" rpy="0 0 0"/>
            <geometry>
                <box size="2.0316206695774084 2.5296358064791526 1.3862235299335635" />
            </geometry>
            <material name="Blue">
                <color rgba="0 1.0 1.0 1.0"/>
            </material>
        </visual>
        <collision>
            <origin xyz="1.0158103347887042 0 0" rpy="0 0 0"/>
            <geometry>
                <box size="2.0316206695774084 2.5296358064791526 1.3862235299335635" />
            </geometry>
        </collision>
    </link>
    <link name="Leg8">
        <inertial>
            <origin xyz="0 0 1.0122794455454829" rpy="0 0 0"/>
            <mass value="1" />
            <inertia ixx="100" ixy="0" ixz="0" iyy="100" iyz="0" izz="100" />
        </inertial>
        <visual>
            <origin xyz="0 0 1.0122794455454829" rpy="0 0 0"/>
            <geometry>
                <box size="2.6145527745189643 1.953611860127832 2.0245588910909658" />
            </geometry>
            <material name="Green">
                <color rgba="0 180.0 0.0 1.0"/>
            </material>
        </visual>
        <collision>
            <origin xyz="0 0 1.0122794455454829" rpy="0 0 0"/>
            <geometry>
                <box size="2.6145527745189643 1.953611860127832 2.0245588910909658" />
            </geometry>
        </collision>
    </link>
    <link name="Leg9">
        <inertial>
            <origin xyz="1.3070297422990425 0 0" rpy="0 0 0"/>
            <mass value="1" />
            <inertia ixx="100" ixy="0" ixz="0" iyy="100" iyz="0" izz="100" />
        </inertial>
        <visual>
            <origin xyz="1.3070297422990425 0 0" rpy="0 0 0"/>
            <geometry>
                <box size="2.614059484598085 2.9961389038946287 2.5889954170757288" />
            </geometry>
            <material name="Green">
                <color rgba="0 180.0 0.0 1.0"/>
            </material>
        </visual>
        <collision>
            <origin xyz="1.3070297422990425 0 0" rpy="0 0 0"/>
            <geometry>
                <box size="2.614059484598085 2.9961389038946287 2.5889954170757288" />
            </geometry>
        </collision>
    </link>
    <link name="Leg10">
        <inertial>
            <origin xyz="0 1.4903448990105501 0" rpy="0 0 0"/>
            <mass value="1" />
            <inertia ixx="100" ixy="0" ixz="0" iyy="100" iyz="0" izz="100" />
        </inertial>
        <visual>
            <origin xyz="0 1.4903448990105501 0" rpy="0 0 0"/>
            <geometry>
                <box size="1.6641128290441007 2.9806897980211002 1.8709206021732339" />
            </geometry>
            <material name="Blue">
                <color rgba="0 1.0 1.0 1.0"/>
            </material>
        </visual>
        <collision>
            <origin xyz="0 1.4903448990105501 0" rpy="0 0 0"/>
            <geometry>
                <box size="1.6641128290441007 2.9806897980211002 1.8709206021732339" />
            </geometry>
        </collision>
    </link>
    <link name="Leg11">
        <inertial>
            <origin xyz="1.4871377303888151 0 0" rpy="0 0 0"/>
            <mass value="1" />
            <inertia ixx="100" ixy="0" ixz="0" iyy="100" iyz="0" izz="100" />
        </inertial>
        <visual>
            <origin xyz="1.4871377303888151 0 0" rpy="0 0 0"/>
            <geometry>
                <box size="2.9742754607776303 2.294462676503496 2.0054230345836777" />
            </geometry>
            <material name="Green">
                <color rgba="0 180.0 0.0 1.0"/>
            </material>
        </visual>
        <collision>
            <origin xyz="1.4871377303888151 0 0" rpy="0 0 0"/>
            <geometry>
                <box size="2.9742754607776303 2.294462676503496 2.0054230345836777" />
            </geometry>
        </collision>
    </link>
    <link name="Leg12">
        <inertial>
            <origin xyz="0 0 0.9993086293307858" rpy="0 0 0"/>
            <mass value="1" />
            <inertia ixx="100" ixy="0" ixz="0" iyy="100" iyz="0" izz="100" />
        </inertial>
        <visual>
            <origin xyz="0 0 0.9993086293307858" rpy="0 0 0"/>
            <geometry>
                <box size="1.0727710744905699 2.4716542125400727 1.9986172586615716" />
            </geometry>
            <material name="Blue">
                <color rgba="0 1.0 1.0 1.0"/>
            </material>
        </visual>
        <collision>
            <origin xyz="0 0 0.9993086293307858" rpy="0 0 0"/>
            <geometry>
                <box size="1.0727710744905699 2.4716542125400727 1.9986172586615716" />
            </geometry>
        </collision>
    </link>
    <link name="Leg13">
        <inertial>
            <origin xyz="0 0 0.724139493415991" rpy="0 0 0"/>
            <mass value="1" />
            <inertia ixx="100" ixy="0" ixz="0" iyy="100" iyz="0" izz="100" />
        </inertial>
        <visual>
            <origin xyz="0 0 0.724139493415991" rpy="0 0 0"/>
            <geometry>
                <box size="2.905788437738344 2.384602528762268 1.448278986831982" />
            </geometry>
            <material name="Blue">
                <color rgba="0 1.0 1.0 1.0"/>
            </material>
        </visual>
        <collision>
            <origin xyz="0 0 0.724139493415991" rpy="0 0 0"/>
            <geometry>
                <box size="2.905788437738344 2.384602528762268 1.448278986831982" />
            </geometry>
        </collision>
    </link>
    <link name="Leg14">
        <inertial>
            <origin xyz="0.5712422213232837 0 0" rpy="0 0 0"/>
            <mass value="1" />
            <inertia ixx="100" ixy="0" ixz="0" iyy="100" iyz="0" izz="100" />
        </inertial>
        <visual>
            <origin xyz="0.5712422213232837 0 0" rpy="0 0 0"/>
            <geometry>
                <box size="1.1424844426465675 2.232468378488357 2.431537954486326" />
            </geometry>
            <material name="Blue">
                <color rgba="0 1.0 1.0 1.0"/>
            </material>
        </visual>
        <collision>
            <origin xyz="0.5712422213232837 0 0" rpy="0 0 0"/>
            <geometry>
                <box size="1.1424844426465675 2.232468378488357 2.431537954486326" />
            </geometry>
        </collision>
    </link>
    <link name="Leg15">
        <inertial>
            <origin xyz="0 1.454718188237063 0" rpy="0 0 0"/>
            <mass value="1" />
            <inertia ixx="100" ixy="0" ixz="0" iyy="100" iyz="0" izz="100" />
        </inertial>
        <visual>
            <origin xyz="0 1.454718188237063 0" rpy="0 0 0"/>
            <geometry>
                <box size="2.3349322779114505 2.909436376474126 2.24540090456232" />
            </geometry>
            <material name="Green">
                <color rgba="0 180.0 0.0 1.0"/>
            </material>
        </visual>
        <collision>
            <origin xyz="0 1.454718188237063 0" rpy="0 0 0"/>
            <geometry>
                <box size="2.3349322779114505 2.909436376474126 2.24540090456232" />
            </geometry>
        </collision>
    </link>
    <link name="Leg16">
        <inertial>
            <origin xyz="0 0 0.7849532732545436" rpy="0 0 0"/>
            <mass value="1" />
            <inertia ixx="100" ixy="0" ixz="0" iyy="100" iyz="0" izz="100" />
        </inertial>
        <visual>
            <origin xyz="0 0 0.7849532732545436" rpy="0 0 0"/>
            <geometry>
                <box size="1.381593784742438 1.6803809881948724 1.5699065465090871" />
            </geometry>
            <material name="Blue">
                <color rgba="0 1.0 1.0 1.0"/>
            </material>
        </visual>
        <collision>
            <origin xyz="0 0 0.7849532732545436" rpy="0 0 0"/>
            <geometry>
                <box size="1.381593784742438 1.6803809881948724 1.5699065465090871" />
            </geometry>
        </collision>
    </link>
    <link name="Leg17">
        <inertial>
            <origin xyz="0 1.0423619906915267 0" rpy="0 0 0"/>
            <mass value="1" />
            <inertia ixx="100" ixy="0" ixz="0" iyy="100" iyz="0" izz="100" />
        </inertial>
        <visual>
            <origin xyz="0 1.0423619906915267 0" rpy="0 0 0"/>
            <geometry>
                <box size="1.297656445934017 2.0847239813830534 1.7782089137035622" />
            </geometry>
            <material name="Green">
                <color rgba="0 180.0 0.0 1.0"/>
            </material>
        </visual>
        <collision>
            <origin xyz="0 1.0423619906915267 0" rpy="0 0 0"/>
            <geometry>
                <box size="1.297656445934017 2.0847239813830534 1.7782089137035622" />
            </geometry>
        </collision>
    </link>
    <link name="Leg18">
        <inertial>
            <origin xyz="0 1.3271143966443413 0" rpy="0 0 0"/>
            <mass value="1" />
            <inertia ixx="100" ixy="0" ixz="0" iyy="100" iyz="0" izz="100" />
        </inertial>
        <visual>
            <origin xyz="0 1.3271143966443413 0" rpy="0 0 0"/>
            <geometry>
                <box size="1.02309045817228 2.6542287932886826 2.8756006748346055" />
            </geometry>
            <material name="Blue">
                <color rgba="0 1.0 1.0 1.0"/>
            </material>
        </visual>
        <collision>
            <origin xyz="0 1.3271143966443413 0" rpy="0 0 0"/>
            <geometry>
                <box size="1.02309045817228 2.6542287932886826 2.8756006748346055" />
            </geometry>
        </collision>
    </link>
    <link name="Leg19">
        <inertial>
            <origin xyz="0 0 1.197435933191139" rpy="0 0 0"/>
            <mass value="1" />
            <inertia ixx="100" ixy="0" ixz="0" iyy="100" iyz="0" izz="100" />
        </inertial>
        <visual>
            <origin xyz="0 0 1.197435933191139" rpy="0 0 0"/>
            <geometry>
                <box size="2.2307357742583074 1.2948571385995324 2.394871866382278" />
            </geometry>
            <material name="Green">
                <color rgba="0 180.0 0.0 1.0"/>
            </material>
        </visual>
        <collision>
            <origin xyz="0 0 1.197435933191139" rpy="0 0 0"/>
            <geometry>
                <box size="2.2307357742583074 1.2948571385995324 2.394871866382278" />
            </geometry>
        </collision>
    </link>
    <link name="Leg20">
        <inertial>
            <origin xyz="0 0 0.7240573853317234" rpy="0 0 0"/>
            <mass value="1" />
            <inertia ixx="100" ixy="0" ixz="0" iyy="100" iyz="0" izz="100" />
        </inertial>
        <visual>
            <origin xyz="0 0 0.7240573853317234" rpy="0 0 0"/>
            <geometry>
                <box size="2.947973354650216 2.7261408793981765 1.4481147706634467" />
            </geometry>
            <material name="Blue">
                <color rgba="0 1.0 1.0 1.0"/>
            </material>
        </visual>
        <collision>
            <origin xyz="0 0 0.7240573853317234" rpy="0 0 0"/>
            <geometry>
                <box size="2.947973354650216 2.7261408793981765 1.4481147706634467" />
            </geometry>
        </collision>
    </link>
    <link name="Leg21">
        <inertial>
            <origin xyz="0 0.9574973737898358 0" rpy="0 0 0"/>
            <mass value="1" />
            <inertia ixx="100" ixy="0" ixz="0" iyy="100" iyz="0" izz="100" />
        </inertial>
        <visual>
            <origin xyz="0 0.9574973737898358 0" rpy="0 0 0"/>
            <geometry>
                <box size="1.5988996309862245 1.9149947475796716 2.8054780388522618" />
            </geometry>
            <material name="Green">
                <color rgba="0 180.0 0.0 1.0"/>
            </material>
        </visual>
        <collision>
            <origin xyz="0 0.9574973737898358 0" rpy="0 0 0"/>
            <geometry>
                <box size="1.5988996309862245 1.9149947475796716 2.8054780388522618" />
            </geometry>
        </collision>
    </link>
    <link name="Leg22">
        <inertial>
            <origin xyz="0 0.6072734454584776 0" rpy="0 0 0"/>
            <mass value="1" />
            <inertia ixx="100" ixy="0" ixz="0" iyy="100" iyz="0" izz="100" />
        </inertial>
        <visual>
            <origin xyz="0 0.6072734454584776 0" rpy="0 0 0"/>
            <geometry>
                <box size="1.5627568483423622 1.2145468909169552 2.097507878859496" />
            </geometry>
            <material name="Green">
                <color rgba="0 180.0 0.0 1.0"/>
            </material>
        </visual>
        <collision>
            <origin xyz="0 0.6072734454584776 0" rpy="0 0 0"/>
            <geometry>
                <box size="1.5627568483423622 1.2145468909169552 2.097507878859496" />
            </geometry>
        </collision>
    </link>
    <link name="Leg23">
        <inertial>
            <origin xyz="0 0.5857601037390394 0" rpy="0 0 0"/>
            <mass value="1" />
            <inertia ixx="100" ixy="0" ixz="0" iyy="100" iyz="0" izz="100" />
        </inertial>
        <visual>
            <origin xyz="0 0.5857601037390394 0" rpy="0 0 0"/>
            <geometry>
                <box size="2.445590563289529 1.1715202074780788 2.7865143265877346" />
            </geometry>
            <material name="Green">
                <color rgba="0 180.0 0.0 1.0"/>
            </material>
        </visual>
        <collision>
            <origin xyz="0 0.5857601037390394 0" rpy="0 0 0"/>
            <geometry>
                <box size="2.445590563289529 1.1715202074780788 2.7865143265877346" />
            </geometry>
        </collision>
    </link>
    <link name="Leg24">
        <inertial>
            <origin xyz="0 0 1.380913658685991" rpy="0 0 0"/>
            <mass value="1" />
            <inertia ixx="100" ixy="0" ixz="0" iyy="100" iyz="0" izz="100" />
        </inertial>
        <visual>
            <origin xyz="0 0 1.380913658685991" rpy="0 0 0"/>
            <geometry>
                <box size="1.9714574381415066 1.3384741866841405 2.761827317371982" />
            </geometry>
            <material name="Green">
                <color rgba="0 180.0 0.0 1.0"/>
            </material>
        </visual>
        <collision>
            <origin xyz="0 0 1.380913658685991" rpy="0 0 0"/>
            <geometry>
                <box size="1.9714574381415066 1.3384741866841405 2.761827317371982" />
            </geometry>
        </collision>
    </link>
    <link name="Leg25">
        <inertial>
            <origin xyz="0 0 0.6136239348921388" rpy="0 0 0"/>
            <mass value="1" />
            <inertia ixx="100" ixy="0" ixz="0" iyy="100" iyz="0" izz="100" />
        </inertial>
        <visual>
            <origin xyz="0 0 0.6136239348921388" rpy="0 0 0"/>
            <geometry>
                <box size="1.2768222668770473 2.900726104944396 1.2272478697842777" />
            </geometry>
            <material name="Blue">
                <color rgba="0 1.0 1.0 1.0"/>
            </material>
        </visual>
        <collision>
            <origin xyz="0 0 0.6136239348921388" rpy="0 0 0"/>
            <geometry>
                <box size="1.2768222668770473 2.900726104944396 1.2272478697842777" />
            </geometry>
        </collision>
    </link>
    <joint name="Torso_Leg1" type="revolute">
       <parent link="Torso"/>
       <child  link="Leg1"/>
       <origin rpy="0 0 0" xyz="0 0 1.8768983273007753" />
     <axis xyz="1 0 0"/>
       <limit effort="0.0" lower="-3.14159" upper="3.14159" velocity="0.0"/>
    </joint>
    <joint name="Leg1_Leg2" type="revolute">
       <parent link="Leg1"/>
       <child  link="Leg2"/>
       <origin rpy="0 0 0" xyz="1.315517515555505 0 0" />
     <axis xyz="1 0 0"/>
       <limit effort="0.0" lower="-3.14159" upper="3.14159" velocity="0.0"/>
    </joint>
    <joint name="Leg2_Leg3" type="revolute">
       <parent link="Leg2"/>
       <child  link="Leg3"/>
       <origin rpy="0 0 0" xyz="1.1606751246825309 0 0" />
     <axis xyz="1 0 0"/>
       <limit effort="0.0" lower="-3.14159" upper="3.14159" velocity="0.0"/>
    </joint>
    <joint name="Torso_Leg4" type="revolute">
       <parent link="Torso"/>
       <child  link="Leg4"/>
       <origin rpy="0 0 0" xyz="0 1.0914512228045758 0.7653865402113703" />
     <axis xyz="1 0 0"/>
       <limit effort="0.0" lower="-3.14159" upper="3.14159" velocity="0.0"/>
    </joint>
    <joint name="Leg4_Leg5" type="revolute">
       <parent link="Leg4"/>
       <child  link="Leg5"/>
       <origin rpy="0 0 0" xyz="2.9443316714916303 0 0" />
     <axis xyz="1 0 0"/>
       <limit effort="0.0" lower="-3.14159" upper="3.14159" velocity="0.0"/>
    </joint>
    <joint name="Leg1_Leg6" type="revolute">
       <parent link="Leg1"/>
       <child  link="Leg6"/>
       <origin rpy="0 0 0" xyz="1.315517515555505 0 1.3678855055910168" />
     <axis xyz="1 0 0"/>
       <limit effort="0.0" lower="-3.14159" upper="3.14159" velocity="0.0"/>
    </joint>
    <joint name="Leg3_Leg7" type="revolute">
       <parent link="Leg3"/>
       <child  link="Leg7"/>
       <origin rpy="0 0 0" xyz="1.3553811854787878 1.225020319092876 0" />
     <axis xyz="1 0 0"/>
       <limit effort="0.0" lower="-3.14159" upper="3.14159" velocity="0.0"/>
    </joint>
    <joint name="Leg3_Leg8" type="revolute">
       <parent link="Leg3"/>
       <child  link="Leg8"/>
       <origin rpy="0 0 0" xyz="1.3553811854787878 1.225020319092876 0.6143722766834392" />
     <axis xyz="1 0 0"/>
       <limit effort="0.0" lower="-3.14159" upper="3.14159" velocity="0.0"/>
    </joint>
    <joint name="Leg5_Leg9" type="revolute">
       <parent link="Leg5"/>
       <child  link="Leg9"/>
       <origin rpy="0 0 0" xyz="0.8146857954901539 0 1.337697410895264" />
     <axis xyz="1 0 0"/>
       <limit effort="0.0" lower="-3.14159" upper="3.14159" velocity="0.0"/>
    </joint>
    <joint name="Leg2_Leg10" type="revolute">
       <parent link="Leg2"/>
       <child  link="Leg10"/>
       <origin rpy="0 0 0" xyz="1.1606751246825309 0.86269421571833 0" />
     <axis xyz="1 0 0"/>
       <limit effort="0.0" lower="-3.14159" upper="3.14159" velocity="0.0"/>
    </joint>
    <joint name="Leg7_Leg11" type="revolute">
       <parent link="Leg7"/>
       <child  link="Leg11"/>
       <origin rpy="0 0 0" xyz="1.3072763872594821 0 1.0122794455454829" />
     <axis xyz="1 0 0"/>
       <limit effort="0.0" lower="-3.14159" upper="3.14159" velocity="0.0"/>
    </joint>
    <joint name="Leg5_Leg12" type="revolute">
       <parent link="Leg5"/>
       <child  link="Leg12"/>
       <origin rpy="0 0 0" xyz="0.8146857954901539 0 2.675394821790528" />
     <axis xyz="1 0 0"/>
       <limit effort="0.0" lower="-3.14159" upper="3.14159" velocity="0.0"/>
    </joint>
    <joint name="Leg10_Leg13" type="revolute">
       <parent link="Leg10"/>
       <child  link="Leg13"/>
       <origin rpy="0 0 0" xyz="1.4871377303888151 0 1.0027115172918388" />
     <axis xyz="1 0 0"/>
       <limit effort="0.0" lower="-3.14159" upper="3.14159" velocity="0.0"/>
    </joint>
    <joint name="Leg9_Leg14" type="revolute">
       <parent link="Leg9"/>
       <child  link="Leg14"/>
       <origin rpy="0 0 0" xyz="0.8320564145220504 1.4903448990105501 0" />
     <axis xyz="1 0 0"/>
       <limit effort="0.0" lower="-3.14159" upper="3.14159" velocity="0.0"/>
    </joint>
    <joint name="Leg8_Leg15" type="revolute">
       <parent link="Leg8"/>
       <child  link="Leg15"/>
       <origin rpy="0 0 0" xyz="1.3070297422990425 1.4980694519473143 0" />
     <axis xyz="1 0 0"/>
       <limit effort="0.0" lower="-3.14159" upper="3.14159" velocity="0.0"/>
    </joint>
    <joint name="Leg7_Leg16" type="revolute">
       <parent link="Leg7"/>
       <child  link="Leg16"/>
       <origin rpy="0 0 0" xyz="1.3072763872594821 0 2.0245588910909658" />
     <axis xyz="1 0 0"/>
       <limit effort="0.0" lower="-3.14159" upper="3.14159" velocity="0.0"/>
    </joint>
    <joint name="Leg10_Leg17" type="revolute">
       <parent link="Leg10"/>
       <child  link="Leg17"/>
       <origin rpy="0 0 0" xyz="1.4871377303888151 1.147231338251748 1.0027115172918388" />
     <axis xyz="1 0 0"/>
       <limit effort="0.0" lower="-3.14159" upper="3.14159" velocity="0.0"/>
    </joint>
    <joint name="Leg7_Leg18" type="revolute">
       <parent link="Leg7"/>
       <child  link="Leg18"/>
       <origin rpy="0 0 0" xyz="1.3072763872594821 0.976805930063916 2.0245588910909658" />
     <axis xyz="1 0 0"/>
       <limit effort="0.0" lower="-3.14159" upper="3.14159" velocity="0.0"/>
    </joint>
    <joint name="Leg2_Leg19" type="revolute">
       <parent link="Leg2"/>
       <child  link="Leg19"/>
       <origin rpy="0 0 0" xyz="1.1606751246825309 0.86269421571833 1.1534980998034703" />
     <axis xyz="1 0 0"/>
       <limit effort="0.0" lower="-3.14159" upper="3.14159" velocity="0.0"/>
    </joint>
    <joint name="Leg12_Leg20" type="revolute">
       <parent link="Leg12"/>
       <child  link="Leg20"/>
       <origin rpy="0 0 0" xyz="0 0 1.448278986831982" />
     <axis xyz="1 0 0"/>
       <limit effort="0.0" lower="-3.14159" upper="3.14159" velocity="0.0"/>
    </joint>
    <joint name="Leg19_Leg21" type="revolute">
       <parent link="Leg19"/>
       <child  link="Leg21"/>
       <origin rpy="0 0 0" xyz="0 1.3630704396990883 0.7240573853317234" />
     <axis xyz="1 0 0"/>
       <limit effort="0.0" lower="-3.14159" upper="3.14159" velocity="0.0"/>
    </joint>
    <joint name="Leg9_Leg22" type="revolute">
       <parent link="Leg9"/>
       <child  link="Leg22"/>
       <origin rpy="0 0 0" xyz="0.8320564145220504 2.9806897980211002 0" />
     <axis xyz="1 0 0"/>
       <limit effort="0.0" lower="-3.14159" upper="3.14159" velocity="0.0"/>
    </joint>
    <joint name="Leg16_Leg23" type="revolute">
       <parent link="Leg16"/>
       <child  link="Leg23"/>
       <origin rpy="0 0 0" xyz="0 2.0847239813830534 0" />
     <axis xyz="1 0 0"/>
       <limit effort="0.0" lower="-3.14159" upper="3.14159" velocity="0.0"/>
    </joint>
    <joint name="Leg19_Leg24" type="revolute">
       <parent link="Leg19"/>
       <child  link="Leg24"/>
       <origin rpy="0 0 0" xyz="0 1.3630704396990883 1.4481147706634467" />
     <axis xyz="1 0 0"/>
       <limit effort="0.0" lower="-3.14159" upper="3.14159" velocity="0.0"/>
    </joint>
    <joint name="Leg8_Leg25" type="revolute">
       <parent link="Leg8"/>
       <child  link="Leg25"/>
       <origin rpy="0 0 0" xyz="1.3070297422990425 1.4980694519473143 1.2944977085378644" />
     <axis xyz="1 0 0"/>
       <limit effort="0.0" lower="-3.14159" upper="3.14159" velocity="0.0"/>
    </joint>
</robot>