<robot name = "robot">
    <link name="Torso">
        <inertial>
            <origin xyz="0 0 1.4983192934237086" rpy="0 0 0"/>
            <mass value="1" />
            <inertia ixx="100" ixy="0" ixz="0" iyy="100" iyz="0" izz="100" />
        </inertial>
        <visual>
            <origin xyz="0 0 1.4983192934237086" rpy="0 0 0"/>
            <geometry>
                <box size="2.849297641840966 1.2651442829376374 1.4983192934237086" />
            </geometry>
            <material name="Green">
                <color rgba="0 180.0 0.0 1.0"/>
            </material>
        </visual>
        <collision>
            <origin xyz="0 0 1.4983192934237086" rpy="0 0 0"/>
            <geometry>
                <box size="2.849297641840966 1.2651442829376374 1.4983192934237086" />
            </geometry>
        </collision>
    </link>
    <link name="Leg1">
        <inertial>
            <origin xyz="0.859862889907482 0.8810106997759528 0.928764371030893" rpy="0 0 0"/>
            <mass value="1" />
            <inertia ixx="100" ixy="0" ixz="0" iyy="100" iyz="0" izz="100" />
        </inertial>
        <visual>
            <origin xyz="0.859862889907482 0.8810106997759528 0.928764371030893" rpy="0 0 0"/>
            <geometry>
                <box size="1.719725779814964 1.7620213995519056 1.857528742061786" />
            </geometry>
            <material name="Blue">
                <color rgba="0 1.0 1.0 1.0"/>
            </material>
        </visual>
        <collision>
            <origin xyz="0.859862889907482 0.8810106997759528 0.928764371030893" rpy="0 0 0"/>
            <geometry>
                <box size="1.719725779814964 1.7620213995519056 1.857528742061786" />
            </geometry>
        </collision>
    </link>
    <link name="Leg2">
        <inertial>
            <origin xyz="1.0573526063925345 0 0.9915046097278846" rpy="0 0 0"/>
            <mass value="1" />
            <inertia ixx="100" ixy="0" ixz="0" iyy="100" iyz="0" izz="100" />
        </inertial>
        <visual>
            <origin xyz="1.0573526063925345 0 0.9915046097278846" rpy="0 0 0"/>
            <geometry>
                <box size="2.114705212785069 1.2250626098864685 1.9830092194557691" />
            </geometry>
            <material name="Blue">
                <color rgba="0 1.0 1.0 1.0"/>
            </material>
        </visual>
        <collision>
            <origin xyz="1.0573526063925345 0 0.9915046097278846" rpy="0 0 0"/>
            <geometry>
                <box size="2.114705212785069 1.2250626098864685 1.9830092194557691" />
            </geometry>
        </collision>
    </link>
    <link name="Leg3">
        <inertial>
            <origin xyz="0 0.5643722117688824 2.701215188161158" rpy="0 0 0"/>
            <mass value="1" />
            <inertia ixx="100" ixy="0" ixz="0" iyy="100" iyz="0" izz="100" />
        </inertial>
        <visual>
            <origin xyz="0 0.5643722117688824 2.701215188161158" rpy="0 0 0"/>
            <geometry>
                <box size="1.036163887101561 1.1287444235377648 2.701215188161158" />
            </geometry>
            <material name="Blue">
                <color rgba="0 1.0 1.0 1.0"/>
            </material>
        </visual>
        <collision>
            <origin xyz="0 0.5643722117688824 2.701215188161158" rpy="0 0 0"/>
            <geometry>
                <box size="1.036163887101561 1.1287444235377648 2.701215188161158" />
            </geometry>
        </collision>
    </link>
    <link name="Leg4">
        <inertial>
            <origin xyz="0.5339725699244038 2.181962651034385 1.198615909310564" rpy="0 0 0"/>
            <mass value="1" />
            <inertia ixx="100" ixy="0" ixz="0" iyy="100" iyz="0" izz="100" />
        </inertial>
        <visual>
            <origin xyz="0.5339725699244038 2.181962651034385 1.198615909310564" rpy="0 0 0"/>
            <geometry>
                <box size="1.0679451398488076 2.181962651034385 2.397231818621128" />
            </geometry>
            <material name="Blue">
                <color rgba="0 1.0 1.0 1.0"/>
            </material>
        </visual>
        <collision>
            <origin xyz="0.5339725699244038 2.181962651034385 1.198615909310564" rpy="0 0 0"/>
            <geometry>
                <box size="1.0679451398488076 2.181962651034385 2.397231818621128" />
            </geometry>
        </collision>
    </link>
    <link name="Leg5">
        <inertial>
            <origin xyz="0 1.2785662478625344 0" rpy="0 0 0"/>
            <mass value="1" />
            <inertia ixx="100" ixy="0" ixz="0" iyy="100" iyz="0" izz="100" />
        </inertial>
        <visual>
            <origin xyz="0 1.2785662478625344 0" rpy="0 0 0"/>
            <geometry>
                <box size="1.1144672909891749 1.2785662478625344 2.9619552167560075" />
            </geometry>
            <material name="Blue">
                <color rgba="0 1.0 1.0 1.0"/>
            </material>
        </visual>
        <collision>
            <origin xyz="0 1.2785662478625344 0" rpy="0 0 0"/>
            <geometry>
                <box size="1.1144672909891749 1.2785662478625344 2.9619552167560075" />
            </geometry>
        </collision>
    </link>
    <link name="Leg6">
        <inertial>
            <origin xyz="0 0 0.6964561507215836" rpy="0 0 0"/>
            <mass value="1" />
            <inertia ixx="100" ixy="0" ixz="0" iyy="100" iyz="0" izz="100" />
        </inertial>
        <visual>
            <origin xyz="0 0 0.6964561507215836" rpy="0 0 0"/>
            <geometry>
                <box size="1.3562848270810322 1.6822857171267098 1.3929123014431672" />
            </geometry>
            <material name="Blue">
                <color rgba="0 1.0 1.0 1.0"/>
            </material>
        </visual>
        <collision>
            <origin xyz="0 0 0.6964561507215836" rpy="0 0 0"/>
            <geometry>
                <box size="1.3562848270810322 1.6822857171267098 1.3929123014431672" />
            </geometry>
        </collision>
    </link>
    <link name="Leg7">
        <inertial>
            <origin xyz="0 0 2.4210868873131917" rpy="0 0 0"/>
            <mass value="1" />
            <inertia ixx="100" ixy="0" ixz="0" iyy="100" iyz="0" izz="100" />
        </inertial>
        <visual>
            <origin xyz="0 0 2.4210868873131917" rpy="0 0 0"/>
            <geometry>
                <box size="2.4218943419640575 2.658562838383922 2.4210868873131917" />
            </geometry>
            <material name="Blue">
                <color rgba="0 1.0 1.0 1.0"/>
            </material>
        </visual>
        <collision>
            <origin xyz="0 0 2.4210868873131917" rpy="0 0 0"/>
            <geometry>
                <box size="2.4218943419640575 2.658562838383922 2.4210868873131917" />
            </geometry>
        </collision>
    </link>
    <link name="Leg8">
        <inertial>
            <origin xyz="1.1445267245167117 0 0.9884416882838689" rpy="0 0 0"/>
            <mass value="1" />
            <inertia ixx="100" ixy="0" ixz="0" iyy="100" iyz="0" izz="100" />
        </inertial>
        <visual>
            <origin xyz="1.1445267245167117 0 0.9884416882838689" rpy="0 0 0"/>
            <geometry>
                <box size="2.2890534490334233 1.054972099740376 1.9768833765677378" />
            </geometry>
            <material name="Blue">
                <color rgba="0 1.0 1.0 1.0"/>
            </material>
        </visual>
        <collision>
            <origin xyz="1.1445267245167117 0 0.9884416882838689" rpy="0 0 0"/>
            <geometry>
                <box size="2.2890534490334233 1.054972099740376 1.9768833765677378" />
            </geometry>
        </collision>
    </link>
    <link name="Leg9">
        <inertial>
            <origin xyz="1.56427942779004 0.691569538232253 0" rpy="0 0 0"/>
            <mass value="1" />
            <inertia ixx="100" ixy="0" ixz="0" iyy="100" iyz="0" izz="100" />
        </inertial>
        <visual>
            <origin xyz="1.56427942779004 0.691569538232253 0" rpy="0 0 0"/>
            <geometry>
                <box size="1.56427942779004 1.383139076464506 2.2306536110790125" />
            </geometry>
            <material name="Blue">
                <color rgba="0 1.0 1.0 1.0"/>
            </material>
        </visual>
        <collision>
            <origin xyz="1.56427942779004 0.691569538232253 0" rpy="0 0 0"/>
            <geometry>
                <box size="1.56427942779004 1.383139076464506 2.2306536110790125" />
            </geometry>
        </collision>
    </link>
    <link name="Leg10">
        <inertial>
            <origin xyz="0 1.5484552386358552 0" rpy="0 0 0"/>
            <mass value="1" />
            <inertia ixx="100" ixy="0" ixz="0" iyy="100" iyz="0" izz="100" />
        </inertial>
        <visual>
            <origin xyz="0 1.5484552386358552 0" rpy="0 0 0"/>
            <geometry>
                <box size="1.795558826620302 1.5484552386358552 2.0285570971370976" />
            </geometry>
            <material name="Blue">
                <color rgba="0 1.0 1.0 1.0"/>
            </material>
        </visual>
        <collision>
            <origin xyz="0 1.5484552386358552 0" rpy="0 0 0"/>
            <geometry>
                <box size="1.795558826620302 1.5484552386358552 2.0285570971370976" />
            </geometry>
        </collision>
    </link>
    <link name="Leg11">
        <inertial>
            <origin xyz="0 0.9805217604638198 1.07177054664517" rpy="0 0 0"/>
            <mass value="1" />
            <inertia ixx="100" ixy="0" ixz="0" iyy="100" iyz="0" izz="100" />
        </inertial>
        <visual>
            <origin xyz="0 0.9805217604638198 1.07177054664517" rpy="0 0 0"/>
            <geometry>
                <box size="1.9507795648511916 1.9610435209276396 2.14354109329034" />
            </geometry>
            <material name="Blue">
                <color rgba="0 1.0 1.0 1.0"/>
            </material>
        </visual>
        <collision>
            <origin xyz="0 0.9805217604638198 1.07177054664517" rpy="0 0 0"/>
            <geometry>
                <box size="1.9507795648511916 1.9610435209276396 2.14354109329034" />
            </geometry>
        </collision>
    </link>
    <link name="Leg12">
        <inertial>
            <origin xyz="0.9140145577844638 1.0121006516317221 1.092602525702821" rpy="0 0 0"/>
            <mass value="1" />
            <inertia ixx="100" ixy="0" ixz="0" iyy="100" iyz="0" izz="100" />
        </inertial>
        <visual>
            <origin xyz="0.9140145577844638 1.0121006516317221 1.092602525702821" rpy="0 0 0"/>
            <geometry>
                <box size="1.8280291155689277 2.0242013032634443 2.185205051405642" />
            </geometry>
            <material name="Blue">
                <color rgba="0 1.0 1.0 1.0"/>
            </material>
        </visual>
        <collision>
            <origin xyz="0.9140145577844638 1.0121006516317221 1.092602525702821" rpy="0 0 0"/>
            <geometry>
                <box size="1.8280291155689277 2.0242013032634443 2.185205051405642" />
            </geometry>
        </collision>
    </link>
    <link name="Leg13">
        <inertial>
            <origin xyz="0 0 2.8304468739230595" rpy="0 0 0"/>
            <mass value="1" />
            <inertia ixx="100" ixy="0" ixz="0" iyy="100" iyz="0" izz="100" />
        </inertial>
        <visual>
            <origin xyz="0 0 2.8304468739230595" rpy="0 0 0"/>
            <geometry>
                <box size="2.176086574752392 1.0851072923246818 2.8304468739230595" />
            </geometry>
            <material name="Blue">
                <color rgba="0 1.0 1.0 1.0"/>
            </material>
        </visual>
        <collision>
            <origin xyz="0 0 2.8304468739230595" rpy="0 0 0"/>
            <geometry>
                <box size="2.176086574752392 1.0851072923246818 2.8304468739230595" />
            </geometry>
        </collision>
    </link>
    <link name="Leg14">
        <inertial>
            <origin xyz="0 0.832287754437826 0.6648663638928527" rpy="0 0 0"/>
            <mass value="1" />
            <inertia ixx="100" ixy="0" ixz="0" iyy="100" iyz="0" izz="100" />
        </inertial>
        <visual>
            <origin xyz="0 0.832287754437826 0.6648663638928527" rpy="0 0 0"/>
            <geometry>
                <box size="1.184387245629069 1.664575508875652 1.3297327277857054" />
            </geometry>
            <material name="Blue">
                <color rgba="0 1.0 1.0 1.0"/>
            </material>
        </visual>
        <collision>
            <origin xyz="0 0.832287754437826 0.6648663638928527" rpy="0 0 0"/>
            <geometry>
                <box size="1.184387245629069 1.664575508875652 1.3297327277857054" />
            </geometry>
        </collision>
    </link>
    <link name="Leg15">
        <inertial>
            <origin xyz="0 0 0.5223305938737011" rpy="0 0 0"/>
            <mass value="1" />
            <inertia ixx="100" ixy="0" ixz="0" iyy="100" iyz="0" izz="100" />
        </inertial>
        <visual>
            <origin xyz="0 0 0.5223305938737011" rpy="0 0 0"/>
            <geometry>
                <box size="2.8580985390605025 1.3305080795920354 1.0446611877474021" />
            </geometry>
            <material name="Blue">
                <color rgba="0 1.0 1.0 1.0"/>
            </material>
        </visual>
        <collision>
            <origin xyz="0 0 0.5223305938737011" rpy="0 0 0"/>
            <geometry>
                <box size="2.8580985390605025 1.3305080795920354 1.0446611877474021" />
            </geometry>
        </collision>
    </link>
    <link name="Leg16">
        <inertial>
            <origin xyz="1.0704609191827157 0 0" rpy="0 0 0"/>
            <mass value="1" />
            <inertia ixx="100" ixy="0" ixz="0" iyy="100" iyz="0" izz="100" />
        </inertial>
        <visual>
            <origin xyz="1.0704609191827157 0 0" rpy="0 0 0"/>
            <geometry>
                <box size="2.1409218383654314 2.2148628444232847 1.1062446122934244" />
            </geometry>
            <material name="Blue">
                <color rgba="0 1.0 1.0 1.0"/>
            </material>
        </visual>
        <collision>
            <origin xyz="1.0704609191827157 0 0" rpy="0 0 0"/>
            <geometry>
                <box size="2.1409218383654314 2.2148628444232847 1.1062446122934244" />
            </geometry>
        </collision>
    </link>
    <link name="Leg17">
        <inertial>
            <origin xyz="1.7572655742024625 1.0736725731367942 0" rpy="0 0 0"/>
            <mass value="1" />
            <inertia ixx="100" ixy="0" ixz="0" iyy="100" iyz="0" izz="100" />
        </inertial>
        <visual>
            <origin xyz="1.7572655742024625 1.0736725731367942 0" rpy="0 0 0"/>
            <geometry>
                <box size="1.7572655742024625 2.1473451462735884 1.6215076132630284" />
            </geometry>
            <material name="Blue">
                <color rgba="0 1.0 1.0 1.0"/>
            </material>
        </visual>
        <collision>
            <origin xyz="1.7572655742024625 1.0736725731367942 0" rpy="0 0 0"/>
            <geometry>
                <box size="1.7572655742024625 2.1473451462735884 1.6215076132630284" />
            </geometry>
        </collision>
    </link>
    <link name="Leg18">
        <inertial>
            <origin xyz="1.3341189503668804 0 1.2387537946082992" rpy="0 0 0"/>
            <mass value="1" />
            <inertia ixx="100" ixy="0" ixz="0" iyy="100" iyz="0" izz="100" />
        </inertial>
        <visual>
            <origin xyz="1.3341189503668804 0 1.2387537946082992" rpy="0 0 0"/>
            <geometry>
                <box size="2.668237900733761 1.1432225757007448 2.4775075892165983" />
            </geometry>
            <material name="Blue">
                <color rgba="0 1.0 1.0 1.0"/>
            </material>
        </visual>
        <collision>
            <origin xyz="1.3341189503668804 0 1.2387537946082992" rpy="0 0 0"/>
            <geometry>
                <box size="2.668237900733761 1.1432225757007448 2.4775075892165983" />
            </geometry>
        </collision>
    </link>
    <link name="Leg19">
        <inertial>
            <origin xyz="0 0 2.096455735783999" rpy="0 0 0"/>
            <mass value="1" />
            <inertia ixx="100" ixy="0" ixz="0" iyy="100" iyz="0" izz="100" />
        </inertial>
        <visual>
            <origin xyz="0 0 2.096455735783999" rpy="0 0 0"/>
            <geometry>
                <box size="1.8031759790825552 1.0307653308620894 2.096455735783999" />
            </geometry>
            <material name="Blue">
                <color rgba="0 1.0 1.0 1.0"/>
            </material>
        </visual>
        <collision>
            <origin xyz="0 0 2.096455735783999" rpy="0 0 0"/>
            <geometry>
                <box size="1.8031759790825552 1.0307653308620894 2.096455735783999" />
            </geometry>
        </collision>
    </link>
    <link name="Leg20">
        <inertial>
            <origin xyz="0 0.6544923911662116 0" rpy="0 0 0"/>
            <mass value="1" />
            <inertia ixx="100" ixy="0" ixz="0" iyy="100" iyz="0" izz="100" />
        </inertial>
        <visual>
            <origin xyz="0 0.6544923911662116 0" rpy="0 0 0"/>
            <geometry>
                <box size="2.6105891471615883 1.3089847823324232 1.2510895973631964" />
            </geometry>
            <material name="Blue">
                <color rgba="0 1.0 1.0 1.0"/>
            </material>
        </visual>
        <collision>
            <origin xyz="0 0.6544923911662116 0" rpy="0 0 0"/>
            <geometry>
                <box size="2.6105891471615883 1.3089847823324232 1.2510895973631964" />
            </geometry>
        </collision>
    </link>
    <link name="Leg21">
        <inertial>
            <origin xyz="0 0.6255396078800073 0.5087033194533933" rpy="0 0 0"/>
            <mass value="1" />
            <inertia ixx="100" ixy="0" ixz="0" iyy="100" iyz="0" izz="100" />
        </inertial>
        <visual>
            <origin xyz="0 0.6255396078800073 0.5087033194533933" rpy="0 0 0"/>
            <geometry>
                <box size="2.909705465898555 1.2510792157600146 1.0174066389067866" />
            </geometry>
            <material name="Blue">
                <color rgba="0 1.0 1.0 1.0"/>
            </material>
        </visual>
        <collision>
            <origin xyz="0 0.6255396078800073 0.5087033194533933" rpy="0 0 0"/>
            <geometry>
                <box size="2.909705465898555 1.2510792157600146 1.0174066389067866" />
            </geometry>
        </collision>
    </link>
    <link name="Leg22">
        <inertial>
            <origin xyz="0.5025894498360142 0 0" rpy="0 0 0"/>
            <mass value="1" />
            <inertia ixx="100" ixy="0" ixz="0" iyy="100" iyz="0" izz="100" />
        </inertial>
        <visual>
            <origin xyz="0.5025894498360142 0 0" rpy="0 0 0"/>
            <geometry>
                <box size="1.0051788996720283 1.073226977721101 2.2139420056856007" />
            </geometry>
            <material name="Blue">
                <color rgba="0 1.0 1.0 1.0"/>
            </material>
        </visual>
        <collision>
            <origin xyz="0.5025894498360142 0 0" rpy="0 0 0"/>
            <geometry>
                <box size="1.0051788996720283 1.073226977721101 2.2139420056856007" />
            </geometry>
        </collision>
    </link>
    <link name="Leg23">
        <inertial>
            <origin xyz="0 1.0403618873157505 0" rpy="0 0 0"/>
            <mass value="1" />
            <inertia ixx="100" ixy="0" ixz="0" iyy="100" iyz="0" izz="100" />
        </inertial>
        <visual>
            <origin xyz="0 1.0403618873157505 0" rpy="0 0 0"/>
            <geometry>
                <box size="1.0976078488827092 2.080723774631501 2.5152110722601" />
            </geometry>
            <material name="Blue">
                <color rgba="0 1.0 1.0 1.0"/>
            </material>
        </visual>
        <collision>
            <origin xyz="0 1.0403618873157505 0" rpy="0 0 0"/>
            <geometry>
                <box size="1.0976078488827092 2.080723774631501 2.5152110722601" />
            </geometry>
        </collision>
    </link>
    <link name="Leg24">
        <inertial>
            <origin xyz="0 0.5460633621692862 0.8599492176702863" rpy="0 0 0"/>
            <mass value="1" />
            <inertia ixx="100" ixy="0" ixz="0" iyy="100" iyz="0" izz="100" />
        </inertial>
        <visual>
            <origin xyz="0 0.5460633621692862 0.8599492176702863" rpy="0 0 0"/>
            <geometry>
                <box size="2.5449644772666247 1.0921267243385724 1.7198984353405726" />
            </geometry>
            <material name="Blue">
                <color rgba="0 1.0 1.0 1.0"/>
            </material>
        </visual>
        <collision>
            <origin xyz="0 0.5460633621692862 0.8599492176702863" rpy="0 0 0"/>
            <geometry>
                <box size="2.5449644772666247 1.0921267243385724 1.7198984353405726" />
            </geometry>
        </collision>
    </link>
    <link name="Leg25">
        <inertial>
            <origin xyz="0 0.7399919997320149 0" rpy="0 0 0"/>
            <mass value="1" />
            <inertia ixx="100" ixy="0" ixz="0" iyy="100" iyz="0" izz="100" />
        </inertial>
        <visual>
            <origin xyz="0 0.7399919997320149 0" rpy="0 0 0"/>
            <geometry>
                <box size="1.2030911762726322 1.4799839994640298 2.5007233121162025" />
            </geometry>
            <material name="Blue">
                <color rgba="0 1.0 1.0 1.0"/>
            </material>
        </visual>
        <collision>
            <origin xyz="0 0.7399919997320149 0" rpy="0 0 0"/>
            <geometry>
                <box size="1.2030911762726322 1.4799839994640298 2.5007233121162025" />
            </geometry>
        </collision>
    </link>
    <link name="Leg26">
        <inertial>
            <origin xyz="0 0 0.572411658948131" rpy="0 0 0"/>
            <mass value="1" />
            <inertia ixx="100" ixy="0" ixz="0" iyy="100" iyz="0" izz="100" />
        </inertial>
        <visual>
            <origin xyz="0 0 0.572411658948131" rpy="0 0 0"/>
            <geometry>
                <box size="2.047013353444859 2.282050760751047 1.144823317896262" />
            </geometry>
            <material name="Blue">
                <color rgba="0 1.0 1.0 1.0"/>
            </material>
        </visual>
        <collision>
            <origin xyz="0 0 0.572411658948131" rpy="0 0 0"/>
            <geometry>
                <box size="2.047013353444859 2.282050760751047 1.144823317896262" />
            </geometry>
        </collision>
    </link>
    <link name="Leg27">
        <inertial>
            <origin xyz="0 0 0.9671401628288688" rpy="0 0 0"/>
            <mass value="1" />
            <inertia ixx="100" ixy="0" ixz="0" iyy="100" iyz="0" izz="100" />
        </inertial>
        <visual>
            <origin xyz="0 0 0.9671401628288688" rpy="0 0 0"/>
            <geometry>
                <box size="1.7171802879972735 1.2008627588181335 1.9342803256577377" />
            </geometry>
            <material name="Green">
                <color rgba="0 180.0 100.0 1.0"/>
            </material>
        </visual>
        <collision>
            <origin xyz="0 0 0.9671401628288688" rpy="0 0 0"/>
            <geometry>
                <box size="1.7171802879972735 1.2008627588181335 1.9342803256577377" />
            </geometry>
        </collision>
    </link>
    <joint name="Torso_Leg1" type="revolute">
       <parent link="Torso"/>
       <child  link="Leg1"/>
       <origin rpy="0 0 0" xyz="0 0 1.4983192934237086" />
     <axis xyz="1 0 0"/>
       <limit effort="0.0" lower="-3.14159" upper="3.14159" velocity="0.0"/>
    </joint>
    <joint name="Torso_Leg2" type="revolute">
       <parent link="Torso"/>
       <child  link="Leg2"/>
       <origin rpy="0 0 0" xyz="0.859862889907482 0.8810106997759528 0.928764371030893" />
     <axis xyz="1 0 0"/>
       <limit effort="0.0" lower="-3.14159" upper="3.14159" velocity="0.0"/>
    </joint>
    <joint name="Leg1_Leg3" type="revolute">
       <parent link="Leg1"/>
       <child  link="Leg3"/>
       <origin rpy="0 0 0" xyz="1.0573526063925345 0 0.9915046097278846" />
     <axis xyz="1 0 0"/>
       <limit effort="0.0" lower="-3.14159" upper="3.14159" velocity="0.0"/>
    </joint>
    <joint name="Leg3_Leg4" type="revolute">
       <parent link="Leg3"/>
       <child  link="Leg4"/>
       <origin rpy="0 0 0" xyz="0.5339725699244038 2.181962651034385 1.198615909310564" />
     <axis xyz="1 0 0"/>
       <limit effort="0.0" lower="-3.14159" upper="3.14159" velocity="0.0"/>
    </joint>
    <joint name="Leg2_Leg5" type="revolute">
       <parent link="Leg2"/>
       <child  link="Leg5"/>
       <origin rpy="0 0 0" xyz="0 0.5643722117688824 2.701215188161158" />
     <axis xyz="1 0 0"/>
       <limit effort="0.0" lower="-3.14159" upper="3.14159" velocity="0.0"/>
    </joint>
    <joint name="Leg2_Leg6" type="revolute">
       <parent link="Leg2"/>
       <child  link="Leg6"/>
       <origin rpy="0 0 0" xyz="0 0.5643722117688824 2.701215188161158" />
     <axis xyz="1 0 0"/>
       <limit effort="0.0" lower="-3.14159" upper="3.14159" velocity="0.0"/>
    </joint>
    <joint name="Leg3_Leg7" type="revolute">
       <parent link="Leg3"/>
       <child  link="Leg7"/>
       <origin rpy="0 0 0" xyz="0.5339725699244038 2.181962651034385 1.198615909310564" />
     <axis xyz="1 0 0"/>
       <limit effort="0.0" lower="-3.14159" upper="3.14159" velocity="0.0"/>
    </joint>
    <joint name="Leg6_Leg8" type="revolute">
       <parent link="Leg6"/>
       <child  link="Leg8"/>
       <origin rpy="0 0 0" xyz="0 0 2.4210868873131917" />
     <axis xyz="1 0 0"/>
       <limit effort="0.0" lower="-3.14159" upper="3.14159" velocity="0.0"/>
    </joint>
    <joint name="Leg3_Leg9" type="revolute">
       <parent link="Leg3"/>
       <child  link="Leg9"/>
       <origin rpy="0 0 0" xyz="0.5339725699244038 2.181962651034385 1.198615909310564" />
     <axis xyz="1 0 0"/>
       <limit effort="0.0" lower="-3.14159" upper="3.14159" velocity="0.0"/>
    </joint>
    <joint name="Leg4_Leg10" type="revolute">
       <parent link="Leg4"/>
       <child  link="Leg10"/>
       <origin rpy="0 0 0" xyz="0 1.2785662478625344 0" />
     <axis xyz="1 0 0"/>
       <limit effort="0.0" lower="-3.14159" upper="3.14159" velocity="0.0"/>
    </joint>
    <joint name="Leg8_Leg11" type="revolute">
       <parent link="Leg8"/>
       <child  link="Leg11"/>
       <origin rpy="0 0 0" xyz="1.56427942779004 0.691569538232253 0" />
     <axis xyz="1 0 0"/>
       <limit effort="0.0" lower="-3.14159" upper="3.14159" velocity="0.0"/>
    </joint>
    <joint name="Leg10_Leg12" type="revolute">
       <parent link="Leg10"/>
       <child  link="Leg12"/>
       <origin rpy="0 0 0" xyz="0 0.9805217604638198 1.07177054664517" />
     <axis xyz="1 0 0"/>
       <limit effort="0.0" lower="-3.14159" upper="3.14159" velocity="0.0"/>
    </joint>
    <joint name="Leg12_Leg13" type="revolute">
       <parent link="Leg12"/>
       <child  link="Leg13"/>
       <origin rpy="0 0 0" xyz="0 0 2.8304468739230595" />
     <axis xyz="1 0 0"/>
       <limit effort="0.0" lower="-3.14159" upper="3.14159" velocity="0.0"/>
    </joint>
    <joint name="Leg9_Leg14" type="revolute">
       <parent link="Leg9"/>
       <child  link="Leg14"/>
       <origin rpy="0 0 0" xyz="0 1.5484552386358552 0" />
     <axis xyz="1 0 0"/>
       <limit effort="0.0" lower="-3.14159" upper="3.14159" velocity="0.0"/>
    </joint>
    <joint name="Leg13_Leg15" type="revolute">
       <parent link="Leg13"/>
       <child  link="Leg15"/>
       <origin rpy="0 0 0" xyz="0 0.832287754437826 0.6648663638928527" />
     <axis xyz="1 0 0"/>
       <limit effort="0.0" lower="-3.14159" upper="3.14159" velocity="0.0"/>
    </joint>
    <joint name="Leg11_Leg16" type="revolute">
       <parent link="Leg11"/>
       <child  link="Leg16"/>
       <origin rpy="0 0 0" xyz="0.9140145577844638 1.0121006516317221 1.092602525702821" />
     <axis xyz="1 0 0"/>
       <limit effort="0.0" lower="-3.14159" upper="3.14159" velocity="0.0"/>
    </joint>
    <joint name="Leg7_Leg17" type="revolute">
       <parent link="Leg7"/>
       <child  link="Leg17"/>
       <origin rpy="0 0 0" xyz="1.1445267245167117 0 0.9884416882838689" />
     <axis xyz="1 0 0"/>
       <limit effort="0.0" lower="-3.14159" upper="3.14159" velocity="0.0"/>
    </joint>
    <joint name="Leg8_Leg18" type="revolute">
       <parent link="Leg8"/>
       <child  link="Leg18"/>
       <origin rpy="0 0 0" xyz="1.56427942779004 0.691569538232253 0" />
     <axis xyz="1 0 0"/>
       <limit effort="0.0" lower="-3.14159" upper="3.14159" velocity="0.0"/>
    </joint>
    <joint name="Leg17_Leg19" type="revolute">
       <parent link="Leg17"/>
       <child  link="Leg19"/>
       <origin rpy="0 0 0" xyz="1.3341189503668804 0 1.2387537946082992" />
     <axis xyz="1 0 0"/>
       <limit effort="0.0" lower="-3.14159" upper="3.14159" velocity="0.0"/>
    </joint>
    <joint name="Leg11_Leg20" type="revolute">
       <parent link="Leg11"/>
       <child  link="Leg20"/>
       <origin rpy="0 0 0" xyz="0.9140145577844638 1.0121006516317221 1.092602525702821" />
     <axis xyz="1 0 0"/>
       <limit effort="0.0" lower="-3.14159" upper="3.14159" velocity="0.0"/>
    </joint>
    <joint name="Leg18_Leg21" type="revolute">
       <parent link="Leg18"/>
       <child  link="Leg21"/>
       <origin rpy="0 0 0" xyz="0 0 2.096455735783999" />
     <axis xyz="1 0 0"/>
       <limit effort="0.0" lower="-3.14159" upper="3.14159" velocity="0.0"/>
    </joint>
    <joint name="Leg16_Leg22" type="revolute">
       <parent link="Leg16"/>
       <child  link="Leg22"/>
       <origin rpy="0 0 0" xyz="1.7572655742024625 1.0736725731367942 0" />
     <axis xyz="1 0 0"/>
       <limit effort="0.0" lower="-3.14159" upper="3.14159" velocity="0.0"/>
    </joint>
    <joint name="Leg16_Leg23" type="revolute">
       <parent link="Leg16"/>
       <child  link="Leg23"/>
       <origin rpy="0 0 0" xyz="1.7572655742024625 1.0736725731367942 0" />
     <axis xyz="1 0 0"/>
       <limit effort="0.0" lower="-3.14159" upper="3.14159" velocity="0.0"/>
    </joint>
    <joint name="Torso_Leg24" type="revolute">
       <parent link="Torso"/>
       <child  link="Leg24"/>
       <origin rpy="0 0 0" xyz="0.859862889907482 0.8810106997759528 0.928764371030893" />
     <axis xyz="1 0 0"/>
       <limit effort="0.0" lower="-3.14159" upper="3.14159" velocity="0.0"/>
    </joint>
    <joint name="Leg20_Leg25" type="revolute">
       <parent link="Leg20"/>
       <child  link="Leg25"/>
       <origin rpy="0 0 0" xyz="0 0.6255396078800073 0.5087033194533933" />
     <axis xyz="1 0 0"/>
       <limit effort="0.0" lower="-3.14159" upper="3.14159" velocity="0.0"/>
    </joint>
    <joint name="Leg23_Leg26" type="revolute">
       <parent link="Leg23"/>
       <child  link="Leg26"/>
       <origin rpy="0 0 0" xyz="0 0.5460633621692862 0.8599492176702863" />
     <axis xyz="1 0 0"/>
       <limit effort="0.0" lower="-3.14159" upper="3.14159" velocity="0.0"/>
    </joint>
    <joint name="Leg26_Leg27" type="revolute">
       <parent link="Leg26"/>
       <child  link="Leg26"/>
       <origin rpy="0 0 0" xyz="0 0 1.144823317896262" />
     <axis xyz="1 0 0"/>
       <limit effort="0.0" lower="-3.14159" upper="3.14159" velocity="0.0"/>
    </joint>
</robot>