<robot name = "robot">
    <link name="Torso">
        <inertial>
            <origin xyz="0 0 0.8681697785189159" rpy="0 0 0"/>
            <mass value="1" />
            <inertia ixx="100" ixy="0" ixz="0" iyy="100" iyz="0" izz="100" />
        </inertial>
        <visual>
            <origin xyz="0 0 0.8681697785189159" rpy="0 0 0"/>
            <geometry>
                <box size="2.8385463849397268 1.9931642002324244 1.7363395570378317" />
            </geometry>
            <material name="Green">
                <color rgba="0 180.0 0.0 1.0"/>
            </material>
        </visual>
        <collision>
            <origin xyz="0 0 0.8681697785189159" rpy="0 0 0"/>
            <geometry>
                <box size="2.8385463849397268 1.9931642002324244 1.7363395570378317" />
            </geometry>
        </collision>
    </link>
    <link name="Leg1">
        <inertial>
            <origin xyz="1.1143813858682796 0 0" rpy="0 0 0"/>
            <mass value="1" />
            <inertia ixx="100" ixy="0" ixz="0" iyy="100" iyz="0" izz="100" />
        </inertial>
        <visual>
            <origin xyz="1.1143813858682796 0 0" rpy="0 0 0"/>
            <geometry>
                <box size="2.2287627717365592 1.0232851626066768 2.8826502093209907" />
            </geometry>
            <material name="Green">
                <color rgba="0 180.0 0.0 1.0"/>
            </material>
        </visual>
        <collision>
            <origin xyz="1.1143813858682796 0 0" rpy="0 0 0"/>
            <geometry>
                <box size="2.2287627717365592 1.0232851626066768 2.8826502093209907" />
            </geometry>
        </collision>
    </link>
    <link name="Leg2">
        <inertial>
            <origin xyz="0.6173178895181524 0 0" rpy="0 0 0"/>
            <mass value="1" />
            <inertia ixx="100" ixy="0" ixz="0" iyy="100" iyz="0" izz="100" />
        </inertial>
        <visual>
            <origin xyz="0.6173178895181524 0 0" rpy="0 0 0"/>
            <geometry>
                <box size="1.2346357790363047 1.426186535194413 2.419762205583719" />
            </geometry>
            <material name="Blue">
                <color rgba="0 1.0 1.0 1.0"/>
            </material>
        </visual>
        <collision>
            <origin xyz="0.6173178895181524 0 0" rpy="0 0 0"/>
            <geometry>
                <box size="1.2346357790363047 1.426186535194413 2.419762205583719" />
            </geometry>
        </collision>
    </link>
    <link name="Leg3">
        <inertial>
            <origin xyz="0 0.6430817698538221 0" rpy="0 0 0"/>
            <mass value="1" />
            <inertia ixx="100" ixy="0" ixz="0" iyy="100" iyz="0" izz="100" />
        </inertial>
        <visual>
            <origin xyz="0 0.6430817698538221 0" rpy="0 0 0"/>
            <geometry>
                <box size="1.4158057769531824 1.2861635397076443 2.324402021739351" />
            </geometry>
            <material name="Blue">
                <color rgba="0 1.0 1.0 1.0"/>
            </material>
        </visual>
        <collision>
            <origin xyz="0 0.6430817698538221 0" rpy="0 0 0"/>
            <geometry>
                <box size="1.4158057769531824 1.2861635397076443 2.324402021739351" />
            </geometry>
        </collision>
    </link>
    <link name="Leg4">
        <inertial>
            <origin xyz="0.928932455871458 0 0" rpy="0 0 0"/>
            <mass value="1" />
            <inertia ixx="100" ixy="0" ixz="0" iyy="100" iyz="0" izz="100" />
        </inertial>
        <visual>
            <origin xyz="0.928932455871458 0 0" rpy="0 0 0"/>
            <geometry>
                <box size="1.857864911742916 2.6621833168789495 2.2566117654316162" />
            </geometry>
            <material name="Green">
                <color rgba="0 180.0 0.0 1.0"/>
            </material>
        </visual>
        <collision>
            <origin xyz="0.928932455871458 0 0" rpy="0 0 0"/>
            <geometry>
                <box size="1.857864911742916 2.6621833168789495 2.2566117654316162" />
            </geometry>
        </collision>
    </link>
    <link name="Leg5">
        <inertial>
            <origin xyz="1.4066231881968303 0 0" rpy="0 0 0"/>
            <mass value="1" />
            <inertia ixx="100" ixy="0" ixz="0" iyy="100" iyz="0" izz="100" />
        </inertial>
        <visual>
            <origin xyz="1.4066231881968303 0 0" rpy="0 0 0"/>
            <geometry>
                <box size="2.8132463763936606 2.091906941904793 1.282919819620704" />
            </geometry>
            <material name="Blue">
                <color rgba="0 1.0 1.0 1.0"/>
            </material>
        </visual>
        <collision>
            <origin xyz="1.4066231881968303 0 0" rpy="0 0 0"/>
            <geometry>
                <box size="2.8132463763936606 2.091906941904793 1.282919819620704" />
            </geometry>
        </collision>
    </link>
    <link name="Leg6">
        <inertial>
            <origin xyz="0 0 1.1840411416906604" rpy="0 0 0"/>
            <mass value="1" />
            <inertia ixx="100" ixy="0" ixz="0" iyy="100" iyz="0" izz="100" />
        </inertial>
        <visual>
            <origin xyz="0 0 1.1840411416906604" rpy="0 0 0"/>
            <geometry>
                <box size="2.5632788327522755 2.088044387983027 2.368082283381321" />
            </geometry>
            <material name="Green">
                <color rgba="0 180.0 0.0 1.0"/>
            </material>
        </visual>
        <collision>
            <origin xyz="0 0 1.1840411416906604" rpy="0 0 0"/>
            <geometry>
                <box size="2.5632788327522755 2.088044387983027 2.368082283381321" />
            </geometry>
        </collision>
    </link>
    <link name="Leg7">
        <inertial>
            <origin xyz="0 0 1.1544535005549694" rpy="0 0 0"/>
            <mass value="1" />
            <inertia ixx="100" ixy="0" ixz="0" iyy="100" iyz="0" izz="100" />
        </inertial>
        <visual>
            <origin xyz="0 0 1.1544535005549694" rpy="0 0 0"/>
            <geometry>
                <box size="1.8192390859586616 2.3183760986906146 2.308907001109939" />
            </geometry>
            <material name="Blue">
                <color rgba="0 1.0 1.0 1.0"/>
            </material>
        </visual>
        <collision>
            <origin xyz="0 0 1.1544535005549694" rpy="0 0 0"/>
            <geometry>
                <box size="1.8192390859586616 2.3183760986906146 2.308907001109939" />
            </geometry>
        </collision>
    </link>
    <link name="Leg8">
        <inertial>
            <origin xyz="0 0.5199264977840418 0" rpy="0 0 0"/>
            <mass value="1" />
            <inertia ixx="100" ixy="0" ixz="0" iyy="100" iyz="0" izz="100" />
        </inertial>
        <visual>
            <origin xyz="0 0.5199264977840418 0" rpy="0 0 0"/>
            <geometry>
                <box size="2.6975148649637077 1.0398529955680835 1.233101320023409" />
            </geometry>
            <material name="Blue">
                <color rgba="0 1.0 1.0 1.0"/>
            </material>
        </visual>
        <collision>
            <origin xyz="0 0.5199264977840418 0" rpy="0 0 0"/>
            <geometry>
                <box size="2.6975148649637077 1.0398529955680835 1.233101320023409" />
            </geometry>
        </collision>
    </link>
    <link name="Leg9">
        <inertial>
            <origin xyz="0 0 1.3224766242719455" rpy="0 0 0"/>
            <mass value="1" />
            <inertia ixx="100" ixy="0" ixz="0" iyy="100" iyz="0" izz="100" />
        </inertial>
        <visual>
            <origin xyz="0 0 1.3224766242719455" rpy="0 0 0"/>
            <geometry>
                <box size="1.6112912246954934 1.5587423777716722 2.644953248543891" />
            </geometry>
            <material name="Blue">
                <color rgba="0 1.0 1.0 1.0"/>
            </material>
        </visual>
        <collision>
            <origin xyz="0 0 1.3224766242719455" rpy="0 0 0"/>
            <geometry>
                <box size="1.6112912246954934 1.5587423777716722 2.644953248543891" />
            </geometry>
        </collision>
    </link>
    <link name="Leg10">
        <inertial>
            <origin xyz="0 0 1.1723863590461976" rpy="0 0 0"/>
            <mass value="1" />
            <inertia ixx="100" ixy="0" ixz="0" iyy="100" iyz="0" izz="100" />
        </inertial>
        <visual>
            <origin xyz="0 0 1.1723863590461976" rpy="0 0 0"/>
            <geometry>
                <box size="2.6104781592026747 2.271982453359128 2.344772718092395" />
            </geometry>
            <material name="Blue">
                <color rgba="0 1.0 1.0 1.0"/>
            </material>
        </visual>
        <collision>
            <origin xyz="0 0 1.1723863590461976" rpy="0 0 0"/>
            <geometry>
                <box size="2.6104781592026747 2.271982453359128 2.344772718092395" />
            </geometry>
        </collision>
    </link>
    <link name="Leg11">
        <inertial>
            <origin xyz="0.8591568402648412 0 0" rpy="0 0 0"/>
            <mass value="1" />
            <inertia ixx="100" ixy="0" ixz="0" iyy="100" iyz="0" izz="100" />
        </inertial>
        <visual>
            <origin xyz="0.8591568402648412 0 0" rpy="0 0 0"/>
            <geometry>
                <box size="1.7183136805296824 1.0689807886569436 2.048286420942687" />
            </geometry>
            <material name="Blue">
                <color rgba="0 1.0 1.0 1.0"/>
            </material>
        </visual>
        <collision>
            <origin xyz="0.8591568402648412 0 0" rpy="0 0 0"/>
            <geometry>
                <box size="1.7183136805296824 1.0689807886569436 2.048286420942687" />
            </geometry>
        </collision>
    </link>
    <link name="Leg12">
        <inertial>
            <origin xyz="0 1.4676575338931834 0" rpy="0 0 0"/>
            <mass value="1" />
            <inertia ixx="100" ixy="0" ixz="0" iyy="100" iyz="0" izz="100" />
        </inertial>
        <visual>
            <origin xyz="0 1.4676575338931834 0" rpy="0 0 0"/>
            <geometry>
                <box size="1.8966649501498944 2.935315067786367 1.802544778047872" />
            </geometry>
            <material name="Blue">
                <color rgba="0 1.0 1.0 1.0"/>
            </material>
        </visual>
        <collision>
            <origin xyz="0 1.4676575338931834 0" rpy="0 0 0"/>
            <geometry>
                <box size="1.8966649501498944 2.935315067786367 1.802544778047872" />
            </geometry>
        </collision>
    </link>
    <link name="Leg13">
        <inertial>
            <origin xyz="0.532816399744533 0 0" rpy="0 0 0"/>
            <mass value="1" />
            <inertia ixx="100" ixy="0" ixz="0" iyy="100" iyz="0" izz="100" />
        </inertial>
        <visual>
            <origin xyz="0.532816399744533 0 0" rpy="0 0 0"/>
            <geometry>
                <box size="1.065632799489066 2.4294832323904783 1.5127313967017384" />
            </geometry>
            <material name="Green">
                <color rgba="0 180.0 0.0 1.0"/>
            </material>
        </visual>
        <collision>
            <origin xyz="0.532816399744533 0 0" rpy="0 0 0"/>
            <geometry>
                <box size="1.065632799489066 2.4294832323904783 1.5127313967017384" />
            </geometry>
        </collision>
    </link>
    <link name="Leg14">
        <inertial>
            <origin xyz="0 1.398669686381418 0" rpy="0 0 0"/>
            <mass value="1" />
            <inertia ixx="100" ixy="0" ixz="0" iyy="100" iyz="0" izz="100" />
        </inertial>
        <visual>
            <origin xyz="0 1.398669686381418 0" rpy="0 0 0"/>
            <geometry>
                <box size="2.5257466473894903 2.797339372762836 2.834340838120351" />
            </geometry>
            <material name="Green">
                <color rgba="0 180.0 0.0 1.0"/>
            </material>
        </visual>
        <collision>
            <origin xyz="0 1.398669686381418 0" rpy="0 0 0"/>
            <geometry>
                <box size="2.5257466473894903 2.797339372762836 2.834340838120351" />
            </geometry>
        </collision>
    </link>
    <link name="Leg15">
        <inertial>
            <origin xyz="0 0 0.8168308062162771" rpy="0 0 0"/>
            <mass value="1" />
            <inertia ixx="100" ixy="0" ixz="0" iyy="100" iyz="0" izz="100" />
        </inertial>
        <visual>
            <origin xyz="0 0 0.8168308062162771" rpy="0 0 0"/>
            <geometry>
                <box size="1.591773752282575 1.5695767057477874 1.6336616124325543" />
            </geometry>
            <material name="Green">
                <color rgba="0 180.0 0.0 1.0"/>
            </material>
        </visual>
        <collision>
            <origin xyz="0 0 0.8168308062162771" rpy="0 0 0"/>
            <geometry>
                <box size="1.591773752282575 1.5695767057477874 1.6336616124325543" />
            </geometry>
        </collision>
    </link>
    <link name="Leg16">
        <inertial>
            <origin xyz="0 0 1.1060895583326618" rpy="0 0 0"/>
            <mass value="1" />
            <inertia ixx="100" ixy="0" ixz="0" iyy="100" iyz="0" izz="100" />
        </inertial>
        <visual>
            <origin xyz="0 0 1.1060895583326618" rpy="0 0 0"/>
            <geometry>
                <box size="1.5525034190036142 2.724416417415344 2.2121791166653235" />
            </geometry>
            <material name="Green">
                <color rgba="0 180.0 0.0 1.0"/>
            </material>
        </visual>
        <collision>
            <origin xyz="0 0 1.1060895583326618" rpy="0 0 0"/>
            <geometry>
                <box size="1.5525034190036142 2.724416417415344 2.2121791166653235" />
            </geometry>
        </collision>
    </link>
    <link name="Leg17">
        <inertial>
            <origin xyz="0 0 0.5402114014176769" rpy="0 0 0"/>
            <mass value="1" />
            <inertia ixx="100" ixy="0" ixz="0" iyy="100" iyz="0" izz="100" />
        </inertial>
        <visual>
            <origin xyz="0 0 0.5402114014176769" rpy="0 0 0"/>
            <geometry>
                <box size="2.643186490747105 2.353702688899365 1.0804228028353537" />
            </geometry>
            <material name="Green">
                <color rgba="0 180.0 0.0 1.0"/>
            </material>
        </visual>
        <collision>
            <origin xyz="0 0 0.5402114014176769" rpy="0 0 0"/>
            <geometry>
                <box size="2.643186490747105 2.353702688899365 1.0804228028353537" />
            </geometry>
        </collision>
    </link>
    <link name="Leg18">
        <inertial>
            <origin xyz="0 1.0571289258015897 0" rpy="0 0 0"/>
            <mass value="1" />
            <inertia ixx="100" ixy="0" ixz="0" iyy="100" iyz="0" izz="100" />
        </inertial>
        <visual>
            <origin xyz="0 1.0571289258015897 0" rpy="0 0 0"/>
            <geometry>
                <box size="1.9094324072248727 2.1142578516031794 2.8705962700133227" />
            </geometry>
            <material name="Green">
                <color rgba="0 180.0 0.0 1.0"/>
            </material>
        </visual>
        <collision>
            <origin xyz="0 1.0571289258015897 0" rpy="0 0 0"/>
            <geometry>
                <box size="1.9094324072248727 2.1142578516031794 2.8705962700133227" />
            </geometry>
        </collision>
    </link>
    <link name="Leg19">
        <inertial>
            <origin xyz="0 0.8178621102358816 0" rpy="0 0 0"/>
            <mass value="1" />
            <inertia ixx="100" ixy="0" ixz="0" iyy="100" iyz="0" izz="100" />
        </inertial>
        <visual>
            <origin xyz="0 0.8178621102358816 0" rpy="0 0 0"/>
            <geometry>
                <box size="1.0360195782765564 1.6357242204717632 2.685976240901785" />
            </geometry>
            <material name="Green">
                <color rgba="0 180.0 0.0 1.0"/>
            </material>
        </visual>
        <collision>
            <origin xyz="0 0.8178621102358816 0" rpy="0 0 0"/>
            <geometry>
                <box size="1.0360195782765564 1.6357242204717632 2.685976240901785" />
            </geometry>
        </collision>
    </link>
    <link name="Leg20">
        <inertial>
            <origin xyz="0 1.4704269178017741 0" rpy="0 0 0"/>
            <mass value="1" />
            <inertia ixx="100" ixy="0" ixz="0" iyy="100" iyz="0" izz="100" />
        </inertial>
        <visual>
            <origin xyz="0 1.4704269178017741 0" rpy="0 0 0"/>
            <geometry>
                <box size="1.9879800006339545 2.9408538356035483 1.5043560861787428" />
            </geometry>
            <material name="Blue">
                <color rgba="0 1.0 1.0 1.0"/>
            </material>
        </visual>
        <collision>
            <origin xyz="0 1.4704269178017741 0" rpy="0 0 0"/>
            <geometry>
                <box size="1.9879800006339545 2.9408538356035483 1.5043560861787428" />
            </geometry>
        </collision>
    </link>
    <link name="Leg21">
        <inertial>
            <origin xyz="1.3004484197436383 0 0" rpy="0 0 0"/>
            <mass value="1" />
            <inertia ixx="100" ixy="0" ixz="0" iyy="100" iyz="0" izz="100" />
        </inertial>
        <visual>
            <origin xyz="1.3004484197436383 0 0" rpy="0 0 0"/>
            <geometry>
                <box size="2.6008968394872767 2.629692267589886 2.5595235022757965" />
            </geometry>
            <material name="Blue">
                <color rgba="0 1.0 1.0 1.0"/>
            </material>
        </visual>
        <collision>
            <origin xyz="1.3004484197436383 0 0" rpy="0 0 0"/>
            <geometry>
                <box size="2.6008968394872767 2.629692267589886 2.5595235022757965" />
            </geometry>
        </collision>
    </link>
    <link name="Leg22">
        <inertial>
            <origin xyz="0.5424072742509826 0 0" rpy="0 0 0"/>
            <mass value="1" />
            <inertia ixx="100" ixy="0" ixz="0" iyy="100" iyz="0" izz="100" />
        </inertial>
        <visual>
            <origin xyz="0.5424072742509826 0 0" rpy="0 0 0"/>
            <geometry>
                <box size="1.0848145485019651 2.733417186857505 1.2607945386265555" />
            </geometry>
            <material name="Blue">
                <color rgba="0 1.0 1.0 1.0"/>
            </material>
        </visual>
        <collision>
            <origin xyz="0.5424072742509826 0 0" rpy="0 0 0"/>
            <geometry>
                <box size="1.0848145485019651 2.733417186857505 1.2607945386265555" />
            </geometry>
        </collision>
    </link>
    <link name="Leg23">
        <inertial>
            <origin xyz="0 0.6120570005182518 0" rpy="0 0 0"/>
            <mass value="1" />
            <inertia ixx="100" ixy="0" ixz="0" iyy="100" iyz="0" izz="100" />
        </inertial>
        <visual>
            <origin xyz="0 0.6120570005182518 0" rpy="0 0 0"/>
            <geometry>
                <box size="2.083205762031675 1.2241140010365037 1.5777955475055414" />
            </geometry>
            <material name="Green">
                <color rgba="0 180.0 0.0 1.0"/>
            </material>
        </visual>
        <collision>
            <origin xyz="0 0.6120570005182518 0" rpy="0 0 0"/>
            <geometry>
                <box size="2.083205762031675 1.2241140010365037 1.5777955475055414" />
            </geometry>
        </collision>
    </link>
    <link name="Leg24">
        <inertial>
            <origin xyz="0 1.454055672395538 0" rpy="0 0 0"/>
            <mass value="1" />
            <inertia ixx="100" ixy="0" ixz="0" iyy="100" iyz="0" izz="100" />
        </inertial>
        <visual>
            <origin xyz="0 1.454055672395538 0" rpy="0 0 0"/>
            <geometry>
                <box size="1.9340523730069943 2.908111344791076 2.3892588386272124" />
            </geometry>
            <material name="Blue">
                <color rgba="0 1.0 1.0 1.0"/>
            </material>
        </visual>
        <collision>
            <origin xyz="0 1.454055672395538 0" rpy="0 0 0"/>
            <geometry>
                <box size="1.9340523730069943 2.908111344791076 2.3892588386272124" />
            </geometry>
        </collision>
    </link>
    <link name="Leg25">
        <inertial>
            <origin xyz="0.7003459992493148 0 0" rpy="0 0 0"/>
            <mass value="1" />
            <inertia ixx="100" ixy="0" ixz="0" iyy="100" iyz="0" izz="100" />
        </inertial>
        <visual>
            <origin xyz="0.7003459992493148 0 0" rpy="0 0 0"/>
            <geometry>
                <box size="1.4006919984986297 2.615054309663757 1.7160068965253683" />
            </geometry>
            <material name="Blue">
                <color rgba="0 1.0 1.0 1.0"/>
            </material>
        </visual>
        <collision>
            <origin xyz="0.7003459992493148 0 0" rpy="0 0 0"/>
            <geometry>
                <box size="1.4006919984986297 2.615054309663757 1.7160068965253683" />
            </geometry>
        </collision>
    </link>
    <joint name="Torso_Leg1" type="revolute">
       <parent link="Torso"/>
       <child  link="Leg1"/>
       <origin rpy="0 0 0" xyz="1.4192731924698634 0 0.8681697785189159" />
     <axis xyz="1 0 0"/>
       <limit effort="0.0" lower="-3.14159" upper="3.14159" velocity="0.0"/>
    </joint>
    <joint name="Leg1_Leg2" type="revolute">
       <parent link="Leg1"/>
       <child  link="Leg2"/>
       <origin rpy="0 0 0" xyz="1.2346357790363047 0 0" />
     <axis xyz="1 0 0"/>
       <limit effort="0.0" lower="-3.14159" upper="3.14159" velocity="0.0"/>
    </joint>
    <joint name="Leg2_Leg3" type="revolute">
       <parent link="Leg2"/>
       <child  link="Leg3"/>
       <origin rpy="0 0 0" xyz="0 1.2861635397076443 0" />
     <axis xyz="1 0 0"/>
       <limit effort="0.0" lower="-3.14159" upper="3.14159" velocity="0.0"/>
    </joint>
    <joint name="Leg2_Leg4" type="revolute">
       <parent link="Leg2"/>
       <child  link="Leg4"/>
       <origin rpy="0 0 0" xyz="0.7079028884765912 1.2861635397076443 0" />
     <axis xyz="1 0 0"/>
       <limit effort="0.0" lower="-3.14159" upper="3.14159" velocity="0.0"/>
    </joint>
    <joint name="Leg4_Leg5" type="revolute">
       <parent link="Leg4"/>
       <child  link="Leg5"/>
       <origin rpy="0 0 0" xyz="2.8132463763936606 0 0" />
     <axis xyz="1 0 0"/>
       <limit effort="0.0" lower="-3.14159" upper="3.14159" velocity="0.0"/>
    </joint>
    <joint name="Leg5_Leg6" type="revolute">
       <parent link="Leg5"/>
       <child  link="Leg6"/>
       <origin rpy="0 0 0" xyz="0 0 2.368082283381321" />
     <axis xyz="1 0 0"/>
       <limit effort="0.0" lower="-3.14159" upper="3.14159" velocity="0.0"/>
    </joint>
    <joint name="Leg1_Leg7" type="revolute">
       <parent link="Leg1"/>
       <child  link="Leg7"/>
       <origin rpy="0 0 0" xyz="1.2346357790363047 0 1.2098811027918595" />
     <axis xyz="1 0 0"/>
       <limit effort="0.0" lower="-3.14159" upper="3.14159" velocity="0.0"/>
    </joint>
    <joint name="Leg5_Leg8" type="revolute">
       <parent link="Leg5"/>
       <child  link="Leg8"/>
       <origin rpy="0 0 0" xyz="0 1.0440221939915135 2.368082283381321" />
     <axis xyz="1 0 0"/>
       <limit effort="0.0" lower="-3.14159" upper="3.14159" velocity="0.0"/>
    </joint>
    <joint name="Leg2_Leg9" type="revolute">
       <parent link="Leg2"/>
       <child  link="Leg9"/>
       <origin rpy="0 0 0" xyz="0.7079028884765912 1.2861635397076443 1.1622010108696754" />
     <axis xyz="1 0 0"/>
       <limit effort="0.0" lower="-3.14159" upper="3.14159" velocity="0.0"/>
    </joint>
    <joint name="Torso_Leg10" type="revolute">
       <parent link="Torso"/>
       <child  link="Leg10"/>
       <origin rpy="0 0 0" xyz="1.1143813858682796 0 1.4413251046604953" />
     <axis xyz="1 0 0"/>
       <limit effort="0.0" lower="-3.14159" upper="3.14159" velocity="0.0"/>
    </joint>
    <joint name="Leg10_Leg11" type="revolute">
       <parent link="Leg10"/>
       <child  link="Leg11"/>
       <origin rpy="0 0 0" xyz="1.7183136805296824 0 0" />
     <axis xyz="1 0 0"/>
       <limit effort="0.0" lower="-3.14159" upper="3.14159" velocity="0.0"/>
    </joint>
    <joint name="Leg6_Leg12" type="revolute">
       <parent link="Leg6"/>
       <child  link="Leg12"/>
       <origin rpy="0 0 0" xyz="0 1.1591880493453073 1.1544535005549694" />
     <axis xyz="1 0 0"/>
       <limit effort="0.0" lower="-3.14159" upper="3.14159" velocity="0.0"/>
    </joint>
    <joint name="Leg11_Leg13" type="revolute">
       <parent link="Leg11"/>
       <child  link="Leg13"/>
       <origin rpy="0 0 0" xyz="0.9483324750749472 1.4676575338931834 0" />
     <axis xyz="1 0 0"/>
       <limit effort="0.0" lower="-3.14159" upper="3.14159" velocity="0.0"/>
    </joint>
    <joint name="Torso_Leg14" type="revolute">
       <parent link="Torso"/>
       <child  link="Leg14"/>
       <origin rpy="0 0 0" xyz="1.1143813858682796 0.5116425813033384 1.4413251046604953" />
     <axis xyz="1 0 0"/>
       <limit effort="0.0" lower="-3.14159" upper="3.14159" velocity="0.0"/>
    </joint>
    <joint name="Leg9_Leg15" type="revolute">
       <parent link="Leg9"/>
       <child  link="Leg15"/>
       <origin rpy="0 0 0" xyz="0 0 2.344772718092395" />
     <axis xyz="1 0 0"/>
       <limit effort="0.0" lower="-3.14159" upper="3.14159" velocity="0.0"/>
    </joint>
    <joint name="Leg12_Leg16" type="revolute">
       <parent link="Leg12"/>
       <child  link="Leg16"/>
       <origin rpy="0 0 0" xyz="0.532816399744533 0 0.7563656983508692" />
     <axis xyz="1 0 0"/>
       <limit effort="0.0" lower="-3.14159" upper="3.14159" velocity="0.0"/>
    </joint>
    <joint name="Leg15_Leg17" type="revolute">
       <parent link="Leg15"/>
       <child  link="Leg17"/>
       <origin rpy="0 0 0" xyz="0 0 2.2121791166653235" />
     <axis xyz="1 0 0"/>
       <limit effort="0.0" lower="-3.14159" upper="3.14159" velocity="0.0"/>
    </joint>
    <joint name="Leg8_Leg18" type="revolute">
       <parent link="Leg8"/>
       <child  link="Leg18"/>
       <origin rpy="0 0 0" xyz="0 0.7793711888858361 1.3224766242719455" />
     <axis xyz="1 0 0"/>
       <limit effort="0.0" lower="-3.14159" upper="3.14159" velocity="0.0"/>
    </joint>
    <joint name="Leg13_Leg19" type="revolute">
       <parent link="Leg13"/>
       <child  link="Leg19"/>
       <origin rpy="0 0 0" xyz="0 2.797339372762836 0" />
     <axis xyz="1 0 0"/>
       <limit effort="0.0" lower="-3.14159" upper="3.14159" velocity="0.0"/>
    </joint>
    <joint name="Leg19_Leg20" type="revolute">
       <parent link="Leg19"/>
       <child  link="Leg20"/>
       <origin rpy="0 0 0" xyz="0 2.9408538356035483 0" />
     <axis xyz="1 0 0"/>
       <limit effort="0.0" lower="-3.14159" upper="3.14159" velocity="0.0"/>
    </joint>
    <joint name="Leg18_Leg21" type="revolute">
       <parent link="Leg18"/>
       <child  link="Leg21"/>
       <origin rpy="0 0 0" xyz="0.5180097891382782 0.8178621102358816 0" />
     <axis xyz="1 0 0"/>
       <limit effort="0.0" lower="-3.14159" upper="3.14159" velocity="0.0"/>
    </joint>
    <joint name="Leg20_Leg22" type="revolute">
       <parent link="Leg20"/>
       <child  link="Leg22"/>
       <origin rpy="0 0 0" xyz="2.6008968394872767 0 0" />
     <axis xyz="1 0 0"/>
       <limit effort="0.0" lower="-3.14159" upper="3.14159" velocity="0.0"/>
    </joint>
    <joint name="Leg22_Leg23" type="revolute">
       <parent link="Leg22"/>
       <child  link="Leg23"/>
       <origin rpy="0 0 0" xyz="0 1.2241140010365037 0" />
     <axis xyz="1 0 0"/>
       <limit effort="0.0" lower="-3.14159" upper="3.14159" velocity="0.0"/>
    </joint>
    <joint name="Leg23_Leg24" type="revolute">
       <parent link="Leg23"/>
       <child  link="Leg24"/>
       <origin rpy="0 0 0" xyz="0 2.908111344791076 0" />
     <axis xyz="1 0 0"/>
       <limit effort="0.0" lower="-3.14159" upper="3.14159" velocity="0.0"/>
    </joint>
    <joint name="Leg19_Leg25" type="revolute">
       <parent link="Leg19"/>
       <child  link="Leg25"/>
       <origin rpy="0 0 0" xyz="0.9939900003169773 2.9408538356035483 0" />
     <axis xyz="1 0 0"/>
       <limit effort="0.0" lower="-3.14159" upper="3.14159" velocity="0.0"/>
    </joint>
</robot>