<robot name = "robot">
    <link name="Torso">
        <inertial>
            <origin xyz="0 0 0.5749343907998673" rpy="0 0 0"/>
            <mass value="1" />
            <inertia ixx="100" ixy="0" ixz="0" iyy="100" iyz="0" izz="100" />
        </inertial>
        <visual>
            <origin xyz="0 0 0.5749343907998673" rpy="0 0 0"/>
            <geometry>
                <box size="1.0225025069591491 1.4703138518228425 1.1498687815997346" />
            </geometry>
            <material name="Green">
                <color rgba="0 180.0 0.0 1.0"/>
            </material>
        </visual>
        <collision>
            <origin xyz="0 0 0.5749343907998673" rpy="0 0 0"/>
            <geometry>
                <box size="1.0225025069591491 1.4703138518228425 1.1498687815997346" />
            </geometry>
        </collision>
    </link>
    <link name="Leg1">
        <inertial>
            <origin xyz="0 1.4548583707806988 0" rpy="0 0 0"/>
            <mass value="1" />
            <inertia ixx="100" ixy="0" ixz="0" iyy="100" iyz="0" izz="100" />
        </inertial>
        <visual>
            <origin xyz="0 1.4548583707806988 0" rpy="0 0 0"/>
            <geometry>
                <box size="1.2420469272374763 2.9097167415613976 2.329948182115378" />
            </geometry>
            <material name="Blue">
                <color rgba="0 1.0 1.0 1.0"/>
            </material>
        </visual>
        <collision>
            <origin xyz="0 1.4548583707806988 0" rpy="0 0 0"/>
            <geometry>
                <box size="1.2420469272374763 2.9097167415613976 2.329948182115378" />
            </geometry>
        </collision>
    </link>
    <link name="Leg2">
        <inertial>
            <origin xyz="0 1.2024151264902847 0" rpy="0 0 0"/>
            <mass value="1" />
            <inertia ixx="100" ixy="0" ixz="0" iyy="100" iyz="0" izz="100" />
        </inertial>
        <visual>
            <origin xyz="0 1.2024151264902847 0" rpy="0 0 0"/>
            <geometry>
                <box size="1.4745949610679483 2.4048302529805694 2.0733961026362957" />
            </geometry>
            <material name="Green">
                <color rgba="0 180.0 0.0 1.0"/>
            </material>
        </visual>
        <collision>
            <origin xyz="0 1.2024151264902847 0" rpy="0 0 0"/>
            <geometry>
                <box size="1.4745949610679483 2.4048302529805694 2.0733961026362957" />
            </geometry>
        </collision>
    </link>
    <link name="Leg3">
        <inertial>
            <origin xyz="0 0.6443709989049334 0" rpy="0 0 0"/>
            <mass value="1" />
            <inertia ixx="100" ixy="0" ixz="0" iyy="100" iyz="0" izz="100" />
        </inertial>
        <visual>
            <origin xyz="0 0.6443709989049334 0" rpy="0 0 0"/>
            <geometry>
                <box size="2.21025534010671 1.2887419978098669 1.7296810469876984" />
            </geometry>
            <material name="Green">
                <color rgba="0 180.0 0.0 1.0"/>
            </material>
        </visual>
        <collision>
            <origin xyz="0 0.6443709989049334 0" rpy="0 0 0"/>
            <geometry>
                <box size="2.21025534010671 1.2887419978098669 1.7296810469876984" />
            </geometry>
        </collision>
    </link>
    <link name="Leg4">
        <inertial>
            <origin xyz="0 0.6342463054663575 0" rpy="0 0 0"/>
            <mass value="1" />
            <inertia ixx="100" ixy="0" ixz="0" iyy="100" iyz="0" izz="100" />
        </inertial>
        <visual>
            <origin xyz="0 0.6342463054663575 0" rpy="0 0 0"/>
            <geometry>
                <box size="1.2635485672579425 1.268492610932715 2.3019108566450095" />
            </geometry>
            <material name="Green">
                <color rgba="0 180.0 0.0 1.0"/>
            </material>
        </visual>
        <collision>
            <origin xyz="0 0.6342463054663575 0" rpy="0 0 0"/>
            <geometry>
                <box size="1.2635485672579425 1.268492610932715 2.3019108566450095" />
            </geometry>
        </collision>
    </link>
    <link name="Leg5">
        <inertial>
            <origin xyz="0 1.358518046632342 0" rpy="0 0 0"/>
            <mass value="1" />
            <inertia ixx="100" ixy="0" ixz="0" iyy="100" iyz="0" izz="100" />
        </inertial>
        <visual>
            <origin xyz="0 1.358518046632342 0" rpy="0 0 0"/>
            <geometry>
                <box size="1.1795770109141965 2.717036093264684 1.960553424745082" />
            </geometry>
            <material name="Green">
                <color rgba="0 180.0 0.0 1.0"/>
            </material>
        </visual>
        <collision>
            <origin xyz="0 1.358518046632342 0" rpy="0 0 0"/>
            <geometry>
                <box size="1.1795770109141965 2.717036093264684 1.960553424745082" />
            </geometry>
        </collision>
    </link>
    <link name="Leg6">
        <inertial>
            <origin xyz="0.5820916141012911 0 0" rpy="0 0 0"/>
            <mass value="1" />
            <inertia ixx="100" ixy="0" ixz="0" iyy="100" iyz="0" izz="100" />
        </inertial>
        <visual>
            <origin xyz="0.5820916141012911 0 0" rpy="0 0 0"/>
            <geometry>
                <box size="1.1641832282025821 1.9920688032140315 2.932767520407932" />
            </geometry>
            <material name="Green">
                <color rgba="0 180.0 0.0 1.0"/>
            </material>
        </visual>
        <collision>
            <origin xyz="0.5820916141012911 0 0" rpy="0 0 0"/>
            <geometry>
                <box size="1.1641832282025821 1.9920688032140315 2.932767520407932" />
            </geometry>
        </collision>
    </link>
    <link name="Leg7">
        <inertial>
            <origin xyz="0 0 1.4243847187017094" rpy="0 0 0"/>
            <mass value="1" />
            <inertia ixx="100" ixy="0" ixz="0" iyy="100" iyz="0" izz="100" />
        </inertial>
        <visual>
            <origin xyz="0 0 1.4243847187017094" rpy="0 0 0"/>
            <geometry>
                <box size="2.776009772769855 2.8033265807707153 2.8487694374034187" />
            </geometry>
            <material name="Blue">
                <color rgba="0 1.0 1.0 1.0"/>
            </material>
        </visual>
        <collision>
            <origin xyz="0 0 1.4243847187017094" rpy="0 0 0"/>
            <geometry>
                <box size="2.776009772769855 2.8033265807707153 2.8487694374034187" />
            </geometry>
        </collision>
    </link>
    <link name="Leg8">
        <inertial>
            <origin xyz="0 0 0.6373123041349464" rpy="0 0 0"/>
            <mass value="1" />
            <inertia ixx="100" ixy="0" ixz="0" iyy="100" iyz="0" izz="100" />
        </inertial>
        <visual>
            <origin xyz="0 0 0.6373123041349464" rpy="0 0 0"/>
            <geometry>
                <box size="1.7053651901717115 1.3150204572114519 1.2746246082698929" />
            </geometry>
            <material name="Green">
                <color rgba="0 180.0 0.0 1.0"/>
            </material>
        </visual>
        <collision>
            <origin xyz="0 0 0.6373123041349464" rpy="0 0 0"/>
            <geometry>
                <box size="1.7053651901717115 1.3150204572114519 1.2746246082698929" />
            </geometry>
        </collision>
    </link>
    <link name="Leg9">
        <inertial>
            <origin xyz="0 0.9225630947627153 0" rpy="0 0 0"/>
            <mass value="1" />
            <inertia ixx="100" ixy="0" ixz="0" iyy="100" iyz="0" izz="100" />
        </inertial>
        <visual>
            <origin xyz="0 0.9225630947627153 0" rpy="0 0 0"/>
            <geometry>
                <box size="1.2739649128217319 1.8451261895254305 1.0644415796397408" />
            </geometry>
            <material name="Blue">
                <color rgba="0 1.0 1.0 1.0"/>
            </material>
        </visual>
        <collision>
            <origin xyz="0 0.9225630947627153 0" rpy="0 0 0"/>
            <geometry>
                <box size="1.2739649128217319 1.8451261895254305 1.0644415796397408" />
            </geometry>
        </collision>
    </link>
    <link name="Leg10">
        <inertial>
            <origin xyz="0 0 1.4538670620528686" rpy="0 0 0"/>
            <mass value="1" />
            <inertia ixx="100" ixy="0" ixz="0" iyy="100" iyz="0" izz="100" />
        </inertial>
        <visual>
            <origin xyz="0 0 1.4538670620528686" rpy="0 0 0"/>
            <geometry>
                <box size="1.3599938524855497 2.3818836285929343 2.9077341241057373" />
            </geometry>
            <material name="Blue">
                <color rgba="0 1.0 1.0 1.0"/>
            </material>
        </visual>
        <collision>
            <origin xyz="0 0 1.4538670620528686" rpy="0 0 0"/>
            <geometry>
                <box size="1.3599938524855497 2.3818836285929343 2.9077341241057373" />
            </geometry>
        </collision>
    </link>
    <link name="Leg11">
        <inertial>
            <origin xyz="0 0.7043686370093907 0" rpy="0 0 0"/>
            <mass value="1" />
            <inertia ixx="100" ixy="0" ixz="0" iyy="100" iyz="0" izz="100" />
        </inertial>
        <visual>
            <origin xyz="0 0.7043686370093907 0" rpy="0 0 0"/>
            <geometry>
                <box size="2.1384603666090722 1.4087372740187813 1.2969719330267175" />
            </geometry>
            <material name="Blue">
                <color rgba="0 1.0 1.0 1.0"/>
            </material>
        </visual>
        <collision>
            <origin xyz="0 0.7043686370093907 0" rpy="0 0 0"/>
            <geometry>
                <box size="2.1384603666090722 1.4087372740187813 1.2969719330267175" />
            </geometry>
        </collision>
    </link>
    <link name="Leg12">
        <inertial>
            <origin xyz="0 0.7894213926765927 0" rpy="0 0 0"/>
            <mass value="1" />
            <inertia ixx="100" ixy="0" ixz="0" iyy="100" iyz="0" izz="100" />
        </inertial>
        <visual>
            <origin xyz="0 0.7894213926765927 0" rpy="0 0 0"/>
            <geometry>
                <box size="2.2207064839204125 1.5788427853531855 2.270974333523644" />
            </geometry>
            <material name="Green">
                <color rgba="0 180.0 0.0 1.0"/>
            </material>
        </visual>
        <collision>
            <origin xyz="0 0.7894213926765927 0" rpy="0 0 0"/>
            <geometry>
                <box size="2.2207064839204125 1.5788427853531855 2.270974333523644" />
            </geometry>
        </collision>
    </link>
    <link name="Leg13">
        <inertial>
            <origin xyz="0 0 1.240580014380416" rpy="0 0 0"/>
            <mass value="1" />
            <inertia ixx="100" ixy="0" ixz="0" iyy="100" iyz="0" izz="100" />
        </inertial>
        <visual>
            <origin xyz="0 0 1.240580014380416" rpy="0 0 0"/>
            <geometry>
                <box size="2.6760513822861975 2.487958186404855 2.481160028760832" />
            </geometry>
            <material name="Green">
                <color rgba="0 180.0 0.0 1.0"/>
            </material>
        </visual>
        <collision>
            <origin xyz="0 0 1.240580014380416" rpy="0 0 0"/>
            <geometry>
                <box size="2.6760513822861975 2.487958186404855 2.481160028760832" />
            </geometry>
        </collision>
    </link>
    <link name="Leg14">
        <inertial>
            <origin xyz="1.0838871776143855 0 0" rpy="0 0 0"/>
            <mass value="1" />
            <inertia ixx="100" ixy="0" ixz="0" iyy="100" iyz="0" izz="100" />
        </inertial>
        <visual>
            <origin xyz="1.0838871776143855 0 0" rpy="0 0 0"/>
            <geometry>
                <box size="2.167774355228771 2.6325181434085803 2.042026605521879" />
            </geometry>
            <material name="Blue">
                <color rgba="0 1.0 1.0 1.0"/>
            </material>
        </visual>
        <collision>
            <origin xyz="1.0838871776143855 0 0" rpy="0 0 0"/>
            <geometry>
                <box size="2.167774355228771 2.6325181434085803 2.042026605521879" />
            </geometry>
        </collision>
    </link>
    <link name="Leg15">
        <inertial>
            <origin xyz="0 0 0.556302287196921" rpy="0 0 0"/>
            <mass value="1" />
            <inertia ixx="100" ixy="0" ixz="0" iyy="100" iyz="0" izz="100" />
        </inertial>
        <visual>
            <origin xyz="0 0 0.556302287196921" rpy="0 0 0"/>
            <geometry>
                <box size="2.8515835130313083 2.9055887479064495 1.112604574393842" />
            </geometry>
            <material name="Green">
                <color rgba="0 180.0 0.0 1.0"/>
            </material>
        </visual>
        <collision>
            <origin xyz="0 0 0.556302287196921" rpy="0 0 0"/>
            <geometry>
                <box size="2.8515835130313083 2.9055887479064495 1.112604574393842" />
            </geometry>
        </collision>
    </link>
    <link name="Leg16">
        <inertial>
            <origin xyz="0.9334525276103671 0 0" rpy="0 0 0"/>
            <mass value="1" />
            <inertia ixx="100" ixy="0" ixz="0" iyy="100" iyz="0" izz="100" />
        </inertial>
        <visual>
            <origin xyz="0.9334525276103671 0 0" rpy="0 0 0"/>
            <geometry>
                <box size="1.8669050552207342 2.7309659783924225 2.6613317272377564" />
            </geometry>
            <material name="Blue">
                <color rgba="0 1.0 1.0 1.0"/>
            </material>
        </visual>
        <collision>
            <origin xyz="0.9334525276103671 0 0" rpy="0 0 0"/>
            <geometry>
                <box size="1.8669050552207342 2.7309659783924225 2.6613317272377564" />
            </geometry>
        </collision>
    </link>
    <link name="Leg17">
        <inertial>
            <origin xyz="0.7852920530114793 0 0" rpy="0 0 0"/>
            <mass value="1" />
            <inertia ixx="100" ixy="0" ixz="0" iyy="100" iyz="0" izz="100" />
        </inertial>
        <visual>
            <origin xyz="0.7852920530114793 0 0" rpy="0 0 0"/>
            <geometry>
                <box size="1.5705841060229586 2.5292118975033846 2.5814001140798553" />
            </geometry>
            <material name="Blue">
                <color rgba="0 1.0 1.0 1.0"/>
            </material>
        </visual>
        <collision>
            <origin xyz="0.7852920530114793 0 0" rpy="0 0 0"/>
            <geometry>
                <box size="1.5705841060229586 2.5292118975033846 2.5814001140798553" />
            </geometry>
        </collision>
    </link>
    <link name="Leg18">
        <inertial>
            <origin xyz="0 1.4097935046945957 0" rpy="0 0 0"/>
            <mass value="1" />
            <inertia ixx="100" ixy="0" ixz="0" iyy="100" iyz="0" izz="100" />
        </inertial>
        <visual>
            <origin xyz="0 1.4097935046945957 0" rpy="0 0 0"/>
            <geometry>
                <box size="1.9105422635342102 2.8195870093891915 2.9697159024133044" />
            </geometry>
            <material name="Blue">
                <color rgba="0 1.0 1.0 1.0"/>
            </material>
        </visual>
        <collision>
            <origin xyz="0 1.4097935046945957 0" rpy="0 0 0"/>
            <geometry>
                <box size="1.9105422635342102 2.8195870093891915 2.9697159024133044" />
            </geometry>
        </collision>
    </link>
    <link name="Leg19">
        <inertial>
            <origin xyz="0 0 0.6824238578553851" rpy="0 0 0"/>
            <mass value="1" />
            <inertia ixx="100" ixy="0" ixz="0" iyy="100" iyz="0" izz="100" />
        </inertial>
        <visual>
            <origin xyz="0 0 0.6824238578553851" rpy="0 0 0"/>
            <geometry>
                <box size="1.948427442623306 1.5793098770398788 1.3648477157107701" />
            </geometry>
            <material name="Blue">
                <color rgba="0 1.0 1.0 1.0"/>
            </material>
        </visual>
        <collision>
            <origin xyz="0 0 0.6824238578553851" rpy="0 0 0"/>
            <geometry>
                <box size="1.948427442623306 1.5793098770398788 1.3648477157107701" />
            </geometry>
        </collision>
    </link>
    <link name="Leg20">
        <inertial>
            <origin xyz="0 0 1.4986282724212634" rpy="0 0 0"/>
            <mass value="1" />
            <inertia ixx="100" ixy="0" ixz="0" iyy="100" iyz="0" izz="100" />
        </inertial>
        <visual>
            <origin xyz="0 0 1.4986282724212634" rpy="0 0 0"/>
            <geometry>
                <box size="2.9033469984346016 1.1837973255153276 2.997256544842527" />
            </geometry>
            <material name="Green">
                <color rgba="0 180.0 0.0 1.0"/>
            </material>
        </visual>
        <collision>
            <origin xyz="0 0 1.4986282724212634" rpy="0 0 0"/>
            <geometry>
                <box size="2.9033469984346016 1.1837973255153276 2.997256544842527" />
            </geometry>
        </collision>
    </link>
    <link name="Leg21">
        <inertial>
            <origin xyz="0.5955881876232652 0 0" rpy="0 0 0"/>
            <mass value="1" />
            <inertia ixx="100" ixy="0" ixz="0" iyy="100" iyz="0" izz="100" />
        </inertial>
        <visual>
            <origin xyz="0.5955881876232652 0 0" rpy="0 0 0"/>
            <geometry>
                <box size="1.1911763752465303 1.1819132741538236 1.1380632369945682" />
            </geometry>
            <material name="Green">
                <color rgba="0 180.0 0.0 1.0"/>
            </material>
        </visual>
        <collision>
            <origin xyz="0.5955881876232652 0 0" rpy="0 0 0"/>
            <geometry>
                <box size="1.1911763752465303 1.1819132741538236 1.1380632369945682" />
            </geometry>
        </collision>
    </link>
    <link name="Leg22">
        <inertial>
            <origin xyz="0 0 0.667637816576949" rpy="0 0 0"/>
            <mass value="1" />
            <inertia ixx="100" ixy="0" ixz="0" iyy="100" iyz="0" izz="100" />
        </inertial>
        <visual>
            <origin xyz="0 0 0.667637816576949" rpy="0 0 0"/>
            <geometry>
                <box size="1.1088230257783964 1.4280159888742772 1.335275633153898" />
            </geometry>
            <material name="Blue">
                <color rgba="0 1.0 1.0 1.0"/>
            </material>
        </visual>
        <collision>
            <origin xyz="0 0 0.667637816576949" rpy="0 0 0"/>
            <geometry>
                <box size="1.1088230257783964 1.4280159888742772 1.335275633153898" />
            </geometry>
        </collision>
    </link>
    <link name="Leg23">
        <inertial>
            <origin xyz="1.207847990731283 0 0" rpy="0 0 0"/>
            <mass value="1" />
            <inertia ixx="100" ixy="0" ixz="0" iyy="100" iyz="0" izz="100" />
        </inertial>
        <visual>
            <origin xyz="1.207847990731283 0 0" rpy="0 0 0"/>
            <geometry>
                <box size="2.415695981462566 2.192666852260372 1.287362579423507" />
            </geometry>
            <material name="Green">
                <color rgba="0 180.0 0.0 1.0"/>
            </material>
        </visual>
        <collision>
            <origin xyz="1.207847990731283 0 0" rpy="0 0 0"/>
            <geometry>
                <box size="2.415695981462566 2.192666852260372 1.287362579423507" />
            </geometry>
        </collision>
    </link>
    <link name="Leg24">
        <inertial>
            <origin xyz="0 0 1.097531497937382" rpy="0 0 0"/>
            <mass value="1" />
            <inertia ixx="100" ixy="0" ixz="0" iyy="100" iyz="0" izz="100" />
        </inertial>
        <visual>
            <origin xyz="0 0 1.097531497937382" rpy="0 0 0"/>
            <geometry>
                <box size="1.7573211681518661 1.5780151325290825 2.195062995874764" />
            </geometry>
            <material name="Blue">
                <color rgba="0 1.0 1.0 1.0"/>
            </material>
        </visual>
        <collision>
            <origin xyz="0 0 1.097531497937382" rpy="0 0 0"/>
            <geometry>
                <box size="1.7573211681518661 1.5780151325290825 2.195062995874764" />
            </geometry>
        </collision>
    </link>
    <link name="Leg25">
        <inertial>
            <origin xyz="0 1.0643275117431452 0" rpy="0 0 0"/>
            <mass value="1" />
            <inertia ixx="100" ixy="0" ixz="0" iyy="100" iyz="0" izz="100" />
        </inertial>
        <visual>
            <origin xyz="0 1.0643275117431452 0" rpy="0 0 0"/>
            <geometry>
                <box size="1.2970737107134196 2.1286550234862904 2.3695427248784435" />
            </geometry>
            <material name="Blue">
                <color rgba="0 1.0 1.0 1.0"/>
            </material>
        </visual>
        <collision>
            <origin xyz="0 1.0643275117431452 0" rpy="0 0 0"/>
            <geometry>
                <box size="1.2970737107134196 2.1286550234862904 2.3695427248784435" />
            </geometry>
        </collision>
    </link>
    <joint name="Torso_Leg1" type="revolute">
       <parent link="Torso"/>
       <child  link="Leg1"/>
       <origin rpy="0 0 0" xyz="0 0.7351569259114212 0.5749343907998673" />
     <axis xyz="1 0 0"/>
       <limit effort="0.0" lower="-3.14159" upper="3.14159" velocity="0.0"/>
    </joint>
    <joint name="Leg1_Leg2" type="revolute">
       <parent link="Leg1"/>
       <child  link="Leg2"/>
       <origin rpy="0 0 0" xyz="0 2.4048302529805694 0" />
     <axis xyz="1 0 0"/>
       <limit effort="0.0" lower="-3.14159" upper="3.14159" velocity="0.0"/>
    </joint>
    <joint name="Leg2_Leg3" type="revolute">
       <parent link="Leg2"/>
       <child  link="Leg3"/>
       <origin rpy="0 0 0" xyz="0 1.2887419978098669 0" />
     <axis xyz="1 0 0"/>
       <limit effort="0.0" lower="-3.14159" upper="3.14159" velocity="0.0"/>
    </joint>
    <joint name="Leg3_Leg4" type="revolute">
       <parent link="Leg3"/>
       <child  link="Leg4"/>
       <origin rpy="0 0 0" xyz="0 1.268492610932715 0" />
     <axis xyz="1 0 0"/>
       <limit effort="0.0" lower="-3.14159" upper="3.14159" velocity="0.0"/>
    </joint>
    <joint name="Leg4_Leg5" type="revolute">
       <parent link="Leg4"/>
       <child  link="Leg5"/>
       <origin rpy="0 0 0" xyz="0 2.717036093264684 0" />
     <axis xyz="1 0 0"/>
       <limit effort="0.0" lower="-3.14159" upper="3.14159" velocity="0.0"/>
    </joint>
    <joint name="Leg1_Leg6" type="revolute">
       <parent link="Leg1"/>
       <child  link="Leg6"/>
       <origin rpy="0 0 0" xyz="0.7372974805339741 2.4048302529805694 0" />
     <axis xyz="1 0 0"/>
       <limit effort="0.0" lower="-3.14159" upper="3.14159" velocity="0.0"/>
    </joint>
    <joint name="Leg2_Leg7" type="revolute">
       <parent link="Leg2"/>
       <child  link="Leg7"/>
       <origin rpy="0 0 0" xyz="0 1.2887419978098669 0.8648405234938492" />
     <axis xyz="1 0 0"/>
       <limit effort="0.0" lower="-3.14159" upper="3.14159" velocity="0.0"/>
    </joint>
    <joint name="Leg6_Leg8" type="revolute">
       <parent link="Leg6"/>
       <child  link="Leg8"/>
       <origin rpy="0 0 0" xyz="0 0 2.8487694374034187" />
     <axis xyz="1 0 0"/>
       <limit effort="0.0" lower="-3.14159" upper="3.14159" velocity="0.0"/>
    </joint>
    <joint name="Leg6_Leg9" type="revolute">
       <parent link="Leg6"/>
       <child  link="Leg9"/>
       <origin rpy="0 0 0" xyz="0 1.4016632903853576 2.8487694374034187" />
     <axis xyz="1 0 0"/>
       <limit effort="0.0" lower="-3.14159" upper="3.14159" velocity="0.0"/>
    </joint>
    <joint name="Leg3_Leg10" type="revolute">
       <parent link="Leg3"/>
       <child  link="Leg10"/>
       <origin rpy="0 0 0" xyz="0 1.268492610932715 1.1509554283225047" />
     <axis xyz="1 0 0"/>
       <limit effort="0.0" lower="-3.14159" upper="3.14159" velocity="0.0"/>
    </joint>
    <joint name="Leg10_Leg11" type="revolute">
       <parent link="Leg10"/>
       <child  link="Leg11"/>
       <origin rpy="0 0 0" xyz="0 1.4087372740187813 0" />
     <axis xyz="1 0 0"/>
       <limit effort="0.0" lower="-3.14159" upper="3.14159" velocity="0.0"/>
    </joint>
    <joint name="Leg5_Leg12" type="revolute">
       <parent link="Leg5"/>
       <child  link="Leg12"/>
       <origin rpy="0 0 0" xyz="0.5820916141012911 0.9960344016070157 0" />
     <axis xyz="1 0 0"/>
       <limit effort="0.0" lower="-3.14159" upper="3.14159" velocity="0.0"/>
    </joint>
    <joint name="Leg7_Leg13" type="revolute">
       <parent link="Leg7"/>
       <child  link="Leg13"/>
       <origin rpy="0 0 0" xyz="0 0 1.2746246082698929" />
     <axis xyz="1 0 0"/>
       <limit effort="0.0" lower="-3.14159" upper="3.14159" velocity="0.0"/>
    </joint>
    <joint name="Leg9_Leg14" type="revolute">
       <parent link="Leg9"/>
       <child  link="Leg14"/>
       <origin rpy="0 0 0" xyz="0.6799969262427749 0 1.4538670620528686" />
     <axis xyz="1 0 0"/>
       <limit effort="0.0" lower="-3.14159" upper="3.14159" velocity="0.0"/>
    </joint>
    <joint name="Leg8_Leg15" type="revolute">
       <parent link="Leg8"/>
       <child  link="Leg15"/>
       <origin rpy="0 0 0" xyz="0 0.9225630947627153 0.5322207898198704" />
     <axis xyz="1 0 0"/>
       <limit effort="0.0" lower="-3.14159" upper="3.14159" velocity="0.0"/>
    </joint>
    <joint name="Torso_Leg16" type="revolute">
       <parent link="Torso"/>
       <child  link="Leg16"/>
       <origin rpy="0 0 0" xyz="0.6210234636187382 1.4548583707806988 0" />
     <axis xyz="1 0 0"/>
       <limit effort="0.0" lower="-3.14159" upper="3.14159" velocity="0.0"/>
    </joint>
    <joint name="Leg13_Leg17" type="revolute">
       <parent link="Leg13"/>
       <child  link="Leg17"/>
       <origin rpy="0 0 0" xyz="2.167774355228771 0 0" />
     <axis xyz="1 0 0"/>
       <limit effort="0.0" lower="-3.14159" upper="3.14159" velocity="0.0"/>
    </joint>
    <joint name="Leg16_Leg18" type="revolute">
       <parent link="Leg16"/>
       <child  link="Leg18"/>
       <origin rpy="0 0 0" xyz="0.7852920530114793 1.2646059487516923 0" />
     <axis xyz="1 0 0"/>
       <limit effort="0.0" lower="-3.14159" upper="3.14159" velocity="0.0"/>
    </joint>
    <joint name="Leg16_Leg19" type="revolute">
       <parent link="Leg16"/>
       <child  link="Leg19"/>
       <origin rpy="0 0 0" xyz="0.7852920530114793 1.2646059487516923 1.2907000570399276" />
     <axis xyz="1 0 0"/>
       <limit effort="0.0" lower="-3.14159" upper="3.14159" velocity="0.0"/>
    </joint>
    <joint name="Leg5_Leg20" type="revolute">
       <parent link="Leg5"/>
       <child  link="Leg20"/>
       <origin rpy="0 0 0" xyz="0.5820916141012911 0.9960344016070157 1.466383760203966" />
     <axis xyz="1 0 0"/>
       <limit effort="0.0" lower="-3.14159" upper="3.14159" velocity="0.0"/>
    </joint>
    <joint name="Leg19_Leg21" type="revolute">
       <parent link="Leg19"/>
       <child  link="Leg21"/>
       <origin rpy="0 0 0" xyz="1.4516734992173008 0 1.4986282724212634" />
     <axis xyz="1 0 0"/>
       <limit effort="0.0" lower="-3.14159" upper="3.14159" velocity="0.0"/>
    </joint>
    <joint name="Leg10_Leg22" type="revolute">
       <parent link="Leg10"/>
       <child  link="Leg22"/>
       <origin rpy="0 0 0" xyz="0 1.4087372740187813 0.6484859665133588" />
     <axis xyz="1 0 0"/>
       <limit effort="0.0" lower="-3.14159" upper="3.14159" velocity="0.0"/>
    </joint>
    <joint name="Leg10_Leg23" type="revolute">
       <parent link="Leg10"/>
       <child  link="Leg23"/>
       <origin rpy="0 0 0" xyz="1.0692301833045361 1.4087372740187813 0.6484859665133588" />
     <axis xyz="1 0 0"/>
       <limit effort="0.0" lower="-3.14159" upper="3.14159" velocity="0.0"/>
    </joint>
    <joint name="Leg23_Leg24" type="revolute">
       <parent link="Leg23"/>
       <child  link="Leg24"/>
       <origin rpy="0 0 0" xyz="0 0 2.195062995874764" />
     <axis xyz="1 0 0"/>
       <limit effort="0.0" lower="-3.14159" upper="3.14159" velocity="0.0"/>
    </joint>
    <joint name="Leg20_Leg25" type="revolute">
       <parent link="Leg20"/>
       <child  link="Leg25"/>
       <origin rpy="0 0 0" xyz="0.5955881876232652 0.5909566370769118 0" />
     <axis xyz="1 0 0"/>
       <limit effort="0.0" lower="-3.14159" upper="3.14159" velocity="0.0"/>
    </joint>
</robot>