<robot name = "robot">
    <link name="Torso">
        <inertial>
            <origin xyz="-6 4 3.0612213381815394" rpy="0 0 0"/>
            <mass value="1" />
            <inertia ixx="100" ixy="0" ixz="0" iyy="100" iyz="0" izz="100" />
        </inertial>
        <visual>
            <origin xyz="-6 4 3.0612213381815394" rpy="0 0 0"/>
            <geometry>
                <box size="5.687541153746738 2.07179629251687 2.0000403666160853" />
            </geometry>
            <material name="Blue">
                <color rgba="0 1.0 1.0 1.0"/>
            </material>
        </visual>
        <collision>
            <origin xyz="-6 4 3.0612213381815394" rpy="0 0 0"/>
            <geometry>
                <box size="5.687541153746738 2.07179629251687 2.0000403666160853" />
            </geometry>
        </collision>
    </link>
    <link name="Leg1">
        <inertial>
            <origin xyz="0 0 -1.0306005774367484" rpy="0 0 0"/>
            <mass value="1" />
            <inertia ixx="100" ixy="0" ixz="0" iyy="100" iyz="0" izz="100" />
        </inertial>
        <visual>
            <origin xyz="0 0 -1.0306005774367484" rpy="0 0 0"/>
            <geometry>
                <box size="0.5253579484417539 1.4054785846503686 2.0612011548734968" />
            </geometry>
            <material name="Green">
                <color rgba="0 180.0 0.0 1.0"/>
            </material>
        </visual>
        <collision>
            <origin xyz="0 0 -1.0306005774367484" rpy="0 0 0"/>
            <geometry>
                <box size="0.5253579484417539 1.4054785846503686 2.0612011548734968" />
            </geometry>
        </collision>
    </link>
    <link name="Leg2">
        <inertial>
            <origin xyz="0 0 -1.0306005774367484" rpy="0 0 0"/>
            <mass value="1" />
            <inertia ixx="100" ixy="0" ixz="0" iyy="100" iyz="0" izz="100" />
        </inertial>
        <visual>
            <origin xyz="0 0 -1.0306005774367484" rpy="0 0 0"/>
            <geometry>
                <box size="0.5253579484417539 1.4054785846503686 2.0612011548734968" />
            </geometry>
            <material name="Green">
                <color rgba="0 180.0 0.0 1.0"/>
            </material>
        </visual>
        <collision>
            <origin xyz="0 0 -1.0306005774367484" rpy="0 0 0"/>
            <geometry>
                <box size="0.5253579484417539 1.4054785846503686 2.0612011548734968" />
            </geometry>
        </collision>
    </link>
    <link name="Leg3">
        <inertial>
            <origin xyz="0 0 -1.0306005774367484" rpy="0 0 0"/>
            <mass value="1" />
            <inertia ixx="100" ixy="0" ixz="0" iyy="100" iyz="0" izz="100" />
        </inertial>
        <visual>
            <origin xyz="0 0 -1.0306005774367484" rpy="0 0 0"/>
            <geometry>
                <box size="0.5253579484417539 1.4054785846503686 2.0612011548734968" />
            </geometry>
            <material name="Blue">
                <color rgba="0 1.0 1.0 1.0"/>
            </material>
        </visual>
        <collision>
            <origin xyz="0 0 -1.0306005774367484" rpy="0 0 0"/>
            <geometry>
                <box size="0.5253579484417539 1.4054785846503686 2.0612011548734968" />
            </geometry>
        </collision>
    </link>
    <link name="Leg4">
        <inertial>
            <origin xyz="0 0 -1.0306005774367484" rpy="0 0 0"/>
            <mass value="1" />
            <inertia ixx="100" ixy="0" ixz="0" iyy="100" iyz="0" izz="100" />
        </inertial>
        <visual>
            <origin xyz="0 0 -1.0306005774367484" rpy="0 0 0"/>
            <geometry>
                <box size="0.5253579484417539 1.4054785846503686 2.0612011548734968" />
            </geometry>
            <material name="Green">
                <color rgba="0 180.0 0.0 1.0"/>
            </material>
        </visual>
        <collision>
            <origin xyz="0 0 -1.0306005774367484" rpy="0 0 0"/>
            <geometry>
                <box size="0.5253579484417539 1.4054785846503686 2.0612011548734968" />
            </geometry>
        </collision>
    </link>
    <link name="Head">
        <inertial>
            <origin xyz="1.6449627401200102 0 1.1125843244445077" rpy="0 0 0"/>
            <mass value="1" />
            <inertia ixx="100" ixy="0" ixz="0" iyy="100" iyz="0" izz="100" />
        </inertial>
        <visual>
            <origin xyz="1.6449627401200102 0 1.1125843244445077" rpy="0 0 0"/>
            <geometry>
                <box size="3.2899254802400204 2.354891068357137 2.2251686488890154" />
            </geometry>
            <material name="Blue">
                <color rgba="0 1.0 1.0 1.0"/>
            </material>
        </visual>
        <collision>
            <origin xyz="1.6449627401200102 0 1.1125843244445077" rpy="0 0 0"/>
            <geometry>
                <box size="3.2899254802400204 2.354891068357137 2.2251686488890154" />
            </geometry>
        </collision>
    </link>
    <joint name="Torso_Leg1" type="revolute">
       <parent link="Torso"/>
       <child  link="Leg1"/>
       <origin rpy="0 0 0" xyz="-8.84377057687337 5.035898146258435 2.0612011548734968" />
     <axis xyz="1 0 0"/>
       <limit effort="0.0" lower="-3.14159" upper="3.14159" velocity="0.0"/>
    </joint>
    <joint name="Torso_Leg2" type="revolute">
       <parent link="Torso"/>
       <child  link="Leg2"/>
       <origin rpy="0 0 0" xyz="-3.156229423126631 5.035898146258435 2.0612011548734968" />
     <axis xyz="1 0 0"/>
       <limit effort="0.0" lower="-3.14159" upper="3.14159" velocity="0.0"/>
    </joint>
    <joint name="Torso_Leg3" type="revolute">
       <parent link="Torso"/>
       <child  link="Leg3"/>
       <origin rpy="0 0 0" xyz="-8.84377057687337 2.964101853741565 2.0612011548734968" />
     <axis xyz="1 0 0"/>
       <limit effort="0.0" lower="-3.14159" upper="3.14159" velocity="0.0"/>
    </joint>
    <joint name="Torso_Leg4" type="revolute">
       <parent link="Torso"/>
       <child  link="Leg4"/>
       <origin rpy="0 0 0" xyz="-3.156229423126631 2.964101853741565 2.0612011548734968" />
     <axis xyz="1 0 0"/>
       <limit effort="0.0" lower="-3.14159" upper="3.14159" velocity="0.0"/>
    </joint>
    <joint name="Torso_Head" type="revolute">
       <parent link="Torso"/>
       <child  link="Head"/>
       <origin rpy="0 0 0" xyz="-3.156229423126631 4 4.061241521489582" />
     <axis xyz="1 0 0"/>
       <limit effort="0.0" lower="-3.14159" upper="3.14159" velocity="0.0"/>
    </joint>
</robot>