<robot name = "robot">
    <link name="Torso">
        <inertial>
            <origin xyz="0 0 1.2118620775112408" rpy="0 0 0"/>
            <mass value="1" />
            <inertia ixx="100" ixy="0" ixz="0" iyy="100" iyz="0" izz="100" />
        </inertial>
        <visual>
            <origin xyz="0 0 1.2118620775112408" rpy="0 0 0"/>
            <geometry>
                <box size="2.232101141737041 2.794620133135356 2.4237241550224815" />
            </geometry>
            <material name="Green">
                <color rgba="0 180.0 0.0 1.0"/>
            </material>
        </visual>
        <collision>
            <origin xyz="0 0 1.2118620775112408" rpy="0 0 0"/>
            <geometry>
                <box size="2.232101141737041 2.794620133135356 2.4237241550224815" />
            </geometry>
        </collision>
    </link>
    <link name="Leg1">
        <inertial>
            <origin xyz="0 0 0.804138744459853" rpy="0 0 0"/>
            <mass value="1" />
            <inertia ixx="100" ixy="0" ixz="0" iyy="100" iyz="0" izz="100" />
        </inertial>
        <visual>
            <origin xyz="0 0 0.804138744459853" rpy="0 0 0"/>
            <geometry>
                <box size="2.842834708000547 2.985671399062482 1.608277488919706" />
            </geometry>
            <material name="Blue">
                <color rgba="0 1.0 1.0 1.0"/>
            </material>
        </visual>
        <collision>
            <origin xyz="0 0 0.804138744459853" rpy="0 0 0"/>
            <geometry>
                <box size="2.842834708000547 2.985671399062482 1.608277488919706" />
            </geometry>
        </collision>
    </link>
    <link name="Leg2">
        <inertial>
            <origin xyz="0 0.5224066017746505 0" rpy="0 0 0"/>
            <mass value="1" />
            <inertia ixx="100" ixy="0" ixz="0" iyy="100" iyz="0" izz="100" />
        </inertial>
        <visual>
            <origin xyz="0 0.5224066017746505 0" rpy="0 0 0"/>
            <geometry>
                <box size="2.4941121742753403 1.044813203549301 1.6921064950869953" />
            </geometry>
            <material name="Blue">
                <color rgba="0 1.0 1.0 1.0"/>
            </material>
        </visual>
        <collision>
            <origin xyz="0 0.5224066017746505 0" rpy="0 0 0"/>
            <geometry>
                <box size="2.4941121742753403 1.044813203549301 1.6921064950869953" />
            </geometry>
        </collision>
    </link>
    <link name="Leg3">
        <inertial>
            <origin xyz="0.6726350218786629 0 0" rpy="0 0 0"/>
            <mass value="1" />
            <inertia ixx="100" ixy="0" ixz="0" iyy="100" iyz="0" izz="100" />
        </inertial>
        <visual>
            <origin xyz="0.6726350218786629 0 0" rpy="0 0 0"/>
            <geometry>
                <box size="1.3452700437573257 1.9130447185408916 1.830430226839563" />
            </geometry>
            <material name="Blue">
                <color rgba="0 1.0 1.0 1.0"/>
            </material>
        </visual>
        <collision>
            <origin xyz="0.6726350218786629 0 0" rpy="0 0 0"/>
            <geometry>
                <box size="1.3452700437573257 1.9130447185408916 1.830430226839563" />
            </geometry>
        </collision>
    </link>
    <link name="Leg4">
        <inertial>
            <origin xyz="0 0 0.6149731084996687" rpy="0 0 0"/>
            <mass value="1" />
            <inertia ixx="100" ixy="0" ixz="0" iyy="100" iyz="0" izz="100" />
        </inertial>
        <visual>
            <origin xyz="0 0 0.6149731084996687" rpy="0 0 0"/>
            <geometry>
                <box size="2.8708033061537996 2.016264728511808 1.2299462169993374" />
            </geometry>
            <material name="Green">
                <color rgba="0 180.0 0.0 1.0"/>
            </material>
        </visual>
        <collision>
            <origin xyz="0 0 0.6149731084996687" rpy="0 0 0"/>
            <geometry>
                <box size="2.8708033061537996 2.016264728511808 1.2299462169993374" />
            </geometry>
        </collision>
    </link>
    <link name="Leg5">
        <inertial>
            <origin xyz="0 1.0612492527816986 0" rpy="0 0 0"/>
            <mass value="1" />
            <inertia ixx="100" ixy="0" ixz="0" iyy="100" iyz="0" izz="100" />
        </inertial>
        <visual>
            <origin xyz="0 1.0612492527816986 0" rpy="0 0 0"/>
            <geometry>
                <box size="1.777725603615495 2.122498505563397 2.5331939627044044" />
            </geometry>
            <material name="Green">
                <color rgba="0 180.0 0.0 1.0"/>
            </material>
        </visual>
        <collision>
            <origin xyz="0 1.0612492527816986 0" rpy="0 0 0"/>
            <geometry>
                <box size="1.777725603615495 2.122498505563397 2.5331939627044044" />
            </geometry>
        </collision>
    </link>
    <link name="Leg6">
        <inertial>
            <origin xyz="1.293210993060737 0 0" rpy="0 0 0"/>
            <mass value="1" />
            <inertia ixx="100" ixy="0" ixz="0" iyy="100" iyz="0" izz="100" />
        </inertial>
        <visual>
            <origin xyz="1.293210993060737 0 0" rpy="0 0 0"/>
            <geometry>
                <box size="2.586421986121474 2.0164939609518804 1.1186410328579222" />
            </geometry>
            <material name="Blue">
                <color rgba="0 1.0 1.0 1.0"/>
            </material>
        </visual>
        <collision>
            <origin xyz="1.293210993060737 0 0" rpy="0 0 0"/>
            <geometry>
                <box size="2.586421986121474 2.0164939609518804 1.1186410328579222" />
            </geometry>
        </collision>
    </link>
    <link name="Leg7">
        <inertial>
            <origin xyz="1.0977326491371984 0 0" rpy="0 0 0"/>
            <mass value="1" />
            <inertia ixx="100" ixy="0" ixz="0" iyy="100" iyz="0" izz="100" />
        </inertial>
        <visual>
            <origin xyz="1.0977326491371984 0 0" rpy="0 0 0"/>
            <geometry>
                <box size="2.1954652982743967 1.6666406395994648 1.1715537151848476" />
            </geometry>
            <material name="Green">
                <color rgba="0 180.0 0.0 1.0"/>
            </material>
        </visual>
        <collision>
            <origin xyz="1.0977326491371984 0 0" rpy="0 0 0"/>
            <geometry>
                <box size="2.1954652982743967 1.6666406395994648 1.1715537151848476" />
            </geometry>
        </collision>
    </link>
    <link name="Leg8">
        <inertial>
            <origin xyz="0 0 0.7060437310893665" rpy="0 0 0"/>
            <mass value="1" />
            <inertia ixx="100" ixy="0" ixz="0" iyy="100" iyz="0" izz="100" />
        </inertial>
        <visual>
            <origin xyz="0 0 0.7060437310893665" rpy="0 0 0"/>
            <geometry>
                <box size="2.443082220401832 2.185261781062516 1.412087462178733" />
            </geometry>
            <material name="Blue">
                <color rgba="0 1.0 1.0 1.0"/>
            </material>
        </visual>
        <collision>
            <origin xyz="0 0 0.7060437310893665" rpy="0 0 0"/>
            <geometry>
                <box size="2.443082220401832 2.185261781062516 1.412087462178733" />
            </geometry>
        </collision>
    </link>
    <link name="Leg9">
        <inertial>
            <origin xyz="0 1.2287531867766677 0" rpy="0 0 0"/>
            <mass value="1" />
            <inertia ixx="100" ixy="0" ixz="0" iyy="100" iyz="0" izz="100" />
        </inertial>
        <visual>
            <origin xyz="0 1.2287531867766677 0" rpy="0 0 0"/>
            <geometry>
                <box size="1.6582057910986705 2.4575063735533353 1.9422724306384087" />
            </geometry>
            <material name="Green">
                <color rgba="0 180.0 0.0 1.0"/>
            </material>
        </visual>
        <collision>
            <origin xyz="0 1.2287531867766677 0" rpy="0 0 0"/>
            <geometry>
                <box size="1.6582057910986705 2.4575063735533353 1.9422724306384087" />
            </geometry>
        </collision>
    </link>
    <link name="Leg10">
        <inertial>
            <origin xyz="0.7727697313881315 0 0" rpy="0 0 0"/>
            <mass value="1" />
            <inertia ixx="100" ixy="0" ixz="0" iyy="100" iyz="0" izz="100" />
        </inertial>
        <visual>
            <origin xyz="0.7727697313881315 0 0" rpy="0 0 0"/>
            <geometry>
                <box size="1.545539462776263 1.3955754646362362 1.0911694247284591" />
            </geometry>
            <material name="Green">
                <color rgba="0 180.0 0.0 1.0"/>
            </material>
        </visual>
        <collision>
            <origin xyz="0.7727697313881315 0 0" rpy="0 0 0"/>
            <geometry>
                <box size="1.545539462776263 1.3955754646362362 1.0911694247284591" />
            </geometry>
        </collision>
    </link>
    <link name="Leg11">
        <inertial>
            <origin xyz="0 0.6791237322593718 0" rpy="0 0 0"/>
            <mass value="1" />
            <inertia ixx="100" ixy="0" ixz="0" iyy="100" iyz="0" izz="100" />
        </inertial>
        <visual>
            <origin xyz="0 0.6791237322593718 0" rpy="0 0 0"/>
            <geometry>
                <box size="2.5948587542230555 1.3582474645187437 1.5902703082763023" />
            </geometry>
            <material name="Green">
                <color rgba="0 180.0 0.0 1.0"/>
            </material>
        </visual>
        <collision>
            <origin xyz="0 0.6791237322593718 0" rpy="0 0 0"/>
            <geometry>
                <box size="2.5948587542230555 1.3582474645187437 1.5902703082763023" />
            </geometry>
        </collision>
    </link>
    <link name="Leg12">
        <inertial>
            <origin xyz="0 0 0.9009787904086441" rpy="0 0 0"/>
            <mass value="1" />
            <inertia ixx="100" ixy="0" ixz="0" iyy="100" iyz="0" izz="100" />
        </inertial>
        <visual>
            <origin xyz="0 0 0.9009787904086441" rpy="0 0 0"/>
            <geometry>
                <box size="2.8741137309485376 2.3922366374366586 1.8019575808172883" />
            </geometry>
            <material name="Blue">
                <color rgba="0 1.0 1.0 1.0"/>
            </material>
        </visual>
        <collision>
            <origin xyz="0 0 0.9009787904086441" rpy="0 0 0"/>
            <geometry>
                <box size="2.8741137309485376 2.3922366374366586 1.8019575808172883" />
            </geometry>
        </collision>
    </link>
    <link name="Leg13">
        <inertial>
            <origin xyz="0 1.4906174838677466 0" rpy="0 0 0"/>
            <mass value="1" />
            <inertia ixx="100" ixy="0" ixz="0" iyy="100" iyz="0" izz="100" />
        </inertial>
        <visual>
            <origin xyz="0 1.4906174838677466 0" rpy="0 0 0"/>
            <geometry>
                <box size="1.8626417269832172 2.9812349677354932 1.6642294489251555" />
            </geometry>
            <material name="Blue">
                <color rgba="0 1.0 1.0 1.0"/>
            </material>
        </visual>
        <collision>
            <origin xyz="0 1.4906174838677466 0" rpy="0 0 0"/>
            <geometry>
                <box size="1.8626417269832172 2.9812349677354932 1.6642294489251555" />
            </geometry>
        </collision>
    </link>
    <link name="Leg14">
        <inertial>
            <origin xyz="0 0 1.181921211496028" rpy="0 0 0"/>
            <mass value="1" />
            <inertia ixx="100" ixy="0" ixz="0" iyy="100" iyz="0" izz="100" />
        </inertial>
        <visual>
            <origin xyz="0 0 1.181921211496028" rpy="0 0 0"/>
            <geometry>
                <box size="1.6046034961525035 2.3116102750327236 2.363842422992056" />
            </geometry>
            <material name="Blue">
                <color rgba="0 1.0 1.0 1.0"/>
            </material>
        </visual>
        <collision>
            <origin xyz="0 0 1.181921211496028" rpy="0 0 0"/>
            <geometry>
                <box size="1.6046034961525035 2.3116102750327236 2.363842422992056" />
            </geometry>
        </collision>
    </link>
    <link name="Leg15">
        <inertial>
            <origin xyz="0 0.6607784912973075 0" rpy="0 0 0"/>
            <mass value="1" />
            <inertia ixx="100" ixy="0" ixz="0" iyy="100" iyz="0" izz="100" />
        </inertial>
        <visual>
            <origin xyz="0 0.6607784912973075 0" rpy="0 0 0"/>
            <geometry>
                <box size="2.542239269351546 1.321556982594615 2.937020943465689" />
            </geometry>
            <material name="Green">
                <color rgba="0 180.0 0.0 1.0"/>
            </material>
        </visual>
        <collision>
            <origin xyz="0 0.6607784912973075 0" rpy="0 0 0"/>
            <geometry>
                <box size="2.542239269351546 1.321556982594615 2.937020943465689" />
            </geometry>
        </collision>
    </link>
    <link name="Leg16">
        <inertial>
            <origin xyz="1.461738072452889 0 0" rpy="0 0 0"/>
            <mass value="1" />
            <inertia ixx="100" ixy="0" ixz="0" iyy="100" iyz="0" izz="100" />
        </inertial>
        <visual>
            <origin xyz="1.461738072452889 0 0" rpy="0 0 0"/>
            <geometry>
                <box size="2.923476144905778 1.0238245503959635 2.3175719493100617" />
            </geometry>
            <material name="Blue">
                <color rgba="0 1.0 1.0 1.0"/>
            </material>
        </visual>
        <collision>
            <origin xyz="1.461738072452889 0 0" rpy="0 0 0"/>
            <geometry>
                <box size="2.923476144905778 1.0238245503959635 2.3175719493100617" />
            </geometry>
        </collision>
    </link>
    <link name="Leg17">
        <inertial>
            <origin xyz="0 1.4753620244781689 0" rpy="0 0 0"/>
            <mass value="1" />
            <inertia ixx="100" ixy="0" ixz="0" iyy="100" iyz="0" izz="100" />
        </inertial>
        <visual>
            <origin xyz="0 1.4753620244781689 0" rpy="0 0 0"/>
            <geometry>
                <box size="2.214060529445227 2.9507240489563378 1.4304003067924773" />
            </geometry>
            <material name="Green">
                <color rgba="0 180.0 0.0 1.0"/>
            </material>
        </visual>
        <collision>
            <origin xyz="0 1.4753620244781689 0" rpy="0 0 0"/>
            <geometry>
                <box size="2.214060529445227 2.9507240489563378 1.4304003067924773" />
            </geometry>
        </collision>
    </link>
    <link name="Leg18">
        <inertial>
            <origin xyz="0 0.6589594919112972 0" rpy="0 0 0"/>
            <mass value="1" />
            <inertia ixx="100" ixy="0" ixz="0" iyy="100" iyz="0" izz="100" />
        </inertial>
        <visual>
            <origin xyz="0 0.6589594919112972 0" rpy="0 0 0"/>
            <geometry>
                <box size="1.613352488999363 1.3179189838225944 2.6426270946689976" />
            </geometry>
            <material name="Blue">
                <color rgba="0 1.0 1.0 1.0"/>
            </material>
        </visual>
        <collision>
            <origin xyz="0 0.6589594919112972 0" rpy="0 0 0"/>
            <geometry>
                <box size="1.613352488999363 1.3179189838225944 2.6426270946689976" />
            </geometry>
        </collision>
    </link>
    <link name="Leg19">
        <inertial>
            <origin xyz="0 0 1.4380849232355513" rpy="0 0 0"/>
            <mass value="1" />
            <inertia ixx="100" ixy="0" ixz="0" iyy="100" iyz="0" izz="100" />
        </inertial>
        <visual>
            <origin xyz="0 0 1.4380849232355513" rpy="0 0 0"/>
            <geometry>
                <box size="1.3556189043656617 1.176889614270867 2.8761698464711025" />
            </geometry>
            <material name="Blue">
                <color rgba="0 1.0 1.0 1.0"/>
            </material>
        </visual>
        <collision>
            <origin xyz="0 0 1.4380849232355513" rpy="0 0 0"/>
            <geometry>
                <box size="1.3556189043656617 1.176889614270867 2.8761698464711025" />
            </geometry>
        </collision>
    </link>
    <link name="Leg20">
        <inertial>
            <origin xyz="0 0 1.2211925143944788" rpy="0 0 0"/>
            <mass value="1" />
            <inertia ixx="100" ixy="0" ixz="0" iyy="100" iyz="0" izz="100" />
        </inertial>
        <visual>
            <origin xyz="0 0 1.2211925143944788" rpy="0 0 0"/>
            <geometry>
                <box size="1.2412101724735392 2.3505245003589117 2.4423850287889577" />
            </geometry>
            <material name="Green">
                <color rgba="0 180.0 0.0 1.0"/>
            </material>
        </visual>
        <collision>
            <origin xyz="0 0 1.2211925143944788" rpy="0 0 0"/>
            <geometry>
                <box size="1.2412101724735392 2.3505245003589117 2.4423850287889577" />
            </geometry>
        </collision>
    </link>
    <link name="Leg21">
        <inertial>
            <origin xyz="0 0 1.1397422148849998" rpy="0 0 0"/>
            <mass value="1" />
            <inertia ixx="100" ixy="0" ixz="0" iyy="100" iyz="0" izz="100" />
        </inertial>
        <visual>
            <origin xyz="0 0 1.1397422148849998" rpy="0 0 0"/>
            <geometry>
                <box size="2.701124250649208 1.093764569417053 2.2794844297699997" />
            </geometry>
            <material name="Blue">
                <color rgba="0 1.0 1.0 1.0"/>
            </material>
        </visual>
        <collision>
            <origin xyz="0 0 1.1397422148849998" rpy="0 0 0"/>
            <geometry>
                <box size="2.701124250649208 1.093764569417053 2.2794844297699997" />
            </geometry>
        </collision>
    </link>
    <link name="Leg22">
        <inertial>
            <origin xyz="0 1.2493977567051229 0" rpy="0 0 0"/>
            <mass value="1" />
            <inertia ixx="100" ixy="0" ixz="0" iyy="100" iyz="0" izz="100" />
        </inertial>
        <visual>
            <origin xyz="0 1.2493977567051229 0" rpy="0 0 0"/>
            <geometry>
                <box size="2.5589217977238885 2.4987955134102457 1.4126409390254835" />
            </geometry>
            <material name="Blue">
                <color rgba="0 1.0 1.0 1.0"/>
            </material>
        </visual>
        <collision>
            <origin xyz="0 1.2493977567051229 0" rpy="0 0 0"/>
            <geometry>
                <box size="2.5589217977238885 2.4987955134102457 1.4126409390254835" />
            </geometry>
        </collision>
    </link>
    <link name="Leg23">
        <inertial>
            <origin xyz="0 0 0.9910228943918531" rpy="0 0 0"/>
            <mass value="1" />
            <inertia ixx="100" ixy="0" ixz="0" iyy="100" iyz="0" izz="100" />
        </inertial>
        <visual>
            <origin xyz="0 0 0.9910228943918531" rpy="0 0 0"/>
            <geometry>
                <box size="2.6279371172743238 2.425405314515415 1.9820457887837062" />
            </geometry>
            <material name="Green">
                <color rgba="0 180.0 0.0 1.0"/>
            </material>
        </visual>
        <collision>
            <origin xyz="0 0 0.9910228943918531" rpy="0 0 0"/>
            <geometry>
                <box size="2.6279371172743238 2.425405314515415 1.9820457887837062" />
            </geometry>
        </collision>
    </link>
    <link name="Leg24">
        <inertial>
            <origin xyz="0 0 1.1865168457544086" rpy="0 0 0"/>
            <mass value="1" />
            <inertia ixx="100" ixy="0" ixz="0" iyy="100" iyz="0" izz="100" />
        </inertial>
        <visual>
            <origin xyz="0 0 1.1865168457544086" rpy="0 0 0"/>
            <geometry>
                <box size="1.125234249605249 2.32739766747844 2.3730336915088173" />
            </geometry>
            <material name="Blue">
                <color rgba="0 1.0 1.0 1.0"/>
            </material>
        </visual>
        <collision>
            <origin xyz="0 0 1.1865168457544086" rpy="0 0 0"/>
            <geometry>
                <box size="1.125234249605249 2.32739766747844 2.3730336915088173" />
            </geometry>
        </collision>
    </link>
    <link name="Leg25">
        <inertial>
            <origin xyz="0 0.8066756420148171 0" rpy="0 0 0"/>
            <mass value="1" />
            <inertia ixx="100" ixy="0" ixz="0" iyy="100" iyz="0" izz="100" />
        </inertial>
        <visual>
            <origin xyz="0 0.8066756420148171 0" rpy="0 0 0"/>
            <geometry>
                <box size="2.897848474971023 1.6133512840296342 1.7041700274349" />
            </geometry>
            <material name="Green">
                <color rgba="0 180.0 0.0 1.0"/>
            </material>
        </visual>
        <collision>
            <origin xyz="0 0.8066756420148171 0" rpy="0 0 0"/>
            <geometry>
                <box size="2.897848474971023 1.6133512840296342 1.7041700274349" />
            </geometry>
        </collision>
    </link>
    <link name="Leg26">
        <inertial>
            <origin xyz="0 0.521725207914014 0" rpy="0 0 0"/>
            <mass value="1" />
            <inertia ixx="100" ixy="0" ixz="0" iyy="100" iyz="0" izz="100" />
        </inertial>
        <visual>
            <origin xyz="0 0.521725207914014 0" rpy="0 0 0"/>
            <geometry>
                <box size="2.440156129856398 1.043450415828028 2.5490105605707636" />
            </geometry>
            <material name="Blue">
                <color rgba="0 1.0 1.0 1.0"/>
            </material>
        </visual>
        <collision>
            <origin xyz="0 0.521725207914014 0" rpy="0 0 0"/>
            <geometry>
                <box size="2.440156129856398 1.043450415828028 2.5490105605707636" />
            </geometry>
        </collision>
    </link>
    <joint name="Torso_Leg1" type="revolute">
       <parent link="Torso"/>
       <child  link="Leg1"/>
       <origin rpy="0 0 0" xyz="0 0 2.4237241550224815" />
     <axis xyz="1 0 0"/>
       <limit effort="0.0" lower="-3.14159" upper="3.14159" velocity="0.0"/>
    </joint>
    <joint name="Torso_Leg2" type="revolute">
       <parent link="Torso"/>
       <child  link="Leg2"/>
       <origin rpy="0 0 0" xyz="0 1.492835699531241 0.804138744459853" />
     <axis xyz="1 0 0"/>
       <limit effort="0.0" lower="-3.14159" upper="3.14159" velocity="0.0"/>
    </joint>
    <joint name="Leg2_Leg3" type="revolute">
       <parent link="Leg2"/>
       <child  link="Leg3"/>
       <origin rpy="0 0 0" xyz="1.3452700437573257 0 0" />
     <axis xyz="1 0 0"/>
       <limit effort="0.0" lower="-3.14159" upper="3.14159" velocity="0.0"/>
    </joint>
    <joint name="Leg1_Leg4" type="revolute">
       <parent link="Leg1"/>
       <child  link="Leg4"/>
       <origin rpy="0 0 0" xyz="0 0.5224066017746505 0.8460532475434976" />
     <axis xyz="1 0 0"/>
       <limit effort="0.0" lower="-3.14159" upper="3.14159" velocity="0.0"/>
    </joint>
    <joint name="Leg3_Leg5" type="revolute">
       <parent link="Leg3"/>
       <child  link="Leg5"/>
       <origin rpy="0 0 0" xyz="0 1.008132364255904 0.6149731084996687" />
     <axis xyz="1 0 0"/>
       <limit effort="0.0" lower="-3.14159" upper="3.14159" velocity="0.0"/>
    </joint>
    <joint name="Leg3_Leg6" type="revolute">
       <parent link="Leg3"/>
       <child  link="Leg6"/>
       <origin rpy="0 0 0" xyz="1.4354016530768998 1.008132364255904 0.6149731084996687" />
     <axis xyz="1 0 0"/>
       <limit effort="0.0" lower="-3.14159" upper="3.14159" velocity="0.0"/>
    </joint>
    <joint name="Leg6_Leg7" type="revolute">
       <parent link="Leg6"/>
       <child  link="Leg7"/>
       <origin rpy="0 0 0" xyz="2.1954652982743967 0 0" />
     <axis xyz="1 0 0"/>
       <limit effort="0.0" lower="-3.14159" upper="3.14159" velocity="0.0"/>
    </joint>
    <joint name="Leg2_Leg8" type="revolute">
       <parent link="Leg2"/>
       <child  link="Leg8"/>
       <origin rpy="0 0 0" xyz="1.3452700437573257 0 0.9152151134197815" />
     <axis xyz="1 0 0"/>
       <limit effort="0.0" lower="-3.14159" upper="3.14159" velocity="0.0"/>
    </joint>
    <joint name="Leg2_Leg9" type="revolute">
       <parent link="Leg2"/>
       <child  link="Leg9"/>
       <origin rpy="0 0 0" xyz="1.3452700437573257 0.9565223592704458 0.9152151134197815" />
     <axis xyz="1 0 0"/>
       <limit effort="0.0" lower="-3.14159" upper="3.14159" velocity="0.0"/>
    </joint>
    <joint name="Leg8_Leg10" type="revolute">
       <parent link="Leg8"/>
       <child  link="Leg10"/>
       <origin rpy="0 0 0" xyz="0.8291028955493353 1.2287531867766677 0" />
     <axis xyz="1 0 0"/>
       <limit effort="0.0" lower="-3.14159" upper="3.14159" velocity="0.0"/>
    </joint>
    <joint name="Leg9_Leg11" type="revolute">
       <parent link="Leg9"/>
       <child  link="Leg11"/>
       <origin rpy="0 0 0" xyz="0.7727697313881315 0.6977877323181181 0" />
     <axis xyz="1 0 0"/>
       <limit effort="0.0" lower="-3.14159" upper="3.14159" velocity="0.0"/>
    </joint>
    <joint name="Leg5_Leg12" type="revolute">
       <parent link="Leg5"/>
       <child  link="Leg12"/>
       <origin rpy="0 0 0" xyz="1.293210993060737 0 0.5593205164289611" />
     <axis xyz="1 0 0"/>
       <limit effort="0.0" lower="-3.14159" upper="3.14159" velocity="0.0"/>
    </joint>
    <joint name="Leg6_Leg13" type="revolute">
       <parent link="Leg6"/>
       <child  link="Leg13"/>
       <origin rpy="0 0 0" xyz="2.1954652982743967 0.8333203197997324 0" />
     <axis xyz="1 0 0"/>
       <limit effort="0.0" lower="-3.14159" upper="3.14159" velocity="0.0"/>
    </joint>
    <joint name="Leg10_Leg14" type="revolute">
       <parent link="Leg10"/>
       <child  link="Leg14"/>
       <origin rpy="0 0 0" xyz="0 0.6791237322593718 0.7951351541381512" />
     <axis xyz="1 0 0"/>
       <limit effort="0.0" lower="-3.14159" upper="3.14159" velocity="0.0"/>
    </joint>
    <joint name="Leg5_Leg15" type="revolute">
       <parent link="Leg5"/>
       <child  link="Leg15"/>
       <origin rpy="0 0 0" xyz="1.293210993060737 1.0082469804759402 0.5593205164289611" />
     <axis xyz="1 0 0"/>
       <limit effort="0.0" lower="-3.14159" upper="3.14159" velocity="0.0"/>
    </joint>
    <joint name="Leg5_Leg16" type="revolute">
       <parent link="Leg5"/>
       <child  link="Leg16"/>
       <origin rpy="0 0 0" xyz="2.586421986121474 1.0082469804759402 0.5593205164289611" />
     <axis xyz="1 0 0"/>
       <limit effort="0.0" lower="-3.14159" upper="3.14159" velocity="0.0"/>
    </joint>
    <joint name="Leg11_Leg17" type="revolute">
       <parent link="Leg11"/>
       <child  link="Leg17"/>
       <origin rpy="0 0 0" xyz="0 1.1961183187183293 0.9009787904086441" />
     <axis xyz="1 0 0"/>
       <limit effort="0.0" lower="-3.14159" upper="3.14159" velocity="0.0"/>
    </joint>
    <joint name="Leg12_Leg18" type="revolute">
       <parent link="Leg12"/>
       <child  link="Leg18"/>
       <origin rpy="0 0 0" xyz="0 2.9812349677354932 0" />
     <axis xyz="1 0 0"/>
       <limit effort="0.0" lower="-3.14159" upper="3.14159" velocity="0.0"/>
    </joint>
    <joint name="Leg6_Leg19" type="revolute">
       <parent link="Leg6"/>
       <child  link="Leg19"/>
       <origin rpy="0 0 0" xyz="2.1954652982743967 0.8333203197997324 0.5857768575924238" />
     <axis xyz="1 0 0"/>
       <limit effort="0.0" lower="-3.14159" upper="3.14159" velocity="0.0"/>
    </joint>
    <joint name="Leg4_Leg20" type="revolute">
       <parent link="Leg4"/>
       <child  link="Leg20"/>
       <origin rpy="0 0 0" xyz="0 1.0612492527816986 1.2665969813522022" />
     <axis xyz="1 0 0"/>
       <limit effort="0.0" lower="-3.14159" upper="3.14159" velocity="0.0"/>
    </joint>
    <joint name="Leg13_Leg21" type="revolute">
       <parent link="Leg13"/>
       <child  link="Leg21"/>
       <origin rpy="0 0 0" xyz="0 0 2.363842422992056" />
     <axis xyz="1 0 0"/>
       <limit effort="0.0" lower="-3.14159" upper="3.14159" velocity="0.0"/>
    </joint>
    <joint name="Leg14_Leg22" type="revolute">
       <parent link="Leg14"/>
       <child  link="Leg22"/>
       <origin rpy="0 0 0" xyz="0 1.321556982594615 0" />
     <axis xyz="1 0 0"/>
       <limit effort="0.0" lower="-3.14159" upper="3.14159" velocity="0.0"/>
    </joint>
    <joint name="Leg18_Leg23" type="revolute">
       <parent link="Leg18"/>
       <child  link="Leg23"/>
       <origin rpy="0 0 0" xyz="0 0 2.8761698464711025" />
     <axis xyz="1 0 0"/>
       <limit effort="0.0" lower="-3.14159" upper="3.14159" velocity="0.0"/>
    </joint>
    <joint name="Leg16_Leg24" type="revolute">
       <parent link="Leg16"/>
       <child  link="Leg24"/>
       <origin rpy="0 0 0" xyz="0 1.4753620244781689 0.7152001533962387" />
     <axis xyz="1 0 0"/>
       <limit effort="0.0" lower="-3.14159" upper="3.14159" velocity="0.0"/>
    </joint>
    <joint name="Leg10_Leg25" type="revolute">
       <parent link="Leg10"/>
       <child  link="Leg25"/>
       <origin rpy="0 0 0" xyz="0 1.3582474645187437 0.7951351541381512" />
     <axis xyz="1 0 0"/>
       <limit effort="0.0" lower="-3.14159" upper="3.14159" velocity="0.0"/>
    </joint>
    <joint name="Leg22_Leg26" type="revolute">
       <parent link="Leg22"/>
       <child  link="Leg26"/>
       <origin rpy="0 0 0" xyz="0 1.2127026572577075 0.9910228943918531" />
     <axis xyz="1 0 0"/>
       <limit effort="0.0" lower="-3.14159" upper="3.14159" velocity="0.0"/>
    </joint>
</robot>