<robot name = "robot">
    <link name="Torso">
        <inertial>
            <origin xyz="0 0 1.386358181190721" rpy="0 0 0"/>
            <mass value="1" />
            <inertia ixx="100" ixy="0" ixz="0" iyy="100" iyz="0" izz="100" />
        </inertial>
        <visual>
            <origin xyz="0 0 1.386358181190721" rpy="0 0 0"/>
            <geometry>
                <box size="2.613590263032647 1.1941826815916543 2.772716362381442" />
            </geometry>
            <material name="Green">
                <color rgba="0 180.0 0.0 1.0"/>
            </material>
        </visual>
        <collision>
            <origin xyz="0 0 1.386358181190721" rpy="0 0 0"/>
            <geometry>
                <box size="2.613590263032647 1.1941826815916543 2.772716362381442" />
            </geometry>
        </collision>
    </link>
    <link name="Leg1">
        <inertial>
            <origin xyz="0 0.7538193701245725 0" rpy="0 0 0"/>
            <mass value="1" />
            <inertia ixx="100" ixy="0" ixz="0" iyy="100" iyz="0" izz="100" />
        </inertial>
        <visual>
            <origin xyz="0 0.7538193701245725 0" rpy="0 0 0"/>
            <geometry>
                <box size="1.9076357730634406 1.507638740249145 1.194561321651021" />
            </geometry>
            <material name="Blue">
                <color rgba="0 1.0 1.0 1.0"/>
            </material>
        </visual>
        <collision>
            <origin xyz="0 0.7538193701245725 0" rpy="0 0 0"/>
            <geometry>
                <box size="1.9076357730634406 1.507638740249145 1.194561321651021" />
            </geometry>
        </collision>
    </link>
    <link name="Leg2">
        <inertial>
            <origin xyz="0 0.9287960534589296 0" rpy="0 0 0"/>
            <mass value="1" />
            <inertia ixx="100" ixy="0" ixz="0" iyy="100" iyz="0" izz="100" />
        </inertial>
        <visual>
            <origin xyz="0 0.9287960534589296 0" rpy="0 0 0"/>
            <geometry>
                <box size="2.8145731357580166 1.8575921069178591 1.3202618809661113" />
            </geometry>
            <material name="Blue">
                <color rgba="0 1.0 1.0 1.0"/>
            </material>
        </visual>
        <collision>
            <origin xyz="0 0.9287960534589296 0" rpy="0 0 0"/>
            <geometry>
                <box size="2.8145731357580166 1.8575921069178591 1.3202618809661113" />
            </geometry>
        </collision>
    </link>
    <link name="Leg3">
        <inertial>
            <origin xyz="0 0 1.135472833051308" rpy="0 0 0"/>
            <mass value="1" />
            <inertia ixx="100" ixy="0" ixz="0" iyy="100" iyz="0" izz="100" />
        </inertial>
        <visual>
            <origin xyz="0 0 1.135472833051308" rpy="0 0 0"/>
            <geometry>
                <box size="2.9734234300195377 2.369337564700735 2.270945666102616" />
            </geometry>
            <material name="Blue">
                <color rgba="0 1.0 1.0 1.0"/>
            </material>
        </visual>
        <collision>
            <origin xyz="0 0 1.135472833051308" rpy="0 0 0"/>
            <geometry>
                <box size="2.9734234300195377 2.369337564700735 2.270945666102616" />
            </geometry>
        </collision>
    </link>
    <link name="Leg4">
        <inertial>
            <origin xyz="0.599378955164942 0 0" rpy="0 0 0"/>
            <mass value="1" />
            <inertia ixx="100" ixy="0" ixz="0" iyy="100" iyz="0" izz="100" />
        </inertial>
        <visual>
            <origin xyz="0.599378955164942 0 0" rpy="0 0 0"/>
            <geometry>
                <box size="1.198757910329884 1.599156051459817 1.5121304059490042" />
            </geometry>
            <material name="Blue">
                <color rgba="0 1.0 1.0 1.0"/>
            </material>
        </visual>
        <collision>
            <origin xyz="0.599378955164942 0 0" rpy="0 0 0"/>
            <geometry>
                <box size="1.198757910329884 1.599156051459817 1.5121304059490042" />
            </geometry>
        </collision>
    </link>
    <link name="Leg5">
        <inertial>
            <origin xyz="0 0 0.5538838249884852" rpy="0 0 0"/>
            <mass value="1" />
            <inertia ixx="100" ixy="0" ixz="0" iyy="100" iyz="0" izz="100" />
        </inertial>
        <visual>
            <origin xyz="0 0 0.5538838249884852" rpy="0 0 0"/>
            <geometry>
                <box size="2.105265403522893 2.6804610528971367 1.1077676499769704" />
            </geometry>
            <material name="Green">
                <color rgba="0 180.0 0.0 1.0"/>
            </material>
        </visual>
        <collision>
            <origin xyz="0 0 0.5538838249884852" rpy="0 0 0"/>
            <geometry>
                <box size="2.105265403522893 2.6804610528971367 1.1077676499769704" />
            </geometry>
        </collision>
    </link>
    <link name="Leg6">
        <inertial>
            <origin xyz="0.8046897827151258 0 0" rpy="0 0 0"/>
            <mass value="1" />
            <inertia ixx="100" ixy="0" ixz="0" iyy="100" iyz="0" izz="100" />
        </inertial>
        <visual>
            <origin xyz="0.8046897827151258 0 0" rpy="0 0 0"/>
            <geometry>
                <box size="1.6093795654302516 1.282399688005198 1.8015855771526657" />
            </geometry>
            <material name="Blue">
                <color rgba="0 1.0 1.0 1.0"/>
            </material>
        </visual>
        <collision>
            <origin xyz="0.8046897827151258 0 0" rpy="0 0 0"/>
            <geometry>
                <box size="1.6093795654302516 1.282399688005198 1.8015855771526657" />
            </geometry>
        </collision>
    </link>
    <link name="Leg7">
        <inertial>
            <origin xyz="1.4802247178020695 0 0" rpy="0 0 0"/>
            <mass value="1" />
            <inertia ixx="100" ixy="0" ixz="0" iyy="100" iyz="0" izz="100" />
        </inertial>
        <visual>
            <origin xyz="1.4802247178020695 0 0" rpy="0 0 0"/>
            <geometry>
                <box size="2.960449435604139 2.2507663454049416 1.8578421019498883" />
            </geometry>
            <material name="Blue">
                <color rgba="0 1.0 1.0 1.0"/>
            </material>
        </visual>
        <collision>
            <origin xyz="1.4802247178020695 0 0" rpy="0 0 0"/>
            <geometry>
                <box size="2.960449435604139 2.2507663454049416 1.8578421019498883" />
            </geometry>
        </collision>
    </link>
    <link name="Leg8">
        <inertial>
            <origin xyz="0 0.6003334582784408 0" rpy="0 0 0"/>
            <mass value="1" />
            <inertia ixx="100" ixy="0" ixz="0" iyy="100" iyz="0" izz="100" />
        </inertial>
        <visual>
            <origin xyz="0 0.6003334582784408 0" rpy="0 0 0"/>
            <geometry>
                <box size="1.3322374126125587 1.2006669165568815 1.4083459987924207" />
            </geometry>
            <material name="Green">
                <color rgba="0 180.0 0.0 1.0"/>
            </material>
        </visual>
        <collision>
            <origin xyz="0 0.6003334582784408 0" rpy="0 0 0"/>
            <geometry>
                <box size="1.3322374126125587 1.2006669165568815 1.4083459987924207" />
            </geometry>
        </collision>
    </link>
    <link name="Leg9">
        <inertial>
            <origin xyz="0 1.2650037897170034 0" rpy="0 0 0"/>
            <mass value="1" />
            <inertia ixx="100" ixy="0" ixz="0" iyy="100" iyz="0" izz="100" />
        </inertial>
        <visual>
            <origin xyz="0 1.2650037897170034 0" rpy="0 0 0"/>
            <geometry>
                <box size="1.9632521463611001 2.530007579434007 2.5356862483748692" />
            </geometry>
            <material name="Blue">
                <color rgba="0 1.0 1.0 1.0"/>
            </material>
        </visual>
        <collision>
            <origin xyz="0 1.2650037897170034 0" rpy="0 0 0"/>
            <geometry>
                <box size="1.9632521463611001 2.530007579434007 2.5356862483748692" />
            </geometry>
        </collision>
    </link>
    <link name="Leg10">
        <inertial>
            <origin xyz="1.479934377193716 0 0" rpy="0 0 0"/>
            <mass value="1" />
            <inertia ixx="100" ixy="0" ixz="0" iyy="100" iyz="0" izz="100" />
        </inertial>
        <visual>
            <origin xyz="1.479934377193716 0 0" rpy="0 0 0"/>
            <geometry>
                <box size="2.959868754387432 1.1853612488758691 1.161658883085127" />
            </geometry>
            <material name="Blue">
                <color rgba="0 1.0 1.0 1.0"/>
            </material>
        </visual>
        <collision>
            <origin xyz="1.479934377193716 0 0" rpy="0 0 0"/>
            <geometry>
                <box size="2.959868754387432 1.1853612488758691 1.161658883085127" />
            </geometry>
        </collision>
    </link>
    <link name="Leg11">
        <inertial>
            <origin xyz="0.9289599656147911 0 0" rpy="0 0 0"/>
            <mass value="1" />
            <inertia ixx="100" ixy="0" ixz="0" iyy="100" iyz="0" izz="100" />
        </inertial>
        <visual>
            <origin xyz="0.9289599656147911 0 0" rpy="0 0 0"/>
            <geometry>
                <box size="1.8579199312295822 1.5592399125273702 1.850522024005624" />
            </geometry>
            <material name="Blue">
                <color rgba="0 1.0 1.0 1.0"/>
            </material>
        </visual>
        <collision>
            <origin xyz="0.9289599656147911 0 0" rpy="0 0 0"/>
            <geometry>
                <box size="1.8579199312295822 1.5592399125273702 1.850522024005624" />
            </geometry>
        </collision>
    </link>
    <link name="Leg12">
        <inertial>
            <origin xyz="0 0.6591157536561476 0" rpy="0 0 0"/>
            <mass value="1" />
            <inertia ixx="100" ixy="0" ixz="0" iyy="100" iyz="0" izz="100" />
        </inertial>
        <visual>
            <origin xyz="0 0.6591157536561476 0" rpy="0 0 0"/>
            <geometry>
                <box size="2.9207733837453453 1.3182315073122952 1.5099695562133333" />
            </geometry>
            <material name="Blue">
                <color rgba="0 1.0 1.0 1.0"/>
            </material>
        </visual>
        <collision>
            <origin xyz="0 0.6591157536561476 0" rpy="0 0 0"/>
            <geometry>
                <box size="2.9207733837453453 1.3182315073122952 1.5099695562133333" />
            </geometry>
        </collision>
    </link>
    <link name="Leg13">
        <inertial>
            <origin xyz="0.7959475548513887 0 0" rpy="0 0 0"/>
            <mass value="1" />
            <inertia ixx="100" ixy="0" ixz="0" iyy="100" iyz="0" izz="100" />
        </inertial>
        <visual>
            <origin xyz="0.7959475548513887 0 0" rpy="0 0 0"/>
            <geometry>
                <box size="1.5918951097027774 1.6637780779124778 1.7358264776405066" />
            </geometry>
            <material name="Blue">
                <color rgba="0 1.0 1.0 1.0"/>
            </material>
        </visual>
        <collision>
            <origin xyz="0.7959475548513887 0 0" rpy="0 0 0"/>
            <geometry>
                <box size="1.5918951097027774 1.6637780779124778 1.7358264776405066" />
            </geometry>
        </collision>
    </link>
    <link name="Leg14">
        <inertial>
            <origin xyz="0 0 0.6235266460143053" rpy="0 0 0"/>
            <mass value="1" />
            <inertia ixx="100" ixy="0" ixz="0" iyy="100" iyz="0" izz="100" />
        </inertial>
        <visual>
            <origin xyz="0 0 0.6235266460143053" rpy="0 0 0"/>
            <geometry>
                <box size="1.3359419910807633 1.8512123942957048 1.2470532920286106" />
            </geometry>
            <material name="Green">
                <color rgba="0 180.0 0.0 1.0"/>
            </material>
        </visual>
        <collision>
            <origin xyz="0 0 0.6235266460143053" rpy="0 0 0"/>
            <geometry>
                <box size="1.3359419910807633 1.8512123942957048 1.2470532920286106" />
            </geometry>
        </collision>
    </link>
    <link name="Leg15">
        <inertial>
            <origin xyz="0 0.6872102997362528 0" rpy="0 0 0"/>
            <mass value="1" />
            <inertia ixx="100" ixy="0" ixz="0" iyy="100" iyz="0" izz="100" />
        </inertial>
        <visual>
            <origin xyz="0 0.6872102997362528 0" rpy="0 0 0"/>
            <geometry>
                <box size="2.472619973218696 1.3744205994725056 1.0255186337941955" />
            </geometry>
            <material name="Green">
                <color rgba="0 180.0 0.0 1.0"/>
            </material>
        </visual>
        <collision>
            <origin xyz="0 0.6872102997362528 0" rpy="0 0 0"/>
            <geometry>
                <box size="2.472619973218696 1.3744205994725056 1.0255186337941955" />
            </geometry>
        </collision>
    </link>
    <link name="Leg16">
        <inertial>
            <origin xyz="1.148558960963995 0 0" rpy="0 0 0"/>
            <mass value="1" />
            <inertia ixx="100" ixy="0" ixz="0" iyy="100" iyz="0" izz="100" />
        </inertial>
        <visual>
            <origin xyz="1.148558960963995 0 0" rpy="0 0 0"/>
            <geometry>
                <box size="2.29711792192799 1.968654189153841 1.7566375055880943" />
            </geometry>
            <material name="Green">
                <color rgba="0 180.0 0.0 1.0"/>
            </material>
        </visual>
        <collision>
            <origin xyz="1.148558960963995 0 0" rpy="0 0 0"/>
            <geometry>
                <box size="2.29711792192799 1.968654189153841 1.7566375055880943" />
            </geometry>
        </collision>
    </link>
    <link name="Leg17">
        <inertial>
            <origin xyz="0.8451371646657863 0 0" rpy="0 0 0"/>
            <mass value="1" />
            <inertia ixx="100" ixy="0" ixz="0" iyy="100" iyz="0" izz="100" />
        </inertial>
        <visual>
            <origin xyz="0.8451371646657863 0 0" rpy="0 0 0"/>
            <geometry>
                <box size="1.6902743293315725 2.5607840159039057 2.0425872309349975" />
            </geometry>
            <material name="Green">
                <color rgba="0 180.0 0.0 1.0"/>
            </material>
        </visual>
        <collision>
            <origin xyz="0.8451371646657863 0 0" rpy="0 0 0"/>
            <geometry>
                <box size="1.6902743293315725 2.5607840159039057 2.0425872309349975" />
            </geometry>
        </collision>
    </link>
    <link name="Leg18">
        <inertial>
            <origin xyz="0.5000242332872644 0 0" rpy="0 0 0"/>
            <mass value="1" />
            <inertia ixx="100" ixy="0" ixz="0" iyy="100" iyz="0" izz="100" />
        </inertial>
        <visual>
            <origin xyz="0.5000242332872644 0 0" rpy="0 0 0"/>
            <geometry>
                <box size="1.0000484665745288 1.7222369705397085 2.1988552734817977" />
            </geometry>
            <material name="Green">
                <color rgba="0 180.0 0.0 1.0"/>
            </material>
        </visual>
        <collision>
            <origin xyz="0.5000242332872644 0 0" rpy="0 0 0"/>
            <geometry>
                <box size="1.0000484665745288 1.7222369705397085 2.1988552734817977" />
            </geometry>
        </collision>
    </link>
    <link name="Leg19">
        <inertial>
            <origin xyz="1.1581993571844187 0 0" rpy="0 0 0"/>
            <mass value="1" />
            <inertia ixx="100" ixy="0" ixz="0" iyy="100" iyz="0" izz="100" />
        </inertial>
        <visual>
            <origin xyz="1.1581993571844187 0 0" rpy="0 0 0"/>
            <geometry>
                <box size="2.3163987143688374 1.3643477814652234 2.1211405035537005" />
            </geometry>
            <material name="Blue">
                <color rgba="0 1.0 1.0 1.0"/>
            </material>
        </visual>
        <collision>
            <origin xyz="1.1581993571844187 0 0" rpy="0 0 0"/>
            <geometry>
                <box size="2.3163987143688374 1.3643477814652234 2.1211405035537005" />
            </geometry>
        </collision>
    </link>
    <link name="Leg20">
        <inertial>
            <origin xyz="0 0 1.1042837150166331" rpy="0 0 0"/>
            <mass value="1" />
            <inertia ixx="100" ixy="0" ixz="0" iyy="100" iyz="0" izz="100" />
        </inertial>
        <visual>
            <origin xyz="0 0 1.1042837150166331" rpy="0 0 0"/>
            <geometry>
                <box size="1.0794660564293173 1.178147481075333 2.2085674300332663" />
            </geometry>
            <material name="Green">
                <color rgba="0 180.0 0.0 1.0"/>
            </material>
        </visual>
        <collision>
            <origin xyz="0 0 1.1042837150166331" rpy="0 0 0"/>
            <geometry>
                <box size="1.0794660564293173 1.178147481075333 2.2085674300332663" />
            </geometry>
        </collision>
    </link>
    <link name="Leg21">
        <inertial>
            <origin xyz="0 0 0.6191322050187635" rpy="0 0 0"/>
            <mass value="1" />
            <inertia ixx="100" ixy="0" ixz="0" iyy="100" iyz="0" izz="100" />
        </inertial>
        <visual>
            <origin xyz="0 0 0.6191322050187635" rpy="0 0 0"/>
            <geometry>
                <box size="1.5108165746224909 2.190674681913716 1.238264410037527" />
            </geometry>
            <material name="Green">
                <color rgba="0 180.0 0.0 1.0"/>
            </material>
        </visual>
        <collision>
            <origin xyz="0 0 0.6191322050187635" rpy="0 0 0"/>
            <geometry>
                <box size="1.5108165746224909 2.190674681913716 1.238264410037527" />
            </geometry>
        </collision>
    </link>
    <link name="Leg22">
        <inertial>
            <origin xyz="0 0 0.835188099640455" rpy="0 0 0"/>
            <mass value="1" />
            <inertia ixx="100" ixy="0" ixz="0" iyy="100" iyz="0" izz="100" />
        </inertial>
        <visual>
            <origin xyz="0 0 0.835188099640455" rpy="0 0 0"/>
            <geometry>
                <box size="1.0284581679799623 1.5668324622282939 1.67037619928091" />
            </geometry>
            <material name="Blue">
                <color rgba="0 1.0 1.0 1.0"/>
            </material>
        </visual>
        <collision>
            <origin xyz="0 0 0.835188099640455" rpy="0 0 0"/>
            <geometry>
                <box size="1.0284581679799623 1.5668324622282939 1.67037619928091" />
            </geometry>
        </collision>
    </link>
    <link name="Leg23">
        <inertial>
            <origin xyz="0 0.5255371300678865 0" rpy="0 0 0"/>
            <mass value="1" />
            <inertia ixx="100" ixy="0" ixz="0" iyy="100" iyz="0" izz="100" />
        </inertial>
        <visual>
            <origin xyz="0 0.5255371300678865 0" rpy="0 0 0"/>
            <geometry>
                <box size="2.51951514557292 1.051074260135773 1.348796323418036" />
            </geometry>
            <material name="Blue">
                <color rgba="0 1.0 1.0 1.0"/>
            </material>
        </visual>
        <collision>
            <origin xyz="0 0.5255371300678865 0" rpy="0 0 0"/>
            <geometry>
                <box size="2.51951514557292 1.051074260135773 1.348796323418036" />
            </geometry>
        </collision>
    </link>
    <link name="Leg24">
        <inertial>
            <origin xyz="0 1.1407550480634934 0" rpy="0 0 0"/>
            <mass value="1" />
            <inertia ixx="100" ixy="0" ixz="0" iyy="100" iyz="0" izz="100" />
        </inertial>
        <visual>
            <origin xyz="0 1.1407550480634934 0" rpy="0 0 0"/>
            <geometry>
                <box size="2.3463520104488875 2.2815100961269867 2.9545609101444805" />
            </geometry>
            <material name="Green">
                <color rgba="0 180.0 0.0 1.0"/>
            </material>
        </visual>
        <collision>
            <origin xyz="0 1.1407550480634934 0" rpy="0 0 0"/>
            <geometry>
                <box size="2.3463520104488875 2.2815100961269867 2.9545609101444805" />
            </geometry>
        </collision>
    </link>
    <link name="Leg25">
        <inertial>
            <origin xyz="0 1.484650713040284 0" rpy="0 0 0"/>
            <mass value="1" />
            <inertia ixx="100" ixy="0" ixz="0" iyy="100" iyz="0" izz="100" />
        </inertial>
        <visual>
            <origin xyz="0 1.484650713040284 0" rpy="0 0 0"/>
            <geometry>
                <box size="1.487356503325994 2.969301426080568 2.0828831300599973" />
            </geometry>
            <material name="Blue">
                <color rgba="0 1.0 1.0 1.0"/>
            </material>
        </visual>
        <collision>
            <origin xyz="0 1.484650713040284 0" rpy="0 0 0"/>
            <geometry>
                <box size="1.487356503325994 2.969301426080568 2.0828831300599973" />
            </geometry>
        </collision>
    </link>
    <joint name="Torso_Leg1" type="revolute">
       <parent link="Torso"/>
       <child  link="Leg1"/>
       <origin rpy="0 0 0" xyz="0 0.5970913407958272 1.386358181190721" />
     <axis xyz="1 0 0"/>
       <limit effort="0.0" lower="-3.14159" upper="3.14159" velocity="0.0"/>
    </joint>
    <joint name="Leg1_Leg2" type="revolute">
       <parent link="Leg1"/>
       <child  link="Leg2"/>
       <origin rpy="0 0 0" xyz="0 1.8575921069178591 0" />
     <axis xyz="1 0 0"/>
       <limit effort="0.0" lower="-3.14159" upper="3.14159" velocity="0.0"/>
    </joint>
    <joint name="Leg2_Leg3" type="revolute">
       <parent link="Leg2"/>
       <child  link="Leg3"/>
       <origin rpy="0 0 0" xyz="0 0 2.270945666102616" />
     <axis xyz="1 0 0"/>
       <limit effort="0.0" lower="-3.14159" upper="3.14159" velocity="0.0"/>
    </joint>
    <joint name="Leg3_Leg4" type="revolute">
       <parent link="Leg3"/>
       <child  link="Leg4"/>
       <origin rpy="0 0 0" xyz="1.198757910329884 0 0" />
     <axis xyz="1 0 0"/>
       <limit effort="0.0" lower="-3.14159" upper="3.14159" velocity="0.0"/>
    </joint>
    <joint name="Leg4_Leg5" type="revolute">
       <parent link="Leg4"/>
       <child  link="Leg5"/>
       <origin rpy="0 0 0" xyz="0 0 1.1077676499769704" />
     <axis xyz="1 0 0"/>
       <limit effort="0.0" lower="-3.14159" upper="3.14159" velocity="0.0"/>
    </joint>
    <joint name="Torso_Leg6" type="revolute">
       <parent link="Torso"/>
       <child  link="Leg6"/>
       <origin rpy="0 0 0" xyz="0.9538178865317203 0.7538193701245725 0" />
     <axis xyz="1 0 0"/>
       <limit effort="0.0" lower="-3.14159" upper="3.14159" velocity="0.0"/>
    </joint>
    <joint name="Leg4_Leg7" type="revolute">
       <parent link="Leg4"/>
       <child  link="Leg7"/>
       <origin rpy="0 0 0" xyz="1.0526327017614465 0 1.1077676499769704" />
     <axis xyz="1 0 0"/>
       <limit effort="0.0" lower="-3.14159" upper="3.14159" velocity="0.0"/>
    </joint>
    <joint name="Leg4_Leg8" type="revolute">
       <parent link="Leg4"/>
       <child  link="Leg8"/>
       <origin rpy="0 0 0" xyz="1.0526327017614465 1.3402305264485683 1.1077676499769704" />
     <axis xyz="1 0 0"/>
       <limit effort="0.0" lower="-3.14159" upper="3.14159" velocity="0.0"/>
    </joint>
    <joint name="Leg6_Leg9" type="revolute">
       <parent link="Leg6"/>
       <child  link="Leg9"/>
       <origin rpy="0 0 0" xyz="1.4802247178020695 1.1253831727024708 0" />
     <axis xyz="1 0 0"/>
       <limit effort="0.0" lower="-3.14159" upper="3.14159" velocity="0.0"/>
    </joint>
    <joint name="Leg9_Leg10" type="revolute">
       <parent link="Leg9"/>
       <child  link="Leg10"/>
       <origin rpy="0 0 0" xyz="2.959868754387432 0 0" />
     <axis xyz="1 0 0"/>
       <limit effort="0.0" lower="-3.14159" upper="3.14159" velocity="0.0"/>
    </joint>
    <joint name="Leg1_Leg11" type="revolute">
       <parent link="Leg1"/>
       <child  link="Leg11"/>
       <origin rpy="0 0 0" xyz="1.4072865678790083 1.8575921069178591 0" />
     <axis xyz="1 0 0"/>
       <limit effort="0.0" lower="-3.14159" upper="3.14159" velocity="0.0"/>
    </joint>
    <joint name="Leg11_Leg12" type="revolute">
       <parent link="Leg11"/>
       <child  link="Leg12"/>
       <origin rpy="0 0 0" xyz="0 1.3182315073122952 0" />
     <axis xyz="1 0 0"/>
       <limit effort="0.0" lower="-3.14159" upper="3.14159" velocity="0.0"/>
    </joint>
    <joint name="Leg10_Leg13" type="revolute">
       <parent link="Leg10"/>
       <child  link="Leg13"/>
       <origin rpy="0 0 0" xyz="1.8579199312295822 0 0" />
     <axis xyz="1 0 0"/>
       <limit effort="0.0" lower="-3.14159" upper="3.14159" velocity="0.0"/>
    </joint>
    <joint name="Leg13_Leg14" type="revolute">
       <parent link="Leg13"/>
       <child  link="Leg14"/>
       <origin rpy="0 0 0" xyz="0 0 1.2470532920286106" />
     <axis xyz="1 0 0"/>
       <limit effort="0.0" lower="-3.14159" upper="3.14159" velocity="0.0"/>
    </joint>
    <joint name="Leg5_Leg15" type="revolute">
       <parent link="Leg5"/>
       <child  link="Leg15"/>
       <origin rpy="0 0 0" xyz="0.8046897827151258 0.641199844002599 0" />
     <axis xyz="1 0 0"/>
       <limit effort="0.0" lower="-3.14159" upper="3.14159" velocity="0.0"/>
    </joint>
    <joint name="Leg7_Leg16" type="revolute">
       <parent link="Leg7"/>
       <child  link="Leg16"/>
       <origin rpy="0 0 0" xyz="0.6661187063062793 0.6003334582784408 0" />
     <axis xyz="1 0 0"/>
       <limit effort="0.0" lower="-3.14159" upper="3.14159" velocity="0.0"/>
    </joint>
    <joint name="Leg14_Leg17" type="revolute">
       <parent link="Leg14"/>
       <child  link="Leg17"/>
       <origin rpy="0 0 0" xyz="1.236309986609348 0.6872102997362528 0" />
     <axis xyz="1 0 0"/>
       <limit effort="0.0" lower="-3.14159" upper="3.14159" velocity="0.0"/>
    </joint>
    <joint name="Leg6_Leg18" type="revolute">
       <parent link="Leg6"/>
       <child  link="Leg18"/>
       <origin rpy="0 0 0" xyz="2.960449435604139 1.1253831727024708 0" />
     <axis xyz="1 0 0"/>
       <limit effort="0.0" lower="-3.14159" upper="3.14159" velocity="0.0"/>
    </joint>
    <joint name="Leg15_Leg19" type="revolute">
       <parent link="Leg15"/>
       <child  link="Leg19"/>
       <origin rpy="0 0 0" xyz="2.29711792192799 0 0" />
     <axis xyz="1 0 0"/>
       <limit effort="0.0" lower="-3.14159" upper="3.14159" velocity="0.0"/>
    </joint>
    <joint name="Leg12_Leg20" type="revolute">
       <parent link="Leg12"/>
       <child  link="Leg20"/>
       <origin rpy="0 0 0" xyz="0.7959475548513887 0 0.8679132388202533" />
     <axis xyz="1 0 0"/>
       <limit effort="0.0" lower="-3.14159" upper="3.14159" velocity="0.0"/>
    </joint>
    <joint name="Leg19_Leg21" type="revolute">
       <parent link="Leg19"/>
       <child  link="Leg21"/>
       <origin rpy="0 0 0" xyz="0 0 2.2085674300332663" />
     <axis xyz="1 0 0"/>
       <limit effort="0.0" lower="-3.14159" upper="3.14159" velocity="0.0"/>
    </joint>
    <joint name="Torso_Leg22" type="revolute">
       <parent link="Torso"/>
       <child  link="Leg22"/>
       <origin rpy="0 0 0" xyz="0.9538178865317203 0.7538193701245725 0.5972806608255105" />
     <axis xyz="1 0 0"/>
       <limit effort="0.0" lower="-3.14159" upper="3.14159" velocity="0.0"/>
    </joint>
    <joint name="Leg21_Leg23" type="revolute">
       <parent link="Leg21"/>
       <child  link="Leg23"/>
       <origin rpy="0 0 0" xyz="0 0.7834162311141469 0.835188099640455" />
     <axis xyz="1 0 0"/>
       <limit effort="0.0" lower="-3.14159" upper="3.14159" velocity="0.0"/>
    </joint>
    <joint name="Leg10_Leg24" type="revolute">
       <parent link="Leg10"/>
       <child  link="Leg24"/>
       <origin rpy="0 0 0" xyz="1.8579199312295822 0.7796199562636851 0" />
     <axis xyz="1 0 0"/>
       <limit effort="0.0" lower="-3.14159" upper="3.14159" velocity="0.0"/>
    </joint>
    <joint name="Leg23_Leg25" type="revolute">
       <parent link="Leg23"/>
       <child  link="Leg25"/>
       <origin rpy="0 0 0" xyz="0 2.2815100961269867 0" />
     <axis xyz="1 0 0"/>
       <limit effort="0.0" lower="-3.14159" upper="3.14159" velocity="0.0"/>
    </joint>
</robot>