<robot name = "robot">
    <link name="Torso">
        <inertial>
            <origin xyz="0 0 1.0425655881164653" rpy="0 0 0"/>
            <mass value="1" />
            <inertia ixx="100" ixy="0" ixz="0" iyy="100" iyz="0" izz="100" />
        </inertial>
        <visual>
            <origin xyz="0 0 1.0425655881164653" rpy="0 0 0"/>
            <geometry>
                <box size="2.184670139596987 1.3055000312239708 2.0851311762329305" />
            </geometry>
            <material name="Green">
                <color rgba="0 180.0 0.0 1.0"/>
            </material>
        </visual>
        <collision>
            <origin xyz="0 0 1.0425655881164653" rpy="0 0 0"/>
            <geometry>
                <box size="2.184670139596987 1.3055000312239708 2.0851311762329305" />
            </geometry>
        </collision>
    </link>
    <link name="Leg1">
        <inertial>
            <origin xyz="0.7872750118560833 0 0" rpy="0 0 0"/>
            <mass value="1" />
            <inertia ixx="100" ixy="0" ixz="0" iyy="100" iyz="0" izz="100" />
        </inertial>
        <visual>
            <origin xyz="0.7872750118560833 0 0" rpy="0 0 0"/>
            <geometry>
                <box size="1.5745500237121666 1.6852193054566407 2.0498380518227814" />
            </geometry>
            <material name="Blue">
                <color rgba="0 1.0 1.0 1.0"/>
            </material>
        </visual>
        <collision>
            <origin xyz="0.7872750118560833 0 0" rpy="0 0 0"/>
            <geometry>
                <box size="1.5745500237121666 1.6852193054566407 2.0498380518227814" />
            </geometry>
        </collision>
    </link>
    <link name="Leg2">
        <inertial>
            <origin xyz="0 1.2001063316342115 0" rpy="0 0 0"/>
            <mass value="1" />
            <inertia ixx="100" ixy="0" ixz="0" iyy="100" iyz="0" izz="100" />
        </inertial>
        <visual>
            <origin xyz="0 1.2001063316342115 0" rpy="0 0 0"/>
            <geometry>
                <box size="1.8791204822887433 2.400212663268423 1.0480083467257573" />
            </geometry>
            <material name="Blue">
                <color rgba="0 1.0 1.0 1.0"/>
            </material>
        </visual>
        <collision>
            <origin xyz="0 1.2001063316342115 0" rpy="0 0 0"/>
            <geometry>
                <box size="1.8791204822887433 2.400212663268423 1.0480083467257573" />
            </geometry>
        </collision>
    </link>
    <link name="Leg3">
        <inertial>
            <origin xyz="0 0 1.4064275934652262" rpy="0 0 0"/>
            <mass value="1" />
            <inertia ixx="100" ixy="0" ixz="0" iyy="100" iyz="0" izz="100" />
        </inertial>
        <visual>
            <origin xyz="0 0 1.4064275934652262" rpy="0 0 0"/>
            <geometry>
                <box size="1.6714884346890675 1.7865537883659888 2.8128551869304523" />
            </geometry>
            <material name="Green">
                <color rgba="0 180.0 0.0 1.0"/>
            </material>
        </visual>
        <collision>
            <origin xyz="0 0 1.4064275934652262" rpy="0 0 0"/>
            <geometry>
                <box size="1.6714884346890675 1.7865537883659888 2.8128551869304523" />
            </geometry>
        </collision>
    </link>
    <link name="Leg4">
        <inertial>
            <origin xyz="0 0 1.0351345591833443" rpy="0 0 0"/>
            <mass value="1" />
            <inertia ixx="100" ixy="0" ixz="0" iyy="100" iyz="0" izz="100" />
        </inertial>
        <visual>
            <origin xyz="0 0 1.0351345591833443" rpy="0 0 0"/>
            <geometry>
                <box size="1.0385402738799223 2.401593672042046 2.0702691183666886" />
            </geometry>
            <material name="Green">
                <color rgba="0 180.0 0.0 1.0"/>
            </material>
        </visual>
        <collision>
            <origin xyz="0 0 1.0351345591833443" rpy="0 0 0"/>
            <geometry>
                <box size="1.0385402738799223 2.401593672042046 2.0702691183666886" />
            </geometry>
        </collision>
    </link>
    <link name="Leg5">
        <inertial>
            <origin xyz="0 0.5240226708858721 0" rpy="0 0 0"/>
            <mass value="1" />
            <inertia ixx="100" ixy="0" ixz="0" iyy="100" iyz="0" izz="100" />
        </inertial>
        <visual>
            <origin xyz="0 0.5240226708858721 0" rpy="0 0 0"/>
            <geometry>
                <box size="2.0932420609322735 1.0480453417717441 1.9217461892362744" />
            </geometry>
            <material name="Blue">
                <color rgba="0 1.0 1.0 1.0"/>
            </material>
        </visual>
        <collision>
            <origin xyz="0 0.5240226708858721 0" rpy="0 0 0"/>
            <geometry>
                <box size="2.0932420609322735 1.0480453417717441 1.9217461892362744" />
            </geometry>
        </collision>
    </link>
    <link name="Leg6">
        <inertial>
            <origin xyz="0.7005155793990518 0 0" rpy="0 0 0"/>
            <mass value="1" />
            <inertia ixx="100" ixy="0" ixz="0" iyy="100" iyz="0" izz="100" />
        </inertial>
        <visual>
            <origin xyz="0.7005155793990518 0 0" rpy="0 0 0"/>
            <geometry>
                <box size="1.4010311587981037 1.2870132011510864 2.099274867817262" />
            </geometry>
            <material name="Blue">
                <color rgba="0 1.0 1.0 1.0"/>
            </material>
        </visual>
        <collision>
            <origin xyz="0.7005155793990518 0 0" rpy="0 0 0"/>
            <geometry>
                <box size="1.4010311587981037 1.2870132011510864 2.099274867817262" />
            </geometry>
        </collision>
    </link>
    <link name="Leg7">
        <inertial>
            <origin xyz="0.9296315251239713 0 0" rpy="0 0 0"/>
            <mass value="1" />
            <inertia ixx="100" ixy="0" ixz="0" iyy="100" iyz="0" izz="100" />
        </inertial>
        <visual>
            <origin xyz="0.9296315251239713 0 0" rpy="0 0 0"/>
            <geometry>
                <box size="1.8592630502479426 1.9975643547946562 2.3627492927263125" />
            </geometry>
            <material name="Green">
                <color rgba="0 180.0 0.0 1.0"/>
            </material>
        </visual>
        <collision>
            <origin xyz="0.9296315251239713 0 0" rpy="0 0 0"/>
            <geometry>
                <box size="1.8592630502479426 1.9975643547946562 2.3627492927263125" />
            </geometry>
        </collision>
    </link>
    <link name="Leg8">
        <inertial>
            <origin xyz="0 1.252443752059599 0" rpy="0 0 0"/>
            <mass value="1" />
            <inertia ixx="100" ixy="0" ixz="0" iyy="100" iyz="0" izz="100" />
        </inertial>
        <visual>
            <origin xyz="0 1.252443752059599 0" rpy="0 0 0"/>
            <geometry>
                <box size="2.650783759331765 2.504887504119198 2.8499685549351708" />
            </geometry>
            <material name="Green">
                <color rgba="0 180.0 0.0 1.0"/>
            </material>
        </visual>
        <collision>
            <origin xyz="0 1.252443752059599 0" rpy="0 0 0"/>
            <geometry>
                <box size="2.650783759331765 2.504887504119198 2.8499685549351708" />
            </geometry>
        </collision>
    </link>
    <link name="Leg9">
        <inertial>
            <origin xyz="0 0 0.6643370127785969" rpy="0 0 0"/>
            <mass value="1" />
            <inertia ixx="100" ixy="0" ixz="0" iyy="100" iyz="0" izz="100" />
        </inertial>
        <visual>
            <origin xyz="0 0 0.6643370127785969" rpy="0 0 0"/>
            <geometry>
                <box size="1.6247572193484379 2.2846303980769127 1.3286740255571938" />
            </geometry>
            <material name="Green">
                <color rgba="0 180.0 0.0 1.0"/>
            </material>
        </visual>
        <collision>
            <origin xyz="0 0 0.6643370127785969" rpy="0 0 0"/>
            <geometry>
                <box size="1.6247572193484379 2.2846303980769127 1.3286740255571938" />
            </geometry>
        </collision>
    </link>
    <link name="Leg10">
        <inertial>
            <origin xyz="0.7586560096966578 0 0" rpy="0 0 0"/>
            <mass value="1" />
            <inertia ixx="100" ixy="0" ixz="0" iyy="100" iyz="0" izz="100" />
        </inertial>
        <visual>
            <origin xyz="0.7586560096966578 0 0" rpy="0 0 0"/>
            <geometry>
                <box size="1.5173120193933156 1.7528874363669449 1.374488167291396" />
            </geometry>
            <material name="Blue">
                <color rgba="0 1.0 1.0 1.0"/>
            </material>
        </visual>
        <collision>
            <origin xyz="0.7586560096966578 0 0" rpy="0 0 0"/>
            <geometry>
                <box size="1.5173120193933156 1.7528874363669449 1.374488167291396" />
            </geometry>
        </collision>
    </link>
    <link name="Leg11">
        <inertial>
            <origin xyz="1.4243876370231292 0 0" rpy="0 0 0"/>
            <mass value="1" />
            <inertia ixx="100" ixy="0" ixz="0" iyy="100" iyz="0" izz="100" />
        </inertial>
        <visual>
            <origin xyz="1.4243876370231292 0 0" rpy="0 0 0"/>
            <geometry>
                <box size="2.8487752740462584 2.026937181390849 1.9865721792779323" />
            </geometry>
            <material name="Green">
                <color rgba="0 180.0 0.0 1.0"/>
            </material>
        </visual>
        <collision>
            <origin xyz="1.4243876370231292 0 0" rpy="0 0 0"/>
            <geometry>
                <box size="2.8487752740462584 2.026937181390849 1.9865721792779323" />
            </geometry>
        </collision>
    </link>
    <link name="Leg12">
        <inertial>
            <origin xyz="1.3539223352312326 0 0" rpy="0 0 0"/>
            <mass value="1" />
            <inertia ixx="100" ixy="0" ixz="0" iyy="100" iyz="0" izz="100" />
        </inertial>
        <visual>
            <origin xyz="1.3539223352312326 0 0" rpy="0 0 0"/>
            <geometry>
                <box size="2.7078446704624652 1.3547911623651396 1.1694586558105957" />
            </geometry>
            <material name="Green">
                <color rgba="0 180.0 0.0 1.0"/>
            </material>
        </visual>
        <collision>
            <origin xyz="1.3539223352312326 0 0" rpy="0 0 0"/>
            <geometry>
                <box size="2.7078446704624652 1.3547911623651396 1.1694586558105957" />
            </geometry>
        </collision>
    </link>
    <link name="Leg13">
        <inertial>
            <origin xyz="0 0.7671740432811974 0" rpy="0 0 0"/>
            <mass value="1" />
            <inertia ixx="100" ixy="0" ixz="0" iyy="100" iyz="0" izz="100" />
        </inertial>
        <visual>
            <origin xyz="0 0.7671740432811974 0" rpy="0 0 0"/>
            <geometry>
                <box size="1.1050986803627323 1.5343480865623949 2.5154388878603795" />
            </geometry>
            <material name="Blue">
                <color rgba="0 1.0 1.0 1.0"/>
            </material>
        </visual>
        <collision>
            <origin xyz="0 0.7671740432811974 0" rpy="0 0 0"/>
            <geometry>
                <box size="1.1050986803627323 1.5343480865623949 2.5154388878603795" />
            </geometry>
        </collision>
    </link>
    <link name="Leg14">
        <inertial>
            <origin xyz="0 1.2513842676071292 0" rpy="0 0 0"/>
            <mass value="1" />
            <inertia ixx="100" ixy="0" ixz="0" iyy="100" iyz="0" izz="100" />
        </inertial>
        <visual>
            <origin xyz="0 1.2513842676071292 0" rpy="0 0 0"/>
            <geometry>
                <box size="1.0347063567524981 2.5027685352142583 1.0131878466719633" />
            </geometry>
            <material name="Blue">
                <color rgba="0 1.0 1.0 1.0"/>
            </material>
        </visual>
        <collision>
            <origin xyz="0 1.2513842676071292 0" rpy="0 0 0"/>
            <geometry>
                <box size="1.0347063567524981 2.5027685352142583 1.0131878466719633" />
            </geometry>
        </collision>
    </link>
    <link name="Leg15">
        <inertial>
            <origin xyz="1.37023882437137 0 0" rpy="0 0 0"/>
            <mass value="1" />
            <inertia ixx="100" ixy="0" ixz="0" iyy="100" iyz="0" izz="100" />
        </inertial>
        <visual>
            <origin xyz="1.37023882437137 0 0" rpy="0 0 0"/>
            <geometry>
                <box size="2.74047764874274 2.894580845245061 1.8823511273491467" />
            </geometry>
            <material name="Blue">
                <color rgba="0 1.0 1.0 1.0"/>
            </material>
        </visual>
        <collision>
            <origin xyz="1.37023882437137 0 0" rpy="0 0 0"/>
            <geometry>
                <box size="2.74047764874274 2.894580845245061 1.8823511273491467" />
            </geometry>
        </collision>
    </link>
    <link name="Leg16">
        <inertial>
            <origin xyz="0 0 1.007929134179276" rpy="0 0 0"/>
            <mass value="1" />
            <inertia ixx="100" ixy="0" ixz="0" iyy="100" iyz="0" izz="100" />
        </inertial>
        <visual>
            <origin xyz="0 0 1.007929134179276" rpy="0 0 0"/>
            <geometry>
                <box size="2.9894973919936367 1.2509589734055804 2.015858268358552" />
            </geometry>
            <material name="Blue">
                <color rgba="0 1.0 1.0 1.0"/>
            </material>
        </visual>
        <collision>
            <origin xyz="0 0 1.007929134179276" rpy="0 0 0"/>
            <geometry>
                <box size="2.9894973919936367 1.2509589734055804 2.015858268358552" />
            </geometry>
        </collision>
    </link>
    <link name="Leg17">
        <inertial>
            <origin xyz="0.6485460294349372 0 0" rpy="0 0 0"/>
            <mass value="1" />
            <inertia ixx="100" ixy="0" ixz="0" iyy="100" iyz="0" izz="100" />
        </inertial>
        <visual>
            <origin xyz="0.6485460294349372 0 0" rpy="0 0 0"/>
            <geometry>
                <box size="1.2970920588698744 2.9355454818161038 2.444792233483572" />
            </geometry>
            <material name="Blue">
                <color rgba="0 1.0 1.0 1.0"/>
            </material>
        </visual>
        <collision>
            <origin xyz="0.6485460294349372 0 0" rpy="0 0 0"/>
            <geometry>
                <box size="1.2970920588698744 2.9355454818161038 2.444792233483572" />
            </geometry>
        </collision>
    </link>
    <link name="Leg18">
        <inertial>
            <origin xyz="0.6854068116271655 0 0" rpy="0 0 0"/>
            <mass value="1" />
            <inertia ixx="100" ixy="0" ixz="0" iyy="100" iyz="0" izz="100" />
        </inertial>
        <visual>
            <origin xyz="0.6854068116271655 0 0" rpy="0 0 0"/>
            <geometry>
                <box size="1.370813623254331 1.3997665262273817 2.30659643938391" />
            </geometry>
            <material name="Green">
                <color rgba="0 180.0 0.0 1.0"/>
            </material>
        </visual>
        <collision>
            <origin xyz="0.6854068116271655 0 0" rpy="0 0 0"/>
            <geometry>
                <box size="1.370813623254331 1.3997665262273817 2.30659643938391" />
            </geometry>
        </collision>
    </link>
    <link name="Leg19">
        <inertial>
            <origin xyz="0 1.1885072017051779 0" rpy="0 0 0"/>
            <mass value="1" />
            <inertia ixx="100" ixy="0" ixz="0" iyy="100" iyz="0" izz="100" />
        </inertial>
        <visual>
            <origin xyz="0 1.1885072017051779 0" rpy="0 0 0"/>
            <geometry>
                <box size="1.9958092360954287 2.3770144034103557 1.9249460344440301" />
            </geometry>
            <material name="Green">
                <color rgba="0 180.0 0.0 1.0"/>
            </material>
        </visual>
        <collision>
            <origin xyz="0 1.1885072017051779 0" rpy="0 0 0"/>
            <geometry>
                <box size="1.9958092360954287 2.3770144034103557 1.9249460344440301" />
            </geometry>
        </collision>
    </link>
    <link name="Leg20">
        <inertial>
            <origin xyz="0 0 0.623824711056326" rpy="0 0 0"/>
            <mass value="1" />
            <inertia ixx="100" ixy="0" ixz="0" iyy="100" iyz="0" izz="100" />
        </inertial>
        <visual>
            <origin xyz="0 0 0.623824711056326" rpy="0 0 0"/>
            <geometry>
                <box size="1.1508571498302833 1.586180702329503 1.247649422112652" />
            </geometry>
            <material name="Blue">
                <color rgba="0 1.0 1.0 1.0"/>
            </material>
        </visual>
        <collision>
            <origin xyz="0 0 0.623824711056326" rpy="0 0 0"/>
            <geometry>
                <box size="1.1508571498302833 1.586180702329503 1.247649422112652" />
            </geometry>
        </collision>
    </link>
    <link name="Leg21">
        <inertial>
            <origin xyz="1.386934759738431 0 0" rpy="0 0 0"/>
            <mass value="1" />
            <inertia ixx="100" ixy="0" ixz="0" iyy="100" iyz="0" izz="100" />
        </inertial>
        <visual>
            <origin xyz="1.386934759738431 0 0" rpy="0 0 0"/>
            <geometry>
                <box size="2.773869519476862 1.2232857602147482 1.366074593923216" />
            </geometry>
            <material name="Blue">
                <color rgba="0 1.0 1.0 1.0"/>
            </material>
        </visual>
        <collision>
            <origin xyz="1.386934759738431 0 0" rpy="0 0 0"/>
            <geometry>
                <box size="2.773869519476862 1.2232857602147482 1.366074593923216" />
            </geometry>
        </collision>
    </link>
    <link name="Leg22">
        <inertial>
            <origin xyz="0 0.8995257810975139 0" rpy="0 0 0"/>
            <mass value="1" />
            <inertia ixx="100" ixy="0" ixz="0" iyy="100" iyz="0" izz="100" />
        </inertial>
        <visual>
            <origin xyz="0 0.8995257810975139 0" rpy="0 0 0"/>
            <geometry>
                <box size="2.0258875352870716 1.7990515621950278 2.3486494777828244" />
            </geometry>
            <material name="Blue">
                <color rgba="0 1.0 1.0 1.0"/>
            </material>
        </visual>
        <collision>
            <origin xyz="0 0.8995257810975139 0" rpy="0 0 0"/>
            <geometry>
                <box size="2.0258875352870716 1.7990515621950278 2.3486494777828244" />
            </geometry>
        </collision>
    </link>
    <link name="Leg23">
        <inertial>
            <origin xyz="0 0 0.9296675081902327" rpy="0 0 0"/>
            <mass value="1" />
            <inertia ixx="100" ixy="0" ixz="0" iyy="100" iyz="0" izz="100" />
        </inertial>
        <visual>
            <origin xyz="0 0 0.9296675081902327" rpy="0 0 0"/>
            <geometry>
                <box size="1.0925575428361685 2.654769055919187 1.8593350163804654" />
            </geometry>
            <material name="Green">
                <color rgba="0 180.0 0.0 1.0"/>
            </material>
        </visual>
        <collision>
            <origin xyz="0 0 0.9296675081902327" rpy="0 0 0"/>
            <geometry>
                <box size="1.0925575428361685 2.654769055919187 1.8593350163804654" />
            </geometry>
        </collision>
    </link>
    <link name="Leg24">
        <inertial>
            <origin xyz="0 1.0148796347592017 0" rpy="0 0 0"/>
            <mass value="1" />
            <inertia ixx="100" ixy="0" ixz="0" iyy="100" iyz="0" izz="100" />
        </inertial>
        <visual>
            <origin xyz="0 1.0148796347592017 0" rpy="0 0 0"/>
            <geometry>
                <box size="1.3423487757108366 2.0297592695184035 2.7695317328598894" />
            </geometry>
            <material name="Green">
                <color rgba="0 180.0 0.0 1.0"/>
            </material>
        </visual>
        <collision>
            <origin xyz="0 1.0148796347592017 0" rpy="0 0 0"/>
            <geometry>
                <box size="1.3423487757108366 2.0297592695184035 2.7695317328598894" />
            </geometry>
        </collision>
    </link>
    <link name="Leg25">
        <inertial>
            <origin xyz="0 0 0.767160192697092" rpy="0 0 0"/>
            <mass value="1" />
            <inertia ixx="100" ixy="0" ixz="0" iyy="100" iyz="0" izz="100" />
        </inertial>
        <visual>
            <origin xyz="0 0 0.767160192697092" rpy="0 0 0"/>
            <geometry>
                <box size="1.7418867341793076 2.7795919924441255 1.534320385394184" />
            </geometry>
            <material name="Blue">
                <color rgba="0 1.0 1.0 1.0"/>
            </material>
        </visual>
        <collision>
            <origin xyz="0 0 0.767160192697092" rpy="0 0 0"/>
            <geometry>
                <box size="1.7418867341793076 2.7795919924441255 1.534320385394184" />
            </geometry>
        </collision>
    </link>
    <joint name="Torso_Leg1" type="revolute">
       <parent link="Torso"/>
       <child  link="Leg1"/>
       <origin rpy="0 0 0" xyz="1.0923350697984935 0 1.0425655881164653" />
     <axis xyz="1 0 0"/>
       <limit effort="0.0" lower="-3.14159" upper="3.14159" velocity="0.0"/>
    </joint>
    <joint name="Torso_Leg2" type="revolute">
       <parent link="Torso"/>
       <child  link="Leg2"/>
       <origin rpy="0 0 0" xyz="0.7872750118560833 0.8426096527283203 0" />
     <axis xyz="1 0 0"/>
       <limit effort="0.0" lower="-3.14159" upper="3.14159" velocity="0.0"/>
    </joint>
    <joint name="Leg2_Leg3" type="revolute">
       <parent link="Leg2"/>
       <child  link="Leg3"/>
       <origin rpy="0 0 0" xyz="0 0 2.8128551869304523" />
     <axis xyz="1 0 0"/>
       <limit effort="0.0" lower="-3.14159" upper="3.14159" velocity="0.0"/>
    </joint>
    <joint name="Leg1_Leg4" type="revolute">
       <parent link="Leg1"/>
       <child  link="Leg4"/>
       <origin rpy="0 0 0" xyz="0 1.2001063316342115 0.5240041733628786" />
     <axis xyz="1 0 0"/>
       <limit effort="0.0" lower="-3.14159" upper="3.14159" velocity="0.0"/>
    </joint>
    <joint name="Leg4_Leg5" type="revolute">
       <parent link="Leg4"/>
       <child  link="Leg5"/>
       <origin rpy="0 0 0" xyz="0 1.0480453417717441 0" />
     <axis xyz="1 0 0"/>
       <limit effort="0.0" lower="-3.14159" upper="3.14159" velocity="0.0"/>
    </joint>
    <joint name="Leg2_Leg6" type="revolute">
       <parent link="Leg2"/>
       <child  link="Leg6"/>
       <origin rpy="0 0 0" xyz="0.8357442173445337 0 2.8128551869304523" />
     <axis xyz="1 0 0"/>
       <limit effort="0.0" lower="-3.14159" upper="3.14159" velocity="0.0"/>
    </joint>
    <joint name="Leg5_Leg7" type="revolute">
       <parent link="Leg5"/>
       <child  link="Leg7"/>
       <origin rpy="0 0 0" xyz="1.4010311587981037 0 0" />
     <axis xyz="1 0 0"/>
       <limit effort="0.0" lower="-3.14159" upper="3.14159" velocity="0.0"/>
    </joint>
    <joint name="Leg3_Leg8" type="revolute">
       <parent link="Leg3"/>
       <child  link="Leg8"/>
       <origin rpy="0 0 0" xyz="0 1.200796836021023 1.0351345591833443" />
     <axis xyz="1 0 0"/>
       <limit effort="0.0" lower="-3.14159" upper="3.14159" velocity="0.0"/>
    </joint>
    <joint name="Leg4_Leg9" type="revolute">
       <parent link="Leg4"/>
       <child  link="Leg9"/>
       <origin rpy="0 0 0" xyz="0 1.0480453417717441 0.9608730946181372" />
     <axis xyz="1 0 0"/>
       <limit effort="0.0" lower="-3.14159" upper="3.14159" velocity="0.0"/>
    </joint>
    <joint name="Leg3_Leg10" type="revolute">
       <parent link="Leg3"/>
       <child  link="Leg10"/>
       <origin rpy="0 0 0" xyz="0.5192701369399612 1.200796836021023 1.0351345591833443" />
     <axis xyz="1 0 0"/>
       <limit effort="0.0" lower="-3.14159" upper="3.14159" velocity="0.0"/>
    </joint>
    <joint name="Leg8_Leg11" type="revolute">
       <parent link="Leg8"/>
       <child  link="Leg11"/>
       <origin rpy="0 0 0" xyz="0.8123786096742189 0 0.6643370127785969" />
     <axis xyz="1 0 0"/>
       <limit effort="0.0" lower="-3.14159" upper="3.14159" velocity="0.0"/>
    </joint>
    <joint name="Leg1_Leg12" type="revolute">
       <parent link="Leg1"/>
       <child  link="Leg12"/>
       <origin rpy="0 0 0" xyz="0.9395602411443716 1.2001063316342115 0.5240041733628786" />
     <axis xyz="1 0 0"/>
       <limit effort="0.0" lower="-3.14159" upper="3.14159" velocity="0.0"/>
    </joint>
    <joint name="Leg11_Leg13" type="revolute">
       <parent link="Leg11"/>
       <child  link="Leg13"/>
       <origin rpy="0 0 0" xyz="1.3539223352312326 0.6773955811825698 0" />
     <axis xyz="1 0 0"/>
       <limit effort="0.0" lower="-3.14159" upper="3.14159" velocity="0.0"/>
    </joint>
    <joint name="Leg2_Leg14" type="revolute">
       <parent link="Leg2"/>
       <child  link="Leg14"/>
       <origin rpy="0 0 0" xyz="0.8357442173445337 0.8932768941829944 2.8128551869304523" />
     <axis xyz="1 0 0"/>
       <limit effort="0.0" lower="-3.14159" upper="3.14159" velocity="0.0"/>
    </joint>
    <joint name="Leg14_Leg15" type="revolute">
       <parent link="Leg14"/>
       <child  link="Leg15"/>
       <origin rpy="0 0 0" xyz="2.74047764874274 0 0" />
     <axis xyz="1 0 0"/>
       <limit effort="0.0" lower="-3.14159" upper="3.14159" velocity="0.0"/>
    </joint>
    <joint name="Leg10_Leg16" type="revolute">
       <parent link="Leg10"/>
       <child  link="Leg16"/>
       <origin rpy="0 0 0" xyz="1.4243876370231292 0 0.9932860896389661" />
     <axis xyz="1 0 0"/>
       <limit effort="0.0" lower="-3.14159" upper="3.14159" velocity="0.0"/>
    </joint>
    <joint name="Leg12_Leg17" type="revolute">
       <parent link="Leg12"/>
       <child  link="Leg17"/>
       <origin rpy="0 0 0" xyz="0.5525493401813661 0.7671740432811974 0" />
     <axis xyz="1 0 0"/>
       <limit effort="0.0" lower="-3.14159" upper="3.14159" velocity="0.0"/>
    </joint>
    <joint name="Leg16_Leg18" type="revolute">
       <parent link="Leg16"/>
       <child  link="Leg18"/>
       <origin rpy="0 0 0" xyz="1.2970920588698744 0 0" />
     <axis xyz="1 0 0"/>
       <limit effort="0.0" lower="-3.14159" upper="3.14159" velocity="0.0"/>
    </joint>
    <joint name="Leg6_Leg19" type="revolute">
       <parent link="Leg6"/>
       <child  link="Leg19"/>
       <origin rpy="0 0 0" xyz="0.9296315251239713 0.9987821773973281 0" />
     <axis xyz="1 0 0"/>
       <limit effort="0.0" lower="-3.14159" upper="3.14159" velocity="0.0"/>
    </joint>
    <joint name="Leg3_Leg20" type="revolute">
       <parent link="Leg3"/>
       <child  link="Leg20"/>
       <origin rpy="0 0 0" xyz="0.5192701369399612 1.200796836021023 2.0702691183666886" />
     <axis xyz="1 0 0"/>
       <limit effort="0.0" lower="-3.14159" upper="3.14159" velocity="0.0"/>
    </joint>
    <joint name="Leg11_Leg21" type="revolute">
       <parent link="Leg11"/>
       <child  link="Leg21"/>
       <origin rpy="0 0 0" xyz="2.7078446704624652 0.6773955811825698 0" />
     <axis xyz="1 0 0"/>
       <limit effort="0.0" lower="-3.14159" upper="3.14159" velocity="0.0"/>
    </joint>
    <joint name="Leg10_Leg22" type="revolute">
       <parent link="Leg10"/>
       <child  link="Leg22"/>
       <origin rpy="0 0 0" xyz="1.4243876370231292 1.0134685906954246 0.9932860896389661" />
     <axis xyz="1 0 0"/>
       <limit effort="0.0" lower="-3.14159" upper="3.14159" velocity="0.0"/>
    </joint>
    <joint name="Leg17_Leg23" type="revolute">
       <parent link="Leg17"/>
       <child  link="Leg23"/>
       <origin rpy="0 0 0" xyz="0.6854068116271655 0 1.153298219691955" />
     <axis xyz="1 0 0"/>
       <limit effort="0.0" lower="-3.14159" upper="3.14159" velocity="0.0"/>
    </joint>
    <joint name="Leg13_Leg24" type="revolute">
       <parent link="Leg13"/>
       <child  link="Leg24"/>
       <origin rpy="0 0 0" xyz="0 2.5027685352142583 0" />
     <axis xyz="1 0 0"/>
       <limit effort="0.0" lower="-3.14159" upper="3.14159" velocity="0.0"/>
    </joint>
    <joint name="Leg18_Leg25" type="revolute">
       <parent link="Leg18"/>
       <child  link="Leg25"/>
       <origin rpy="0 0 0" xyz="0 1.1885072017051779 0.9624730172220151" />
     <axis xyz="1 0 0"/>
       <limit effort="0.0" lower="-3.14159" upper="3.14159" velocity="0.0"/>
    </joint>
</robot>