<robot name = "robot">
    <link name="Torso">
        <inertial>
            <origin xyz="0 0 0.856101755577824" rpy="0 0 0"/>
            <mass value="1" />
            <inertia ixx="100" ixy="0" ixz="0" iyy="100" iyz="0" izz="100" />
        </inertial>
        <visual>
            <origin xyz="0 0 0.856101755577824" rpy="0 0 0"/>
            <geometry>
                <box size="1.1764571439787286 2.5393333334083756 1.712203511155648" />
            </geometry>
            <material name="Green">
                <color rgba="0 180.0 0.0 1.0"/>
            </material>
        </visual>
        <collision>
            <origin xyz="0 0 0.856101755577824" rpy="0 0 0"/>
            <geometry>
                <box size="1.1764571439787286 2.5393333334083756 1.712203511155648" />
            </geometry>
        </collision>
    </link>
    <link name="Leg1">
        <inertial>
            <origin xyz="0 0.7139797599169466 0" rpy="0 0 0"/>
            <mass value="1" />
            <inertia ixx="100" ixy="0" ixz="0" iyy="100" iyz="0" izz="100" />
        </inertial>
        <visual>
            <origin xyz="0 0.7139797599169466 0" rpy="0 0 0"/>
            <geometry>
                <box size="2.9692935612455846 1.4279595198338932 2.621160581540047" />
            </geometry>
            <material name="Green">
                <color rgba="0 180.0 0.0 1.0"/>
            </material>
        </visual>
        <collision>
            <origin xyz="0 0.7139797599169466 0" rpy="0 0 0"/>
            <geometry>
                <box size="2.9692935612455846 1.4279595198338932 2.621160581540047" />
            </geometry>
        </collision>
    </link>
    <link name="Leg2">
        <inertial>
            <origin xyz="0.755832776948049 0 0" rpy="0 0 0"/>
            <mass value="1" />
            <inertia ixx="100" ixy="0" ixz="0" iyy="100" iyz="0" izz="100" />
        </inertial>
        <visual>
            <origin xyz="0.755832776948049 0 0" rpy="0 0 0"/>
            <geometry>
                <box size="1.511665553896098 1.4562959020545443 1.2271643987307541" />
            </geometry>
            <material name="Green">
                <color rgba="0 180.0 0.0 1.0"/>
            </material>
        </visual>
        <collision>
            <origin xyz="0.755832776948049 0 0" rpy="0 0 0"/>
            <geometry>
                <box size="1.511665553896098 1.4562959020545443 1.2271643987307541" />
            </geometry>
        </collision>
    </link>
    <link name="Leg3">
        <inertial>
            <origin xyz="1.123703787167842 0 0" rpy="0 0 0"/>
            <mass value="1" />
            <inertia ixx="100" ixy="0" ixz="0" iyy="100" iyz="0" izz="100" />
        </inertial>
        <visual>
            <origin xyz="1.123703787167842 0 0" rpy="0 0 0"/>
            <geometry>
                <box size="2.247407574335684 1.259378144814774 1.247631269683019" />
            </geometry>
            <material name="Green">
                <color rgba="0 180.0 0.0 1.0"/>
            </material>
        </visual>
        <collision>
            <origin xyz="1.123703787167842 0 0" rpy="0 0 0"/>
            <geometry>
                <box size="2.247407574335684 1.259378144814774 1.247631269683019" />
            </geometry>
        </collision>
    </link>
    <link name="Leg4">
        <inertial>
            <origin xyz="0 0 0.7498023964926561" rpy="0 0 0"/>
            <mass value="1" />
            <inertia ixx="100" ixy="0" ixz="0" iyy="100" iyz="0" izz="100" />
        </inertial>
        <visual>
            <origin xyz="0 0 0.7498023964926561" rpy="0 0 0"/>
            <geometry>
                <box size="1.3110120834799806 1.300295829493232 1.4996047929853122" />
            </geometry>
            <material name="Green">
                <color rgba="0 180.0 0.0 1.0"/>
            </material>
        </visual>
        <collision>
            <origin xyz="0 0 0.7498023964926561" rpy="0 0 0"/>
            <geometry>
                <box size="1.3110120834799806 1.300295829493232 1.4996047929853122" />
            </geometry>
        </collision>
    </link>
    <link name="Leg5">
        <inertial>
            <origin xyz="0.8688841224350785 0 0" rpy="0 0 0"/>
            <mass value="1" />
            <inertia ixx="100" ixy="0" ixz="0" iyy="100" iyz="0" izz="100" />
        </inertial>
        <visual>
            <origin xyz="0.8688841224350785 0 0" rpy="0 0 0"/>
            <geometry>
                <box size="1.737768244870157 2.66897841608143 1.9249981354751038" />
            </geometry>
            <material name="Green">
                <color rgba="0 180.0 0.0 1.0"/>
            </material>
        </visual>
        <collision>
            <origin xyz="0.8688841224350785 0 0" rpy="0 0 0"/>
            <geometry>
                <box size="1.737768244870157 2.66897841608143 1.9249981354751038" />
            </geometry>
        </collision>
    </link>
    <link name="Leg6">
        <inertial>
            <origin xyz="0 0 0.9477205889233337" rpy="0 0 0"/>
            <mass value="1" />
            <inertia ixx="100" ixy="0" ixz="0" iyy="100" iyz="0" izz="100" />
        </inertial>
        <visual>
            <origin xyz="0 0 0.9477205889233337" rpy="0 0 0"/>
            <geometry>
                <box size="1.1027772596796348 1.2089087496525772 1.8954411778466673" />
            </geometry>
            <material name="Green">
                <color rgba="0 180.0 0.0 1.0"/>
            </material>
        </visual>
        <collision>
            <origin xyz="0 0 0.9477205889233337" rpy="0 0 0"/>
            <geometry>
                <box size="1.1027772596796348 1.2089087496525772 1.8954411778466673" />
            </geometry>
        </collision>
    </link>
    <link name="Leg7">
        <inertial>
            <origin xyz="0.6340702965382699 0 0" rpy="0 0 0"/>
            <mass value="1" />
            <inertia ixx="100" ixy="0" ixz="0" iyy="100" iyz="0" izz="100" />
        </inertial>
        <visual>
            <origin xyz="0.6340702965382699 0 0" rpy="0 0 0"/>
            <geometry>
                <box size="1.2681405930765397 2.017202326243686 2.9348950711930515" />
            </geometry>
            <material name="Blue">
                <color rgba="0 1.0 1.0 1.0"/>
            </material>
        </visual>
        <collision>
            <origin xyz="0.6340702965382699 0 0" rpy="0 0 0"/>
            <geometry>
                <box size="1.2681405930765397 2.017202326243686 2.9348950711930515" />
            </geometry>
        </collision>
    </link>
    <link name="Leg8">
        <inertial>
            <origin xyz="0 0 1.0720876019923429" rpy="0 0 0"/>
            <mass value="1" />
            <inertia ixx="100" ixy="0" ixz="0" iyy="100" iyz="0" izz="100" />
        </inertial>
        <visual>
            <origin xyz="0 0 1.0720876019923429" rpy="0 0 0"/>
            <geometry>
                <box size="1.1477730487907327 1.6231686846679916 2.1441752039846858" />
            </geometry>
            <material name="Blue">
                <color rgba="0 1.0 1.0 1.0"/>
            </material>
        </visual>
        <collision>
            <origin xyz="0 0 1.0720876019923429" rpy="0 0 0"/>
            <geometry>
                <box size="1.1477730487907327 1.6231686846679916 2.1441752039846858" />
            </geometry>
        </collision>
    </link>
    <link name="Leg9">
        <inertial>
            <origin xyz="0 0.9243475823873699 0" rpy="0 0 0"/>
            <mass value="1" />
            <inertia ixx="100" ixy="0" ixz="0" iyy="100" iyz="0" izz="100" />
        </inertial>
        <visual>
            <origin xyz="0 0.9243475823873699 0" rpy="0 0 0"/>
            <geometry>
                <box size="2.196378272050998 1.8486951647747398 2.4000650083367914" />
            </geometry>
            <material name="Blue">
                <color rgba="0 1.0 1.0 1.0"/>
            </material>
        </visual>
        <collision>
            <origin xyz="0 0.9243475823873699 0" rpy="0 0 0"/>
            <geometry>
                <box size="2.196378272050998 1.8486951647747398 2.4000650083367914" />
            </geometry>
        </collision>
    </link>
    <link name="Leg10">
        <inertial>
            <origin xyz="0.7856230616518886 0 0" rpy="0 0 0"/>
            <mass value="1" />
            <inertia ixx="100" ixy="0" ixz="0" iyy="100" iyz="0" izz="100" />
        </inertial>
        <visual>
            <origin xyz="0.7856230616518886 0 0" rpy="0 0 0"/>
            <geometry>
                <box size="1.571246123303777 2.7512795161504364 2.9476861775703553" />
            </geometry>
            <material name="Blue">
                <color rgba="0 1.0 1.0 1.0"/>
            </material>
        </visual>
        <collision>
            <origin xyz="0.7856230616518886 0 0" rpy="0 0 0"/>
            <geometry>
                <box size="1.571246123303777 2.7512795161504364 2.9476861775703553" />
            </geometry>
        </collision>
    </link>
    <link name="Leg11">
        <inertial>
            <origin xyz="0 1.361530783132105 0" rpy="0 0 0"/>
            <mass value="1" />
            <inertia ixx="100" ixy="0" ixz="0" iyy="100" iyz="0" izz="100" />
        </inertial>
        <visual>
            <origin xyz="0 1.361530783132105 0" rpy="0 0 0"/>
            <geometry>
                <box size="1.7889705215016596 2.72306156626421 2.45705334819907" />
            </geometry>
            <material name="Blue">
                <color rgba="0 1.0 1.0 1.0"/>
            </material>
        </visual>
        <collision>
            <origin xyz="0 1.361530783132105 0" rpy="0 0 0"/>
            <geometry>
                <box size="1.7889705215016596 2.72306156626421 2.45705334819907" />
            </geometry>
        </collision>
    </link>
    <link name="Leg12">
        <inertial>
            <origin xyz="1.4561998015759134 0 0" rpy="0 0 0"/>
            <mass value="1" />
            <inertia ixx="100" ixy="0" ixz="0" iyy="100" iyz="0" izz="100" />
        </inertial>
        <visual>
            <origin xyz="1.4561998015759134 0 0" rpy="0 0 0"/>
            <geometry>
                <box size="2.912399603151827 1.8729074823847138 2.986136002434923" />
            </geometry>
            <material name="Green">
                <color rgba="0 180.0 0.0 1.0"/>
            </material>
        </visual>
        <collision>
            <origin xyz="1.4561998015759134 0 0" rpy="0 0 0"/>
            <geometry>
                <box size="2.912399603151827 1.8729074823847138 2.986136002434923" />
            </geometry>
        </collision>
    </link>
    <link name="Leg13">
        <inertial>
            <origin xyz="0 0.8487214803986683 0" rpy="0 0 0"/>
            <mass value="1" />
            <inertia ixx="100" ixy="0" ixz="0" iyy="100" iyz="0" izz="100" />
        </inertial>
        <visual>
            <origin xyz="0 0.8487214803986683 0" rpy="0 0 0"/>
            <geometry>
                <box size="2.8847738586897895 1.6974429607973367 1.4444712959789519" />
            </geometry>
            <material name="Green">
                <color rgba="0 180.0 0.0 1.0"/>
            </material>
        </visual>
        <collision>
            <origin xyz="0 0.8487214803986683 0" rpy="0 0 0"/>
            <geometry>
                <box size="2.8847738586897895 1.6974429607973367 1.4444712959789519" />
            </geometry>
        </collision>
    </link>
    <link name="Leg14">
        <inertial>
            <origin xyz="0 0 1.4604488616282931" rpy="0 0 0"/>
            <mass value="1" />
            <inertia ixx="100" ixy="0" ixz="0" iyy="100" iyz="0" izz="100" />
        </inertial>
        <visual>
            <origin xyz="0 0 1.4604488616282931" rpy="0 0 0"/>
            <geometry>
                <box size="2.9264704857420316 1.7189653023859561 2.9208977232565863" />
            </geometry>
            <material name="Blue">
                <color rgba="0 1.0 1.0 1.0"/>
            </material>
        </visual>
        <collision>
            <origin xyz="0 0 1.4604488616282931" rpy="0 0 0"/>
            <geometry>
                <box size="2.9264704857420316 1.7189653023859561 2.9208977232565863" />
            </geometry>
        </collision>
    </link>
    <link name="Leg15">
        <inertial>
            <origin xyz="0 0 1.4050736449274377" rpy="0 0 0"/>
            <mass value="1" />
            <inertia ixx="100" ixy="0" ixz="0" iyy="100" iyz="0" izz="100" />
        </inertial>
        <visual>
            <origin xyz="0 0 1.4050736449274377" rpy="0 0 0"/>
            <geometry>
                <box size="1.1142400686532512 1.7369770050843591 2.8101472898548754" />
            </geometry>
            <material name="Blue">
                <color rgba="0 1.0 1.0 1.0"/>
            </material>
        </visual>
        <collision>
            <origin xyz="0 0 1.4050736449274377" rpy="0 0 0"/>
            <geometry>
                <box size="1.1142400686532512 1.7369770050843591 2.8101472898548754" />
            </geometry>
        </collision>
    </link>
    <link name="Leg16">
        <inertial>
            <origin xyz="0 0 1.1618267540786262" rpy="0 0 0"/>
            <mass value="1" />
            <inertia ixx="100" ixy="0" ixz="0" iyy="100" iyz="0" izz="100" />
        </inertial>
        <visual>
            <origin xyz="0 0 1.1618267540786262" rpy="0 0 0"/>
            <geometry>
                <box size="2.6633095517671244 1.9145507192072984 2.3236535081572525" />
            </geometry>
            <material name="Blue">
                <color rgba="0 1.0 1.0 1.0"/>
            </material>
        </visual>
        <collision>
            <origin xyz="0 0 1.1618267540786262" rpy="0 0 0"/>
            <geometry>
                <box size="2.6633095517671244 1.9145507192072984 2.3236535081572525" />
            </geometry>
        </collision>
    </link>
    <link name="Leg17">
        <inertial>
            <origin xyz="1.1638986653021053 0 0" rpy="0 0 0"/>
            <mass value="1" />
            <inertia ixx="100" ixy="0" ixz="0" iyy="100" iyz="0" izz="100" />
        </inertial>
        <visual>
            <origin xyz="1.1638986653021053 0 0" rpy="0 0 0"/>
            <geometry>
                <box size="2.3277973306042106 1.9433516906202855 2.385028381189901" />
            </geometry>
            <material name="Green">
                <color rgba="0 180.0 0.0 1.0"/>
            </material>
        </visual>
        <collision>
            <origin xyz="1.1638986653021053 0 0" rpy="0 0 0"/>
            <geometry>
                <box size="2.3277973306042106 1.9433516906202855 2.385028381189901" />
            </geometry>
        </collision>
    </link>
    <link name="Leg18">
        <inertial>
            <origin xyz="0 1.1694483761142846 0" rpy="0 0 0"/>
            <mass value="1" />
            <inertia ixx="100" ixy="0" ixz="0" iyy="100" iyz="0" izz="100" />
        </inertial>
        <visual>
            <origin xyz="0 1.1694483761142846 0" rpy="0 0 0"/>
            <geometry>
                <box size="2.816071668034682 2.3388967522285693 1.841324917934144" />
            </geometry>
            <material name="Blue">
                <color rgba="0 1.0 1.0 1.0"/>
            </material>
        </visual>
        <collision>
            <origin xyz="0 1.1694483761142846 0" rpy="0 0 0"/>
            <geometry>
                <box size="2.816071668034682 2.3388967522285693 1.841324917934144" />
            </geometry>
        </collision>
    </link>
    <link name="Leg19">
        <inertial>
            <origin xyz="0 0 0.9671480780028066" rpy="0 0 0"/>
            <mass value="1" />
            <inertia ixx="100" ixy="0" ixz="0" iyy="100" iyz="0" izz="100" />
        </inertial>
        <visual>
            <origin xyz="0 0 0.9671480780028066" rpy="0 0 0"/>
            <geometry>
                <box size="1.6046387529117185 1.3838102289497423 1.934296156005613" />
            </geometry>
            <material name="Green">
                <color rgba="0 180.0 0.0 1.0"/>
            </material>
        </visual>
        <collision>
            <origin xyz="0 0 0.9671480780028066" rpy="0 0 0"/>
            <geometry>
                <box size="1.6046387529117185 1.3838102289497423 1.934296156005613" />
            </geometry>
        </collision>
    </link>
    <link name="Leg20">
        <inertial>
            <origin xyz="1.042152222038784 0 0" rpy="0 0 0"/>
            <mass value="1" />
            <inertia ixx="100" ixy="0" ixz="0" iyy="100" iyz="0" izz="100" />
        </inertial>
        <visual>
            <origin xyz="1.042152222038784 0 0" rpy="0 0 0"/>
            <geometry>
                <box size="2.084304444077568 2.8266437005909286 1.9861939502213612" />
            </geometry>
            <material name="Green">
                <color rgba="0 180.0 0.0 1.0"/>
            </material>
        </visual>
        <collision>
            <origin xyz="1.042152222038784 0 0" rpy="0 0 0"/>
            <geometry>
                <box size="2.084304444077568 2.8266437005909286 1.9861939502213612" />
            </geometry>
        </collision>
    </link>
    <link name="Leg21">
        <inertial>
            <origin xyz="1.4982044209857026 0 0" rpy="0 0 0"/>
            <mass value="1" />
            <inertia ixx="100" ixy="0" ixz="0" iyy="100" iyz="0" izz="100" />
        </inertial>
        <visual>
            <origin xyz="1.4982044209857026 0 0" rpy="0 0 0"/>
            <geometry>
                <box size="2.9964088419714052 2.340361676062977 1.0908395702948899" />
            </geometry>
            <material name="Green">
                <color rgba="0 180.0 0.0 1.0"/>
            </material>
        </visual>
        <collision>
            <origin xyz="1.4982044209857026 0 0" rpy="0 0 0"/>
            <geometry>
                <box size="2.9964088419714052 2.340361676062977 1.0908395702948899" />
            </geometry>
        </collision>
    </link>
    <link name="Leg22">
        <inertial>
            <origin xyz="0 1.3826128226627863 0" rpy="0 0 0"/>
            <mass value="1" />
            <inertia ixx="100" ixy="0" ixz="0" iyy="100" iyz="0" izz="100" />
        </inertial>
        <visual>
            <origin xyz="0 1.3826128226627863 0" rpy="0 0 0"/>
            <geometry>
                <box size="1.5676489331061614 2.7652256453255726 1.7412121328179033" />
            </geometry>
            <material name="Green">
                <color rgba="0 180.0 0.0 1.0"/>
            </material>
        </visual>
        <collision>
            <origin xyz="0 1.3826128226627863 0" rpy="0 0 0"/>
            <geometry>
                <box size="1.5676489331061614 2.7652256453255726 1.7412121328179033" />
            </geometry>
        </collision>
    </link>
    <link name="Leg23">
        <inertial>
            <origin xyz="0 0 0.7880517534664329" rpy="0 0 0"/>
            <mass value="1" />
            <inertia ixx="100" ixy="0" ixz="0" iyy="100" iyz="0" izz="100" />
        </inertial>
        <visual>
            <origin xyz="0 0 0.7880517534664329" rpy="0 0 0"/>
            <geometry>
                <box size="2.4908631445657994 1.4443341032149812 1.5761035069328657" />
            </geometry>
            <material name="Blue">
                <color rgba="0 1.0 1.0 1.0"/>
            </material>
        </visual>
        <collision>
            <origin xyz="0 0 0.7880517534664329" rpy="0 0 0"/>
            <geometry>
                <box size="2.4908631445657994 1.4443341032149812 1.5761035069328657" />
            </geometry>
        </collision>
    </link>
    <link name="Leg24">
        <inertial>
            <origin xyz="0.5293444453539766 0 0" rpy="0 0 0"/>
            <mass value="1" />
            <inertia ixx="100" ixy="0" ixz="0" iyy="100" iyz="0" izz="100" />
        </inertial>
        <visual>
            <origin xyz="0.5293444453539766 0 0" rpy="0 0 0"/>
            <geometry>
                <box size="1.0586888907079532 1.6349417478471764 2.7909131128187212" />
            </geometry>
            <material name="Green">
                <color rgba="0 180.0 0.0 1.0"/>
            </material>
        </visual>
        <collision>
            <origin xyz="0.5293444453539766 0 0" rpy="0 0 0"/>
            <geometry>
                <box size="1.0586888907079532 1.6349417478471764 2.7909131128187212" />
            </geometry>
        </collision>
    </link>
    <link name="Leg25">
        <inertial>
            <origin xyz="0 1.0446148881837698 0" rpy="0 0 0"/>
            <mass value="1" />
            <inertia ixx="100" ixy="0" ixz="0" iyy="100" iyz="0" izz="100" />
        </inertial>
        <visual>
            <origin xyz="0 1.0446148881837698 0" rpy="0 0 0"/>
            <geometry>
                <box size="2.1129456057024774 2.0892297763675396 1.464241089035261" />
            </geometry>
            <material name="Blue">
                <color rgba="0 1.0 1.0 1.0"/>
            </material>
        </visual>
        <collision>
            <origin xyz="0 1.0446148881837698 0" rpy="0 0 0"/>
            <geometry>
                <box size="2.1129456057024774 2.0892297763675396 1.464241089035261" />
            </geometry>
        </collision>
    </link>
    <joint name="Torso_Leg1" type="revolute">
       <parent link="Torso"/>
       <child  link="Leg1"/>
       <origin rpy="0 0 0" xyz="0 1.2696666667041878 0.856101755577824" />
     <axis xyz="1 0 0"/>
       <limit effort="0.0" lower="-3.14159" upper="3.14159" velocity="0.0"/>
    </joint>
    <joint name="Torso_Leg2" type="revolute">
       <parent link="Torso"/>
       <child  link="Leg2"/>
       <origin rpy="0 0 0" xyz="1.4846467806227923 0.7139797599169466 0" />
     <axis xyz="1 0 0"/>
       <limit effort="0.0" lower="-3.14159" upper="3.14159" velocity="0.0"/>
    </joint>
    <joint name="Leg1_Leg3" type="revolute">
       <parent link="Leg1"/>
       <child  link="Leg3"/>
       <origin rpy="0 0 0" xyz="1.511665553896098 0 0" />
     <axis xyz="1 0 0"/>
       <limit effort="0.0" lower="-3.14159" upper="3.14159" velocity="0.0"/>
    </joint>
    <joint name="Leg2_Leg4" type="revolute">
       <parent link="Leg2"/>
       <child  link="Leg4"/>
       <origin rpy="0 0 0" xyz="1.123703787167842 0 0.6238156348415095" />
     <axis xyz="1 0 0"/>
       <limit effort="0.0" lower="-3.14159" upper="3.14159" velocity="0.0"/>
    </joint>
    <joint name="Leg2_Leg5" type="revolute">
       <parent link="Leg2"/>
       <child  link="Leg5"/>
       <origin rpy="0 0 0" xyz="2.247407574335684 0 0.6238156348415095" />
     <axis xyz="1 0 0"/>
       <limit effort="0.0" lower="-3.14159" upper="3.14159" velocity="0.0"/>
    </joint>
    <joint name="Torso_Leg6" type="revolute">
       <parent link="Torso"/>
       <child  link="Leg6"/>
       <origin rpy="0 0 0" xyz="1.4846467806227923 0.7139797599169466 1.3105802907700235" />
     <axis xyz="1 0 0"/>
       <limit effort="0.0" lower="-3.14159" upper="3.14159" velocity="0.0"/>
    </joint>
    <joint name="Leg3_Leg7" type="revolute">
       <parent link="Leg3"/>
       <child  link="Leg7"/>
       <origin rpy="0 0 0" xyz="0.6555060417399903 0 0.7498023964926561" />
     <axis xyz="1 0 0"/>
       <limit effort="0.0" lower="-3.14159" upper="3.14159" velocity="0.0"/>
    </joint>
    <joint name="Leg4_Leg8" type="revolute">
       <parent link="Leg4"/>
       <child  link="Leg8"/>
       <origin rpy="0 0 0" xyz="0.8688841224350785 0 0.9624990677375519" />
     <axis xyz="1 0 0"/>
       <limit effort="0.0" lower="-3.14159" upper="3.14159" velocity="0.0"/>
    </joint>
    <joint name="Leg7_Leg9" type="revolute">
       <parent link="Leg7"/>
       <child  link="Leg9"/>
       <origin rpy="0 0 0" xyz="0 0.8115843423339958 1.0720876019923429" />
     <axis xyz="1 0 0"/>
       <limit effort="0.0" lower="-3.14159" upper="3.14159" velocity="0.0"/>
    </joint>
    <joint name="Leg8_Leg10" type="revolute">
       <parent link="Leg8"/>
       <child  link="Leg10"/>
       <origin rpy="0 0 0" xyz="1.098189136025499 0.9243475823873699 0" />
     <axis xyz="1 0 0"/>
       <limit effort="0.0" lower="-3.14159" upper="3.14159" velocity="0.0"/>
    </joint>
    <joint name="Leg3_Leg11" type="revolute">
       <parent link="Leg3"/>
       <child  link="Leg11"/>
       <origin rpy="0 0 0" xyz="0.6555060417399903 0.650147914746616 0.7498023964926561" />
     <axis xyz="1 0 0"/>
       <limit effort="0.0" lower="-3.14159" upper="3.14159" velocity="0.0"/>
    </joint>
    <joint name="Leg4_Leg12" type="revolute">
       <parent link="Leg4"/>
       <child  link="Leg12"/>
       <origin rpy="0 0 0" xyz="1.737768244870157 0 0.9624990677375519" />
     <axis xyz="1 0 0"/>
       <limit effort="0.0" lower="-3.14159" upper="3.14159" velocity="0.0"/>
    </joint>
    <joint name="Leg12_Leg13" type="revolute">
       <parent link="Leg12"/>
       <child  link="Leg13"/>
       <origin rpy="0 0 0" xyz="0 1.6974429607973367 0" />
     <axis xyz="1 0 0"/>
       <limit effort="0.0" lower="-3.14159" upper="3.14159" velocity="0.0"/>
    </joint>
    <joint name="Leg5_Leg14" type="revolute">
       <parent link="Leg5"/>
       <child  link="Leg14"/>
       <origin rpy="0 0 0" xyz="0 0 1.8954411778466673" />
     <axis xyz="1 0 0"/>
       <limit effort="0.0" lower="-3.14159" upper="3.14159" velocity="0.0"/>
    </joint>
    <joint name="Leg7_Leg15" type="revolute">
       <parent link="Leg7"/>
       <child  link="Leg15"/>
       <origin rpy="0 0 0" xyz="0 0.8115843423339958 2.1441752039846858" />
     <axis xyz="1 0 0"/>
       <limit effort="0.0" lower="-3.14159" upper="3.14159" velocity="0.0"/>
    </joint>
    <joint name="Leg3_Leg16" type="revolute">
       <parent link="Leg3"/>
       <child  link="Leg16"/>
       <origin rpy="0 0 0" xyz="0.6555060417399903 0.650147914746616 1.4996047929853122" />
     <axis xyz="1 0 0"/>
       <limit effort="0.0" lower="-3.14159" upper="3.14159" velocity="0.0"/>
    </joint>
    <joint name="Leg9_Leg17" type="revolute">
       <parent link="Leg9"/>
       <child  link="Leg17"/>
       <origin rpy="0 0 0" xyz="1.571246123303777 0 0" />
     <axis xyz="1 0 0"/>
       <limit effort="0.0" lower="-3.14159" upper="3.14159" velocity="0.0"/>
    </joint>
    <joint name="Leg17_Leg18" type="revolute">
       <parent link="Leg17"/>
       <child  link="Leg18"/>
       <origin rpy="0 0 0" xyz="0 2.3388967522285693 0" />
     <axis xyz="1 0 0"/>
       <limit effort="0.0" lower="-3.14159" upper="3.14159" velocity="0.0"/>
    </joint>
    <joint name="Leg9_Leg19" type="revolute">
       <parent link="Leg9"/>
       <child  link="Leg19"/>
       <origin rpy="0 0 0" xyz="1.571246123303777 0 1.4738430887851777" />
     <axis xyz="1 0 0"/>
       <limit effort="0.0" lower="-3.14159" upper="3.14159" velocity="0.0"/>
    </joint>
    <joint name="Leg7_Leg20" type="revolute">
       <parent link="Leg7"/>
       <child  link="Leg20"/>
       <origin rpy="0 0 0" xyz="0.5738865243953664 0.8115843423339958 2.1441752039846858" />
     <axis xyz="1 0 0"/>
       <limit effort="0.0" lower="-3.14159" upper="3.14159" velocity="0.0"/>
    </joint>
    <joint name="Leg6_Leg21" type="revolute">
       <parent link="Leg6"/>
       <child  link="Leg21"/>
       <origin rpy="0 0 0" xyz="1.2681405930765397 0 0" />
     <axis xyz="1 0 0"/>
       <limit effort="0.0" lower="-3.14159" upper="3.14159" velocity="0.0"/>
    </joint>
    <joint name="Leg6_Leg22" type="revolute">
       <parent link="Leg6"/>
       <child  link="Leg22"/>
       <origin rpy="0 0 0" xyz="1.2681405930765397 1.008601163121843 0" />
     <axis xyz="1 0 0"/>
       <limit effort="0.0" lower="-3.14159" upper="3.14159" velocity="0.0"/>
    </joint>
    <joint name="Leg12_Leg23" type="revolute">
       <parent link="Leg12"/>
       <child  link="Leg23"/>
       <origin rpy="0 0 0" xyz="0 1.6974429607973367 0.7222356479894759" />
     <axis xyz="1 0 0"/>
       <limit effort="0.0" lower="-3.14159" upper="3.14159" velocity="0.0"/>
    </joint>
    <joint name="Leg19_Leg24" type="revolute">
       <parent link="Leg19"/>
       <child  link="Leg24"/>
       <origin rpy="0 0 0" xyz="2.084304444077568 0 0" />
     <axis xyz="1 0 0"/>
       <limit effort="0.0" lower="-3.14159" upper="3.14159" velocity="0.0"/>
    </joint>
    <joint name="Leg11_Leg25" type="revolute">
       <parent link="Leg11"/>
       <child  link="Leg25"/>
       <origin rpy="0 0 0" xyz="1.4561998015759134 0.9364537411923569 0" />
     <axis xyz="1 0 0"/>
       <limit effort="0.0" lower="-3.14159" upper="3.14159" velocity="0.0"/>
    </joint>
</robot>