<robot name = "robot">
    <link name="Torso">
        <inertial>
            <origin xyz="0 0 0.9019574032234249" rpy="0 0 0"/>
            <mass value="1" />
            <inertia ixx="100" ixy="0" ixz="0" iyy="100" iyz="0" izz="100" />
        </inertial>
        <visual>
            <origin xyz="0 0 0.9019574032234249" rpy="0 0 0"/>
            <geometry>
                <box size="2.2127653366463242 1.5191816699061982 1.8039148064468498" />
            </geometry>
            <material name="Green">
                <color rgba="0 180.0 0.0 1.0"/>
            </material>
        </visual>
        <collision>
            <origin xyz="0 0 0.9019574032234249" rpy="0 0 0"/>
            <geometry>
                <box size="2.2127653366463242 1.5191816699061982 1.8039148064468498" />
            </geometry>
        </collision>
    </link>
    <link name="Leg1">
        <inertial>
            <origin xyz="0.7287138449250777 0 0" rpy="0 0 0"/>
            <mass value="1" />
            <inertia ixx="100" ixy="0" ixz="0" iyy="100" iyz="0" izz="100" />
        </inertial>
        <visual>
            <origin xyz="0.7287138449250777 0 0" rpy="0 0 0"/>
            <geometry>
                <box size="1.4574276898501555 1.783104308791556 1.1216060354056838" />
            </geometry>
            <material name="Blue">
                <color rgba="0 1.0 1.0 1.0"/>
            </material>
        </visual>
        <collision>
            <origin xyz="0.7287138449250777 0 0" rpy="0 0 0"/>
            <geometry>
                <box size="1.4574276898501555 1.783104308791556 1.1216060354056838" />
            </geometry>
        </collision>
    </link>
    <link name="Leg2">
        <inertial>
            <origin xyz="0 0 0.6906762260461321" rpy="0 0 0"/>
            <mass value="1" />
            <inertia ixx="100" ixy="0" ixz="0" iyy="100" iyz="0" izz="100" />
        </inertial>
        <visual>
            <origin xyz="0 0 0.6906762260461321" rpy="0 0 0"/>
            <geometry>
                <box size="1.096445232964482 2.9394336928104132 1.3813524520922642" />
            </geometry>
            <material name="Green">
                <color rgba="0 180.0 0.0 1.0"/>
            </material>
        </visual>
        <collision>
            <origin xyz="0 0 0.6906762260461321" rpy="0 0 0"/>
            <geometry>
                <box size="1.096445232964482 2.9394336928104132 1.3813524520922642" />
            </geometry>
        </collision>
    </link>
    <link name="Leg3">
        <inertial>
            <origin xyz="1.4428537190826227 0 0" rpy="0 0 0"/>
            <mass value="1" />
            <inertia ixx="100" ixy="0" ixz="0" iyy="100" iyz="0" izz="100" />
        </inertial>
        <visual>
            <origin xyz="1.4428537190826227 0 0" rpy="0 0 0"/>
            <geometry>
                <box size="2.8857074381652454 2.088924552666063 2.4363213296855033" />
            </geometry>
            <material name="Blue">
                <color rgba="0 1.0 1.0 1.0"/>
            </material>
        </visual>
        <collision>
            <origin xyz="1.4428537190826227 0 0" rpy="0 0 0"/>
            <geometry>
                <box size="2.8857074381652454 2.088924552666063 2.4363213296855033" />
            </geometry>
        </collision>
    </link>
    <link name="Leg4">
        <inertial>
            <origin xyz="0.5823246385296207 0 0" rpy="0 0 0"/>
            <mass value="1" />
            <inertia ixx="100" ixy="0" ixz="0" iyy="100" iyz="0" izz="100" />
        </inertial>
        <visual>
            <origin xyz="0.5823246385296207 0 0" rpy="0 0 0"/>
            <geometry>
                <box size="1.1646492770592414 1.5530668802682042 2.5323604047072177" />
            </geometry>
            <material name="Blue">
                <color rgba="0 1.0 1.0 1.0"/>
            </material>
        </visual>
        <collision>
            <origin xyz="0.5823246385296207 0 0" rpy="0 0 0"/>
            <geometry>
                <box size="1.1646492770592414 1.5530668802682042 2.5323604047072177" />
            </geometry>
        </collision>
    </link>
    <link name="Leg5">
        <inertial>
            <origin xyz="0 0.9634533696091362 0" rpy="0 0 0"/>
            <mass value="1" />
            <inertia ixx="100" ixy="0" ixz="0" iyy="100" iyz="0" izz="100" />
        </inertial>
        <visual>
            <origin xyz="0 0.9634533696091362 0" rpy="0 0 0"/>
            <geometry>
                <box size="1.679315361158638 1.9269067392182724 1.5755132559014133" />
            </geometry>
            <material name="Blue">
                <color rgba="0 1.0 1.0 1.0"/>
            </material>
        </visual>
        <collision>
            <origin xyz="0 0.9634533696091362 0" rpy="0 0 0"/>
            <geometry>
                <box size="1.679315361158638 1.9269067392182724 1.5755132559014133" />
            </geometry>
        </collision>
    </link>
    <link name="Leg6">
        <inertial>
            <origin xyz="0.8512203652937659 0 0" rpy="0 0 0"/>
            <mass value="1" />
            <inertia ixx="100" ixy="0" ixz="0" iyy="100" iyz="0" izz="100" />
        </inertial>
        <visual>
            <origin xyz="0.8512203652937659 0 0" rpy="0 0 0"/>
            <geometry>
                <box size="1.7024407305875318 1.2131137038503597 1.7141335718159725" />
            </geometry>
            <material name="Blue">
                <color rgba="0 1.0 1.0 1.0"/>
            </material>
        </visual>
        <collision>
            <origin xyz="0.8512203652937659 0 0" rpy="0 0 0"/>
            <geometry>
                <box size="1.7024407305875318 1.2131137038503597 1.7141335718159725" />
            </geometry>
        </collision>
    </link>
    <link name="Leg7">
        <inertial>
            <origin xyz="1.231754427192108 0 0" rpy="0 0 0"/>
            <mass value="1" />
            <inertia ixx="100" ixy="0" ixz="0" iyy="100" iyz="0" izz="100" />
        </inertial>
        <visual>
            <origin xyz="1.231754427192108 0 0" rpy="0 0 0"/>
            <geometry>
                <box size="2.463508854384216 1.7816319451537936 1.2849918701470786" />
            </geometry>
            <material name="Blue">
                <color rgba="0 1.0 1.0 1.0"/>
            </material>
        </visual>
        <collision>
            <origin xyz="1.231754427192108 0 0" rpy="0 0 0"/>
            <geometry>
                <box size="2.463508854384216 1.7816319451537936 1.2849918701470786" />
            </geometry>
        </collision>
    </link>
    <link name="Leg8">
        <inertial>
            <origin xyz="1.321368226107953 0 0" rpy="0 0 0"/>
            <mass value="1" />
            <inertia ixx="100" ixy="0" ixz="0" iyy="100" iyz="0" izz="100" />
        </inertial>
        <visual>
            <origin xyz="1.321368226107953 0 0" rpy="0 0 0"/>
            <geometry>
                <box size="2.642736452215906 1.4729831480456503 2.313194953633254" />
            </geometry>
            <material name="Blue">
                <color rgba="0 1.0 1.0 1.0"/>
            </material>
        </visual>
        <collision>
            <origin xyz="1.321368226107953 0 0" rpy="0 0 0"/>
            <geometry>
                <box size="2.642736452215906 1.4729831480456503 2.313194953633254" />
            </geometry>
        </collision>
    </link>
    <link name="Leg9">
        <inertial>
            <origin xyz="0 0.8621050341642376 0" rpy="0 0 0"/>
            <mass value="1" />
            <inertia ixx="100" ixy="0" ixz="0" iyy="100" iyz="0" izz="100" />
        </inertial>
        <visual>
            <origin xyz="0 0.8621050341642376 0" rpy="0 0 0"/>
            <geometry>
                <box size="1.7544432062133812 1.7242100683284751 2.746475599079247" />
            </geometry>
            <material name="Green">
                <color rgba="0 180.0 0.0 1.0"/>
            </material>
        </visual>
        <collision>
            <origin xyz="0 0.8621050341642376 0" rpy="0 0 0"/>
            <geometry>
                <box size="1.7544432062133812 1.7242100683284751 2.746475599079247" />
            </geometry>
        </collision>
    </link>
    <link name="Leg10">
        <inertial>
            <origin xyz="0 0 0.5107043488813244" rpy="0 0 0"/>
            <mass value="1" />
            <inertia ixx="100" ixy="0" ixz="0" iyy="100" iyz="0" izz="100" />
        </inertial>
        <visual>
            <origin xyz="0 0 0.5107043488813244" rpy="0 0 0"/>
            <geometry>
                <box size="2.5923828871252184 2.9631989499571407 1.0214086977626489" />
            </geometry>
            <material name="Blue">
                <color rgba="0 1.0 1.0 1.0"/>
            </material>
        </visual>
        <collision>
            <origin xyz="0 0 0.5107043488813244" rpy="0 0 0"/>
            <geometry>
                <box size="2.5923828871252184 2.9631989499571407 1.0214086977626489" />
            </geometry>
        </collision>
    </link>
    <link name="Leg11">
        <inertial>
            <origin xyz="1.267659198296744 0 0" rpy="0 0 0"/>
            <mass value="1" />
            <inertia ixx="100" ixy="0" ixz="0" iyy="100" iyz="0" izz="100" />
        </inertial>
        <visual>
            <origin xyz="1.267659198296744 0 0" rpy="0 0 0"/>
            <geometry>
                <box size="2.535318396593488 1.3675242161707357 1.1289074672830504" />
            </geometry>
            <material name="Blue">
                <color rgba="0 1.0 1.0 1.0"/>
            </material>
        </visual>
        <collision>
            <origin xyz="1.267659198296744 0 0" rpy="0 0 0"/>
            <geometry>
                <box size="2.535318396593488 1.3675242161707357 1.1289074672830504" />
            </geometry>
        </collision>
    </link>
    <link name="Leg12">
        <inertial>
            <origin xyz="0 0 1.1490108193785868" rpy="0 0 0"/>
            <mass value="1" />
            <inertia ixx="100" ixy="0" ixz="0" iyy="100" iyz="0" izz="100" />
        </inertial>
        <visual>
            <origin xyz="0 0 1.1490108193785868" rpy="0 0 0"/>
            <geometry>
                <box size="1.4249718214433618 1.5752706253425621 2.2980216387571737" />
            </geometry>
            <material name="Blue">
                <color rgba="0 1.0 1.0 1.0"/>
            </material>
        </visual>
        <collision>
            <origin xyz="0 0 1.1490108193785868" rpy="0 0 0"/>
            <geometry>
                <box size="1.4249718214433618 1.5752706253425621 2.2980216387571737" />
            </geometry>
        </collision>
    </link>
    <link name="Leg13">
        <inertial>
            <origin xyz="0 0.8569176913744385 0" rpy="0 0 0"/>
            <mass value="1" />
            <inertia ixx="100" ixy="0" ixz="0" iyy="100" iyz="0" izz="100" />
        </inertial>
        <visual>
            <origin xyz="0 0.8569176913744385 0" rpy="0 0 0"/>
            <geometry>
                <box size="1.5726294209784548 1.713835382748877 1.5541302876377183" />
            </geometry>
            <material name="Green">
                <color rgba="0 180.0 0.0 1.0"/>
            </material>
        </visual>
        <collision>
            <origin xyz="0 0.8569176913744385 0" rpy="0 0 0"/>
            <geometry>
                <box size="1.5726294209784548 1.713835382748877 1.5541302876377183" />
            </geometry>
        </collision>
    </link>
    <link name="Leg14">
        <inertial>
            <origin xyz="0 0 0.8723130149415674" rpy="0 0 0"/>
            <mass value="1" />
            <inertia ixx="100" ixy="0" ixz="0" iyy="100" iyz="0" izz="100" />
        </inertial>
        <visual>
            <origin xyz="0 0 0.8723130149415674" rpy="0 0 0"/>
            <geometry>
                <box size="1.5172947176477545 1.2083967615282987 1.7446260298831349" />
            </geometry>
            <material name="Blue">
                <color rgba="0 1.0 1.0 1.0"/>
            </material>
        </visual>
        <collision>
            <origin xyz="0 0 0.8723130149415674" rpy="0 0 0"/>
            <geometry>
                <box size="1.5172947176477545 1.2083967615282987 1.7446260298831349" />
            </geometry>
        </collision>
    </link>
    <link name="Leg15">
        <inertial>
            <origin xyz="0.8119087333605847 0 0" rpy="0 0 0"/>
            <mass value="1" />
            <inertia ixx="100" ixy="0" ixz="0" iyy="100" iyz="0" izz="100" />
        </inertial>
        <visual>
            <origin xyz="0.8119087333605847 0 0" rpy="0 0 0"/>
            <geometry>
                <box size="1.6238174667211693 1.1838118514992384 2.4965694463623205" />
            </geometry>
            <material name="Green">
                <color rgba="0 180.0 0.0 1.0"/>
            </material>
        </visual>
        <collision>
            <origin xyz="0.8119087333605847 0 0" rpy="0 0 0"/>
            <geometry>
                <box size="1.6238174667211693 1.1838118514992384 2.4965694463623205" />
            </geometry>
        </collision>
    </link>
    <link name="Leg16">
        <inertial>
            <origin xyz="0 0.8883648494664826 0" rpy="0 0 0"/>
            <mass value="1" />
            <inertia ixx="100" ixy="0" ixz="0" iyy="100" iyz="0" izz="100" />
        </inertial>
        <visual>
            <origin xyz="0 0.8883648494664826 0" rpy="0 0 0"/>
            <geometry>
                <box size="1.1226193373301132 1.7767296989329653 1.6105958630431367" />
            </geometry>
            <material name="Blue">
                <color rgba="0 1.0 1.0 1.0"/>
            </material>
        </visual>
        <collision>
            <origin xyz="0 0.8883648494664826 0" rpy="0 0 0"/>
            <geometry>
                <box size="1.1226193373301132 1.7767296989329653 1.6105958630431367" />
            </geometry>
        </collision>
    </link>
    <link name="Leg17">
        <inertial>
            <origin xyz="0 0 0.9915542831724595" rpy="0 0 0"/>
            <mass value="1" />
            <inertia ixx="100" ixy="0" ixz="0" iyy="100" iyz="0" izz="100" />
        </inertial>
        <visual>
            <origin xyz="0 0 0.9915542831724595" rpy="0 0 0"/>
            <geometry>
                <box size="1.6652704675928562 1.7888437604044927 1.983108566344919" />
            </geometry>
            <material name="Blue">
                <color rgba="0 1.0 1.0 1.0"/>
            </material>
        </visual>
        <collision>
            <origin xyz="0 0 0.9915542831724595" rpy="0 0 0"/>
            <geometry>
                <box size="1.6652704675928562 1.7888437604044927 1.983108566344919" />
            </geometry>
        </collision>
    </link>
    <link name="Leg18">
        <inertial>
            <origin xyz="0 1.250613970353831 0" rpy="0 0 0"/>
            <mass value="1" />
            <inertia ixx="100" ixy="0" ixz="0" iyy="100" iyz="0" izz="100" />
        </inertial>
        <visual>
            <origin xyz="0 1.250613970353831 0" rpy="0 0 0"/>
            <geometry>
                <box size="1.9906128357995314 2.501227940707662 2.8738905213511603" />
            </geometry>
            <material name="Blue">
                <color rgba="0 1.0 1.0 1.0"/>
            </material>
        </visual>
        <collision>
            <origin xyz="0 1.250613970353831 0" rpy="0 0 0"/>
            <geometry>
                <box size="1.9906128357995314 2.501227940707662 2.8738905213511603" />
            </geometry>
        </collision>
    </link>
    <link name="Leg19">
        <inertial>
            <origin xyz="0 1.056684696929572 0" rpy="0 0 0"/>
            <mass value="1" />
            <inertia ixx="100" ixy="0" ixz="0" iyy="100" iyz="0" izz="100" />
        </inertial>
        <visual>
            <origin xyz="0 1.056684696929572 0" rpy="0 0 0"/>
            <geometry>
                <box size="2.1311616994266407 2.113369393859144 1.3414726227484883" />
            </geometry>
            <material name="Blue">
                <color rgba="0 1.0 1.0 1.0"/>
            </material>
        </visual>
        <collision>
            <origin xyz="0 1.056684696929572 0" rpy="0 0 0"/>
            <geometry>
                <box size="2.1311616994266407 2.113369393859144 1.3414726227484883" />
            </geometry>
        </collision>
    </link>
    <link name="Leg20">
        <inertial>
            <origin xyz="0.9672328022079139 0 0" rpy="0 0 0"/>
            <mass value="1" />
            <inertia ixx="100" ixy="0" ixz="0" iyy="100" iyz="0" izz="100" />
        </inertial>
        <visual>
            <origin xyz="0.9672328022079139 0 0" rpy="0 0 0"/>
            <geometry>
                <box size="1.9344656044158277 1.6261022272968637 2.8870995598582727" />
            </geometry>
            <material name="Blue">
                <color rgba="0 1.0 1.0 1.0"/>
            </material>
        </visual>
        <collision>
            <origin xyz="0.9672328022079139 0 0" rpy="0 0 0"/>
            <geometry>
                <box size="1.9344656044158277 1.6261022272968637 2.8870995598582727" />
            </geometry>
        </collision>
    </link>
    <link name="Leg21">
        <inertial>
            <origin xyz="0 1.2324750250271466 0" rpy="0 0 0"/>
            <mass value="1" />
            <inertia ixx="100" ixy="0" ixz="0" iyy="100" iyz="0" izz="100" />
        </inertial>
        <visual>
            <origin xyz="0 1.2324750250271466 0" rpy="0 0 0"/>
            <geometry>
                <box size="1.9307353272967336 2.464950050054293 2.390860721708595" />
            </geometry>
            <material name="Green">
                <color rgba="0 180.0 0.0 1.0"/>
            </material>
        </visual>
        <collision>
            <origin xyz="0 1.2324750250271466 0" rpy="0 0 0"/>
            <geometry>
                <box size="1.9307353272967336 2.464950050054293 2.390860721708595" />
            </geometry>
        </collision>
    </link>
    <link name="Leg22">
        <inertial>
            <origin xyz="0 0.965749308283585 0" rpy="0 0 0"/>
            <mass value="1" />
            <inertia ixx="100" ixy="0" ixz="0" iyy="100" iyz="0" izz="100" />
        </inertial>
        <visual>
            <origin xyz="0 0.965749308283585 0" rpy="0 0 0"/>
            <geometry>
                <box size="2.325965593514437 1.93149861656717 1.419560108037303" />
            </geometry>
            <material name="Green">
                <color rgba="0 180.0 0.0 1.0"/>
            </material>
        </visual>
        <collision>
            <origin xyz="0 0.965749308283585 0" rpy="0 0 0"/>
            <geometry>
                <box size="2.325965593514437 1.93149861656717 1.419560108037303" />
            </geometry>
        </collision>
    </link>
    <link name="Leg23">
        <inertial>
            <origin xyz="1.0893646256841674 0 0" rpy="0 0 0"/>
            <mass value="1" />
            <inertia ixx="100" ixy="0" ixz="0" iyy="100" iyz="0" izz="100" />
        </inertial>
        <visual>
            <origin xyz="1.0893646256841674 0 0" rpy="0 0 0"/>
            <geometry>
                <box size="2.1787292513683347 2.7760496109349906 1.2892756627575566" />
            </geometry>
            <material name="Green">
                <color rgba="0 180.0 0.0 1.0"/>
            </material>
        </visual>
        <collision>
            <origin xyz="1.0893646256841674 0 0" rpy="0 0 0"/>
            <geometry>
                <box size="2.1787292513683347 2.7760496109349906 1.2892756627575566" />
            </geometry>
        </collision>
    </link>
    <link name="Leg24">
        <inertial>
            <origin xyz="0 0 1.3506773344147462" rpy="0 0 0"/>
            <mass value="1" />
            <inertia ixx="100" ixy="0" ixz="0" iyy="100" iyz="0" izz="100" />
        </inertial>
        <visual>
            <origin xyz="0 0 1.3506773344147462" rpy="0 0 0"/>
            <geometry>
                <box size="1.0184326516019906 1.0752057633422767 2.7013546688294925" />
            </geometry>
            <material name="Blue">
                <color rgba="0 1.0 1.0 1.0"/>
            </material>
        </visual>
        <collision>
            <origin xyz="0 0 1.3506773344147462" rpy="0 0 0"/>
            <geometry>
                <box size="1.0184326516019906 1.0752057633422767 2.7013546688294925" />
            </geometry>
        </collision>
    </link>
    <link name="Leg25">
        <inertial>
            <origin xyz="0 0 1.0361272560042947" rpy="0 0 0"/>
            <mass value="1" />
            <inertia ixx="100" ixy="0" ixz="0" iyy="100" iyz="0" izz="100" />
        </inertial>
        <visual>
            <origin xyz="0 0 1.0361272560042947" rpy="0 0 0"/>
            <geometry>
                <box size="1.203556989780756 2.47564988607411 2.0722545120085893" />
            </geometry>
            <material name="Green">
                <color rgba="0 180.0 0.0 1.0"/>
            </material>
        </visual>
        <collision>
            <origin xyz="0 0 1.0361272560042947" rpy="0 0 0"/>
            <geometry>
                <box size="1.203556989780756 2.47564988607411 2.0722545120085893" />
            </geometry>
        </collision>
    </link>
    <link name="Leg26">
        <inertial>
            <origin xyz="1.4438590737112922 0 0" rpy="0 0 0"/>
            <mass value="1" />
            <inertia ixx="100" ixy="0" ixz="0" iyy="100" iyz="0" izz="100" />
        </inertial>
        <visual>
            <origin xyz="1.4438590737112922 0 0" rpy="0 0 0"/>
            <geometry>
                <box size="2.8877181474225844 2.05918707129758 2.576727397355988" />
            </geometry>
            <material name="Blue">
                <color rgba="0 1.0 1.0 1.0"/>
            </material>
        </visual>
        <collision>
            <origin xyz="1.4438590737112922 0 0" rpy="0 0 0"/>
            <geometry>
                <box size="2.8877181474225844 2.05918707129758 2.576727397355988" />
            </geometry>
        </collision>
    </link>
    <joint name="Torso_Leg1" type="revolute">
       <parent link="Torso"/>
       <child  link="Leg1"/>
       <origin rpy="0 0 0" xyz="1.1063826683231621 0 0.9019574032234249" />
     <axis xyz="1 0 0"/>
       <limit effort="0.0" lower="-3.14159" upper="3.14159" velocity="0.0"/>
    </joint>
    <joint name="Leg1_Leg2" type="revolute">
       <parent link="Leg1"/>
       <child  link="Leg2"/>
       <origin rpy="0 0 0" xyz="0 0 1.3813524520922642" />
     <axis xyz="1 0 0"/>
       <limit effort="0.0" lower="-3.14159" upper="3.14159" velocity="0.0"/>
    </joint>
    <joint name="Leg1_Leg3" type="revolute">
       <parent link="Leg1"/>
       <child  link="Leg3"/>
       <origin rpy="0 0 0" xyz="0.548222616482241 0 1.3813524520922642" />
     <axis xyz="1 0 0"/>
       <limit effort="0.0" lower="-3.14159" upper="3.14159" velocity="0.0"/>
    </joint>
    <joint name="Leg3_Leg4" type="revolute">
       <parent link="Leg3"/>
       <child  link="Leg4"/>
       <origin rpy="0 0 0" xyz="1.1646492770592414 0 0" />
     <axis xyz="1 0 0"/>
       <limit effort="0.0" lower="-3.14159" upper="3.14159" velocity="0.0"/>
    </joint>
    <joint name="Leg4_Leg5" type="revolute">
       <parent link="Leg4"/>
       <child  link="Leg5"/>
       <origin rpy="0 0 0" xyz="0 1.9269067392182724 0" />
     <axis xyz="1 0 0"/>
       <limit effort="0.0" lower="-3.14159" upper="3.14159" velocity="0.0"/>
    </joint>
    <joint name="Leg5_Leg6" type="revolute">
       <parent link="Leg5"/>
       <child  link="Leg6"/>
       <origin rpy="0 0 0" xyz="1.7024407305875318 0 0" />
     <axis xyz="1 0 0"/>
       <limit effort="0.0" lower="-3.14159" upper="3.14159" velocity="0.0"/>
    </joint>
    <joint name="Leg6_Leg7" type="revolute">
       <parent link="Leg6"/>
       <child  link="Leg7"/>
       <origin rpy="0 0 0" xyz="2.463508854384216 0 0" />
     <axis xyz="1 0 0"/>
       <limit effort="0.0" lower="-3.14159" upper="3.14159" velocity="0.0"/>
    </joint>
    <joint name="Leg2_Leg8" type="revolute">
       <parent link="Leg2"/>
       <child  link="Leg8"/>
       <origin rpy="0 0 0" xyz="2.8857074381652454 0 0" />
     <axis xyz="1 0 0"/>
       <limit effort="0.0" lower="-3.14159" upper="3.14159" velocity="0.0"/>
    </joint>
    <joint name="Leg5_Leg9" type="revolute">
       <parent link="Leg5"/>
       <child  link="Leg9"/>
       <origin rpy="0 0 0" xyz="1.7024407305875318 0.6065568519251798 0" />
     <axis xyz="1 0 0"/>
       <limit effort="0.0" lower="-3.14159" upper="3.14159" velocity="0.0"/>
    </joint>
    <joint name="Leg4_Leg10" type="revolute">
       <parent link="Leg4"/>
       <child  link="Leg10"/>
       <origin rpy="0 0 0" xyz="0 1.9269067392182724 0.7877566279507067" />
     <axis xyz="1 0 0"/>
       <limit effort="0.0" lower="-3.14159" upper="3.14159" velocity="0.0"/>
    </joint>
    <joint name="Leg10_Leg11" type="revolute">
       <parent link="Leg10"/>
       <child  link="Leg11"/>
       <origin rpy="0 0 0" xyz="2.535318396593488 0 0" />
     <axis xyz="1 0 0"/>
       <limit effort="0.0" lower="-3.14159" upper="3.14159" velocity="0.0"/>
    </joint>
    <joint name="Leg8_Leg12" type="revolute">
       <parent link="Leg8"/>
       <child  link="Leg12"/>
       <origin rpy="0 0 0" xyz="0 0.8621050341642376 1.3732377995396234" />
     <axis xyz="1 0 0"/>
       <limit effort="0.0" lower="-3.14159" upper="3.14159" velocity="0.0"/>
    </joint>
    <joint name="Torso_Leg13" type="revolute">
       <parent link="Torso"/>
       <child  link="Leg13"/>
       <origin rpy="0 0 0" xyz="0.7287138449250777 0.891552154395778 0" />
     <axis xyz="1 0 0"/>
       <limit effort="0.0" lower="-3.14159" upper="3.14159" velocity="0.0"/>
    </joint>
    <joint name="Leg7_Leg14" type="revolute">
       <parent link="Leg7"/>
       <child  link="Leg14"/>
       <origin rpy="0 0 0" xyz="1.321368226107953 0 1.156597476816627" />
     <axis xyz="1 0 0"/>
       <limit effort="0.0" lower="-3.14159" upper="3.14159" velocity="0.0"/>
    </joint>
    <joint name="Leg13_Leg15" type="revolute">
       <parent link="Leg13"/>
       <child  link="Leg15"/>
       <origin rpy="0 0 0" xyz="0.7586473588238772 0 0.8723130149415674" />
     <axis xyz="1 0 0"/>
       <limit effort="0.0" lower="-3.14159" upper="3.14159" velocity="0.0"/>
    </joint>
    <joint name="Leg15_Leg16" type="revolute">
       <parent link="Leg15"/>
       <child  link="Leg16"/>
       <origin rpy="0 0 0" xyz="0 1.7767296989329653 0" />
     <axis xyz="1 0 0"/>
       <limit effort="0.0" lower="-3.14159" upper="3.14159" velocity="0.0"/>
    </joint>
    <joint name="Leg5_Leg17" type="revolute">
       <parent link="Leg5"/>
       <child  link="Leg17"/>
       <origin rpy="0 0 0" xyz="1.7024407305875318 0.6065568519251798 0.8570667859079862" />
     <axis xyz="1 0 0"/>
       <limit effort="0.0" lower="-3.14159" upper="3.14159" velocity="0.0"/>
    </joint>
    <joint name="Leg12_Leg18" type="revolute">
       <parent link="Leg12"/>
       <child  link="Leg18"/>
       <origin rpy="0 0 0" xyz="0 1.713835382748877 0" />
     <axis xyz="1 0 0"/>
       <limit effort="0.0" lower="-3.14159" upper="3.14159" velocity="0.0"/>
    </joint>
    <joint name="Leg17_Leg19" type="revolute">
       <parent link="Leg17"/>
       <child  link="Leg19"/>
       <origin rpy="0 0 0" xyz="0 2.501227940707662 0" />
     <axis xyz="1 0 0"/>
       <limit effort="0.0" lower="-3.14159" upper="3.14159" velocity="0.0"/>
    </joint>
    <joint name="Leg14_Leg20" type="revolute">
       <parent link="Leg14"/>
       <child  link="Leg20"/>
       <origin rpy="0 0 0" xyz="1.6238174667211693 0 0" />
     <axis xyz="1 0 0"/>
       <limit effort="0.0" lower="-3.14159" upper="3.14159" velocity="0.0"/>
    </joint>
    <joint name="Leg2_Leg21" type="revolute">
       <parent link="Leg2"/>
       <child  link="Leg21"/>
       <origin rpy="0 0 0" xyz="2.8857074381652454 1.0444622763330316 0" />
     <axis xyz="1 0 0"/>
       <limit effort="0.0" lower="-3.14159" upper="3.14159" velocity="0.0"/>
    </joint>
    <joint name="Leg8_Leg22" type="revolute">
       <parent link="Leg8"/>
       <child  link="Leg22"/>
       <origin rpy="0 0 0" xyz="0 1.7242100683284751 1.3732377995396234" />
     <axis xyz="1 0 0"/>
       <limit effort="0.0" lower="-3.14159" upper="3.14159" velocity="0.0"/>
    </joint>
    <joint name="Leg21_Leg23" type="revolute">
       <parent link="Leg21"/>
       <child  link="Leg23"/>
       <origin rpy="0 0 0" xyz="1.1629827967572186 0.965749308283585 0" />
     <axis xyz="1 0 0"/>
       <limit effort="0.0" lower="-3.14159" upper="3.14159" velocity="0.0"/>
    </joint>
    <joint name="Leg12_Leg24" type="revolute">
       <parent link="Leg12"/>
       <child  link="Leg24"/>
       <origin rpy="0 0 0" xyz="0 1.713835382748877 0.7770651438188592" />
     <axis xyz="1 0 0"/>
       <limit effort="0.0" lower="-3.14159" upper="3.14159" velocity="0.0"/>
    </joint>
    <joint name="Leg22_Leg25" type="revolute">
       <parent link="Leg22"/>
       <child  link="Leg25"/>
       <origin rpy="0 0 0" xyz="1.0893646256841674 0 0.6446378313787783" />
     <axis xyz="1 0 0"/>
       <limit effort="0.0" lower="-3.14159" upper="3.14159" velocity="0.0"/>
    </joint>
    <joint name="Leg12_Leg26" type="revolute">
       <parent link="Leg12"/>
       <child  link="Leg26"/>
       <origin rpy="0 0 0" xyz="0.7863147104892274 1.713835382748877 0.7770651438188592" />
     <axis xyz="1 0 0"/>
       <limit effort="0.0" lower="-3.14159" upper="3.14159" velocity="0.0"/>
    </joint>
</robot>