<robot name = "robot">
    <link name="Torso">
        <inertial>
            <origin xyz="0 0 1.339315540266301" rpy="0 0 0"/>
            <mass value="1" />
            <inertia ixx="100" ixy="0" ixz="0" iyy="100" iyz="0" izz="100" />
        </inertial>
        <visual>
            <origin xyz="0 0 1.339315540266301" rpy="0 0 0"/>
            <geometry>
                <box size="1.3260110295246215 2.7231774907013335 2.678631080532602" />
            </geometry>
            <material name="Green">
                <color rgba="0 180.0 0.0 1.0"/>
            </material>
        </visual>
        <collision>
            <origin xyz="0 0 1.339315540266301" rpy="0 0 0"/>
            <geometry>
                <box size="1.3260110295246215 2.7231774907013335 2.678631080532602" />
            </geometry>
        </collision>
    </link>
    <link name="Leg1">
        <inertial>
            <origin xyz="0.6779812415155053 0 0" rpy="0 0 0"/>
            <mass value="1" />
            <inertia ixx="100" ixy="0" ixz="0" iyy="100" iyz="0" izz="100" />
        </inertial>
        <visual>
            <origin xyz="0.6779812415155053 0 0" rpy="0 0 0"/>
            <geometry>
                <box size="1.3559624830310106 1.5675878615326622 1.19128519615515" />
            </geometry>
            <material name="Green">
                <color rgba="0 180.0 0.0 1.0"/>
            </material>
        </visual>
        <collision>
            <origin xyz="0.6779812415155053 0 0" rpy="0 0 0"/>
            <geometry>
                <box size="1.3559624830310106 1.5675878615326622 1.19128519615515" />
            </geometry>
        </collision>
    </link>
    <link name="Leg2">
        <inertial>
            <origin xyz="0.7211295293166372 0 0" rpy="0 0 0"/>
            <mass value="1" />
            <inertia ixx="100" ixy="0" ixz="0" iyy="100" iyz="0" izz="100" />
        </inertial>
        <visual>
            <origin xyz="0.7211295293166372 0 0" rpy="0 0 0"/>
            <geometry>
                <box size="1.4422590586332744 2.128408016681411 2.7977536479601173" />
            </geometry>
            <material name="Green">
                <color rgba="0 180.0 0.0 1.0"/>
            </material>
        </visual>
        <collision>
            <origin xyz="0.7211295293166372 0 0" rpy="0 0 0"/>
            <geometry>
                <box size="1.4422590586332744 2.128408016681411 2.7977536479601173" />
            </geometry>
        </collision>
    </link>
    <link name="Leg3">
        <inertial>
            <origin xyz="0 0.9105719339304402 0" rpy="0 0 0"/>
            <mass value="1" />
            <inertia ixx="100" ixy="0" ixz="0" iyy="100" iyz="0" izz="100" />
        </inertial>
        <visual>
            <origin xyz="0 0.9105719339304402 0" rpy="0 0 0"/>
            <geometry>
                <box size="1.250769347111138 1.8211438678608804 1.9043764579306832" />
            </geometry>
            <material name="Green">
                <color rgba="0 180.0 0.0 1.0"/>
            </material>
        </visual>
        <collision>
            <origin xyz="0 0.9105719339304402 0" rpy="0 0 0"/>
            <geometry>
                <box size="1.250769347111138 1.8211438678608804 1.9043764579306832" />
            </geometry>
        </collision>
    </link>
    <link name="Leg4">
        <inertial>
            <origin xyz="0 0 0.9751728032525169" rpy="0 0 0"/>
            <mass value="1" />
            <inertia ixx="100" ixy="0" ixz="0" iyy="100" iyz="0" izz="100" />
        </inertial>
        <visual>
            <origin xyz="0 0 0.9751728032525169" rpy="0 0 0"/>
            <geometry>
                <box size="1.9044503778174715 1.7196319027519047 1.9503456065050337" />
            </geometry>
            <material name="Green">
                <color rgba="0 180.0 0.0 1.0"/>
            </material>
        </visual>
        <collision>
            <origin xyz="0 0 0.9751728032525169" rpy="0 0 0"/>
            <geometry>
                <box size="1.9044503778174715 1.7196319027519047 1.9503456065050337" />
            </geometry>
        </collision>
    </link>
    <link name="Leg5">
        <inertial>
            <origin xyz="0.8201877039135406 0 0" rpy="0 0 0"/>
            <mass value="1" />
            <inertia ixx="100" ixy="0" ixz="0" iyy="100" iyz="0" izz="100" />
        </inertial>
        <visual>
            <origin xyz="0.8201877039135406 0 0" rpy="0 0 0"/>
            <geometry>
                <box size="1.6403754078270811 2.4917214068988756 2.859558372074208" />
            </geometry>
            <material name="Blue">
                <color rgba="0 1.0 1.0 1.0"/>
            </material>
        </visual>
        <collision>
            <origin xyz="0.8201877039135406 0 0" rpy="0 0 0"/>
            <geometry>
                <box size="1.6403754078270811 2.4917214068988756 2.859558372074208" />
            </geometry>
        </collision>
    </link>
    <link name="Leg6">
        <inertial>
            <origin xyz="0 1.114530745023054 0" rpy="0 0 0"/>
            <mass value="1" />
            <inertia ixx="100" ixy="0" ixz="0" iyy="100" iyz="0" izz="100" />
        </inertial>
        <visual>
            <origin xyz="0 1.114530745023054 0" rpy="0 0 0"/>
            <geometry>
                <box size="1.1483593998154584 2.229061490046108 1.226229492736214" />
            </geometry>
            <material name="Blue">
                <color rgba="0 1.0 1.0 1.0"/>
            </material>
        </visual>
        <collision>
            <origin xyz="0 1.114530745023054 0" rpy="0 0 0"/>
            <geometry>
                <box size="1.1483593998154584 2.229061490046108 1.226229492736214" />
            </geometry>
        </collision>
    </link>
    <link name="Leg7">
        <inertial>
            <origin xyz="0 1.2433361753306382 0" rpy="0 0 0"/>
            <mass value="1" />
            <inertia ixx="100" ixy="0" ixz="0" iyy="100" iyz="0" izz="100" />
        </inertial>
        <visual>
            <origin xyz="0 1.2433361753306382 0" rpy="0 0 0"/>
            <geometry>
                <box size="1.9208033890755773 2.4866723506612765 1.4041371989194984" />
            </geometry>
            <material name="Blue">
                <color rgba="0 1.0 1.0 1.0"/>
            </material>
        </visual>
        <collision>
            <origin xyz="0 1.2433361753306382 0" rpy="0 0 0"/>
            <geometry>
                <box size="1.9208033890755773 2.4866723506612765 1.4041371989194984" />
            </geometry>
        </collision>
    </link>
    <link name="Leg8">
        <inertial>
            <origin xyz="0 0 1.0824272547041276" rpy="0 0 0"/>
            <mass value="1" />
            <inertia ixx="100" ixy="0" ixz="0" iyy="100" iyz="0" izz="100" />
        </inertial>
        <visual>
            <origin xyz="0 0 1.0824272547041276" rpy="0 0 0"/>
            <geometry>
                <box size="2.1669777057358806 2.6500664188424228 2.164854509408255" />
            </geometry>
            <material name="Blue">
                <color rgba="0 1.0 1.0 1.0"/>
            </material>
        </visual>
        <collision>
            <origin xyz="0 0 1.0824272547041276" rpy="0 0 0"/>
            <geometry>
                <box size="2.1669777057358806 2.6500664188424228 2.164854509408255" />
            </geometry>
        </collision>
    </link>
    <link name="Leg9">
        <inertial>
            <origin xyz="0 0 1.2744183348079086" rpy="0 0 0"/>
            <mass value="1" />
            <inertia ixx="100" ixy="0" ixz="0" iyy="100" iyz="0" izz="100" />
        </inertial>
        <visual>
            <origin xyz="0 0 1.2744183348079086" rpy="0 0 0"/>
            <geometry>
                <box size="1.3613768456785726 1.7306806591627935 2.548836669615817" />
            </geometry>
            <material name="Green">
                <color rgba="0 180.0 0.0 1.0"/>
            </material>
        </visual>
        <collision>
            <origin xyz="0 0 1.2744183348079086" rpy="0 0 0"/>
            <geometry>
                <box size="1.3613768456785726 1.7306806591627935 2.548836669615817" />
            </geometry>
        </collision>
    </link>
    <link name="Leg10">
        <inertial>
            <origin xyz="1.2494577421482012 0 0" rpy="0 0 0"/>
            <mass value="1" />
            <inertia ixx="100" ixy="0" ixz="0" iyy="100" iyz="0" izz="100" />
        </inertial>
        <visual>
            <origin xyz="1.2494577421482012 0 0" rpy="0 0 0"/>
            <geometry>
                <box size="2.4989154842964023 2.9036050875340114 2.370929069644381" />
            </geometry>
            <material name="Green">
                <color rgba="0 180.0 0.0 1.0"/>
            </material>
        </visual>
        <collision>
            <origin xyz="1.2494577421482012 0 0" rpy="0 0 0"/>
            <geometry>
                <box size="2.4989154842964023 2.9036050875340114 2.370929069644381" />
            </geometry>
        </collision>
    </link>
    <link name="Leg11">
        <inertial>
            <origin xyz="0.8737538675921002 0 0" rpy="0 0 0"/>
            <mass value="1" />
            <inertia ixx="100" ixy="0" ixz="0" iyy="100" iyz="0" izz="100" />
        </inertial>
        <visual>
            <origin xyz="0.8737538675921002 0 0" rpy="0 0 0"/>
            <geometry>
                <box size="1.7475077351842003 2.570696019985615 2.944621105905152" />
            </geometry>
            <material name="Blue">
                <color rgba="0 1.0 1.0 1.0"/>
            </material>
        </visual>
        <collision>
            <origin xyz="0.8737538675921002 0 0" rpy="0 0 0"/>
            <geometry>
                <box size="1.7475077351842003 2.570696019985615 2.944621105905152" />
            </geometry>
        </collision>
    </link>
    <link name="Leg12">
        <inertial>
            <origin xyz="0 1.2598067071334431 0" rpy="0 0 0"/>
            <mass value="1" />
            <inertia ixx="100" ixy="0" ixz="0" iyy="100" iyz="0" izz="100" />
        </inertial>
        <visual>
            <origin xyz="0 1.2598067071334431 0" rpy="0 0 0"/>
            <geometry>
                <box size="1.8450813048101284 2.5196134142668862 1.3620340745782304" />
            </geometry>
            <material name="Green">
                <color rgba="0 180.0 0.0 1.0"/>
            </material>
        </visual>
        <collision>
            <origin xyz="0 1.2598067071334431 0" rpy="0 0 0"/>
            <geometry>
                <box size="1.8450813048101284 2.5196134142668862 1.3620340745782304" />
            </geometry>
        </collision>
    </link>
    <link name="Leg13">
        <inertial>
            <origin xyz="0 0 1.404578244968933" rpy="0 0 0"/>
            <mass value="1" />
            <inertia ixx="100" ixy="0" ixz="0" iyy="100" iyz="0" izz="100" />
        </inertial>
        <visual>
            <origin xyz="0 0 1.404578244968933" rpy="0 0 0"/>
            <geometry>
                <box size="1.3732682219820318 2.9979596586045876 2.809156489937866" />
            </geometry>
            <material name="Green">
                <color rgba="0 180.0 0.0 1.0"/>
            </material>
        </visual>
        <collision>
            <origin xyz="0 0 1.404578244968933" rpy="0 0 0"/>
            <geometry>
                <box size="1.3732682219820318 2.9979596586045876 2.809156489937866" />
            </geometry>
        </collision>
    </link>
    <link name="Leg14">
        <inertial>
            <origin xyz="0 0 1.4910965341741447" rpy="0 0 0"/>
            <mass value="1" />
            <inertia ixx="100" ixy="0" ixz="0" iyy="100" iyz="0" izz="100" />
        </inertial>
        <visual>
            <origin xyz="0 0 1.4910965341741447" rpy="0 0 0"/>
            <geometry>
                <box size="2.696777045729437 2.7101425728134156 2.9821930683482893" />
            </geometry>
            <material name="Blue">
                <color rgba="0 1.0 1.0 1.0"/>
            </material>
        </visual>
        <collision>
            <origin xyz="0 0 1.4910965341741447" rpy="0 0 0"/>
            <geometry>
                <box size="2.696777045729437 2.7101425728134156 2.9821930683482893" />
            </geometry>
        </collision>
    </link>
    <link name="Leg15">
        <inertial>
            <origin xyz="0.7590180016850125 0 0" rpy="0 0 0"/>
            <mass value="1" />
            <inertia ixx="100" ixy="0" ixz="0" iyy="100" iyz="0" izz="100" />
        </inertial>
        <visual>
            <origin xyz="0.7590180016850125 0 0" rpy="0 0 0"/>
            <geometry>
                <box size="1.518036003370025 1.5820859803164293 2.427981253772012" />
            </geometry>
            <material name="Blue">
                <color rgba="0 1.0 1.0 1.0"/>
            </material>
        </visual>
        <collision>
            <origin xyz="0.7590180016850125 0 0" rpy="0 0 0"/>
            <geometry>
                <box size="1.518036003370025 1.5820859803164293 2.427981253772012" />
            </geometry>
        </collision>
    </link>
    <link name="Leg16">
        <inertial>
            <origin xyz="0.7044477286761284 0 0" rpy="0 0 0"/>
            <mass value="1" />
            <inertia ixx="100" ixy="0" ixz="0" iyy="100" iyz="0" izz="100" />
        </inertial>
        <visual>
            <origin xyz="0.7044477286761284 0 0" rpy="0 0 0"/>
            <geometry>
                <box size="1.4088954573522567 1.6044404771161802 2.3259529397906995" />
            </geometry>
            <material name="Blue">
                <color rgba="0 1.0 1.0 1.0"/>
            </material>
        </visual>
        <collision>
            <origin xyz="0.7044477286761284 0 0" rpy="0 0 0"/>
            <geometry>
                <box size="1.4088954573522567 1.6044404771161802 2.3259529397906995" />
            </geometry>
        </collision>
    </link>
    <link name="Leg17">
        <inertial>
            <origin xyz="1.2654683083299774 0 0" rpy="0 0 0"/>
            <mass value="1" />
            <inertia ixx="100" ixy="0" ixz="0" iyy="100" iyz="0" izz="100" />
        </inertial>
        <visual>
            <origin xyz="1.2654683083299774 0 0" rpy="0 0 0"/>
            <geometry>
                <box size="2.5309366166599547 1.3932205736925902 2.804557834023564" />
            </geometry>
            <material name="Green">
                <color rgba="0 180.0 0.0 1.0"/>
            </material>
        </visual>
        <collision>
            <origin xyz="1.2654683083299774 0 0" rpy="0 0 0"/>
            <geometry>
                <box size="2.5309366166599547 1.3932205736925902 2.804557834023564" />
            </geometry>
        </collision>
    </link>
    <link name="Leg18">
        <inertial>
            <origin xyz="0.7351488378351216 0 0" rpy="0 0 0"/>
            <mass value="1" />
            <inertia ixx="100" ixy="0" ixz="0" iyy="100" iyz="0" izz="100" />
        </inertial>
        <visual>
            <origin xyz="0.7351488378351216 0 0" rpy="0 0 0"/>
            <geometry>
                <box size="1.4702976756702433 1.2850209601662126 1.787268181792422" />
            </geometry>
            <material name="Blue">
                <color rgba="0 1.0 1.0 1.0"/>
            </material>
        </visual>
        <collision>
            <origin xyz="0.7351488378351216 0 0" rpy="0 0 0"/>
            <geometry>
                <box size="1.4702976756702433 1.2850209601662126 1.787268181792422" />
            </geometry>
        </collision>
    </link>
    <link name="Leg19">
        <inertial>
            <origin xyz="0 1.153340659440989 0" rpy="0 0 0"/>
            <mass value="1" />
            <inertia ixx="100" ixy="0" ixz="0" iyy="100" iyz="0" izz="100" />
        </inertial>
        <visual>
            <origin xyz="0 1.153340659440989 0" rpy="0 0 0"/>
            <geometry>
                <box size="2.2257230173662057 2.306681318881978 1.9486992688345774" />
            </geometry>
            <material name="Blue">
                <color rgba="0 1.0 1.0 1.0"/>
            </material>
        </visual>
        <collision>
            <origin xyz="0 1.153340659440989 0" rpy="0 0 0"/>
            <geometry>
                <box size="2.2257230173662057 2.306681318881978 1.9486992688345774" />
            </geometry>
        </collision>
    </link>
    <link name="Leg20">
        <inertial>
            <origin xyz="0 1.3381142765434642 0" rpy="0 0 0"/>
            <mass value="1" />
            <inertia ixx="100" ixy="0" ixz="0" iyy="100" iyz="0" izz="100" />
        </inertial>
        <visual>
            <origin xyz="0 1.3381142765434642 0" rpy="0 0 0"/>
            <geometry>
                <box size="2.1432364220932003 2.6762285530869283 1.6379238888707623" />
            </geometry>
            <material name="Green">
                <color rgba="0 180.0 0.0 1.0"/>
            </material>
        </visual>
        <collision>
            <origin xyz="0 1.3381142765434642 0" rpy="0 0 0"/>
            <geometry>
                <box size="2.1432364220932003 2.6762285530869283 1.6379238888707623" />
            </geometry>
        </collision>
    </link>
    <link name="Leg21">
        <inertial>
            <origin xyz="0 0 1.355565428245666" rpy="0 0 0"/>
            <mass value="1" />
            <inertia ixx="100" ixy="0" ixz="0" iyy="100" iyz="0" izz="100" />
        </inertial>
        <visual>
            <origin xyz="0 0 1.355565428245666" rpy="0 0 0"/>
            <geometry>
                <box size="2.5339619092678607 2.3448974173719117 2.711130856491332" />
            </geometry>
            <material name="Blue">
                <color rgba="0 1.0 1.0 1.0"/>
            </material>
        </visual>
        <collision>
            <origin xyz="0 0 1.355565428245666" rpy="0 0 0"/>
            <geometry>
                <box size="2.5339619092678607 2.3448974173719117 2.711130856491332" />
            </geometry>
        </collision>
    </link>
    <link name="Leg22">
        <inertial>
            <origin xyz="0 0 0.9322427169857072" rpy="0 0 0"/>
            <mass value="1" />
            <inertia ixx="100" ixy="0" ixz="0" iyy="100" iyz="0" izz="100" />
        </inertial>
        <visual>
            <origin xyz="0 0 0.9322427169857072" rpy="0 0 0"/>
            <geometry>
                <box size="2.271941075289638 1.285398115114507 1.8644854339714143" />
            </geometry>
            <material name="Blue">
                <color rgba="0 1.0 1.0 1.0"/>
            </material>
        </visual>
        <collision>
            <origin xyz="0 0 0.9322427169857072" rpy="0 0 0"/>
            <geometry>
                <box size="2.271941075289638 1.285398115114507 1.8644854339714143" />
            </geometry>
        </collision>
    </link>
    <link name="Leg23">
        <inertial>
            <origin xyz="1.1579932605579961 0 0" rpy="0 0 0"/>
            <mass value="1" />
            <inertia ixx="100" ixy="0" ixz="0" iyy="100" iyz="0" izz="100" />
        </inertial>
        <visual>
            <origin xyz="1.1579932605579961 0 0" rpy="0 0 0"/>
            <geometry>
                <box size="2.3159865211159922 1.1732990142517723 2.6926301179483305" />
            </geometry>
            <material name="Blue">
                <color rgba="0 1.0 1.0 1.0"/>
            </material>
        </visual>
        <collision>
            <origin xyz="1.1579932605579961 0 0" rpy="0 0 0"/>
            <geometry>
                <box size="2.3159865211159922 1.1732990142517723 2.6926301179483305" />
            </geometry>
        </collision>
    </link>
    <link name="Leg24">
        <inertial>
            <origin xyz="0 0 1.4334103864518246" rpy="0 0 0"/>
            <mass value="1" />
            <inertia ixx="100" ixy="0" ixz="0" iyy="100" iyz="0" izz="100" />
        </inertial>
        <visual>
            <origin xyz="0 0 1.4334103864518246" rpy="0 0 0"/>
            <geometry>
                <box size="2.7106308793339036 2.3441018956872837 2.8668207729036492" />
            </geometry>
            <material name="Blue">
                <color rgba="0 1.0 1.0 1.0"/>
            </material>
        </visual>
        <collision>
            <origin xyz="0 0 1.4334103864518246" rpy="0 0 0"/>
            <geometry>
                <box size="2.7106308793339036 2.3441018956872837 2.8668207729036492" />
            </geometry>
        </collision>
    </link>
    <link name="Leg25">
        <inertial>
            <origin xyz="0 0.657844122492607 0" rpy="0 0 0"/>
            <mass value="1" />
            <inertia ixx="100" ixy="0" ixz="0" iyy="100" iyz="0" izz="100" />
        </inertial>
        <visual>
            <origin xyz="0 0.657844122492607 0" rpy="0 0 0"/>
            <geometry>
                <box size="1.5891982091593606 1.315688244985214 1.5091202383351106" />
            </geometry>
            <material name="Green">
                <color rgba="0 180.0 0.0 1.0"/>
            </material>
        </visual>
        <collision>
            <origin xyz="0 0.657844122492607 0" rpy="0 0 0"/>
            <geometry>
                <box size="1.5891982091593606 1.315688244985214 1.5091202383351106" />
            </geometry>
        </collision>
    </link>
    <link name="Leg26">
        <inertial>
            <origin xyz="0 0 1.3399907096165875" rpy="0 0 0"/>
            <mass value="1" />
            <inertia ixx="100" ixy="0" ixz="0" iyy="100" iyz="0" izz="100" />
        </inertial>
        <visual>
            <origin xyz="0 0 1.3399907096165875" rpy="0 0 0"/>
            <geometry>
                <box size="2.724423795530924 1.898969999197328 2.679981419233175" />
            </geometry>
            <material name="Blue">
                <color rgba="0 1.0 1.0 1.0"/>
            </material>
        </visual>
        <collision>
            <origin xyz="0 0 1.3399907096165875" rpy="0 0 0"/>
            <geometry>
                <box size="2.724423795530924 1.898969999197328 2.679981419233175" />
            </geometry>
        </collision>
    </link>
    <link name="Leg27">
        <inertial>
            <origin xyz="0 1.1285501494864825 0" rpy="0 0 0"/>
            <mass value="1" />
            <inertia ixx="100" ixy="0" ixz="0" iyy="100" iyz="0" izz="100" />
        </inertial>
        <visual>
            <origin xyz="0 1.1285501494864825 0" rpy="0 0 0"/>
            <geometry>
                <box size="2.1779348805626846 2.257100298972965 2.3801894580759693" />
            </geometry>
            <material name="Green">
                <color rgba="0 180.0 0.0 1.0"/>
            </material>
        </visual>
        <collision>
            <origin xyz="0 1.1285501494864825 0" rpy="0 0 0"/>
            <geometry>
                <box size="2.1779348805626846 2.257100298972965 2.3801894580759693" />
            </geometry>
        </collision>
    </link>
    <joint name="Torso_Leg1" type="revolute">
       <parent link="Torso"/>
       <child  link="Leg1"/>
       <origin rpy="0 0 0" xyz="0.6630055147623107 0 1.339315540266301" />
     <axis xyz="1 0 0"/>
       <limit effort="0.0" lower="-3.14159" upper="3.14159" velocity="0.0"/>
    </joint>
    <joint name="Leg1_Leg2" type="revolute">
       <parent link="Leg1"/>
       <child  link="Leg2"/>
       <origin rpy="0 0 0" xyz="1.4422590586332744 0 0" />
     <axis xyz="1 0 0"/>
       <limit effort="0.0" lower="-3.14159" upper="3.14159" velocity="0.0"/>
    </joint>
    <joint name="Leg2_Leg3" type="revolute">
       <parent link="Leg2"/>
       <child  link="Leg3"/>
       <origin rpy="0 0 0" xyz="0 1.8211438678608804 0" />
     <axis xyz="1 0 0"/>
       <limit effort="0.0" lower="-3.14159" upper="3.14159" velocity="0.0"/>
    </joint>
    <joint name="Torso_Leg4" type="revolute">
       <parent link="Torso"/>
       <child  link="Leg4"/>
       <origin rpy="0 0 0" xyz="0.6779812415155053 0 0.595642598077575" />
     <axis xyz="1 0 0"/>
       <limit effort="0.0" lower="-3.14159" upper="3.14159" velocity="0.0"/>
    </joint>
    <joint name="Leg4_Leg5" type="revolute">
       <parent link="Leg4"/>
       <child  link="Leg5"/>
       <origin rpy="0 0 0" xyz="1.6403754078270811 0 0" />
     <axis xyz="1 0 0"/>
       <limit effort="0.0" lower="-3.14159" upper="3.14159" velocity="0.0"/>
    </joint>
    <joint name="Leg5_Leg6" type="revolute">
       <parent link="Leg5"/>
       <child  link="Leg6"/>
       <origin rpy="0 0 0" xyz="0 2.229061490046108 0" />
     <axis xyz="1 0 0"/>
       <limit effort="0.0" lower="-3.14159" upper="3.14159" velocity="0.0"/>
    </joint>
    <joint name="Leg4_Leg7" type="revolute">
       <parent link="Leg4"/>
       <child  link="Leg7"/>
       <origin rpy="0 0 0" xyz="1.6403754078270811 1.2458607034494378 0" />
     <axis xyz="1 0 0"/>
       <limit effort="0.0" lower="-3.14159" upper="3.14159" velocity="0.0"/>
    </joint>
    <joint name="Leg7_Leg8" type="revolute">
       <parent link="Leg7"/>
       <child  link="Leg8"/>
       <origin rpy="0 0 0" xyz="0 0 2.164854509408255" />
     <axis xyz="1 0 0"/>
       <limit effort="0.0" lower="-3.14159" upper="3.14159" velocity="0.0"/>
    </joint>
    <joint name="Leg2_Leg9" type="revolute">
       <parent link="Leg2"/>
       <child  link="Leg9"/>
       <origin rpy="0 0 0" xyz="0 1.8211438678608804 0.9521882289653416" />
     <axis xyz="1 0 0"/>
       <limit effort="0.0" lower="-3.14159" upper="3.14159" velocity="0.0"/>
    </joint>
    <joint name="Leg6_Leg10" type="revolute">
       <parent link="Leg6"/>
       <child  link="Leg10"/>
       <origin rpy="0 0 0" xyz="0.9604016945377887 1.2433361753306382 0" />
     <axis xyz="1 0 0"/>
       <limit effort="0.0" lower="-3.14159" upper="3.14159" velocity="0.0"/>
    </joint>
    <joint name="Leg3_Leg11" type="revolute">
       <parent link="Leg3"/>
       <child  link="Leg11"/>
       <origin rpy="0 0 0" xyz="0.9522251889087358 0 0.9751728032525169" />
     <axis xyz="1 0 0"/>
       <limit effort="0.0" lower="-3.14159" upper="3.14159" velocity="0.0"/>
    </joint>
    <joint name="Leg1_Leg12" type="revolute">
       <parent link="Leg1"/>
       <child  link="Leg12"/>
       <origin rpy="0 0 0" xyz="1.4422590586332744 1.0642040083407056 0" />
     <axis xyz="1 0 0"/>
       <limit effort="0.0" lower="-3.14159" upper="3.14159" velocity="0.0"/>
    </joint>
    <joint name="Leg12_Leg13" type="revolute">
       <parent link="Leg12"/>
       <child  link="Leg13"/>
       <origin rpy="0 0 0" xyz="0 0 2.809156489937866" />
     <axis xyz="1 0 0"/>
       <limit effort="0.0" lower="-3.14159" upper="3.14159" velocity="0.0"/>
    </joint>
    <joint name="Leg5_Leg14" type="revolute">
       <parent link="Leg5"/>
       <child  link="Leg14"/>
       <origin rpy="0 0 0" xyz="0 2.229061490046108 0.613114746368107" />
     <axis xyz="1 0 0"/>
       <limit effort="0.0" lower="-3.14159" upper="3.14159" velocity="0.0"/>
    </joint>
    <joint name="Leg8_Leg15" type="revolute">
       <parent link="Leg8"/>
       <child  link="Leg15"/>
       <origin rpy="0 0 0" xyz="0.6806884228392863 0 1.2744183348079086" />
     <axis xyz="1 0 0"/>
       <limit effort="0.0" lower="-3.14159" upper="3.14159" velocity="0.0"/>
    </joint>
    <joint name="Leg14_Leg16" type="revolute">
       <parent link="Leg14"/>
       <child  link="Leg16"/>
       <origin rpy="0 0 0" xyz="1.518036003370025 0 0" />
     <axis xyz="1 0 0"/>
       <limit effort="0.0" lower="-3.14159" upper="3.14159" velocity="0.0"/>
    </joint>
    <joint name="Leg7_Leg17" type="revolute">
       <parent link="Leg7"/>
       <child  link="Leg17"/>
       <origin rpy="0 0 0" xyz="1.0834888528679403 0 2.164854509408255" />
     <axis xyz="1 0 0"/>
       <limit effort="0.0" lower="-3.14159" upper="3.14159" velocity="0.0"/>
    </joint>
    <joint name="Leg10_Leg18" type="revolute">
       <parent link="Leg10"/>
       <child  link="Leg18"/>
       <origin rpy="0 0 0" xyz="1.7475077351842003 0 0" />
     <axis xyz="1 0 0"/>
       <limit effort="0.0" lower="-3.14159" upper="3.14159" velocity="0.0"/>
    </joint>
    <joint name="Leg7_Leg19" type="revolute">
       <parent link="Leg7"/>
       <child  link="Leg19"/>
       <origin rpy="0 0 0" xyz="1.0834888528679403 1.3250332094212114 2.164854509408255" />
     <axis xyz="1 0 0"/>
       <limit effort="0.0" lower="-3.14159" upper="3.14159" velocity="0.0"/>
    </joint>
    <joint name="Leg17_Leg20" type="revolute">
       <parent link="Leg17"/>
       <child  link="Leg20"/>
       <origin rpy="0 0 0" xyz="0.7351488378351216 0.6425104800831063 0" />
     <axis xyz="1 0 0"/>
       <limit effort="0.0" lower="-3.14159" upper="3.14159" velocity="0.0"/>
    </joint>
    <joint name="Leg1_Leg21" type="revolute">
       <parent link="Leg1"/>
       <child  link="Leg21"/>
       <origin rpy="0 0 0" xyz="1.4422590586332744 1.0642040083407056 1.3988768239800586" />
     <axis xyz="1 0 0"/>
       <limit effort="0.0" lower="-3.14159" upper="3.14159" velocity="0.0"/>
    </joint>
    <joint name="Leg16_Leg22" type="revolute">
       <parent link="Leg16"/>
       <child  link="Leg22"/>
       <origin rpy="0 0 0" xyz="1.2654683083299774 0 1.402278917011782" />
     <axis xyz="1 0 0"/>
       <limit effort="0.0" lower="-3.14159" upper="3.14159" velocity="0.0"/>
    </joint>
    <joint name="Leg20_Leg23" type="revolute">
       <parent link="Leg20"/>
       <child  link="Leg23"/>
       <origin rpy="0 0 0" xyz="1.2669809546339303 0 1.355565428245666" />
     <axis xyz="1 0 0"/>
       <limit effort="0.0" lower="-3.14159" upper="3.14159" velocity="0.0"/>
    </joint>
    <joint name="Leg3_Leg24" type="revolute">
       <parent link="Leg3"/>
       <child  link="Leg24"/>
       <origin rpy="0 0 0" xyz="0.9522251889087358 0 1.9503456065050337" />
     <axis xyz="1 0 0"/>
       <limit effort="0.0" lower="-3.14159" upper="3.14159" velocity="0.0"/>
    </joint>
    <joint name="Leg6_Leg25" type="revolute">
       <parent link="Leg6"/>
       <child  link="Leg25"/>
       <origin rpy="0 0 0" xyz="0.9604016945377887 2.4866723506612765 0" />
     <axis xyz="1 0 0"/>
       <limit effort="0.0" lower="-3.14159" upper="3.14159" velocity="0.0"/>
    </joint>
    <joint name="Leg18_Leg26" type="revolute">
       <parent link="Leg18"/>
       <child  link="Leg26"/>
       <origin rpy="0 0 0" xyz="0 1.153340659440989 0.9743496344172887" />
     <axis xyz="1 0 0"/>
       <limit effort="0.0" lower="-3.14159" upper="3.14159" velocity="0.0"/>
    </joint>
    <joint name="Leg26_Leg27" type="revolute">
       <parent link="Leg26"/>
       <child  link="Leg27"/>
       <origin rpy="0 0 0" xyz="0 2.257100298972965 0" />
     <axis xyz="1 0 0"/>
       <limit effort="0.0" lower="-3.14159" upper="3.14159" velocity="0.0"/>
    </joint>
</robot>