<robot name = "robot">
    <link name="Torso">
        <inertial>
            <origin xyz="0 0 0.7591098370897026" rpy="0 0 0"/>
            <mass value="1" />
            <inertia ixx="100" ixy="0" ixz="0" iyy="100" iyz="0" izz="100" />
        </inertial>
        <visual>
            <origin xyz="0 0 0.7591098370897026" rpy="0 0 0"/>
            <geometry>
                <box size="2.0903840454171183 2.044859198350353 1.5182196741794052" />
            </geometry>
            <material name="Green">
                <color rgba="0 180.0 0.0 1.0"/>
            </material>
        </visual>
        <collision>
            <origin xyz="0 0 0.7591098370897026" rpy="0 0 0"/>
            <geometry>
                <box size="2.0903840454171183 2.044859198350353 1.5182196741794052" />
            </geometry>
        </collision>
    </link>
    <link name="Leg1">
        <inertial>
            <origin xyz="0 1.2731956632269976 0" rpy="0 0 0"/>
            <mass value="1" />
            <inertia ixx="100" ixy="0" ixz="0" iyy="100" iyz="0" izz="100" />
        </inertial>
        <visual>
            <origin xyz="0 1.2731956632269976 0" rpy="0 0 0"/>
            <geometry>
                <box size="2.1117969115559845 2.5463913264539952 1.51920664181443" />
            </geometry>
            <material name="Blue">
                <color rgba="0 1.0 1.0 1.0"/>
            </material>
        </visual>
        <collision>
            <origin xyz="0 1.2731956632269976 0" rpy="0 0 0"/>
            <geometry>
                <box size="2.1117969115559845 2.5463913264539952 1.51920664181443" />
            </geometry>
        </collision>
    </link>
    <link name="Leg2">
        <inertial>
            <origin xyz="0 0 1.1862282196200706" rpy="0 0 0"/>
            <mass value="1" />
            <inertia ixx="100" ixy="0" ixz="0" iyy="100" iyz="0" izz="100" />
        </inertial>
        <visual>
            <origin xyz="0 0 1.1862282196200706" rpy="0 0 0"/>
            <geometry>
                <box size="1.9309975465784834 2.4044971954543475 2.3724564392401413" />
            </geometry>
            <material name="Blue">
                <color rgba="0 1.0 1.0 1.0"/>
            </material>
        </visual>
        <collision>
            <origin xyz="0 0 1.1862282196200706" rpy="0 0 0"/>
            <geometry>
                <box size="1.9309975465784834 2.4044971954543475 2.3724564392401413" />
            </geometry>
        </collision>
    </link>
    <link name="Leg3">
        <inertial>
            <origin xyz="0 0 0.5067266413813986" rpy="0 0 0"/>
            <mass value="1" />
            <inertia ixx="100" ixy="0" ixz="0" iyy="100" iyz="0" izz="100" />
        </inertial>
        <visual>
            <origin xyz="0 0 0.5067266413813986" rpy="0 0 0"/>
            <geometry>
                <box size="1.2290891516620022 1.731186763124453 1.0134532827627971" />
            </geometry>
            <material name="Green">
                <color rgba="0 180.0 0.0 1.0"/>
            </material>
        </visual>
        <collision>
            <origin xyz="0 0 0.5067266413813986" rpy="0 0 0"/>
            <geometry>
                <box size="1.2290891516620022 1.731186763124453 1.0134532827627971" />
            </geometry>
        </collision>
    </link>
    <link name="Leg4">
        <inertial>
            <origin xyz="0 0 1.1782475191719386" rpy="0 0 0"/>
            <mass value="1" />
            <inertia ixx="100" ixy="0" ixz="0" iyy="100" iyz="0" izz="100" />
        </inertial>
        <visual>
            <origin xyz="0 0 1.1782475191719386" rpy="0 0 0"/>
            <geometry>
                <box size="2.1216849652393224 1.0262338272875067 2.356495038343877" />
            </geometry>
            <material name="Green">
                <color rgba="0 180.0 0.0 1.0"/>
            </material>
        </visual>
        <collision>
            <origin xyz="0 0 1.1782475191719386" rpy="0 0 0"/>
            <geometry>
                <box size="2.1216849652393224 1.0262338272875067 2.356495038343877" />
            </geometry>
        </collision>
    </link>
    <link name="Leg5">
        <inertial>
            <origin xyz="0 1.4430822820322566 0" rpy="0 0 0"/>
            <mass value="1" />
            <inertia ixx="100" ixy="0" ixz="0" iyy="100" iyz="0" izz="100" />
        </inertial>
        <visual>
            <origin xyz="0 1.4430822820322566 0" rpy="0 0 0"/>
            <geometry>
                <box size="2.9187846847436933 2.8861645640645133 1.9531971840249016" />
            </geometry>
            <material name="Green">
                <color rgba="0 180.0 0.0 1.0"/>
            </material>
        </visual>
        <collision>
            <origin xyz="0 1.4430822820322566 0" rpy="0 0 0"/>
            <geometry>
                <box size="2.9187846847436933 2.8861645640645133 1.9531971840249016" />
            </geometry>
        </collision>
    </link>
    <link name="Leg6">
        <inertial>
            <origin xyz="0 0.5726912198648932 0" rpy="0 0 0"/>
            <mass value="1" />
            <inertia ixx="100" ixy="0" ixz="0" iyy="100" iyz="0" izz="100" />
        </inertial>
        <visual>
            <origin xyz="0 0.5726912198648932 0" rpy="0 0 0"/>
            <geometry>
                <box size="2.35878451642688 1.1453824397297865 1.9942423337609443" />
            </geometry>
            <material name="Blue">
                <color rgba="0 1.0 1.0 1.0"/>
            </material>
        </visual>
        <collision>
            <origin xyz="0 0.5726912198648932 0" rpy="0 0 0"/>
            <geometry>
                <box size="2.35878451642688 1.1453824397297865 1.9942423337609443" />
            </geometry>
        </collision>
    </link>
    <link name="Leg7">
        <inertial>
            <origin xyz="1.023255129742853 0 0" rpy="0 0 0"/>
            <mass value="1" />
            <inertia ixx="100" ixy="0" ixz="0" iyy="100" iyz="0" izz="100" />
        </inertial>
        <visual>
            <origin xyz="1.023255129742853 0 0" rpy="0 0 0"/>
            <geometry>
                <box size="2.046510259485706 1.745251861399335 1.706163801497345" />
            </geometry>
            <material name="Green">
                <color rgba="0 180.0 0.0 1.0"/>
            </material>
        </visual>
        <collision>
            <origin xyz="1.023255129742853 0 0" rpy="0 0 0"/>
            <geometry>
                <box size="2.046510259485706 1.745251861399335 1.706163801497345" />
            </geometry>
        </collision>
    </link>
    <link name="Leg8">
        <inertial>
            <origin xyz="1.031087710787324 0 0" rpy="0 0 0"/>
            <mass value="1" />
            <inertia ixx="100" ixy="0" ixz="0" iyy="100" iyz="0" izz="100" />
        </inertial>
        <visual>
            <origin xyz="1.031087710787324 0 0" rpy="0 0 0"/>
            <geometry>
                <box size="2.062175421574648 2.85180688792955 1.3558313903906867" />
            </geometry>
            <material name="Green">
                <color rgba="0 180.0 0.0 1.0"/>
            </material>
        </visual>
        <collision>
            <origin xyz="1.031087710787324 0 0" rpy="0 0 0"/>
            <geometry>
                <box size="2.062175421574648 2.85180688792955 1.3558313903906867" />
            </geometry>
        </collision>
    </link>
    <link name="Leg9">
        <inertial>
            <origin xyz="0 0 1.1234830904669648" rpy="0 0 0"/>
            <mass value="1" />
            <inertia ixx="100" ixy="0" ixz="0" iyy="100" iyz="0" izz="100" />
        </inertial>
        <visual>
            <origin xyz="0 0 1.1234830904669648" rpy="0 0 0"/>
            <geometry>
                <box size="2.071501069704386 2.6389516114667035 2.2469661809339296" />
            </geometry>
            <material name="Green">
                <color rgba="0 180.0 0.0 1.0"/>
            </material>
        </visual>
        <collision>
            <origin xyz="0 0 1.1234830904669648" rpy="0 0 0"/>
            <geometry>
                <box size="2.071501069704386 2.6389516114667035 2.2469661809339296" />
            </geometry>
        </collision>
    </link>
    <link name="Leg10">
        <inertial>
            <origin xyz="0 0 1.113309802348992" rpy="0 0 0"/>
            <mass value="1" />
            <inertia ixx="100" ixy="0" ixz="0" iyy="100" iyz="0" izz="100" />
        </inertial>
        <visual>
            <origin xyz="0 0 1.113309802348992" rpy="0 0 0"/>
            <geometry>
                <box size="2.466277295194809 1.918277250704615 2.226619604697984" />
            </geometry>
            <material name="Blue">
                <color rgba="0 1.0 1.0 1.0"/>
            </material>
        </visual>
        <collision>
            <origin xyz="0 0 1.113309802348992" rpy="0 0 0"/>
            <geometry>
                <box size="2.466277295194809 1.918277250704615 2.226619604697984" />
            </geometry>
        </collision>
    </link>
    <link name="Leg11">
        <inertial>
            <origin xyz="0 0.6038082345793876 0" rpy="0 0 0"/>
            <mass value="1" />
            <inertia ixx="100" ixy="0" ixz="0" iyy="100" iyz="0" izz="100" />
        </inertial>
        <visual>
            <origin xyz="0 0.6038082345793876 0" rpy="0 0 0"/>
            <geometry>
                <box size="1.2134155632749368 1.2076164691587752 1.1132366845873056" />
            </geometry>
            <material name="Green">
                <color rgba="0 180.0 0.0 1.0"/>
            </material>
        </visual>
        <collision>
            <origin xyz="0 0.6038082345793876 0" rpy="0 0 0"/>
            <geometry>
                <box size="1.2134155632749368 1.2076164691587752 1.1132366845873056" />
            </geometry>
        </collision>
    </link>
    <link name="Leg12">
        <inertial>
            <origin xyz="0 0 1.1907789425923154" rpy="0 0 0"/>
            <mass value="1" />
            <inertia ixx="100" ixy="0" ixz="0" iyy="100" iyz="0" izz="100" />
        </inertial>
        <visual>
            <origin xyz="0 0 1.1907789425923154" rpy="0 0 0"/>
            <geometry>
                <box size="1.5023222486956982 1.652827944809069 2.381557885184631" />
            </geometry>
            <material name="Green">
                <color rgba="0 180.0 0.0 1.0"/>
            </material>
        </visual>
        <collision>
            <origin xyz="0 0 1.1907789425923154" rpy="0 0 0"/>
            <geometry>
                <box size="1.5023222486956982 1.652827944809069 2.381557885184631" />
            </geometry>
        </collision>
    </link>
    <link name="Leg13">
        <inertial>
            <origin xyz="0 0 1.294057286264078" rpy="0 0 0"/>
            <mass value="1" />
            <inertia ixx="100" ixy="0" ixz="0" iyy="100" iyz="0" izz="100" />
        </inertial>
        <visual>
            <origin xyz="0 0 1.294057286264078" rpy="0 0 0"/>
            <geometry>
                <box size="2.414297753791218 1.9993742140580282 2.588114572528156" />
            </geometry>
            <material name="Blue">
                <color rgba="0 1.0 1.0 1.0"/>
            </material>
        </visual>
        <collision>
            <origin xyz="0 0 1.294057286264078" rpy="0 0 0"/>
            <geometry>
                <box size="2.414297753791218 1.9993742140580282 2.588114572528156" />
            </geometry>
        </collision>
    </link>
    <link name="Leg14">
        <inertial>
            <origin xyz="0 0.7876492087125255 0" rpy="0 0 0"/>
            <mass value="1" />
            <inertia ixx="100" ixy="0" ixz="0" iyy="100" iyz="0" izz="100" />
        </inertial>
        <visual>
            <origin xyz="0 0.7876492087125255 0" rpy="0 0 0"/>
            <geometry>
                <box size="2.0807727328768673 1.575298417425051 1.6395141569740856" />
            </geometry>
            <material name="Blue">
                <color rgba="0 1.0 1.0 1.0"/>
            </material>
        </visual>
        <collision>
            <origin xyz="0 0.7876492087125255 0" rpy="0 0 0"/>
            <geometry>
                <box size="2.0807727328768673 1.575298417425051 1.6395141569740856" />
            </geometry>
        </collision>
    </link>
    <link name="Leg15">
        <inertial>
            <origin xyz="0 0.7001822616296706 0" rpy="0 0 0"/>
            <mass value="1" />
            <inertia ixx="100" ixy="0" ixz="0" iyy="100" iyz="0" izz="100" />
        </inertial>
        <visual>
            <origin xyz="0 0.7001822616296706 0" rpy="0 0 0"/>
            <geometry>
                <box size="1.666085519095986 1.4003645232593411 2.293588557842754" />
            </geometry>
            <material name="Green">
                <color rgba="0 180.0 0.0 1.0"/>
            </material>
        </visual>
        <collision>
            <origin xyz="0 0.7001822616296706 0" rpy="0 0 0"/>
            <geometry>
                <box size="1.666085519095986 1.4003645232593411 2.293588557842754" />
            </geometry>
        </collision>
    </link>
    <link name="Leg16">
        <inertial>
            <origin xyz="0 0.9717055727344899 0" rpy="0 0 0"/>
            <mass value="1" />
            <inertia ixx="100" ixy="0" ixz="0" iyy="100" iyz="0" izz="100" />
        </inertial>
        <visual>
            <origin xyz="0 0.9717055727344899 0" rpy="0 0 0"/>
            <geometry>
                <box size="2.842582502259286 1.9434111454689798 2.078682068729583" />
            </geometry>
            <material name="Green">
                <color rgba="0 180.0 0.0 1.0"/>
            </material>
        </visual>
        <collision>
            <origin xyz="0 0.9717055727344899 0" rpy="0 0 0"/>
            <geometry>
                <box size="2.842582502259286 1.9434111454689798 2.078682068729583" />
            </geometry>
        </collision>
    </link>
    <link name="Leg17">
        <inertial>
            <origin xyz="0 0 1.0971660557450882" rpy="0 0 0"/>
            <mass value="1" />
            <inertia ixx="100" ixy="0" ixz="0" iyy="100" iyz="0" izz="100" />
        </inertial>
        <visual>
            <origin xyz="0 0 1.0971660557450882" rpy="0 0 0"/>
            <geometry>
                <box size="2.2468919580730207 1.8532238433277135 2.1943321114901764" />
            </geometry>
            <material name="Green">
                <color rgba="0 180.0 0.0 1.0"/>
            </material>
        </visual>
        <collision>
            <origin xyz="0 0 1.0971660557450882" rpy="0 0 0"/>
            <geometry>
                <box size="2.2468919580730207 1.8532238433277135 2.1943321114901764" />
            </geometry>
        </collision>
    </link>
    <link name="Leg18">
        <inertial>
            <origin xyz="0.8169760790257228 0 0" rpy="0 0 0"/>
            <mass value="1" />
            <inertia ixx="100" ixy="0" ixz="0" iyy="100" iyz="0" izz="100" />
        </inertial>
        <visual>
            <origin xyz="0.8169760790257228 0 0" rpy="0 0 0"/>
            <geometry>
                <box size="1.6339521580514456 2.8246246839111055 2.857237404136186" />
            </geometry>
            <material name="Green">
                <color rgba="0 180.0 0.0 1.0"/>
            </material>
        </visual>
        <collision>
            <origin xyz="0.8169760790257228 0 0" rpy="0 0 0"/>
            <geometry>
                <box size="1.6339521580514456 2.8246246839111055 2.857237404136186" />
            </geometry>
        </collision>
    </link>
    <link name="Leg19">
        <inertial>
            <origin xyz="1.4947130152836352 0 0" rpy="0 0 0"/>
            <mass value="1" />
            <inertia ixx="100" ixy="0" ixz="0" iyy="100" iyz="0" izz="100" />
        </inertial>
        <visual>
            <origin xyz="1.4947130152836352 0 0" rpy="0 0 0"/>
            <geometry>
                <box size="2.9894260305672704 1.858367097317193 2.916661203154934" />
            </geometry>
            <material name="Blue">
                <color rgba="0 1.0 1.0 1.0"/>
            </material>
        </visual>
        <collision>
            <origin xyz="1.4947130152836352 0 0" rpy="0 0 0"/>
            <geometry>
                <box size="2.9894260305672704 1.858367097317193 2.916661203154934" />
            </geometry>
        </collision>
    </link>
    <link name="Leg20">
        <inertial>
            <origin xyz="0 1.3069442525217074 0" rpy="0 0 0"/>
            <mass value="1" />
            <inertia ixx="100" ixy="0" ixz="0" iyy="100" iyz="0" izz="100" />
        </inertial>
        <visual>
            <origin xyz="0 1.3069442525217074 0" rpy="0 0 0"/>
            <geometry>
                <box size="1.6514304370566912 2.613888505043415 1.1968408221813065" />
            </geometry>
            <material name="Blue">
                <color rgba="0 1.0 1.0 1.0"/>
            </material>
        </visual>
        <collision>
            <origin xyz="0 1.3069442525217074 0" rpy="0 0 0"/>
            <geometry>
                <box size="1.6514304370566912 2.613888505043415 1.1968408221813065" />
            </geometry>
        </collision>
    </link>
    <link name="Leg21">
        <inertial>
            <origin xyz="0 0.8329712120611854 0" rpy="0 0 0"/>
            <mass value="1" />
            <inertia ixx="100" ixy="0" ixz="0" iyy="100" iyz="0" izz="100" />
        </inertial>
        <visual>
            <origin xyz="0 0.8329712120611854 0" rpy="0 0 0"/>
            <geometry>
                <box size="1.8289920978755259 1.6659424241223708 1.3131371654808766" />
            </geometry>
            <material name="Blue">
                <color rgba="0 1.0 1.0 1.0"/>
            </material>
        </visual>
        <collision>
            <origin xyz="0 0.8329712120611854 0" rpy="0 0 0"/>
            <geometry>
                <box size="1.8289920978755259 1.6659424241223708 1.3131371654808766" />
            </geometry>
        </collision>
    </link>
    <link name="Leg22">
        <inertial>
            <origin xyz="0.9684002393324139 0 0" rpy="0 0 0"/>
            <mass value="1" />
            <inertia ixx="100" ixy="0" ixz="0" iyy="100" iyz="0" izz="100" />
        </inertial>
        <visual>
            <origin xyz="0.9684002393324139 0 0" rpy="0 0 0"/>
            <geometry>
                <box size="1.9368004786648279 1.5673164177335641 2.9678622617757378" />
            </geometry>
            <material name="Green">
                <color rgba="0 180.0 0.0 1.0"/>
            </material>
        </visual>
        <collision>
            <origin xyz="0.9684002393324139 0 0" rpy="0 0 0"/>
            <geometry>
                <box size="1.9368004786648279 1.5673164177335641 2.9678622617757378" />
            </geometry>
        </collision>
    </link>
    <link name="Leg23">
        <inertial>
            <origin xyz="1.2284704611367943 0 0" rpy="0 0 0"/>
            <mass value="1" />
            <inertia ixx="100" ixy="0" ixz="0" iyy="100" iyz="0" izz="100" />
        </inertial>
        <visual>
            <origin xyz="1.2284704611367943 0 0" rpy="0 0 0"/>
            <geometry>
                <box size="2.4569409222735885 2.1420114560429546 1.7847571698994866" />
            </geometry>
            <material name="Green">
                <color rgba="0 180.0 0.0 1.0"/>
            </material>
        </visual>
        <collision>
            <origin xyz="1.2284704611367943 0 0" rpy="0 0 0"/>
            <geometry>
                <box size="2.4569409222735885 2.1420114560429546 1.7847571698994866" />
            </geometry>
        </collision>
    </link>
    <link name="Leg24">
        <inertial>
            <origin xyz="0 0 1.0024399805519093" rpy="0 0 0"/>
            <mass value="1" />
            <inertia ixx="100" ixy="0" ixz="0" iyy="100" iyz="0" izz="100" />
        </inertial>
        <visual>
            <origin xyz="0 0 1.0024399805519093" rpy="0 0 0"/>
            <geometry>
                <box size="1.576134314891506 1.5971161548011594 2.0048799611038186" />
            </geometry>
            <material name="Green">
                <color rgba="0 180.0 0.0 1.0"/>
            </material>
        </visual>
        <collision>
            <origin xyz="0 0 1.0024399805519093" rpy="0 0 0"/>
            <geometry>
                <box size="1.576134314891506 1.5971161548011594 2.0048799611038186" />
            </geometry>
        </collision>
    </link>
    <link name="Leg25">
        <inertial>
            <origin xyz="0 0 1.1790085890847553" rpy="0 0 0"/>
            <mass value="1" />
            <inertia ixx="100" ixy="0" ixz="0" iyy="100" iyz="0" izz="100" />
        </inertial>
        <visual>
            <origin xyz="0 0 1.1790085890847553" rpy="0 0 0"/>
            <geometry>
                <box size="2.1660125767798606 2.7005700744498125 2.3580171781695105" />
            </geometry>
            <material name="Green">
                <color rgba="0 180.0 0.0 1.0"/>
            </material>
        </visual>
        <collision>
            <origin xyz="0 0 1.1790085890847553" rpy="0 0 0"/>
            <geometry>
                <box size="2.1660125767798606 2.7005700744498125 2.3580171781695105" />
            </geometry>
        </collision>
    </link>
    <link name="Leg26">
        <inertial>
            <origin xyz="0 0.7612623390303883 0" rpy="0 0 0"/>
            <mass value="1" />
            <inertia ixx="100" ixy="0" ixz="0" iyy="100" iyz="0" izz="100" />
        </inertial>
        <visual>
            <origin xyz="0 0.7612623390303883 0" rpy="0 0 0"/>
            <geometry>
                <box size="2.064089090074994 1.5225246780607766 1.8714645235810565" />
            </geometry>
            <material name="Green">
                <color rgba="0 180.0 0.0 1.0"/>
            </material>
        </visual>
        <collision>
            <origin xyz="0 0.7612623390303883 0" rpy="0 0 0"/>
            <geometry>
                <box size="2.064089090074994 1.5225246780607766 1.8714645235810565" />
            </geometry>
        </collision>
    </link>
    <joint name="Torso_Leg1" type="revolute">
       <parent link="Torso"/>
       <child  link="Leg1"/>
       <origin rpy="0 0 0" xyz="0 1.0224295991751764 0.7591098370897026" />
     <axis xyz="1 0 0"/>
       <limit effort="0.0" lower="-3.14159" upper="3.14159" velocity="0.0"/>
    </joint>
    <joint name="Leg1_Leg2" type="revolute">
       <parent link="Leg1"/>
       <child  link="Leg2"/>
       <origin rpy="0 0 0" xyz="0 0 2.3724564392401413" />
     <axis xyz="1 0 0"/>
       <limit effort="0.0" lower="-3.14159" upper="3.14159" velocity="0.0"/>
    </joint>
    <joint name="Torso_Leg3" type="revolute">
       <parent link="Torso"/>
       <child  link="Leg3"/>
       <origin rpy="0 0 0" xyz="0 1.2731956632269976 0.759603320907215" />
     <axis xyz="1 0 0"/>
       <limit effort="0.0" lower="-3.14159" upper="3.14159" velocity="0.0"/>
    </joint>
    <joint name="Leg2_Leg4" type="revolute">
       <parent link="Leg2"/>
       <child  link="Leg4"/>
       <origin rpy="0 0 0" xyz="0 0 1.0134532827627971" />
     <axis xyz="1 0 0"/>
       <limit effort="0.0" lower="-3.14159" upper="3.14159" velocity="0.0"/>
    </joint>
    <joint name="Leg4_Leg5" type="revolute">
       <parent link="Leg4"/>
       <child  link="Leg5"/>
       <origin rpy="0 0 0" xyz="0 2.8861645640645133 0" />
     <axis xyz="1 0 0"/>
       <limit effort="0.0" lower="-3.14159" upper="3.14159" velocity="0.0"/>
    </joint>
    <joint name="Leg2_Leg6" type="revolute">
       <parent link="Leg2"/>
       <child  link="Leg6"/>
       <origin rpy="0 0 0" xyz="0 0.8655933815622265 1.0134532827627971" />
     <axis xyz="1 0 0"/>
       <limit effort="0.0" lower="-3.14159" upper="3.14159" velocity="0.0"/>
    </joint>
    <joint name="Leg6_Leg7" type="revolute">
       <parent link="Leg6"/>
       <child  link="Leg7"/>
       <origin rpy="0 0 0" xyz="2.046510259485706 0 0" />
     <axis xyz="1 0 0"/>
       <limit effort="0.0" lower="-3.14159" upper="3.14159" velocity="0.0"/>
    </joint>
    <joint name="Leg2_Leg8" type="revolute">
       <parent link="Leg2"/>
       <child  link="Leg8"/>
       <origin rpy="0 0 0" xyz="0.6145445758310011 0.8655933815622265 1.0134532827627971" />
     <axis xyz="1 0 0"/>
       <limit effort="0.0" lower="-3.14159" upper="3.14159" velocity="0.0"/>
    </joint>
    <joint name="Leg7_Leg9" type="revolute">
       <parent link="Leg7"/>
       <child  link="Leg9"/>
       <origin rpy="0 0 0" xyz="1.031087710787324 0 0.6779156951953433" />
     <axis xyz="1 0 0"/>
       <limit effort="0.0" lower="-3.14159" upper="3.14159" velocity="0.0"/>
    </joint>
    <joint name="Leg4_Leg10" type="revolute">
       <parent link="Leg4"/>
       <child  link="Leg10"/>
       <origin rpy="0 0 0" xyz="0 2.8861645640645133 0.9765985920124508" />
     <axis xyz="1 0 0"/>
       <limit effort="0.0" lower="-3.14159" upper="3.14159" velocity="0.0"/>
    </joint>
    <joint name="Leg1_Leg11" type="revolute">
       <parent link="Leg1"/>
       <child  link="Leg11"/>
       <origin rpy="0 0 0" xyz="0 1.2022485977271737 2.3724564392401413" />
     <axis xyz="1 0 0"/>
       <limit effort="0.0" lower="-3.14159" upper="3.14159" velocity="0.0"/>
    </joint>
    <joint name="Leg3_Leg12" type="revolute">
       <parent link="Leg3"/>
       <child  link="Leg12"/>
       <origin rpy="0 0 0" xyz="0 0 2.356495038343877" />
     <axis xyz="1 0 0"/>
       <limit effort="0.0" lower="-3.14159" upper="3.14159" velocity="0.0"/>
    </joint>
    <joint name="Leg10_Leg13" type="revolute">
       <parent link="Leg10"/>
       <child  link="Leg13"/>
       <origin rpy="0 0 0" xyz="0 0.6038082345793876 0.5566183422936528" />
     <axis xyz="1 0 0"/>
       <limit effort="0.0" lower="-3.14159" upper="3.14159" velocity="0.0"/>
    </joint>
    <joint name="Leg12_Leg14" type="revolute">
       <parent link="Leg12"/>
       <child  link="Leg14"/>
       <origin rpy="0 0 0" xyz="0 0.9996871070290141 1.294057286264078" />
     <axis xyz="1 0 0"/>
       <limit effort="0.0" lower="-3.14159" upper="3.14159" velocity="0.0"/>
    </joint>
    <joint name="Leg14_Leg15" type="revolute">
       <parent link="Leg14"/>
       <child  link="Leg15"/>
       <origin rpy="0 0 0" xyz="0 1.4003645232593411 0" />
     <axis xyz="1 0 0"/>
       <limit effort="0.0" lower="-3.14159" upper="3.14159" velocity="0.0"/>
    </joint>
    <joint name="Leg8_Leg16" type="revolute">
       <parent link="Leg8"/>
       <child  link="Leg16"/>
       <origin rpy="0 0 0" xyz="0 1.3194758057333518 1.1234830904669648" />
     <axis xyz="1 0 0"/>
       <limit effort="0.0" lower="-3.14159" upper="3.14159" velocity="0.0"/>
    </joint>
    <joint name="Leg5_Leg17" type="revolute">
       <parent link="Leg5"/>
       <child  link="Leg17"/>
       <origin rpy="0 0 0" xyz="0 0.5726912198648932 0.9971211668804721" />
     <axis xyz="1 0 0"/>
       <limit effort="0.0" lower="-3.14159" upper="3.14159" velocity="0.0"/>
    </joint>
    <joint name="Leg9_Leg18" type="revolute">
       <parent link="Leg9"/>
       <child  link="Leg18"/>
       <origin rpy="0 0 0" xyz="1.2331386475974044 0 1.113309802348992" />
     <axis xyz="1 0 0"/>
       <limit effort="0.0" lower="-3.14159" upper="3.14159" velocity="0.0"/>
    </joint>
    <joint name="Leg4_Leg19" type="revolute">
       <parent link="Leg4"/>
       <child  link="Leg19"/>
       <origin rpy="0 0 0" xyz="1.4593923423718467 2.8861645640645133 0.9765985920124508" />
     <axis xyz="1 0 0"/>
       <limit effort="0.0" lower="-3.14159" upper="3.14159" velocity="0.0"/>
    </joint>
    <joint name="Leg5_Leg20" type="revolute">
       <parent link="Leg5"/>
       <child  link="Leg20"/>
       <origin rpy="0 0 0" xyz="0 1.1453824397297865 0.9971211668804721" />
     <axis xyz="1 0 0"/>
       <limit effort="0.0" lower="-3.14159" upper="3.14159" velocity="0.0"/>
    </joint>
    <joint name="Leg18_Leg21" type="revolute">
       <parent link="Leg18"/>
       <child  link="Leg21"/>
       <origin rpy="0 0 0" xyz="1.4947130152836352 0.9291835486585965 0" />
     <axis xyz="1 0 0"/>
       <limit effort="0.0" lower="-3.14159" upper="3.14159" velocity="0.0"/>
    </joint>
    <joint name="Leg16_Leg22" type="revolute">
       <parent link="Leg16"/>
       <child  link="Leg22"/>
       <origin rpy="0 0 0" xyz="1.1234459790365103 0 1.0971660557450882" />
     <axis xyz="1 0 0"/>
       <limit effort="0.0" lower="-3.14159" upper="3.14159" velocity="0.0"/>
    </joint>
    <joint name="Leg8_Leg23" type="revolute">
       <parent link="Leg8"/>
       <child  link="Leg23"/>
       <origin rpy="0 0 0" xyz="1.035750534852193 1.3194758057333518 1.1234830904669648" />
     <axis xyz="1 0 0"/>
       <limit effort="0.0" lower="-3.14159" upper="3.14159" velocity="0.0"/>
    </joint>
    <joint name="Leg16_Leg24" type="revolute">
       <parent link="Leg16"/>
       <child  link="Leg24"/>
       <origin rpy="0 0 0" xyz="1.1234459790365103 0 2.1943321114901764" />
     <axis xyz="1 0 0"/>
       <limit effort="0.0" lower="-3.14159" upper="3.14159" velocity="0.0"/>
    </joint>
    <joint name="Leg22_Leg25" type="revolute">
       <parent link="Leg22"/>
       <child  link="Leg25"/>
       <origin rpy="0 0 0" xyz="1.2284704611367943 0 0.8923785849497433" />
     <axis xyz="1 0 0"/>
       <limit effort="0.0" lower="-3.14159" upper="3.14159" velocity="0.0"/>
    </joint>
    <joint name="Leg6_Leg26" type="revolute">
       <parent link="Leg6"/>
       <child  link="Leg26"/>
       <origin rpy="0 0 0" xyz="2.046510259485706 0.8726259306996675 0" />
     <axis xyz="1 0 0"/>
       <limit effort="0.0" lower="-3.14159" upper="3.14159" velocity="0.0"/>
    </joint>
</robot>