<robot name = "robot">
    <link name="Torso">
        <inertial>
            <origin xyz="0 1.335392549797787 1.0651914556646946" rpy="0 0 0"/>
            <mass value="1" />
            <inertia ixx="100" ixy="0" ixz="0" iyy="100" iyz="0" izz="100" />
        </inertial>
        <visual>
            <origin xyz="0 1.335392549797787 1.0651914556646946" rpy="0 0 0"/>
            <geometry>
                <box size="1.3788336004575923 2.670785099595574 2.1303829113293893" />
            </geometry>
            <material name="Green">
                <color rgba="0 180.0 0.0 1.0"/>
            </material>
        </visual>
        <collision>
            <origin xyz="0 1.335392549797787 1.0651914556646946" rpy="0 0 0"/>
            <geometry>
                <box size="1.3788336004575923 2.670785099595574 2.1303829113293893" />
            </geometry>
        </collision>
    </link>
    <link name="Leg1">
        <inertial>
            <origin xyz="1.4288462056689926 1.2498629003820887 0.9896800477401971" rpy="0 0 0"/>
            <mass value="1" />
            <inertia ixx="100" ixy="0" ixz="0" iyy="100" iyz="0" izz="100" />
        </inertial>
        <visual>
            <origin xyz="1.4288462056689926 1.2498629003820887 0.9896800477401971" rpy="0 0 0"/>
            <geometry>
                <box size="2.857692411337985 2.4997258007641774 1.9793600954803943" />
            </geometry>
            <material name="Blue">
                <color rgba="0 1.0 1.0 1.0"/>
            </material>
        </visual>
        <collision>
            <origin xyz="1.4288462056689926 1.2498629003820887 0.9896800477401971" rpy="0 0 0"/>
            <geometry>
                <box size="2.857692411337985 2.4997258007641774 1.9793600954803943" />
            </geometry>
        </collision>
    </link>
    <link name="Leg2">
        <inertial>
            <origin xyz="0.7299484836006072 0 1.9945812671721797" rpy="0 0 0"/>
            <mass value="1" />
            <inertia ixx="100" ixy="0" ixz="0" iyy="100" iyz="0" izz="100" />
        </inertial>
        <visual>
            <origin xyz="0.7299484836006072 0 1.9945812671721797" rpy="0 0 0"/>
            <geometry>
                <box size="1.4598969672012143 2.594954588189963 1.9945812671721797" />
            </geometry>
            <material name="Blue">
                <color rgba="0 1.0 1.0 1.0"/>
            </material>
        </visual>
        <collision>
            <origin xyz="0.7299484836006072 0 1.9945812671721797" rpy="0 0 0"/>
            <geometry>
                <box size="1.4598969672012143 2.594954588189963 1.9945812671721797" />
            </geometry>
        </collision>
    </link>
    <link name="Leg3">
        <inertial>
            <origin xyz="0.7497258561732043 0.5538602558975813 1.8411180078271434" rpy="0 0 0"/>
            <mass value="1" />
            <inertia ixx="100" ixy="0" ixz="0" iyy="100" iyz="0" izz="100" />
        </inertial>
        <visual>
            <origin xyz="0.7497258561732043 0.5538602558975813 1.8411180078271434" rpy="0 0 0"/>
            <geometry>
                <box size="1.4994517123464086 1.1077205117951625 1.8411180078271434" />
            </geometry>
            <material name="Blue">
                <color rgba="0 1.0 1.0 1.0"/>
            </material>
        </visual>
        <collision>
            <origin xyz="0.7497258561732043 0.5538602558975813 1.8411180078271434" rpy="0 0 0"/>
            <geometry>
                <box size="1.4994517123464086 1.1077205117951625 1.8411180078271434" />
            </geometry>
        </collision>
    </link>
    <link name="Leg4">
        <inertial>
            <origin xyz="0.8712816229210935 0.5684833520318604 1.4567563699621107" rpy="0 0 0"/>
            <mass value="1" />
            <inertia ixx="100" ixy="0" ixz="0" iyy="100" iyz="0" izz="100" />
        </inertial>
        <visual>
            <origin xyz="0.8712816229210935 0.5684833520318604 1.4567563699621107" rpy="0 0 0"/>
            <geometry>
                <box size="1.742563245842187 1.1369667040637208 2.9135127399242213" />
            </geometry>
            <material name="Blue">
                <color rgba="0 1.0 1.0 1.0"/>
            </material>
        </visual>
        <collision>
            <origin xyz="0.8712816229210935 0.5684833520318604 1.4567563699621107" rpy="0 0 0"/>
            <geometry>
                <box size="1.742563245842187 1.1369667040637208 2.9135127399242213" />
            </geometry>
        </collision>
    </link>
    <link name="Leg5">
        <inertial>
            <origin xyz="0 0 1.1679057926622922" rpy="0 0 0"/>
            <mass value="1" />
            <inertia ixx="100" ixy="0" ixz="0" iyy="100" iyz="0" izz="100" />
        </inertial>
        <visual>
            <origin xyz="0 0 1.1679057926622922" rpy="0 0 0"/>
            <geometry>
                <box size="1.8690492325788466 2.915357282465491 2.3358115853245844" />
            </geometry>
            <material name="Blue">
                <color rgba="0 1.0 1.0 1.0"/>
            </material>
        </visual>
        <collision>
            <origin xyz="0 0 1.1679057926622922" rpy="0 0 0"/>
            <geometry>
                <box size="1.8690492325788466 2.915357282465491 2.3358115853245844" />
            </geometry>
        </collision>
    </link>
    <link name="Leg6">
        <inertial>
            <origin xyz="0.5997287069075292 1.110965719890845 0" rpy="0 0 0"/>
            <mass value="1" />
            <inertia ixx="100" ixy="0" ixz="0" iyy="100" iyz="0" izz="100" />
        </inertial>
        <visual>
            <origin xyz="0.5997287069075292 1.110965719890845 0" rpy="0 0 0"/>
            <geometry>
                <box size="1.1994574138150584 2.22193143978169 1.3753381399901121" />
            </geometry>
            <material name="Blue">
                <color rgba="0 1.0 1.0 1.0"/>
            </material>
        </visual>
        <collision>
            <origin xyz="0.5997287069075292 1.110965719890845 0" rpy="0 0 0"/>
            <geometry>
                <box size="1.1994574138150584 2.22193143978169 1.3753381399901121" />
            </geometry>
        </collision>
    </link>
    <link name="Leg7">
        <inertial>
            <origin xyz="1.895337963714251 0 0.5656961194552116" rpy="0 0 0"/>
            <mass value="1" />
            <inertia ixx="100" ixy="0" ixz="0" iyy="100" iyz="0" izz="100" />
        </inertial>
        <visual>
            <origin xyz="1.895337963714251 0 0.5656961194552116" rpy="0 0 0"/>
            <geometry>
                <box size="1.895337963714251 2.1410515869483544 1.1313922389104232" />
            </geometry>
            <material name="Blue">
                <color rgba="0 1.0 1.0 1.0"/>
            </material>
        </visual>
        <collision>
            <origin xyz="1.895337963714251 0 0.5656961194552116" rpy="0 0 0"/>
            <geometry>
                <box size="1.895337963714251 2.1410515869483544 1.1313922389104232" />
            </geometry>
        </collision>
    </link>
    <link name="Leg8">
        <inertial>
            <origin xyz="0.9047059386295975 2.7284811850954602 0.7694901059760321" rpy="0 0 0"/>
            <mass value="1" />
            <inertia ixx="100" ixy="0" ixz="0" iyy="100" iyz="0" izz="100" />
        </inertial>
        <visual>
            <origin xyz="0.9047059386295975 2.7284811850954602 0.7694901059760321" rpy="0 0 0"/>
            <geometry>
                <box size="1.809411877259195 2.7284811850954602 1.5389802119520641" />
            </geometry>
            <material name="Blue">
                <color rgba="0 1.0 1.0 1.0"/>
            </material>
        </visual>
        <collision>
            <origin xyz="0.9047059386295975 2.7284811850954602 0.7694901059760321" rpy="0 0 0"/>
            <geometry>
                <box size="1.809411877259195 2.7284811850954602 1.5389802119520641" />
            </geometry>
        </collision>
    </link>
    <link name="Leg9">
        <inertial>
            <origin xyz="0.942222014176304 1.120081443425018 1.4002074030957217" rpy="0 0 0"/>
            <mass value="1" />
            <inertia ixx="100" ixy="0" ixz="0" iyy="100" iyz="0" izz="100" />
        </inertial>
        <visual>
            <origin xyz="0.942222014176304 1.120081443425018 1.4002074030957217" rpy="0 0 0"/>
            <geometry>
                <box size="1.884444028352608 2.240162886850036 2.8004148061914433" />
            </geometry>
            <material name="Blue">
                <color rgba="0 1.0 1.0 1.0"/>
            </material>
        </visual>
        <collision>
            <origin xyz="0.942222014176304 1.120081443425018 1.4002074030957217" rpy="0 0 0"/>
            <geometry>
                <box size="1.884444028352608 2.240162886850036 2.8004148061914433" />
            </geometry>
        </collision>
    </link>
    <link name="Leg10">
        <inertial>
            <origin xyz="0 0 2.5030219379092458" rpy="0 0 0"/>
            <mass value="1" />
            <inertia ixx="100" ixy="0" ixz="0" iyy="100" iyz="0" izz="100" />
        </inertial>
        <visual>
            <origin xyz="0 0 2.5030219379092458" rpy="0 0 0"/>
            <geometry>
                <box size="1.9372762200383862 1.1922331331078988 2.5030219379092458" />
            </geometry>
            <material name="Blue">
                <color rgba="0 1.0 1.0 1.0"/>
            </material>
        </visual>
        <collision>
            <origin xyz="0 0 2.5030219379092458" rpy="0 0 0"/>
            <geometry>
                <box size="1.9372762200383862 1.1922331331078988 2.5030219379092458" />
            </geometry>
        </collision>
    </link>
    <link name="Leg11">
        <inertial>
            <origin xyz="0 0 0.931004491645714" rpy="0 0 0"/>
            <mass value="1" />
            <inertia ixx="100" ixy="0" ixz="0" iyy="100" iyz="0" izz="100" />
        </inertial>
        <visual>
            <origin xyz="0 0 0.931004491645714" rpy="0 0 0"/>
            <geometry>
                <box size="2.6525584933714335 2.369516427769745 1.862008983291428" />
            </geometry>
            <material name="Blue">
                <color rgba="0 1.0 1.0 1.0"/>
            </material>
        </visual>
        <collision>
            <origin xyz="0 0 0.931004491645714" rpy="0 0 0"/>
            <geometry>
                <box size="2.6525584933714335 2.369516427769745 1.862008983291428" />
            </geometry>
        </collision>
    </link>
    <link name="Leg12">
        <inertial>
            <origin xyz="1.2089142018513344 0 0" rpy="0 0 0"/>
            <mass value="1" />
            <inertia ixx="100" ixy="0" ixz="0" iyy="100" iyz="0" izz="100" />
        </inertial>
        <visual>
            <origin xyz="1.2089142018513344 0 0" rpy="0 0 0"/>
            <geometry>
                <box size="2.4178284037026687 2.680352175473409 2.0064734427613287" />
            </geometry>
            <material name="Blue">
                <color rgba="0 1.0 1.0 1.0"/>
            </material>
        </visual>
        <collision>
            <origin xyz="1.2089142018513344 0 0" rpy="0 0 0"/>
            <geometry>
                <box size="2.4178284037026687 2.680352175473409 2.0064734427613287" />
            </geometry>
        </collision>
    </link>
    <link name="Leg13">
        <inertial>
            <origin xyz="1.1337483875435332 0 0" rpy="0 0 0"/>
            <mass value="1" />
            <inertia ixx="100" ixy="0" ixz="0" iyy="100" iyz="0" izz="100" />
        </inertial>
        <visual>
            <origin xyz="1.1337483875435332 0 0" rpy="0 0 0"/>
            <geometry>
                <box size="2.2674967750870665 1.1736967471507385 2.993169705341102" />
            </geometry>
            <material name="Blue">
                <color rgba="0 1.0 1.0 1.0"/>
            </material>
        </visual>
        <collision>
            <origin xyz="1.1337483875435332 0 0" rpy="0 0 0"/>
            <geometry>
                <box size="2.2674967750870665 1.1736967471507385 2.993169705341102" />
            </geometry>
        </collision>
    </link>
    <link name="Leg14">
        <inertial>
            <origin xyz="1.0795875784710525 0 1.2383049741707648" rpy="0 0 0"/>
            <mass value="1" />
            <inertia ixx="100" ixy="0" ixz="0" iyy="100" iyz="0" izz="100" />
        </inertial>
        <visual>
            <origin xyz="1.0795875784710525 0 1.2383049741707648" rpy="0 0 0"/>
            <geometry>
                <box size="2.159175156942105 2.5626779124992023 2.4766099483415296" />
            </geometry>
            <material name="Blue">
                <color rgba="0 1.0 1.0 1.0"/>
            </material>
        </visual>
        <collision>
            <origin xyz="1.0795875784710525 0 1.2383049741707648" rpy="0 0 0"/>
            <geometry>
                <box size="2.159175156942105 2.5626779124992023 2.4766099483415296" />
            </geometry>
        </collision>
    </link>
    <link name="Leg15">
        <inertial>
            <origin xyz="2.9572253632219896 0 0" rpy="0 0 0"/>
            <mass value="1" />
            <inertia ixx="100" ixy="0" ixz="0" iyy="100" iyz="0" izz="100" />
        </inertial>
        <visual>
            <origin xyz="2.9572253632219896 0 0" rpy="0 0 0"/>
            <geometry>
                <box size="2.9572253632219896 1.5555111829775143 1.9799310496736835" />
            </geometry>
            <material name="Blue">
                <color rgba="0 1.0 1.0 1.0"/>
            </material>
        </visual>
        <collision>
            <origin xyz="2.9572253632219896 0 0" rpy="0 0 0"/>
            <geometry>
                <box size="2.9572253632219896 1.5555111829775143 1.9799310496736835" />
            </geometry>
        </collision>
    </link>
    <link name="Leg16">
        <inertial>
            <origin xyz="0 0 1.2939977057829535" rpy="0 0 0"/>
            <mass value="1" />
            <inertia ixx="100" ixy="0" ixz="0" iyy="100" iyz="0" izz="100" />
        </inertial>
        <visual>
            <origin xyz="0 0 1.2939977057829535" rpy="0 0 0"/>
            <geometry>
                <box size="1.1878999496599407 2.969356058225087 2.587995411565907" />
            </geometry>
            <material name="Blue">
                <color rgba="0 1.0 1.0 1.0"/>
            </material>
        </visual>
        <collision>
            <origin xyz="0 0 1.2939977057829535" rpy="0 0 0"/>
            <geometry>
                <box size="1.1878999496599407 2.969356058225087 2.587995411565907" />
            </geometry>
        </collision>
    </link>
    <link name="Leg17">
        <inertial>
            <origin xyz="0 0.6687183110350744 0" rpy="0 0 0"/>
            <mass value="1" />
            <inertia ixx="100" ixy="0" ixz="0" iyy="100" iyz="0" izz="100" />
        </inertial>
        <visual>
            <origin xyz="0 0.6687183110350744 0" rpy="0 0 0"/>
            <geometry>
                <box size="2.1500779680603044 1.3374366220701488 1.944168174312253" />
            </geometry>
            <material name="Blue">
                <color rgba="0 1.0 1.0 1.0"/>
            </material>
        </visual>
        <collision>
            <origin xyz="0 0.6687183110350744 0" rpy="0 0 0"/>
            <geometry>
                <box size="2.1500779680603044 1.3374366220701488 1.944168174312253" />
            </geometry>
        </collision>
    </link>
    <link name="Leg18">
        <inertial>
            <origin xyz="0 1.3770303193136604 0" rpy="0 0 0"/>
            <mass value="1" />
            <inertia ixx="100" ixy="0" ixz="0" iyy="100" iyz="0" izz="100" />
        </inertial>
        <visual>
            <origin xyz="0 1.3770303193136604 0" rpy="0 0 0"/>
            <geometry>
                <box size="1.0523218122173468 1.3770303193136604 2.411648002222481" />
            </geometry>
            <material name="Blue">
                <color rgba="0 1.0 1.0 1.0"/>
            </material>
        </visual>
        <collision>
            <origin xyz="0 1.3770303193136604 0" rpy="0 0 0"/>
            <geometry>
                <box size="1.0523218122173468 1.3770303193136604 2.411648002222481" />
            </geometry>
        </collision>
    </link>
    <link name="Leg19">
        <inertial>
            <origin xyz="1.2329145920004798 0 0.5872433416281562" rpy="0 0 0"/>
            <mass value="1" />
            <inertia ixx="100" ixy="0" ixz="0" iyy="100" iyz="0" izz="100" />
        </inertial>
        <visual>
            <origin xyz="1.2329145920004798 0 0.5872433416281562" rpy="0 0 0"/>
            <geometry>
                <box size="2.4658291840009596 1.4834282033319266 1.1744866832563123" />
            </geometry>
            <material name="Blue">
                <color rgba="0 1.0 1.0 1.0"/>
            </material>
        </visual>
        <collision>
            <origin xyz="1.2329145920004798 0 0.5872433416281562" rpy="0 0 0"/>
            <geometry>
                <box size="2.4658291840009596 1.4834282033319266 1.1744866832563123" />
            </geometry>
        </collision>
    </link>
    <link name="Leg20">
        <inertial>
            <origin xyz="0.8206389982653772 1.0146220206226513 0" rpy="0 0 0"/>
            <mass value="1" />
            <inertia ixx="100" ixy="0" ixz="0" iyy="100" iyz="0" izz="100" />
        </inertial>
        <visual>
            <origin xyz="0.8206389982653772 1.0146220206226513 0" rpy="0 0 0"/>
            <geometry>
                <box size="1.6412779965307545 2.0292440412453026 1.3884233912655832" />
            </geometry>
            <material name="Blue">
                <color rgba="0 1.0 1.0 1.0"/>
            </material>
        </visual>
        <collision>
            <origin xyz="0.8206389982653772 1.0146220206226513 0" rpy="0 0 0"/>
            <geometry>
                <box size="1.6412779965307545 2.0292440412453026 1.3884233912655832" />
            </geometry>
        </collision>
    </link>
    <link name="Leg21">
        <inertial>
            <origin xyz="0 0.8255420820521836 0" rpy="0 0 0"/>
            <mass value="1" />
            <inertia ixx="100" ixy="0" ixz="0" iyy="100" iyz="0" izz="100" />
        </inertial>
        <visual>
            <origin xyz="0 0.8255420820521836 0" rpy="0 0 0"/>
            <geometry>
                <box size="1.2355439510969584 1.6510841641043672 1.3532103033372112" />
            </geometry>
            <material name="Blue">
                <color rgba="0 1.0 1.0 1.0"/>
            </material>
        </visual>
        <collision>
            <origin xyz="0 0.8255420820521836 0" rpy="0 0 0"/>
            <geometry>
                <box size="1.2355439510969584 1.6510841641043672 1.3532103033372112" />
            </geometry>
        </collision>
    </link>
    <link name="Leg22">
        <inertial>
            <origin xyz="0 0 0.9347757773711134" rpy="0 0 0"/>
            <mass value="1" />
            <inertia ixx="100" ixy="0" ixz="0" iyy="100" iyz="0" izz="100" />
        </inertial>
        <visual>
            <origin xyz="0 0 0.9347757773711134" rpy="0 0 0"/>
            <geometry>
                <box size="2.999373491234425 2.1810191080290453 1.8695515547422268" />
            </geometry>
            <material name="Blue">
                <color rgba="0 1.0 1.0 1.0"/>
            </material>
        </visual>
        <collision>
            <origin xyz="0 0 0.9347757773711134" rpy="0 0 0"/>
            <geometry>
                <box size="2.999373491234425 2.1810191080290453 1.8695515547422268" />
            </geometry>
        </collision>
    </link>
    <link name="Leg23">
        <inertial>
            <origin xyz="0 0 1.3919251874078902" rpy="0 0 0"/>
            <mass value="1" />
            <inertia ixx="100" ixy="0" ixz="0" iyy="100" iyz="0" izz="100" />
        </inertial>
        <visual>
            <origin xyz="0 0 1.3919251874078902" rpy="0 0 0"/>
            <geometry>
                <box size="2.8537188343314934 1.3136095343065648 2.7838503748157803" />
            </geometry>
            <material name="Blue">
                <color rgba="0 1.0 1.0 1.0"/>
            </material>
        </visual>
        <collision>
            <origin xyz="0 0 1.3919251874078902" rpy="0 0 0"/>
            <geometry>
                <box size="2.8537188343314934 1.3136095343065648 2.7838503748157803" />
            </geometry>
        </collision>
    </link>
    <link name="Leg24">
        <inertial>
            <origin xyz="0 1.245193632643188 0" rpy="0 0 0"/>
            <mass value="1" />
            <inertia ixx="100" ixy="0" ixz="0" iyy="100" iyz="0" izz="100" />
        </inertial>
        <visual>
            <origin xyz="0 1.245193632643188 0" rpy="0 0 0"/>
            <geometry>
                <box size="1.825073412299973 2.490387265286376 2.932574799342995" />
            </geometry>
            <material name="Blue">
                <color rgba="0 1.0 1.0 1.0"/>
            </material>
        </visual>
        <collision>
            <origin xyz="0 1.245193632643188 0" rpy="0 0 0"/>
            <geometry>
                <box size="1.825073412299973 2.490387265286376 2.932574799342995" />
            </geometry>
        </collision>
    </link>
    <link name="Leg25">
        <inertial>
            <origin xyz="0 1.1408747662355687 0" rpy="0 0 0"/>
            <mass value="1" />
            <inertia ixx="100" ixy="0" ixz="0" iyy="100" iyz="0" izz="100" />
        </inertial>
        <visual>
            <origin xyz="0 1.1408747662355687 0" rpy="0 0 0"/>
            <geometry>
                <box size="2.1272234167817956 2.2817495324711374 2.385501755720779" />
            </geometry>
            <material name="Green">
                <color rgba="0 180.0 100.0 1.0"/>
            </material>
        </visual>
        <collision>
            <origin xyz="0 1.1408747662355687 0" rpy="0 0 0"/>
            <geometry>
                <box size="2.1272234167817956 2.2817495324711374 2.385501755720779" />
            </geometry>
        </collision>
    </link>
    <joint name="Torso_Leg1" type="revolute">
       <parent link="Torso"/>
       <child  link="Leg1"/>
       <origin rpy="0 0 0" xyz="0 1.335392549797787 1.0651914556646946" />
     <axis xyz="1 0 0"/>
       <limit effort="0.0" lower="-3.14159" upper="3.14159" velocity="0.0"/>
    </joint>
    <joint name="Leg1_Leg2" type="revolute">
       <parent link="Leg1"/>
       <child  link="Leg2"/>
       <origin rpy="0 0 0" xyz="0.7299484836006072 0 1.9945812671721797" />
     <axis xyz="1 0 0"/>
       <limit effort="0.0" lower="-3.14159" upper="3.14159" velocity="0.0"/>
    </joint>
    <joint name="Leg2_Leg3" type="revolute">
       <parent link="Leg2"/>
       <child  link="Leg3"/>
       <origin rpy="0 0 0" xyz="0.7497258561732043 0.5538602558975813 1.8411180078271434" />
     <axis xyz="1 0 0"/>
       <limit effort="0.0" lower="-3.14159" upper="3.14159" velocity="0.0"/>
    </joint>
    <joint name="Torso_Leg4" type="revolute">
       <parent link="Torso"/>
       <child  link="Leg4"/>
       <origin rpy="0 0 0" xyz="1.4288462056689926 1.2498629003820887 0.9896800477401971" />
     <axis xyz="1 0 0"/>
       <limit effort="0.0" lower="-3.14159" upper="3.14159" velocity="0.0"/>
    </joint>
    <joint name="Leg3_Leg5" type="revolute">
       <parent link="Leg3"/>
       <child  link="Leg5"/>
       <origin rpy="0 0 0" xyz="0.8712816229210935 0.5684833520318604 1.4567563699621107" />
     <axis xyz="1 0 0"/>
       <limit effort="0.0" lower="-3.14159" upper="3.14159" velocity="0.0"/>
    </joint>
    <joint name="Leg1_Leg6" type="revolute">
       <parent link="Leg1"/>
       <child  link="Leg6"/>
       <origin rpy="0 0 0" xyz="0.7299484836006072 0 1.9945812671721797" />
     <axis xyz="1 0 0"/>
       <limit effort="0.0" lower="-3.14159" upper="3.14159" velocity="0.0"/>
    </joint>
    <joint name="Leg2_Leg7" type="revolute">
       <parent link="Leg2"/>
       <child  link="Leg7"/>
       <origin rpy="0 0 0" xyz="0.7497258561732043 0.5538602558975813 1.8411180078271434" />
     <axis xyz="1 0 0"/>
       <limit effort="0.0" lower="-3.14159" upper="3.14159" velocity="0.0"/>
    </joint>
    <joint name="Leg5_Leg8" type="revolute">
       <parent link="Leg5"/>
       <child  link="Leg8"/>
       <origin rpy="0 0 0" xyz="0.5997287069075292 1.110965719890845 0" />
     <axis xyz="1 0 0"/>
       <limit effort="0.0" lower="-3.14159" upper="3.14159" velocity="0.0"/>
    </joint>
    <joint name="Leg3_Leg9" type="revolute">
       <parent link="Leg3"/>
       <child  link="Leg9"/>
       <origin rpy="0 0 0" xyz="0.8712816229210935 0.5684833520318604 1.4567563699621107" />
     <axis xyz="1 0 0"/>
       <limit effort="0.0" lower="-3.14159" upper="3.14159" velocity="0.0"/>
    </joint>
    <joint name="Leg7_Leg10" type="revolute">
       <parent link="Leg7"/>
       <child  link="Leg10"/>
       <origin rpy="0 0 0" xyz="0.9047059386295975 2.7284811850954602 0.7694901059760321" />
     <axis xyz="1 0 0"/>
       <limit effort="0.0" lower="-3.14159" upper="3.14159" velocity="0.0"/>
    </joint>
    <joint name="Leg6_Leg11" type="revolute">
       <parent link="Leg6"/>
       <child  link="Leg11"/>
       <origin rpy="0 0 0" xyz="1.895337963714251 0 0.5656961194552116" />
     <axis xyz="1 0 0"/>
       <limit effort="0.0" lower="-3.14159" upper="3.14159" velocity="0.0"/>
    </joint>
    <joint name="Leg6_Leg12" type="revolute">
       <parent link="Leg6"/>
       <child  link="Leg12"/>
       <origin rpy="0 0 0" xyz="1.895337963714251 0 0.5656961194552116" />
     <axis xyz="1 0 0"/>
       <limit effort="0.0" lower="-3.14159" upper="3.14159" velocity="0.0"/>
    </joint>
    <joint name="Leg7_Leg13" type="revolute">
       <parent link="Leg7"/>
       <child  link="Leg13"/>
       <origin rpy="0 0 0" xyz="0.9047059386295975 2.7284811850954602 0.7694901059760321" />
     <axis xyz="1 0 0"/>
       <limit effort="0.0" lower="-3.14159" upper="3.14159" velocity="0.0"/>
    </joint>
    <joint name="Leg9_Leg14" type="revolute">
       <parent link="Leg9"/>
       <child  link="Leg14"/>
       <origin rpy="0 0 0" xyz="0 0 2.5030219379092458" />
     <axis xyz="1 0 0"/>
       <limit effort="0.0" lower="-3.14159" upper="3.14159" velocity="0.0"/>
    </joint>
    <joint name="Leg8_Leg15" type="revolute">
       <parent link="Leg8"/>
       <child  link="Leg15"/>
       <origin rpy="0 0 0" xyz="0.942222014176304 1.120081443425018 1.4002074030957217" />
     <axis xyz="1 0 0"/>
       <limit effort="0.0" lower="-3.14159" upper="3.14159" velocity="0.0"/>
    </joint>
    <joint name="Leg8_Leg16" type="revolute">
       <parent link="Leg8"/>
       <child  link="Leg16"/>
       <origin rpy="0 0 0" xyz="0.942222014176304 1.120081443425018 1.4002074030957217" />
     <axis xyz="1 0 0"/>
       <limit effort="0.0" lower="-3.14159" upper="3.14159" velocity="0.0"/>
    </joint>
    <joint name="Leg2_Leg17" type="revolute">
       <parent link="Leg2"/>
       <child  link="Leg17"/>
       <origin rpy="0 0 0" xyz="0.7497258561732043 0.5538602558975813 1.8411180078271434" />
     <axis xyz="1 0 0"/>
       <limit effort="0.0" lower="-3.14159" upper="3.14159" velocity="0.0"/>
    </joint>
    <joint name="Leg7_Leg18" type="revolute">
       <parent link="Leg7"/>
       <child  link="Leg18"/>
       <origin rpy="0 0 0" xyz="0.9047059386295975 2.7284811850954602 0.7694901059760321" />
     <axis xyz="1 0 0"/>
       <limit effort="0.0" lower="-3.14159" upper="3.14159" velocity="0.0"/>
    </joint>
    <joint name="Leg13_Leg19" type="revolute">
       <parent link="Leg13"/>
       <child  link="Leg19"/>
       <origin rpy="0 0 0" xyz="1.0795875784710525 0 1.2383049741707648" />
     <axis xyz="1 0 0"/>
       <limit effort="0.0" lower="-3.14159" upper="3.14159" velocity="0.0"/>
    </joint>
    <joint name="Leg14_Leg20" type="revolute">
       <parent link="Leg14"/>
       <child  link="Leg20"/>
       <origin rpy="0 0 0" xyz="2.9572253632219896 0 0" />
     <axis xyz="1 0 0"/>
       <limit effort="0.0" lower="-3.14159" upper="3.14159" velocity="0.0"/>
    </joint>
    <joint name="Leg17_Leg21" type="revolute">
       <parent link="Leg17"/>
       <child  link="Leg21"/>
       <origin rpy="0 0 0" xyz="0 1.3770303193136604 0" />
     <axis xyz="1 0 0"/>
       <limit effort="0.0" lower="-3.14159" upper="3.14159" velocity="0.0"/>
    </joint>
    <joint name="Leg18_Leg22" type="revolute">
       <parent link="Leg18"/>
       <child  link="Leg22"/>
       <origin rpy="0 0 0" xyz="1.2329145920004798 0 0.5872433416281562" />
     <axis xyz="1 0 0"/>
       <limit effort="0.0" lower="-3.14159" upper="3.14159" velocity="0.0"/>
    </joint>
    <joint name="Torso_Leg23" type="revolute">
       <parent link="Torso"/>
       <child  link="Leg23"/>
       <origin rpy="0 0 0" xyz="1.4288462056689926 1.2498629003820887 0.9896800477401971" />
     <axis xyz="1 0 0"/>
       <limit effort="0.0" lower="-3.14159" upper="3.14159" velocity="0.0"/>
    </joint>
    <joint name="Leg19_Leg24" type="revolute">
       <parent link="Leg19"/>
       <child  link="Leg24"/>
       <origin rpy="0 0 0" xyz="0.8206389982653772 1.0146220206226513 0" />
     <axis xyz="1 0 0"/>
       <limit effort="0.0" lower="-3.14159" upper="3.14159" velocity="0.0"/>
    </joint>
    <joint name="Leg24_Leg25" type="revolute">
       <parent link="Leg24"/>
       <child  link="Leg24"/>
       <origin rpy="0 0 0" xyz="0 2.490387265286376 0" />
     <axis xyz="1 0 0"/>
       <limit effort="0.0" lower="-3.14159" upper="3.14159" velocity="0.0"/>
    </joint>
</robot>