<robot name = "robot">
    <link name="Torso">
        <inertial>
            <origin xyz="0 0 1.1504032897952254" rpy="0 0 0"/>
            <mass value="1" />
            <inertia ixx="100" ixy="0" ixz="0" iyy="100" iyz="0" izz="100" />
        </inertial>
        <visual>
            <origin xyz="0 0 1.1504032897952254" rpy="0 0 0"/>
            <geometry>
                <box size="2.6280620246280035 1.508330145383524 2.300806579590451" />
            </geometry>
            <material name="Green">
                <color rgba="0 180.0 0.0 1.0"/>
            </material>
        </visual>
        <collision>
            <origin xyz="0 0 1.1504032897952254" rpy="0 0 0"/>
            <geometry>
                <box size="2.6280620246280035 1.508330145383524 2.300806579590451" />
            </geometry>
        </collision>
    </link>
    <link name="Leg1">
        <inertial>
            <origin xyz="0.6262797758486719 0 0" rpy="0 0 0"/>
            <mass value="1" />
            <inertia ixx="100" ixy="0" ixz="0" iyy="100" iyz="0" izz="100" />
        </inertial>
        <visual>
            <origin xyz="0.6262797758486719 0 0" rpy="0 0 0"/>
            <geometry>
                <box size="1.2525595516973438 1.0280606513964705 1.4699136243562145" />
            </geometry>
            <material name="Green">
                <color rgba="0 180.0 0.0 1.0"/>
            </material>
        </visual>
        <collision>
            <origin xyz="0.6262797758486719 0 0" rpy="0 0 0"/>
            <geometry>
                <box size="1.2525595516973438 1.0280606513964705 1.4699136243562145" />
            </geometry>
        </collision>
    </link>
    <link name="Leg2">
        <inertial>
            <origin xyz="0.9981569566180742 0 0" rpy="0 0 0"/>
            <mass value="1" />
            <inertia ixx="100" ixy="0" ixz="0" iyy="100" iyz="0" izz="100" />
        </inertial>
        <visual>
            <origin xyz="0.9981569566180742 0 0" rpy="0 0 0"/>
            <geometry>
                <box size="1.9963139132361485 2.0657658585075227 2.3851685313832305" />
            </geometry>
            <material name="Green">
                <color rgba="0 180.0 0.0 1.0"/>
            </material>
        </visual>
        <collision>
            <origin xyz="0.9981569566180742 0 0" rpy="0 0 0"/>
            <geometry>
                <box size="1.9963139132361485 2.0657658585075227 2.3851685313832305" />
            </geometry>
        </collision>
    </link>
    <link name="Leg3">
        <inertial>
            <origin xyz="0 0.9493788566040109 0" rpy="0 0 0"/>
            <mass value="1" />
            <inertia ixx="100" ixy="0" ixz="0" iyy="100" iyz="0" izz="100" />
        </inertial>
        <visual>
            <origin xyz="0 0.9493788566040109 0" rpy="0 0 0"/>
            <geometry>
                <box size="1.831982991422296 1.8987577132080218 2.8485070361503966" />
            </geometry>
            <material name="Green">
                <color rgba="0 180.0 0.0 1.0"/>
            </material>
        </visual>
        <collision>
            <origin xyz="0 0.9493788566040109 0" rpy="0 0 0"/>
            <geometry>
                <box size="1.831982991422296 1.8987577132080218 2.8485070361503966" />
            </geometry>
        </collision>
    </link>
    <link name="Leg4">
        <inertial>
            <origin xyz="1.3376318461188457 0 0" rpy="0 0 0"/>
            <mass value="1" />
            <inertia ixx="100" ixy="0" ixz="0" iyy="100" iyz="0" izz="100" />
        </inertial>
        <visual>
            <origin xyz="1.3376318461188457 0 0" rpy="0 0 0"/>
            <geometry>
                <box size="2.6752636922376913 1.1177033927836129 2.2270228787547146" />
            </geometry>
            <material name="Green">
                <color rgba="0 180.0 0.0 1.0"/>
            </material>
        </visual>
        <collision>
            <origin xyz="1.3376318461188457 0 0" rpy="0 0 0"/>
            <geometry>
                <box size="2.6752636922376913 1.1177033927836129 2.2270228787547146" />
            </geometry>
        </collision>
    </link>
    <link name="Leg5">
        <inertial>
            <origin xyz="0 0 1.4623311312328204" rpy="0 0 0"/>
            <mass value="1" />
            <inertia ixx="100" ixy="0" ixz="0" iyy="100" iyz="0" izz="100" />
        </inertial>
        <visual>
            <origin xyz="0 0 1.4623311312328204" rpy="0 0 0"/>
            <geometry>
                <box size="1.3722882856659067 2.6326101068532157 2.924662262465641" />
            </geometry>
            <material name="Green">
                <color rgba="0 180.0 0.0 1.0"/>
            </material>
        </visual>
        <collision>
            <origin xyz="0 0 1.4623311312328204" rpy="0 0 0"/>
            <geometry>
                <box size="1.3722882856659067 2.6326101068532157 2.924662262465641" />
            </geometry>
        </collision>
    </link>
    <link name="Leg6">
        <inertial>
            <origin xyz="0 0.5414764902524106 0" rpy="0 0 0"/>
            <mass value="1" />
            <inertia ixx="100" ixy="0" ixz="0" iyy="100" iyz="0" izz="100" />
        </inertial>
        <visual>
            <origin xyz="0 0.5414764902524106 0" rpy="0 0 0"/>
            <geometry>
                <box size="1.6990888321624982 1.0829529805048212 2.4677577951978753" />
            </geometry>
            <material name="Green">
                <color rgba="0 180.0 0.0 1.0"/>
            </material>
        </visual>
        <collision>
            <origin xyz="0 0.5414764902524106 0" rpy="0 0 0"/>
            <geometry>
                <box size="1.6990888321624982 1.0829529805048212 2.4677577951978753" />
            </geometry>
        </collision>
    </link>
    <link name="Leg7">
        <inertial>
            <origin xyz="0 0 1.0941844785498078" rpy="0 0 0"/>
            <mass value="1" />
            <inertia ixx="100" ixy="0" ixz="0" iyy="100" iyz="0" izz="100" />
        </inertial>
        <visual>
            <origin xyz="0 0 1.0941844785498078" rpy="0 0 0"/>
            <geometry>
                <box size="2.9863943251117036 2.849949269145408 2.1883689570996157" />
            </geometry>
            <material name="Green">
                <color rgba="0 180.0 0.0 1.0"/>
            </material>
        </visual>
        <collision>
            <origin xyz="0 0 1.0941844785498078" rpy="0 0 0"/>
            <geometry>
                <box size="2.9863943251117036 2.849949269145408 2.1883689570996157" />
            </geometry>
        </collision>
    </link>
    <link name="Leg8">
        <inertial>
            <origin xyz="0 0 1.2027178342874847" rpy="0 0 0"/>
            <mass value="1" />
            <inertia ixx="100" ixy="0" ixz="0" iyy="100" iyz="0" izz="100" />
        </inertial>
        <visual>
            <origin xyz="0 0 1.2027178342874847" rpy="0 0 0"/>
            <geometry>
                <box size="1.520712116601032 1.0754266596366366 2.4054356685749694" />
            </geometry>
            <material name="Green">
                <color rgba="0 180.0 0.0 1.0"/>
            </material>
        </visual>
        <collision>
            <origin xyz="0 0 1.2027178342874847" rpy="0 0 0"/>
            <geometry>
                <box size="1.520712116601032 1.0754266596366366 2.4054356685749694" />
            </geometry>
        </collision>
    </link>
    <link name="Leg9">
        <inertial>
            <origin xyz="0 1.4146100351813666 0" rpy="0 0 0"/>
            <mass value="1" />
            <inertia ixx="100" ixy="0" ixz="0" iyy="100" iyz="0" izz="100" />
        </inertial>
        <visual>
            <origin xyz="0 1.4146100351813666 0" rpy="0 0 0"/>
            <geometry>
                <box size="1.7702140133888966 2.8292200703627333 1.876218126080485" />
            </geometry>
            <material name="Blue">
                <color rgba="0 1.0 1.0 1.0"/>
            </material>
        </visual>
        <collision>
            <origin xyz="0 1.4146100351813666 0" rpy="0 0 0"/>
            <geometry>
                <box size="1.7702140133888966 2.8292200703627333 1.876218126080485" />
            </geometry>
        </collision>
    </link>
    <link name="Leg10">
        <inertial>
            <origin xyz="0 0 0.7611088345057365" rpy="0 0 0"/>
            <mass value="1" />
            <inertia ixx="100" ixy="0" ixz="0" iyy="100" iyz="0" izz="100" />
        </inertial>
        <visual>
            <origin xyz="0 0 0.7611088345057365" rpy="0 0 0"/>
            <geometry>
                <box size="1.102294861566459 1.4935465999791626 1.522217669011473" />
            </geometry>
            <material name="Blue">
                <color rgba="0 1.0 1.0 1.0"/>
            </material>
        </visual>
        <collision>
            <origin xyz="0 0 0.7611088345057365" rpy="0 0 0"/>
            <geometry>
                <box size="1.102294861566459 1.4935465999791626 1.522217669011473" />
            </geometry>
        </collision>
    </link>
    <link name="Leg11">
        <inertial>
            <origin xyz="0 0.8630013665922719 0" rpy="0 0 0"/>
            <mass value="1" />
            <inertia ixx="100" ixy="0" ixz="0" iyy="100" iyz="0" izz="100" />
        </inertial>
        <visual>
            <origin xyz="0 0.8630013665922719 0" rpy="0 0 0"/>
            <geometry>
                <box size="2.9015780037538863 1.7260027331845438 2.8380626297435523" />
            </geometry>
            <material name="Green">
                <color rgba="0 180.0 0.0 1.0"/>
            </material>
        </visual>
        <collision>
            <origin xyz="0 0.8630013665922719 0" rpy="0 0 0"/>
            <geometry>
                <box size="2.9015780037538863 1.7260027331845438 2.8380626297435523" />
            </geometry>
        </collision>
    </link>
    <link name="Leg12">
        <inertial>
            <origin xyz="0.5202330352590822 0 0" rpy="0 0 0"/>
            <mass value="1" />
            <inertia ixx="100" ixy="0" ixz="0" iyy="100" iyz="0" izz="100" />
        </inertial>
        <visual>
            <origin xyz="0.5202330352590822 0 0" rpy="0 0 0"/>
            <geometry>
                <box size="1.0404660705181643 1.445675385209497 2.5556498325734442" />
            </geometry>
            <material name="Blue">
                <color rgba="0 1.0 1.0 1.0"/>
            </material>
        </visual>
        <collision>
            <origin xyz="0.5202330352590822 0 0" rpy="0 0 0"/>
            <geometry>
                <box size="1.0404660705181643 1.445675385209497 2.5556498325734442" />
            </geometry>
        </collision>
    </link>
    <link name="Leg13">
        <inertial>
            <origin xyz="0 1.3074865053222768 0" rpy="0 0 0"/>
            <mass value="1" />
            <inertia ixx="100" ixy="0" ixz="0" iyy="100" iyz="0" izz="100" />
        </inertial>
        <visual>
            <origin xyz="0 1.3074865053222768 0" rpy="0 0 0"/>
            <geometry>
                <box size="1.1241492087214424 2.6149730106445537 1.755816252633547" />
            </geometry>
            <material name="Green">
                <color rgba="0 180.0 0.0 1.0"/>
            </material>
        </visual>
        <collision>
            <origin xyz="0 1.3074865053222768 0" rpy="0 0 0"/>
            <geometry>
                <box size="1.1241492087214424 2.6149730106445537 1.755816252633547" />
            </geometry>
        </collision>
    </link>
    <link name="Leg14">
        <inertial>
            <origin xyz="0 0 0.6126635793830362" rpy="0 0 0"/>
            <mass value="1" />
            <inertia ixx="100" ixy="0" ixz="0" iyy="100" iyz="0" izz="100" />
        </inertial>
        <visual>
            <origin xyz="0 0 0.6126635793830362" rpy="0 0 0"/>
            <geometry>
                <box size="1.1454547952952825 1.3660447163229057 1.2253271587660723" />
            </geometry>
            <material name="Green">
                <color rgba="0 180.0 0.0 1.0"/>
            </material>
        </visual>
        <collision>
            <origin xyz="0 0 0.6126635793830362" rpy="0 0 0"/>
            <geometry>
                <box size="1.1454547952952825 1.3660447163229057 1.2253271587660723" />
            </geometry>
        </collision>
    </link>
    <link name="Leg15">
        <inertial>
            <origin xyz="0 0 1.0691558355722401" rpy="0 0 0"/>
            <mass value="1" />
            <inertia ixx="100" ixy="0" ixz="0" iyy="100" iyz="0" izz="100" />
        </inertial>
        <visual>
            <origin xyz="0 0 1.0691558355722401" rpy="0 0 0"/>
            <geometry>
                <box size="1.1626535383548218 1.290326234390024 2.1383116711444803" />
            </geometry>
            <material name="Blue">
                <color rgba="0 1.0 1.0 1.0"/>
            </material>
        </visual>
        <collision>
            <origin xyz="0 0 1.0691558355722401" rpy="0 0 0"/>
            <geometry>
                <box size="1.1626535383548218 1.290326234390024 2.1383116711444803" />
            </geometry>
        </collision>
    </link>
    <link name="Leg16">
        <inertial>
            <origin xyz="0 0 0.6672773160547738" rpy="0 0 0"/>
            <mass value="1" />
            <inertia ixx="100" ixy="0" ixz="0" iyy="100" iyz="0" izz="100" />
        </inertial>
        <visual>
            <origin xyz="0 0 0.6672773160547738" rpy="0 0 0"/>
            <geometry>
                <box size="1.2234131345225805 1.7886328212888567 1.3345546321095476" />
            </geometry>
            <material name="Blue">
                <color rgba="0 1.0 1.0 1.0"/>
            </material>
        </visual>
        <collision>
            <origin xyz="0 0 0.6672773160547738" rpy="0 0 0"/>
            <geometry>
                <box size="1.2234131345225805 1.7886328212888567 1.3345546321095476" />
            </geometry>
        </collision>
    </link>
    <link name="Leg17">
        <inertial>
            <origin xyz="0 1.1610533317719378 0" rpy="0 0 0"/>
            <mass value="1" />
            <inertia ixx="100" ixy="0" ixz="0" iyy="100" iyz="0" izz="100" />
        </inertial>
        <visual>
            <origin xyz="0 1.1610533317719378 0" rpy="0 0 0"/>
            <geometry>
                <box size="2.684174267191745 2.3221066635438756 2.562184501113279" />
            </geometry>
            <material name="Blue">
                <color rgba="0 1.0 1.0 1.0"/>
            </material>
        </visual>
        <collision>
            <origin xyz="0 1.1610533317719378 0" rpy="0 0 0"/>
            <geometry>
                <box size="2.684174267191745 2.3221066635438756 2.562184501113279" />
            </geometry>
        </collision>
    </link>
    <link name="Leg18">
        <inertial>
            <origin xyz="0 1.093833882057209 0" rpy="0 0 0"/>
            <mass value="1" />
            <inertia ixx="100" ixy="0" ixz="0" iyy="100" iyz="0" izz="100" />
        </inertial>
        <visual>
            <origin xyz="0 1.093833882057209 0" rpy="0 0 0"/>
            <geometry>
                <box size="1.7717268563259807 2.187667764114418 2.8231256896064734" />
            </geometry>
            <material name="Green">
                <color rgba="0 180.0 0.0 1.0"/>
            </material>
        </visual>
        <collision>
            <origin xyz="0 1.093833882057209 0" rpy="0 0 0"/>
            <geometry>
                <box size="1.7717268563259807 2.187667764114418 2.8231256896064734" />
            </geometry>
        </collision>
    </link>
    <link name="Leg19">
        <inertial>
            <origin xyz="0.5750203037210725 0 0" rpy="0 0 0"/>
            <mass value="1" />
            <inertia ixx="100" ixy="0" ixz="0" iyy="100" iyz="0" izz="100" />
        </inertial>
        <visual>
            <origin xyz="0.5750203037210725 0 0" rpy="0 0 0"/>
            <geometry>
                <box size="1.150040607442145 2.091551928149806 2.300746329349366" />
            </geometry>
            <material name="Green">
                <color rgba="0 180.0 0.0 1.0"/>
            </material>
        </visual>
        <collision>
            <origin xyz="0.5750203037210725 0 0" rpy="0 0 0"/>
            <geometry>
                <box size="1.150040607442145 2.091551928149806 2.300746329349366" />
            </geometry>
        </collision>
    </link>
    <link name="Leg20">
        <inertial>
            <origin xyz="0 0.5380995841536595 0" rpy="0 0 0"/>
            <mass value="1" />
            <inertia ixx="100" ixy="0" ixz="0" iyy="100" iyz="0" izz="100" />
        </inertial>
        <visual>
            <origin xyz="0 0.5380995841536595 0" rpy="0 0 0"/>
            <geometry>
                <box size="1.9426964472753565 1.076199168307319 2.390866265479197" />
            </geometry>
            <material name="Blue">
                <color rgba="0 1.0 1.0 1.0"/>
            </material>
        </visual>
        <collision>
            <origin xyz="0 0.5380995841536595 0" rpy="0 0 0"/>
            <geometry>
                <box size="1.9426964472753565 1.076199168307319 2.390866265479197" />
            </geometry>
        </collision>
    </link>
    <link name="Leg21">
        <inertial>
            <origin xyz="0 0 0.6018103587698824" rpy="0 0 0"/>
            <mass value="1" />
            <inertia ixx="100" ixy="0" ixz="0" iyy="100" iyz="0" izz="100" />
        </inertial>
        <visual>
            <origin xyz="0 0 0.6018103587698824" rpy="0 0 0"/>
            <geometry>
                <box size="1.375658139667541 2.0953740508960457 1.2036207175397649" />
            </geometry>
            <material name="Green">
                <color rgba="0 180.0 0.0 1.0"/>
            </material>
        </visual>
        <collision>
            <origin xyz="0 0 0.6018103587698824" rpy="0 0 0"/>
            <geometry>
                <box size="1.375658139667541 2.0953740508960457 1.2036207175397649" />
            </geometry>
        </collision>
    </link>
    <link name="Leg22">
        <inertial>
            <origin xyz="0 0 1.1438172830045703" rpy="0 0 0"/>
            <mass value="1" />
            <inertia ixx="100" ixy="0" ixz="0" iyy="100" iyz="0" izz="100" />
        </inertial>
        <visual>
            <origin xyz="0 0 1.1438172830045703" rpy="0 0 0"/>
            <geometry>
                <box size="2.0769861412906256 2.474538845732889 2.2876345660091406" />
            </geometry>
            <material name="Green">
                <color rgba="0 180.0 0.0 1.0"/>
            </material>
        </visual>
        <collision>
            <origin xyz="0 0 1.1438172830045703" rpy="0 0 0"/>
            <geometry>
                <box size="2.0769861412906256 2.474538845732889 2.2876345660091406" />
            </geometry>
        </collision>
    </link>
    <link name="Leg23">
        <inertial>
            <origin xyz="0 0 0.9827891382875168" rpy="0 0 0"/>
            <mass value="1" />
            <inertia ixx="100" ixy="0" ixz="0" iyy="100" iyz="0" izz="100" />
        </inertial>
        <visual>
            <origin xyz="0 0 0.9827891382875168" rpy="0 0 0"/>
            <geometry>
                <box size="2.935792348809978 1.47569562723532 1.9655782765750336" />
            </geometry>
            <material name="Green">
                <color rgba="0 180.0 0.0 1.0"/>
            </material>
        </visual>
        <collision>
            <origin xyz="0 0 0.9827891382875168" rpy="0 0 0"/>
            <geometry>
                <box size="2.935792348809978 1.47569562723532 1.9655782765750336" />
            </geometry>
        </collision>
    </link>
    <link name="Leg24">
        <inertial>
            <origin xyz="0.9473420369028246 0 0" rpy="0 0 0"/>
            <mass value="1" />
            <inertia ixx="100" ixy="0" ixz="0" iyy="100" iyz="0" izz="100" />
        </inertial>
        <visual>
            <origin xyz="0.9473420369028246 0 0" rpy="0 0 0"/>
            <geometry>
                <box size="1.8946840738056492 2.4677907036212403 1.3009220769990983" />
            </geometry>
            <material name="Blue">
                <color rgba="0 1.0 1.0 1.0"/>
            </material>
        </visual>
        <collision>
            <origin xyz="0.9473420369028246 0 0" rpy="0 0 0"/>
            <geometry>
                <box size="1.8946840738056492 2.4677907036212403 1.3009220769990983" />
            </geometry>
        </collision>
    </link>
    <link name="Leg25">
        <inertial>
            <origin xyz="0 0.7148807891856006 0" rpy="0 0 0"/>
            <mass value="1" />
            <inertia ixx="100" ixy="0" ixz="0" iyy="100" iyz="0" izz="100" />
        </inertial>
        <visual>
            <origin xyz="0 0.7148807891856006 0" rpy="0 0 0"/>
            <geometry>
                <box size="2.142866846541156 1.4297615783712012 1.9265446654976002" />
            </geometry>
            <material name="Blue">
                <color rgba="0 1.0 1.0 1.0"/>
            </material>
        </visual>
        <collision>
            <origin xyz="0 0.7148807891856006 0" rpy="0 0 0"/>
            <geometry>
                <box size="2.142866846541156 1.4297615783712012 1.9265446654976002" />
            </geometry>
        </collision>
    </link>
    <joint name="Torso_Leg1" type="revolute">
       <parent link="Torso"/>
       <child  link="Leg1"/>
       <origin rpy="0 0 0" xyz="1.3140310123140018 0 1.1504032897952254" />
     <axis xyz="1 0 0"/>
       <limit effort="0.0" lower="-3.14159" upper="3.14159" velocity="0.0"/>
    </joint>
    <joint name="Leg1_Leg2" type="revolute">
       <parent link="Leg1"/>
       <child  link="Leg2"/>
       <origin rpy="0 0 0" xyz="1.9963139132361485 0 0" />
     <axis xyz="1 0 0"/>
       <limit effort="0.0" lower="-3.14159" upper="3.14159" velocity="0.0"/>
    </joint>
    <joint name="Leg1_Leg3" type="revolute">
       <parent link="Leg1"/>
       <child  link="Leg3"/>
       <origin rpy="0 0 0" xyz="1.9963139132361485 1.0328829292537614 0" />
     <axis xyz="1 0 0"/>
       <limit effort="0.0" lower="-3.14159" upper="3.14159" velocity="0.0"/>
    </joint>
    <joint name="Leg3_Leg4" type="revolute">
       <parent link="Leg3"/>
       <child  link="Leg4"/>
       <origin rpy="0 0 0" xyz="2.6752636922376913 0 0" />
     <axis xyz="1 0 0"/>
       <limit effort="0.0" lower="-3.14159" upper="3.14159" velocity="0.0"/>
    </joint>
    <joint name="Leg1_Leg5" type="revolute">
       <parent link="Leg1"/>
       <child  link="Leg5"/>
       <origin rpy="0 0 0" xyz="1.9963139132361485 1.0328829292537614 1.1925842656916152" />
     <axis xyz="1 0 0"/>
       <limit effort="0.0" lower="-3.14159" upper="3.14159" velocity="0.0"/>
    </joint>
    <joint name="Torso_Leg6" type="revolute">
       <parent link="Torso"/>
       <child  link="Leg6"/>
       <origin rpy="0 0 0" xyz="0.6262797758486719 0.5140303256982353 0" />
     <axis xyz="1 0 0"/>
       <limit effort="0.0" lower="-3.14159" upper="3.14159" velocity="0.0"/>
    </joint>
    <joint name="Leg3_Leg7" type="revolute">
       <parent link="Leg3"/>
       <child  link="Leg7"/>
       <origin rpy="0 0 0" xyz="2.6752636922376913 0 1.1135114393773573" />
     <axis xyz="1 0 0"/>
       <limit effort="0.0" lower="-3.14159" upper="3.14159" velocity="0.0"/>
    </joint>
    <joint name="Leg5_Leg8" type="revolute">
       <parent link="Leg5"/>
       <child  link="Leg8"/>
       <origin rpy="0 0 0" xyz="0 0.5414764902524106 1.2338788975989377" />
     <axis xyz="1 0 0"/>
       <limit effort="0.0" lower="-3.14159" upper="3.14159" velocity="0.0"/>
    </joint>
    <joint name="Leg2_Leg9" type="revolute">
       <parent link="Leg2"/>
       <child  link="Leg9"/>
       <origin rpy="0 0 0" xyz="0 1.8987577132080218 0" />
     <axis xyz="1 0 0"/>
       <limit effort="0.0" lower="-3.14159" upper="3.14159" velocity="0.0"/>
    </joint>
    <joint name="Leg9_Leg10" type="revolute">
       <parent link="Leg9"/>
       <child  link="Leg10"/>
       <origin rpy="0 0 0" xyz="0 0 1.522217669011473" />
     <axis xyz="1 0 0"/>
       <limit effort="0.0" lower="-3.14159" upper="3.14159" velocity="0.0"/>
    </joint>
    <joint name="Leg9_Leg11" type="revolute">
       <parent link="Leg9"/>
       <child  link="Leg11"/>
       <origin rpy="0 0 0" xyz="0 0.7467732999895813 1.522217669011473" />
     <axis xyz="1 0 0"/>
       <limit effort="0.0" lower="-3.14159" upper="3.14159" velocity="0.0"/>
    </joint>
    <joint name="Leg11_Leg12" type="revolute">
       <parent link="Leg11"/>
       <child  link="Leg12"/>
       <origin rpy="0 0 0" xyz="1.0404660705181643 0 0" />
     <axis xyz="1 0 0"/>
       <limit effort="0.0" lower="-3.14159" upper="3.14159" velocity="0.0"/>
    </joint>
    <joint name="Leg6_Leg13" type="revolute">
       <parent link="Leg6"/>
       <child  link="Leg13"/>
       <origin rpy="0 0 0" xyz="0 1.424974634572704 1.0941844785498078" />
     <axis xyz="1 0 0"/>
       <limit effort="0.0" lower="-3.14159" upper="3.14159" velocity="0.0"/>
    </joint>
    <joint name="Leg12_Leg14" type="revolute">
       <parent link="Leg12"/>
       <child  link="Leg14"/>
       <origin rpy="0 0 0" xyz="0 1.3074865053222768 0.8779081263167735" />
     <axis xyz="1 0 0"/>
       <limit effort="0.0" lower="-3.14159" upper="3.14159" velocity="0.0"/>
    </joint>
    <joint name="Leg14_Leg15" type="revolute">
       <parent link="Leg14"/>
       <child  link="Leg15"/>
       <origin rpy="0 0 0" xyz="0 0 2.1383116711444803" />
     <axis xyz="1 0 0"/>
       <limit effort="0.0" lower="-3.14159" upper="3.14159" velocity="0.0"/>
    </joint>
    <joint name="Leg13_Leg16" type="revolute">
       <parent link="Leg13"/>
       <child  link="Leg16"/>
       <origin rpy="0 0 0" xyz="0 0 1.2253271587660723" />
     <axis xyz="1 0 0"/>
       <limit effort="0.0" lower="-3.14159" upper="3.14159" velocity="0.0"/>
    </joint>
    <joint name="Leg12_Leg17" type="revolute">
       <parent link="Leg12"/>
       <child  link="Leg17"/>
       <origin rpy="0 0 0" xyz="0 2.6149730106445537 0.8779081263167735" />
     <axis xyz="1 0 0"/>
       <limit effort="0.0" lower="-3.14159" upper="3.14159" velocity="0.0"/>
    </joint>
    <joint name="Leg5_Leg18" type="revolute">
       <parent link="Leg5"/>
       <child  link="Leg18"/>
       <origin rpy="0 0 0" xyz="0 1.0829529805048212 1.2338788975989377" />
     <axis xyz="1 0 0"/>
       <limit effort="0.0" lower="-3.14159" upper="3.14159" velocity="0.0"/>
    </joint>
    <joint name="Leg17_Leg19" type="revolute">
       <parent link="Leg17"/>
       <child  link="Leg19"/>
       <origin rpy="0 0 0" xyz="0.8858634281629904 1.093833882057209 0" />
     <axis xyz="1 0 0"/>
       <limit effort="0.0" lower="-3.14159" upper="3.14159" velocity="0.0"/>
    </joint>
    <joint name="Leg13_Leg20" type="revolute">
       <parent link="Leg13"/>
       <child  link="Leg20"/>
       <origin rpy="0 0 0" xyz="0 0.6830223581614528 1.2253271587660723" />
     <axis xyz="1 0 0"/>
       <limit effort="0.0" lower="-3.14159" upper="3.14159" velocity="0.0"/>
    </joint>
    <joint name="Leg20_Leg21" type="revolute">
       <parent link="Leg20"/>
       <child  link="Leg21"/>
       <origin rpy="0 0 0" xyz="0 0 1.2036207175397649" />
     <axis xyz="1 0 0"/>
       <limit effort="0.0" lower="-3.14159" upper="3.14159" velocity="0.0"/>
    </joint>
    <joint name="Leg8_Leg22" type="revolute">
       <parent link="Leg8"/>
       <child  link="Leg22"/>
       <origin rpy="0 0 0" xyz="0 1.4146100351813666 0.9381090630402426" />
     <axis xyz="1 0 0"/>
       <limit effort="0.0" lower="-3.14159" upper="3.14159" velocity="0.0"/>
    </joint>
    <joint name="Leg11_Leg23" type="revolute">
       <parent link="Leg11"/>
       <child  link="Leg23"/>
       <origin rpy="0 0 0" xyz="1.0404660705181643 0 1.2778249162867221" />
     <axis xyz="1 0 0"/>
       <limit effort="0.0" lower="-3.14159" upper="3.14159" velocity="0.0"/>
    </joint>
    <joint name="Leg7_Leg24" type="revolute">
       <parent link="Leg7"/>
       <child  link="Leg24"/>
       <origin rpy="0 0 0" xyz="0.760356058300516 0 1.2027178342874847" />
     <axis xyz="1 0 0"/>
       <limit effort="0.0" lower="-3.14159" upper="3.14159" velocity="0.0"/>
    </joint>
    <joint name="Leg23_Leg25" type="revolute">
       <parent link="Leg23"/>
       <child  link="Leg25"/>
       <origin rpy="0 0 0" xyz="0.9473420369028246 1.2338953518106202 0" />
     <axis xyz="1 0 0"/>
       <limit effort="0.0" lower="-3.14159" upper="3.14159" velocity="0.0"/>
    </joint>
</robot>