<robot name = "robot">
    <link name="Torso">
        <inertial>
            <origin xyz="0 0 0.8165136792032941" rpy="0 0 0"/>
            <mass value="1" />
            <inertia ixx="100" ixy="0" ixz="0" iyy="100" iyz="0" izz="100" />
        </inertial>
        <visual>
            <origin xyz="0 0 0.8165136792032941" rpy="0 0 0"/>
            <geometry>
                <box size="2.7704690014124966 1.852271763252511 1.6330273584065882" />
            </geometry>
            <material name="Green">
                <color rgba="0 180.0 0.0 1.0"/>
            </material>
        </visual>
        <collision>
            <origin xyz="0 0 0.8165136792032941" rpy="0 0 0"/>
            <geometry>
                <box size="2.7704690014124966 1.852271763252511 1.6330273584065882" />
            </geometry>
        </collision>
    </link>
    <link name="Leg1">
        <inertial>
            <origin xyz="0 0.7901573943917399 0" rpy="0 0 0"/>
            <mass value="1" />
            <inertia ixx="100" ixy="0" ixz="0" iyy="100" iyz="0" izz="100" />
        </inertial>
        <visual>
            <origin xyz="0 0.7901573943917399 0" rpy="0 0 0"/>
            <geometry>
                <box size="2.8871957991412796 1.5803147887834799 2.8352509570650835" />
            </geometry>
            <material name="Green">
                <color rgba="0 180.0 0.0 1.0"/>
            </material>
        </visual>
        <collision>
            <origin xyz="0 0.7901573943917399 0" rpy="0 0 0"/>
            <geometry>
                <box size="2.8871957991412796 1.5803147887834799 2.8352509570650835" />
            </geometry>
        </collision>
    </link>
    <link name="Leg2">
        <inertial>
            <origin xyz="0 0 0.8313607450003294" rpy="0 0 0"/>
            <mass value="1" />
            <inertia ixx="100" ixy="0" ixz="0" iyy="100" iyz="0" izz="100" />
        </inertial>
        <visual>
            <origin xyz="0 0 0.8313607450003294" rpy="0 0 0"/>
            <geometry>
                <box size="2.220047408272939 1.2782608610606991 1.6627214900006588" />
            </geometry>
            <material name="Blue">
                <color rgba="0 1.0 1.0 1.0"/>
            </material>
        </visual>
        <collision>
            <origin xyz="0 0 0.8313607450003294" rpy="0 0 0"/>
            <geometry>
                <box size="2.220047408272939 1.2782608610606991 1.6627214900006588" />
            </geometry>
        </collision>
    </link>
    <link name="Leg3">
        <inertial>
            <origin xyz="0 0 0.500001516136253" rpy="0 0 0"/>
            <mass value="1" />
            <inertia ixx="100" ixy="0" ixz="0" iyy="100" iyz="0" izz="100" />
        </inertial>
        <visual>
            <origin xyz="0 0 0.500001516136253" rpy="0 0 0"/>
            <geometry>
                <box size="1.952660076358515 2.9231208038651326 1.000003032272506" />
            </geometry>
            <material name="Blue">
                <color rgba="0 1.0 1.0 1.0"/>
            </material>
        </visual>
        <collision>
            <origin xyz="0 0 0.500001516136253" rpy="0 0 0"/>
            <geometry>
                <box size="1.952660076358515 2.9231208038651326 1.000003032272506" />
            </geometry>
        </collision>
    </link>
    <link name="Leg4">
        <inertial>
            <origin xyz="0 0.6239989275526601 0" rpy="0 0 0"/>
            <mass value="1" />
            <inertia ixx="100" ixy="0" ixz="0" iyy="100" iyz="0" izz="100" />
        </inertial>
        <visual>
            <origin xyz="0 0.6239989275526601 0" rpy="0 0 0"/>
            <geometry>
                <box size="2.6374657763465112 1.2479978551053201 2.9643915592106014" />
            </geometry>
            <material name="Blue">
                <color rgba="0 1.0 1.0 1.0"/>
            </material>
        </visual>
        <collision>
            <origin xyz="0 0.6239989275526601 0" rpy="0 0 0"/>
            <geometry>
                <box size="2.6374657763465112 1.2479978551053201 2.9643915592106014" />
            </geometry>
        </collision>
    </link>
    <link name="Leg5">
        <inertial>
            <origin xyz="0.7914462110432209 0 0" rpy="0 0 0"/>
            <mass value="1" />
            <inertia ixx="100" ixy="0" ixz="0" iyy="100" iyz="0" izz="100" />
        </inertial>
        <visual>
            <origin xyz="0.7914462110432209 0 0" rpy="0 0 0"/>
            <geometry>
                <box size="1.5828924220864418 1.6920737735295 1.2046285361289926" />
            </geometry>
            <material name="Green">
                <color rgba="0 180.0 0.0 1.0"/>
            </material>
        </visual>
        <collision>
            <origin xyz="0.7914462110432209 0 0" rpy="0 0 0"/>
            <geometry>
                <box size="1.5828924220864418 1.6920737735295 1.2046285361289926" />
            </geometry>
        </collision>
    </link>
    <link name="Leg6">
        <inertial>
            <origin xyz="0 0.7949007945239627 0" rpy="0 0 0"/>
            <mass value="1" />
            <inertia ixx="100" ixy="0" ixz="0" iyy="100" iyz="0" izz="100" />
        </inertial>
        <visual>
            <origin xyz="0 0.7949007945239627 0" rpy="0 0 0"/>
            <geometry>
                <box size="2.8185620794890465 1.5898015890479253 1.570579909804613" />
            </geometry>
            <material name="Blue">
                <color rgba="0 1.0 1.0 1.0"/>
            </material>
        </visual>
        <collision>
            <origin xyz="0 0.7949007945239627 0" rpy="0 0 0"/>
            <geometry>
                <box size="2.8185620794890465 1.5898015890479253 1.570579909804613" />
            </geometry>
        </collision>
    </link>
    <link name="Leg7">
        <inertial>
            <origin xyz="0 1.3520712506216477 0" rpy="0 0 0"/>
            <mass value="1" />
            <inertia ixx="100" ixy="0" ixz="0" iyy="100" iyz="0" izz="100" />
        </inertial>
        <visual>
            <origin xyz="0 1.3520712506216477 0" rpy="0 0 0"/>
            <geometry>
                <box size="2.56529312500599 2.7041425012432954 2.841147393629125" />
            </geometry>
            <material name="Blue">
                <color rgba="0 1.0 1.0 1.0"/>
            </material>
        </visual>
        <collision>
            <origin xyz="0 1.3520712506216477 0" rpy="0 0 0"/>
            <geometry>
                <box size="2.56529312500599 2.7041425012432954 2.841147393629125" />
            </geometry>
        </collision>
    </link>
    <link name="Leg8">
        <inertial>
            <origin xyz="0.8482575573634081 0 0" rpy="0 0 0"/>
            <mass value="1" />
            <inertia ixx="100" ixy="0" ixz="0" iyy="100" iyz="0" izz="100" />
        </inertial>
        <visual>
            <origin xyz="0.8482575573634081 0 0" rpy="0 0 0"/>
            <geometry>
                <box size="1.6965151147268163 2.171052390963473 1.3624737009365155" />
            </geometry>
            <material name="Blue">
                <color rgba="0 1.0 1.0 1.0"/>
            </material>
        </visual>
        <collision>
            <origin xyz="0.8482575573634081 0 0" rpy="0 0 0"/>
            <geometry>
                <box size="1.6965151147268163 2.171052390963473 1.3624737009365155" />
            </geometry>
        </collision>
    </link>
    <link name="Leg9">
        <inertial>
            <origin xyz="0 0 1.0163778508051817" rpy="0 0 0"/>
            <mass value="1" />
            <inertia ixx="100" ixy="0" ixz="0" iyy="100" iyz="0" izz="100" />
        </inertial>
        <visual>
            <origin xyz="0 0 1.0163778508051817" rpy="0 0 0"/>
            <geometry>
                <box size="1.6751885899945869 2.1728035230190805 2.0327557016103635" />
            </geometry>
            <material name="Blue">
                <color rgba="0 1.0 1.0 1.0"/>
            </material>
        </visual>
        <collision>
            <origin xyz="0 0 1.0163778508051817" rpy="0 0 0"/>
            <geometry>
                <box size="1.6751885899945869 2.1728035230190805 2.0327557016103635" />
            </geometry>
        </collision>
    </link>
    <link name="Leg10">
        <inertial>
            <origin xyz="0.9975765226805127 0 0" rpy="0 0 0"/>
            <mass value="1" />
            <inertia ixx="100" ixy="0" ixz="0" iyy="100" iyz="0" izz="100" />
        </inertial>
        <visual>
            <origin xyz="0.9975765226805127 0 0" rpy="0 0 0"/>
            <geometry>
                <box size="1.9951530453610253 2.0369522016403985 1.9518870267889032" />
            </geometry>
            <material name="Green">
                <color rgba="0 180.0 0.0 1.0"/>
            </material>
        </visual>
        <collision>
            <origin xyz="0.9975765226805127 0 0" rpy="0 0 0"/>
            <geometry>
                <box size="1.9951530453610253 2.0369522016403985 1.9518870267889032" />
            </geometry>
        </collision>
    </link>
    <link name="Leg11">
        <inertial>
            <origin xyz="0 1.1337608041057006 0" rpy="0 0 0"/>
            <mass value="1" />
            <inertia ixx="100" ixy="0" ixz="0" iyy="100" iyz="0" izz="100" />
        </inertial>
        <visual>
            <origin xyz="0 1.1337608041057006 0" rpy="0 0 0"/>
            <geometry>
                <box size="1.8330832182359946 2.267521608211401 2.3986995439484184" />
            </geometry>
            <material name="Green">
                <color rgba="0 180.0 0.0 1.0"/>
            </material>
        </visual>
        <collision>
            <origin xyz="0 1.1337608041057006 0" rpy="0 0 0"/>
            <geometry>
                <box size="1.8330832182359946 2.267521608211401 2.3986995439484184" />
            </geometry>
        </collision>
    </link>
    <link name="Leg12">
        <inertial>
            <origin xyz="0.9802442259188772 0 0" rpy="0 0 0"/>
            <mass value="1" />
            <inertia ixx="100" ixy="0" ixz="0" iyy="100" iyz="0" izz="100" />
        </inertial>
        <visual>
            <origin xyz="0.9802442259188772 0 0" rpy="0 0 0"/>
            <geometry>
                <box size="1.9604884518377543 2.612411557446212 2.278939037726146" />
            </geometry>
            <material name="Green">
                <color rgba="0 180.0 0.0 1.0"/>
            </material>
        </visual>
        <collision>
            <origin xyz="0.9802442259188772 0 0" rpy="0 0 0"/>
            <geometry>
                <box size="1.9604884518377543 2.612411557446212 2.278939037726146" />
            </geometry>
        </collision>
    </link>
    <link name="Leg13">
        <inertial>
            <origin xyz="0.8907383782140141 0 0" rpy="0 0 0"/>
            <mass value="1" />
            <inertia ixx="100" ixy="0" ixz="0" iyy="100" iyz="0" izz="100" />
        </inertial>
        <visual>
            <origin xyz="0.8907383782140141 0 0" rpy="0 0 0"/>
            <geometry>
                <box size="1.7814767564280283 2.8360180341654786 2.402939737222412" />
            </geometry>
            <material name="Blue">
                <color rgba="0 1.0 1.0 1.0"/>
            </material>
        </visual>
        <collision>
            <origin xyz="0.8907383782140141 0 0" rpy="0 0 0"/>
            <geometry>
                <box size="1.7814767564280283 2.8360180341654786 2.402939737222412" />
            </geometry>
        </collision>
    </link>
    <link name="Leg14">
        <inertial>
            <origin xyz="1.1548908084766263 0 0" rpy="0 0 0"/>
            <mass value="1" />
            <inertia ixx="100" ixy="0" ixz="0" iyy="100" iyz="0" izz="100" />
        </inertial>
        <visual>
            <origin xyz="1.1548908084766263 0 0" rpy="0 0 0"/>
            <geometry>
                <box size="2.3097816169532526 1.8121749453894178 2.6590825283844426" />
            </geometry>
            <material name="Blue">
                <color rgba="0 1.0 1.0 1.0"/>
            </material>
        </visual>
        <collision>
            <origin xyz="1.1548908084766263 0 0" rpy="0 0 0"/>
            <geometry>
                <box size="2.3097816169532526 1.8121749453894178 2.6590825283844426" />
            </geometry>
        </collision>
    </link>
    <link name="Leg15">
        <inertial>
            <origin xyz="0 0 0.8574737485462426" rpy="0 0 0"/>
            <mass value="1" />
            <inertia ixx="100" ixy="0" ixz="0" iyy="100" iyz="0" izz="100" />
        </inertial>
        <visual>
            <origin xyz="0 0 0.8574737485462426" rpy="0 0 0"/>
            <geometry>
                <box size="1.5379619627388676 1.7946777144357005 1.7149474970924852" />
            </geometry>
            <material name="Green">
                <color rgba="0 180.0 0.0 1.0"/>
            </material>
        </visual>
        <collision>
            <origin xyz="0 0 0.8574737485462426" rpy="0 0 0"/>
            <geometry>
                <box size="1.5379619627388676 1.7946777144357005 1.7149474970924852" />
            </geometry>
        </collision>
    </link>
    <link name="Leg16">
        <inertial>
            <origin xyz="0 0 1.4713501468938113" rpy="0 0 0"/>
            <mass value="1" />
            <inertia ixx="100" ixy="0" ixz="0" iyy="100" iyz="0" izz="100" />
        </inertial>
        <visual>
            <origin xyz="0 0 1.4713501468938113" rpy="0 0 0"/>
            <geometry>
                <box size="1.9585289745147927 2.2445072681461347 2.9427002937876225" />
            </geometry>
            <material name="Green">
                <color rgba="0 180.0 0.0 1.0"/>
            </material>
        </visual>
        <collision>
            <origin xyz="0 0 1.4713501468938113" rpy="0 0 0"/>
            <geometry>
                <box size="1.9585289745147927 2.2445072681461347 2.9427002937876225" />
            </geometry>
        </collision>
    </link>
    <link name="Leg17">
        <inertial>
            <origin xyz="1.4330109388189993 0 0" rpy="0 0 0"/>
            <mass value="1" />
            <inertia ixx="100" ixy="0" ixz="0" iyy="100" iyz="0" izz="100" />
        </inertial>
        <visual>
            <origin xyz="1.4330109388189993 0 0" rpy="0 0 0"/>
            <geometry>
                <box size="2.8660218776379986 2.761699381128647 1.39158057363522" />
            </geometry>
            <material name="Green">
                <color rgba="0 180.0 0.0 1.0"/>
            </material>
        </visual>
        <collision>
            <origin xyz="1.4330109388189993 0 0" rpy="0 0 0"/>
            <geometry>
                <box size="2.8660218776379986 2.761699381128647 1.39158057363522" />
            </geometry>
        </collision>
    </link>
    <link name="Leg18">
        <inertial>
            <origin xyz="0 0.8993441541079696 0" rpy="0 0 0"/>
            <mass value="1" />
            <inertia ixx="100" ixy="0" ixz="0" iyy="100" iyz="0" izz="100" />
        </inertial>
        <visual>
            <origin xyz="0 0.8993441541079696 0" rpy="0 0 0"/>
            <geometry>
                <box size="1.181142599412398 1.7986883082159393 2.419999018614928" />
            </geometry>
            <material name="Blue">
                <color rgba="0 1.0 1.0 1.0"/>
            </material>
        </visual>
        <collision>
            <origin xyz="0 0.8993441541079696 0" rpy="0 0 0"/>
            <geometry>
                <box size="1.181142599412398 1.7986883082159393 2.419999018614928" />
            </geometry>
        </collision>
    </link>
    <link name="Leg19">
        <inertial>
            <origin xyz="1.4407953636068338 0 0" rpy="0 0 0"/>
            <mass value="1" />
            <inertia ixx="100" ixy="0" ixz="0" iyy="100" iyz="0" izz="100" />
        </inertial>
        <visual>
            <origin xyz="1.4407953636068338 0 0" rpy="0 0 0"/>
            <geometry>
                <box size="2.8815907272136676 2.9458813316930694 1.4998707989644564" />
            </geometry>
            <material name="Blue">
                <color rgba="0 1.0 1.0 1.0"/>
            </material>
        </visual>
        <collision>
            <origin xyz="1.4407953636068338 0 0" rpy="0 0 0"/>
            <geometry>
                <box size="2.8815907272136676 2.9458813316930694 1.4998707989644564" />
            </geometry>
        </collision>
    </link>
    <link name="Leg20">
        <inertial>
            <origin xyz="0 0 0.8475840650336418" rpy="0 0 0"/>
            <mass value="1" />
            <inertia ixx="100" ixy="0" ixz="0" iyy="100" iyz="0" izz="100" />
        </inertial>
        <visual>
            <origin xyz="0 0 0.8475840650336418" rpy="0 0 0"/>
            <geometry>
                <box size="1.109487930017907 2.902263488796356 1.6951681300672836" />
            </geometry>
            <material name="Green">
                <color rgba="0 180.0 0.0 1.0"/>
            </material>
        </visual>
        <collision>
            <origin xyz="0 0 0.8475840650336418" rpy="0 0 0"/>
            <geometry>
                <box size="1.109487930017907 2.902263488796356 1.6951681300672836" />
            </geometry>
        </collision>
    </link>
    <link name="Leg21">
        <inertial>
            <origin xyz="0 0.9418465151388695 0" rpy="0 0 0"/>
            <mass value="1" />
            <inertia ixx="100" ixy="0" ixz="0" iyy="100" iyz="0" izz="100" />
        </inertial>
        <visual>
            <origin xyz="0 0.9418465151388695 0" rpy="0 0 0"/>
            <geometry>
                <box size="2.7851349672152947 1.883693030277739 2.400005817597364" />
            </geometry>
            <material name="Green">
                <color rgba="0 180.0 0.0 1.0"/>
            </material>
        </visual>
        <collision>
            <origin xyz="0 0.9418465151388695 0" rpy="0 0 0"/>
            <geometry>
                <box size="2.7851349672152947 1.883693030277739 2.400005817597364" />
            </geometry>
        </collision>
    </link>
    <link name="Leg22">
        <inertial>
            <origin xyz="0 0.8750958081930619 0" rpy="0 0 0"/>
            <mass value="1" />
            <inertia ixx="100" ixy="0" ixz="0" iyy="100" iyz="0" izz="100" />
        </inertial>
        <visual>
            <origin xyz="0 0.8750958081930619 0" rpy="0 0 0"/>
            <geometry>
                <box size="1.6145799770061822 1.7501916163861237 2.1610671416951326" />
            </geometry>
            <material name="Green">
                <color rgba="0 180.0 0.0 1.0"/>
            </material>
        </visual>
        <collision>
            <origin xyz="0 0.8750958081930619 0" rpy="0 0 0"/>
            <geometry>
                <box size="1.6145799770061822 1.7501916163861237 2.1610671416951326" />
            </geometry>
        </collision>
    </link>
    <link name="Leg23">
        <inertial>
            <origin xyz="0 0 0.5844157544286" rpy="0 0 0"/>
            <mass value="1" />
            <inertia ixx="100" ixy="0" ixz="0" iyy="100" iyz="0" izz="100" />
        </inertial>
        <visual>
            <origin xyz="0 0 0.5844157544286" rpy="0 0 0"/>
            <geometry>
                <box size="1.736257158961739 2.2958832274189405 1.1688315088572" />
            </geometry>
            <material name="Blue">
                <color rgba="0 1.0 1.0 1.0"/>
            </material>
        </visual>
        <collision>
            <origin xyz="0 0 0.5844157544286" rpy="0 0 0"/>
            <geometry>
                <box size="1.736257158961739 2.2958832274189405 1.1688315088572" />
            </geometry>
        </collision>
    </link>
    <link name="Leg24">
        <inertial>
            <origin xyz="1.28213624944227 0 0" rpy="0 0 0"/>
            <mass value="1" />
            <inertia ixx="100" ixy="0" ixz="0" iyy="100" iyz="0" izz="100" />
        </inertial>
        <visual>
            <origin xyz="1.28213624944227 0 0" rpy="0 0 0"/>
            <geometry>
                <box size="2.56427249888454 1.2312969161426341 1.3972332685536597" />
            </geometry>
            <material name="Blue">
                <color rgba="0 1.0 1.0 1.0"/>
            </material>
        </visual>
        <collision>
            <origin xyz="1.28213624944227 0 0" rpy="0 0 0"/>
            <geometry>
                <box size="2.56427249888454 1.2312969161426341 1.3972332685536597" />
            </geometry>
        </collision>
    </link>
    <link name="Leg25">
        <inertial>
            <origin xyz="0 0 1.183505252065292" rpy="0 0 0"/>
            <mass value="1" />
            <inertia ixx="100" ixy="0" ixz="0" iyy="100" iyz="0" izz="100" />
        </inertial>
        <visual>
            <origin xyz="0 0 1.183505252065292" rpy="0 0 0"/>
            <geometry>
                <box size="1.9837997144994277 1.7801015098784112 2.367010504130584" />
            </geometry>
            <material name="Blue">
                <color rgba="0 1.0 1.0 1.0"/>
            </material>
        </visual>
        <collision>
            <origin xyz="0 0 1.183505252065292" rpy="0 0 0"/>
            <geometry>
                <box size="1.9837997144994277 1.7801015098784112 2.367010504130584" />
            </geometry>
        </collision>
    </link>
    <joint name="Torso_Leg1" type="revolute">
       <parent link="Torso"/>
       <child  link="Leg1"/>
       <origin rpy="0 0 0" xyz="0 0.9261358816262555 0.8165136792032941" />
     <axis xyz="1 0 0"/>
       <limit effort="0.0" lower="-3.14159" upper="3.14159" velocity="0.0"/>
    </joint>
    <joint name="Torso_Leg2" type="revolute">
       <parent link="Torso"/>
       <child  link="Leg2"/>
       <origin rpy="0 0 0" xyz="0 0.7901573943917399 1.4176254785325417" />
     <axis xyz="1 0 0"/>
       <limit effort="0.0" lower="-3.14159" upper="3.14159" velocity="0.0"/>
    </joint>
    <joint name="Leg2_Leg3" type="revolute">
       <parent link="Leg2"/>
       <child  link="Leg3"/>
       <origin rpy="0 0 0" xyz="0 0 1.000003032272506" />
     <axis xyz="1 0 0"/>
       <limit effort="0.0" lower="-3.14159" upper="3.14159" velocity="0.0"/>
    </joint>
    <joint name="Leg2_Leg4" type="revolute">
       <parent link="Leg2"/>
       <child  link="Leg4"/>
       <origin rpy="0 0 0" xyz="0 1.4615604019325663 1.000003032272506" />
     <axis xyz="1 0 0"/>
       <limit effort="0.0" lower="-3.14159" upper="3.14159" velocity="0.0"/>
    </joint>
    <joint name="Leg1_Leg5" type="revolute">
       <parent link="Leg1"/>
       <child  link="Leg5"/>
       <origin rpy="0 0 0" xyz="1.1100237041364696 0 0.8313607450003294" />
     <axis xyz="1 0 0"/>
       <limit effort="0.0" lower="-3.14159" upper="3.14159" velocity="0.0"/>
    </joint>
    <joint name="Leg5_Leg6" type="revolute">
       <parent link="Leg5"/>
       <child  link="Leg6"/>
       <origin rpy="0 0 0" xyz="0 1.5898015890479253 0" />
     <axis xyz="1 0 0"/>
       <limit effort="0.0" lower="-3.14159" upper="3.14159" velocity="0.0"/>
    </joint>
    <joint name="Leg1_Leg7" type="revolute">
       <parent link="Leg1"/>
       <child  link="Leg7"/>
       <origin rpy="0 0 0" xyz="1.1100237041364696 0.6391304305303496 0.8313607450003294" />
     <axis xyz="1 0 0"/>
       <limit effort="0.0" lower="-3.14159" upper="3.14159" velocity="0.0"/>
    </joint>
    <joint name="Leg6_Leg8" type="revolute">
       <parent link="Leg6"/>
       <child  link="Leg8"/>
       <origin rpy="0 0 0" xyz="1.282646562502995 1.3520712506216477 0" />
     <axis xyz="1 0 0"/>
       <limit effort="0.0" lower="-3.14159" upper="3.14159" velocity="0.0"/>
    </joint>
    <joint name="Leg1_Leg9" type="revolute">
       <parent link="Leg1"/>
       <child  link="Leg9"/>
       <origin rpy="0 0 0" xyz="1.1100237041364696 0.6391304305303496 1.6627214900006588" />
     <axis xyz="1 0 0"/>
       <limit effort="0.0" lower="-3.14159" upper="3.14159" velocity="0.0"/>
    </joint>
    <joint name="Leg7_Leg10" type="revolute">
       <parent link="Leg7"/>
       <child  link="Leg10"/>
       <origin rpy="0 0 0" xyz="1.6965151147268163 0 0" />
     <axis xyz="1 0 0"/>
       <limit effort="0.0" lower="-3.14159" upper="3.14159" velocity="0.0"/>
    </joint>
    <joint name="Leg8_Leg11" type="revolute">
       <parent link="Leg8"/>
       <child  link="Leg11"/>
       <origin rpy="0 0 0" xyz="0 1.0864017615095403 1.0163778508051817" />
     <axis xyz="1 0 0"/>
       <limit effort="0.0" lower="-3.14159" upper="3.14159" velocity="0.0"/>
    </joint>
    <joint name="Torso_Leg12" type="revolute">
       <parent link="Torso"/>
       <child  link="Leg12"/>
       <origin rpy="0 0 0" xyz="1.4435978995706398 0.7901573943917399 1.4176254785325417" />
     <axis xyz="1 0 0"/>
       <limit effort="0.0" lower="-3.14159" upper="3.14159" velocity="0.0"/>
    </joint>
    <joint name="Leg4_Leg13" type="revolute">
       <parent link="Leg4"/>
       <child  link="Leg13"/>
       <origin rpy="0 0 0" xyz="1.5828924220864418 0 0" />
     <axis xyz="1 0 0"/>
       <limit effort="0.0" lower="-3.14159" upper="3.14159" velocity="0.0"/>
    </joint>
    <joint name="Leg9_Leg14" type="revolute">
       <parent link="Leg9"/>
       <child  link="Leg14"/>
       <origin rpy="0 0 0" xyz="1.9951530453610253 0 0" />
     <axis xyz="1 0 0"/>
       <limit effort="0.0" lower="-3.14159" upper="3.14159" velocity="0.0"/>
    </joint>
    <joint name="Leg11_Leg15" type="revolute">
       <parent link="Leg11"/>
       <child  link="Leg15"/>
       <origin rpy="0 0 0" xyz="0.9802442259188772 0 1.139469518863073" />
     <axis xyz="1 0 0"/>
       <limit effort="0.0" lower="-3.14159" upper="3.14159" velocity="0.0"/>
    </joint>
    <joint name="Leg7_Leg16" type="revolute">
       <parent link="Leg7"/>
       <child  link="Leg16"/>
       <origin rpy="0 0 0" xyz="1.6965151147268163 0 0.6812368504682578" />
     <axis xyz="1 0 0"/>
       <limit effort="0.0" lower="-3.14159" upper="3.14159" velocity="0.0"/>
    </joint>
    <joint name="Leg11_Leg17" type="revolute">
       <parent link="Leg11"/>
       <child  link="Leg17"/>
       <origin rpy="0 0 0" xyz="1.9604884518377543 0 1.139469518863073" />
     <axis xyz="1 0 0"/>
       <limit effort="0.0" lower="-3.14159" upper="3.14159" velocity="0.0"/>
    </joint>
    <joint name="Leg7_Leg18" type="revolute">
       <parent link="Leg7"/>
       <child  link="Leg18"/>
       <origin rpy="0 0 0" xyz="1.6965151147268163 1.0855261954817366 0.6812368504682578" />
     <axis xyz="1 0 0"/>
       <limit effort="0.0" lower="-3.14159" upper="3.14159" velocity="0.0"/>
    </joint>
    <joint name="Leg13_Leg19" type="revolute">
       <parent link="Leg13"/>
       <child  link="Leg19"/>
       <origin rpy="0 0 0" xyz="2.3097816169532526 0 0" />
     <axis xyz="1 0 0"/>
       <limit effort="0.0" lower="-3.14159" upper="3.14159" velocity="0.0"/>
    </joint>
    <joint name="Leg19_Leg20" type="revolute">
       <parent link="Leg19"/>
       <child  link="Leg20"/>
       <origin rpy="0 0 0" xyz="0 0 1.6951681300672836" />
     <axis xyz="1 0 0"/>
       <limit effort="0.0" lower="-3.14159" upper="3.14159" velocity="0.0"/>
    </joint>
    <joint name="Leg20_Leg21" type="revolute">
       <parent link="Leg20"/>
       <child  link="Leg21"/>
       <origin rpy="0 0 0" xyz="0 1.883693030277739 0" />
     <axis xyz="1 0 0"/>
       <limit effort="0.0" lower="-3.14159" upper="3.14159" velocity="0.0"/>
    </joint>
    <joint name="Leg14_Leg22" type="revolute">
       <parent link="Leg14"/>
       <child  link="Leg22"/>
       <origin rpy="0 0 0" xyz="0 0.8973388572178502 0.8574737485462426" />
     <axis xyz="1 0 0"/>
       <limit effort="0.0" lower="-3.14159" upper="3.14159" velocity="0.0"/>
    </joint>
    <joint name="Leg3_Leg23" type="revolute">
       <parent link="Leg3"/>
       <child  link="Leg23"/>
       <origin rpy="0 0 0" xyz="0 0.6239989275526601 1.4821957796053007" />
     <axis xyz="1 0 0"/>
       <limit effort="0.0" lower="-3.14159" upper="3.14159" velocity="0.0"/>
    </joint>
    <joint name="Leg22_Leg24" type="revolute">
       <parent link="Leg22"/>
       <child  link="Leg24"/>
       <origin rpy="0 0 0" xyz="0.8681285794808695 0 0.5844157544286" />
     <axis xyz="1 0 0"/>
       <limit effort="0.0" lower="-3.14159" upper="3.14159" velocity="0.0"/>
    </joint>
    <joint name="Leg6_Leg25" type="revolute">
       <parent link="Leg6"/>
       <child  link="Leg25"/>
       <origin rpy="0 0 0" xyz="1.282646562502995 1.3520712506216477 1.4205736968145626" />
     <axis xyz="1 0 0"/>
       <limit effort="0.0" lower="-3.14159" upper="3.14159" velocity="0.0"/>
    </joint>
</robot>