<robot name = "robot">
    <link name="Torso">
        <inertial>
            <origin xyz="0 0 1.0409379261094132" rpy="0 0 0"/>
            <mass value="1" />
            <inertia ixx="100" ixy="0" ixz="0" iyy="100" iyz="0" izz="100" />
        </inertial>
        <visual>
            <origin xyz="0 0 1.0409379261094132" rpy="0 0 0"/>
            <geometry>
                <box size="2.5576893589704515 1.065778659060495 2.0818758522188263" />
            </geometry>
            <material name="Green">
                <color rgba="0 180.0 0.0 1.0"/>
            </material>
        </visual>
        <collision>
            <origin xyz="0 0 1.0409379261094132" rpy="0 0 0"/>
            <geometry>
                <box size="2.5576893589704515 1.065778659060495 2.0818758522188263" />
            </geometry>
        </collision>
    </link>
    <link name="Leg1">
        <inertial>
            <origin xyz="1.0662131263536498 0 0" rpy="0 0 0"/>
            <mass value="1" />
            <inertia ixx="100" ixy="0" ixz="0" iyy="100" iyz="0" izz="100" />
        </inertial>
        <visual>
            <origin xyz="1.0662131263536498 0 0" rpy="0 0 0"/>
            <geometry>
                <box size="2.1324262527072997 1.3438994085133371 1.0305253204649945" />
            </geometry>
            <material name="Green">
                <color rgba="0 180.0 0.0 1.0"/>
            </material>
        </visual>
        <collision>
            <origin xyz="1.0662131263536498 0 0" rpy="0 0 0"/>
            <geometry>
                <box size="2.1324262527072997 1.3438994085133371 1.0305253204649945" />
            </geometry>
        </collision>
    </link>
    <link name="Leg2">
        <inertial>
            <origin xyz="0 0 1.4602441749538897" rpy="0 0 0"/>
            <mass value="1" />
            <inertia ixx="100" ixy="0" ixz="0" iyy="100" iyz="0" izz="100" />
        </inertial>
        <visual>
            <origin xyz="0 0 1.4602441749538897" rpy="0 0 0"/>
            <geometry>
                <box size="2.083716752297762 1.445285482020491 2.9204883499077794" />
            </geometry>
            <material name="Green">
                <color rgba="0 180.0 0.0 1.0"/>
            </material>
        </visual>
        <collision>
            <origin xyz="0 0 1.4602441749538897" rpy="0 0 0"/>
            <geometry>
                <box size="2.083716752297762 1.445285482020491 2.9204883499077794" />
            </geometry>
        </collision>
    </link>
    <link name="Leg3">
        <inertial>
            <origin xyz="0.9995295890726751 0 0" rpy="0 0 0"/>
            <mass value="1" />
            <inertia ixx="100" ixy="0" ixz="0" iyy="100" iyz="0" izz="100" />
        </inertial>
        <visual>
            <origin xyz="0.9995295890726751 0 0" rpy="0 0 0"/>
            <geometry>
                <box size="1.9990591781453502 1.7692355535396738 1.6600629900933523" />
            </geometry>
            <material name="Green">
                <color rgba="0 180.0 0.0 1.0"/>
            </material>
        </visual>
        <collision>
            <origin xyz="0.9995295890726751 0 0" rpy="0 0 0"/>
            <geometry>
                <box size="1.9990591781453502 1.7692355535396738 1.6600629900933523" />
            </geometry>
        </collision>
    </link>
    <link name="Leg4">
        <inertial>
            <origin xyz="0 1.4899123590708645 0" rpy="0 0 0"/>
            <mass value="1" />
            <inertia ixx="100" ixy="0" ixz="0" iyy="100" iyz="0" izz="100" />
        </inertial>
        <visual>
            <origin xyz="0 1.4899123590708645 0" rpy="0 0 0"/>
            <geometry>
                <box size="1.6340019088328537 2.979824718141729 1.3028449199832248" />
            </geometry>
            <material name="Green">
                <color rgba="0 180.0 0.0 1.0"/>
            </material>
        </visual>
        <collision>
            <origin xyz="0 1.4899123590708645 0" rpy="0 0 0"/>
            <geometry>
                <box size="1.6340019088328537 2.979824718141729 1.3028449199832248" />
            </geometry>
        </collision>
    </link>
    <link name="Leg5">
        <inertial>
            <origin xyz="1.084072877878029 0 0" rpy="0 0 0"/>
            <mass value="1" />
            <inertia ixx="100" ixy="0" ixz="0" iyy="100" iyz="0" izz="100" />
        </inertial>
        <visual>
            <origin xyz="1.084072877878029 0 0" rpy="0 0 0"/>
            <geometry>
                <box size="2.168145755756058 1.0955074069505502 2.2646780052197437" />
            </geometry>
            <material name="Blue">
                <color rgba="0 1.0 1.0 1.0"/>
            </material>
        </visual>
        <collision>
            <origin xyz="1.084072877878029 0 0" rpy="0 0 0"/>
            <geometry>
                <box size="2.168145755756058 1.0955074069505502 2.2646780052197437" />
            </geometry>
        </collision>
    </link>
    <link name="Leg6">
        <inertial>
            <origin xyz="0 0 0.6124896507616034" rpy="0 0 0"/>
            <mass value="1" />
            <inertia ixx="100" ixy="0" ixz="0" iyy="100" iyz="0" izz="100" />
        </inertial>
        <visual>
            <origin xyz="0 0 0.6124896507616034" rpy="0 0 0"/>
            <geometry>
                <box size="1.9604735388979306 2.9784169600789347 1.2249793015232069" />
            </geometry>
            <material name="Blue">
                <color rgba="0 1.0 1.0 1.0"/>
            </material>
        </visual>
        <collision>
            <origin xyz="0 0 0.6124896507616034" rpy="0 0 0"/>
            <geometry>
                <box size="1.9604735388979306 2.9784169600789347 1.2249793015232069" />
            </geometry>
        </collision>
    </link>
    <link name="Leg7">
        <inertial>
            <origin xyz="0 0 1.0830910568405139" rpy="0 0 0"/>
            <mass value="1" />
            <inertia ixx="100" ixy="0" ixz="0" iyy="100" iyz="0" izz="100" />
        </inertial>
        <visual>
            <origin xyz="0 0 1.0830910568405139" rpy="0 0 0"/>
            <geometry>
                <box size="1.7389375055950753 2.80185575234376 2.1661821136810278" />
            </geometry>
            <material name="Blue">
                <color rgba="0 1.0 1.0 1.0"/>
            </material>
        </visual>
        <collision>
            <origin xyz="0 0 1.0830910568405139" rpy="0 0 0"/>
            <geometry>
                <box size="1.7389375055950753 2.80185575234376 2.1661821136810278" />
            </geometry>
        </collision>
    </link>
    <link name="Leg8">
        <inertial>
            <origin xyz="0 0 1.0345074645113899" rpy="0 0 0"/>
            <mass value="1" />
            <inertia ixx="100" ixy="0" ixz="0" iyy="100" iyz="0" izz="100" />
        </inertial>
        <visual>
            <origin xyz="0 0 1.0345074645113899" rpy="0 0 0"/>
            <geometry>
                <box size="1.1227742820838231 1.340642905961077 2.0690149290227797" />
            </geometry>
            <material name="Blue">
                <color rgba="0 1.0 1.0 1.0"/>
            </material>
        </visual>
        <collision>
            <origin xyz="0 0 1.0345074645113899" rpy="0 0 0"/>
            <geometry>
                <box size="1.1227742820838231 1.340642905961077 2.0690149290227797" />
            </geometry>
        </collision>
    </link>
    <link name="Leg9">
        <inertial>
            <origin xyz="0 0.9982940355144957 0" rpy="0 0 0"/>
            <mass value="1" />
            <inertia ixx="100" ixy="0" ixz="0" iyy="100" iyz="0" izz="100" />
        </inertial>
        <visual>
            <origin xyz="0 0.9982940355144957 0" rpy="0 0 0"/>
            <geometry>
                <box size="1.8646353983058297 1.9965880710289914 2.2139003119002525" />
            </geometry>
            <material name="Green">
                <color rgba="0 180.0 0.0 1.0"/>
            </material>
        </visual>
        <collision>
            <origin xyz="0 0.9982940355144957 0" rpy="0 0 0"/>
            <geometry>
                <box size="1.8646353983058297 1.9965880710289914 2.2139003119002525" />
            </geometry>
        </collision>
    </link>
    <link name="Leg10">
        <inertial>
            <origin xyz="0 0 0.7928103302604841" rpy="0 0 0"/>
            <mass value="1" />
            <inertia ixx="100" ixy="0" ixz="0" iyy="100" iyz="0" izz="100" />
        </inertial>
        <visual>
            <origin xyz="0 0 0.7928103302604841" rpy="0 0 0"/>
            <geometry>
                <box size="2.8461899223588505 1.8869721356227096 1.5856206605209682" />
            </geometry>
            <material name="Green">
                <color rgba="0 180.0 0.0 1.0"/>
            </material>
        </visual>
        <collision>
            <origin xyz="0 0 0.7928103302604841" rpy="0 0 0"/>
            <geometry>
                <box size="2.8461899223588505 1.8869721356227096 1.5856206605209682" />
            </geometry>
        </collision>
    </link>
    <link name="Leg11">
        <inertial>
            <origin xyz="0 0.9113367877589088 0" rpy="0 0 0"/>
            <mass value="1" />
            <inertia ixx="100" ixy="0" ixz="0" iyy="100" iyz="0" izz="100" />
        </inertial>
        <visual>
            <origin xyz="0 0.9113367877589088 0" rpy="0 0 0"/>
            <geometry>
                <box size="2.097532334922383 1.8226735755178176 1.0066960527299917" />
            </geometry>
            <material name="Blue">
                <color rgba="0 1.0 1.0 1.0"/>
            </material>
        </visual>
        <collision>
            <origin xyz="0 0.9113367877589088 0" rpy="0 0 0"/>
            <geometry>
                <box size="2.097532334922383 1.8226735755178176 1.0066960527299917" />
            </geometry>
        </collision>
    </link>
    <link name="Leg12">
        <inertial>
            <origin xyz="0 1.0572617865951535 0" rpy="0 0 0"/>
            <mass value="1" />
            <inertia ixx="100" ixy="0" ixz="0" iyy="100" iyz="0" izz="100" />
        </inertial>
        <visual>
            <origin xyz="0 1.0572617865951535 0" rpy="0 0 0"/>
            <geometry>
                <box size="2.198001353354792 2.114523573190307 2.6825061954281493" />
            </geometry>
            <material name="Blue">
                <color rgba="0 1.0 1.0 1.0"/>
            </material>
        </visual>
        <collision>
            <origin xyz="0 1.0572617865951535 0" rpy="0 0 0"/>
            <geometry>
                <box size="2.198001353354792 2.114523573190307 2.6825061954281493" />
            </geometry>
        </collision>
    </link>
    <link name="Leg13">
        <inertial>
            <origin xyz="0.7112132524258316 0 0" rpy="0 0 0"/>
            <mass value="1" />
            <inertia ixx="100" ixy="0" ixz="0" iyy="100" iyz="0" izz="100" />
        </inertial>
        <visual>
            <origin xyz="0.7112132524258316 0 0" rpy="0 0 0"/>
            <geometry>
                <box size="1.422426504851663 1.3545829270869083 2.583982777738769" />
            </geometry>
            <material name="Green">
                <color rgba="0 180.0 0.0 1.0"/>
            </material>
        </visual>
        <collision>
            <origin xyz="0.7112132524258316 0 0" rpy="0 0 0"/>
            <geometry>
                <box size="1.422426504851663 1.3545829270869083 2.583982777738769" />
            </geometry>
        </collision>
    </link>
    <link name="Leg14">
        <inertial>
            <origin xyz="0 1.3136816920056147 0" rpy="0 0 0"/>
            <mass value="1" />
            <inertia ixx="100" ixy="0" ixz="0" iyy="100" iyz="0" izz="100" />
        </inertial>
        <visual>
            <origin xyz="0 1.3136816920056147 0" rpy="0 0 0"/>
            <geometry>
                <box size="2.218620998887212 2.6273633840112294 2.9580756016576486" />
            </geometry>
            <material name="Green">
                <color rgba="0 180.0 0.0 1.0"/>
            </material>
        </visual>
        <collision>
            <origin xyz="0 1.3136816920056147 0" rpy="0 0 0"/>
            <geometry>
                <box size="2.218620998887212 2.6273633840112294 2.9580756016576486" />
            </geometry>
        </collision>
    </link>
    <link name="Leg15">
        <inertial>
            <origin xyz="0 1.235051791963738 0" rpy="0 0 0"/>
            <mass value="1" />
            <inertia ixx="100" ixy="0" ixz="0" iyy="100" iyz="0" izz="100" />
        </inertial>
        <visual>
            <origin xyz="0 1.235051791963738 0" rpy="0 0 0"/>
            <geometry>
                <box size="1.8059923078020215 2.470103583927476 2.8641217220658697" />
            </geometry>
            <material name="Blue">
                <color rgba="0 1.0 1.0 1.0"/>
            </material>
        </visual>
        <collision>
            <origin xyz="0 1.235051791963738 0" rpy="0 0 0"/>
            <geometry>
                <box size="1.8059923078020215 2.470103583927476 2.8641217220658697" />
            </geometry>
        </collision>
    </link>
    <link name="Leg16">
        <inertial>
            <origin xyz="0 0 0.9120418157739648" rpy="0 0 0"/>
            <mass value="1" />
            <inertia ixx="100" ixy="0" ixz="0" iyy="100" iyz="0" izz="100" />
        </inertial>
        <visual>
            <origin xyz="0 0 0.9120418157739648" rpy="0 0 0"/>
            <geometry>
                <box size="2.9883400117394947 2.372505446411627 1.8240836315479296" />
            </geometry>
            <material name="Blue">
                <color rgba="0 1.0 1.0 1.0"/>
            </material>
        </visual>
        <collision>
            <origin xyz="0 0 0.9120418157739648" rpy="0 0 0"/>
            <geometry>
                <box size="2.9883400117394947 2.372505446411627 1.8240836315479296" />
            </geometry>
        </collision>
    </link>
    <link name="Leg17">
        <inertial>
            <origin xyz="0 1.331242066099127 0" rpy="0 0 0"/>
            <mass value="1" />
            <inertia ixx="100" ixy="0" ixz="0" iyy="100" iyz="0" izz="100" />
        </inertial>
        <visual>
            <origin xyz="0 1.331242066099127 0" rpy="0 0 0"/>
            <geometry>
                <box size="2.556028677135975 2.662484132198254 2.6441495542097195" />
            </geometry>
            <material name="Green">
                <color rgba="0 180.0 0.0 1.0"/>
            </material>
        </visual>
        <collision>
            <origin xyz="0 1.331242066099127 0" rpy="0 0 0"/>
            <geometry>
                <box size="2.556028677135975 2.662484132198254 2.6441495542097195" />
            </geometry>
        </collision>
    </link>
    <link name="Leg18">
        <inertial>
            <origin xyz="1.1341141702793758 0 0" rpy="0 0 0"/>
            <mass value="1" />
            <inertia ixx="100" ixy="0" ixz="0" iyy="100" iyz="0" izz="100" />
        </inertial>
        <visual>
            <origin xyz="1.1341141702793758 0 0" rpy="0 0 0"/>
            <geometry>
                <box size="2.2682283405587516 2.58258917278759 1.1191108536682135" />
            </geometry>
            <material name="Green">
                <color rgba="0 180.0 0.0 1.0"/>
            </material>
        </visual>
        <collision>
            <origin xyz="1.1341141702793758 0 0" rpy="0 0 0"/>
            <geometry>
                <box size="2.2682283405587516 2.58258917278759 1.1191108536682135" />
            </geometry>
        </collision>
    </link>
    <link name="Leg19">
        <inertial>
            <origin xyz="0 0.8799038078832061 0" rpy="0 0 0"/>
            <mass value="1" />
            <inertia ixx="100" ixy="0" ixz="0" iyy="100" iyz="0" izz="100" />
        </inertial>
        <visual>
            <origin xyz="0 0.8799038078832061 0" rpy="0 0 0"/>
            <geometry>
                <box size="1.714834635247839 1.7598076157664122 1.425778531242128" />
            </geometry>
            <material name="Blue">
                <color rgba="0 1.0 1.0 1.0"/>
            </material>
        </visual>
        <collision>
            <origin xyz="0 0.8799038078832061 0" rpy="0 0 0"/>
            <geometry>
                <box size="1.714834635247839 1.7598076157664122 1.425778531242128" />
            </geometry>
        </collision>
    </link>
    <link name="Leg20">
        <inertial>
            <origin xyz="0.7154746522040456 0 0" rpy="0 0 0"/>
            <mass value="1" />
            <inertia ixx="100" ixy="0" ixz="0" iyy="100" iyz="0" izz="100" />
        </inertial>
        <visual>
            <origin xyz="0.7154746522040456 0 0" rpy="0 0 0"/>
            <geometry>
                <box size="1.4309493044080912 2.7170413565887146 2.628444909270149" />
            </geometry>
            <material name="Green">
                <color rgba="0 180.0 0.0 1.0"/>
            </material>
        </visual>
        <collision>
            <origin xyz="0.7154746522040456 0 0" rpy="0 0 0"/>
            <geometry>
                <box size="1.4309493044080912 2.7170413565887146 2.628444909270149" />
            </geometry>
        </collision>
    </link>
    <link name="Leg21">
        <inertial>
            <origin xyz="0 0 0.5330035975133424" rpy="0 0 0"/>
            <mass value="1" />
            <inertia ixx="100" ixy="0" ixz="0" iyy="100" iyz="0" izz="100" />
        </inertial>
        <visual>
            <origin xyz="0 0 0.5330035975133424" rpy="0 0 0"/>
            <geometry>
                <box size="2.0533549976469585 2.163076353724902 1.0660071950266847" />
            </geometry>
            <material name="Blue">
                <color rgba="0 1.0 1.0 1.0"/>
            </material>
        </visual>
        <collision>
            <origin xyz="0 0 0.5330035975133424" rpy="0 0 0"/>
            <geometry>
                <box size="2.0533549976469585 2.163076353724902 1.0660071950266847" />
            </geometry>
        </collision>
    </link>
    <link name="Leg22">
        <inertial>
            <origin xyz="1.3186252117698505 0 0" rpy="0 0 0"/>
            <mass value="1" />
            <inertia ixx="100" ixy="0" ixz="0" iyy="100" iyz="0" izz="100" />
        </inertial>
        <visual>
            <origin xyz="1.3186252117698505 0 0" rpy="0 0 0"/>
            <geometry>
                <box size="2.637250423539701 1.8385453544254815 1.266382112883916" />
            </geometry>
            <material name="Green">
                <color rgba="0 180.0 0.0 1.0"/>
            </material>
        </visual>
        <collision>
            <origin xyz="1.3186252117698505 0 0" rpy="0 0 0"/>
            <geometry>
                <box size="2.637250423539701 1.8385453544254815 1.266382112883916" />
            </geometry>
        </collision>
    </link>
    <link name="Leg23">
        <inertial>
            <origin xyz="0 0 1.4322706804095398" rpy="0 0 0"/>
            <mass value="1" />
            <inertia ixx="100" ixy="0" ixz="0" iyy="100" iyz="0" izz="100" />
        </inertial>
        <visual>
            <origin xyz="0 0 1.4322706804095398" rpy="0 0 0"/>
            <geometry>
                <box size="2.354596952711629 2.314415062733845 2.8645413608190795" />
            </geometry>
            <material name="Green">
                <color rgba="0 180.0 0.0 1.0"/>
            </material>
        </visual>
        <collision>
            <origin xyz="0 0 1.4322706804095398" rpy="0 0 0"/>
            <geometry>
                <box size="2.354596952711629 2.314415062733845 2.8645413608190795" />
            </geometry>
        </collision>
    </link>
    <link name="Leg24">
        <inertial>
            <origin xyz="0 1.1014541103501412 0" rpy="0 0 0"/>
            <mass value="1" />
            <inertia ixx="100" ixy="0" ixz="0" iyy="100" iyz="0" izz="100" />
        </inertial>
        <visual>
            <origin xyz="0 1.1014541103501412 0" rpy="0 0 0"/>
            <geometry>
                <box size="1.812315722767291 2.2029082207002824 1.5243373625522318" />
            </geometry>
            <material name="Green">
                <color rgba="0 180.0 0.0 1.0"/>
            </material>
        </visual>
        <collision>
            <origin xyz="0 1.1014541103501412 0" rpy="0 0 0"/>
            <geometry>
                <box size="1.812315722767291 2.2029082207002824 1.5243373625522318" />
            </geometry>
        </collision>
    </link>
    <link name="Leg25">
        <inertial>
            <origin xyz="1.0462743693219607 0 0" rpy="0 0 0"/>
            <mass value="1" />
            <inertia ixx="100" ixy="0" ixz="0" iyy="100" iyz="0" izz="100" />
        </inertial>
        <visual>
            <origin xyz="1.0462743693219607 0 0" rpy="0 0 0"/>
            <geometry>
                <box size="2.0925487386439214 1.7912860063840061 1.5208767298070691" />
            </geometry>
            <material name="Blue">
                <color rgba="0 1.0 1.0 1.0"/>
            </material>
        </visual>
        <collision>
            <origin xyz="1.0462743693219607 0 0" rpy="0 0 0"/>
            <geometry>
                <box size="2.0925487386439214 1.7912860063840061 1.5208767298070691" />
            </geometry>
        </collision>
    </link>
    <joint name="Torso_Leg1" type="revolute">
       <parent link="Torso"/>
       <child  link="Leg1"/>
       <origin rpy="0 0 0" xyz="1.2788446794852257 0 1.0409379261094132" />
     <axis xyz="1 0 0"/>
       <limit effort="0.0" lower="-3.14159" upper="3.14159" velocity="0.0"/>
    </joint>
    <joint name="Torso_Leg2" type="revolute">
       <parent link="Torso"/>
       <child  link="Leg2"/>
       <origin rpy="0 0 0" xyz="1.0662131263536498 0 0.5152626602324972" />
     <axis xyz="1 0 0"/>
       <limit effort="0.0" lower="-3.14159" upper="3.14159" velocity="0.0"/>
    </joint>
    <joint name="Leg2_Leg3" type="revolute">
       <parent link="Leg2"/>
       <child  link="Leg3"/>
       <origin rpy="0 0 0" xyz="1.9990591781453502 0 0" />
     <axis xyz="1 0 0"/>
       <limit effort="0.0" lower="-3.14159" upper="3.14159" velocity="0.0"/>
    </joint>
    <joint name="Leg1_Leg4" type="revolute">
       <parent link="Leg1"/>
       <child  link="Leg4"/>
       <origin rpy="0 0 0" xyz="0 0.7226427410102455 1.4602441749538897" />
     <axis xyz="1 0 0"/>
       <limit effort="0.0" lower="-3.14159" upper="3.14159" velocity="0.0"/>
    </joint>
    <joint name="Leg4_Leg5" type="revolute">
       <parent link="Leg4"/>
       <child  link="Leg5"/>
       <origin rpy="0 0 0" xyz="2.168145755756058 0 0" />
     <axis xyz="1 0 0"/>
       <limit effort="0.0" lower="-3.14159" upper="3.14159" velocity="0.0"/>
    </joint>
    <joint name="Leg4_Leg6" type="revolute">
       <parent link="Leg4"/>
       <child  link="Leg6"/>
       <origin rpy="0 0 0" xyz="2.168145755756058 0 1.1323390026098719" />
     <axis xyz="1 0 0"/>
       <limit effort="0.0" lower="-3.14159" upper="3.14159" velocity="0.0"/>
    </joint>
    <joint name="Leg1_Leg7" type="revolute">
       <parent link="Leg1"/>
       <child  link="Leg7"/>
       <origin rpy="0 0 0" xyz="0 0.7226427410102455 2.9204883499077794" />
     <axis xyz="1 0 0"/>
       <limit effort="0.0" lower="-3.14159" upper="3.14159" velocity="0.0"/>
    </joint>
    <joint name="Leg7_Leg8" type="revolute">
       <parent link="Leg7"/>
       <child  link="Leg8"/>
       <origin rpy="0 0 0" xyz="0 0 2.0690149290227797" />
     <axis xyz="1 0 0"/>
       <limit effort="0.0" lower="-3.14159" upper="3.14159" velocity="0.0"/>
    </joint>
    <joint name="Torso_Leg9" type="revolute">
       <parent link="Torso"/>
       <child  link="Leg9"/>
       <origin rpy="0 0 0" xyz="1.0662131263536498 0.6719497042566686 0.5152626602324972" />
     <axis xyz="1 0 0"/>
       <limit effort="0.0" lower="-3.14159" upper="3.14159" velocity="0.0"/>
    </joint>
    <joint name="Leg6_Leg10" type="revolute">
       <parent link="Leg6"/>
       <child  link="Leg10"/>
       <origin rpy="0 0 0" xyz="0 0 2.1661821136810278" />
     <axis xyz="1 0 0"/>
       <limit effort="0.0" lower="-3.14159" upper="3.14159" velocity="0.0"/>
    </joint>
    <joint name="Leg9_Leg11" type="revolute">
       <parent link="Leg9"/>
       <child  link="Leg11"/>
       <origin rpy="0 0 0" xyz="0 0.9434860678113548 0.7928103302604841" />
     <axis xyz="1 0 0"/>
       <limit effort="0.0" lower="-3.14159" upper="3.14159" velocity="0.0"/>
    </joint>
    <joint name="Leg7_Leg12" type="revolute">
       <parent link="Leg7"/>
       <child  link="Leg12"/>
       <origin rpy="0 0 0" xyz="0 0.6703214529805385 2.0690149290227797" />
     <axis xyz="1 0 0"/>
       <limit effort="0.0" lower="-3.14159" upper="3.14159" velocity="0.0"/>
    </joint>
    <joint name="Leg6_Leg13" type="revolute">
       <parent link="Leg6"/>
       <child  link="Leg13"/>
       <origin rpy="0 0 0" xyz="0.8694687527975377 0 2.1661821136810278" />
     <axis xyz="1 0 0"/>
       <limit effort="0.0" lower="-3.14159" upper="3.14159" velocity="0.0"/>
    </joint>
    <joint name="Leg12_Leg14" type="revolute">
       <parent link="Leg12"/>
       <child  link="Leg14"/>
       <origin rpy="0 0 0" xyz="0.7112132524258316 0.6772914635434542 0" />
     <axis xyz="1 0 0"/>
       <limit effort="0.0" lower="-3.14159" upper="3.14159" velocity="0.0"/>
    </joint>
    <joint name="Leg5_Leg15" type="revolute">
       <parent link="Leg5"/>
       <child  link="Leg15"/>
       <origin rpy="0 0 0" xyz="0 1.4892084800394674 0.6124896507616034" />
     <axis xyz="1 0 0"/>
       <limit effort="0.0" lower="-3.14159" upper="3.14159" velocity="0.0"/>
    </joint>
    <joint name="Leg3_Leg16" type="revolute">
       <parent link="Leg3"/>
       <child  link="Leg16"/>
       <origin rpy="0 0 0" xyz="0 1.4899123590708645 0.6514224599916124" />
     <axis xyz="1 0 0"/>
       <limit effort="0.0" lower="-3.14159" upper="3.14159" velocity="0.0"/>
    </joint>
    <joint name="Leg10_Leg17" type="revolute">
       <parent link="Leg10"/>
       <child  link="Leg17"/>
       <origin rpy="0 0 0" xyz="0 1.8226735755178176 0" />
     <axis xyz="1 0 0"/>
       <limit effort="0.0" lower="-3.14159" upper="3.14159" velocity="0.0"/>
    </joint>
    <joint name="Leg10_Leg18" type="revolute">
       <parent link="Leg10"/>
       <child  link="Leg18"/>
       <origin rpy="0 0 0" xyz="1.0487661674611914 1.8226735755178176 0" />
     <axis xyz="1 0 0"/>
       <limit effort="0.0" lower="-3.14159" upper="3.14159" velocity="0.0"/>
    </joint>
    <joint name="Leg18_Leg19" type="revolute">
       <parent link="Leg18"/>
       <child  link="Leg19"/>
       <origin rpy="0 0 0" xyz="0 1.7598076157664122 0" />
     <axis xyz="1 0 0"/>
       <limit effort="0.0" lower="-3.14159" upper="3.14159" velocity="0.0"/>
    </joint>
    <joint name="Leg7_Leg20" type="revolute">
       <parent link="Leg7"/>
       <child  link="Leg20"/>
       <origin rpy="0 0 0" xyz="0.5613871410419116 0.6703214529805385 2.0690149290227797" />
     <axis xyz="1 0 0"/>
       <limit effort="0.0" lower="-3.14159" upper="3.14159" velocity="0.0"/>
    </joint>
    <joint name="Leg9_Leg21" type="revolute">
       <parent link="Leg9"/>
       <child  link="Leg21"/>
       <origin rpy="0 0 0" xyz="0 0.9434860678113548 1.5856206605209682" />
     <axis xyz="1 0 0"/>
       <limit effort="0.0" lower="-3.14159" upper="3.14159" velocity="0.0"/>
    </joint>
    <joint name="Leg12_Leg22" type="revolute">
       <parent link="Leg12"/>
       <child  link="Leg22"/>
       <origin rpy="0 0 0" xyz="1.422426504851663 0.6772914635434542 0" />
     <axis xyz="1 0 0"/>
       <limit effort="0.0" lower="-3.14159" upper="3.14159" velocity="0.0"/>
    </joint>
    <joint name="Leg5_Leg23" type="revolute">
       <parent link="Leg5"/>
       <child  link="Leg23"/>
       <origin rpy="0 0 0" xyz="0 1.4892084800394674 1.2249793015232069" />
     <axis xyz="1 0 0"/>
       <limit effort="0.0" lower="-3.14159" upper="3.14159" velocity="0.0"/>
    </joint>
    <joint name="Leg4_Leg24" type="revolute">
       <parent link="Leg4"/>
       <child  link="Leg24"/>
       <origin rpy="0 0 0" xyz="2.168145755756058 0.5477537034752751 1.1323390026098719" />
     <axis xyz="1 0 0"/>
       <limit effort="0.0" lower="-3.14159" upper="3.14159" velocity="0.0"/>
    </joint>
    <joint name="Leg20_Leg25" type="revolute">
       <parent link="Leg20"/>
       <child  link="Leg25"/>
       <origin rpy="0 0 0" xyz="1.0266774988234793 0 0.5330035975133424" />
     <axis xyz="1 0 0"/>
       <limit effort="0.0" lower="-3.14159" upper="3.14159" velocity="0.0"/>
    </joint>
</robot>