<robot name = "robot">
    <link name="Torso">
        <inertial>
            <origin xyz="0 0 0.8971584887639198" rpy="0 0 0"/>
            <mass value="1" />
            <inertia ixx="100" ixy="0" ixz="0" iyy="100" iyz="0" izz="100" />
        </inertial>
        <visual>
            <origin xyz="0 0 0.8971584887639198" rpy="0 0 0"/>
            <geometry>
                <box size="1.524665626773099 2.2113290536109274 1.7943169775278396" />
            </geometry>
            <material name="Green">
                <color rgba="0 180.0 0.0 1.0"/>
            </material>
        </visual>
        <collision>
            <origin xyz="0 0 0.8971584887639198" rpy="0 0 0"/>
            <geometry>
                <box size="1.524665626773099 2.2113290536109274 1.7943169775278396" />
            </geometry>
        </collision>
    </link>
    <link name="Leg1">
        <inertial>
            <origin xyz="0 0 0.5070948595111991" rpy="0 0 0"/>
            <mass value="1" />
            <inertia ixx="100" ixy="0" ixz="0" iyy="100" iyz="0" izz="100" />
        </inertial>
        <visual>
            <origin xyz="0 0 0.5070948595111991" rpy="0 0 0"/>
            <geometry>
                <box size="2.230207351304263 1.2099481532203835 1.0141897190223983" />
            </geometry>
            <material name="Blue">
                <color rgba="0 1.0 1.0 1.0"/>
            </material>
        </visual>
        <collision>
            <origin xyz="0 0 0.5070948595111991" rpy="0 0 0"/>
            <geometry>
                <box size="2.230207351304263 1.2099481532203835 1.0141897190223983" />
            </geometry>
        </collision>
    </link>
    <link name="Leg2">
        <inertial>
            <origin xyz="0 0.7975335590841005 0" rpy="0 0 0"/>
            <mass value="1" />
            <inertia ixx="100" ixy="0" ixz="0" iyy="100" iyz="0" izz="100" />
        </inertial>
        <visual>
            <origin xyz="0 0.7975335590841005 0" rpy="0 0 0"/>
            <geometry>
                <box size="1.9350009212103303 1.595067118168201 2.5937208682595405" />
            </geometry>
            <material name="Blue">
                <color rgba="0 1.0 1.0 1.0"/>
            </material>
        </visual>
        <collision>
            <origin xyz="0 0.7975335590841005 0" rpy="0 0 0"/>
            <geometry>
                <box size="1.9350009212103303 1.595067118168201 2.5937208682595405" />
            </geometry>
        </collision>
    </link>
    <link name="Leg3">
        <inertial>
            <origin xyz="1.037496818930002 0 0" rpy="0 0 0"/>
            <mass value="1" />
            <inertia ixx="100" ixy="0" ixz="0" iyy="100" iyz="0" izz="100" />
        </inertial>
        <visual>
            <origin xyz="1.037496818930002 0 0" rpy="0 0 0"/>
            <geometry>
                <box size="2.074993637860004 1.2671911943576888 1.2917689448601308" />
            </geometry>
            <material name="Green">
                <color rgba="0 180.0 0.0 1.0"/>
            </material>
        </visual>
        <collision>
            <origin xyz="1.037496818930002 0 0" rpy="0 0 0"/>
            <geometry>
                <box size="2.074993637860004 1.2671911943576888 1.2917689448601308" />
            </geometry>
        </collision>
    </link>
    <link name="Leg4">
        <inertial>
            <origin xyz="0 0 0.5564222234227609" rpy="0 0 0"/>
            <mass value="1" />
            <inertia ixx="100" ixy="0" ixz="0" iyy="100" iyz="0" izz="100" />
        </inertial>
        <visual>
            <origin xyz="0 0 0.5564222234227609" rpy="0 0 0"/>
            <geometry>
                <box size="2.5666408044939235 1.1777023646306313 1.1128444468455219" />
            </geometry>
            <material name="Green">
                <color rgba="0 180.0 0.0 1.0"/>
            </material>
        </visual>
        <collision>
            <origin xyz="0 0 0.5564222234227609" rpy="0 0 0"/>
            <geometry>
                <box size="2.5666408044939235 1.1777023646306313 1.1128444468455219" />
            </geometry>
        </collision>
    </link>
    <link name="Leg5">
        <inertial>
            <origin xyz="0 0 1.4072687574876193" rpy="0 0 0"/>
            <mass value="1" />
            <inertia ixx="100" ixy="0" ixz="0" iyy="100" iyz="0" izz="100" />
        </inertial>
        <visual>
            <origin xyz="0 0 1.4072687574876193" rpy="0 0 0"/>
            <geometry>
                <box size="1.9630161575236524 1.3128352405214967 2.8145375149752385" />
            </geometry>
            <material name="Green">
                <color rgba="0 180.0 0.0 1.0"/>
            </material>
        </visual>
        <collision>
            <origin xyz="0 0 1.4072687574876193" rpy="0 0 0"/>
            <geometry>
                <box size="1.9630161575236524 1.3128352405214967 2.8145375149752385" />
            </geometry>
        </collision>
    </link>
    <link name="Leg6">
        <inertial>
            <origin xyz="0 1.231849403641644 0" rpy="0 0 0"/>
            <mass value="1" />
            <inertia ixx="100" ixy="0" ixz="0" iyy="100" iyz="0" izz="100" />
        </inertial>
        <visual>
            <origin xyz="0 1.231849403641644 0" rpy="0 0 0"/>
            <geometry>
                <box size="1.9202932967396305 2.463698807283288 2.5806021591851174" />
            </geometry>
            <material name="Blue">
                <color rgba="0 1.0 1.0 1.0"/>
            </material>
        </visual>
        <collision>
            <origin xyz="0 1.231849403641644 0" rpy="0 0 0"/>
            <geometry>
                <box size="1.9202932967396305 2.463698807283288 2.5806021591851174" />
            </geometry>
        </collision>
    </link>
    <link name="Leg7">
        <inertial>
            <origin xyz="1.186036842330764 0 0" rpy="0 0 0"/>
            <mass value="1" />
            <inertia ixx="100" ixy="0" ixz="0" iyy="100" iyz="0" izz="100" />
        </inertial>
        <visual>
            <origin xyz="1.186036842330764 0 0" rpy="0 0 0"/>
            <geometry>
                <box size="2.372073684661528 2.709870519672731 1.6757029944014263" />
            </geometry>
            <material name="Green">
                <color rgba="0 180.0 0.0 1.0"/>
            </material>
        </visual>
        <collision>
            <origin xyz="1.186036842330764 0 0" rpy="0 0 0"/>
            <geometry>
                <box size="2.372073684661528 2.709870519672731 1.6757029944014263" />
            </geometry>
        </collision>
    </link>
    <link name="Leg8">
        <inertial>
            <origin xyz="1.2329549499144798 0 0" rpy="0 0 0"/>
            <mass value="1" />
            <inertia ixx="100" ixy="0" ixz="0" iyy="100" iyz="0" izz="100" />
        </inertial>
        <visual>
            <origin xyz="1.2329549499144798 0 0" rpy="0 0 0"/>
            <geometry>
                <box size="2.4659098998289597 2.5865898887288052 2.52720734343111" />
            </geometry>
            <material name="Blue">
                <color rgba="0 1.0 1.0 1.0"/>
            </material>
        </visual>
        <collision>
            <origin xyz="1.2329549499144798 0 0" rpy="0 0 0"/>
            <geometry>
                <box size="2.4659098998289597 2.5865898887288052 2.52720734343111" />
            </geometry>
        </collision>
    </link>
    <link name="Leg9">
        <inertial>
            <origin xyz="0 0 0.6496735449538298" rpy="0 0 0"/>
            <mass value="1" />
            <inertia ixx="100" ixy="0" ixz="0" iyy="100" iyz="0" izz="100" />
        </inertial>
        <visual>
            <origin xyz="0 0 0.6496735449538298" rpy="0 0 0"/>
            <geometry>
                <box size="2.2248140183632734 2.2909123625675787 1.2993470899076596" />
            </geometry>
            <material name="Green">
                <color rgba="0 180.0 0.0 1.0"/>
            </material>
        </visual>
        <collision>
            <origin xyz="0 0 0.6496735449538298" rpy="0 0 0"/>
            <geometry>
                <box size="2.2248140183632734 2.2909123625675787 1.2993470899076596" />
            </geometry>
        </collision>
    </link>
    <link name="Leg10">
        <inertial>
            <origin xyz="0 0.8721731349274401 0" rpy="0 0 0"/>
            <mass value="1" />
            <inertia ixx="100" ixy="0" ixz="0" iyy="100" iyz="0" izz="100" />
        </inertial>
        <visual>
            <origin xyz="0 0.8721731349274401 0" rpy="0 0 0"/>
            <geometry>
                <box size="2.264483110521792 1.7443462698548802 2.745166537483131" />
            </geometry>
            <material name="Blue">
                <color rgba="0 1.0 1.0 1.0"/>
            </material>
        </visual>
        <collision>
            <origin xyz="0 0.8721731349274401 0" rpy="0 0 0"/>
            <geometry>
                <box size="2.264483110521792 1.7443462698548802 2.745166537483131" />
            </geometry>
        </collision>
    </link>
    <link name="Leg11">
        <inertial>
            <origin xyz="0 1.20724789086188 0" rpy="0 0 0"/>
            <mass value="1" />
            <inertia ixx="100" ixy="0" ixz="0" iyy="100" iyz="0" izz="100" />
        </inertial>
        <visual>
            <origin xyz="0 1.20724789086188 0" rpy="0 0 0"/>
            <geometry>
                <box size="2.122105518400547 2.41449578172376 2.04314450867638" />
            </geometry>
            <material name="Blue">
                <color rgba="0 1.0 1.0 1.0"/>
            </material>
        </visual>
        <collision>
            <origin xyz="0 1.20724789086188 0" rpy="0 0 0"/>
            <geometry>
                <box size="2.122105518400547 2.41449578172376 2.04314450867638" />
            </geometry>
        </collision>
    </link>
    <link name="Leg12">
        <inertial>
            <origin xyz="0.9927703656363475 0 0" rpy="0 0 0"/>
            <mass value="1" />
            <inertia ixx="100" ixy="0" ixz="0" iyy="100" iyz="0" izz="100" />
        </inertial>
        <visual>
            <origin xyz="0.9927703656363475 0 0" rpy="0 0 0"/>
            <geometry>
                <box size="1.985540731272695 1.9021187335617735 2.8832855452000974" />
            </geometry>
            <material name="Green">
                <color rgba="0 180.0 0.0 1.0"/>
            </material>
        </visual>
        <collision>
            <origin xyz="0.9927703656363475 0 0" rpy="0 0 0"/>
            <geometry>
                <box size="1.985540731272695 1.9021187335617735 2.8832855452000974" />
            </geometry>
        </collision>
    </link>
    <link name="Leg13">
        <inertial>
            <origin xyz="0 1.2397440342491448 0" rpy="0 0 0"/>
            <mass value="1" />
            <inertia ixx="100" ixy="0" ixz="0" iyy="100" iyz="0" izz="100" />
        </inertial>
        <visual>
            <origin xyz="0 1.2397440342491448 0" rpy="0 0 0"/>
            <geometry>
                <box size="1.1030240468353165 2.4794880684982896 2.7499142930685285" />
            </geometry>
            <material name="Blue">
                <color rgba="0 1.0 1.0 1.0"/>
            </material>
        </visual>
        <collision>
            <origin xyz="0 1.2397440342491448 0" rpy="0 0 0"/>
            <geometry>
                <box size="1.1030240468353165 2.4794880684982896 2.7499142930685285" />
            </geometry>
        </collision>
    </link>
    <link name="Leg14">
        <inertial>
            <origin xyz="0 0 0.7595953471858238" rpy="0 0 0"/>
            <mass value="1" />
            <inertia ixx="100" ixy="0" ixz="0" iyy="100" iyz="0" izz="100" />
        </inertial>
        <visual>
            <origin xyz="0 0 0.7595953471858238" rpy="0 0 0"/>
            <geometry>
                <box size="2.2520057032250733 1.1900475668100745 1.5191906943716476" />
            </geometry>
            <material name="Blue">
                <color rgba="0 1.0 1.0 1.0"/>
            </material>
        </visual>
        <collision>
            <origin xyz="0 0 0.7595953471858238" rpy="0 0 0"/>
            <geometry>
                <box size="2.2520057032250733 1.1900475668100745 1.5191906943716476" />
            </geometry>
        </collision>
    </link>
    <link name="Leg15">
        <inertial>
            <origin xyz="0 0 1.4749351494661476" rpy="0 0 0"/>
            <mass value="1" />
            <inertia ixx="100" ixy="0" ixz="0" iyy="100" iyz="0" izz="100" />
        </inertial>
        <visual>
            <origin xyz="0 0 1.4749351494661476" rpy="0 0 0"/>
            <geometry>
                <box size="1.7131277702194527 2.1916986437157444 2.949870298932295" />
            </geometry>
            <material name="Blue">
                <color rgba="0 1.0 1.0 1.0"/>
            </material>
        </visual>
        <collision>
            <origin xyz="0 0 1.4749351494661476" rpy="0 0 0"/>
            <geometry>
                <box size="1.7131277702194527 2.1916986437157444 2.949870298932295" />
            </geometry>
        </collision>
    </link>
    <link name="Leg16">
        <inertial>
            <origin xyz="0 0.9490051354034776 0" rpy="0 0 0"/>
            <mass value="1" />
            <inertia ixx="100" ixy="0" ixz="0" iyy="100" iyz="0" izz="100" />
        </inertial>
        <visual>
            <origin xyz="0 0.9490051354034776 0" rpy="0 0 0"/>
            <geometry>
                <box size="2.368848361197479 1.8980102708069553 2.9937051310843423" />
            </geometry>
            <material name="Blue">
                <color rgba="0 1.0 1.0 1.0"/>
            </material>
        </visual>
        <collision>
            <origin xyz="0 0.9490051354034776 0" rpy="0 0 0"/>
            <geometry>
                <box size="2.368848361197479 1.8980102708069553 2.9937051310843423" />
            </geometry>
        </collision>
    </link>
    <link name="Leg17">
        <inertial>
            <origin xyz="0 1.4849424044370914 0" rpy="0 0 0"/>
            <mass value="1" />
            <inertia ixx="100" ixy="0" ixz="0" iyy="100" iyz="0" izz="100" />
        </inertial>
        <visual>
            <origin xyz="0 1.4849424044370914 0" rpy="0 0 0"/>
            <geometry>
                <box size="1.4795083683444965 2.9698848088741827 2.1578509130251238" />
            </geometry>
            <material name="Blue">
                <color rgba="0 1.0 1.0 1.0"/>
            </material>
        </visual>
        <collision>
            <origin xyz="0 1.4849424044370914 0" rpy="0 0 0"/>
            <geometry>
                <box size="1.4795083683444965 2.9698848088741827 2.1578509130251238" />
            </geometry>
        </collision>
    </link>
    <link name="Leg18">
        <inertial>
            <origin xyz="0 1.3808986636120495 0" rpy="0 0 0"/>
            <mass value="1" />
            <inertia ixx="100" ixy="0" ixz="0" iyy="100" iyz="0" izz="100" />
        </inertial>
        <visual>
            <origin xyz="0 1.3808986636120495 0" rpy="0 0 0"/>
            <geometry>
                <box size="2.7101721447342406 2.761797327224099 1.5319608467886512" />
            </geometry>
            <material name="Green">
                <color rgba="0 180.0 0.0 1.0"/>
            </material>
        </visual>
        <collision>
            <origin xyz="0 1.3808986636120495 0" rpy="0 0 0"/>
            <geometry>
                <box size="2.7101721447342406 2.761797327224099 1.5319608467886512" />
            </geometry>
        </collision>
    </link>
    <link name="Leg19">
        <inertial>
            <origin xyz="1.2984885553052967 0 0" rpy="0 0 0"/>
            <mass value="1" />
            <inertia ixx="100" ixy="0" ixz="0" iyy="100" iyz="0" izz="100" />
        </inertial>
        <visual>
            <origin xyz="1.2984885553052967 0 0" rpy="0 0 0"/>
            <geometry>
                <box size="2.5969771106105934 2.334495794072174 2.360341376153055" />
            </geometry>
            <material name="Blue">
                <color rgba="0 1.0 1.0 1.0"/>
            </material>
        </visual>
        <collision>
            <origin xyz="1.2984885553052967 0 0" rpy="0 0 0"/>
            <geometry>
                <box size="2.5969771106105934 2.334495794072174 2.360341376153055" />
            </geometry>
        </collision>
    </link>
    <link name="Leg20">
        <inertial>
            <origin xyz="1.2527946861335364 0 0" rpy="0 0 0"/>
            <mass value="1" />
            <inertia ixx="100" ixy="0" ixz="0" iyy="100" iyz="0" izz="100" />
        </inertial>
        <visual>
            <origin xyz="1.2527946861335364 0 0" rpy="0 0 0"/>
            <geometry>
                <box size="2.505589372267073 1.0914321025451188 1.7556262400584033" />
            </geometry>
            <material name="Green">
                <color rgba="0 180.0 0.0 1.0"/>
            </material>
        </visual>
        <collision>
            <origin xyz="1.2527946861335364 0 0" rpy="0 0 0"/>
            <geometry>
                <box size="2.505589372267073 1.0914321025451188 1.7556262400584033" />
            </geometry>
        </collision>
    </link>
    <link name="Leg21">
        <inertial>
            <origin xyz="0.5852721736252531 0 0" rpy="0 0 0"/>
            <mass value="1" />
            <inertia ixx="100" ixy="0" ixz="0" iyy="100" iyz="0" izz="100" />
        </inertial>
        <visual>
            <origin xyz="0.5852721736252531 0 0" rpy="0 0 0"/>
            <geometry>
                <box size="1.1705443472505062 2.8566542270824504 1.3221099410563315" />
            </geometry>
            <material name="Blue">
                <color rgba="0 1.0 1.0 1.0"/>
            </material>
        </visual>
        <collision>
            <origin xyz="0.5852721736252531 0 0" rpy="0 0 0"/>
            <geometry>
                <box size="1.1705443472505062 2.8566542270824504 1.3221099410563315" />
            </geometry>
        </collision>
    </link>
    <link name="Leg22">
        <inertial>
            <origin xyz="0 0 1.2444227870095395" rpy="0 0 0"/>
            <mass value="1" />
            <inertia ixx="100" ixy="0" ixz="0" iyy="100" iyz="0" izz="100" />
        </inertial>
        <visual>
            <origin xyz="0 0 1.2444227870095395" rpy="0 0 0"/>
            <geometry>
                <box size="1.8698498713013814 2.9457579092583233 2.488845574019079" />
            </geometry>
            <material name="Blue">
                <color rgba="0 1.0 1.0 1.0"/>
            </material>
        </visual>
        <collision>
            <origin xyz="0 0 1.2444227870095395" rpy="0 0 0"/>
            <geometry>
                <box size="1.8698498713013814 2.9457579092583233 2.488845574019079" />
            </geometry>
        </collision>
    </link>
    <link name="Leg23">
        <inertial>
            <origin xyz="0 0.9161545875377501 0" rpy="0 0 0"/>
            <mass value="1" />
            <inertia ixx="100" ixy="0" ixz="0" iyy="100" iyz="0" izz="100" />
        </inertial>
        <visual>
            <origin xyz="0 0.9161545875377501 0" rpy="0 0 0"/>
            <geometry>
                <box size="1.734690948502178 1.8323091750755003 1.0681611847222048" />
            </geometry>
            <material name="Blue">
                <color rgba="0 1.0 1.0 1.0"/>
            </material>
        </visual>
        <collision>
            <origin xyz="0 0.9161545875377501 0" rpy="0 0 0"/>
            <geometry>
                <box size="1.734690948502178 1.8323091750755003 1.0681611847222048" />
            </geometry>
        </collision>
    </link>
    <link name="Leg24">
        <inertial>
            <origin xyz="0 0 1.4908347043531274" rpy="0 0 0"/>
            <mass value="1" />
            <inertia ixx="100" ixy="0" ixz="0" iyy="100" iyz="0" izz="100" />
        </inertial>
        <visual>
            <origin xyz="0 0 1.4908347043531274" rpy="0 0 0"/>
            <geometry>
                <box size="1.2242512479684384 1.7986624145665229 2.9816694087062547" />
            </geometry>
            <material name="Green">
                <color rgba="0 180.0 0.0 1.0"/>
            </material>
        </visual>
        <collision>
            <origin xyz="0 0 1.4908347043531274" rpy="0 0 0"/>
            <geometry>
                <box size="1.2242512479684384 1.7986624145665229 2.9816694087062547" />
            </geometry>
        </collision>
    </link>
    <link name="Leg25">
        <inertial>
            <origin xyz="0 1.3145971913521985 0" rpy="0 0 0"/>
            <mass value="1" />
            <inertia ixx="100" ixy="0" ixz="0" iyy="100" iyz="0" izz="100" />
        </inertial>
        <visual>
            <origin xyz="0 1.3145971913521985 0" rpy="0 0 0"/>
            <geometry>
                <box size="1.729650244258114 2.629194382704397 1.3677832751686134" />
            </geometry>
            <material name="Green">
                <color rgba="0 180.0 0.0 1.0"/>
            </material>
        </visual>
        <collision>
            <origin xyz="0 1.3145971913521985 0" rpy="0 0 0"/>
            <geometry>
                <box size="1.729650244258114 2.629194382704397 1.3677832751686134" />
            </geometry>
        </collision>
    </link>
    <joint name="Torso_Leg1" type="revolute">
       <parent link="Torso"/>
       <child  link="Leg1"/>
       <origin rpy="0 0 0" xyz="0 0 1.7943169775278396" />
     <axis xyz="1 0 0"/>
       <limit effort="0.0" lower="-3.14159" upper="3.14159" velocity="0.0"/>
    </joint>
    <joint name="Leg1_Leg2" type="revolute">
       <parent link="Leg1"/>
       <child  link="Leg2"/>
       <origin rpy="0 0 0" xyz="0 1.595067118168201 0" />
     <axis xyz="1 0 0"/>
       <limit effort="0.0" lower="-3.14159" upper="3.14159" velocity="0.0"/>
    </joint>
    <joint name="Leg2_Leg3" type="revolute">
       <parent link="Leg2"/>
       <child  link="Leg3"/>
       <origin rpy="0 0 0" xyz="2.074993637860004 0 0" />
     <axis xyz="1 0 0"/>
       <limit effort="0.0" lower="-3.14159" upper="3.14159" velocity="0.0"/>
    </joint>
    <joint name="Leg3_Leg4" type="revolute">
       <parent link="Leg3"/>
       <child  link="Leg4"/>
       <origin rpy="0 0 0" xyz="0 0 1.1128444468455219" />
     <axis xyz="1 0 0"/>
       <limit effort="0.0" lower="-3.14159" upper="3.14159" velocity="0.0"/>
    </joint>
    <joint name="Leg4_Leg5" type="revolute">
       <parent link="Leg4"/>
       <child  link="Leg5"/>
       <origin rpy="0 0 0" xyz="0 0 2.8145375149752385" />
     <axis xyz="1 0 0"/>
       <limit effort="0.0" lower="-3.14159" upper="3.14159" velocity="0.0"/>
    </joint>
    <joint name="Leg4_Leg6" type="revolute">
       <parent link="Leg4"/>
       <child  link="Leg6"/>
       <origin rpy="0 0 0" xyz="0 0.6564176202607483 2.8145375149752385" />
     <axis xyz="1 0 0"/>
       <limit effort="0.0" lower="-3.14159" upper="3.14159" velocity="0.0"/>
    </joint>
    <joint name="Torso_Leg7" type="revolute">
       <parent link="Torso"/>
       <child  link="Leg7"/>
       <origin rpy="0 0 0" xyz="1.1151036756521315 0 0.5070948595111991" />
     <axis xyz="1 0 0"/>
       <limit effort="0.0" lower="-3.14159" upper="3.14159" velocity="0.0"/>
    </joint>
    <joint name="Leg1_Leg8" type="revolute">
       <parent link="Leg1"/>
       <child  link="Leg8"/>
       <origin rpy="0 0 0" xyz="0.9675004606051651 1.595067118168201 0" />
     <axis xyz="1 0 0"/>
       <limit effort="0.0" lower="-3.14159" upper="3.14159" velocity="0.0"/>
    </joint>
    <joint name="Leg5_Leg9" type="revolute">
       <parent link="Leg5"/>
       <child  link="Leg9"/>
       <origin rpy="0 0 0" xyz="0 1.231849403641644 1.2903010795925587" />
     <axis xyz="1 0 0"/>
       <limit effort="0.0" lower="-3.14159" upper="3.14159" velocity="0.0"/>
    </joint>
    <joint name="Leg6_Leg10" type="revolute">
       <parent link="Leg6"/>
       <child  link="Leg10"/>
       <origin rpy="0 0 0" xyz="1.186036842330764 1.3549352598363655 0" />
     <axis xyz="1 0 0"/>
       <limit effort="0.0" lower="-3.14159" upper="3.14159" velocity="0.0"/>
    </joint>
    <joint name="Leg9_Leg11" type="revolute">
       <parent link="Leg9"/>
       <child  link="Leg11"/>
       <origin rpy="0 0 0" xyz="0 1.7443462698548802 0" />
     <axis xyz="1 0 0"/>
       <limit effort="0.0" lower="-3.14159" upper="3.14159" velocity="0.0"/>
    </joint>
    <joint name="Leg3_Leg12" type="revolute">
       <parent link="Leg3"/>
       <child  link="Leg12"/>
       <origin rpy="0 0 0" xyz="1.2833204022469618 0 1.1128444468455219" />
     <axis xyz="1 0 0"/>
       <limit effort="0.0" lower="-3.14159" upper="3.14159" velocity="0.0"/>
    </joint>
    <joint name="Leg7_Leg13" type="revolute">
       <parent link="Leg7"/>
       <child  link="Leg13"/>
       <origin rpy="0 0 0" xyz="1.2329549499144798 1.2932949443644026 0" />
     <axis xyz="1 0 0"/>
       <limit effort="0.0" lower="-3.14159" upper="3.14159" velocity="0.0"/>
    </joint>
    <joint name="Leg11_Leg14" type="revolute">
       <parent link="Leg11"/>
       <child  link="Leg14"/>
       <origin rpy="0 0 0" xyz="0.9927703656363475 0 1.4416427726000487" />
     <axis xyz="1 0 0"/>
       <limit effort="0.0" lower="-3.14159" upper="3.14159" velocity="0.0"/>
    </joint>
    <joint name="Leg8_Leg15" type="revolute">
       <parent link="Leg8"/>
       <child  link="Leg15"/>
       <origin rpy="0 0 0" xyz="0 0 1.2993470899076596" />
     <axis xyz="1 0 0"/>
       <limit effort="0.0" lower="-3.14159" upper="3.14159" velocity="0.0"/>
    </joint>
    <joint name="Torso_Leg16" type="revolute">
       <parent link="Torso"/>
       <child  link="Leg16"/>
       <origin rpy="0 0 0" xyz="1.1151036756521315 0.6049740766101918 0.5070948595111991" />
     <axis xyz="1 0 0"/>
       <limit effort="0.0" lower="-3.14159" upper="3.14159" velocity="0.0"/>
    </joint>
    <joint name="Leg11_Leg17" type="revolute">
       <parent link="Leg11"/>
       <child  link="Leg17"/>
       <origin rpy="0 0 0" xyz="0.9927703656363475 0.9510593667808868 1.4416427726000487" />
     <axis xyz="1 0 0"/>
       <limit effort="0.0" lower="-3.14159" upper="3.14159" velocity="0.0"/>
    </joint>
    <joint name="Leg17_Leg18" type="revolute">
       <parent link="Leg17"/>
       <child  link="Leg18"/>
       <origin rpy="0 0 0" xyz="0 2.761797327224099 0" />
     <axis xyz="1 0 0"/>
       <limit effort="0.0" lower="-3.14159" upper="3.14159" velocity="0.0"/>
    </joint>
    <joint name="Leg17_Leg19" type="revolute">
       <parent link="Leg17"/>
       <child  link="Leg19"/>
       <origin rpy="0 0 0" xyz="1.3550860723671203 2.761797327224099 0" />
     <axis xyz="1 0 0"/>
       <limit effort="0.0" lower="-3.14159" upper="3.14159" velocity="0.0"/>
    </joint>
    <joint name="Leg11_Leg20" type="revolute">
       <parent link="Leg11"/>
       <child  link="Leg20"/>
       <origin rpy="0 0 0" xyz="1.985540731272695 0.9510593667808868 1.4416427726000487" />
     <axis xyz="1 0 0"/>
       <limit effort="0.0" lower="-3.14159" upper="3.14159" velocity="0.0"/>
    </joint>
    <joint name="Leg13_Leg21" type="revolute">
       <parent link="Leg13"/>
       <child  link="Leg21"/>
       <origin rpy="0 0 0" xyz="1.1260028516125367 0 0.7595953471858238" />
     <axis xyz="1 0 0"/>
       <limit effort="0.0" lower="-3.14159" upper="3.14159" velocity="0.0"/>
    </joint>
    <joint name="Leg16_Leg22" type="revolute">
       <parent link="Leg16"/>
       <child  link="Leg22"/>
       <origin rpy="0 0 0" xyz="0 1.4849424044370914 1.0789254565125619" />
     <axis xyz="1 0 0"/>
       <limit effort="0.0" lower="-3.14159" upper="3.14159" velocity="0.0"/>
    </joint>
    <joint name="Leg5_Leg23" type="revolute">
       <parent link="Leg5"/>
       <child  link="Leg23"/>
       <origin rpy="0 0 0" xyz="0 2.463698807283288 1.2903010795925587" />
     <axis xyz="1 0 0"/>
       <limit effort="0.0" lower="-3.14159" upper="3.14159" velocity="0.0"/>
    </joint>
    <joint name="Leg13_Leg24" type="revolute">
       <parent link="Leg13"/>
       <child  link="Leg24"/>
       <origin rpy="0 0 0" xyz="1.1260028516125367 0 1.5191906943716476" />
     <axis xyz="1 0 0"/>
       <limit effort="0.0" lower="-3.14159" upper="3.14159" velocity="0.0"/>
    </joint>
    <joint name="Leg14_Leg25" type="revolute">
       <parent link="Leg14"/>
       <child  link="Leg25"/>
       <origin rpy="0 0 0" xyz="0 1.0958493218578722 1.4749351494661476" />
     <axis xyz="1 0 0"/>
       <limit effort="0.0" lower="-3.14159" upper="3.14159" velocity="0.0"/>
    </joint>
</robot>