<robot name = "robot">
    <link name="Torso">
        <inertial>
            <origin xyz="-6 4 4.869162614918833" rpy="0 0 0"/>
            <mass value="1" />
            <inertia ixx="100" ixy="0" ixz="0" iyy="100" iyz="0" izz="100" />
        </inertial>
        <visual>
            <origin xyz="-6 4 4.869162614918833" rpy="0 0 0"/>
            <geometry>
                <box size="3.1767034049911973 5.206081749125547 3.690599777093589" />
            </geometry>
            <material name="Blue">
                <color rgba="0 1.0 1.0 1.0"/>
            </material>
        </visual>
        <collision>
            <origin xyz="-6 4 4.869162614918833" rpy="0 0 0"/>
            <geometry>
                <box size="3.1767034049911973 5.206081749125547 3.690599777093589" />
            </geometry>
        </collision>
    </link>
    <link name="Leg1">
        <inertial>
            <origin xyz="0 0 -1.5119313631860194" rpy="0 0 0"/>
            <mass value="1" />
            <inertia ixx="100" ixy="0" ixz="0" iyy="100" iyz="0" izz="100" />
        </inertial>
        <visual>
            <origin xyz="0 0 -1.5119313631860194" rpy="0 0 0"/>
            <geometry>
                <box size="1.2359666637384505 1.9696540158868125 3.023862726372039" />
            </geometry>
            <material name="Blue">
                <color rgba="0 1.0 1.0 1.0"/>
            </material>
        </visual>
        <collision>
            <origin xyz="0 0 -1.5119313631860194" rpy="0 0 0"/>
            <geometry>
                <box size="1.2359666637384505 1.9696540158868125 3.023862726372039" />
            </geometry>
        </collision>
    </link>
    <link name="Leg2">
        <inertial>
            <origin xyz="0 0 -1.5119313631860194" rpy="0 0 0"/>
            <mass value="1" />
            <inertia ixx="100" ixy="0" ixz="0" iyy="100" iyz="0" izz="100" />
        </inertial>
        <visual>
            <origin xyz="0 0 -1.5119313631860194" rpy="0 0 0"/>
            <geometry>
                <box size="1.2359666637384505 1.9696540158868125 3.023862726372039" />
            </geometry>
            <material name="Green">
                <color rgba="0 180.0 0.0 1.0"/>
            </material>
        </visual>
        <collision>
            <origin xyz="0 0 -1.5119313631860194" rpy="0 0 0"/>
            <geometry>
                <box size="1.2359666637384505 1.9696540158868125 3.023862726372039" />
            </geometry>
        </collision>
    </link>
    <link name="Leg3">
        <inertial>
            <origin xyz="0 0 -1.5119313631860194" rpy="0 0 0"/>
            <mass value="1" />
            <inertia ixx="100" ixy="0" ixz="0" iyy="100" iyz="0" izz="100" />
        </inertial>
        <visual>
            <origin xyz="0 0 -1.5119313631860194" rpy="0 0 0"/>
            <geometry>
                <box size="1.2359666637384505 1.9696540158868125 3.023862726372039" />
            </geometry>
            <material name="Green">
                <color rgba="0 180.0 0.0 1.0"/>
            </material>
        </visual>
        <collision>
            <origin xyz="0 0 -1.5119313631860194" rpy="0 0 0"/>
            <geometry>
                <box size="1.2359666637384505 1.9696540158868125 3.023862726372039" />
            </geometry>
        </collision>
    </link>
    <link name="Leg4">
        <inertial>
            <origin xyz="0 0 -1.5119313631860194" rpy="0 0 0"/>
            <mass value="1" />
            <inertia ixx="100" ixy="0" ixz="0" iyy="100" iyz="0" izz="100" />
        </inertial>
        <visual>
            <origin xyz="0 0 -1.5119313631860194" rpy="0 0 0"/>
            <geometry>
                <box size="1.2359666637384505 1.9696540158868125 3.023862726372039" />
            </geometry>
            <material name="Blue">
                <color rgba="0 1.0 1.0 1.0"/>
            </material>
        </visual>
        <collision>
            <origin xyz="0 0 -1.5119313631860194" rpy="0 0 0"/>
            <geometry>
                <box size="1.2359666637384505 1.9696540158868125 3.023862726372039" />
            </geometry>
        </collision>
    </link>
    <link name="Head">
        <inertial>
            <origin xyz="1.1379141423747834 0 0.9154542993190898" rpy="0 0 0"/>
            <mass value="1" />
            <inertia ixx="100" ixy="0" ixz="0" iyy="100" iyz="0" izz="100" />
        </inertial>
        <visual>
            <origin xyz="1.1379141423747834 0 0.9154542993190898" rpy="0 0 0"/>
            <geometry>
                <box size="2.2758282847495668 2.2363855058509134 1.8309085986381797" />
            </geometry>
            <material name="Green">
                <color rgba="0 180.0 0.0 1.0"/>
            </material>
        </visual>
        <collision>
            <origin xyz="1.1379141423747834 0 0.9154542993190898" rpy="0 0 0"/>
            <geometry>
                <box size="2.2758282847495668 2.2363855058509134 1.8309085986381797" />
            </geometry>
        </collision>
    </link>
    <link name="Wing0">
        <inertial>
            <origin xyz="0 2.7526696910937414 0" rpy="0 0 0"/>
            <mass value="1" />
            <inertia ixx="100" ixy="0" ixz="0" iyy="100" iyz="0" izz="100" />
        </inertial>
        <visual>
            <origin xyz="0 2.7526696910937414 0" rpy="0 0 0"/>
            <geometry>
                <box size="2.4657703115517866 5.505339382187483 0.14141815571854605" />
            </geometry>
            <material name="Green">
                <color rgba="0 180.0 0.0 1.0"/>
            </material>
        </visual>
        <collision>
            <origin xyz="0 2.7526696910937414 0" rpy="0 0 0"/>
            <geometry>
                <box size="2.4657703115517866 5.505339382187483 0.14141815571854605" />
            </geometry>
        </collision>
    </link>
    <link name="Wing1">
        <inertial>
            <origin xyz="0 -2.2720523203789815 0" rpy="0 0 0"/>
            <mass value="1" />
            <inertia ixx="100" ixy="0" ixz="0" iyy="100" iyz="0" izz="100" />
        </inertial>
        <visual>
            <origin xyz="0 -2.2720523203789815 0" rpy="0 0 0"/>
            <geometry>
                <box size="1.3514576332906891 4.544104640757963 1.8239382427265094" />
            </geometry>
            <material name="Green">
                <color rgba="0 180.0 0.0 1.0"/>
            </material>
        </visual>
        <collision>
            <origin xyz="0 -2.2720523203789815 0" rpy="0 0 0"/>
            <geometry>
                <box size="1.3514576332906891 4.544104640757963 1.8239382427265094" />
            </geometry>
        </collision>
    </link>
    <joint name="Torso_Leg1" type="revolute">
       <parent link="Torso"/>
       <child  link="Leg1"/>
       <origin rpy="0 0 0" xyz="-7.588351702495599 6.603040874562773 3.023862726372039" />
     <axis xyz="1 0 0"/>
       <limit effort="0.0" lower="-3.14159" upper="3.14159" velocity="0.0"/>
    </joint>
    <joint name="Torso_Leg2" type="revolute">
       <parent link="Torso"/>
       <child  link="Leg2"/>
       <origin rpy="0 0 0" xyz="-4.411648297504401 6.603040874562773 3.023862726372039" />
     <axis xyz="1 0 0"/>
       <limit effort="0.0" lower="-3.14159" upper="3.14159" velocity="0.0"/>
    </joint>
    <joint name="Torso_Leg3" type="revolute">
       <parent link="Torso"/>
       <child  link="Leg3"/>
       <origin rpy="0 0 0" xyz="-7.588351702495599 1.3969591254372267 3.023862726372039" />
     <axis xyz="1 0 0"/>
       <limit effort="0.0" lower="-3.14159" upper="3.14159" velocity="0.0"/>
    </joint>
    <joint name="Torso_Leg4" type="revolute">
       <parent link="Torso"/>
       <child  link="Leg4"/>
       <origin rpy="0 0 0" xyz="-4.411648297504401 1.3969591254372267 3.023862726372039" />
     <axis xyz="1 0 0"/>
       <limit effort="0.0" lower="-3.14159" upper="3.14159" velocity="0.0"/>
    </joint>
    <joint name="Torso_Head" type="revolute">
       <parent link="Torso"/>
       <child  link="Head"/>
       <origin rpy="0 0 0" xyz="-4.411648297504401 4 6.714462503465628" />
     <axis xyz="1 0 0"/>
       <limit effort="0.0" lower="-3.14159" upper="3.14159" velocity="0.0"/>
    </joint>
    <joint name="Torso_Wing0" type="revolute">
       <parent link="Torso"/>
       <child  link="Wing0"/>
       <origin rpy="0 0 0" xyz="-6 6.603040874562773 4.869162614918833" />
     <axis xyz="1 0 0"/>
       <limit effort="0.0" lower="-3.14159" upper="3.14159" velocity="0.0"/>
    </joint>
    <joint name="Torso_Wing1" type="revolute">
       <parent link="Torso"/>
       <child  link="Wing1"/>
       <origin rpy="0 0 0" xyz="-6 1.3969591254372267 4.869162614918833" />
     <axis xyz="1 0 0"/>
       <limit effort="0.0" lower="-3.14159" upper="3.14159" velocity="0.0"/>
    </joint>
</robot>