<robot name = "robot">
    <link name="Torso">
        <inertial>
            <origin xyz="0 0 1.48466706760279" rpy="0 0 0"/>
            <mass value="1" />
            <inertia ixx="100" ixy="0" ixz="0" iyy="100" iyz="0" izz="100" />
        </inertial>
        <visual>
            <origin xyz="0 0 1.48466706760279" rpy="0 0 0"/>
            <geometry>
                <box size="2.2287715460679474 1.8391858297142454 2.96933413520558" />
            </geometry>
            <material name="Green">
                <color rgba="0 180.0 0.0 1.0"/>
            </material>
        </visual>
        <collision>
            <origin xyz="0 0 1.48466706760279" rpy="0 0 0"/>
            <geometry>
                <box size="2.2287715460679474 1.8391858297142454 2.96933413520558" />
            </geometry>
        </collision>
    </link>
    <link name="Leg1">
        <inertial>
            <origin xyz="0 0 1.179034419394094" rpy="0 0 0"/>
            <mass value="1" />
            <inertia ixx="100" ixy="0" ixz="0" iyy="100" iyz="0" izz="100" />
        </inertial>
        <visual>
            <origin xyz="0 0 1.179034419394094" rpy="0 0 0"/>
            <geometry>
                <box size="2.1964359902283332 2.578103717600311 2.358068838788188" />
            </geometry>
            <material name="Blue">
                <color rgba="0 1.0 1.0 1.0"/>
            </material>
        </visual>
        <collision>
            <origin xyz="0 0 1.179034419394094" rpy="0 0 0"/>
            <geometry>
                <box size="2.1964359902283332 2.578103717600311 2.358068838788188" />
            </geometry>
        </collision>
    </link>
    <link name="Leg2">
        <inertial>
            <origin xyz="0.6760650172256523 0 0" rpy="0 0 0"/>
            <mass value="1" />
            <inertia ixx="100" ixy="0" ixz="0" iyy="100" iyz="0" izz="100" />
        </inertial>
        <visual>
            <origin xyz="0.6760650172256523 0 0" rpy="0 0 0"/>
            <geometry>
                <box size="1.3521300344513045 1.6084512334847074 1.9387805853868272" />
            </geometry>
            <material name="Blue">
                <color rgba="0 1.0 1.0 1.0"/>
            </material>
        </visual>
        <collision>
            <origin xyz="0.6760650172256523 0 0" rpy="0 0 0"/>
            <geometry>
                <box size="1.3521300344513045 1.6084512334847074 1.9387805853868272" />
            </geometry>
        </collision>
    </link>
    <link name="Leg3">
        <inertial>
            <origin xyz="0 0 0.7007742399739537" rpy="0 0 0"/>
            <mass value="1" />
            <inertia ixx="100" ixy="0" ixz="0" iyy="100" iyz="0" izz="100" />
        </inertial>
        <visual>
            <origin xyz="0 0 0.7007742399739537" rpy="0 0 0"/>
            <geometry>
                <box size="1.4281177095585944 2.824182112839164 1.4015484799479074" />
            </geometry>
            <material name="Green">
                <color rgba="0 180.0 0.0 1.0"/>
            </material>
        </visual>
        <collision>
            <origin xyz="0 0 0.7007742399739537" rpy="0 0 0"/>
            <geometry>
                <box size="1.4281177095585944 2.824182112839164 1.4015484799479074" />
            </geometry>
        </collision>
    </link>
    <link name="Leg4">
        <inertial>
            <origin xyz="0 0 1.076808824267743" rpy="0 0 0"/>
            <mass value="1" />
            <inertia ixx="100" ixy="0" ixz="0" iyy="100" iyz="0" izz="100" />
        </inertial>
        <visual>
            <origin xyz="0 0 1.076808824267743" rpy="0 0 0"/>
            <geometry>
                <box size="1.6852607794477092 1.7828452687286935 2.153617648535486" />
            </geometry>
            <material name="Blue">
                <color rgba="0 1.0 1.0 1.0"/>
            </material>
        </visual>
        <collision>
            <origin xyz="0 0 1.076808824267743" rpy="0 0 0"/>
            <geometry>
                <box size="1.6852607794477092 1.7828452687286935 2.153617648535486" />
            </geometry>
        </collision>
    </link>
    <link name="Leg5">
        <inertial>
            <origin xyz="0 0 0.6989473561382333" rpy="0 0 0"/>
            <mass value="1" />
            <inertia ixx="100" ixy="0" ixz="0" iyy="100" iyz="0" izz="100" />
        </inertial>
        <visual>
            <origin xyz="0 0 0.6989473561382333" rpy="0 0 0"/>
            <geometry>
                <box size="2.268594163443157 2.096952023490628 1.3978947122764667" />
            </geometry>
            <material name="Blue">
                <color rgba="0 1.0 1.0 1.0"/>
            </material>
        </visual>
        <collision>
            <origin xyz="0 0 0.6989473561382333" rpy="0 0 0"/>
            <geometry>
                <box size="2.268594163443157 2.096952023490628 1.3978947122764667" />
            </geometry>
        </collision>
    </link>
    <link name="Leg6">
        <inertial>
            <origin xyz="0 0 0.5775149535831163" rpy="0 0 0"/>
            <mass value="1" />
            <inertia ixx="100" ixy="0" ixz="0" iyy="100" iyz="0" izz="100" />
        </inertial>
        <visual>
            <origin xyz="0 0 0.5775149535831163" rpy="0 0 0"/>
            <geometry>
                <box size="1.748548904083618 1.4523974221848028 1.1550299071662327" />
            </geometry>
            <material name="Blue">
                <color rgba="0 1.0 1.0 1.0"/>
            </material>
        </visual>
        <collision>
            <origin xyz="0 0 0.5775149535831163" rpy="0 0 0"/>
            <geometry>
                <box size="1.748548904083618 1.4523974221848028 1.1550299071662327" />
            </geometry>
        </collision>
    </link>
    <link name="Leg7">
        <inertial>
            <origin xyz="0 1.09824515716471 0" rpy="0 0 0"/>
            <mass value="1" />
            <inertia ixx="100" ixy="0" ixz="0" iyy="100" iyz="0" izz="100" />
        </inertial>
        <visual>
            <origin xyz="0 1.09824515716471 0" rpy="0 0 0"/>
            <geometry>
                <box size="2.677436211401181 2.19649031432942 2.2227663663928157" />
            </geometry>
            <material name="Green">
                <color rgba="0 180.0 0.0 1.0"/>
            </material>
        </visual>
        <collision>
            <origin xyz="0 1.09824515716471 0" rpy="0 0 0"/>
            <geometry>
                <box size="2.677436211401181 2.19649031432942 2.2227663663928157" />
            </geometry>
        </collision>
    </link>
    <link name="Leg8">
        <inertial>
            <origin xyz="1.4596382964574164 0 0" rpy="0 0 0"/>
            <mass value="1" />
            <inertia ixx="100" ixy="0" ixz="0" iyy="100" iyz="0" izz="100" />
        </inertial>
        <visual>
            <origin xyz="1.4596382964574164 0 0" rpy="0 0 0"/>
            <geometry>
                <box size="2.9192765929148328 2.88438804659446 2.20833808919536" />
            </geometry>
            <material name="Blue">
                <color rgba="0 1.0 1.0 1.0"/>
            </material>
        </visual>
        <collision>
            <origin xyz="1.4596382964574164 0 0" rpy="0 0 0"/>
            <geometry>
                <box size="2.9192765929148328 2.88438804659446 2.20833808919536" />
            </geometry>
        </collision>
    </link>
    <link name="Leg9">
        <inertial>
            <origin xyz="0 0 0.7941093972962413" rpy="0 0 0"/>
            <mass value="1" />
            <inertia ixx="100" ixy="0" ixz="0" iyy="100" iyz="0" izz="100" />
        </inertial>
        <visual>
            <origin xyz="0 0 0.7941093972962413" rpy="0 0 0"/>
            <geometry>
                <box size="2.6939007325417337 2.3164587357858264 1.5882187945924826" />
            </geometry>
            <material name="Blue">
                <color rgba="0 1.0 1.0 1.0"/>
            </material>
        </visual>
        <collision>
            <origin xyz="0 0 0.7941093972962413" rpy="0 0 0"/>
            <geometry>
                <box size="2.6939007325417337 2.3164587357858264 1.5882187945924826" />
            </geometry>
        </collision>
    </link>
    <link name="Leg10">
        <inertial>
            <origin xyz="0 1.4895184810318933 0" rpy="0 0 0"/>
            <mass value="1" />
            <inertia ixx="100" ixy="0" ixz="0" iyy="100" iyz="0" izz="100" />
        </inertial>
        <visual>
            <origin xyz="0 1.4895184810318933 0" rpy="0 0 0"/>
            <geometry>
                <box size="2.971562286410052 2.9790369620637867 2.307999138552475" />
            </geometry>
            <material name="Green">
                <color rgba="0 180.0 0.0 1.0"/>
            </material>
        </visual>
        <collision>
            <origin xyz="0 1.4895184810318933 0" rpy="0 0 0"/>
            <geometry>
                <box size="2.971562286410052 2.9790369620637867 2.307999138552475" />
            </geometry>
        </collision>
    </link>
    <link name="Leg11">
        <inertial>
            <origin xyz="1.0577003042804112 0 0" rpy="0 0 0"/>
            <mass value="1" />
            <inertia ixx="100" ixy="0" ixz="0" iyy="100" iyz="0" izz="100" />
        </inertial>
        <visual>
            <origin xyz="1.0577003042804112 0 0" rpy="0 0 0"/>
            <geometry>
                <box size="2.1154006085608223 2.0918623216377994 2.057090826839241" />
            </geometry>
            <material name="Green">
                <color rgba="0 180.0 0.0 1.0"/>
            </material>
        </visual>
        <collision>
            <origin xyz="1.0577003042804112 0 0" rpy="0 0 0"/>
            <geometry>
                <box size="2.1154006085608223 2.0918623216377994 2.057090826839241" />
            </geometry>
        </collision>
    </link>
    <link name="Leg12">
        <inertial>
            <origin xyz="0.91558907420951 0 0" rpy="0 0 0"/>
            <mass value="1" />
            <inertia ixx="100" ixy="0" ixz="0" iyy="100" iyz="0" izz="100" />
        </inertial>
        <visual>
            <origin xyz="0.91558907420951 0 0" rpy="0 0 0"/>
            <geometry>
                <box size="1.83117814841902 1.1754084178433046 1.7665542520107986" />
            </geometry>
            <material name="Blue">
                <color rgba="0 1.0 1.0 1.0"/>
            </material>
        </visual>
        <collision>
            <origin xyz="0.91558907420951 0 0" rpy="0 0 0"/>
            <geometry>
                <box size="1.83117814841902 1.1754084178433046 1.7665542520107986" />
            </geometry>
        </collision>
    </link>
    <link name="Leg13">
        <inertial>
            <origin xyz="0 0.8001535736129515 0" rpy="0 0 0"/>
            <mass value="1" />
            <inertia ixx="100" ixy="0" ixz="0" iyy="100" iyz="0" izz="100" />
        </inertial>
        <visual>
            <origin xyz="0 0.8001535736129515 0" rpy="0 0 0"/>
            <geometry>
                <box size="1.0739439498656946 1.600307147225903 2.2119793833093504" />
            </geometry>
            <material name="Green">
                <color rgba="0 180.0 0.0 1.0"/>
            </material>
        </visual>
        <collision>
            <origin xyz="0 0.8001535736129515 0" rpy="0 0 0"/>
            <geometry>
                <box size="1.0739439498656946 1.600307147225903 2.2119793833093504" />
            </geometry>
        </collision>
    </link>
    <link name="Leg14">
        <inertial>
            <origin xyz="0 1.1187854554096444 0" rpy="0 0 0"/>
            <mass value="1" />
            <inertia ixx="100" ixy="0" ixz="0" iyy="100" iyz="0" izz="100" />
        </inertial>
        <visual>
            <origin xyz="0 1.1187854554096444 0" rpy="0 0 0"/>
            <geometry>
                <box size="1.8043245628374296 2.2375709108192887 2.683634965395214" />
            </geometry>
            <material name="Blue">
                <color rgba="0 1.0 1.0 1.0"/>
            </material>
        </visual>
        <collision>
            <origin xyz="0 1.1187854554096444 0" rpy="0 0 0"/>
            <geometry>
                <box size="1.8043245628374296 2.2375709108192887 2.683634965395214" />
            </geometry>
        </collision>
    </link>
    <link name="Leg15">
        <inertial>
            <origin xyz="0 0 0.8727798930631003" rpy="0 0 0"/>
            <mass value="1" />
            <inertia ixx="100" ixy="0" ixz="0" iyy="100" iyz="0" izz="100" />
        </inertial>
        <visual>
            <origin xyz="0 0 0.8727798930631003" rpy="0 0 0"/>
            <geometry>
                <box size="1.737609029324032 1.8564745334362223 1.7455597861262007" />
            </geometry>
            <material name="Blue">
                <color rgba="0 1.0 1.0 1.0"/>
            </material>
        </visual>
        <collision>
            <origin xyz="0 0 0.8727798930631003" rpy="0 0 0"/>
            <geometry>
                <box size="1.737609029324032 1.8564745334362223 1.7455597861262007" />
            </geometry>
        </collision>
    </link>
    <link name="Leg16">
        <inertial>
            <origin xyz="0 0.5041852566154585 0" rpy="0 0 0"/>
            <mass value="1" />
            <inertia ixx="100" ixy="0" ixz="0" iyy="100" iyz="0" izz="100" />
        </inertial>
        <visual>
            <origin xyz="0 0.5041852566154585 0" rpy="0 0 0"/>
            <geometry>
                <box size="2.4662472015356993 1.008370513230917 1.3198638134636025" />
            </geometry>
            <material name="Green">
                <color rgba="0 180.0 0.0 1.0"/>
            </material>
        </visual>
        <collision>
            <origin xyz="0 0.5041852566154585 0" rpy="0 0 0"/>
            <geometry>
                <box size="2.4662472015356993 1.008370513230917 1.3198638134636025" />
            </geometry>
        </collision>
    </link>
    <link name="Leg17">
        <inertial>
            <origin xyz="0 0 1.1576682338492899" rpy="0 0 0"/>
            <mass value="1" />
            <inertia ixx="100" ixy="0" ixz="0" iyy="100" iyz="0" izz="100" />
        </inertial>
        <visual>
            <origin xyz="0 0 1.1576682338492899" rpy="0 0 0"/>
            <geometry>
                <box size="2.5349414910668933 1.9625557733128352 2.3153364676985797" />
            </geometry>
            <material name="Green">
                <color rgba="0 180.0 0.0 1.0"/>
            </material>
        </visual>
        <collision>
            <origin xyz="0 0 1.1576682338492899" rpy="0 0 0"/>
            <geometry>
                <box size="2.5349414910668933 1.9625557733128352 2.3153364676985797" />
            </geometry>
        </collision>
    </link>
    <link name="Leg18">
        <inertial>
            <origin xyz="0 1.072190824790438 0" rpy="0 0 0"/>
            <mass value="1" />
            <inertia ixx="100" ixy="0" ixz="0" iyy="100" iyz="0" izz="100" />
        </inertial>
        <visual>
            <origin xyz="0 1.072190824790438 0" rpy="0 0 0"/>
            <geometry>
                <box size="1.0297449628113318 2.144381649580876 2.1116069212302175" />
            </geometry>
            <material name="Green">
                <color rgba="0 180.0 0.0 1.0"/>
            </material>
        </visual>
        <collision>
            <origin xyz="0 1.072190824790438 0" rpy="0 0 0"/>
            <geometry>
                <box size="1.0297449628113318 2.144381649580876 2.1116069212302175" />
            </geometry>
        </collision>
    </link>
    <link name="Leg19">
        <inertial>
            <origin xyz="0 1.3602779020137332 0" rpy="0 0 0"/>
            <mass value="1" />
            <inertia ixx="100" ixy="0" ixz="0" iyy="100" iyz="0" izz="100" />
        </inertial>
        <visual>
            <origin xyz="0 1.3602779020137332 0" rpy="0 0 0"/>
            <geometry>
                <box size="2.905166162402535 2.7205558040274664 1.4517309261160516" />
            </geometry>
            <material name="Green">
                <color rgba="0 180.0 0.0 1.0"/>
            </material>
        </visual>
        <collision>
            <origin xyz="0 1.3602779020137332 0" rpy="0 0 0"/>
            <geometry>
                <box size="2.905166162402535 2.7205558040274664 1.4517309261160516" />
            </geometry>
        </collision>
    </link>
    <link name="Leg20">
        <inertial>
            <origin xyz="0 0 0.9096815920518738" rpy="0 0 0"/>
            <mass value="1" />
            <inertia ixx="100" ixy="0" ixz="0" iyy="100" iyz="0" izz="100" />
        </inertial>
        <visual>
            <origin xyz="0 0 0.9096815920518738" rpy="0 0 0"/>
            <geometry>
                <box size="2.618163304651969 1.1100711241943884 1.8193631841037476" />
            </geometry>
            <material name="Green">
                <color rgba="0 180.0 0.0 1.0"/>
            </material>
        </visual>
        <collision>
            <origin xyz="0 0 0.9096815920518738" rpy="0 0 0"/>
            <geometry>
                <box size="2.618163304651969 1.1100711241943884 1.8193631841037476" />
            </geometry>
        </collision>
    </link>
    <link name="Leg21">
        <inertial>
            <origin xyz="0 1.3676346403463426 0" rpy="0 0 0"/>
            <mass value="1" />
            <inertia ixx="100" ixy="0" ixz="0" iyy="100" iyz="0" izz="100" />
        </inertial>
        <visual>
            <origin xyz="0 1.3676346403463426 0" rpy="0 0 0"/>
            <geometry>
                <box size="1.1359755380722159 2.7352692806926853 1.935024264037194" />
            </geometry>
            <material name="Blue">
                <color rgba="0 1.0 1.0 1.0"/>
            </material>
        </visual>
        <collision>
            <origin xyz="0 1.3676346403463426 0" rpy="0 0 0"/>
            <geometry>
                <box size="1.1359755380722159 2.7352692806926853 1.935024264037194" />
            </geometry>
        </collision>
    </link>
    <link name="Leg22">
        <inertial>
            <origin xyz="1.116006402385863 0 0" rpy="0 0 0"/>
            <mass value="1" />
            <inertia ixx="100" ixy="0" ixz="0" iyy="100" iyz="0" izz="100" />
        </inertial>
        <visual>
            <origin xyz="1.116006402385863 0 0" rpy="0 0 0"/>
            <geometry>
                <box size="2.232012804771726 1.1479802300005715 1.3727919380545575" />
            </geometry>
            <material name="Green">
                <color rgba="0 180.0 0.0 1.0"/>
            </material>
        </visual>
        <collision>
            <origin xyz="1.116006402385863 0 0" rpy="0 0 0"/>
            <geometry>
                <box size="2.232012804771726 1.1479802300005715 1.3727919380545575" />
            </geometry>
        </collision>
    </link>
    <link name="Leg23">
        <inertial>
            <origin xyz="0.508645909786488 0 0" rpy="0 0 0"/>
            <mass value="1" />
            <inertia ixx="100" ixy="0" ixz="0" iyy="100" iyz="0" izz="100" />
        </inertial>
        <visual>
            <origin xyz="0.508645909786488 0 0" rpy="0 0 0"/>
            <geometry>
                <box size="1.017291819572976 2.109703655653848 2.695804863687355" />
            </geometry>
            <material name="Green">
                <color rgba="0 180.0 0.0 1.0"/>
            </material>
        </visual>
        <collision>
            <origin xyz="0.508645909786488 0 0" rpy="0 0 0"/>
            <geometry>
                <box size="1.017291819572976 2.109703655653848 2.695804863687355" />
            </geometry>
        </collision>
    </link>
    <link name="Leg24">
        <inertial>
            <origin xyz="0 0.7026425446660157 0" rpy="0 0 0"/>
            <mass value="1" />
            <inertia ixx="100" ixy="0" ixz="0" iyy="100" iyz="0" izz="100" />
        </inertial>
        <visual>
            <origin xyz="0 0.7026425446660157 0" rpy="0 0 0"/>
            <geometry>
                <box size="1.9673489380798488 1.4052850893320314 2.21402291993017" />
            </geometry>
            <material name="Green">
                <color rgba="0 180.0 0.0 1.0"/>
            </material>
        </visual>
        <collision>
            <origin xyz="0 0.7026425446660157 0" rpy="0 0 0"/>
            <geometry>
                <box size="1.9673489380798488 1.4052850893320314 2.21402291993017" />
            </geometry>
        </collision>
    </link>
    <link name="Leg25">
        <inertial>
            <origin xyz="0 0 1.4622115794667165" rpy="0 0 0"/>
            <mass value="1" />
            <inertia ixx="100" ixy="0" ixz="0" iyy="100" iyz="0" izz="100" />
        </inertial>
        <visual>
            <origin xyz="0 0 1.4622115794667165" rpy="0 0 0"/>
            <geometry>
                <box size="2.3698573681331885 2.6285336716886727 2.924423158933433" />
            </geometry>
            <material name="Blue">
                <color rgba="0 1.0 1.0 1.0"/>
            </material>
        </visual>
        <collision>
            <origin xyz="0 0 1.4622115794667165" rpy="0 0 0"/>
            <geometry>
                <box size="2.3698573681331885 2.6285336716886727 2.924423158933433" />
            </geometry>
        </collision>
    </link>
    <link name="Leg26">
        <inertial>
            <origin xyz="0 0 0.702743199602069" rpy="0 0 0"/>
            <mass value="1" />
            <inertia ixx="100" ixy="0" ixz="0" iyy="100" iyz="0" izz="100" />
        </inertial>
        <visual>
            <origin xyz="0 0 0.702743199602069" rpy="0 0 0"/>
            <geometry>
                <box size="2.8726394388856322 2.372587460927336 1.405486399204138" />
            </geometry>
            <material name="Green">
                <color rgba="0 180.0 0.0 1.0"/>
            </material>
        </visual>
        <collision>
            <origin xyz="0 0 0.702743199602069" rpy="0 0 0"/>
            <geometry>
                <box size="2.8726394388856322 2.372587460927336 1.405486399204138" />
            </geometry>
        </collision>
    </link>
    <link name="Leg27">
        <inertial>
            <origin xyz="0 0 0.5514175608808489" rpy="0 0 0"/>
            <mass value="1" />
            <inertia ixx="100" ixy="0" ixz="0" iyy="100" iyz="0" izz="100" />
        </inertial>
        <visual>
            <origin xyz="0 0 0.5514175608808489" rpy="0 0 0"/>
            <geometry>
                <box size="1.3800092717757384 1.974894804788357 1.1028351217616978" />
            </geometry>
            <material name="Green">
                <color rgba="0 180.0 0.0 1.0"/>
            </material>
        </visual>
        <collision>
            <origin xyz="0 0 0.5514175608808489" rpy="0 0 0"/>
            <geometry>
                <box size="1.3800092717757384 1.974894804788357 1.1028351217616978" />
            </geometry>
        </collision>
    </link>
    <joint name="Torso_Leg1" type="revolute">
       <parent link="Torso"/>
       <child  link="Leg1"/>
       <origin rpy="0 0 0" xyz="0 0 2.96933413520558" />
     <axis xyz="1 0 0"/>
       <limit effort="0.0" lower="-3.14159" upper="3.14159" velocity="0.0"/>
    </joint>
    <joint name="Leg1_Leg2" type="revolute">
       <parent link="Leg1"/>
       <child  link="Leg2"/>
       <origin rpy="0 0 0" xyz="1.3521300344513045 0 0" />
     <axis xyz="1 0 0"/>
       <limit effort="0.0" lower="-3.14159" upper="3.14159" velocity="0.0"/>
    </joint>
    <joint name="Leg1_Leg3" type="revolute">
       <parent link="Leg1"/>
       <child  link="Leg3"/>
       <origin rpy="0 0 0" xyz="1.3521300344513045 0 0.9693902926934136" />
     <axis xyz="1 0 0"/>
       <limit effort="0.0" lower="-3.14159" upper="3.14159" velocity="0.0"/>
    </joint>
    <joint name="Leg2_Leg4" type="revolute">
       <parent link="Leg2"/>
       <child  link="Leg4"/>
       <origin rpy="0 0 0" xyz="0 0 1.4015484799479074" />
     <axis xyz="1 0 0"/>
       <limit effort="0.0" lower="-3.14159" upper="3.14159" velocity="0.0"/>
    </joint>
    <joint name="Leg4_Leg5" type="revolute">
       <parent link="Leg4"/>
       <child  link="Leg5"/>
       <origin rpy="0 0 0" xyz="0 0 1.3978947122764667" />
     <axis xyz="1 0 0"/>
       <limit effort="0.0" lower="-3.14159" upper="3.14159" velocity="0.0"/>
    </joint>
    <joint name="Leg3_Leg6" type="revolute">
       <parent link="Leg3"/>
       <child  link="Leg6"/>
       <origin rpy="0 0 0" xyz="0 0 2.153617648535486" />
     <axis xyz="1 0 0"/>
       <limit effort="0.0" lower="-3.14159" upper="3.14159" velocity="0.0"/>
    </joint>
    <joint name="Leg1_Leg7" type="revolute">
       <parent link="Leg1"/>
       <child  link="Leg7"/>
       <origin rpy="0 0 0" xyz="1.3521300344513045 0.8042256167423537 0.9693902926934136" />
     <axis xyz="1 0 0"/>
       <limit effort="0.0" lower="-3.14159" upper="3.14159" velocity="0.0"/>
    </joint>
    <joint name="Torso_Leg8" type="revolute">
       <parent link="Torso"/>
       <child  link="Leg8"/>
       <origin rpy="0 0 0" xyz="1.0982179951141666 0 1.179034419394094" />
     <axis xyz="1 0 0"/>
       <limit effort="0.0" lower="-3.14159" upper="3.14159" velocity="0.0"/>
    </joint>
    <joint name="Leg5_Leg9" type="revolute">
       <parent link="Leg5"/>
       <child  link="Leg9"/>
       <origin rpy="0 0 0" xyz="0 0 1.1550299071662327" />
     <axis xyz="1 0 0"/>
       <limit effort="0.0" lower="-3.14159" upper="3.14159" velocity="0.0"/>
    </joint>
    <joint name="Leg5_Leg10" type="revolute">
       <parent link="Leg5"/>
       <child  link="Leg10"/>
       <origin rpy="0 0 0" xyz="0 0.7261987110924014 1.1550299071662327" />
     <axis xyz="1 0 0"/>
       <limit effort="0.0" lower="-3.14159" upper="3.14159" velocity="0.0"/>
    </joint>
    <joint name="Leg6_Leg11" type="revolute">
       <parent link="Leg6"/>
       <child  link="Leg11"/>
       <origin rpy="0 0 0" xyz="1.3387181057005906 1.09824515716471 0" />
     <axis xyz="1 0 0"/>
       <limit effort="0.0" lower="-3.14159" upper="3.14159" velocity="0.0"/>
    </joint>
    <joint name="Leg8_Leg12" type="revolute">
       <parent link="Leg8"/>
       <child  link="Leg12"/>
       <origin rpy="0 0 0" xyz="1.3469503662708668 0 0.7941093972962413" />
     <axis xyz="1 0 0"/>
       <limit effort="0.0" lower="-3.14159" upper="3.14159" velocity="0.0"/>
    </joint>
    <joint name="Leg8_Leg13" type="revolute">
       <parent link="Leg8"/>
       <child  link="Leg13"/>
       <origin rpy="0 0 0" xyz="1.3469503662708668 1.1582293678929132 0.7941093972962413" />
     <axis xyz="1 0 0"/>
       <limit effort="0.0" lower="-3.14159" upper="3.14159" velocity="0.0"/>
    </joint>
    <joint name="Leg6_Leg14" type="revolute">
       <parent link="Leg6"/>
       <child  link="Leg14"/>
       <origin rpy="0 0 0" xyz="1.3387181057005906 2.19649031432942 0" />
     <axis xyz="1 0 0"/>
       <limit effort="0.0" lower="-3.14159" upper="3.14159" velocity="0.0"/>
    </joint>
    <joint name="Leg7_Leg15" type="revolute">
       <parent link="Leg7"/>
       <child  link="Leg15"/>
       <origin rpy="0 0 0" xyz="1.4596382964574164 0 1.10416904459768" />
     <axis xyz="1 0 0"/>
       <limit effort="0.0" lower="-3.14159" upper="3.14159" velocity="0.0"/>
    </joint>
    <joint name="Leg2_Leg16" type="revolute">
       <parent link="Leg2"/>
       <child  link="Leg16"/>
       <origin rpy="0 0 0" xyz="0 1.412091056419582 1.4015484799479074" />
     <axis xyz="1 0 0"/>
       <limit effort="0.0" lower="-3.14159" upper="3.14159" velocity="0.0"/>
    </joint>
    <joint name="Leg12_Leg17" type="revolute">
       <parent link="Leg12"/>
       <child  link="Leg17"/>
       <origin rpy="0 0 0" xyz="0 0.8001535736129515 1.1059896916546752" />
     <axis xyz="1 0 0"/>
       <limit effort="0.0" lower="-3.14159" upper="3.14159" velocity="0.0"/>
    </joint>
    <joint name="Leg13_Leg18" type="revolute">
       <parent link="Leg13"/>
       <child  link="Leg18"/>
       <origin rpy="0 0 0" xyz="0 2.2375709108192887 0" />
     <axis xyz="1 0 0"/>
       <limit effort="0.0" lower="-3.14159" upper="3.14159" velocity="0.0"/>
    </joint>
    <joint name="Leg16_Leg19" type="revolute">
       <parent link="Leg16"/>
       <child  link="Leg19"/>
       <origin rpy="0 0 0" xyz="0 0.9812778866564176 1.1576682338492899" />
     <axis xyz="1 0 0"/>
       <limit effort="0.0" lower="-3.14159" upper="3.14159" velocity="0.0"/>
    </joint>
    <joint name="Leg17_Leg20" type="revolute">
       <parent link="Leg17"/>
       <child  link="Leg20"/>
       <origin rpy="0 0 0" xyz="0 1.072190824790438 1.0558034606151088" />
     <axis xyz="1 0 0"/>
       <limit effort="0.0" lower="-3.14159" upper="3.14159" velocity="0.0"/>
    </joint>
    <joint name="Leg17_Leg21" type="revolute">
       <parent link="Leg17"/>
       <child  link="Leg21"/>
       <origin rpy="0 0 0" xyz="0 2.144381649580876 1.0558034606151088" />
     <axis xyz="1 0 0"/>
       <limit effort="0.0" lower="-3.14159" upper="3.14159" velocity="0.0"/>
    </joint>
    <joint name="Leg12_Leg22" type="revolute">
       <parent link="Leg12"/>
       <child  link="Leg22"/>
       <origin rpy="0 0 0" xyz="0.5369719749328473 0.8001535736129515 1.1059896916546752" />
     <axis xyz="1 0 0"/>
       <limit effort="0.0" lower="-3.14159" upper="3.14159" velocity="0.0"/>
    </joint>
    <joint name="Leg4_Leg23" type="revolute">
       <parent link="Leg4"/>
       <child  link="Leg23"/>
       <origin rpy="0 0 0" xyz="1.1342970817215785 0 1.3978947122764667" />
     <axis xyz="1 0 0"/>
       <limit effort="0.0" lower="-3.14159" upper="3.14159" velocity="0.0"/>
    </joint>
    <joint name="Leg7_Leg24" type="revolute">
       <parent link="Leg7"/>
       <child  link="Leg24"/>
       <origin rpy="0 0 0" xyz="1.4596382964574164 1.44219402329723 1.10416904459768" />
     <axis xyz="1 0 0"/>
       <limit effort="0.0" lower="-3.14159" upper="3.14159" velocity="0.0"/>
    </joint>
    <joint name="Leg10_Leg25" type="revolute">
       <parent link="Leg10"/>
       <child  link="Leg25"/>
       <origin rpy="0 0 0" xyz="1.0577003042804112 0 1.0285454134196206" />
     <axis xyz="1 0 0"/>
       <limit effort="0.0" lower="-3.14159" upper="3.14159" velocity="0.0"/>
    </joint>
    <joint name="Leg18_Leg26" type="revolute">
       <parent link="Leg18"/>
       <child  link="Leg26"/>
       <origin rpy="0 0 0" xyz="0 1.3602779020137332 0.7258654630580258" />
     <axis xyz="1 0 0"/>
       <limit effort="0.0" lower="-3.14159" upper="3.14159" velocity="0.0"/>
    </joint>
    <joint name="Leg21_Leg27" type="revolute">
       <parent link="Leg21"/>
       <child  link="Leg27"/>
       <origin rpy="0 0 0" xyz="1.116006402385863 0 0.6863959690272787" />
     <axis xyz="1 0 0"/>
       <limit effort="0.0" lower="-3.14159" upper="3.14159" velocity="0.0"/>
    </joint>
</robot>