<robot name = "robot">
    <link name="Torso">
        <inertial>
            <origin xyz="0 0 0.7081735328160802" rpy="0 0 0"/>
            <mass value="1" />
            <inertia ixx="100" ixy="0" ixz="0" iyy="100" iyz="0" izz="100" />
        </inertial>
        <visual>
            <origin xyz="0 0 0.7081735328160802" rpy="0 0 0"/>
            <geometry>
                <box size="2.190843742439676 1.376498164363276 1.4163470656321604" />
            </geometry>
            <material name="Green">
                <color rgba="0 180.0 0.0 1.0"/>
            </material>
        </visual>
        <collision>
            <origin xyz="0 0 0.7081735328160802" rpy="0 0 0"/>
            <geometry>
                <box size="2.190843742439676 1.376498164363276 1.4163470656321604" />
            </geometry>
        </collision>
    </link>
    <link name="Leg1">
        <inertial>
            <origin xyz="0 0.6488572428012429 0" rpy="0 0 0"/>
            <mass value="1" />
            <inertia ixx="100" ixy="0" ixz="0" iyy="100" iyz="0" izz="100" />
        </inertial>
        <visual>
            <origin xyz="0 0.6488572428012429 0" rpy="0 0 0"/>
            <geometry>
                <box size="2.3146353732877314 1.2977144856024858 2.7171535436547263" />
            </geometry>
            <material name="Green">
                <color rgba="0 180.0 0.0 1.0"/>
            </material>
        </visual>
        <collision>
            <origin xyz="0 0.6488572428012429 0" rpy="0 0 0"/>
            <geometry>
                <box size="2.3146353732877314 1.2977144856024858 2.7171535436547263" />
            </geometry>
        </collision>
    </link>
    <link name="Leg2">
        <inertial>
            <origin xyz="0 0 1.4243909968489057" rpy="0 0 0"/>
            <mass value="1" />
            <inertia ixx="100" ixy="0" ixz="0" iyy="100" iyz="0" izz="100" />
        </inertial>
        <visual>
            <origin xyz="0 0 1.4243909968489057" rpy="0 0 0"/>
            <geometry>
                <box size="1.1427671710788336 1.6467176562028043 2.8487819936978114" />
            </geometry>
            <material name="Green">
                <color rgba="0 180.0 0.0 1.0"/>
            </material>
        </visual>
        <collision>
            <origin xyz="0 0 1.4243909968489057" rpy="0 0 0"/>
            <geometry>
                <box size="1.1427671710788336 1.6467176562028043 2.8487819936978114" />
            </geometry>
        </collision>
    </link>
    <link name="Leg3">
        <inertial>
            <origin xyz="0 0 1.0506645085943576" rpy="0 0 0"/>
            <mass value="1" />
            <inertia ixx="100" ixy="0" ixz="0" iyy="100" iyz="0" izz="100" />
        </inertial>
        <visual>
            <origin xyz="0 0 1.0506645085943576" rpy="0 0 0"/>
            <geometry>
                <box size="2.697201440602697 2.7126303434329473 2.101329017188715" />
            </geometry>
            <material name="Blue">
                <color rgba="0 1.0 1.0 1.0"/>
            </material>
        </visual>
        <collision>
            <origin xyz="0 0 1.0506645085943576" rpy="0 0 0"/>
            <geometry>
                <box size="2.697201440602697 2.7126303434329473 2.101329017188715" />
            </geometry>
        </collision>
    </link>
    <link name="Leg4">
        <inertial>
            <origin xyz="0 0.9831051361505786 0" rpy="0 0 0"/>
            <mass value="1" />
            <inertia ixx="100" ixy="0" ixz="0" iyy="100" iyz="0" izz="100" />
        </inertial>
        <visual>
            <origin xyz="0 0.9831051361505786 0" rpy="0 0 0"/>
            <geometry>
                <box size="2.3203540686192508 1.9662102723011572 1.9192995404245963" />
            </geometry>
            <material name="Blue">
                <color rgba="0 1.0 1.0 1.0"/>
            </material>
        </visual>
        <collision>
            <origin xyz="0 0.9831051361505786 0" rpy="0 0 0"/>
            <geometry>
                <box size="2.3203540686192508 1.9662102723011572 1.9192995404245963" />
            </geometry>
        </collision>
    </link>
    <link name="Leg5">
        <inertial>
            <origin xyz="0 0 1.1996362540273182" rpy="0 0 0"/>
            <mass value="1" />
            <inertia ixx="100" ixy="0" ixz="0" iyy="100" iyz="0" izz="100" />
        </inertial>
        <visual>
            <origin xyz="0 0 1.1996362540273182" rpy="0 0 0"/>
            <geometry>
                <box size="1.7343391623123197 1.9128562369601483 2.3992725080546364" />
            </geometry>
            <material name="Green">
                <color rgba="0 180.0 0.0 1.0"/>
            </material>
        </visual>
        <collision>
            <origin xyz="0 0 1.1996362540273182" rpy="0 0 0"/>
            <geometry>
                <box size="1.7343391623123197 1.9128562369601483 2.3992725080546364" />
            </geometry>
        </collision>
    </link>
    <link name="Leg6">
        <inertial>
            <origin xyz="1.2948251079239839 0 0" rpy="0 0 0"/>
            <mass value="1" />
            <inertia ixx="100" ixy="0" ixz="0" iyy="100" iyz="0" izz="100" />
        </inertial>
        <visual>
            <origin xyz="1.2948251079239839 0 0" rpy="0 0 0"/>
            <geometry>
                <box size="2.5896502158479677 2.3761035025891477 1.9817562231632884" />
            </geometry>
            <material name="Green">
                <color rgba="0 180.0 0.0 1.0"/>
            </material>
        </visual>
        <collision>
            <origin xyz="1.2948251079239839 0 0" rpy="0 0 0"/>
            <geometry>
                <box size="2.5896502158479677 2.3761035025891477 1.9817562231632884" />
            </geometry>
        </collision>
    </link>
    <link name="Leg7">
        <inertial>
            <origin xyz="0 0.6907771202512502 0" rpy="0 0 0"/>
            <mass value="1" />
            <inertia ixx="100" ixy="0" ixz="0" iyy="100" iyz="0" izz="100" />
        </inertial>
        <visual>
            <origin xyz="0 0.6907771202512502 0" rpy="0 0 0"/>
            <geometry>
                <box size="1.7432783728644778 1.3815542405025003 1.0706784590539953" />
            </geometry>
            <material name="Green">
                <color rgba="0 180.0 0.0 1.0"/>
            </material>
        </visual>
        <collision>
            <origin xyz="0 0.6907771202512502 0" rpy="0 0 0"/>
            <geometry>
                <box size="1.7432783728644778 1.3815542405025003 1.0706784590539953" />
            </geometry>
        </collision>
    </link>
    <link name="Leg8">
        <inertial>
            <origin xyz="0 0 1.060603964136733" rpy="0 0 0"/>
            <mass value="1" />
            <inertia ixx="100" ixy="0" ixz="0" iyy="100" iyz="0" izz="100" />
        </inertial>
        <visual>
            <origin xyz="0 0 1.060603964136733" rpy="0 0 0"/>
            <geometry>
                <box size="2.8166509725244326 2.473287234839741 2.121207928273466" />
            </geometry>
            <material name="Green">
                <color rgba="0 180.0 0.0 1.0"/>
            </material>
        </visual>
        <collision>
            <origin xyz="0 0 1.060603964136733" rpy="0 0 0"/>
            <geometry>
                <box size="2.8166509725244326 2.473287234839741 2.121207928273466" />
            </geometry>
        </collision>
    </link>
    <link name="Leg9">
        <inertial>
            <origin xyz="1.1523072765827664 0 0" rpy="0 0 0"/>
            <mass value="1" />
            <inertia ixx="100" ixy="0" ixz="0" iyy="100" iyz="0" izz="100" />
        </inertial>
        <visual>
            <origin xyz="1.1523072765827664 0 0" rpy="0 0 0"/>
            <geometry>
                <box size="2.304614553165533 2.866426325769824 2.0248810895059397" />
            </geometry>
            <material name="Green">
                <color rgba="0 180.0 0.0 1.0"/>
            </material>
        </visual>
        <collision>
            <origin xyz="1.1523072765827664 0 0" rpy="0 0 0"/>
            <geometry>
                <box size="2.304614553165533 2.866426325769824 2.0248810895059397" />
            </geometry>
        </collision>
    </link>
    <link name="Leg10">
        <inertial>
            <origin xyz="0 0 1.3875324801450353" rpy="0 0 0"/>
            <mass value="1" />
            <inertia ixx="100" ixy="0" ixz="0" iyy="100" iyz="0" izz="100" />
        </inertial>
        <visual>
            <origin xyz="0 0 1.3875324801450353" rpy="0 0 0"/>
            <geometry>
                <box size="2.5747795447706467 2.53867538330345 2.7750649602900705" />
            </geometry>
            <material name="Green">
                <color rgba="0 180.0 0.0 1.0"/>
            </material>
        </visual>
        <collision>
            <origin xyz="0 0 1.3875324801450353" rpy="0 0 0"/>
            <geometry>
                <box size="2.5747795447706467 2.53867538330345 2.7750649602900705" />
            </geometry>
        </collision>
    </link>
    <link name="Leg11">
        <inertial>
            <origin xyz="1.4163562570489003 0 0" rpy="0 0 0"/>
            <mass value="1" />
            <inertia ixx="100" ixy="0" ixz="0" iyy="100" iyz="0" izz="100" />
        </inertial>
        <visual>
            <origin xyz="1.4163562570489003 0 0" rpy="0 0 0"/>
            <geometry>
                <box size="2.8327125140978007 1.397148793616196 1.2663931102203785" />
            </geometry>
            <material name="Green">
                <color rgba="0 180.0 0.0 1.0"/>
            </material>
        </visual>
        <collision>
            <origin xyz="1.4163562570489003 0 0" rpy="0 0 0"/>
            <geometry>
                <box size="2.8327125140978007 1.397148793616196 1.2663931102203785" />
            </geometry>
        </collision>
    </link>
    <link name="Leg12">
        <inertial>
            <origin xyz="0 0 1.3651896590012786" rpy="0 0 0"/>
            <mass value="1" />
            <inertia ixx="100" ixy="0" ixz="0" iyy="100" iyz="0" izz="100" />
        </inertial>
        <visual>
            <origin xyz="0 0 1.3651896590012786" rpy="0 0 0"/>
            <geometry>
                <box size="2.1168365491942085 2.178975221474335 2.7303793180025573" />
            </geometry>
            <material name="Green">
                <color rgba="0 180.0 0.0 1.0"/>
            </material>
        </visual>
        <collision>
            <origin xyz="0 0 1.3651896590012786" rpy="0 0 0"/>
            <geometry>
                <box size="2.1168365491942085 2.178975221474335 2.7303793180025573" />
            </geometry>
        </collision>
    </link>
    <link name="Leg13">
        <inertial>
            <origin xyz="0 0 0.8299800001582361" rpy="0 0 0"/>
            <mass value="1" />
            <inertia ixx="100" ixy="0" ixz="0" iyy="100" iyz="0" izz="100" />
        </inertial>
        <visual>
            <origin xyz="0 0 0.8299800001582361" rpy="0 0 0"/>
            <geometry>
                <box size="2.4061859418026197 1.8453222656729835 1.6599600003164723" />
            </geometry>
            <material name="Green">
                <color rgba="0 180.0 0.0 1.0"/>
            </material>
        </visual>
        <collision>
            <origin xyz="0 0 0.8299800001582361" rpy="0 0 0"/>
            <geometry>
                <box size="2.4061859418026197 1.8453222656729835 1.6599600003164723" />
            </geometry>
        </collision>
    </link>
    <link name="Leg14">
        <inertial>
            <origin xyz="1.0401031010738455 0 0" rpy="0 0 0"/>
            <mass value="1" />
            <inertia ixx="100" ixy="0" ixz="0" iyy="100" iyz="0" izz="100" />
        </inertial>
        <visual>
            <origin xyz="1.0401031010738455 0 0" rpy="0 0 0"/>
            <geometry>
                <box size="2.080206202147691 2.383172910512884 1.9213383315953922" />
            </geometry>
            <material name="Blue">
                <color rgba="0 1.0 1.0 1.0"/>
            </material>
        </visual>
        <collision>
            <origin xyz="1.0401031010738455 0 0" rpy="0 0 0"/>
            <geometry>
                <box size="2.080206202147691 2.383172910512884 1.9213383315953922" />
            </geometry>
        </collision>
    </link>
    <link name="Leg15">
        <inertial>
            <origin xyz="0.8539432895441493 0 0" rpy="0 0 0"/>
            <mass value="1" />
            <inertia ixx="100" ixy="0" ixz="0" iyy="100" iyz="0" izz="100" />
        </inertial>
        <visual>
            <origin xyz="0.8539432895441493 0 0" rpy="0 0 0"/>
            <geometry>
                <box size="1.7078865790882987 1.075676563347539 2.6355414665987533" />
            </geometry>
            <material name="Green">
                <color rgba="0 180.0 0.0 1.0"/>
            </material>
        </visual>
        <collision>
            <origin xyz="0.8539432895441493 0 0" rpy="0 0 0"/>
            <geometry>
                <box size="1.7078865790882987 1.075676563347539 2.6355414665987533" />
            </geometry>
        </collision>
    </link>
    <link name="Leg16">
        <inertial>
            <origin xyz="1.1713667858535501 0 0" rpy="0 0 0"/>
            <mass value="1" />
            <inertia ixx="100" ixy="0" ixz="0" iyy="100" iyz="0" izz="100" />
        </inertial>
        <visual>
            <origin xyz="1.1713667858535501 0 0" rpy="0 0 0"/>
            <geometry>
                <box size="2.3427335717071003 2.723176174587503 2.3125178586024" />
            </geometry>
            <material name="Blue">
                <color rgba="0 1.0 1.0 1.0"/>
            </material>
        </visual>
        <collision>
            <origin xyz="1.1713667858535501 0 0" rpy="0 0 0"/>
            <geometry>
                <box size="2.3427335717071003 2.723176174587503 2.3125178586024" />
            </geometry>
        </collision>
    </link>
    <link name="Leg17">
        <inertial>
            <origin xyz="0 0.872544099856381 0" rpy="0 0 0"/>
            <mass value="1" />
            <inertia ixx="100" ixy="0" ixz="0" iyy="100" iyz="0" izz="100" />
        </inertial>
        <visual>
            <origin xyz="0 0.872544099856381 0" rpy="0 0 0"/>
            <geometry>
                <box size="1.8161738713379325 1.745088199712762 1.4461764294568247" />
            </geometry>
            <material name="Blue">
                <color rgba="0 1.0 1.0 1.0"/>
            </material>
        </visual>
        <collision>
            <origin xyz="0 0.872544099856381 0" rpy="0 0 0"/>
            <geometry>
                <box size="1.8161738713379325 1.745088199712762 1.4461764294568247" />
            </geometry>
        </collision>
    </link>
    <link name="Leg18">
        <inertial>
            <origin xyz="0 0 0.6365239284756674" rpy="0 0 0"/>
            <mass value="1" />
            <inertia ixx="100" ixy="0" ixz="0" iyy="100" iyz="0" izz="100" />
        </inertial>
        <visual>
            <origin xyz="0 0 0.6365239284756674" rpy="0 0 0"/>
            <geometry>
                <box size="2.5208936365909618 2.5560923252937595 1.2730478569513348" />
            </geometry>
            <material name="Green">
                <color rgba="0 180.0 0.0 1.0"/>
            </material>
        </visual>
        <collision>
            <origin xyz="0 0 0.6365239284756674" rpy="0 0 0"/>
            <geometry>
                <box size="2.5208936365909618 2.5560923252937595 1.2730478569513348" />
            </geometry>
        </collision>
    </link>
    <link name="Leg19">
        <inertial>
            <origin xyz="0 0.5066406750382357 0" rpy="0 0 0"/>
            <mass value="1" />
            <inertia ixx="100" ixy="0" ixz="0" iyy="100" iyz="0" izz="100" />
        </inertial>
        <visual>
            <origin xyz="0 0.5066406750382357 0" rpy="0 0 0"/>
            <geometry>
                <box size="1.9078612095746 1.0132813500764715 1.4656754438222526" />
            </geometry>
            <material name="Green">
                <color rgba="0 180.0 0.0 1.0"/>
            </material>
        </visual>
        <collision>
            <origin xyz="0 0.5066406750382357 0" rpy="0 0 0"/>
            <geometry>
                <box size="1.9078612095746 1.0132813500764715 1.4656754438222526" />
            </geometry>
        </collision>
    </link>
    <link name="Leg20">
        <inertial>
            <origin xyz="0 1.456410846859481 0" rpy="0 0 0"/>
            <mass value="1" />
            <inertia ixx="100" ixy="0" ixz="0" iyy="100" iyz="0" izz="100" />
        </inertial>
        <visual>
            <origin xyz="0 1.456410846859481 0" rpy="0 0 0"/>
            <geometry>
                <box size="1.44340897664638 2.912821693718962 1.0557486482367735" />
            </geometry>
            <material name="Blue">
                <color rgba="0 1.0 1.0 1.0"/>
            </material>
        </visual>
        <collision>
            <origin xyz="0 1.456410846859481 0" rpy="0 0 0"/>
            <geometry>
                <box size="1.44340897664638 2.912821693718962 1.0557486482367735" />
            </geometry>
        </collision>
    </link>
    <link name="Leg21">
        <inertial>
            <origin xyz="0 0.7830497887588697 0" rpy="0 0 0"/>
            <mass value="1" />
            <inertia ixx="100" ixy="0" ixz="0" iyy="100" iyz="0" izz="100" />
        </inertial>
        <visual>
            <origin xyz="0 0.7830497887588697 0" rpy="0 0 0"/>
            <geometry>
                <box size="2.319643776495904 1.5660995775177393 2.0710702498956963" />
            </geometry>
            <material name="Blue">
                <color rgba="0 1.0 1.0 1.0"/>
            </material>
        </visual>
        <collision>
            <origin xyz="0 0.7830497887588697 0" rpy="0 0 0"/>
            <geometry>
                <box size="2.319643776495904 1.5660995775177393 2.0710702498956963" />
            </geometry>
        </collision>
    </link>
    <link name="Leg22">
        <inertial>
            <origin xyz="0 0.8430513661931385 0" rpy="0 0 0"/>
            <mass value="1" />
            <inertia ixx="100" ixy="0" ixz="0" iyy="100" iyz="0" izz="100" />
        </inertial>
        <visual>
            <origin xyz="0 0.8430513661931385 0" rpy="0 0 0"/>
            <geometry>
                <box size="2.3023187648314227 1.686102732386277 1.7322850748635399" />
            </geometry>
            <material name="Green">
                <color rgba="0 180.0 0.0 1.0"/>
            </material>
        </visual>
        <collision>
            <origin xyz="0 0.8430513661931385 0" rpy="0 0 0"/>
            <geometry>
                <box size="2.3023187648314227 1.686102732386277 1.7322850748635399" />
            </geometry>
        </collision>
    </link>
    <link name="Leg23">
        <inertial>
            <origin xyz="1.2327701115050638 0 0" rpy="0 0 0"/>
            <mass value="1" />
            <inertia ixx="100" ixy="0" ixz="0" iyy="100" iyz="0" izz="100" />
        </inertial>
        <visual>
            <origin xyz="1.2327701115050638 0 0" rpy="0 0 0"/>
            <geometry>
                <box size="2.4655402230101275 1.239766281766765 2.8516418165457607" />
            </geometry>
            <material name="Blue">
                <color rgba="0 1.0 1.0 1.0"/>
            </material>
        </visual>
        <collision>
            <origin xyz="1.2327701115050638 0 0" rpy="0 0 0"/>
            <geometry>
                <box size="2.4655402230101275 1.239766281766765 2.8516418165457607" />
            </geometry>
        </collision>
    </link>
    <link name="Leg24">
        <inertial>
            <origin xyz="0.6607217570781887 0 0" rpy="0 0 0"/>
            <mass value="1" />
            <inertia ixx="100" ixy="0" ixz="0" iyy="100" iyz="0" izz="100" />
        </inertial>
        <visual>
            <origin xyz="0.6607217570781887 0 0" rpy="0 0 0"/>
            <geometry>
                <box size="1.3214435141563774 1.359845469976262 2.7928270132493984" />
            </geometry>
            <material name="Blue">
                <color rgba="0 1.0 1.0 1.0"/>
            </material>
        </visual>
        <collision>
            <origin xyz="0.6607217570781887 0 0" rpy="0 0 0"/>
            <geometry>
                <box size="1.3214435141563774 1.359845469976262 2.7928270132493984" />
            </geometry>
        </collision>
    </link>
    <link name="Leg25">
        <inertial>
            <origin xyz="1.4219236475431996 0 0" rpy="0 0 0"/>
            <mass value="1" />
            <inertia ixx="100" ixy="0" ixz="0" iyy="100" iyz="0" izz="100" />
        </inertial>
        <visual>
            <origin xyz="1.4219236475431996 0 0" rpy="0 0 0"/>
            <geometry>
                <box size="2.843847295086399 1.217948315342985 2.261391096490324" />
            </geometry>
            <material name="Green">
                <color rgba="0 180.0 0.0 1.0"/>
            </material>
        </visual>
        <collision>
            <origin xyz="1.4219236475431996 0 0" rpy="0 0 0"/>
            <geometry>
                <box size="2.843847295086399 1.217948315342985 2.261391096490324" />
            </geometry>
        </collision>
    </link>
    <link name="Leg26">
        <inertial>
            <origin xyz="0 0 1.0786024912798957" rpy="0 0 0"/>
            <mass value="1" />
            <inertia ixx="100" ixy="0" ixz="0" iyy="100" iyz="0" izz="100" />
        </inertial>
        <visual>
            <origin xyz="0 0 1.0786024912798957" rpy="0 0 0"/>
            <geometry>
                <box size="1.0815729822646825 1.6305787776625287 2.1572049825597914" />
            </geometry>
            <material name="Blue">
                <color rgba="0 1.0 1.0 1.0"/>
            </material>
        </visual>
        <collision>
            <origin xyz="0 0 1.0786024912798957" rpy="0 0 0"/>
            <geometry>
                <box size="1.0815729822646825 1.6305787776625287 2.1572049825597914" />
            </geometry>
        </collision>
    </link>
    <link name="Leg27">
        <inertial>
            <origin xyz="0.8332631409137585 0 0" rpy="0 0 0"/>
            <mass value="1" />
            <inertia ixx="100" ixy="0" ixz="0" iyy="100" iyz="0" izz="100" />
        </inertial>
        <visual>
            <origin xyz="0.8332631409137585 0 0" rpy="0 0 0"/>
            <geometry>
                <box size="1.666526281827517 2.7461495493560113 1.0760084336966853" />
            </geometry>
            <material name="Green">
                <color rgba="0 180.0 0.0 1.0"/>
            </material>
        </visual>
        <collision>
            <origin xyz="0.8332631409137585 0 0" rpy="0 0 0"/>
            <geometry>
                <box size="1.666526281827517 2.7461495493560113 1.0760084336966853" />
            </geometry>
        </collision>
    </link>
    <joint name="Torso_Leg1" type="revolute">
       <parent link="Torso"/>
       <child  link="Leg1"/>
       <origin rpy="0 0 0" xyz="0 0.688249082181638 0.7081735328160802" />
     <axis xyz="1 0 0"/>
       <limit effort="0.0" lower="-3.14159" upper="3.14159" velocity="0.0"/>
    </joint>
    <joint name="Torso_Leg2" type="revolute">
       <parent link="Torso"/>
       <child  link="Leg2"/>
       <origin rpy="0 0 0" xyz="0 0.6488572428012429 1.3585767718273631" />
     <axis xyz="1 0 0"/>
       <limit effort="0.0" lower="-3.14159" upper="3.14159" velocity="0.0"/>
    </joint>
    <joint name="Leg1_Leg3" type="revolute">
       <parent link="Leg1"/>
       <child  link="Leg3"/>
       <origin rpy="0 0 0" xyz="0 0 2.8487819936978114" />
     <axis xyz="1 0 0"/>
       <limit effort="0.0" lower="-3.14159" upper="3.14159" velocity="0.0"/>
    </joint>
    <joint name="Leg2_Leg4" type="revolute">
       <parent link="Leg2"/>
       <child  link="Leg4"/>
       <origin rpy="0 0 0" xyz="0 1.3563151717164736 1.0506645085943576" />
     <axis xyz="1 0 0"/>
       <limit effort="0.0" lower="-3.14159" upper="3.14159" velocity="0.0"/>
    </joint>
    <joint name="Leg4_Leg5" type="revolute">
       <parent link="Leg4"/>
       <child  link="Leg5"/>
       <origin rpy="0 0 0" xyz="0 0 2.3992725080546364" />
     <axis xyz="1 0 0"/>
       <limit effort="0.0" lower="-3.14159" upper="3.14159" velocity="0.0"/>
    </joint>
    <joint name="Torso_Leg6" type="revolute">
       <parent link="Torso"/>
       <child  link="Leg6"/>
       <origin rpy="0 0 0" xyz="1.1573176866438657 0.6488572428012429 1.3585767718273631" />
     <axis xyz="1 0 0"/>
       <limit effort="0.0" lower="-3.14159" upper="3.14159" velocity="0.0"/>
    </joint>
    <joint name="Leg5_Leg7" type="revolute">
       <parent link="Leg5"/>
       <child  link="Leg7"/>
       <origin rpy="0 0 0" xyz="1.2948251079239839 1.1880517512945739 0" />
     <axis xyz="1 0 0"/>
       <limit effort="0.0" lower="-3.14159" upper="3.14159" velocity="0.0"/>
    </joint>
    <joint name="Leg2_Leg8" type="revolute">
       <parent link="Leg2"/>
       <child  link="Leg8"/>
       <origin rpy="0 0 0" xyz="0 1.3563151717164736 2.101329017188715" />
     <axis xyz="1 0 0"/>
       <limit effort="0.0" lower="-3.14159" upper="3.14159" velocity="0.0"/>
    </joint>
    <joint name="Leg6_Leg9" type="revolute">
       <parent link="Leg6"/>
       <child  link="Leg9"/>
       <origin rpy="0 0 0" xyz="0.8716391864322389 0.6907771202512502 0" />
     <axis xyz="1 0 0"/>
       <limit effort="0.0" lower="-3.14159" upper="3.14159" velocity="0.0"/>
    </joint>
    <joint name="Leg6_Leg10" type="revolute">
       <parent link="Leg6"/>
       <child  link="Leg10"/>
       <origin rpy="0 0 0" xyz="0.8716391864322389 0.6907771202512502 0.5353392295269976" />
     <axis xyz="1 0 0"/>
       <limit effort="0.0" lower="-3.14159" upper="3.14159" velocity="0.0"/>
    </joint>
    <joint name="Leg10_Leg11" type="revolute">
       <parent link="Leg10"/>
       <child  link="Leg11"/>
       <origin rpy="0 0 0" xyz="2.8327125140978007 0 0" />
     <axis xyz="1 0 0"/>
       <limit effort="0.0" lower="-3.14159" upper="3.14159" velocity="0.0"/>
    </joint>
    <joint name="Leg5_Leg12" type="revolute">
       <parent link="Leg5"/>
       <child  link="Leg12"/>
       <origin rpy="0 0 0" xyz="1.2948251079239839 1.1880517512945739 0.9908781115816442" />
     <axis xyz="1 0 0"/>
       <limit effort="0.0" lower="-3.14159" upper="3.14159" velocity="0.0"/>
    </joint>
    <joint name="Leg12_Leg13" type="revolute">
       <parent link="Leg12"/>
       <child  link="Leg13"/>
       <origin rpy="0 0 0" xyz="0 0 1.6599600003164723" />
     <axis xyz="1 0 0"/>
       <limit effort="0.0" lower="-3.14159" upper="3.14159" velocity="0.0"/>
    </joint>
    <joint name="Leg1_Leg14" type="revolute">
       <parent link="Leg1"/>
       <child  link="Leg14"/>
       <origin rpy="0 0 0" xyz="0.5713835855394168 0 2.8487819936978114" />
     <axis xyz="1 0 0"/>
       <limit effort="0.0" lower="-3.14159" upper="3.14159" velocity="0.0"/>
    </joint>
    <joint name="Leg4_Leg15" type="revolute">
       <parent link="Leg4"/>
       <child  link="Leg15"/>
       <origin rpy="0 0 0" xyz="0.8671695811561598 0 2.3992725080546364" />
     <axis xyz="1 0 0"/>
       <limit effort="0.0" lower="-3.14159" upper="3.14159" velocity="0.0"/>
    </joint>
    <joint name="Leg13_Leg16" type="revolute">
       <parent link="Leg13"/>
       <child  link="Leg16"/>
       <origin rpy="0 0 0" xyz="2.080206202147691 0 0" />
     <axis xyz="1 0 0"/>
       <limit effort="0.0" lower="-3.14159" upper="3.14159" velocity="0.0"/>
    </joint>
    <joint name="Leg1_Leg17" type="revolute">
       <parent link="Leg1"/>
       <child  link="Leg17"/>
       <origin rpy="0 0 0" xyz="0.5713835855394168 0.8233588281014022 2.8487819936978114" />
     <axis xyz="1 0 0"/>
       <limit effort="0.0" lower="-3.14159" upper="3.14159" velocity="0.0"/>
    </joint>
    <joint name="Leg7_Leg18" type="revolute">
       <parent link="Leg7"/>
       <child  link="Leg18"/>
       <origin rpy="0 0 0" xyz="0 0 2.121207928273466" />
     <axis xyz="1 0 0"/>
       <limit effort="0.0" lower="-3.14159" upper="3.14159" velocity="0.0"/>
    </joint>
    <joint name="Leg15_Leg19" type="revolute">
       <parent link="Leg15"/>
       <child  link="Leg19"/>
       <origin rpy="0 0 0" xyz="1.1713667858535501 1.3615880872937516 0" />
     <axis xyz="1 0 0"/>
       <limit effort="0.0" lower="-3.14159" upper="3.14159" velocity="0.0"/>
    </joint>
    <joint name="Leg9_Leg20" type="revolute">
       <parent link="Leg9"/>
       <child  link="Leg20"/>
       <origin rpy="0 0 0" xyz="0 1.269337691651725 1.3875324801450353" />
     <axis xyz="1 0 0"/>
       <limit effort="0.0" lower="-3.14159" upper="3.14159" velocity="0.0"/>
    </joint>
    <joint name="Leg8_Leg21" type="revolute">
       <parent link="Leg8"/>
       <child  link="Leg21"/>
       <origin rpy="0 0 0" xyz="1.1523072765827664 1.433213162884912 0" />
     <axis xyz="1 0 0"/>
       <limit effort="0.0" lower="-3.14159" upper="3.14159" velocity="0.0"/>
    </joint>
    <joint name="Leg17_Leg22" type="revolute">
       <parent link="Leg17"/>
       <child  link="Leg22"/>
       <origin rpy="0 0 0" xyz="0 1.2780461626468798 0.6365239284756674" />
     <axis xyz="1 0 0"/>
       <limit effort="0.0" lower="-3.14159" upper="3.14159" velocity="0.0"/>
    </joint>
    <joint name="Leg3_Leg23" type="revolute">
       <parent link="Leg3"/>
       <child  link="Leg23"/>
       <origin rpy="0 0 0" xyz="1.1601770343096254 0.9831051361505786 0" />
     <axis xyz="1 0 0"/>
       <limit effort="0.0" lower="-3.14159" upper="3.14159" velocity="0.0"/>
    </joint>
    <joint name="Leg15_Leg24" type="revolute">
       <parent link="Leg15"/>
       <child  link="Leg24"/>
       <origin rpy="0 0 0" xyz="2.3427335717071003 1.3615880872937516 0" />
     <axis xyz="1 0 0"/>
       <limit effort="0.0" lower="-3.14159" upper="3.14159" velocity="0.0"/>
    </joint>
    <joint name="Leg7_Leg25" type="revolute">
       <parent link="Leg7"/>
       <child  link="Leg25"/>
       <origin rpy="0 0 0" xyz="1.4083254862622163 0 2.121207928273466" />
     <axis xyz="1 0 0"/>
       <limit effort="0.0" lower="-3.14159" upper="3.14159" velocity="0.0"/>
    </joint>
    <joint name="Leg9_Leg26" type="revolute">
       <parent link="Leg9"/>
       <child  link="Leg26"/>
       <origin rpy="0 0 0" xyz="0 1.269337691651725 2.7750649602900705" />
     <axis xyz="1 0 0"/>
       <limit effort="0.0" lower="-3.14159" upper="3.14159" velocity="0.0"/>
    </joint>
    <joint name="Leg14_Leg27" type="revolute">
       <parent link="Leg14"/>
       <child  link="Leg27"/>
       <origin rpy="0 0 0" xyz="1.7078865790882987 0 0" />
     <axis xyz="1 0 0"/>
       <limit effort="0.0" lower="-3.14159" upper="3.14159" velocity="0.0"/>
    </joint>
</robot>