<robot name = "robot">
    <link name="Torso">
        <inertial>
            <origin xyz="0 0 0.712882137924653" rpy="0 0 0"/>
            <mass value="1" />
            <inertia ixx="100" ixy="0" ixz="0" iyy="100" iyz="0" izz="100" />
        </inertial>
        <visual>
            <origin xyz="0 0 0.712882137924653" rpy="0 0 0"/>
            <geometry>
                <box size="1.0973788622229719 1.631789851651361 1.425764275849306" />
            </geometry>
            <material name="Green">
                <color rgba="0 180.0 0.0 1.0"/>
            </material>
        </visual>
        <collision>
            <origin xyz="0 0 0.712882137924653" rpy="0 0 0"/>
            <geometry>
                <box size="1.0973788622229719 1.631789851651361 1.425764275849306" />
            </geometry>
        </collision>
    </link>
    <link name="Leg1">
        <inertial>
            <origin xyz="0 0 0.8291408056915206" rpy="0 0 0"/>
            <mass value="1" />
            <inertia ixx="100" ixy="0" ixz="0" iyy="100" iyz="0" izz="100" />
        </inertial>
        <visual>
            <origin xyz="0 0 0.8291408056915206" rpy="0 0 0"/>
            <geometry>
                <box size="1.9142241184736286 2.9824743481057623 1.6582816113830412" />
            </geometry>
            <material name="Green">
                <color rgba="0 180.0 0.0 1.0"/>
            </material>
        </visual>
        <collision>
            <origin xyz="0 0 0.8291408056915206" rpy="0 0 0"/>
            <geometry>
                <box size="1.9142241184736286 2.9824743481057623 1.6582816113830412" />
            </geometry>
        </collision>
    </link>
    <link name="Leg2">
        <inertial>
            <origin xyz="0.9527341923200766 0 0" rpy="0 0 0"/>
            <mass value="1" />
            <inertia ixx="100" ixy="0" ixz="0" iyy="100" iyz="0" izz="100" />
        </inertial>
        <visual>
            <origin xyz="0.9527341923200766 0 0" rpy="0 0 0"/>
            <geometry>
                <box size="1.9054683846401532 2.346787400622711 1.7454912314834614" />
            </geometry>
            <material name="Blue">
                <color rgba="0 1.0 1.0 1.0"/>
            </material>
        </visual>
        <collision>
            <origin xyz="0.9527341923200766 0 0" rpy="0 0 0"/>
            <geometry>
                <box size="1.9054683846401532 2.346787400622711 1.7454912314834614" />
            </geometry>
        </collision>
    </link>
    <link name="Leg3">
        <inertial>
            <origin xyz="0 1.4700847444577794 0" rpy="0 0 0"/>
            <mass value="1" />
            <inertia ixx="100" ixy="0" ixz="0" iyy="100" iyz="0" izz="100" />
        </inertial>
        <visual>
            <origin xyz="0 1.4700847444577794 0" rpy="0 0 0"/>
            <geometry>
                <box size="2.431934034796561 2.9401694889155587 1.8225693855895901" />
            </geometry>
            <material name="Blue">
                <color rgba="0 1.0 1.0 1.0"/>
            </material>
        </visual>
        <collision>
            <origin xyz="0 1.4700847444577794 0" rpy="0 0 0"/>
            <geometry>
                <box size="2.431934034796561 2.9401694889155587 1.8225693855895901" />
            </geometry>
        </collision>
    </link>
    <link name="Leg4">
        <inertial>
            <origin xyz="0 0 0.6231332558812795" rpy="0 0 0"/>
            <mass value="1" />
            <inertia ixx="100" ixy="0" ixz="0" iyy="100" iyz="0" izz="100" />
        </inertial>
        <visual>
            <origin xyz="0 0 0.6231332558812795" rpy="0 0 0"/>
            <geometry>
                <box size="1.028580063903568 1.9823433327998352 1.246266511762559" />
            </geometry>
            <material name="Blue">
                <color rgba="0 1.0 1.0 1.0"/>
            </material>
        </visual>
        <collision>
            <origin xyz="0 0 0.6231332558812795" rpy="0 0 0"/>
            <geometry>
                <box size="1.028580063903568 1.9823433327998352 1.246266511762559" />
            </geometry>
        </collision>
    </link>
    <link name="Leg5">
        <inertial>
            <origin xyz="0 0 0.9011757319165358" rpy="0 0 0"/>
            <mass value="1" />
            <inertia ixx="100" ixy="0" ixz="0" iyy="100" iyz="0" izz="100" />
        </inertial>
        <visual>
            <origin xyz="0 0 0.9011757319165358" rpy="0 0 0"/>
            <geometry>
                <box size="2.6116056686504305 1.1373783041774193 1.8023514638330715" />
            </geometry>
            <material name="Blue">
                <color rgba="0 1.0 1.0 1.0"/>
            </material>
        </visual>
        <collision>
            <origin xyz="0 0 0.9011757319165358" rpy="0 0 0"/>
            <geometry>
                <box size="2.6116056686504305 1.1373783041774193 1.8023514638330715" />
            </geometry>
        </collision>
    </link>
    <link name="Leg6">
        <inertial>
            <origin xyz="0 0 0.8766791829366609" rpy="0 0 0"/>
            <mass value="1" />
            <inertia ixx="100" ixy="0" ixz="0" iyy="100" iyz="0" izz="100" />
        </inertial>
        <visual>
            <origin xyz="0 0 0.8766791829366609" rpy="0 0 0"/>
            <geometry>
                <box size="2.2937463033533225 2.746212552189095 1.7533583658733218" />
            </geometry>
            <material name="Green">
                <color rgba="0 180.0 0.0 1.0"/>
            </material>
        </visual>
        <collision>
            <origin xyz="0 0 0.8766791829366609" rpy="0 0 0"/>
            <geometry>
                <box size="2.2937463033533225 2.746212552189095 1.7533583658733218" />
            </geometry>
        </collision>
    </link>
    <link name="Leg7">
        <inertial>
            <origin xyz="0 1.1929740242522522 0" rpy="0 0 0"/>
            <mass value="1" />
            <inertia ixx="100" ixy="0" ixz="0" iyy="100" iyz="0" izz="100" />
        </inertial>
        <visual>
            <origin xyz="0 1.1929740242522522 0" rpy="0 0 0"/>
            <geometry>
                <box size="2.5344784669084355 2.3859480485045044 2.616044887489296" />
            </geometry>
            <material name="Blue">
                <color rgba="0 1.0 1.0 1.0"/>
            </material>
        </visual>
        <collision>
            <origin xyz="0 1.1929740242522522 0" rpy="0 0 0"/>
            <geometry>
                <box size="2.5344784669084355 2.3859480485045044 2.616044887489296" />
            </geometry>
        </collision>
    </link>
    <link name="Leg8">
        <inertial>
            <origin xyz="1.1895984585163595 0 0" rpy="0 0 0"/>
            <mass value="1" />
            <inertia ixx="100" ixy="0" ixz="0" iyy="100" iyz="0" izz="100" />
        </inertial>
        <visual>
            <origin xyz="1.1895984585163595 0 0" rpy="0 0 0"/>
            <geometry>
                <box size="2.379196917032719 1.6481389837305676 1.27086936687123" />
            </geometry>
            <material name="Blue">
                <color rgba="0 1.0 1.0 1.0"/>
            </material>
        </visual>
        <collision>
            <origin xyz="1.1895984585163595 0 0" rpy="0 0 0"/>
            <geometry>
                <box size="2.379196917032719 1.6481389837305676 1.27086936687123" />
            </geometry>
        </collision>
    </link>
    <link name="Leg9">
        <inertial>
            <origin xyz="0 0.7852413487114156 0" rpy="0 0 0"/>
            <mass value="1" />
            <inertia ixx="100" ixy="0" ixz="0" iyy="100" iyz="0" izz="100" />
        </inertial>
        <visual>
            <origin xyz="0 0.7852413487114156 0" rpy="0 0 0"/>
            <geometry>
                <box size="1.422848220749447 1.5704826974228312 2.2562878732947302" />
            </geometry>
            <material name="Green">
                <color rgba="0 180.0 0.0 1.0"/>
            </material>
        </visual>
        <collision>
            <origin xyz="0 0.7852413487114156 0" rpy="0 0 0"/>
            <geometry>
                <box size="1.422848220749447 1.5704826974228312 2.2562878732947302" />
            </geometry>
        </collision>
    </link>
    <link name="Leg10">
        <inertial>
            <origin xyz="0 0.9709433309416923 0" rpy="0 0 0"/>
            <mass value="1" />
            <inertia ixx="100" ixy="0" ixz="0" iyy="100" iyz="0" izz="100" />
        </inertial>
        <visual>
            <origin xyz="0 0.9709433309416923 0" rpy="0 0 0"/>
            <geometry>
                <box size="2.614271745686796 1.9418866618833845 2.781575562270871" />
            </geometry>
            <material name="Blue">
                <color rgba="0 1.0 1.0 1.0"/>
            </material>
        </visual>
        <collision>
            <origin xyz="0 0.9709433309416923 0" rpy="0 0 0"/>
            <geometry>
                <box size="2.614271745686796 1.9418866618833845 2.781575562270871" />
            </geometry>
        </collision>
    </link>
    <link name="Leg11">
        <inertial>
            <origin xyz="0 0.9178004506442528 0" rpy="0 0 0"/>
            <mass value="1" />
            <inertia ixx="100" ixy="0" ixz="0" iyy="100" iyz="0" izz="100" />
        </inertial>
        <visual>
            <origin xyz="0 0.9178004506442528 0" rpy="0 0 0"/>
            <geometry>
                <box size="2.224604062159707 1.8356009012885055 1.2650625141726146" />
            </geometry>
            <material name="Blue">
                <color rgba="0 1.0 1.0 1.0"/>
            </material>
        </visual>
        <collision>
            <origin xyz="0 0.9178004506442528 0" rpy="0 0 0"/>
            <geometry>
                <box size="2.224604062159707 1.8356009012885055 1.2650625141726146" />
            </geometry>
        </collision>
    </link>
    <link name="Leg12">
        <inertial>
            <origin xyz="1.4202433793436882 0 0" rpy="0 0 0"/>
            <mass value="1" />
            <inertia ixx="100" ixy="0" ixz="0" iyy="100" iyz="0" izz="100" />
        </inertial>
        <visual>
            <origin xyz="1.4202433793436882 0 0" rpy="0 0 0"/>
            <geometry>
                <box size="2.8404867586873763 1.2266610093687245 1.707794161124148" />
            </geometry>
            <material name="Green">
                <color rgba="0 180.0 0.0 1.0"/>
            </material>
        </visual>
        <collision>
            <origin xyz="1.4202433793436882 0 0" rpy="0 0 0"/>
            <geometry>
                <box size="2.8404867586873763 1.2266610093687245 1.707794161124148" />
            </geometry>
        </collision>
    </link>
    <link name="Leg13">
        <inertial>
            <origin xyz="0 0 1.329965834927978" rpy="0 0 0"/>
            <mass value="1" />
            <inertia ixx="100" ixy="0" ixz="0" iyy="100" iyz="0" izz="100" />
        </inertial>
        <visual>
            <origin xyz="0 0 1.329965834927978" rpy="0 0 0"/>
            <geometry>
                <box size="1.1109737292381774 2.1239767892216834 2.659931669855956" />
            </geometry>
            <material name="Green">
                <color rgba="0 180.0 0.0 1.0"/>
            </material>
        </visual>
        <collision>
            <origin xyz="0 0 1.329965834927978" rpy="0 0 0"/>
            <geometry>
                <box size="1.1109737292381774 2.1239767892216834 2.659931669855956" />
            </geometry>
        </collision>
    </link>
    <link name="Leg14">
        <inertial>
            <origin xyz="0 0 1.3752393440901292" rpy="0 0 0"/>
            <mass value="1" />
            <inertia ixx="100" ixy="0" ixz="0" iyy="100" iyz="0" izz="100" />
        </inertial>
        <visual>
            <origin xyz="0 0 1.3752393440901292" rpy="0 0 0"/>
            <geometry>
                <box size="2.0006466174533015 1.3442091257681814 2.7504786881802583" />
            </geometry>
            <material name="Green">
                <color rgba="0 180.0 0.0 1.0"/>
            </material>
        </visual>
        <collision>
            <origin xyz="0 0 1.3752393440901292" rpy="0 0 0"/>
            <geometry>
                <box size="2.0006466174533015 1.3442091257681814 2.7504786881802583" />
            </geometry>
        </collision>
    </link>
    <link name="Leg15">
        <inertial>
            <origin xyz="0 0 1.482988562972314" rpy="0 0 0"/>
            <mass value="1" />
            <inertia ixx="100" ixy="0" ixz="0" iyy="100" iyz="0" izz="100" />
        </inertial>
        <visual>
            <origin xyz="0 0 1.482988562972314" rpy="0 0 0"/>
            <geometry>
                <box size="2.382633601433695 1.551002857061339 2.965977125944628" />
            </geometry>
            <material name="Green">
                <color rgba="0 180.0 0.0 1.0"/>
            </material>
        </visual>
        <collision>
            <origin xyz="0 0 1.482988562972314" rpy="0 0 0"/>
            <geometry>
                <box size="2.382633601433695 1.551002857061339 2.965977125944628" />
            </geometry>
        </collision>
    </link>
    <link name="Leg16">
        <inertial>
            <origin xyz="0 0.7716791043070406 0" rpy="0 0 0"/>
            <mass value="1" />
            <inertia ixx="100" ixy="0" ixz="0" iyy="100" iyz="0" izz="100" />
        </inertial>
        <visual>
            <origin xyz="0 0.7716791043070406 0" rpy="0 0 0"/>
            <geometry>
                <box size="1.8044100270885766 1.5433582086140811 1.3253928032795546" />
            </geometry>
            <material name="Blue">
                <color rgba="0 1.0 1.0 1.0"/>
            </material>
        </visual>
        <collision>
            <origin xyz="0 0.7716791043070406 0" rpy="0 0 0"/>
            <geometry>
                <box size="1.8044100270885766 1.5433582086140811 1.3253928032795546" />
            </geometry>
        </collision>
    </link>
    <link name="Leg17">
        <inertial>
            <origin xyz="1.2824397325692543 0 0" rpy="0 0 0"/>
            <mass value="1" />
            <inertia ixx="100" ixy="0" ixz="0" iyy="100" iyz="0" izz="100" />
        </inertial>
        <visual>
            <origin xyz="1.2824397325692543 0 0" rpy="0 0 0"/>
            <geometry>
                <box size="2.5648794651385085 1.4814159996159701 1.6312788319972336" />
            </geometry>
            <material name="Green">
                <color rgba="0 180.0 0.0 1.0"/>
            </material>
        </visual>
        <collision>
            <origin xyz="1.2824397325692543 0 0" rpy="0 0 0"/>
            <geometry>
                <box size="2.5648794651385085 1.4814159996159701 1.6312788319972336" />
            </geometry>
        </collision>
    </link>
    <link name="Leg18">
        <inertial>
            <origin xyz="0 0 0.8431737321806195" rpy="0 0 0"/>
            <mass value="1" />
            <inertia ixx="100" ixy="0" ixz="0" iyy="100" iyz="0" izz="100" />
        </inertial>
        <visual>
            <origin xyz="0 0 0.8431737321806195" rpy="0 0 0"/>
            <geometry>
                <box size="2.217658499314152 1.6734613898062862 1.686347464361239" />
            </geometry>
            <material name="Blue">
                <color rgba="0 1.0 1.0 1.0"/>
            </material>
        </visual>
        <collision>
            <origin xyz="0 0 0.8431737321806195" rpy="0 0 0"/>
            <geometry>
                <box size="2.217658499314152 1.6734613898062862 1.686347464361239" />
            </geometry>
        </collision>
    </link>
    <link name="Leg19">
        <inertial>
            <origin xyz="0 0.6573018548226547 0" rpy="0 0 0"/>
            <mass value="1" />
            <inertia ixx="100" ixy="0" ixz="0" iyy="100" iyz="0" izz="100" />
        </inertial>
        <visual>
            <origin xyz="0 0.6573018548226547 0" rpy="0 0 0"/>
            <geometry>
                <box size="1.2148002754652316 1.3146037096453094 1.6784655687731447" />
            </geometry>
            <material name="Blue">
                <color rgba="0 1.0 1.0 1.0"/>
            </material>
        </visual>
        <collision>
            <origin xyz="0 0.6573018548226547 0" rpy="0 0 0"/>
            <geometry>
                <box size="1.2148002754652316 1.3146037096453094 1.6784655687731447" />
            </geometry>
        </collision>
    </link>
    <link name="Leg20">
        <inertial>
            <origin xyz="0 1.434593388971594 0" rpy="0 0 0"/>
            <mass value="1" />
            <inertia ixx="100" ixy="0" ixz="0" iyy="100" iyz="0" izz="100" />
        </inertial>
        <visual>
            <origin xyz="0 1.434593388971594 0" rpy="0 0 0"/>
            <geometry>
                <box size="2.0640353131648914 2.869186777943188 1.1478796344712416" />
            </geometry>
            <material name="Blue">
                <color rgba="0 1.0 1.0 1.0"/>
            </material>
        </visual>
        <collision>
            <origin xyz="0 1.434593388971594 0" rpy="0 0 0"/>
            <geometry>
                <box size="2.0640353131648914 2.869186777943188 1.1478796344712416" />
            </geometry>
        </collision>
    </link>
    <link name="Leg21">
        <inertial>
            <origin xyz="0 0 0.7905918463283056" rpy="0 0 0"/>
            <mass value="1" />
            <inertia ixx="100" ixy="0" ixz="0" iyy="100" iyz="0" izz="100" />
        </inertial>
        <visual>
            <origin xyz="0 0 0.7905918463283056" rpy="0 0 0"/>
            <geometry>
                <box size="2.018425158006494 2.487021471248471 1.5811836926566112" />
            </geometry>
            <material name="Green">
                <color rgba="0 180.0 0.0 1.0"/>
            </material>
        </visual>
        <collision>
            <origin xyz="0 0 0.7905918463283056" rpy="0 0 0"/>
            <geometry>
                <box size="2.018425158006494 2.487021471248471 1.5811836926566112" />
            </geometry>
        </collision>
    </link>
    <link name="Leg22">
        <inertial>
            <origin xyz="0 0.9375497371009639 0" rpy="0 0 0"/>
            <mass value="1" />
            <inertia ixx="100" ixy="0" ixz="0" iyy="100" iyz="0" izz="100" />
        </inertial>
        <visual>
            <origin xyz="0 0.9375497371009639 0" rpy="0 0 0"/>
            <geometry>
                <box size="2.1684583669233115 1.8750994742019278 1.3372244437008172" />
            </geometry>
            <material name="Blue">
                <color rgba="0 1.0 1.0 1.0"/>
            </material>
        </visual>
        <collision>
            <origin xyz="0 0.9375497371009639 0" rpy="0 0 0"/>
            <geometry>
                <box size="2.1684583669233115 1.8750994742019278 1.3372244437008172" />
            </geometry>
        </collision>
    </link>
    <link name="Leg23">
        <inertial>
            <origin xyz="1.0315986379748279 0 0" rpy="0 0 0"/>
            <mass value="1" />
            <inertia ixx="100" ixy="0" ixz="0" iyy="100" iyz="0" izz="100" />
        </inertial>
        <visual>
            <origin xyz="1.0315986379748279 0 0" rpy="0 0 0"/>
            <geometry>
                <box size="2.0631972759496557 2.896788307905391 2.9168822537060795" />
            </geometry>
            <material name="Blue">
                <color rgba="0 1.0 1.0 1.0"/>
            </material>
        </visual>
        <collision>
            <origin xyz="1.0315986379748279 0 0" rpy="0 0 0"/>
            <geometry>
                <box size="2.0631972759496557 2.896788307905391 2.9168822537060795" />
            </geometry>
        </collision>
    </link>
    <link name="Leg24">
        <inertial>
            <origin xyz="0 0.5093919318629152 0" rpy="0 0 0"/>
            <mass value="1" />
            <inertia ixx="100" ixy="0" ixz="0" iyy="100" iyz="0" izz="100" />
        </inertial>
        <visual>
            <origin xyz="0 0.5093919318629152 0" rpy="0 0 0"/>
            <geometry>
                <box size="1.7609116491945824 1.0187838637258304 2.924423354722167" />
            </geometry>
            <material name="Blue">
                <color rgba="0 1.0 1.0 1.0"/>
            </material>
        </visual>
        <collision>
            <origin xyz="0 0.5093919318629152 0" rpy="0 0 0"/>
            <geometry>
                <box size="1.7609116491945824 1.0187838637258304 2.924423354722167" />
            </geometry>
        </collision>
    </link>
    <link name="Leg25">
        <inertial>
            <origin xyz="0 0.5702690004793768 0" rpy="0 0 0"/>
            <mass value="1" />
            <inertia ixx="100" ixy="0" ixz="0" iyy="100" iyz="0" izz="100" />
        </inertial>
        <visual>
            <origin xyz="0 0.5702690004793768 0" rpy="0 0 0"/>
            <geometry>
                <box size="1.6737985954974022 1.1405380009587536 2.1653098872675645" />
            </geometry>
            <material name="Blue">
                <color rgba="0 1.0 1.0 1.0"/>
            </material>
        </visual>
        <collision>
            <origin xyz="0 0.5702690004793768 0" rpy="0 0 0"/>
            <geometry>
                <box size="1.6737985954974022 1.1405380009587536 2.1653098872675645" />
            </geometry>
        </collision>
    </link>
    <joint name="Torso_Leg1" type="revolute">
       <parent link="Torso"/>
       <child  link="Leg1"/>
       <origin rpy="0 0 0" xyz="0 0 1.425764275849306" />
     <axis xyz="1 0 0"/>
       <limit effort="0.0" lower="-3.14159" upper="3.14159" velocity="0.0"/>
    </joint>
    <joint name="Leg1_Leg2" type="revolute">
       <parent link="Leg1"/>
       <child  link="Leg2"/>
       <origin rpy="0 0 0" xyz="1.9054683846401532 0 0" />
     <axis xyz="1 0 0"/>
       <limit effort="0.0" lower="-3.14159" upper="3.14159" velocity="0.0"/>
    </joint>
    <joint name="Leg1_Leg3" type="revolute">
       <parent link="Leg1"/>
       <child  link="Leg3"/>
       <origin rpy="0 0 0" xyz="1.9054683846401532 1.1733937003113555 0" />
     <axis xyz="1 0 0"/>
       <limit effort="0.0" lower="-3.14159" upper="3.14159" velocity="0.0"/>
    </joint>
    <joint name="Leg2_Leg4" type="revolute">
       <parent link="Leg2"/>
       <child  link="Leg4"/>
       <origin rpy="0 0 0" xyz="0 1.4700847444577794 0.9112846927947951" />
     <axis xyz="1 0 0"/>
       <limit effort="0.0" lower="-3.14159" upper="3.14159" velocity="0.0"/>
    </joint>
    <joint name="Leg4_Leg5" type="revolute">
       <parent link="Leg4"/>
       <child  link="Leg5"/>
       <origin rpy="0 0 0" xyz="0 0 1.8023514638330715" />
     <axis xyz="1 0 0"/>
       <limit effort="0.0" lower="-3.14159" upper="3.14159" velocity="0.0"/>
    </joint>
    <joint name="Leg1_Leg6" type="revolute">
       <parent link="Leg1"/>
       <child  link="Leg6"/>
       <origin rpy="0 0 0" xyz="1.9054683846401532 1.1733937003113555 0.8727456157417307" />
     <axis xyz="1 0 0"/>
       <limit effort="0.0" lower="-3.14159" upper="3.14159" velocity="0.0"/>
    </joint>
    <joint name="Leg2_Leg7" type="revolute">
       <parent link="Leg2"/>
       <child  link="Leg7"/>
       <origin rpy="0 0 0" xyz="0 2.9401694889155587 0.9112846927947951" />
     <axis xyz="1 0 0"/>
       <limit effort="0.0" lower="-3.14159" upper="3.14159" velocity="0.0"/>
    </joint>
    <joint name="Leg3_Leg8" type="revolute">
       <parent link="Leg3"/>
       <child  link="Leg8"/>
       <origin rpy="0 0 0" xyz="0.514290031951784 0 0.6231332558812795" />
     <axis xyz="1 0 0"/>
       <limit effort="0.0" lower="-3.14159" upper="3.14159" velocity="0.0"/>
    </joint>
    <joint name="Leg8_Leg9" type="revolute">
       <parent link="Leg8"/>
       <child  link="Leg9"/>
       <origin rpy="0 0 0" xyz="0 1.5704826974228312 0" />
     <axis xyz="1 0 0"/>
       <limit effort="0.0" lower="-3.14159" upper="3.14159" velocity="0.0"/>
    </joint>
    <joint name="Leg6_Leg10" type="revolute">
       <parent link="Leg6"/>
       <child  link="Leg10"/>
       <origin rpy="0 0 0" xyz="0 2.3859480485045044 0" />
     <axis xyz="1 0 0"/>
       <limit effort="0.0" lower="-3.14159" upper="3.14159" velocity="0.0"/>
    </joint>
    <joint name="Leg7_Leg11" type="revolute">
       <parent link="Leg7"/>
       <child  link="Leg11"/>
       <origin rpy="0 0 0" xyz="1.1895984585163595 0.8240694918652838 0" />
     <axis xyz="1 0 0"/>
       <limit effort="0.0" lower="-3.14159" upper="3.14159" velocity="0.0"/>
    </joint>
    <joint name="Leg6_Leg12" type="revolute">
       <parent link="Leg6"/>
       <child  link="Leg12"/>
       <origin rpy="0 0 0" xyz="1.2672392334542177 2.3859480485045044 0" />
     <axis xyz="1 0 0"/>
       <limit effort="0.0" lower="-3.14159" upper="3.14159" velocity="0.0"/>
    </joint>
    <joint name="Leg8_Leg13" type="revolute">
       <parent link="Leg8"/>
       <child  link="Leg13"/>
       <origin rpy="0 0 0" xyz="0 1.5704826974228312 1.1281439366473651" />
     <axis xyz="1 0 0"/>
       <limit effort="0.0" lower="-3.14159" upper="3.14159" velocity="0.0"/>
    </joint>
    <joint name="Leg7_Leg14" type="revolute">
       <parent link="Leg7"/>
       <child  link="Leg14"/>
       <origin rpy="0 0 0" xyz="1.1895984585163595 0.8240694918652838 0.635434683435615" />
     <axis xyz="1 0 0"/>
       <limit effort="0.0" lower="-3.14159" upper="3.14159" velocity="0.0"/>
    </joint>
    <joint name="Leg11_Leg15" type="revolute">
       <parent link="Leg11"/>
       <child  link="Leg15"/>
       <origin rpy="0 0 0" xyz="1.4202433793436882 0 0.853897080562074" />
     <axis xyz="1 0 0"/>
       <limit effort="0.0" lower="-3.14159" upper="3.14159" velocity="0.0"/>
    </joint>
    <joint name="Leg10_Leg16" type="revolute">
       <parent link="Leg10"/>
       <child  link="Leg16"/>
       <origin rpy="0 0 0" xyz="0 1.8356009012885055 0" />
     <axis xyz="1 0 0"/>
       <limit effort="0.0" lower="-3.14159" upper="3.14159" velocity="0.0"/>
    </joint>
    <joint name="Leg7_Leg17" type="revolute">
       <parent link="Leg7"/>
       <child  link="Leg17"/>
       <origin rpy="0 0 0" xyz="2.379196917032719 0.8240694918652838 0.635434683435615" />
     <axis xyz="1 0 0"/>
       <limit effort="0.0" lower="-3.14159" upper="3.14159" velocity="0.0"/>
    </joint>
    <joint name="Leg6_Leg18" type="revolute">
       <parent link="Leg6"/>
       <child  link="Leg18"/>
       <origin rpy="0 0 0" xyz="1.2672392334542177 2.3859480485045044 1.308022443744648" />
     <axis xyz="1 0 0"/>
       <limit effort="0.0" lower="-3.14159" upper="3.14159" velocity="0.0"/>
    </joint>
    <joint name="Leg3_Leg19" type="revolute">
       <parent link="Leg3"/>
       <child  link="Leg19"/>
       <origin rpy="0 0 0" xyz="0.514290031951784 0.9911716663999176 0.6231332558812795" />
     <axis xyz="1 0 0"/>
       <limit effort="0.0" lower="-3.14159" upper="3.14159" velocity="0.0"/>
    </joint>
    <joint name="Leg5_Leg20" type="revolute">
       <parent link="Leg5"/>
       <child  link="Leg20"/>
       <origin rpy="0 0 0" xyz="0 1.3731062760945476 0.8766791829366609" />
     <axis xyz="1 0 0"/>
       <limit effort="0.0" lower="-3.14159" upper="3.14159" velocity="0.0"/>
    </joint>
    <joint name="Leg5_Leg21" type="revolute">
       <parent link="Leg5"/>
       <child  link="Leg21"/>
       <origin rpy="0 0 0" xyz="0 1.3731062760945476 1.7533583658733218" />
     <axis xyz="1 0 0"/>
       <limit effort="0.0" lower="-3.14159" upper="3.14159" velocity="0.0"/>
    </joint>
    <joint name="Leg17_Leg22" type="revolute">
       <parent link="Leg17"/>
       <child  link="Leg22"/>
       <origin rpy="0 0 0" xyz="0 0.8367306949031431 0.8431737321806195" />
     <axis xyz="1 0 0"/>
       <limit effort="0.0" lower="-3.14159" upper="3.14159" velocity="0.0"/>
    </joint>
    <joint name="Leg12_Leg23" type="revolute">
       <parent link="Leg12"/>
       <child  link="Leg23"/>
       <origin rpy="0 0 0" xyz="0.5554868646190887 0 1.329965834927978" />
     <axis xyz="1 0 0"/>
       <limit effort="0.0" lower="-3.14159" upper="3.14159" velocity="0.0"/>
    </joint>
    <joint name="Leg15_Leg24" type="revolute">
       <parent link="Leg15"/>
       <child  link="Leg24"/>
       <origin rpy="0 0 0" xyz="0 1.5433582086140811 0" />
     <axis xyz="1 0 0"/>
       <limit effort="0.0" lower="-3.14159" upper="3.14159" velocity="0.0"/>
    </joint>
    <joint name="Leg12_Leg25" type="revolute">
       <parent link="Leg12"/>
       <child  link="Leg25"/>
       <origin rpy="0 0 0" xyz="0.5554868646190887 1.0619883946108417 1.329965834927978" />
     <axis xyz="1 0 0"/>
       <limit effort="0.0" lower="-3.14159" upper="3.14159" velocity="0.0"/>
    </joint>
</robot>