<robot name = "robot">
    <link name="Torso">
        <inertial>
            <origin xyz="0 0 1.0786905966230944" rpy="0 0 0"/>
            <mass value="1" />
            <inertia ixx="100" ixy="0" ixz="0" iyy="100" iyz="0" izz="100" />
        </inertial>
        <visual>
            <origin xyz="0 0 1.0786905966230944" rpy="0 0 0"/>
            <geometry>
                <box size="1.8549025169666575 1.6017976907755944 2.157381193246189" />
            </geometry>
            <material name="Green">
                <color rgba="0 180.0 0.0 1.0"/>
            </material>
        </visual>
        <collision>
            <origin xyz="0 0 1.0786905966230944" rpy="0 0 0"/>
            <geometry>
                <box size="1.8549025169666575 1.6017976907755944 2.157381193246189" />
            </geometry>
        </collision>
    </link>
    <link name="Leg1">
        <inertial>
            <origin xyz="0 1.3751416629467803 0" rpy="0 0 0"/>
            <mass value="1" />
            <inertia ixx="100" ixy="0" ixz="0" iyy="100" iyz="0" izz="100" />
        </inertial>
        <visual>
            <origin xyz="0 1.3751416629467803 0" rpy="0 0 0"/>
            <geometry>
                <box size="1.0111142668869701 2.7502833258935606 1.1115330630819753" />
            </geometry>
            <material name="Blue">
                <color rgba="0 1.0 1.0 1.0"/>
            </material>
        </visual>
        <collision>
            <origin xyz="0 1.3751416629467803 0" rpy="0 0 0"/>
            <geometry>
                <box size="1.0111142668869701 2.7502833258935606 1.1115330630819753" />
            </geometry>
        </collision>
    </link>
    <link name="Leg2">
        <inertial>
            <origin xyz="0 0.800710759704346 0" rpy="0 0 0"/>
            <mass value="1" />
            <inertia ixx="100" ixy="0" ixz="0" iyy="100" iyz="0" izz="100" />
        </inertial>
        <visual>
            <origin xyz="0 0.800710759704346 0" rpy="0 0 0"/>
            <geometry>
                <box size="1.8998396926006729 1.601421519408692 2.6069080058310536" />
            </geometry>
            <material name="Blue">
                <color rgba="0 1.0 1.0 1.0"/>
            </material>
        </visual>
        <collision>
            <origin xyz="0 0.800710759704346 0" rpy="0 0 0"/>
            <geometry>
                <box size="1.8998396926006729 1.601421519408692 2.6069080058310536" />
            </geometry>
        </collision>
    </link>
    <link name="Leg3">
        <inertial>
            <origin xyz="0 1.4936197608068507 0" rpy="0 0 0"/>
            <mass value="1" />
            <inertia ixx="100" ixy="0" ixz="0" iyy="100" iyz="0" izz="100" />
        </inertial>
        <visual>
            <origin xyz="0 1.4936197608068507 0" rpy="0 0 0"/>
            <geometry>
                <box size="1.0276729035906413 2.9872395216137013 2.676971255142327" />
            </geometry>
            <material name="Blue">
                <color rgba="0 1.0 1.0 1.0"/>
            </material>
        </visual>
        <collision>
            <origin xyz="0 1.4936197608068507 0" rpy="0 0 0"/>
            <geometry>
                <box size="1.0276729035906413 2.9872395216137013 2.676971255142327" />
            </geometry>
        </collision>
    </link>
    <link name="Leg4">
        <inertial>
            <origin xyz="0 1.081328863415099 0" rpy="0 0 0"/>
            <mass value="1" />
            <inertia ixx="100" ixy="0" ixz="0" iyy="100" iyz="0" izz="100" />
        </inertial>
        <visual>
            <origin xyz="0 1.081328863415099 0" rpy="0 0 0"/>
            <geometry>
                <box size="1.1622260386390764 2.162657726830198 2.213856375114296" />
            </geometry>
            <material name="Blue">
                <color rgba="0 1.0 1.0 1.0"/>
            </material>
        </visual>
        <collision>
            <origin xyz="0 1.081328863415099 0" rpy="0 0 0"/>
            <geometry>
                <box size="1.1622260386390764 2.162657726830198 2.213856375114296" />
            </geometry>
        </collision>
    </link>
    <link name="Leg5">
        <inertial>
            <origin xyz="0 1.056487133796665 0" rpy="0 0 0"/>
            <mass value="1" />
            <inertia ixx="100" ixy="0" ixz="0" iyy="100" iyz="0" izz="100" />
        </inertial>
        <visual>
            <origin xyz="0 1.056487133796665 0" rpy="0 0 0"/>
            <geometry>
                <box size="2.7699416321894574 2.11297426759333 1.0242026387040442" />
            </geometry>
            <material name="Blue">
                <color rgba="0 1.0 1.0 1.0"/>
            </material>
        </visual>
        <collision>
            <origin xyz="0 1.056487133796665 0" rpy="0 0 0"/>
            <geometry>
                <box size="2.7699416321894574 2.11297426759333 1.0242026387040442" />
            </geometry>
        </collision>
    </link>
    <link name="Leg6">
        <inertial>
            <origin xyz="0.741483674933228 0 0" rpy="0 0 0"/>
            <mass value="1" />
            <inertia ixx="100" ixy="0" ixz="0" iyy="100" iyz="0" izz="100" />
        </inertial>
        <visual>
            <origin xyz="0.741483674933228 0 0" rpy="0 0 0"/>
            <geometry>
                <box size="1.482967349866456 2.093628406902061 1.3395801621501946" />
            </geometry>
            <material name="Blue">
                <color rgba="0 1.0 1.0 1.0"/>
            </material>
        </visual>
        <collision>
            <origin xyz="0.741483674933228 0 0" rpy="0 0 0"/>
            <geometry>
                <box size="1.482967349866456 2.093628406902061 1.3395801621501946" />
            </geometry>
        </collision>
    </link>
    <link name="Leg7">
        <inertial>
            <origin xyz="0 0 0.6768636397670723" rpy="0 0 0"/>
            <mass value="1" />
            <inertia ixx="100" ixy="0" ixz="0" iyy="100" iyz="0" izz="100" />
        </inertial>
        <visual>
            <origin xyz="0 0 0.6768636397670723" rpy="0 0 0"/>
            <geometry>
                <box size="1.7325086651450683 1.1534059424807943 1.3537272795341446" />
            </geometry>
            <material name="Blue">
                <color rgba="0 1.0 1.0 1.0"/>
            </material>
        </visual>
        <collision>
            <origin xyz="0 0 0.6768636397670723" rpy="0 0 0"/>
            <geometry>
                <box size="1.7325086651450683 1.1534059424807943 1.3537272795341446" />
            </geometry>
        </collision>
    </link>
    <link name="Leg8">
        <inertial>
            <origin xyz="1.0037932290633975 0 0" rpy="0 0 0"/>
            <mass value="1" />
            <inertia ixx="100" ixy="0" ixz="0" iyy="100" iyz="0" izz="100" />
        </inertial>
        <visual>
            <origin xyz="1.0037932290633975 0 0" rpy="0 0 0"/>
            <geometry>
                <box size="2.007586458126795 1.564548723179022 1.1797406057347066" />
            </geometry>
            <material name="Green">
                <color rgba="0 180.0 0.0 1.0"/>
            </material>
        </visual>
        <collision>
            <origin xyz="1.0037932290633975 0 0" rpy="0 0 0"/>
            <geometry>
                <box size="2.007586458126795 1.564548723179022 1.1797406057347066" />
            </geometry>
        </collision>
    </link>
    <link name="Leg9">
        <inertial>
            <origin xyz="0 1.381839248402489 0" rpy="0 0 0"/>
            <mass value="1" />
            <inertia ixx="100" ixy="0" ixz="0" iyy="100" iyz="0" izz="100" />
        </inertial>
        <visual>
            <origin xyz="0 1.381839248402489 0" rpy="0 0 0"/>
            <geometry>
                <box size="2.4753708508387398 2.763678496804978 2.8439139660459434" />
            </geometry>
            <material name="Blue">
                <color rgba="0 1.0 1.0 1.0"/>
            </material>
        </visual>
        <collision>
            <origin xyz="0 1.381839248402489 0" rpy="0 0 0"/>
            <geometry>
                <box size="2.4753708508387398 2.763678496804978 2.8439139660459434" />
            </geometry>
        </collision>
    </link>
    <link name="Leg10">
        <inertial>
            <origin xyz="0.8538838499323156 0 0" rpy="0 0 0"/>
            <mass value="1" />
            <inertia ixx="100" ixy="0" ixz="0" iyy="100" iyz="0" izz="100" />
        </inertial>
        <visual>
            <origin xyz="0.8538838499323156 0 0" rpy="0 0 0"/>
            <geometry>
                <box size="1.7077676998646312 1.7034481032079853 2.609519552374543" />
            </geometry>
            <material name="Blue">
                <color rgba="0 1.0 1.0 1.0"/>
            </material>
        </visual>
        <collision>
            <origin xyz="0.8538838499323156 0 0" rpy="0 0 0"/>
            <geometry>
                <box size="1.7077676998646312 1.7034481032079853 2.609519552374543" />
            </geometry>
        </collision>
    </link>
    <link name="Leg11">
        <inertial>
            <origin xyz="0 0 0.9895426734103973" rpy="0 0 0"/>
            <mass value="1" />
            <inertia ixx="100" ixy="0" ixz="0" iyy="100" iyz="0" izz="100" />
        </inertial>
        <visual>
            <origin xyz="0 0 0.9895426734103973" rpy="0 0 0"/>
            <geometry>
                <box size="2.688072414853665 1.3987217359091995 1.9790853468207945" />
            </geometry>
            <material name="Green">
                <color rgba="0 180.0 0.0 1.0"/>
            </material>
        </visual>
        <collision>
            <origin xyz="0 0 0.9895426734103973" rpy="0 0 0"/>
            <geometry>
                <box size="2.688072414853665 1.3987217359091995 1.9790853468207945" />
            </geometry>
        </collision>
    </link>
    <link name="Leg12">
        <inertial>
            <origin xyz="1.4750268992178124 0 0" rpy="0 0 0"/>
            <mass value="1" />
            <inertia ixx="100" ixy="0" ixz="0" iyy="100" iyz="0" izz="100" />
        </inertial>
        <visual>
            <origin xyz="1.4750268992178124 0 0" rpy="0 0 0"/>
            <geometry>
                <box size="2.9500537984356248 1.171534644755235 2.0458682808993602" />
            </geometry>
            <material name="Blue">
                <color rgba="0 1.0 1.0 1.0"/>
            </material>
        </visual>
        <collision>
            <origin xyz="1.4750268992178124 0 0" rpy="0 0 0"/>
            <geometry>
                <box size="2.9500537984356248 1.171534644755235 2.0458682808993602" />
            </geometry>
        </collision>
    </link>
    <link name="Leg13">
        <inertial>
            <origin xyz="0 0.722267769734728 0" rpy="0 0 0"/>
            <mass value="1" />
            <inertia ixx="100" ixy="0" ixz="0" iyy="100" iyz="0" izz="100" />
        </inertial>
        <visual>
            <origin xyz="0 0.722267769734728 0" rpy="0 0 0"/>
            <geometry>
                <box size="1.7703935990555895 1.444535539469456 2.400753191507075" />
            </geometry>
            <material name="Green">
                <color rgba="0 180.0 0.0 1.0"/>
            </material>
        </visual>
        <collision>
            <origin xyz="0 0.722267769734728 0" rpy="0 0 0"/>
            <geometry>
                <box size="1.7703935990555895 1.444535539469456 2.400753191507075" />
            </geometry>
        </collision>
    </link>
    <link name="Leg14">
        <inertial>
            <origin xyz="0 1.14308343216236 0" rpy="0 0 0"/>
            <mass value="1" />
            <inertia ixx="100" ixy="0" ixz="0" iyy="100" iyz="0" izz="100" />
        </inertial>
        <visual>
            <origin xyz="0 1.14308343216236 0" rpy="0 0 0"/>
            <geometry>
                <box size="2.645570167159695 2.28616686432472 1.1564868391594558" />
            </geometry>
            <material name="Green">
                <color rgba="0 180.0 0.0 1.0"/>
            </material>
        </visual>
        <collision>
            <origin xyz="0 1.14308343216236 0" rpy="0 0 0"/>
            <geometry>
                <box size="2.645570167159695 2.28616686432472 1.1564868391594558" />
            </geometry>
        </collision>
    </link>
    <link name="Leg15">
        <inertial>
            <origin xyz="0 0.6681751019902021 0" rpy="0 0 0"/>
            <mass value="1" />
            <inertia ixx="100" ixy="0" ixz="0" iyy="100" iyz="0" izz="100" />
        </inertial>
        <visual>
            <origin xyz="0 0.6681751019902021 0" rpy="0 0 0"/>
            <geometry>
                <box size="2.127515424906688 1.3363502039804043 1.554466791782222" />
            </geometry>
            <material name="Blue">
                <color rgba="0 1.0 1.0 1.0"/>
            </material>
        </visual>
        <collision>
            <origin xyz="0 0.6681751019902021 0" rpy="0 0 0"/>
            <geometry>
                <box size="2.127515424906688 1.3363502039804043 1.554466791782222" />
            </geometry>
        </collision>
    </link>
    <link name="Leg16">
        <inertial>
            <origin xyz="1.3339011263093252 0 0" rpy="0 0 0"/>
            <mass value="1" />
            <inertia ixx="100" ixy="0" ixz="0" iyy="100" iyz="0" izz="100" />
        </inertial>
        <visual>
            <origin xyz="1.3339011263093252 0 0" rpy="0 0 0"/>
            <geometry>
                <box size="2.6678022526186504 2.1364070400247943 1.044253570691066" />
            </geometry>
            <material name="Green">
                <color rgba="0 180.0 0.0 1.0"/>
            </material>
        </visual>
        <collision>
            <origin xyz="1.3339011263093252 0 0" rpy="0 0 0"/>
            <geometry>
                <box size="2.6678022526186504 2.1364070400247943 1.044253570691066" />
            </geometry>
        </collision>
    </link>
    <link name="Leg17">
        <inertial>
            <origin xyz="0 0.5477687861958493 0" rpy="0 0 0"/>
            <mass value="1" />
            <inertia ixx="100" ixy="0" ixz="0" iyy="100" iyz="0" izz="100" />
        </inertial>
        <visual>
            <origin xyz="0 0.5477687861958493 0" rpy="0 0 0"/>
            <geometry>
                <box size="2.887650903785892 1.0955375723916987 1.1848305570756357" />
            </geometry>
            <material name="Green">
                <color rgba="0 180.0 0.0 1.0"/>
            </material>
        </visual>
        <collision>
            <origin xyz="0 0.5477687861958493 0" rpy="0 0 0"/>
            <geometry>
                <box size="2.887650903785892 1.0955375723916987 1.1848305570756357" />
            </geometry>
        </collision>
    </link>
    <link name="Leg18">
        <inertial>
            <origin xyz="1.027315702837918 0 0" rpy="0 0 0"/>
            <mass value="1" />
            <inertia ixx="100" ixy="0" ixz="0" iyy="100" iyz="0" izz="100" />
        </inertial>
        <visual>
            <origin xyz="1.027315702837918 0 0" rpy="0 0 0"/>
            <geometry>
                <box size="2.054631405675836 2.189232595201185 2.614382294008895" />
            </geometry>
            <material name="Green">
                <color rgba="0 180.0 0.0 1.0"/>
            </material>
        </visual>
        <collision>
            <origin xyz="1.027315702837918 0 0" rpy="0 0 0"/>
            <geometry>
                <box size="2.054631405675836 2.189232595201185 2.614382294008895" />
            </geometry>
        </collision>
    </link>
    <link name="Leg19">
        <inertial>
            <origin xyz="0.6007771214122134 0 0" rpy="0 0 0"/>
            <mass value="1" />
            <inertia ixx="100" ixy="0" ixz="0" iyy="100" iyz="0" izz="100" />
        </inertial>
        <visual>
            <origin xyz="0.6007771214122134 0 0" rpy="0 0 0"/>
            <geometry>
                <box size="1.2015542428244268 1.2180380360932086 2.6171998951105087" />
            </geometry>
            <material name="Green">
                <color rgba="0 180.0 0.0 1.0"/>
            </material>
        </visual>
        <collision>
            <origin xyz="0.6007771214122134 0 0" rpy="0 0 0"/>
            <geometry>
                <box size="1.2015542428244268 1.2180380360932086 2.6171998951105087" />
            </geometry>
        </collision>
    </link>
    <link name="Leg20">
        <inertial>
            <origin xyz="0 0 0.5241793955313564" rpy="0 0 0"/>
            <mass value="1" />
            <inertia ixx="100" ixy="0" ixz="0" iyy="100" iyz="0" izz="100" />
        </inertial>
        <visual>
            <origin xyz="0 0 0.5241793955313564" rpy="0 0 0"/>
            <geometry>
                <box size="2.902771909012037 1.474510504137543 1.0483587910627128" />
            </geometry>
            <material name="Blue">
                <color rgba="0 1.0 1.0 1.0"/>
            </material>
        </visual>
        <collision>
            <origin xyz="0 0 0.5241793955313564" rpy="0 0 0"/>
            <geometry>
                <box size="2.902771909012037 1.474510504137543 1.0483587910627128" />
            </geometry>
        </collision>
    </link>
    <link name="Leg21">
        <inertial>
            <origin xyz="0 0.8054145411719335 0" rpy="0 0 0"/>
            <mass value="1" />
            <inertia ixx="100" ixy="0" ixz="0" iyy="100" iyz="0" izz="100" />
        </inertial>
        <visual>
            <origin xyz="0 0.8054145411719335 0" rpy="0 0 0"/>
            <geometry>
                <box size="1.5915130123273673 1.610829082343867 1.396167770055392" />
            </geometry>
            <material name="Green">
                <color rgba="0 180.0 0.0 1.0"/>
            </material>
        </visual>
        <collision>
            <origin xyz="0 0.8054145411719335 0" rpy="0 0 0"/>
            <geometry>
                <box size="1.5915130123273673 1.610829082343867 1.396167770055392" />
            </geometry>
        </collision>
    </link>
    <link name="Leg22">
        <inertial>
            <origin xyz="0.8154875821006666 0 0" rpy="0 0 0"/>
            <mass value="1" />
            <inertia ixx="100" ixy="0" ixz="0" iyy="100" iyz="0" izz="100" />
        </inertial>
        <visual>
            <origin xyz="0.8154875821006666 0 0" rpy="0 0 0"/>
            <geometry>
                <box size="1.6309751642013333 2.9639166616159227 2.064072283465495" />
            </geometry>
            <material name="Blue">
                <color rgba="0 1.0 1.0 1.0"/>
            </material>
        </visual>
        <collision>
            <origin xyz="0.8154875821006666 0 0" rpy="0 0 0"/>
            <geometry>
                <box size="1.6309751642013333 2.9639166616159227 2.064072283465495" />
            </geometry>
        </collision>
    </link>
    <link name="Leg23">
        <inertial>
            <origin xyz="0 1.4357139700367358 0" rpy="0 0 0"/>
            <mass value="1" />
            <inertia ixx="100" ixy="0" ixz="0" iyy="100" iyz="0" izz="100" />
        </inertial>
        <visual>
            <origin xyz="0 1.4357139700367358 0" rpy="0 0 0"/>
            <geometry>
                <box size="1.343036948942575 2.8714279400734717 1.2254927507048334" />
            </geometry>
            <material name="Blue">
                <color rgba="0 1.0 1.0 1.0"/>
            </material>
        </visual>
        <collision>
            <origin xyz="0 1.4357139700367358 0" rpy="0 0 0"/>
            <geometry>
                <box size="1.343036948942575 2.8714279400734717 1.2254927507048334" />
            </geometry>
        </collision>
    </link>
    <link name="Leg24">
        <inertial>
            <origin xyz="1.1001731145888185 0 0" rpy="0 0 0"/>
            <mass value="1" />
            <inertia ixx="100" ixy="0" ixz="0" iyy="100" iyz="0" izz="100" />
        </inertial>
        <visual>
            <origin xyz="1.1001731145888185 0 0" rpy="0 0 0"/>
            <geometry>
                <box size="2.200346229177637 2.3898519224591928 2.5759497552880335" />
            </geometry>
            <material name="Blue">
                <color rgba="0 1.0 1.0 1.0"/>
            </material>
        </visual>
        <collision>
            <origin xyz="1.1001731145888185 0 0" rpy="0 0 0"/>
            <geometry>
                <box size="2.200346229177637 2.3898519224591928 2.5759497552880335" />
            </geometry>
        </collision>
    </link>
    <joint name="Torso_Leg1" type="revolute">
       <parent link="Torso"/>
       <child  link="Leg1"/>
       <origin rpy="0 0 0" xyz="0 0.8008988453877972 1.0786905966230944" />
     <axis xyz="1 0 0"/>
       <limit effort="0.0" lower="-3.14159" upper="3.14159" velocity="0.0"/>
    </joint>
    <joint name="Leg1_Leg2" type="revolute">
       <parent link="Leg1"/>
       <child  link="Leg2"/>
       <origin rpy="0 0 0" xyz="0 1.601421519408692 0" />
     <axis xyz="1 0 0"/>
       <limit effort="0.0" lower="-3.14159" upper="3.14159" velocity="0.0"/>
    </joint>
    <joint name="Leg2_Leg3" type="revolute">
       <parent link="Leg2"/>
       <child  link="Leg3"/>
       <origin rpy="0 0 0" xyz="0 2.9872395216137013 0" />
     <axis xyz="1 0 0"/>
       <limit effort="0.0" lower="-3.14159" upper="3.14159" velocity="0.0"/>
    </joint>
    <joint name="Leg3_Leg4" type="revolute">
       <parent link="Leg3"/>
       <child  link="Leg4"/>
       <origin rpy="0 0 0" xyz="0 2.162657726830198 0" />
     <axis xyz="1 0 0"/>
       <limit effort="0.0" lower="-3.14159" upper="3.14159" velocity="0.0"/>
    </joint>
    <joint name="Leg4_Leg5" type="revolute">
       <parent link="Leg4"/>
       <child  link="Leg5"/>
       <origin rpy="0 0 0" xyz="0 2.11297426759333 0" />
     <axis xyz="1 0 0"/>
       <limit effort="0.0" lower="-3.14159" upper="3.14159" velocity="0.0"/>
    </joint>
    <joint name="Leg1_Leg6" type="revolute">
       <parent link="Leg1"/>
       <child  link="Leg6"/>
       <origin rpy="0 0 0" xyz="0.9499198463003364 1.601421519408692 0" />
     <axis xyz="1 0 0"/>
       <limit effort="0.0" lower="-3.14159" upper="3.14159" velocity="0.0"/>
    </joint>
    <joint name="Leg2_Leg7" type="revolute">
       <parent link="Leg2"/>
       <child  link="Leg7"/>
       <origin rpy="0 0 0" xyz="0 2.9872395216137013 1.3384856275711634" />
     <axis xyz="1 0 0"/>
       <limit effort="0.0" lower="-3.14159" upper="3.14159" velocity="0.0"/>
    </joint>
    <joint name="Leg7_Leg8" type="revolute">
       <parent link="Leg7"/>
       <child  link="Leg8"/>
       <origin rpy="0 0 0" xyz="2.007586458126795 0 0" />
     <axis xyz="1 0 0"/>
       <limit effort="0.0" lower="-3.14159" upper="3.14159" velocity="0.0"/>
    </joint>
    <joint name="Leg7_Leg9" type="revolute">
       <parent link="Leg7"/>
       <child  link="Leg9"/>
       <origin rpy="0 0 0" xyz="2.007586458126795 0.782274361589511 0" />
     <axis xyz="1 0 0"/>
       <limit effort="0.0" lower="-3.14159" upper="3.14159" velocity="0.0"/>
    </joint>
    <joint name="Torso_Leg10" type="revolute">
       <parent link="Torso"/>
       <child  link="Leg10"/>
       <origin rpy="0 0 0" xyz="0.5055571334434851 1.3751416629467803 0" />
     <axis xyz="1 0 0"/>
       <limit effort="0.0" lower="-3.14159" upper="3.14159" velocity="0.0"/>
    </joint>
    <joint name="Leg10_Leg11" type="revolute">
       <parent link="Leg10"/>
       <child  link="Leg11"/>
       <origin rpy="0 0 0" xyz="0 0 1.9790853468207945" />
     <axis xyz="1 0 0"/>
       <limit effort="0.0" lower="-3.14159" upper="3.14159" velocity="0.0"/>
    </joint>
    <joint name="Leg10_Leg12" type="revolute">
       <parent link="Leg10"/>
       <child  link="Leg12"/>
       <origin rpy="0 0 0" xyz="1.3440362074268326 0 1.9790853468207945" />
     <axis xyz="1 0 0"/>
       <limit effort="0.0" lower="-3.14159" upper="3.14159" velocity="0.0"/>
    </joint>
    <joint name="Leg9_Leg13" type="revolute">
       <parent link="Leg9"/>
       <child  link="Leg13"/>
       <origin rpy="0 0 0" xyz="0.8538838499323156 0.8517240516039927 0" />
     <axis xyz="1 0 0"/>
       <limit effort="0.0" lower="-3.14159" upper="3.14159" velocity="0.0"/>
    </joint>
    <joint name="Leg13_Leg14" type="revolute">
       <parent link="Leg13"/>
       <child  link="Leg14"/>
       <origin rpy="0 0 0" xyz="0 2.28616686432472 0" />
     <axis xyz="1 0 0"/>
       <limit effort="0.0" lower="-3.14159" upper="3.14159" velocity="0.0"/>
    </joint>
    <joint name="Leg14_Leg15" type="revolute">
       <parent link="Leg14"/>
       <child  link="Leg15"/>
       <origin rpy="0 0 0" xyz="0 1.3363502039804043 0" />
     <axis xyz="1 0 0"/>
       <limit effort="0.0" lower="-3.14159" upper="3.14159" velocity="0.0"/>
    </joint>
    <joint name="Leg2_Leg16" type="revolute">
       <parent link="Leg2"/>
       <child  link="Leg16"/>
       <origin rpy="0 0 0" xyz="0.5138364517953207 2.9872395216137013 1.3384856275711634" />
     <axis xyz="1 0 0"/>
       <limit effort="0.0" lower="-3.14159" upper="3.14159" velocity="0.0"/>
    </joint>
    <joint name="Leg16_Leg17" type="revolute">
       <parent link="Leg16"/>
       <child  link="Leg17"/>
       <origin rpy="0 0 0" xyz="0 1.0955375723916987 0" />
     <axis xyz="1 0 0"/>
       <limit effort="0.0" lower="-3.14159" upper="3.14159" velocity="0.0"/>
    </joint>
    <joint name="Leg14_Leg18" type="revolute">
       <parent link="Leg14"/>
       <child  link="Leg18"/>
       <origin rpy="0 0 0" xyz="1.063757712453344 1.3363502039804043 0" />
     <axis xyz="1 0 0"/>
       <limit effort="0.0" lower="-3.14159" upper="3.14159" velocity="0.0"/>
    </joint>
    <joint name="Leg8_Leg19" type="revolute">
       <parent link="Leg8"/>
       <child  link="Leg19"/>
       <origin rpy="0 0 0" xyz="1.2376854254193699 1.381839248402489 0" />
     <axis xyz="1 0 0"/>
       <limit effort="0.0" lower="-3.14159" upper="3.14159" velocity="0.0"/>
    </joint>
    <joint name="Leg18_Leg20" type="revolute">
       <parent link="Leg18"/>
       <child  link="Leg20"/>
       <origin rpy="0 0 0" xyz="0.6007771214122134 0 1.3085999475552543" />
     <axis xyz="1 0 0"/>
       <limit effort="0.0" lower="-3.14159" upper="3.14159" velocity="0.0"/>
    </joint>
    <joint name="Leg17_Leg21" type="revolute">
       <parent link="Leg17"/>
       <child  link="Leg21"/>
       <origin rpy="0 0 0" xyz="1.027315702837918 1.0946162976005924 0" />
     <axis xyz="1 0 0"/>
       <limit effort="0.0" lower="-3.14159" upper="3.14159" velocity="0.0"/>
    </joint>
    <joint name="Leg15_Leg22" type="revolute">
       <parent link="Leg15"/>
       <child  link="Leg22"/>
       <origin rpy="0 0 0" xyz="2.6678022526186504 0 0" />
     <axis xyz="1 0 0"/>
       <limit effort="0.0" lower="-3.14159" upper="3.14159" velocity="0.0"/>
    </joint>
    <joint name="Leg18_Leg23" type="revolute">
       <parent link="Leg18"/>
       <child  link="Leg23"/>
       <origin rpy="0 0 0" xyz="0.6007771214122134 0.6090190180466043 1.3085999475552543" />
     <axis xyz="1 0 0"/>
       <limit effort="0.0" lower="-3.14159" upper="3.14159" velocity="0.0"/>
    </joint>
    <joint name="Leg11_Leg24" type="revolute">
       <parent link="Leg11"/>
       <child  link="Leg24"/>
       <origin rpy="0 0 0" xyz="2.9500537984356248 0 0" />
     <axis xyz="1 0 0"/>
       <limit effort="0.0" lower="-3.14159" upper="3.14159" velocity="0.0"/>
    </joint>
</robot>