<robot name = "robot">
    <link name="Torso">
        <inertial>
            <origin xyz="0 0 1.3274804090896866" rpy="0 0 0"/>
            <mass value="1" />
            <inertia ixx="100" ixy="0" ixz="0" iyy="100" iyz="0" izz="100" />
        </inertial>
        <visual>
            <origin xyz="0 0 1.3274804090896866" rpy="0 0 0"/>
            <geometry>
                <box size="1.2739120229384844 2.100027692003815 2.654960818179373" />
            </geometry>
            <material name="Green">
                <color rgba="0 180.0 0.0 1.0"/>
            </material>
        </visual>
        <collision>
            <origin xyz="0 0 1.3274804090896866" rpy="0 0 0"/>
            <geometry>
                <box size="1.2739120229384844 2.100027692003815 2.654960818179373" />
            </geometry>
        </collision>
    </link>
    <link name="Leg1">
        <inertial>
            <origin xyz="0 1.2763689389883677 0" rpy="0 0 0"/>
            <mass value="1" />
            <inertia ixx="100" ixy="0" ixz="0" iyy="100" iyz="0" izz="100" />
        </inertial>
        <visual>
            <origin xyz="0 1.2763689389883677 0" rpy="0 0 0"/>
            <geometry>
                <box size="1.98779149211369 2.5527378779767353 1.5011187033700923" />
            </geometry>
            <material name="Blue">
                <color rgba="0 1.0 1.0 1.0"/>
            </material>
        </visual>
        <collision>
            <origin xyz="0 1.2763689389883677 0" rpy="0 0 0"/>
            <geometry>
                <box size="1.98779149211369 2.5527378779767353 1.5011187033700923" />
            </geometry>
        </collision>
    </link>
    <link name="Leg2">
        <inertial>
            <origin xyz="0.5926504869399386 0 0" rpy="0 0 0"/>
            <mass value="1" />
            <inertia ixx="100" ixy="0" ixz="0" iyy="100" iyz="0" izz="100" />
        </inertial>
        <visual>
            <origin xyz="0.5926504869399386 0 0" rpy="0 0 0"/>
            <geometry>
                <box size="1.1853009738798772 2.7101231553134855 1.8610303788621618" />
            </geometry>
            <material name="Blue">
                <color rgba="0 1.0 1.0 1.0"/>
            </material>
        </visual>
        <collision>
            <origin xyz="0.5926504869399386 0 0" rpy="0 0 0"/>
            <geometry>
                <box size="1.1853009738798772 2.7101231553134855 1.8610303788621618" />
            </geometry>
        </collision>
    </link>
    <link name="Leg3">
        <inertial>
            <origin xyz="0.7460356859790882 0 0" rpy="0 0 0"/>
            <mass value="1" />
            <inertia ixx="100" ixy="0" ixz="0" iyy="100" iyz="0" izz="100" />
        </inertial>
        <visual>
            <origin xyz="0.7460356859790882 0 0" rpy="0 0 0"/>
            <geometry>
                <box size="1.4920713719581764 1.1014520848446931 2.4514296564940263" />
            </geometry>
            <material name="Green">
                <color rgba="0 180.0 0.0 1.0"/>
            </material>
        </visual>
        <collision>
            <origin xyz="0.7460356859790882 0 0" rpy="0 0 0"/>
            <geometry>
                <box size="1.4920713719581764 1.1014520848446931 2.4514296564940263" />
            </geometry>
        </collision>
    </link>
    <link name="Leg4">
        <inertial>
            <origin xyz="0 1.4169385125513878 0" rpy="0 0 0"/>
            <mass value="1" />
            <inertia ixx="100" ixy="0" ixz="0" iyy="100" iyz="0" izz="100" />
        </inertial>
        <visual>
            <origin xyz="0 1.4169385125513878 0" rpy="0 0 0"/>
            <geometry>
                <box size="1.6546403721930467 2.8338770251027756 2.152868886209887" />
            </geometry>
            <material name="Blue">
                <color rgba="0 1.0 1.0 1.0"/>
            </material>
        </visual>
        <collision>
            <origin xyz="0 1.4169385125513878 0" rpy="0 0 0"/>
            <geometry>
                <box size="1.6546403721930467 2.8338770251027756 2.152868886209887" />
            </geometry>
        </collision>
    </link>
    <link name="Leg5">
        <inertial>
            <origin xyz="0 0 0.671081718536677" rpy="0 0 0"/>
            <mass value="1" />
            <inertia ixx="100" ixy="0" ixz="0" iyy="100" iyz="0" izz="100" />
        </inertial>
        <visual>
            <origin xyz="0 0 0.671081718536677" rpy="0 0 0"/>
            <geometry>
                <box size="1.8870557323118264 1.8124364329156029 1.342163437073354" />
            </geometry>
            <material name="Blue">
                <color rgba="0 1.0 1.0 1.0"/>
            </material>
        </visual>
        <collision>
            <origin xyz="0 0 0.671081718536677" rpy="0 0 0"/>
            <geometry>
                <box size="1.8870557323118264 1.8124364329156029 1.342163437073354" />
            </geometry>
        </collision>
    </link>
    <link name="Leg6">
        <inertial>
            <origin xyz="0 0.6677323860231426 0" rpy="0 0 0"/>
            <mass value="1" />
            <inertia ixx="100" ixy="0" ixz="0" iyy="100" iyz="0" izz="100" />
        </inertial>
        <visual>
            <origin xyz="0 0.6677323860231426 0" rpy="0 0 0"/>
            <geometry>
                <box size="2.1032550517568414 1.335464772046285 2.959320391325691" />
            </geometry>
            <material name="Green">
                <color rgba="0 180.0 0.0 1.0"/>
            </material>
        </visual>
        <collision>
            <origin xyz="0 0.6677323860231426 0" rpy="0 0 0"/>
            <geometry>
                <box size="2.1032550517568414 1.335464772046285 2.959320391325691" />
            </geometry>
        </collision>
    </link>
    <link name="Leg7">
        <inertial>
            <origin xyz="1.4244087241029946 0 0" rpy="0 0 0"/>
            <mass value="1" />
            <inertia ixx="100" ixy="0" ixz="0" iyy="100" iyz="0" izz="100" />
        </inertial>
        <visual>
            <origin xyz="1.4244087241029946 0 0" rpy="0 0 0"/>
            <geometry>
                <box size="2.848817448205989 1.8216875941980968 2.077621300790362" />
            </geometry>
            <material name="Blue">
                <color rgba="0 1.0 1.0 1.0"/>
            </material>
        </visual>
        <collision>
            <origin xyz="1.4244087241029946 0 0" rpy="0 0 0"/>
            <geometry>
                <box size="2.848817448205989 1.8216875941980968 2.077621300790362" />
            </geometry>
        </collision>
    </link>
    <link name="Leg8">
        <inertial>
            <origin xyz="0 0 1.3620256155658095" rpy="0 0 0"/>
            <mass value="1" />
            <inertia ixx="100" ixy="0" ixz="0" iyy="100" iyz="0" izz="100" />
        </inertial>
        <visual>
            <origin xyz="0 0 1.3620256155658095" rpy="0 0 0"/>
            <geometry>
                <box size="2.9704040920605594 2.1508413169348763 2.724051231131619" />
            </geometry>
            <material name="Green">
                <color rgba="0 180.0 0.0 1.0"/>
            </material>
        </visual>
        <collision>
            <origin xyz="0 0 1.3620256155658095" rpy="0 0 0"/>
            <geometry>
                <box size="2.9704040920605594 2.1508413169348763 2.724051231131619" />
            </geometry>
        </collision>
    </link>
    <link name="Leg9">
        <inertial>
            <origin xyz="0 1.3450734846918322 0" rpy="0 0 0"/>
            <mass value="1" />
            <inertia ixx="100" ixy="0" ixz="0" iyy="100" iyz="0" izz="100" />
        </inertial>
        <visual>
            <origin xyz="0 1.3450734846918322 0" rpy="0 0 0"/>
            <geometry>
                <box size="1.5484886297324205 2.6901469693836644 2.2204294715158865" />
            </geometry>
            <material name="Blue">
                <color rgba="0 1.0 1.0 1.0"/>
            </material>
        </visual>
        <collision>
            <origin xyz="0 1.3450734846918322 0" rpy="0 0 0"/>
            <geometry>
                <box size="1.5484886297324205 2.6901469693836644 2.2204294715158865" />
            </geometry>
        </collision>
    </link>
    <link name="Leg10">
        <inertial>
            <origin xyz="0 0.6917413330924767 0" rpy="0 0 0"/>
            <mass value="1" />
            <inertia ixx="100" ixy="0" ixz="0" iyy="100" iyz="0" izz="100" />
        </inertial>
        <visual>
            <origin xyz="0 0.6917413330924767 0" rpy="0 0 0"/>
            <geometry>
                <box size="2.49949066838045 1.3834826661849533 2.2155414312155877" />
            </geometry>
            <material name="Green">
                <color rgba="0 180.0 0.0 1.0"/>
            </material>
        </visual>
        <collision>
            <origin xyz="0 0.6917413330924767 0" rpy="0 0 0"/>
            <geometry>
                <box size="2.49949066838045 1.3834826661849533 2.2155414312155877" />
            </geometry>
        </collision>
    </link>
    <link name="Leg11">
        <inertial>
            <origin xyz="0 0 0.8774739810134795" rpy="0 0 0"/>
            <mass value="1" />
            <inertia ixx="100" ixy="0" ixz="0" iyy="100" iyz="0" izz="100" />
        </inertial>
        <visual>
            <origin xyz="0 0 0.8774739810134795" rpy="0 0 0"/>
            <geometry>
                <box size="1.372763268367731 2.9092434276783967 1.754947962026959" />
            </geometry>
            <material name="Blue">
                <color rgba="0 1.0 1.0 1.0"/>
            </material>
        </visual>
        <collision>
            <origin xyz="0 0 0.8774739810134795" rpy="0 0 0"/>
            <geometry>
                <box size="1.372763268367731 2.9092434276783967 1.754947962026959" />
            </geometry>
        </collision>
    </link>
    <link name="Leg12">
        <inertial>
            <origin xyz="0.5654115322688321 0 0" rpy="0 0 0"/>
            <mass value="1" />
            <inertia ixx="100" ixy="0" ixz="0" iyy="100" iyz="0" izz="100" />
        </inertial>
        <visual>
            <origin xyz="0.5654115322688321 0 0" rpy="0 0 0"/>
            <geometry>
                <box size="1.1308230645376642 1.9028677778490501 1.6181106798909775" />
            </geometry>
            <material name="Blue">
                <color rgba="0 1.0 1.0 1.0"/>
            </material>
        </visual>
        <collision>
            <origin xyz="0.5654115322688321 0 0" rpy="0 0 0"/>
            <geometry>
                <box size="1.1308230645376642 1.9028677778490501 1.6181106798909775" />
            </geometry>
        </collision>
    </link>
    <link name="Leg13">
        <inertial>
            <origin xyz="0.6956413904470998 0 0" rpy="0 0 0"/>
            <mass value="1" />
            <inertia ixx="100" ixy="0" ixz="0" iyy="100" iyz="0" izz="100" />
        </inertial>
        <visual>
            <origin xyz="0.6956413904470998 0 0" rpy="0 0 0"/>
            <geometry>
                <box size="1.3912827808941997 1.93915678323633 1.934737046306899" />
            </geometry>
            <material name="Green">
                <color rgba="0 180.0 0.0 1.0"/>
            </material>
        </visual>
        <collision>
            <origin xyz="0.6956413904470998 0 0" rpy="0 0 0"/>
            <geometry>
                <box size="1.3912827808941997 1.93915678323633 1.934737046306899" />
            </geometry>
        </collision>
    </link>
    <link name="Leg14">
        <inertial>
            <origin xyz="1.158559331096749 0 0" rpy="0 0 0"/>
            <mass value="1" />
            <inertia ixx="100" ixy="0" ixz="0" iyy="100" iyz="0" izz="100" />
        </inertial>
        <visual>
            <origin xyz="1.158559331096749 0 0" rpy="0 0 0"/>
            <geometry>
                <box size="2.317118662193498 2.5000695590242232 2.8555513509590034" />
            </geometry>
            <material name="Green">
                <color rgba="0 180.0 0.0 1.0"/>
            </material>
        </visual>
        <collision>
            <origin xyz="1.158559331096749 0 0" rpy="0 0 0"/>
            <geometry>
                <box size="2.317118662193498 2.5000695590242232 2.8555513509590034" />
            </geometry>
        </collision>
    </link>
    <link name="Leg15">
        <inertial>
            <origin xyz="0 0.5485764108829788 0" rpy="0 0 0"/>
            <mass value="1" />
            <inertia ixx="100" ixy="0" ixz="0" iyy="100" iyz="0" izz="100" />
        </inertial>
        <visual>
            <origin xyz="0 0.5485764108829788 0" rpy="0 0 0"/>
            <geometry>
                <box size="2.7824071052957917 1.0971528217659576 1.091342192751459" />
            </geometry>
            <material name="Green">
                <color rgba="0 180.0 0.0 1.0"/>
            </material>
        </visual>
        <collision>
            <origin xyz="0 0.5485764108829788 0" rpy="0 0 0"/>
            <geometry>
                <box size="2.7824071052957917 1.0971528217659576 1.091342192751459" />
            </geometry>
        </collision>
    </link>
    <link name="Leg16">
        <inertial>
            <origin xyz="0.9213211422262267 0 0" rpy="0 0 0"/>
            <mass value="1" />
            <inertia ixx="100" ixy="0" ixz="0" iyy="100" iyz="0" izz="100" />
        </inertial>
        <visual>
            <origin xyz="0.9213211422262267 0 0" rpy="0 0 0"/>
            <geometry>
                <box size="1.8426422844524535 2.0594374472770873 1.2707493686714622" />
            </geometry>
            <material name="Blue">
                <color rgba="0 1.0 1.0 1.0"/>
            </material>
        </visual>
        <collision>
            <origin xyz="0.9213211422262267 0 0" rpy="0 0 0"/>
            <geometry>
                <box size="1.8426422844524535 2.0594374472770873 1.2707493686714622" />
            </geometry>
        </collision>
    </link>
    <link name="Leg17">
        <inertial>
            <origin xyz="0 0.9269305735640655 0" rpy="0 0 0"/>
            <mass value="1" />
            <inertia ixx="100" ixy="0" ixz="0" iyy="100" iyz="0" izz="100" />
        </inertial>
        <visual>
            <origin xyz="0 0.9269305735640655 0" rpy="0 0 0"/>
            <geometry>
                <box size="1.2397174071900214 1.853861147128131 1.4832807004424597" />
            </geometry>
            <material name="Green">
                <color rgba="0 180.0 0.0 1.0"/>
            </material>
        </visual>
        <collision>
            <origin xyz="0 0.9269305735640655 0" rpy="0 0 0"/>
            <geometry>
                <box size="1.2397174071900214 1.853861147128131 1.4832807004424597" />
            </geometry>
        </collision>
    </link>
    <link name="Leg18">
        <inertial>
            <origin xyz="0 0 1.0630228921579346" rpy="0 0 0"/>
            <mass value="1" />
            <inertia ixx="100" ixy="0" ixz="0" iyy="100" iyz="0" izz="100" />
        </inertial>
        <visual>
            <origin xyz="0 0 1.0630228921579346" rpy="0 0 0"/>
            <geometry>
                <box size="2.693524230882122 1.9332102344103728 2.126045784315869" />
            </geometry>
            <material name="Blue">
                <color rgba="0 1.0 1.0 1.0"/>
            </material>
        </visual>
        <collision>
            <origin xyz="0 0 1.0630228921579346" rpy="0 0 0"/>
            <geometry>
                <box size="2.693524230882122 1.9332102344103728 2.126045784315869" />
            </geometry>
        </collision>
    </link>
    <link name="Leg19">
        <inertial>
            <origin xyz="0 0 0.705160030903606" rpy="0 0 0"/>
            <mass value="1" />
            <inertia ixx="100" ixy="0" ixz="0" iyy="100" iyz="0" izz="100" />
        </inertial>
        <visual>
            <origin xyz="0 0 0.705160030903606" rpy="0 0 0"/>
            <geometry>
                <box size="1.1743189292250087 1.4940330249305354 1.410320061807212" />
            </geometry>
            <material name="Blue">
                <color rgba="0 1.0 1.0 1.0"/>
            </material>
        </visual>
        <collision>
            <origin xyz="0 0 0.705160030903606" rpy="0 0 0"/>
            <geometry>
                <box size="1.1743189292250087 1.4940330249305354 1.410320061807212" />
            </geometry>
        </collision>
    </link>
    <link name="Leg20">
        <inertial>
            <origin xyz="0 0 0.591689443868853" rpy="0 0 0"/>
            <mass value="1" />
            <inertia ixx="100" ixy="0" ixz="0" iyy="100" iyz="0" izz="100" />
        </inertial>
        <visual>
            <origin xyz="0 0 0.591689443868853" rpy="0 0 0"/>
            <geometry>
                <box size="2.3484220177164237 1.8241272445217562 1.183378887737706" />
            </geometry>
            <material name="Green">
                <color rgba="0 180.0 0.0 1.0"/>
            </material>
        </visual>
        <collision>
            <origin xyz="0 0 0.591689443868853" rpy="0 0 0"/>
            <geometry>
                <box size="2.3484220177164237 1.8241272445217562 1.183378887737706" />
            </geometry>
        </collision>
    </link>
    <link name="Leg21">
        <inertial>
            <origin xyz="0 0.677667538220123 0" rpy="0 0 0"/>
            <mass value="1" />
            <inertia ixx="100" ixy="0" ixz="0" iyy="100" iyz="0" izz="100" />
        </inertial>
        <visual>
            <origin xyz="0 0.677667538220123 0" rpy="0 0 0"/>
            <geometry>
                <box size="1.746122470025381 1.355335076440246 1.1226108409813675" />
            </geometry>
            <material name="Blue">
                <color rgba="0 1.0 1.0 1.0"/>
            </material>
        </visual>
        <collision>
            <origin xyz="0 0.677667538220123 0" rpy="0 0 0"/>
            <geometry>
                <box size="1.746122470025381 1.355335076440246 1.1226108409813675" />
            </geometry>
        </collision>
    </link>
    <link name="Leg22">
        <inertial>
            <origin xyz="0 0.7686612825735292 0" rpy="0 0 0"/>
            <mass value="1" />
            <inertia ixx="100" ixy="0" ixz="0" iyy="100" iyz="0" izz="100" />
        </inertial>
        <visual>
            <origin xyz="0 0.7686612825735292 0" rpy="0 0 0"/>
            <geometry>
                <box size="2.573670985630329 1.5373225651470583 2.7196894290446068" />
            </geometry>
            <material name="Green">
                <color rgba="0 180.0 0.0 1.0"/>
            </material>
        </visual>
        <collision>
            <origin xyz="0 0.7686612825735292 0" rpy="0 0 0"/>
            <geometry>
                <box size="2.573670985630329 1.5373225651470583 2.7196894290446068" />
            </geometry>
        </collision>
    </link>
    <link name="Leg23">
        <inertial>
            <origin xyz="0 0 1.3141541121440747" rpy="0 0 0"/>
            <mass value="1" />
            <inertia ixx="100" ixy="0" ixz="0" iyy="100" iyz="0" izz="100" />
        </inertial>
        <visual>
            <origin xyz="0 0 1.3141541121440747" rpy="0 0 0"/>
            <geometry>
                <box size="1.8583385085596797 2.774871309845151 2.6283082242881495" />
            </geometry>
            <material name="Blue">
                <color rgba="0 1.0 1.0 1.0"/>
            </material>
        </visual>
        <collision>
            <origin xyz="0 0 1.3141541121440747" rpy="0 0 0"/>
            <geometry>
                <box size="1.8583385085596797 2.774871309845151 2.6283082242881495" />
            </geometry>
        </collision>
    </link>
    <link name="Leg24">
        <inertial>
            <origin xyz="0 1.167602538502126 0" rpy="0 0 0"/>
            <mass value="1" />
            <inertia ixx="100" ixy="0" ixz="0" iyy="100" iyz="0" izz="100" />
        </inertial>
        <visual>
            <origin xyz="0 1.167602538502126 0" rpy="0 0 0"/>
            <geometry>
                <box size="1.1885454184527546 2.335205077004252 1.7469797522477224" />
            </geometry>
            <material name="Green">
                <color rgba="0 180.0 0.0 1.0"/>
            </material>
        </visual>
        <collision>
            <origin xyz="0 1.167602538502126 0" rpy="0 0 0"/>
            <geometry>
                <box size="1.1885454184527546 2.335205077004252 1.7469797522477224" />
            </geometry>
        </collision>
    </link>
    <link name="Leg25">
        <inertial>
            <origin xyz="0 0 0.9364052098746081" rpy="0 0 0"/>
            <mass value="1" />
            <inertia ixx="100" ixy="0" ixz="0" iyy="100" iyz="0" izz="100" />
        </inertial>
        <visual>
            <origin xyz="0 0 0.9364052098746081" rpy="0 0 0"/>
            <geometry>
                <box size="2.8710002128133554 2.5272463374550718 1.8728104197492161" />
            </geometry>
            <material name="Blue">
                <color rgba="0 1.0 1.0 1.0"/>
            </material>
        </visual>
        <collision>
            <origin xyz="0 0 0.9364052098746081" rpy="0 0 0"/>
            <geometry>
                <box size="2.8710002128133554 2.5272463374550718 1.8728104197492161" />
            </geometry>
        </collision>
    </link>
    <link name="Leg26">
        <inertial>
            <origin xyz="0.8912297071368922 0 0" rpy="0 0 0"/>
            <mass value="1" />
            <inertia ixx="100" ixy="0" ixz="0" iyy="100" iyz="0" izz="100" />
        </inertial>
        <visual>
            <origin xyz="0.8912297071368922 0 0" rpy="0 0 0"/>
            <geometry>
                <box size="1.7824594142737844 1.6063200517322624 2.3551670702157166" />
            </geometry>
            <material name="Blue">
                <color rgba="0 1.0 1.0 1.0"/>
            </material>
        </visual>
        <collision>
            <origin xyz="0.8912297071368922 0 0" rpy="0 0 0"/>
            <geometry>
                <box size="1.7824594142737844 1.6063200517322624 2.3551670702157166" />
            </geometry>
        </collision>
    </link>
    <link name="Leg27">
        <inertial>
            <origin xyz="0 0 1.2053699573837866" rpy="0 0 0"/>
            <mass value="1" />
            <inertia ixx="100" ixy="0" ixz="0" iyy="100" iyz="0" izz="100" />
        </inertial>
        <visual>
            <origin xyz="0 0 1.2053699573837866" rpy="0 0 0"/>
            <geometry>
                <box size="1.6228016682795623 2.23688357927371 2.410739914767573" />
            </geometry>
            <material name="Green">
                <color rgba="0 180.0 0.0 1.0"/>
            </material>
        </visual>
        <collision>
            <origin xyz="0 0 1.2053699573837866" rpy="0 0 0"/>
            <geometry>
                <box size="1.6228016682795623 2.23688357927371 2.410739914767573" />
            </geometry>
        </collision>
    </link>
    <joint name="Torso_Leg1" type="revolute">
       <parent link="Torso"/>
       <child  link="Leg1"/>
       <origin rpy="0 0 0" xyz="0 1.0500138460019075 1.3274804090896866" />
     <axis xyz="1 0 0"/>
       <limit effort="0.0" lower="-3.14159" upper="3.14159" velocity="0.0"/>
    </joint>
    <joint name="Leg1_Leg2" type="revolute">
       <parent link="Leg1"/>
       <child  link="Leg2"/>
       <origin rpy="0 0 0" xyz="1.1853009738798772 0 0" />
     <axis xyz="1 0 0"/>
       <limit effort="0.0" lower="-3.14159" upper="3.14159" velocity="0.0"/>
    </joint>
    <joint name="Leg2_Leg3" type="revolute">
       <parent link="Leg2"/>
       <child  link="Leg3"/>
       <origin rpy="0 0 0" xyz="1.4920713719581764 0 0" />
     <axis xyz="1 0 0"/>
       <limit effort="0.0" lower="-3.14159" upper="3.14159" velocity="0.0"/>
    </joint>
    <joint name="Leg2_Leg4" type="revolute">
       <parent link="Leg2"/>
       <child  link="Leg4"/>
       <origin rpy="0 0 0" xyz="1.4920713719581764 0.5507260424223466 0" />
     <axis xyz="1 0 0"/>
       <limit effort="0.0" lower="-3.14159" upper="3.14159" velocity="0.0"/>
    </joint>
    <joint name="Leg1_Leg5" type="revolute">
       <parent link="Leg1"/>
       <child  link="Leg5"/>
       <origin rpy="0 0 0" xyz="1.1853009738798772 0 0.9305151894310809" />
     <axis xyz="1 0 0"/>
       <limit effort="0.0" lower="-3.14159" upper="3.14159" velocity="0.0"/>
    </joint>
    <joint name="Leg1_Leg6" type="revolute">
       <parent link="Leg1"/>
       <child  link="Leg6"/>
       <origin rpy="0 0 0" xyz="1.1853009738798772 1.3550615776567427 0.9305151894310809" />
     <axis xyz="1 0 0"/>
       <limit effort="0.0" lower="-3.14159" upper="3.14159" velocity="0.0"/>
    </joint>
    <joint name="Leg3_Leg7" type="revolute">
       <parent link="Leg3"/>
       <child  link="Leg7"/>
       <origin rpy="0 0 0" xyz="0.8273201860965234 1.4169385125513878 0" />
     <axis xyz="1 0 0"/>
       <limit effort="0.0" lower="-3.14159" upper="3.14159" velocity="0.0"/>
    </joint>
    <joint name="Leg6_Leg8" type="revolute">
       <parent link="Leg6"/>
       <child  link="Leg8"/>
       <origin rpy="0 0 0" xyz="1.4244087241029946 0 1.038810650395181" />
     <axis xyz="1 0 0"/>
       <limit effort="0.0" lower="-3.14159" upper="3.14159" velocity="0.0"/>
    </joint>
    <joint name="Leg3_Leg9" type="revolute">
       <parent link="Leg3"/>
       <child  link="Leg9"/>
       <origin rpy="0 0 0" xyz="0.8273201860965234 2.8338770251027756 0" />
     <axis xyz="1 0 0"/>
       <limit effort="0.0" lower="-3.14159" upper="3.14159" velocity="0.0"/>
    </joint>
    <joint name="Leg7_Leg10" type="revolute">
       <parent link="Leg7"/>
       <child  link="Leg10"/>
       <origin rpy="0 0 0" xyz="0 1.0754206584674382 1.3620256155658095" />
     <axis xyz="1 0 0"/>
       <limit effort="0.0" lower="-3.14159" upper="3.14159" velocity="0.0"/>
    </joint>
    <joint name="Leg8_Leg11" type="revolute">
       <parent link="Leg8"/>
       <child  link="Leg11"/>
       <origin rpy="0 0 0" xyz="0 1.3450734846918322 1.1102147357579433" />
     <axis xyz="1 0 0"/>
       <limit effort="0.0" lower="-3.14159" upper="3.14159" velocity="0.0"/>
    </joint>
    <joint name="Leg10_Leg12" type="revolute">
       <parent link="Leg10"/>
       <child  link="Leg12"/>
       <origin rpy="0 0 0" xyz="0.6863816341838656 0 0.8774739810134795" />
     <axis xyz="1 0 0"/>
       <limit effort="0.0" lower="-3.14159" upper="3.14159" velocity="0.0"/>
    </joint>
    <joint name="Leg8_Leg13" type="revolute">
       <parent link="Leg8"/>
       <child  link="Leg13"/>
       <origin rpy="0 0 0" xyz="0.7742443148662103 1.3450734846918322 1.1102147357579433" />
     <axis xyz="1 0 0"/>
       <limit effort="0.0" lower="-3.14159" upper="3.14159" velocity="0.0"/>
    </joint>
    <joint name="Leg9_Leg14" type="revolute">
       <parent link="Leg9"/>
       <child  link="Leg14"/>
       <origin rpy="0 0 0" xyz="1.249745334190225 0.6917413330924767 0" />
     <axis xyz="1 0 0"/>
       <limit effort="0.0" lower="-3.14159" upper="3.14159" velocity="0.0"/>
    </joint>
    <joint name="Leg8_Leg15" type="revolute">
       <parent link="Leg8"/>
       <child  link="Leg15"/>
       <origin rpy="0 0 0" xyz="0.7742443148662103 2.6901469693836644 1.1102147357579433" />
     <axis xyz="1 0 0"/>
       <limit effort="0.0" lower="-3.14159" upper="3.14159" velocity="0.0"/>
    </joint>
    <joint name="Leg14_Leg16" type="revolute">
       <parent link="Leg14"/>
       <child  link="Leg16"/>
       <origin rpy="0 0 0" xyz="1.3912035526478959 0.5485764108829788 0" />
     <axis xyz="1 0 0"/>
       <limit effort="0.0" lower="-3.14159" upper="3.14159" velocity="0.0"/>
    </joint>
    <joint name="Leg13_Leg17" type="revolute">
       <parent link="Leg13"/>
       <child  link="Leg17"/>
       <origin rpy="0 0 0" xyz="1.158559331096749 1.2500347795121116 0" />
     <axis xyz="1 0 0"/>
       <limit effort="0.0" lower="-3.14159" upper="3.14159" velocity="0.0"/>
    </joint>
    <joint name="Leg2_Leg18" type="revolute">
       <parent link="Leg2"/>
       <child  link="Leg18"/>
       <origin rpy="0 0 0" xyz="1.4920713719581764 0.5507260424223466 1.2257148282470132" />
     <axis xyz="1 0 0"/>
       <limit effort="0.0" lower="-3.14159" upper="3.14159" velocity="0.0"/>
    </joint>
    <joint name="Leg3_Leg19" type="revolute">
       <parent link="Leg3"/>
       <child  link="Leg19"/>
       <origin rpy="0 0 0" xyz="0.8273201860965234 2.8338770251027756 1.0764344431049435" />
     <axis xyz="1 0 0"/>
       <limit effort="0.0" lower="-3.14159" upper="3.14159" velocity="0.0"/>
    </joint>
    <joint name="Leg15_Leg20" type="revolute">
       <parent link="Leg15"/>
       <child  link="Leg20"/>
       <origin rpy="0 0 0" xyz="0.9213211422262267 0 0.6353746843357311" />
     <axis xyz="1 0 0"/>
       <limit effort="0.0" lower="-3.14159" upper="3.14159" velocity="0.0"/>
    </joint>
    <joint name="Leg10_Leg21" type="revolute">
       <parent link="Leg10"/>
       <child  link="Leg21"/>
       <origin rpy="0 0 0" xyz="0.6863816341838656 1.4546217138391984 0.8774739810134795" />
     <axis xyz="1 0 0"/>
       <limit effort="0.0" lower="-3.14159" upper="3.14159" velocity="0.0"/>
    </joint>
    <joint name="Leg20_Leg22" type="revolute">
       <parent link="Leg20"/>
       <child  link="Leg22"/>
       <origin rpy="0 0 0" xyz="0 1.355335076440246 0" />
     <axis xyz="1 0 0"/>
       <limit effort="0.0" lower="-3.14159" upper="3.14159" velocity="0.0"/>
    </joint>
    <joint name="Leg13_Leg23" type="revolute">
       <parent link="Leg13"/>
       <child  link="Leg23"/>
       <origin rpy="0 0 0" xyz="1.158559331096749 1.2500347795121116 1.4277756754795017" />
     <axis xyz="1 0 0"/>
       <limit effort="0.0" lower="-3.14159" upper="3.14159" velocity="0.0"/>
    </joint>
    <joint name="Leg22_Leg24" type="revolute">
       <parent link="Leg22"/>
       <child  link="Leg24"/>
       <origin rpy="0 0 0" xyz="0 1.3874356549225755 1.3141541121440747" />
     <axis xyz="1 0 0"/>
       <limit effort="0.0" lower="-3.14159" upper="3.14159" velocity="0.0"/>
    </joint>
    <joint name="Leg19_Leg25" type="revolute">
       <parent link="Leg19"/>
       <child  link="Leg25"/>
       <origin rpy="0 0 0" xyz="0 0 1.183378887737706" />
     <axis xyz="1 0 0"/>
       <limit effort="0.0" lower="-3.14159" upper="3.14159" velocity="0.0"/>
    </joint>
    <joint name="Leg15_Leg26" type="revolute">
       <parent link="Leg15"/>
       <child  link="Leg26"/>
       <origin rpy="0 0 0" xyz="1.8426422844524535 0 0.6353746843357311" />
     <axis xyz="1 0 0"/>
       <limit effort="0.0" lower="-3.14159" upper="3.14159" velocity="0.0"/>
    </joint>
    <joint name="Leg7_Leg27" type="revolute">
       <parent link="Leg7"/>
       <child  link="Leg27"/>
       <origin rpy="0 0 0" xyz="0 1.0754206584674382 2.724051231131619" />
     <axis xyz="1 0 0"/>
       <limit effort="0.0" lower="-3.14159" upper="3.14159" velocity="0.0"/>
    </joint>
</robot>