<robot name = "robot">
    <link name="Torso">
        <inertial>
            <origin xyz="0 0 1.3077533381741409" rpy="0 0 0"/>
            <mass value="1" />
            <inertia ixx="100" ixy="0" ixz="0" iyy="100" iyz="0" izz="100" />
        </inertial>
        <visual>
            <origin xyz="0 0 1.3077533381741409" rpy="0 0 0"/>
            <geometry>
                <box size="2.174094252806526 2.086978837029622 2.6155066763482817" />
            </geometry>
            <material name="Green">
                <color rgba="0 180.0 0.0 1.0"/>
            </material>
        </visual>
        <collision>
            <origin xyz="0 0 1.3077533381741409" rpy="0 0 0"/>
            <geometry>
                <box size="2.174094252806526 2.086978837029622 2.6155066763482817" />
            </geometry>
        </collision>
    </link>
    <link name="Leg1">
        <inertial>
            <origin xyz="0 0.9137298399049424 0" rpy="0 0 0"/>
            <mass value="1" />
            <inertia ixx="100" ixy="0" ixz="0" iyy="100" iyz="0" izz="100" />
        </inertial>
        <visual>
            <origin xyz="0 0.9137298399049424 0" rpy="0 0 0"/>
            <geometry>
                <box size="1.4281470303443022 1.8274596798098848 2.2534032585477424" />
            </geometry>
            <material name="Green">
                <color rgba="0 180.0 0.0 1.0"/>
            </material>
        </visual>
        <collision>
            <origin xyz="0 0.9137298399049424 0" rpy="0 0 0"/>
            <geometry>
                <box size="1.4281470303443022 1.8274596798098848 2.2534032585477424" />
            </geometry>
        </collision>
    </link>
    <link name="Leg2">
        <inertial>
            <origin xyz="0.848518137090346 0 0" rpy="0 0 0"/>
            <mass value="1" />
            <inertia ixx="100" ixy="0" ixz="0" iyy="100" iyz="0" izz="100" />
        </inertial>
        <visual>
            <origin xyz="0.848518137090346 0 0" rpy="0 0 0"/>
            <geometry>
                <box size="1.697036274180692 2.1157726416516143 1.514040632905117" />
            </geometry>
            <material name="Green">
                <color rgba="0 180.0 0.0 1.0"/>
            </material>
        </visual>
        <collision>
            <origin xyz="0.848518137090346 0 0" rpy="0 0 0"/>
            <geometry>
                <box size="1.697036274180692 2.1157726416516143 1.514040632905117" />
            </geometry>
        </collision>
    </link>
    <link name="Leg3">
        <inertial>
            <origin xyz="0.5621954623813614 0 0" rpy="0 0 0"/>
            <mass value="1" />
            <inertia ixx="100" ixy="0" ixz="0" iyy="100" iyz="0" izz="100" />
        </inertial>
        <visual>
            <origin xyz="0.5621954623813614 0 0" rpy="0 0 0"/>
            <geometry>
                <box size="1.1243909247627228 1.156573405314738 1.2823006982983887" />
            </geometry>
            <material name="Green">
                <color rgba="0 180.0 0.0 1.0"/>
            </material>
        </visual>
        <collision>
            <origin xyz="0.5621954623813614 0 0" rpy="0 0 0"/>
            <geometry>
                <box size="1.1243909247627228 1.156573405314738 1.2823006982983887" />
            </geometry>
        </collision>
    </link>
    <link name="Leg4">
        <inertial>
            <origin xyz="0 0.9717928705192076 0" rpy="0 0 0"/>
            <mass value="1" />
            <inertia ixx="100" ixy="0" ixz="0" iyy="100" iyz="0" izz="100" />
        </inertial>
        <visual>
            <origin xyz="0 0.9717928705192076 0" rpy="0 0 0"/>
            <geometry>
                <box size="1.9860316514293743 1.9435857410384152 2.777925707372411" />
            </geometry>
            <material name="Blue">
                <color rgba="0 1.0 1.0 1.0"/>
            </material>
        </visual>
        <collision>
            <origin xyz="0 0.9717928705192076 0" rpy="0 0 0"/>
            <geometry>
                <box size="1.9860316514293743 1.9435857410384152 2.777925707372411" />
            </geometry>
        </collision>
    </link>
    <link name="Leg5">
        <inertial>
            <origin xyz="0 0 1.4668050601600617" rpy="0 0 0"/>
            <mass value="1" />
            <inertia ixx="100" ixy="0" ixz="0" iyy="100" iyz="0" izz="100" />
        </inertial>
        <visual>
            <origin xyz="0 0 1.4668050601600617" rpy="0 0 0"/>
            <geometry>
                <box size="2.537047792382741 1.6191584548550604 2.9336101203201235" />
            </geometry>
            <material name="Green">
                <color rgba="0 180.0 0.0 1.0"/>
            </material>
        </visual>
        <collision>
            <origin xyz="0 0 1.4668050601600617" rpy="0 0 0"/>
            <geometry>
                <box size="2.537047792382741 1.6191584548550604 2.9336101203201235" />
            </geometry>
        </collision>
    </link>
    <link name="Leg6">
        <inertial>
            <origin xyz="0 0 0.9455014728054265" rpy="0 0 0"/>
            <mass value="1" />
            <inertia ixx="100" ixy="0" ixz="0" iyy="100" iyz="0" izz="100" />
        </inertial>
        <visual>
            <origin xyz="0 0 0.9455014728054265" rpy="0 0 0"/>
            <geometry>
                <box size="2.20390178380404 1.6353849741820865 1.891002945610853" />
            </geometry>
            <material name="Blue">
                <color rgba="0 1.0 1.0 1.0"/>
            </material>
        </visual>
        <collision>
            <origin xyz="0 0 0.9455014728054265" rpy="0 0 0"/>
            <geometry>
                <box size="2.20390178380404 1.6353849741820865 1.891002945610853" />
            </geometry>
        </collision>
    </link>
    <link name="Leg7">
        <inertial>
            <origin xyz="1.4087959801965253 0 0" rpy="0 0 0"/>
            <mass value="1" />
            <inertia ixx="100" ixy="0" ixz="0" iyy="100" iyz="0" izz="100" />
        </inertial>
        <visual>
            <origin xyz="1.4087959801965253 0 0" rpy="0 0 0"/>
            <geometry>
                <box size="2.8175919603930506 2.814120084793589 2.5156717652879594" />
            </geometry>
            <material name="Green">
                <color rgba="0 180.0 0.0 1.0"/>
            </material>
        </visual>
        <collision>
            <origin xyz="1.4087959801965253 0 0" rpy="0 0 0"/>
            <geometry>
                <box size="2.8175919603930506 2.814120084793589 2.5156717652879594" />
            </geometry>
        </collision>
    </link>
    <link name="Leg8">
        <inertial>
            <origin xyz="1.2395698079170787 0 0" rpy="0 0 0"/>
            <mass value="1" />
            <inertia ixx="100" ixy="0" ixz="0" iyy="100" iyz="0" izz="100" />
        </inertial>
        <visual>
            <origin xyz="1.2395698079170787 0 0" rpy="0 0 0"/>
            <geometry>
                <box size="2.4791396158341574 2.6479333990693035 1.9634382145895537" />
            </geometry>
            <material name="Blue">
                <color rgba="0 1.0 1.0 1.0"/>
            </material>
        </visual>
        <collision>
            <origin xyz="1.2395698079170787 0 0" rpy="0 0 0"/>
            <geometry>
                <box size="2.4791396158341574 2.6479333990693035 1.9634382145895537" />
            </geometry>
        </collision>
    </link>
    <link name="Leg9">
        <inertial>
            <origin xyz="0 1.362312349441513 0" rpy="0 0 0"/>
            <mass value="1" />
            <inertia ixx="100" ixy="0" ixz="0" iyy="100" iyz="0" izz="100" />
        </inertial>
        <visual>
            <origin xyz="0 1.362312349441513 0" rpy="0 0 0"/>
            <geometry>
                <box size="1.195010070744673 2.724624698883026 2.355275665418316" />
            </geometry>
            <material name="Blue">
                <color rgba="0 1.0 1.0 1.0"/>
            </material>
        </visual>
        <collision>
            <origin xyz="0 1.362312349441513 0" rpy="0 0 0"/>
            <geometry>
                <box size="1.195010070744673 2.724624698883026 2.355275665418316" />
            </geometry>
        </collision>
    </link>
    <link name="Leg10">
        <inertial>
            <origin xyz="1.4343779724697194 0 0" rpy="0 0 0"/>
            <mass value="1" />
            <inertia ixx="100" ixy="0" ixz="0" iyy="100" iyz="0" izz="100" />
        </inertial>
        <visual>
            <origin xyz="1.4343779724697194 0 0" rpy="0 0 0"/>
            <geometry>
                <box size="2.868755944939439 1.5646950562499502 2.421436407038632" />
            </geometry>
            <material name="Green">
                <color rgba="0 180.0 0.0 1.0"/>
            </material>
        </visual>
        <collision>
            <origin xyz="1.4343779724697194 0 0" rpy="0 0 0"/>
            <geometry>
                <box size="2.868755944939439 1.5646950562499502 2.421436407038632" />
            </geometry>
        </collision>
    </link>
    <link name="Leg11">
        <inertial>
            <origin xyz="0 1.0875568037720615 0" rpy="0 0 0"/>
            <mass value="1" />
            <inertia ixx="100" ixy="0" ixz="0" iyy="100" iyz="0" izz="100" />
        </inertial>
        <visual>
            <origin xyz="0 1.0875568037720615 0" rpy="0 0 0"/>
            <geometry>
                <box size="1.889020365799391 2.175113607544123 2.7869059397531473" />
            </geometry>
            <material name="Blue">
                <color rgba="0 1.0 1.0 1.0"/>
            </material>
        </visual>
        <collision>
            <origin xyz="0 1.0875568037720615 0" rpy="0 0 0"/>
            <geometry>
                <box size="1.889020365799391 2.175113607544123 2.7869059397531473" />
            </geometry>
        </collision>
    </link>
    <link name="Leg12">
        <inertial>
            <origin xyz="0.7911874467572423 0 0" rpy="0 0 0"/>
            <mass value="1" />
            <inertia ixx="100" ixy="0" ixz="0" iyy="100" iyz="0" izz="100" />
        </inertial>
        <visual>
            <origin xyz="0.7911874467572423 0 0" rpy="0 0 0"/>
            <geometry>
                <box size="1.5823748935144846 2.9416854015124274 1.9659053479287496" />
            </geometry>
            <material name="Blue">
                <color rgba="0 1.0 1.0 1.0"/>
            </material>
        </visual>
        <collision>
            <origin xyz="0.7911874467572423 0 0" rpy="0 0 0"/>
            <geometry>
                <box size="1.5823748935144846 2.9416854015124274 1.9659053479287496" />
            </geometry>
        </collision>
    </link>
    <link name="Leg13">
        <inertial>
            <origin xyz="1.1755573190518187 0 0" rpy="0 0 0"/>
            <mass value="1" />
            <inertia ixx="100" ixy="0" ixz="0" iyy="100" iyz="0" izz="100" />
        </inertial>
        <visual>
            <origin xyz="1.1755573190518187 0 0" rpy="0 0 0"/>
            <geometry>
                <box size="2.3511146381036374 2.8998115118535632 2.484076974306415" />
            </geometry>
            <material name="Blue">
                <color rgba="0 1.0 1.0 1.0"/>
            </material>
        </visual>
        <collision>
            <origin xyz="1.1755573190518187 0 0" rpy="0 0 0"/>
            <geometry>
                <box size="2.3511146381036374 2.8998115118535632 2.484076974306415" />
            </geometry>
        </collision>
    </link>
    <link name="Leg14">
        <inertial>
            <origin xyz="0 0 0.6318322015298455" rpy="0 0 0"/>
            <mass value="1" />
            <inertia ixx="100" ixy="0" ixz="0" iyy="100" iyz="0" izz="100" />
        </inertial>
        <visual>
            <origin xyz="0 0 0.6318322015298455" rpy="0 0 0"/>
            <geometry>
                <box size="1.895167933867021 2.331199211902545 1.263664403059691" />
            </geometry>
            <material name="Blue">
                <color rgba="0 1.0 1.0 1.0"/>
            </material>
        </visual>
        <collision>
            <origin xyz="0 0 0.6318322015298455" rpy="0 0 0"/>
            <geometry>
                <box size="1.895167933867021 2.331199211902545 1.263664403059691" />
            </geometry>
        </collision>
    </link>
    <link name="Leg15">
        <inertial>
            <origin xyz="0 0 1.4873819939910038" rpy="0 0 0"/>
            <mass value="1" />
            <inertia ixx="100" ixy="0" ixz="0" iyy="100" iyz="0" izz="100" />
        </inertial>
        <visual>
            <origin xyz="0 0 1.4873819939910038" rpy="0 0 0"/>
            <geometry>
                <box size="2.32469996321909 1.7881792043827534 2.9747639879820076" />
            </geometry>
            <material name="Green">
                <color rgba="0 180.0 0.0 1.0"/>
            </material>
        </visual>
        <collision>
            <origin xyz="0 0 1.4873819939910038" rpy="0 0 0"/>
            <geometry>
                <box size="2.32469996321909 1.7881792043827534 2.9747639879820076" />
            </geometry>
        </collision>
    </link>
    <link name="Leg16">
        <inertial>
            <origin xyz="0 0.8094345414426325 0" rpy="0 0 0"/>
            <mass value="1" />
            <inertia ixx="100" ixy="0" ixz="0" iyy="100" iyz="0" izz="100" />
        </inertial>
        <visual>
            <origin xyz="0 0.8094345414426325 0" rpy="0 0 0"/>
            <geometry>
                <box size="2.9600246447068175 1.618869082885265 2.658109805595453" />
            </geometry>
            <material name="Blue">
                <color rgba="0 1.0 1.0 1.0"/>
            </material>
        </visual>
        <collision>
            <origin xyz="0 0.8094345414426325 0" rpy="0 0 0"/>
            <geometry>
                <box size="2.9600246447068175 1.618869082885265 2.658109805595453" />
            </geometry>
        </collision>
    </link>
    <link name="Leg17">
        <inertial>
            <origin xyz="0 0 0.8664140426836485" rpy="0 0 0"/>
            <mass value="1" />
            <inertia ixx="100" ixy="0" ixz="0" iyy="100" iyz="0" izz="100" />
        </inertial>
        <visual>
            <origin xyz="0 0 0.8664140426836485" rpy="0 0 0"/>
            <geometry>
                <box size="1.9601515711867796 2.8976914789763666 1.732828085367297" />
            </geometry>
            <material name="Green">
                <color rgba="0 180.0 0.0 1.0"/>
            </material>
        </visual>
        <collision>
            <origin xyz="0 0 0.8664140426836485" rpy="0 0 0"/>
            <geometry>
                <box size="1.9601515711867796 2.8976914789763666 1.732828085367297" />
            </geometry>
        </collision>
    </link>
    <link name="Leg18">
        <inertial>
            <origin xyz="0 1.0329070668384759 0" rpy="0 0 0"/>
            <mass value="1" />
            <inertia ixx="100" ixy="0" ixz="0" iyy="100" iyz="0" izz="100" />
        </inertial>
        <visual>
            <origin xyz="0 1.0329070668384759 0" rpy="0 0 0"/>
            <geometry>
                <box size="1.6098464569042605 2.0658141336769518 2.7206223913289485" />
            </geometry>
            <material name="Green">
                <color rgba="0 180.0 0.0 1.0"/>
            </material>
        </visual>
        <collision>
            <origin xyz="0 1.0329070668384759 0" rpy="0 0 0"/>
            <geometry>
                <box size="1.6098464569042605 2.0658141336769518 2.7206223913289485" />
            </geometry>
        </collision>
    </link>
    <link name="Leg19">
        <inertial>
            <origin xyz="0.9465763509545781 0 0" rpy="0 0 0"/>
            <mass value="1" />
            <inertia ixx="100" ixy="0" ixz="0" iyy="100" iyz="0" izz="100" />
        </inertial>
        <visual>
            <origin xyz="0.9465763509545781 0 0" rpy="0 0 0"/>
            <geometry>
                <box size="1.8931527019091563 1.0561800921043643 2.5330137600782714" />
            </geometry>
            <material name="Blue">
                <color rgba="0 1.0 1.0 1.0"/>
            </material>
        </visual>
        <collision>
            <origin xyz="0.9465763509545781 0 0" rpy="0 0 0"/>
            <geometry>
                <box size="1.8931527019091563 1.0561800921043643 2.5330137600782714" />
            </geometry>
        </collision>
    </link>
    <link name="Leg20">
        <inertial>
            <origin xyz="0 0 0.909057960920924" rpy="0 0 0"/>
            <mass value="1" />
            <inertia ixx="100" ixy="0" ixz="0" iyy="100" iyz="0" izz="100" />
        </inertial>
        <visual>
            <origin xyz="0 0 0.909057960920924" rpy="0 0 0"/>
            <geometry>
                <box size="2.323478878376129 2.163706448427079 1.818115921841848" />
            </geometry>
            <material name="Green">
                <color rgba="0 180.0 0.0 1.0"/>
            </material>
        </visual>
        <collision>
            <origin xyz="0 0 0.909057960920924" rpy="0 0 0"/>
            <geometry>
                <box size="2.323478878376129 2.163706448427079 1.818115921841848" />
            </geometry>
        </collision>
    </link>
    <link name="Leg21">
        <inertial>
            <origin xyz="1.3063598881969867 0 0" rpy="0 0 0"/>
            <mass value="1" />
            <inertia ixx="100" ixy="0" ixz="0" iyy="100" iyz="0" izz="100" />
        </inertial>
        <visual>
            <origin xyz="1.3063598881969867 0 0" rpy="0 0 0"/>
            <geometry>
                <box size="2.6127197763939733 2.1767571616718957 1.1780704076352702" />
            </geometry>
            <material name="Blue">
                <color rgba="0 1.0 1.0 1.0"/>
            </material>
        </visual>
        <collision>
            <origin xyz="1.3063598881969867 0 0" rpy="0 0 0"/>
            <geometry>
                <box size="2.6127197763939733 2.1767571616718957 1.1780704076352702" />
            </geometry>
        </collision>
    </link>
    <link name="Leg22">
        <inertial>
            <origin xyz="1.0031739095124552 0 0" rpy="0 0 0"/>
            <mass value="1" />
            <inertia ixx="100" ixy="0" ixz="0" iyy="100" iyz="0" izz="100" />
        </inertial>
        <visual>
            <origin xyz="1.0031739095124552 0 0" rpy="0 0 0"/>
            <geometry>
                <box size="2.0063478190249104 2.924580817741976 2.962792773809108" />
            </geometry>
            <material name="Blue">
                <color rgba="0 1.0 1.0 1.0"/>
            </material>
        </visual>
        <collision>
            <origin xyz="1.0031739095124552 0 0" rpy="0 0 0"/>
            <geometry>
                <box size="2.0063478190249104 2.924580817741976 2.962792773809108" />
            </geometry>
        </collision>
    </link>
    <link name="Leg23">
        <inertial>
            <origin xyz="0 0 0.9005624010005892" rpy="0 0 0"/>
            <mass value="1" />
            <inertia ixx="100" ixy="0" ixz="0" iyy="100" iyz="0" izz="100" />
        </inertial>
        <visual>
            <origin xyz="0 0 0.9005624010005892" rpy="0 0 0"/>
            <geometry>
                <box size="1.9926039714887722 1.8983351540245916 1.8011248020011783" />
            </geometry>
            <material name="Green">
                <color rgba="0 180.0 0.0 1.0"/>
            </material>
        </visual>
        <collision>
            <origin xyz="0 0 0.9005624010005892" rpy="0 0 0"/>
            <geometry>
                <box size="1.9926039714887722 1.8983351540245916 1.8011248020011783" />
            </geometry>
        </collision>
    </link>
    <link name="Leg24">
        <inertial>
            <origin xyz="0 1.2230735425694204 0" rpy="0 0 0"/>
            <mass value="1" />
            <inertia ixx="100" ixy="0" ixz="0" iyy="100" iyz="0" izz="100" />
        </inertial>
        <visual>
            <origin xyz="0 1.2230735425694204 0" rpy="0 0 0"/>
            <geometry>
                <box size="2.516085711377887 2.4461470851388407 1.042567248324632" />
            </geometry>
            <material name="Blue">
                <color rgba="0 1.0 1.0 1.0"/>
            </material>
        </visual>
        <collision>
            <origin xyz="0 1.2230735425694204 0" rpy="0 0 0"/>
            <geometry>
                <box size="2.516085711377887 2.4461470851388407 1.042567248324632" />
            </geometry>
        </collision>
    </link>
    <link name="Leg25">
        <inertial>
            <origin xyz="1.327599881456494 0 0" rpy="0 0 0"/>
            <mass value="1" />
            <inertia ixx="100" ixy="0" ixz="0" iyy="100" iyz="0" izz="100" />
        </inertial>
        <visual>
            <origin xyz="1.327599881456494 0 0" rpy="0 0 0"/>
            <geometry>
                <box size="2.655199762912988 2.7246325676560144 1.495178497328382" />
            </geometry>
            <material name="Blue">
                <color rgba="0 1.0 1.0 1.0"/>
            </material>
        </visual>
        <collision>
            <origin xyz="1.327599881456494 0 0" rpy="0 0 0"/>
            <geometry>
                <box size="2.655199762912988 2.7246325676560144 1.495178497328382" />
            </geometry>
        </collision>
    </link>
    <link name="Leg26">
        <inertial>
            <origin xyz="1.4735967126056582 0 0" rpy="0 0 0"/>
            <mass value="1" />
            <inertia ixx="100" ixy="0" ixz="0" iyy="100" iyz="0" izz="100" />
        </inertial>
        <visual>
            <origin xyz="1.4735967126056582 0 0" rpy="0 0 0"/>
            <geometry>
                <box size="2.9471934252113163 1.2970655479164268 1.5384826215959106" />
            </geometry>
            <material name="Blue">
                <color rgba="0 1.0 1.0 1.0"/>
            </material>
        </visual>
        <collision>
            <origin xyz="1.4735967126056582 0 0" rpy="0 0 0"/>
            <geometry>
                <box size="2.9471934252113163 1.2970655479164268 1.5384826215959106" />
            </geometry>
        </collision>
    </link>
    <joint name="Torso_Leg1" type="revolute">
       <parent link="Torso"/>
       <child  link="Leg1"/>
       <origin rpy="0 0 0" xyz="0 1.043489418514811 1.3077533381741409" />
     <axis xyz="1 0 0"/>
       <limit effort="0.0" lower="-3.14159" upper="3.14159" velocity="0.0"/>
    </joint>
    <joint name="Torso_Leg2" type="revolute">
       <parent link="Torso"/>
       <child  link="Leg2"/>
       <origin rpy="0 0 0" xyz="0.7140735151721511 0.9137298399049424 0" />
     <axis xyz="1 0 0"/>
       <limit effort="0.0" lower="-3.14159" upper="3.14159" velocity="0.0"/>
    </joint>
    <joint name="Leg2_Leg3" type="revolute">
       <parent link="Leg2"/>
       <child  link="Leg3"/>
       <origin rpy="0 0 0" xyz="1.1243909247627228 0 0" />
     <axis xyz="1 0 0"/>
       <limit effort="0.0" lower="-3.14159" upper="3.14159" velocity="0.0"/>
    </joint>
    <joint name="Leg2_Leg4" type="revolute">
       <parent link="Leg2"/>
       <child  link="Leg4"/>
       <origin rpy="0 0 0" xyz="1.1243909247627228 0.578286702657369 0" />
     <axis xyz="1 0 0"/>
       <limit effort="0.0" lower="-3.14159" upper="3.14159" velocity="0.0"/>
    </joint>
    <joint name="Leg3_Leg5" type="revolute">
       <parent link="Leg3"/>
       <child  link="Leg5"/>
       <origin rpy="0 0 0" xyz="0 0.9717928705192076 1.3889628536862055" />
     <axis xyz="1 0 0"/>
       <limit effort="0.0" lower="-3.14159" upper="3.14159" velocity="0.0"/>
    </joint>
    <joint name="Leg2_Leg6" type="revolute">
       <parent link="Leg2"/>
       <child  link="Leg6"/>
       <origin rpy="0 0 0" xyz="1.1243909247627228 0.578286702657369 0.6411503491491943" />
     <axis xyz="1 0 0"/>
       <limit effort="0.0" lower="-3.14159" upper="3.14159" velocity="0.0"/>
    </joint>
    <joint name="Leg4_Leg7" type="revolute">
       <parent link="Leg4"/>
       <child  link="Leg7"/>
       <origin rpy="0 0 0" xyz="1.2685238961913705 0 1.4668050601600617" />
     <axis xyz="1 0 0"/>
       <limit effort="0.0" lower="-3.14159" upper="3.14159" velocity="0.0"/>
    </joint>
    <joint name="Leg6_Leg8" type="revolute">
       <parent link="Leg6"/>
       <child  link="Leg8"/>
       <origin rpy="0 0 0" xyz="2.8175919603930506 0 0" />
     <axis xyz="1 0 0"/>
       <limit effort="0.0" lower="-3.14159" upper="3.14159" velocity="0.0"/>
    </joint>
    <joint name="Leg4_Leg9" type="revolute">
       <parent link="Leg4"/>
       <child  link="Leg9"/>
       <origin rpy="0 0 0" xyz="1.2685238961913705 0.8095792274275302 1.4668050601600617" />
     <axis xyz="1 0 0"/>
       <limit effort="0.0" lower="-3.14159" upper="3.14159" velocity="0.0"/>
    </joint>
    <joint name="Leg7_Leg10" type="revolute">
       <parent link="Leg7"/>
       <child  link="Leg10"/>
       <origin rpy="0 0 0" xyz="2.4791396158341574 0 0" />
     <axis xyz="1 0 0"/>
       <limit effort="0.0" lower="-3.14159" upper="3.14159" velocity="0.0"/>
    </joint>
    <joint name="Leg8_Leg11" type="revolute">
       <parent link="Leg8"/>
       <child  link="Leg11"/>
       <origin rpy="0 0 0" xyz="0 2.724624698883026 0" />
     <axis xyz="1 0 0"/>
       <limit effort="0.0" lower="-3.14159" upper="3.14159" velocity="0.0"/>
    </joint>
    <joint name="Leg10_Leg12" type="revolute">
       <parent link="Leg10"/>
       <child  link="Leg12"/>
       <origin rpy="0 0 0" xyz="0.9445101828996955 1.0875568037720615 0" />
     <axis xyz="1 0 0"/>
       <limit effort="0.0" lower="-3.14159" upper="3.14159" velocity="0.0"/>
    </joint>
    <joint name="Leg8_Leg13" type="revolute">
       <parent link="Leg8"/>
       <child  link="Leg13"/>
       <origin rpy="0 0 0" xyz="0.5975050353723365 2.724624698883026 0" />
     <axis xyz="1 0 0"/>
       <limit effort="0.0" lower="-3.14159" upper="3.14159" velocity="0.0"/>
    </joint>
    <joint name="Leg7_Leg14" type="revolute">
       <parent link="Leg7"/>
       <child  link="Leg14"/>
       <origin rpy="0 0 0" xyz="2.4791396158341574 0 0.9817191072947768" />
     <axis xyz="1 0 0"/>
       <limit effort="0.0" lower="-3.14159" upper="3.14159" velocity="0.0"/>
    </joint>
    <joint name="Leg11_Leg15" type="revolute">
       <parent link="Leg11"/>
       <child  link="Leg15"/>
       <origin rpy="0 0 0" xyz="0.7911874467572423 0 0.9829526739643748" />
     <axis xyz="1 0 0"/>
       <limit effort="0.0" lower="-3.14159" upper="3.14159" velocity="0.0"/>
    </joint>
    <joint name="Leg1_Leg16" type="revolute">
       <parent link="Leg1"/>
       <child  link="Leg16"/>
       <origin rpy="0 0 0" xyz="0.848518137090346 1.0578863208258071 0" />
     <axis xyz="1 0 0"/>
       <limit effort="0.0" lower="-3.14159" upper="3.14159" velocity="0.0"/>
    </joint>
    <joint name="Leg12_Leg17" type="revolute">
       <parent link="Leg12"/>
       <child  link="Leg17"/>
       <origin rpy="0 0 0" xyz="1.1755573190518187 0 1.2420384871532075" />
     <axis xyz="1 0 0"/>
       <limit effort="0.0" lower="-3.14159" upper="3.14159" velocity="0.0"/>
    </joint>
    <joint name="Leg15_Leg18" type="revolute">
       <parent link="Leg15"/>
       <child  link="Leg18"/>
       <origin rpy="0 0 0" xyz="0 1.618869082885265 0" />
     <axis xyz="1 0 0"/>
       <limit effort="0.0" lower="-3.14159" upper="3.14159" velocity="0.0"/>
    </joint>
    <joint name="Leg13_Leg19" type="revolute">
       <parent link="Leg13"/>
       <child  link="Leg19"/>
       <origin rpy="0 0 0" xyz="0.9475839669335105 0 0.6318322015298455" />
     <axis xyz="1 0 0"/>
       <limit effort="0.0" lower="-3.14159" upper="3.14159" velocity="0.0"/>
    </joint>
    <joint name="Leg14_Leg20" type="revolute">
       <parent link="Leg14"/>
       <child  link="Leg20"/>
       <origin rpy="0 0 0" xyz="0 0 2.9747639879820076" />
     <axis xyz="1 0 0"/>
       <limit effort="0.0" lower="-3.14159" upper="3.14159" velocity="0.0"/>
    </joint>
    <joint name="Leg11_Leg21" type="revolute">
       <parent link="Leg11"/>
       <child  link="Leg21"/>
       <origin rpy="0 0 0" xyz="1.5823748935144846 0 0.9829526739643748" />
     <axis xyz="1 0 0"/>
       <limit effort="0.0" lower="-3.14159" upper="3.14159" velocity="0.0"/>
    </joint>
    <joint name="Leg5_Leg22" type="revolute">
       <parent link="Leg5"/>
       <child  link="Leg22"/>
       <origin rpy="0 0 0" xyz="1.10195089190202 0 0.9455014728054265" />
     <axis xyz="1 0 0"/>
       <limit effort="0.0" lower="-3.14159" upper="3.14159" velocity="0.0"/>
    </joint>
    <joint name="Leg9_Leg23" type="revolute">
       <parent link="Leg9"/>
       <child  link="Leg23"/>
       <origin rpy="0 0 0" xyz="1.4343779724697194 0 1.210718203519316" />
     <axis xyz="1 0 0"/>
       <limit effort="0.0" lower="-3.14159" upper="3.14159" velocity="0.0"/>
    </joint>
    <joint name="Leg23_Leg24" type="revolute">
       <parent link="Leg23"/>
       <child  link="Leg24"/>
       <origin rpy="0 0 0" xyz="0 2.4461470851388407 0" />
     <axis xyz="1 0 0"/>
       <limit effort="0.0" lower="-3.14159" upper="3.14159" velocity="0.0"/>
    </joint>
    <joint name="Leg1_Leg25" type="revolute">
       <parent link="Leg1"/>
       <child  link="Leg25"/>
       <origin rpy="0 0 0" xyz="1.697036274180692 1.0578863208258071 0" />
     <axis xyz="1 0 0"/>
       <limit effort="0.0" lower="-3.14159" upper="3.14159" velocity="0.0"/>
    </joint>
    <joint name="Leg12_Leg26" type="revolute">
       <parent link="Leg12"/>
       <child  link="Leg26"/>
       <origin rpy="0 0 0" xyz="2.3511146381036374 0 1.2420384871532075" />
     <axis xyz="1 0 0"/>
       <limit effort="0.0" lower="-3.14159" upper="3.14159" velocity="0.0"/>
    </joint>
</robot>