<robot name = "robot">
    <link name="Torso">
        <inertial>
            <origin xyz="0 0 1.0303399299207316" rpy="0 0 0"/>
            <mass value="1" />
            <inertia ixx="100" ixy="0" ixz="0" iyy="100" iyz="0" izz="100" />
        </inertial>
        <visual>
            <origin xyz="0 0 1.0303399299207316" rpy="0 0 0"/>
            <geometry>
                <box size="1.4114961448803378 2.8607225346537075 2.0606798598414633" />
            </geometry>
            <material name="Green">
                <color rgba="0 180.0 0.0 1.0"/>
            </material>
        </visual>
        <collision>
            <origin xyz="0 0 1.0303399299207316" rpy="0 0 0"/>
            <geometry>
                <box size="1.4114961448803378 2.8607225346537075 2.0606798598414633" />
            </geometry>
        </collision>
    </link>
    <link name="Leg1">
        <inertial>
            <origin xyz="0 0 1.0302794911041109" rpy="0 0 0"/>
            <mass value="1" />
            <inertia ixx="100" ixy="0" ixz="0" iyy="100" iyz="0" izz="100" />
        </inertial>
        <visual>
            <origin xyz="0 0 1.0302794911041109" rpy="0 0 0"/>
            <geometry>
                <box size="1.5935581790940796 1.1171754871112938 2.0605589822082218" />
            </geometry>
            <material name="Blue">
                <color rgba="0 1.0 1.0 1.0"/>
            </material>
        </visual>
        <collision>
            <origin xyz="0 0 1.0302794911041109" rpy="0 0 0"/>
            <geometry>
                <box size="1.5935581790940796 1.1171754871112938 2.0605589822082218" />
            </geometry>
        </collision>
    </link>
    <link name="Leg2">
        <inertial>
            <origin xyz="0 0.697979578642776 0" rpy="0 0 0"/>
            <mass value="1" />
            <inertia ixx="100" ixy="0" ixz="0" iyy="100" iyz="0" izz="100" />
        </inertial>
        <visual>
            <origin xyz="0 0.697979578642776 0" rpy="0 0 0"/>
            <geometry>
                <box size="2.054092633522679 1.395959157285552 1.5695509884183967" />
            </geometry>
            <material name="Green">
                <color rgba="0 180.0 0.0 1.0"/>
            </material>
        </visual>
        <collision>
            <origin xyz="0 0.697979578642776 0" rpy="0 0 0"/>
            <geometry>
                <box size="2.054092633522679 1.395959157285552 1.5695509884183967" />
            </geometry>
        </collision>
    </link>
    <link name="Leg3">
        <inertial>
            <origin xyz="0 0.6038192062263844 0" rpy="0 0 0"/>
            <mass value="1" />
            <inertia ixx="100" ixy="0" ixz="0" iyy="100" iyz="0" izz="100" />
        </inertial>
        <visual>
            <origin xyz="0 0.6038192062263844 0" rpy="0 0 0"/>
            <geometry>
                <box size="1.5212622637208744 1.2076384124527688 2.3754784034501752" />
            </geometry>
            <material name="Green">
                <color rgba="0 180.0 0.0 1.0"/>
            </material>
        </visual>
        <collision>
            <origin xyz="0 0.6038192062263844 0" rpy="0 0 0"/>
            <geometry>
                <box size="1.5212622637208744 1.2076384124527688 2.3754784034501752" />
            </geometry>
        </collision>
    </link>
    <link name="Leg4">
        <inertial>
            <origin xyz="0 0 1.4668793939963973" rpy="0 0 0"/>
            <mass value="1" />
            <inertia ixx="100" ixy="0" ixz="0" iyy="100" iyz="0" izz="100" />
        </inertial>
        <visual>
            <origin xyz="0 0 1.4668793939963973" rpy="0 0 0"/>
            <geometry>
                <box size="1.4435365567344356 2.393027764398951 2.9337587879927947" />
            </geometry>
            <material name="Blue">
                <color rgba="0 1.0 1.0 1.0"/>
            </material>
        </visual>
        <collision>
            <origin xyz="0 0 1.4668793939963973" rpy="0 0 0"/>
            <geometry>
                <box size="1.4435365567344356 2.393027764398951 2.9337587879927947" />
            </geometry>
        </collision>
    </link>
    <link name="Leg5">
        <inertial>
            <origin xyz="0.5167340403972479 0 0" rpy="0 0 0"/>
            <mass value="1" />
            <inertia ixx="100" ixy="0" ixz="0" iyy="100" iyz="0" izz="100" />
        </inertial>
        <visual>
            <origin xyz="0.5167340403972479 0 0" rpy="0 0 0"/>
            <geometry>
                <box size="1.0334680807944958 1.4150414241554174 2.3620733114608568" />
            </geometry>
            <material name="Blue">
                <color rgba="0 1.0 1.0 1.0"/>
            </material>
        </visual>
        <collision>
            <origin xyz="0.5167340403972479 0 0" rpy="0 0 0"/>
            <geometry>
                <box size="1.0334680807944958 1.4150414241554174 2.3620733114608568" />
            </geometry>
        </collision>
    </link>
    <link name="Leg6">
        <inertial>
            <origin xyz="1.1774115458583592 0 0" rpy="0 0 0"/>
            <mass value="1" />
            <inertia ixx="100" ixy="0" ixz="0" iyy="100" iyz="0" izz="100" />
        </inertial>
        <visual>
            <origin xyz="1.1774115458583592 0 0" rpy="0 0 0"/>
            <geometry>
                <box size="2.3548230917167183 1.6615019987141884 2.292177665279543" />
            </geometry>
            <material name="Blue">
                <color rgba="0 1.0 1.0 1.0"/>
            </material>
        </visual>
        <collision>
            <origin xyz="1.1774115458583592 0 0" rpy="0 0 0"/>
            <geometry>
                <box size="2.3548230917167183 1.6615019987141884 2.292177665279543" />
            </geometry>
        </collision>
    </link>
    <link name="Leg7">
        <inertial>
            <origin xyz="0 0.5393469249101224 0" rpy="0 0 0"/>
            <mass value="1" />
            <inertia ixx="100" ixy="0" ixz="0" iyy="100" iyz="0" izz="100" />
        </inertial>
        <visual>
            <origin xyz="0 0.5393469249101224 0" rpy="0 0 0"/>
            <geometry>
                <box size="2.7823162435710485 1.0786938498202447 2.2418793662638197" />
            </geometry>
            <material name="Blue">
                <color rgba="0 1.0 1.0 1.0"/>
            </material>
        </visual>
        <collision>
            <origin xyz="0 0.5393469249101224 0" rpy="0 0 0"/>
            <geometry>
                <box size="2.7823162435710485 1.0786938498202447 2.2418793662638197" />
            </geometry>
        </collision>
    </link>
    <link name="Leg8">
        <inertial>
            <origin xyz="0 0 1.259805359690378" rpy="0 0 0"/>
            <mass value="1" />
            <inertia ixx="100" ixy="0" ixz="0" iyy="100" iyz="0" izz="100" />
        </inertial>
        <visual>
            <origin xyz="0 0 1.259805359690378" rpy="0 0 0"/>
            <geometry>
                <box size="1.499014545257894 2.0036790319430167 2.519610719380756" />
            </geometry>
            <material name="Green">
                <color rgba="0 180.0 0.0 1.0"/>
            </material>
        </visual>
        <collision>
            <origin xyz="0 0 1.259805359690378" rpy="0 0 0"/>
            <geometry>
                <box size="1.499014545257894 2.0036790319430167 2.519610719380756" />
            </geometry>
        </collision>
    </link>
    <link name="Leg9">
        <inertial>
            <origin xyz="0.7031064342445956 0 0" rpy="0 0 0"/>
            <mass value="1" />
            <inertia ixx="100" ixy="0" ixz="0" iyy="100" iyz="0" izz="100" />
        </inertial>
        <visual>
            <origin xyz="0.7031064342445956 0 0" rpy="0 0 0"/>
            <geometry>
                <box size="1.4062128684891912 1.8385781614459857 1.9012560778925753" />
            </geometry>
            <material name="Blue">
                <color rgba="0 1.0 1.0 1.0"/>
            </material>
        </visual>
        <collision>
            <origin xyz="0.7031064342445956 0 0" rpy="0 0 0"/>
            <geometry>
                <box size="1.4062128684891912 1.8385781614459857 1.9012560778925753" />
            </geometry>
        </collision>
    </link>
    <link name="Leg10">
        <inertial>
            <origin xyz="0.84417546304461 0 0" rpy="0 0 0"/>
            <mass value="1" />
            <inertia ixx="100" ixy="0" ixz="0" iyy="100" iyz="0" izz="100" />
        </inertial>
        <visual>
            <origin xyz="0.84417546304461 0 0" rpy="0 0 0"/>
            <geometry>
                <box size="1.68835092608922 1.296023946752144 2.7472238398200073" />
            </geometry>
            <material name="Green">
                <color rgba="0 180.0 0.0 1.0"/>
            </material>
        </visual>
        <collision>
            <origin xyz="0.84417546304461 0 0" rpy="0 0 0"/>
            <geometry>
                <box size="1.68835092608922 1.296023946752144 2.7472238398200073" />
            </geometry>
        </collision>
    </link>
    <link name="Leg11">
        <inertial>
            <origin xyz="0 0 1.0512952879584176" rpy="0 0 0"/>
            <mass value="1" />
            <inertia ixx="100" ixy="0" ixz="0" iyy="100" iyz="0" izz="100" />
        </inertial>
        <visual>
            <origin xyz="0 0 1.0512952879584176" rpy="0 0 0"/>
            <geometry>
                <box size="2.2624022634751277 2.364093693869642 2.1025905759168353" />
            </geometry>
            <material name="Blue">
                <color rgba="0 1.0 1.0 1.0"/>
            </material>
        </visual>
        <collision>
            <origin xyz="0 0 1.0512952879584176" rpy="0 0 0"/>
            <geometry>
                <box size="2.2624022634751277 2.364093693869642 2.1025905759168353" />
            </geometry>
        </collision>
    </link>
    <link name="Leg12">
        <inertial>
            <origin xyz="0.6161246699564499 0 0" rpy="0 0 0"/>
            <mass value="1" />
            <inertia ixx="100" ixy="0" ixz="0" iyy="100" iyz="0" izz="100" />
        </inertial>
        <visual>
            <origin xyz="0.6161246699564499 0 0" rpy="0 0 0"/>
            <geometry>
                <box size="1.2322493399128998 2.395047074056198 2.829016830170273" />
            </geometry>
            <material name="Blue">
                <color rgba="0 1.0 1.0 1.0"/>
            </material>
        </visual>
        <collision>
            <origin xyz="0.6161246699564499 0 0" rpy="0 0 0"/>
            <geometry>
                <box size="1.2322493399128998 2.395047074056198 2.829016830170273" />
            </geometry>
        </collision>
    </link>
    <link name="Leg13">
        <inertial>
            <origin xyz="1.3973199378028425 0 0" rpy="0 0 0"/>
            <mass value="1" />
            <inertia ixx="100" ixy="0" ixz="0" iyy="100" iyz="0" izz="100" />
        </inertial>
        <visual>
            <origin xyz="1.3973199378028425 0 0" rpy="0 0 0"/>
            <geometry>
                <box size="2.794639875605685 2.19050465407544 2.8282625903540364" />
            </geometry>
            <material name="Blue">
                <color rgba="0 1.0 1.0 1.0"/>
            </material>
        </visual>
        <collision>
            <origin xyz="1.3973199378028425 0 0" rpy="0 0 0"/>
            <geometry>
                <box size="2.794639875605685 2.19050465407544 2.8282625903540364" />
            </geometry>
        </collision>
    </link>
    <link name="Leg14">
        <inertial>
            <origin xyz="0 1.16167406027725 0" rpy="0 0 0"/>
            <mass value="1" />
            <inertia ixx="100" ixy="0" ixz="0" iyy="100" iyz="0" izz="100" />
        </inertial>
        <visual>
            <origin xyz="0 1.16167406027725 0" rpy="0 0 0"/>
            <geometry>
                <box size="1.8579728388038301 2.3233481205545 1.531528052485616" />
            </geometry>
            <material name="Green">
                <color rgba="0 180.0 0.0 1.0"/>
            </material>
        </visual>
        <collision>
            <origin xyz="0 1.16167406027725 0" rpy="0 0 0"/>
            <geometry>
                <box size="1.8579728388038301 2.3233481205545 1.531528052485616" />
            </geometry>
        </collision>
    </link>
    <link name="Leg15">
        <inertial>
            <origin xyz="1.4189743987922927 0 0" rpy="0 0 0"/>
            <mass value="1" />
            <inertia ixx="100" ixy="0" ixz="0" iyy="100" iyz="0" izz="100" />
        </inertial>
        <visual>
            <origin xyz="1.4189743987922927 0 0" rpy="0 0 0"/>
            <geometry>
                <box size="2.8379487975845854 1.5603535063401024 2.321841755454397" />
            </geometry>
            <material name="Blue">
                <color rgba="0 1.0 1.0 1.0"/>
            </material>
        </visual>
        <collision>
            <origin xyz="1.4189743987922927 0 0" rpy="0 0 0"/>
            <geometry>
                <box size="2.8379487975845854 1.5603535063401024 2.321841755454397" />
            </geometry>
        </collision>
    </link>
    <link name="Leg16">
        <inertial>
            <origin xyz="0 0 1.3636350996246889" rpy="0 0 0"/>
            <mass value="1" />
            <inertia ixx="100" ixy="0" ixz="0" iyy="100" iyz="0" izz="100" />
        </inertial>
        <visual>
            <origin xyz="0 0 1.3636350996246889" rpy="0 0 0"/>
            <geometry>
                <box size="2.466038671185755 2.602332137718899 2.7272701992493777" />
            </geometry>
            <material name="Green">
                <color rgba="0 180.0 0.0 1.0"/>
            </material>
        </visual>
        <collision>
            <origin xyz="0 0 1.3636350996246889" rpy="0 0 0"/>
            <geometry>
                <box size="2.466038671185755 2.602332137718899 2.7272701992493777" />
            </geometry>
        </collision>
    </link>
    <link name="Leg17">
        <inertial>
            <origin xyz="0 1.4851508364269064 0" rpy="0 0 0"/>
            <mass value="1" />
            <inertia ixx="100" ixy="0" ixz="0" iyy="100" iyz="0" izz="100" />
        </inertial>
        <visual>
            <origin xyz="0 1.4851508364269064 0" rpy="0 0 0"/>
            <geometry>
                <box size="2.2645922694236265 2.9703016728538127 2.7859631763544717" />
            </geometry>
            <material name="Blue">
                <color rgba="0 1.0 1.0 1.0"/>
            </material>
        </visual>
        <collision>
            <origin xyz="0 1.4851508364269064 0" rpy="0 0 0"/>
            <geometry>
                <box size="2.2645922694236265 2.9703016728538127 2.7859631763544717" />
            </geometry>
        </collision>
    </link>
    <link name="Leg18">
        <inertial>
            <origin xyz="0 0 0.7202569795223862" rpy="0 0 0"/>
            <mass value="1" />
            <inertia ixx="100" ixy="0" ixz="0" iyy="100" iyz="0" izz="100" />
        </inertial>
        <visual>
            <origin xyz="0 0 0.7202569795223862" rpy="0 0 0"/>
            <geometry>
                <box size="1.0079287908765262 2.5922373971430464 1.4405139590447724" />
            </geometry>
            <material name="Blue">
                <color rgba="0 1.0 1.0 1.0"/>
            </material>
        </visual>
        <collision>
            <origin xyz="0 0 0.7202569795223862" rpy="0 0 0"/>
            <geometry>
                <box size="1.0079287908765262 2.5922373971430464 1.4405139590447724" />
            </geometry>
        </collision>
    </link>
    <link name="Leg19">
        <inertial>
            <origin xyz="0 0.5824340182333192 0" rpy="0 0 0"/>
            <mass value="1" />
            <inertia ixx="100" ixy="0" ixz="0" iyy="100" iyz="0" izz="100" />
        </inertial>
        <visual>
            <origin xyz="0 0.5824340182333192 0" rpy="0 0 0"/>
            <geometry>
                <box size="2.611871780557969 1.1648680364666384 1.7749882343542023" />
            </geometry>
            <material name="Green">
                <color rgba="0 180.0 0.0 1.0"/>
            </material>
        </visual>
        <collision>
            <origin xyz="0 0.5824340182333192 0" rpy="0 0 0"/>
            <geometry>
                <box size="2.611871780557969 1.1648680364666384 1.7749882343542023" />
            </geometry>
        </collision>
    </link>
    <link name="Leg20">
        <inertial>
            <origin xyz="0 0 1.306268571645774" rpy="0 0 0"/>
            <mass value="1" />
            <inertia ixx="100" ixy="0" ixz="0" iyy="100" iyz="0" izz="100" />
        </inertial>
        <visual>
            <origin xyz="0 0 1.306268571645774" rpy="0 0 0"/>
            <geometry>
                <box size="2.216144816894642 2.194142215164085 2.612537143291548" />
            </geometry>
            <material name="Green">
                <color rgba="0 180.0 0.0 1.0"/>
            </material>
        </visual>
        <collision>
            <origin xyz="0 0 1.306268571645774" rpy="0 0 0"/>
            <geometry>
                <box size="2.216144816894642 2.194142215164085 2.612537143291548" />
            </geometry>
        </collision>
    </link>
    <link name="Leg21">
        <inertial>
            <origin xyz="0 1.2116560071632172 0" rpy="0 0 0"/>
            <mass value="1" />
            <inertia ixx="100" ixy="0" ixz="0" iyy="100" iyz="0" izz="100" />
        </inertial>
        <visual>
            <origin xyz="0 1.2116560071632172 0" rpy="0 0 0"/>
            <geometry>
                <box size="2.9937930037531753 2.4233120143264344 2.1749946092104855" />
            </geometry>
            <material name="Blue">
                <color rgba="0 1.0 1.0 1.0"/>
            </material>
        </visual>
        <collision>
            <origin xyz="0 1.2116560071632172 0" rpy="0 0 0"/>
            <geometry>
                <box size="2.9937930037531753 2.4233120143264344 2.1749946092104855" />
            </geometry>
        </collision>
    </link>
    <link name="Leg22">
        <inertial>
            <origin xyz="0 0 1.0523447447929186" rpy="0 0 0"/>
            <mass value="1" />
            <inertia ixx="100" ixy="0" ixz="0" iyy="100" iyz="0" izz="100" />
        </inertial>
        <visual>
            <origin xyz="0 0 1.0523447447929186" rpy="0 0 0"/>
            <geometry>
                <box size="2.5602986894253243 2.420868371573812 2.1046894895858372" />
            </geometry>
            <material name="Green">
                <color rgba="0 180.0 0.0 1.0"/>
            </material>
        </visual>
        <collision>
            <origin xyz="0 0 1.0523447447929186" rpy="0 0 0"/>
            <geometry>
                <box size="2.5602986894253243 2.420868371573812 2.1046894895858372" />
            </geometry>
        </collision>
    </link>
    <link name="Leg23">
        <inertial>
            <origin xyz="0 0 0.5853589209771639" rpy="0 0 0"/>
            <mass value="1" />
            <inertia ixx="100" ixy="0" ixz="0" iyy="100" iyz="0" izz="100" />
        </inertial>
        <visual>
            <origin xyz="0 0 0.5853589209771639" rpy="0 0 0"/>
            <geometry>
                <box size="2.591687115407317 2.572687712050084 1.1707178419543278" />
            </geometry>
            <material name="Green">
                <color rgba="0 180.0 0.0 1.0"/>
            </material>
        </visual>
        <collision>
            <origin xyz="0 0 0.5853589209771639" rpy="0 0 0"/>
            <geometry>
                <box size="2.591687115407317 2.572687712050084 1.1707178419543278" />
            </geometry>
        </collision>
    </link>
    <link name="Leg24">
        <inertial>
            <origin xyz="0 0 1.1730963140358563" rpy="0 0 0"/>
            <mass value="1" />
            <inertia ixx="100" ixy="0" ixz="0" iyy="100" iyz="0" izz="100" />
        </inertial>
        <visual>
            <origin xyz="0 0 1.1730963140358563" rpy="0 0 0"/>
            <geometry>
                <box size="1.2451108944108435 2.4955530177901704 2.3461926280717127" />
            </geometry>
            <material name="Blue">
                <color rgba="0 1.0 1.0 1.0"/>
            </material>
        </visual>
        <collision>
            <origin xyz="0 0 1.1730963140358563" rpy="0 0 0"/>
            <geometry>
                <box size="1.2451108944108435 2.4955530177901704 2.3461926280717127" />
            </geometry>
        </collision>
    </link>
    <link name="Leg25">
        <inertial>
            <origin xyz="0 0 0.5151667745091181" rpy="0 0 0"/>
            <mass value="1" />
            <inertia ixx="100" ixy="0" ixz="0" iyy="100" iyz="0" izz="100" />
        </inertial>
        <visual>
            <origin xyz="0 0 0.5151667745091181" rpy="0 0 0"/>
            <geometry>
                <box size="1.1778341333541762 1.0455519883886777 1.0303335490182362" />
            </geometry>
            <material name="Blue">
                <color rgba="0 1.0 1.0 1.0"/>
            </material>
        </visual>
        <collision>
            <origin xyz="0 0 0.5151667745091181" rpy="0 0 0"/>
            <geometry>
                <box size="1.1778341333541762 1.0455519883886777 1.0303335490182362" />
            </geometry>
        </collision>
    </link>
    <joint name="Torso_Leg1" type="revolute">
       <parent link="Torso"/>
       <child  link="Leg1"/>
       <origin rpy="0 0 0" xyz="0 0 2.0606798598414633" />
     <axis xyz="1 0 0"/>
       <limit effort="0.0" lower="-3.14159" upper="3.14159" velocity="0.0"/>
    </joint>
    <joint name="Torso_Leg2" type="revolute">
       <parent link="Torso"/>
       <child  link="Leg2"/>
       <origin rpy="0 0 0" xyz="0 0.5585877435556469 1.0302794911041109" />
     <axis xyz="1 0 0"/>
       <limit effort="0.0" lower="-3.14159" upper="3.14159" velocity="0.0"/>
    </joint>
    <joint name="Leg2_Leg3" type="revolute">
       <parent link="Leg2"/>
       <child  link="Leg3"/>
       <origin rpy="0 0 0" xyz="0 1.2076384124527688 0" />
     <axis xyz="1 0 0"/>
       <limit effort="0.0" lower="-3.14159" upper="3.14159" velocity="0.0"/>
    </joint>
    <joint name="Leg2_Leg4" type="revolute">
       <parent link="Leg2"/>
       <child  link="Leg4"/>
       <origin rpy="0 0 0" xyz="0 1.2076384124527688 1.1877392017250876" />
     <axis xyz="1 0 0"/>
       <limit effort="0.0" lower="-3.14159" upper="3.14159" velocity="0.0"/>
    </joint>
    <joint name="Leg1_Leg5" type="revolute">
       <parent link="Leg1"/>
       <child  link="Leg5"/>
       <origin rpy="0 0 0" xyz="1.0270463167613395 0.697979578642776 0" />
     <axis xyz="1 0 0"/>
       <limit effort="0.0" lower="-3.14159" upper="3.14159" velocity="0.0"/>
    </joint>
    <joint name="Torso_Leg6" type="revolute">
       <parent link="Torso"/>
       <child  link="Leg6"/>
       <origin rpy="0 0 0" xyz="0.7967790895470398 0.5585877435556469 1.0302794911041109" />
     <axis xyz="1 0 0"/>
       <limit effort="0.0" lower="-3.14159" upper="3.14159" velocity="0.0"/>
    </joint>
    <joint name="Leg3_Leg7" type="revolute">
       <parent link="Leg3"/>
       <child  link="Leg7"/>
       <origin rpy="0 0 0" xyz="0 1.1965138821994754 1.4668793939963973" />
     <axis xyz="1 0 0"/>
       <limit effort="0.0" lower="-3.14159" upper="3.14159" velocity="0.0"/>
    </joint>
    <joint name="Leg5_Leg8" type="revolute">
       <parent link="Leg5"/>
       <child  link="Leg8"/>
       <origin rpy="0 0 0" xyz="1.1774115458583592 0 1.1460888326397716" />
     <axis xyz="1 0 0"/>
       <limit effort="0.0" lower="-3.14159" upper="3.14159" velocity="0.0"/>
    </joint>
    <joint name="Leg8_Leg9" type="revolute">
       <parent link="Leg8"/>
       <child  link="Leg9"/>
       <origin rpy="0 0 0" xyz="1.4062128684891912 0 0" />
     <axis xyz="1 0 0"/>
       <limit effort="0.0" lower="-3.14159" upper="3.14159" velocity="0.0"/>
    </joint>
    <joint name="Leg5_Leg10" type="revolute">
       <parent link="Leg5"/>
       <child  link="Leg10"/>
       <origin rpy="0 0 0" xyz="2.3548230917167183 0 1.1460888326397716" />
     <axis xyz="1 0 0"/>
       <limit effort="0.0" lower="-3.14159" upper="3.14159" velocity="0.0"/>
    </joint>
    <joint name="Leg6_Leg11" type="revolute">
       <parent link="Leg6"/>
       <child  link="Leg11"/>
       <origin rpy="0 0 0" xyz="0 0.5393469249101224 1.1209396831319098" />
     <axis xyz="1 0 0"/>
       <limit effort="0.0" lower="-3.14159" upper="3.14159" velocity="0.0"/>
    </joint>
    <joint name="Leg2_Leg12" type="revolute">
       <parent link="Leg2"/>
       <child  link="Leg12"/>
       <origin rpy="0 0 0" xyz="0.7606311318604372 1.2076384124527688 1.1877392017250876" />
     <axis xyz="1 0 0"/>
       <limit effort="0.0" lower="-3.14159" upper="3.14159" velocity="0.0"/>
    </joint>
    <joint name="Leg3_Leg13" type="revolute">
       <parent link="Leg3"/>
       <child  link="Leg13"/>
       <origin rpy="0 0 0" xyz="0.7217682783672178 1.1965138821994754 1.4668793939963973" />
     <axis xyz="1 0 0"/>
       <limit effort="0.0" lower="-3.14159" upper="3.14159" velocity="0.0"/>
    </joint>
    <joint name="Leg6_Leg14" type="revolute">
       <parent link="Leg6"/>
       <child  link="Leg14"/>
       <origin rpy="0 0 0" xyz="0 1.0786938498202447 1.1209396831319098" />
     <axis xyz="1 0 0"/>
       <limit effort="0.0" lower="-3.14159" upper="3.14159" velocity="0.0"/>
    </joint>
    <joint name="Leg6_Leg15" type="revolute">
       <parent link="Leg6"/>
       <child  link="Leg15"/>
       <origin rpy="0 0 0" xyz="1.3911581217855242 1.0786938498202447 1.1209396831319098" />
     <axis xyz="1 0 0"/>
       <limit effort="0.0" lower="-3.14159" upper="3.14159" velocity="0.0"/>
    </joint>
    <joint name="Leg14_Leg16" type="revolute">
       <parent link="Leg14"/>
       <child  link="Leg16"/>
       <origin rpy="0 0 0" xyz="1.4189743987922927 0 1.1609208777271984" />
     <axis xyz="1 0 0"/>
       <limit effort="0.0" lower="-3.14159" upper="3.14159" velocity="0.0"/>
    </joint>
    <joint name="Leg10_Leg17" type="revolute">
       <parent link="Leg10"/>
       <child  link="Leg17"/>
       <origin rpy="0 0 0" xyz="0 1.182046846934821 1.0512952879584176" />
     <axis xyz="1 0 0"/>
       <limit effort="0.0" lower="-3.14159" upper="3.14159" velocity="0.0"/>
    </joint>
    <joint name="Leg1_Leg18" type="revolute">
       <parent link="Leg1"/>
       <child  link="Leg18"/>
       <origin rpy="0 0 0" xyz="1.0270463167613395 0.697979578642776 0.7847754942091983" />
     <axis xyz="1 0 0"/>
       <limit effort="0.0" lower="-3.14159" upper="3.14159" velocity="0.0"/>
    </joint>
    <joint name="Leg9_Leg19" type="revolute">
       <parent link="Leg9"/>
       <child  link="Leg19"/>
       <origin rpy="0 0 0" xyz="0.84417546304461 0.648011973376072 0" />
     <axis xyz="1 0 0"/>
       <limit effort="0.0" lower="-3.14159" upper="3.14159" velocity="0.0"/>
    </joint>
    <joint name="Leg8_Leg20" type="revolute">
       <parent link="Leg8"/>
       <child  link="Leg20"/>
       <origin rpy="0 0 0" xyz="1.4062128684891912 0 0.9506280389462877" />
     <axis xyz="1 0 0"/>
       <limit effort="0.0" lower="-3.14159" upper="3.14159" velocity="0.0"/>
    </joint>
    <joint name="Leg13_Leg21" type="revolute">
       <parent link="Leg13"/>
       <child  link="Leg21"/>
       <origin rpy="0 0 0" xyz="0 2.3233481205545 0" />
     <axis xyz="1 0 0"/>
       <limit effort="0.0" lower="-3.14159" upper="3.14159" velocity="0.0"/>
    </joint>
    <joint name="Leg18_Leg22" type="revolute">
       <parent link="Leg18"/>
       <child  link="Leg22"/>
       <origin rpy="0 0 0" xyz="0 0.5824340182333192 0.8874941171771011" />
     <axis xyz="1 0 0"/>
       <limit effort="0.0" lower="-3.14159" upper="3.14159" velocity="0.0"/>
    </joint>
    <joint name="Leg4_Leg23" type="revolute">
       <parent link="Leg4"/>
       <child  link="Leg23"/>
       <origin rpy="0 0 0" xyz="0.5167340403972479 0 1.1810366557304284" />
     <axis xyz="1 0 0"/>
       <limit effort="0.0" lower="-3.14159" upper="3.14159" velocity="0.0"/>
    </joint>
    <joint name="Leg23_Leg24" type="revolute">
       <parent link="Leg23"/>
       <child  link="Leg24"/>
       <origin rpy="0 0 0" xyz="0 0 2.3461926280717127" />
     <axis xyz="1 0 0"/>
       <limit effort="0.0" lower="-3.14159" upper="3.14159" velocity="0.0"/>
    </joint>
    <joint name="Leg19_Leg25" type="revolute">
       <parent link="Leg19"/>
       <child  link="Leg25"/>
       <origin rpy="0 0 0" xyz="0 0 2.612537143291548" />
     <axis xyz="1 0 0"/>
       <limit effort="0.0" lower="-3.14159" upper="3.14159" velocity="0.0"/>
    </joint>
</robot>