<robot name = "robot">
    <link name="Torso">
        <inertial>
            <origin xyz="0 0 1.4107539499756927" rpy="0 0 0"/>
            <mass value="1" />
            <inertia ixx="100" ixy="0" ixz="0" iyy="100" iyz="0" izz="100" />
        </inertial>
        <visual>
            <origin xyz="0 0 1.4107539499756927" rpy="0 0 0"/>
            <geometry>
                <box size="2.176690777185743 2.46755034687136 2.8215078999513854" />
            </geometry>
            <material name="Green">
                <color rgba="0 180.0 0.0 1.0"/>
            </material>
        </visual>
        <collision>
            <origin xyz="0 0 1.4107539499756927" rpy="0 0 0"/>
            <geometry>
                <box size="2.176690777185743 2.46755034687136 2.8215078999513854" />
            </geometry>
        </collision>
    </link>
    <link name="Leg1">
        <inertial>
            <origin xyz="0 1.2607930699964067 0" rpy="0 0 0"/>
            <mass value="1" />
            <inertia ixx="100" ixy="0" ixz="0" iyy="100" iyz="0" izz="100" />
        </inertial>
        <visual>
            <origin xyz="0 1.2607930699964067 0" rpy="0 0 0"/>
            <geometry>
                <box size="2.049924138189745 2.5215861399928134 1.4275414608590264" />
            </geometry>
            <material name="Blue">
                <color rgba="0 1.0 1.0 1.0"/>
            </material>
        </visual>
        <collision>
            <origin xyz="0 1.2607930699964067 0" rpy="0 0 0"/>
            <geometry>
                <box size="2.049924138189745 2.5215861399928134 1.4275414608590264" />
            </geometry>
        </collision>
    </link>
    <link name="Leg2">
        <inertial>
            <origin xyz="0 0 1.0710836354296491" rpy="0 0 0"/>
            <mass value="1" />
            <inertia ixx="100" ixy="0" ixz="0" iyy="100" iyz="0" izz="100" />
        </inertial>
        <visual>
            <origin xyz="0 0 1.0710836354296491" rpy="0 0 0"/>
            <geometry>
                <box size="2.494210358943059 2.6367709181488026 2.1421672708592983" />
            </geometry>
            <material name="Blue">
                <color rgba="0 1.0 1.0 1.0"/>
            </material>
        </visual>
        <collision>
            <origin xyz="0 0 1.0710836354296491" rpy="0 0 0"/>
            <geometry>
                <box size="2.494210358943059 2.6367709181488026 2.1421672708592983" />
            </geometry>
        </collision>
    </link>
    <link name="Leg3">
        <inertial>
            <origin xyz="0 1.0906276839043316 0" rpy="0 0 0"/>
            <mass value="1" />
            <inertia ixx="100" ixy="0" ixz="0" iyy="100" iyz="0" izz="100" />
        </inertial>
        <visual>
            <origin xyz="0 1.0906276839043316 0" rpy="0 0 0"/>
            <geometry>
                <box size="1.596023278541864 2.1812553678086632 2.6638291952986557" />
            </geometry>
            <material name="Green">
                <color rgba="0 180.0 0.0 1.0"/>
            </material>
        </visual>
        <collision>
            <origin xyz="0 1.0906276839043316 0" rpy="0 0 0"/>
            <geometry>
                <box size="1.596023278541864 2.1812553678086632 2.6638291952986557" />
            </geometry>
        </collision>
    </link>
    <link name="Leg4">
        <inertial>
            <origin xyz="0 1.0065471519070746 0" rpy="0 0 0"/>
            <mass value="1" />
            <inertia ixx="100" ixy="0" ixz="0" iyy="100" iyz="0" izz="100" />
        </inertial>
        <visual>
            <origin xyz="0 1.0065471519070746 0" rpy="0 0 0"/>
            <geometry>
                <box size="2.562514571233619 2.013094303814149 1.0571905177257759" />
            </geometry>
            <material name="Green">
                <color rgba="0 180.0 0.0 1.0"/>
            </material>
        </visual>
        <collision>
            <origin xyz="0 1.0065471519070746 0" rpy="0 0 0"/>
            <geometry>
                <box size="2.562514571233619 2.013094303814149 1.0571905177257759" />
            </geometry>
        </collision>
    </link>
    <link name="Leg5">
        <inertial>
            <origin xyz="0 0 0.9347631771484887" rpy="0 0 0"/>
            <mass value="1" />
            <inertia ixx="100" ixy="0" ixz="0" iyy="100" iyz="0" izz="100" />
        </inertial>
        <visual>
            <origin xyz="0 0 0.9347631771484887" rpy="0 0 0"/>
            <geometry>
                <box size="2.5332620545761473 1.9962471504846322 1.8695263542969773" />
            </geometry>
            <material name="Blue">
                <color rgba="0 1.0 1.0 1.0"/>
            </material>
        </visual>
        <collision>
            <origin xyz="0 0 0.9347631771484887" rpy="0 0 0"/>
            <geometry>
                <box size="2.5332620545761473 1.9962471504846322 1.8695263542969773" />
            </geometry>
        </collision>
    </link>
    <link name="Leg6">
        <inertial>
            <origin xyz="0 0 0.6430203376879559" rpy="0 0 0"/>
            <mass value="1" />
            <inertia ixx="100" ixy="0" ixz="0" iyy="100" iyz="0" izz="100" />
        </inertial>
        <visual>
            <origin xyz="0 0 0.6430203376879559" rpy="0 0 0"/>
            <geometry>
                <box size="2.7678289765387154 2.748493569889227 1.2860406753759117" />
            </geometry>
            <material name="Blue">
                <color rgba="0 1.0 1.0 1.0"/>
            </material>
        </visual>
        <collision>
            <origin xyz="0 0 0.6430203376879559" rpy="0 0 0"/>
            <geometry>
                <box size="2.7678289765387154 2.748493569889227 1.2860406753759117" />
            </geometry>
        </collision>
    </link>
    <link name="Leg7">
        <inertial>
            <origin xyz="0 0 1.2936898435550237" rpy="0 0 0"/>
            <mass value="1" />
            <inertia ixx="100" ixy="0" ixz="0" iyy="100" iyz="0" izz="100" />
        </inertial>
        <visual>
            <origin xyz="0 0 1.2936898435550237" rpy="0 0 0"/>
            <geometry>
                <box size="1.4267885488722445 1.8424553562552042 2.5873796871100474" />
            </geometry>
            <material name="Blue">
                <color rgba="0 1.0 1.0 1.0"/>
            </material>
        </visual>
        <collision>
            <origin xyz="0 0 1.2936898435550237" rpy="0 0 0"/>
            <geometry>
                <box size="1.4267885488722445 1.8424553562552042 2.5873796871100474" />
            </geometry>
        </collision>
    </link>
    <link name="Leg8">
        <inertial>
            <origin xyz="0.5846154593160995 0 0" rpy="0 0 0"/>
            <mass value="1" />
            <inertia ixx="100" ixy="0" ixz="0" iyy="100" iyz="0" izz="100" />
        </inertial>
        <visual>
            <origin xyz="0.5846154593160995 0 0" rpy="0 0 0"/>
            <geometry>
                <box size="1.169230918632199 1.1996384575033405 1.5898790473727886" />
            </geometry>
            <material name="Blue">
                <color rgba="0 1.0 1.0 1.0"/>
            </material>
        </visual>
        <collision>
            <origin xyz="0.5846154593160995 0 0" rpy="0 0 0"/>
            <geometry>
                <box size="1.169230918632199 1.1996384575033405 1.5898790473727886" />
            </geometry>
        </collision>
    </link>
    <link name="Leg9">
        <inertial>
            <origin xyz="0 0.7011055027777882 0" rpy="0 0 0"/>
            <mass value="1" />
            <inertia ixx="100" ixy="0" ixz="0" iyy="100" iyz="0" izz="100" />
        </inertial>
        <visual>
            <origin xyz="0 0.7011055027777882 0" rpy="0 0 0"/>
            <geometry>
                <box size="1.9828764600396502 1.4022110055555763 2.96788581006314" />
            </geometry>
            <material name="Blue">
                <color rgba="0 1.0 1.0 1.0"/>
            </material>
        </visual>
        <collision>
            <origin xyz="0 0.7011055027777882 0" rpy="0 0 0"/>
            <geometry>
                <box size="1.9828764600396502 1.4022110055555763 2.96788581006314" />
            </geometry>
        </collision>
    </link>
    <link name="Leg10">
        <inertial>
            <origin xyz="0 1.4576958467342258 0" rpy="0 0 0"/>
            <mass value="1" />
            <inertia ixx="100" ixy="0" ixz="0" iyy="100" iyz="0" izz="100" />
        </inertial>
        <visual>
            <origin xyz="0 1.4576958467342258 0" rpy="0 0 0"/>
            <geometry>
                <box size="2.418892594078042 2.9153916934684516 2.3818940664202692" />
            </geometry>
            <material name="Green">
                <color rgba="0 180.0 0.0 1.0"/>
            </material>
        </visual>
        <collision>
            <origin xyz="0 1.4576958467342258 0" rpy="0 0 0"/>
            <geometry>
                <box size="2.418892594078042 2.9153916934684516 2.3818940664202692" />
            </geometry>
        </collision>
    </link>
    <link name="Leg11">
        <inertial>
            <origin xyz="0 0.8734941891478458 0" rpy="0 0 0"/>
            <mass value="1" />
            <inertia ixx="100" ixy="0" ixz="0" iyy="100" iyz="0" izz="100" />
        </inertial>
        <visual>
            <origin xyz="0 0.8734941891478458 0" rpy="0 0 0"/>
            <geometry>
                <box size="1.9252247473178652 1.7469883782956916 1.0922366254460765" />
            </geometry>
            <material name="Green">
                <color rgba="0 180.0 0.0 1.0"/>
            </material>
        </visual>
        <collision>
            <origin xyz="0 0.8734941891478458 0" rpy="0 0 0"/>
            <geometry>
                <box size="1.9252247473178652 1.7469883782956916 1.0922366254460765" />
            </geometry>
        </collision>
    </link>
    <link name="Leg12">
        <inertial>
            <origin xyz="0.8789677983476407 0 0" rpy="0 0 0"/>
            <mass value="1" />
            <inertia ixx="100" ixy="0" ixz="0" iyy="100" iyz="0" izz="100" />
        </inertial>
        <visual>
            <origin xyz="0.8789677983476407 0 0" rpy="0 0 0"/>
            <geometry>
                <box size="1.7579355966952814 2.4898179881593516 2.813218889489104" />
            </geometry>
            <material name="Green">
                <color rgba="0 180.0 0.0 1.0"/>
            </material>
        </visual>
        <collision>
            <origin xyz="0.8789677983476407 0 0" rpy="0 0 0"/>
            <geometry>
                <box size="1.7579355966952814 2.4898179881593516 2.813218889489104" />
            </geometry>
        </collision>
    </link>
    <link name="Leg13">
        <inertial>
            <origin xyz="1.2046895559019783 0 0" rpy="0 0 0"/>
            <mass value="1" />
            <inertia ixx="100" ixy="0" ixz="0" iyy="100" iyz="0" izz="100" />
        </inertial>
        <visual>
            <origin xyz="1.2046895559019783 0 0" rpy="0 0 0"/>
            <geometry>
                <box size="2.4093791118039567 2.148739617232623 1.8924219393985566" />
            </geometry>
            <material name="Green">
                <color rgba="0 180.0 0.0 1.0"/>
            </material>
        </visual>
        <collision>
            <origin xyz="1.2046895559019783 0 0" rpy="0 0 0"/>
            <geometry>
                <box size="2.4093791118039567 2.148739617232623 1.8924219393985566" />
            </geometry>
        </collision>
    </link>
    <link name="Leg14">
        <inertial>
            <origin xyz="0 0 1.4042206605867236" rpy="0 0 0"/>
            <mass value="1" />
            <inertia ixx="100" ixy="0" ixz="0" iyy="100" iyz="0" izz="100" />
        </inertial>
        <visual>
            <origin xyz="0 0 1.4042206605867236" rpy="0 0 0"/>
            <geometry>
                <box size="1.7916177654363028 2.91192030971067 2.808441321173447" />
            </geometry>
            <material name="Blue">
                <color rgba="0 1.0 1.0 1.0"/>
            </material>
        </visual>
        <collision>
            <origin xyz="0 0 1.4042206605867236" rpy="0 0 0"/>
            <geometry>
                <box size="1.7916177654363028 2.91192030971067 2.808441321173447" />
            </geometry>
        </collision>
    </link>
    <link name="Leg15">
        <inertial>
            <origin xyz="0 0.8583086346220232 0" rpy="0 0 0"/>
            <mass value="1" />
            <inertia ixx="100" ixy="0" ixz="0" iyy="100" iyz="0" izz="100" />
        </inertial>
        <visual>
            <origin xyz="0 0.8583086346220232 0" rpy="0 0 0"/>
            <geometry>
                <box size="2.955288801345676 1.7166172692440465 1.2760973768610404" />
            </geometry>
            <material name="Green">
                <color rgba="0 180.0 0.0 1.0"/>
            </material>
        </visual>
        <collision>
            <origin xyz="0 0.8583086346220232 0" rpy="0 0 0"/>
            <geometry>
                <box size="2.955288801345676 1.7166172692440465 1.2760973768610404" />
            </geometry>
        </collision>
    </link>
    <link name="Leg16">
        <inertial>
            <origin xyz="0 0 1.058699774325131" rpy="0 0 0"/>
            <mass value="1" />
            <inertia ixx="100" ixy="0" ixz="0" iyy="100" iyz="0" izz="100" />
        </inertial>
        <visual>
            <origin xyz="0 0 1.058699774325131" rpy="0 0 0"/>
            <geometry>
                <box size="2.0252089503803097 2.3909442312452422 2.117399548650262" />
            </geometry>
            <material name="Blue">
                <color rgba="0 1.0 1.0 1.0"/>
            </material>
        </visual>
        <collision>
            <origin xyz="0 0 1.058699774325131" rpy="0 0 0"/>
            <geometry>
                <box size="2.0252089503803097 2.3909442312452422 2.117399548650262" />
            </geometry>
        </collision>
    </link>
    <link name="Leg17">
        <inertial>
            <origin xyz="0 0.7322617977886381 0" rpy="0 0 0"/>
            <mass value="1" />
            <inertia ixx="100" ixy="0" ixz="0" iyy="100" iyz="0" izz="100" />
        </inertial>
        <visual>
            <origin xyz="0 0.7322617977886381 0" rpy="0 0 0"/>
            <geometry>
                <box size="1.938551288044437 1.4645235955772762 2.41814171347001" />
            </geometry>
            <material name="Blue">
                <color rgba="0 1.0 1.0 1.0"/>
            </material>
        </visual>
        <collision>
            <origin xyz="0 0.7322617977886381 0" rpy="0 0 0"/>
            <geometry>
                <box size="1.938551288044437 1.4645235955772762 2.41814171347001" />
            </geometry>
        </collision>
    </link>
    <link name="Leg18">
        <inertial>
            <origin xyz="0.5337250098533545 0 0" rpy="0 0 0"/>
            <mass value="1" />
            <inertia ixx="100" ixy="0" ixz="0" iyy="100" iyz="0" izz="100" />
        </inertial>
        <visual>
            <origin xyz="0.5337250098533545 0 0" rpy="0 0 0"/>
            <geometry>
                <box size="1.067450019706709 2.17737851294977 1.856556912309901" />
            </geometry>
            <material name="Green">
                <color rgba="0 180.0 0.0 1.0"/>
            </material>
        </visual>
        <collision>
            <origin xyz="0.5337250098533545 0 0" rpy="0 0 0"/>
            <geometry>
                <box size="1.067450019706709 2.17737851294977 1.856556912309901" />
            </geometry>
        </collision>
    </link>
    <link name="Leg19">
        <inertial>
            <origin xyz="1.3178462159001012 0 0" rpy="0 0 0"/>
            <mass value="1" />
            <inertia ixx="100" ixy="0" ixz="0" iyy="100" iyz="0" izz="100" />
        </inertial>
        <visual>
            <origin xyz="1.3178462159001012 0 0" rpy="0 0 0"/>
            <geometry>
                <box size="2.6356924318002024 1.6963279611040611 1.2239898141259362" />
            </geometry>
            <material name="Blue">
                <color rgba="0 1.0 1.0 1.0"/>
            </material>
        </visual>
        <collision>
            <origin xyz="1.3178462159001012 0 0" rpy="0 0 0"/>
            <geometry>
                <box size="2.6356924318002024 1.6963279611040611 1.2239898141259362" />
            </geometry>
        </collision>
    </link>
    <link name="Leg20">
        <inertial>
            <origin xyz="1.2239649629261988 0 0" rpy="0 0 0"/>
            <mass value="1" />
            <inertia ixx="100" ixy="0" ixz="0" iyy="100" iyz="0" izz="100" />
        </inertial>
        <visual>
            <origin xyz="1.2239649629261988 0 0" rpy="0 0 0"/>
            <geometry>
                <box size="2.4479299258523977 2.9829107075624224 1.4555693421725182" />
            </geometry>
            <material name="Green">
                <color rgba="0 180.0 0.0 1.0"/>
            </material>
        </visual>
        <collision>
            <origin xyz="1.2239649629261988 0 0" rpy="0 0 0"/>
            <geometry>
                <box size="2.4479299258523977 2.9829107075624224 1.4555693421725182" />
            </geometry>
        </collision>
    </link>
    <link name="Leg21">
        <inertial>
            <origin xyz="0 0.6714008991081645 0" rpy="0 0 0"/>
            <mass value="1" />
            <inertia ixx="100" ixy="0" ixz="0" iyy="100" iyz="0" izz="100" />
        </inertial>
        <visual>
            <origin xyz="0 0.6714008991081645 0" rpy="0 0 0"/>
            <geometry>
                <box size="1.0792994408713947 1.342801798216329 1.2283779867989244" />
            </geometry>
            <material name="Blue">
                <color rgba="0 1.0 1.0 1.0"/>
            </material>
        </visual>
        <collision>
            <origin xyz="0 0.6714008991081645 0" rpy="0 0 0"/>
            <geometry>
                <box size="1.0792994408713947 1.342801798216329 1.2283779867989244" />
            </geometry>
        </collision>
    </link>
    <link name="Leg22">
        <inertial>
            <origin xyz="0 0.9759128483825655 0" rpy="0 0 0"/>
            <mass value="1" />
            <inertia ixx="100" ixy="0" ixz="0" iyy="100" iyz="0" izz="100" />
        </inertial>
        <visual>
            <origin xyz="0 0.9759128483825655 0" rpy="0 0 0"/>
            <geometry>
                <box size="1.3692762047365898 1.951825696765131 2.890728682727974" />
            </geometry>
            <material name="Blue">
                <color rgba="0 1.0 1.0 1.0"/>
            </material>
        </visual>
        <collision>
            <origin xyz="0 0.9759128483825655 0" rpy="0 0 0"/>
            <geometry>
                <box size="1.3692762047365898 1.951825696765131 2.890728682727974" />
            </geometry>
        </collision>
    </link>
    <link name="Leg23">
        <inertial>
            <origin xyz="0 0 1.0792505401426022" rpy="0 0 0"/>
            <mass value="1" />
            <inertia ixx="100" ixy="0" ixz="0" iyy="100" iyz="0" izz="100" />
        </inertial>
        <visual>
            <origin xyz="0 0 1.0792505401426022" rpy="0 0 0"/>
            <geometry>
                <box size="1.5033704118406424 2.5746967228819573 2.1585010802852045" />
            </geometry>
            <material name="Blue">
                <color rgba="0 1.0 1.0 1.0"/>
            </material>
        </visual>
        <collision>
            <origin xyz="0 0 1.0792505401426022" rpy="0 0 0"/>
            <geometry>
                <box size="1.5033704118406424 2.5746967228819573 2.1585010802852045" />
            </geometry>
        </collision>
    </link>
    <link name="Leg24">
        <inertial>
            <origin xyz="0 0.5714006268993261 0" rpy="0 0 0"/>
            <mass value="1" />
            <inertia ixx="100" ixy="0" ixz="0" iyy="100" iyz="0" izz="100" />
        </inertial>
        <visual>
            <origin xyz="0 0.5714006268993261 0" rpy="0 0 0"/>
            <geometry>
                <box size="2.141867653917691 1.1428012537986523 1.5833055020248812" />
            </geometry>
            <material name="Green">
                <color rgba="0 180.0 0.0 1.0"/>
            </material>
        </visual>
        <collision>
            <origin xyz="0 0.5714006268993261 0" rpy="0 0 0"/>
            <geometry>
                <box size="2.141867653917691 1.1428012537986523 1.5833055020248812" />
            </geometry>
        </collision>
    </link>
    <link name="Leg25">
        <inertial>
            <origin xyz="0 0 0.8808791947887988" rpy="0 0 0"/>
            <mass value="1" />
            <inertia ixx="100" ixy="0" ixz="0" iyy="100" iyz="0" izz="100" />
        </inertial>
        <visual>
            <origin xyz="0 0 0.8808791947887988" rpy="0 0 0"/>
            <geometry>
                <box size="2.6712625351824903 2.7454806077647613 1.7617583895775977" />
            </geometry>
            <material name="Green">
                <color rgba="0 180.0 0.0 1.0"/>
            </material>
        </visual>
        <collision>
            <origin xyz="0 0 0.8808791947887988" rpy="0 0 0"/>
            <geometry>
                <box size="2.6712625351824903 2.7454806077647613 1.7617583895775977" />
            </geometry>
        </collision>
    </link>
    <link name="Leg26">
        <inertial>
            <origin xyz="0 0.6898678917798637 0" rpy="0 0 0"/>
            <mass value="1" />
            <inertia ixx="100" ixy="0" ixz="0" iyy="100" iyz="0" izz="100" />
        </inertial>
        <visual>
            <origin xyz="0 0.6898678917798637 0" rpy="0 0 0"/>
            <geometry>
                <box size="1.0469039137879161 1.3797357835597275 2.22617855702907" />
            </geometry>
            <material name="Blue">
                <color rgba="0 1.0 1.0 1.0"/>
            </material>
        </visual>
        <collision>
            <origin xyz="0 0.6898678917798637 0" rpy="0 0 0"/>
            <geometry>
                <box size="1.0469039137879161 1.3797357835597275 2.22617855702907" />
            </geometry>
        </collision>
    </link>
    <link name="Leg27">
        <inertial>
            <origin xyz="0 1.3540891719891617 0" rpy="0 0 0"/>
            <mass value="1" />
            <inertia ixx="100" ixy="0" ixz="0" iyy="100" iyz="0" izz="100" />
        </inertial>
        <visual>
            <origin xyz="0 1.3540891719891617 0" rpy="0 0 0"/>
            <geometry>
                <box size="2.0164870254501572 2.7081783439783234 1.5457612159437149" />
            </geometry>
            <material name="Green">
                <color rgba="0 180.0 0.0 1.0"/>
            </material>
        </visual>
        <collision>
            <origin xyz="0 1.3540891719891617 0" rpy="0 0 0"/>
            <geometry>
                <box size="2.0164870254501572 2.7081783439783234 1.5457612159437149" />
            </geometry>
        </collision>
    </link>
    <joint name="Torso_Leg1" type="revolute">
       <parent link="Torso"/>
       <child  link="Leg1"/>
       <origin rpy="0 0 0" xyz="0 1.23377517343568 1.4107539499756927" />
     <axis xyz="1 0 0"/>
       <limit effort="0.0" lower="-3.14159" upper="3.14159" velocity="0.0"/>
    </joint>
    <joint name="Torso_Leg2" type="revolute">
       <parent link="Torso"/>
       <child  link="Leg2"/>
       <origin rpy="0 0 0" xyz="0 1.2607930699964067 0.7137707304295132" />
     <axis xyz="1 0 0"/>
       <limit effort="0.0" lower="-3.14159" upper="3.14159" velocity="0.0"/>
    </joint>
    <joint name="Leg1_Leg3" type="revolute">
       <parent link="Leg1"/>
       <child  link="Leg3"/>
       <origin rpy="0 0 0" xyz="0 1.3183854590744013 1.0710836354296491" />
     <axis xyz="1 0 0"/>
       <limit effort="0.0" lower="-3.14159" upper="3.14159" velocity="0.0"/>
    </joint>
    <joint name="Leg3_Leg4" type="revolute">
       <parent link="Leg3"/>
       <child  link="Leg4"/>
       <origin rpy="0 0 0" xyz="0 2.013094303814149 0" />
     <axis xyz="1 0 0"/>
       <limit effort="0.0" lower="-3.14159" upper="3.14159" velocity="0.0"/>
    </joint>
    <joint name="Leg4_Leg5" type="revolute">
       <parent link="Leg4"/>
       <child  link="Leg5"/>
       <origin rpy="0 0 0" xyz="0 0 1.8695263542969773" />
     <axis xyz="1 0 0"/>
       <limit effort="0.0" lower="-3.14159" upper="3.14159" velocity="0.0"/>
    </joint>
    <joint name="Leg2_Leg6" type="revolute">
       <parent link="Leg2"/>
       <child  link="Leg6"/>
       <origin rpy="0 0 0" xyz="0 1.0906276839043316 1.3319145976493278" />
     <axis xyz="1 0 0"/>
       <limit effort="0.0" lower="-3.14159" upper="3.14159" velocity="0.0"/>
    </joint>
    <joint name="Leg6_Leg7" type="revolute">
       <parent link="Leg6"/>
       <child  link="Leg7"/>
       <origin rpy="0 0 0" xyz="0 0 2.5873796871100474" />
     <axis xyz="1 0 0"/>
       <limit effort="0.0" lower="-3.14159" upper="3.14159" velocity="0.0"/>
    </joint>
    <joint name="Leg4_Leg8" type="revolute">
       <parent link="Leg4"/>
       <child  link="Leg8"/>
       <origin rpy="0 0 0" xyz="1.2666310272880736 0 1.8695263542969773" />
     <axis xyz="1 0 0"/>
       <limit effort="0.0" lower="-3.14159" upper="3.14159" velocity="0.0"/>
    </joint>
    <joint name="Leg7_Leg9" type="revolute">
       <parent link="Leg7"/>
       <child  link="Leg9"/>
       <origin rpy="0 0 0" xyz="0.5846154593160995 0.5998192287516703 0" />
     <axis xyz="1 0 0"/>
       <limit effort="0.0" lower="-3.14159" upper="3.14159" velocity="0.0"/>
    </joint>
    <joint name="Leg8_Leg10" type="revolute">
       <parent link="Leg8"/>
       <child  link="Leg10"/>
       <origin rpy="0 0 0" xyz="0 1.4022110055555763 0" />
     <axis xyz="1 0 0"/>
       <limit effort="0.0" lower="-3.14159" upper="3.14159" velocity="0.0"/>
    </joint>
    <joint name="Leg10_Leg11" type="revolute">
       <parent link="Leg10"/>
       <child  link="Leg11"/>
       <origin rpy="0 0 0" xyz="0 1.7469883782956916 0" />
     <axis xyz="1 0 0"/>
       <limit effort="0.0" lower="-3.14159" upper="3.14159" velocity="0.0"/>
    </joint>
    <joint name="Torso_Leg12" type="revolute">
       <parent link="Torso"/>
       <child  link="Leg12"/>
       <origin rpy="0 0 0" xyz="1.0249620690948724 1.2607930699964067 0.7137707304295132" />
     <axis xyz="1 0 0"/>
       <limit effort="0.0" lower="-3.14159" upper="3.14159" velocity="0.0"/>
    </joint>
    <joint name="Leg10_Leg13" type="revolute">
       <parent link="Leg10"/>
       <child  link="Leg13"/>
       <origin rpy="0 0 0" xyz="0.9626123736589326 1.7469883782956916 0" />
     <axis xyz="1 0 0"/>
       <limit effort="0.0" lower="-3.14159" upper="3.14159" velocity="0.0"/>
    </joint>
    <joint name="Leg1_Leg14" type="revolute">
       <parent link="Leg1"/>
       <child  link="Leg14"/>
       <origin rpy="0 0 0" xyz="0 1.3183854590744013 2.1421672708592983" />
     <axis xyz="1 0 0"/>
       <limit effort="0.0" lower="-3.14159" upper="3.14159" velocity="0.0"/>
    </joint>
    <joint name="Leg5_Leg15" type="revolute">
       <parent link="Leg5"/>
       <child  link="Leg15"/>
       <origin rpy="0 0 0" xyz="0 1.3742467849446136 0.6430203376879559" />
     <axis xyz="1 0 0"/>
       <limit effort="0.0" lower="-3.14159" upper="3.14159" velocity="0.0"/>
    </joint>
    <joint name="Leg9_Leg16" type="revolute">
       <parent link="Leg9"/>
       <child  link="Leg16"/>
       <origin rpy="0 0 0" xyz="0 1.4576958467342258 1.1909470332101346" />
     <axis xyz="1 0 0"/>
       <limit effort="0.0" lower="-3.14159" upper="3.14159" velocity="0.0"/>
    </joint>
    <joint name="Leg6_Leg17" type="revolute">
       <parent link="Leg6"/>
       <child  link="Leg17"/>
       <origin rpy="0 0 0" xyz="0 0.9212276781276021 2.5873796871100474" />
     <axis xyz="1 0 0"/>
       <limit effort="0.0" lower="-3.14159" upper="3.14159" velocity="0.0"/>
    </joint>
    <joint name="Leg14_Leg18" type="revolute">
       <parent link="Leg14"/>
       <child  link="Leg18"/>
       <origin rpy="0 0 0" xyz="1.477644400672838 0.8583086346220232 0" />
     <axis xyz="1 0 0"/>
       <limit effort="0.0" lower="-3.14159" upper="3.14159" velocity="0.0"/>
    </joint>
    <joint name="Leg11_Leg19" type="revolute">
       <parent link="Leg11"/>
       <child  link="Leg19"/>
       <origin rpy="0 0 0" xyz="1.7579355966952814 0 0" />
     <axis xyz="1 0 0"/>
       <limit effort="0.0" lower="-3.14159" upper="3.14159" velocity="0.0"/>
    </joint>
    <joint name="Leg5_Leg20" type="revolute">
       <parent link="Leg5"/>
       <child  link="Leg20"/>
       <origin rpy="0 0 0" xyz="1.3839144882693577 1.3742467849446136 0.6430203376879559" />
     <axis xyz="1 0 0"/>
       <limit effort="0.0" lower="-3.14159" upper="3.14159" velocity="0.0"/>
    </joint>
    <joint name="Leg11_Leg21" type="revolute">
       <parent link="Leg11"/>
       <child  link="Leg21"/>
       <origin rpy="0 0 0" xyz="1.7579355966952814 1.2449089940796758 0" />
     <axis xyz="1 0 0"/>
       <limit effort="0.0" lower="-3.14159" upper="3.14159" velocity="0.0"/>
    </joint>
    <joint name="Leg9_Leg22" type="revolute">
       <parent link="Leg9"/>
       <child  link="Leg22"/>
       <origin rpy="0 0 0" xyz="0 2.9153916934684516 1.1909470332101346" />
     <axis xyz="1 0 0"/>
       <limit effort="0.0" lower="-3.14159" upper="3.14159" velocity="0.0"/>
    </joint>
    <joint name="Leg16_Leg23" type="revolute">
       <parent link="Leg16"/>
       <child  link="Leg23"/>
       <origin rpy="0 0 0" xyz="0 0.7322617977886381 1.209070856735005" />
     <axis xyz="1 0 0"/>
       <limit effort="0.0" lower="-3.14159" upper="3.14159" velocity="0.0"/>
    </joint>
    <joint name="Leg2_Leg24" type="revolute">
       <parent link="Leg2"/>
       <child  link="Leg24"/>
       <origin rpy="0 0 0" xyz="0 2.1812553678086632 1.3319145976493278" />
     <axis xyz="1 0 0"/>
       <limit effort="0.0" lower="-3.14159" upper="3.14159" velocity="0.0"/>
    </joint>
    <joint name="Leg12_Leg25" type="revolute">
       <parent link="Leg12"/>
       <child  link="Leg25"/>
       <origin rpy="0 0 0" xyz="1.2046895559019783 0 0.9462109696992783" />
     <axis xyz="1 0 0"/>
       <limit effort="0.0" lower="-3.14159" upper="3.14159" velocity="0.0"/>
    </joint>
    <joint name="Leg19_Leg26" type="revolute">
       <parent link="Leg19"/>
       <child  link="Leg26"/>
       <origin rpy="0 0 0" xyz="1.2239649629261988 1.4914553537812112 0" />
     <axis xyz="1 0 0"/>
       <limit effort="0.0" lower="-3.14159" upper="3.14159" velocity="0.0"/>
    </joint>
    <joint name="Leg18_Leg27" type="revolute">
       <parent link="Leg18"/>
       <child  link="Leg27"/>
       <origin rpy="0 0 0" xyz="1.3178462159001012 0.8481639805520306 0" />
     <axis xyz="1 0 0"/>
       <limit effort="0.0" lower="-3.14159" upper="3.14159" velocity="0.0"/>
    </joint>
</robot>