<robot name = "robot">
    <link name="Torso">
        <inertial>
            <origin xyz="0 0 1.1905804517893512" rpy="0 0 0"/>
            <mass value="1" />
            <inertia ixx="100" ixy="0" ixz="0" iyy="100" iyz="0" izz="100" />
        </inertial>
        <visual>
            <origin xyz="0 0 1.1905804517893512" rpy="0 0 0"/>
            <geometry>
                <box size="2.599069711834865 2.8053414862209305 2.3811609035787025" />
            </geometry>
            <material name="Green">
                <color rgba="0 180.0 0.0 1.0"/>
            </material>
        </visual>
        <collision>
            <origin xyz="0 0 1.1905804517893512" rpy="0 0 0"/>
            <geometry>
                <box size="2.599069711834865 2.8053414862209305 2.3811609035787025" />
            </geometry>
        </collision>
    </link>
    <link name="Leg1">
        <inertial>
            <origin xyz="1.2653719880230174 0 0" rpy="0 0 0"/>
            <mass value="1" />
            <inertia ixx="100" ixy="0" ixz="0" iyy="100" iyz="0" izz="100" />
        </inertial>
        <visual>
            <origin xyz="1.2653719880230174 0 0" rpy="0 0 0"/>
            <geometry>
                <box size="2.530743976046035 2.4016767140328295 2.852606141320218" />
            </geometry>
            <material name="Green">
                <color rgba="0 180.0 0.0 1.0"/>
            </material>
        </visual>
        <collision>
            <origin xyz="1.2653719880230174 0 0" rpy="0 0 0"/>
            <geometry>
                <box size="2.530743976046035 2.4016767140328295 2.852606141320218" />
            </geometry>
        </collision>
    </link>
    <link name="Leg2">
        <inertial>
            <origin xyz="0 0 1.3284665470275627" rpy="0 0 0"/>
            <mass value="1" />
            <inertia ixx="100" ixy="0" ixz="0" iyy="100" iyz="0" izz="100" />
        </inertial>
        <visual>
            <origin xyz="0 0 1.3284665470275627" rpy="0 0 0"/>
            <geometry>
                <box size="1.614695927526221 1.425025155552467 2.6569330940551255" />
            </geometry>
            <material name="Blue">
                <color rgba="0 1.0 1.0 1.0"/>
            </material>
        </visual>
        <collision>
            <origin xyz="0 0 1.3284665470275627" rpy="0 0 0"/>
            <geometry>
                <box size="1.614695927526221 1.425025155552467 2.6569330940551255" />
            </geometry>
        </collision>
    </link>
    <link name="Leg3">
        <inertial>
            <origin xyz="0.9085233129788147 0 0" rpy="0 0 0"/>
            <mass value="1" />
            <inertia ixx="100" ixy="0" ixz="0" iyy="100" iyz="0" izz="100" />
        </inertial>
        <visual>
            <origin xyz="0.9085233129788147 0 0" rpy="0 0 0"/>
            <geometry>
                <box size="1.8170466259576294 2.7352131420214527 1.5092679792674795" />
            </geometry>
            <material name="Green">
                <color rgba="0 180.0 0.0 1.0"/>
            </material>
        </visual>
        <collision>
            <origin xyz="0.9085233129788147 0 0" rpy="0 0 0"/>
            <geometry>
                <box size="1.8170466259576294 2.7352131420214527 1.5092679792674795" />
            </geometry>
        </collision>
    </link>
    <link name="Leg4">
        <inertial>
            <origin xyz="1.4326802893506694 0 0" rpy="0 0 0"/>
            <mass value="1" />
            <inertia ixx="100" ixy="0" ixz="0" iyy="100" iyz="0" izz="100" />
        </inertial>
        <visual>
            <origin xyz="1.4326802893506694 0 0" rpy="0 0 0"/>
            <geometry>
                <box size="2.8653605787013388 1.8368626917448627 2.032527245966669" />
            </geometry>
            <material name="Blue">
                <color rgba="0 1.0 1.0 1.0"/>
            </material>
        </visual>
        <collision>
            <origin xyz="1.4326802893506694 0 0" rpy="0 0 0"/>
            <geometry>
                <box size="2.8653605787013388 1.8368626917448627 2.032527245966669" />
            </geometry>
        </collision>
    </link>
    <link name="Leg5">
        <inertial>
            <origin xyz="0 1.1438802124047536 0" rpy="0 0 0"/>
            <mass value="1" />
            <inertia ixx="100" ixy="0" ixz="0" iyy="100" iyz="0" izz="100" />
        </inertial>
        <visual>
            <origin xyz="0 1.1438802124047536 0" rpy="0 0 0"/>
            <geometry>
                <box size="1.3587123004370227 2.287760424809507 1.9298306483523129" />
            </geometry>
            <material name="Blue">
                <color rgba="0 1.0 1.0 1.0"/>
            </material>
        </visual>
        <collision>
            <origin xyz="0 1.1438802124047536 0" rpy="0 0 0"/>
            <geometry>
                <box size="1.3587123004370227 2.287760424809507 1.9298306483523129" />
            </geometry>
        </collision>
    </link>
    <link name="Leg6">
        <inertial>
            <origin xyz="1.361473888632733 0 0" rpy="0 0 0"/>
            <mass value="1" />
            <inertia ixx="100" ixy="0" ixz="0" iyy="100" iyz="0" izz="100" />
        </inertial>
        <visual>
            <origin xyz="1.361473888632733 0 0" rpy="0 0 0"/>
            <geometry>
                <box size="2.722947777265466 1.9277878732094926 1.4059049027635073" />
            </geometry>
            <material name="Green">
                <color rgba="0 180.0 0.0 1.0"/>
            </material>
        </visual>
        <collision>
            <origin xyz="1.361473888632733 0 0" rpy="0 0 0"/>
            <geometry>
                <box size="2.722947777265466 1.9277878732094926 1.4059049027635073" />
            </geometry>
        </collision>
    </link>
    <link name="Leg7">
        <inertial>
            <origin xyz="0 0.7677500417030145 0" rpy="0 0 0"/>
            <mass value="1" />
            <inertia ixx="100" ixy="0" ixz="0" iyy="100" iyz="0" izz="100" />
        </inertial>
        <visual>
            <origin xyz="0 0.7677500417030145 0" rpy="0 0 0"/>
            <geometry>
                <box size="2.522025129753003 1.535500083406029 1.1831974347297824" />
            </geometry>
            <material name="Green">
                <color rgba="0 180.0 0.0 1.0"/>
            </material>
        </visual>
        <collision>
            <origin xyz="0 0.7677500417030145 0" rpy="0 0 0"/>
            <geometry>
                <box size="2.522025129753003 1.535500083406029 1.1831974347297824" />
            </geometry>
        </collision>
    </link>
    <link name="Leg8">
        <inertial>
            <origin xyz="0 0 1.0176949382111802" rpy="0 0 0"/>
            <mass value="1" />
            <inertia ixx="100" ixy="0" ixz="0" iyy="100" iyz="0" izz="100" />
        </inertial>
        <visual>
            <origin xyz="0 0 1.0176949382111802" rpy="0 0 0"/>
            <geometry>
                <box size="1.485896082073759 1.721193422232187 2.0353898764223604" />
            </geometry>
            <material name="Green">
                <color rgba="0 180.0 0.0 1.0"/>
            </material>
        </visual>
        <collision>
            <origin xyz="0 0 1.0176949382111802" rpy="0 0 0"/>
            <geometry>
                <box size="1.485896082073759 1.721193422232187 2.0353898764223604" />
            </geometry>
        </collision>
    </link>
    <link name="Leg9">
        <inertial>
            <origin xyz="0 0 1.4605372880595382" rpy="0 0 0"/>
            <mass value="1" />
            <inertia ixx="100" ixy="0" ixz="0" iyy="100" iyz="0" izz="100" />
        </inertial>
        <visual>
            <origin xyz="0 0 1.4605372880595382" rpy="0 0 0"/>
            <geometry>
                <box size="2.747648828133474 2.486100312724796 2.9210745761190764" />
            </geometry>
            <material name="Green">
                <color rgba="0 180.0 0.0 1.0"/>
            </material>
        </visual>
        <collision>
            <origin xyz="0 0 1.4605372880595382" rpy="0 0 0"/>
            <geometry>
                <box size="2.747648828133474 2.486100312724796 2.9210745761190764" />
            </geometry>
        </collision>
    </link>
    <link name="Leg10">
        <inertial>
            <origin xyz="0 0.5897031897408691 0" rpy="0 0 0"/>
            <mass value="1" />
            <inertia ixx="100" ixy="0" ixz="0" iyy="100" iyz="0" izz="100" />
        </inertial>
        <visual>
            <origin xyz="0 0.5897031897408691 0" rpy="0 0 0"/>
            <geometry>
                <box size="1.4836591907091443 1.1794063794817382 1.754248436695745" />
            </geometry>
            <material name="Green">
                <color rgba="0 180.0 0.0 1.0"/>
            </material>
        </visual>
        <collision>
            <origin xyz="0 0.5897031897408691 0" rpy="0 0 0"/>
            <geometry>
                <box size="1.4836591907091443 1.1794063794817382 1.754248436695745" />
            </geometry>
        </collision>
    </link>
    <link name="Leg11">
        <inertial>
            <origin xyz="0.6563339695769077 0 0" rpy="0 0 0"/>
            <mass value="1" />
            <inertia ixx="100" ixy="0" ixz="0" iyy="100" iyz="0" izz="100" />
        </inertial>
        <visual>
            <origin xyz="0.6563339695769077 0 0" rpy="0 0 0"/>
            <geometry>
                <box size="1.3126679391538154 1.8140059263906323 1.4012789699243084" />
            </geometry>
            <material name="Blue">
                <color rgba="0 1.0 1.0 1.0"/>
            </material>
        </visual>
        <collision>
            <origin xyz="0.6563339695769077 0 0" rpy="0 0 0"/>
            <geometry>
                <box size="1.3126679391538154 1.8140059263906323 1.4012789699243084" />
            </geometry>
        </collision>
    </link>
    <link name="Leg12">
        <inertial>
            <origin xyz="1.0001065446291861 0 0" rpy="0 0 0"/>
            <mass value="1" />
            <inertia ixx="100" ixy="0" ixz="0" iyy="100" iyz="0" izz="100" />
        </inertial>
        <visual>
            <origin xyz="1.0001065446291861 0 0" rpy="0 0 0"/>
            <geometry>
                <box size="2.0002130892583723 2.8279692990343666 2.3034039308548255" />
            </geometry>
            <material name="Green">
                <color rgba="0 180.0 0.0 1.0"/>
            </material>
        </visual>
        <collision>
            <origin xyz="1.0001065446291861 0 0" rpy="0 0 0"/>
            <geometry>
                <box size="2.0002130892583723 2.8279692990343666 2.3034039308548255" />
            </geometry>
        </collision>
    </link>
    <link name="Leg13">
        <inertial>
            <origin xyz="0 0 0.7816266463224243" rpy="0 0 0"/>
            <mass value="1" />
            <inertia ixx="100" ixy="0" ixz="0" iyy="100" iyz="0" izz="100" />
        </inertial>
        <visual>
            <origin xyz="0 0 0.7816266463224243" rpy="0 0 0"/>
            <geometry>
                <box size="2.0596404139667794 2.86159864189493 1.5632532926448486" />
            </geometry>
            <material name="Blue">
                <color rgba="0 1.0 1.0 1.0"/>
            </material>
        </visual>
        <collision>
            <origin xyz="0 0 0.7816266463224243" rpy="0 0 0"/>
            <geometry>
                <box size="2.0596404139667794 2.86159864189493 1.5632532926448486" />
            </geometry>
        </collision>
    </link>
    <link name="Leg14">
        <inertial>
            <origin xyz="0 0.9722252296219165 0" rpy="0 0 0"/>
            <mass value="1" />
            <inertia ixx="100" ixy="0" ixz="0" iyy="100" iyz="0" izz="100" />
        </inertial>
        <visual>
            <origin xyz="0 0.9722252296219165 0" rpy="0 0 0"/>
            <geometry>
                <box size="1.3869741388699812 1.944450459243833 2.331279245119143" />
            </geometry>
            <material name="Green">
                <color rgba="0 180.0 0.0 1.0"/>
            </material>
        </visual>
        <collision>
            <origin xyz="0 0.9722252296219165 0" rpy="0 0 0"/>
            <geometry>
                <box size="1.3869741388699812 1.944450459243833 2.331279245119143" />
            </geometry>
        </collision>
    </link>
    <link name="Leg15">
        <inertial>
            <origin xyz="1.0825864584762313 0 0" rpy="0 0 0"/>
            <mass value="1" />
            <inertia ixx="100" ixy="0" ixz="0" iyy="100" iyz="0" izz="100" />
        </inertial>
        <visual>
            <origin xyz="1.0825864584762313 0 0" rpy="0 0 0"/>
            <geometry>
                <box size="2.1651729169524625 1.70320244884853 2.5149307237695426" />
            </geometry>
            <material name="Blue">
                <color rgba="0 1.0 1.0 1.0"/>
            </material>
        </visual>
        <collision>
            <origin xyz="1.0825864584762313 0 0" rpy="0 0 0"/>
            <geometry>
                <box size="2.1651729169524625 1.70320244884853 2.5149307237695426" />
            </geometry>
        </collision>
    </link>
    <link name="Leg16">
        <inertial>
            <origin xyz="0 1.4281292212055612 0" rpy="0 0 0"/>
            <mass value="1" />
            <inertia ixx="100" ixy="0" ixz="0" iyy="100" iyz="0" izz="100" />
        </inertial>
        <visual>
            <origin xyz="0 1.4281292212055612 0" rpy="0 0 0"/>
            <geometry>
                <box size="1.5609224426645576 2.8562584424111224 2.4650223267506153" />
            </geometry>
            <material name="Green">
                <color rgba="0 180.0 0.0 1.0"/>
            </material>
        </visual>
        <collision>
            <origin xyz="0 1.4281292212055612 0" rpy="0 0 0"/>
            <geometry>
                <box size="1.5609224426645576 2.8562584424111224 2.4650223267506153" />
            </geometry>
        </collision>
    </link>
    <link name="Leg17">
        <inertial>
            <origin xyz="0.6458027281199717 0 0" rpy="0 0 0"/>
            <mass value="1" />
            <inertia ixx="100" ixy="0" ixz="0" iyy="100" iyz="0" izz="100" />
        </inertial>
        <visual>
            <origin xyz="0.6458027281199717 0 0" rpy="0 0 0"/>
            <geometry>
                <box size="1.2916054562399435 2.704156585030381 1.347048535127089" />
            </geometry>
            <material name="Blue">
                <color rgba="0 1.0 1.0 1.0"/>
            </material>
        </visual>
        <collision>
            <origin xyz="0.6458027281199717 0 0" rpy="0 0 0"/>
            <geometry>
                <box size="1.2916054562399435 2.704156585030381 1.347048535127089" />
            </geometry>
        </collision>
    </link>
    <link name="Leg18">
        <inertial>
            <origin xyz="0.839994885490772 0 0" rpy="0 0 0"/>
            <mass value="1" />
            <inertia ixx="100" ixy="0" ixz="0" iyy="100" iyz="0" izz="100" />
        </inertial>
        <visual>
            <origin xyz="0.839994885490772 0 0" rpy="0 0 0"/>
            <geometry>
                <box size="1.679989770981544 2.8973560132237415 2.4770817354404393" />
            </geometry>
            <material name="Blue">
                <color rgba="0 1.0 1.0 1.0"/>
            </material>
        </visual>
        <collision>
            <origin xyz="0.839994885490772 0 0" rpy="0 0 0"/>
            <geometry>
                <box size="1.679989770981544 2.8973560132237415 2.4770817354404393" />
            </geometry>
        </collision>
    </link>
    <link name="Leg19">
        <inertial>
            <origin xyz="0 1.0735921300793287 0" rpy="0 0 0"/>
            <mass value="1" />
            <inertia ixx="100" ixy="0" ixz="0" iyy="100" iyz="0" izz="100" />
        </inertial>
        <visual>
            <origin xyz="0 1.0735921300793287 0" rpy="0 0 0"/>
            <geometry>
                <box size="2.0189306012449544 2.1471842601586575 1.5113399104910612" />
            </geometry>
            <material name="Blue">
                <color rgba="0 1.0 1.0 1.0"/>
            </material>
        </visual>
        <collision>
            <origin xyz="0 1.0735921300793287 0" rpy="0 0 0"/>
            <geometry>
                <box size="2.0189306012449544 2.1471842601586575 1.5113399104910612" />
            </geometry>
        </collision>
    </link>
    <link name="Leg20">
        <inertial>
            <origin xyz="0 0.5099787550389243 0" rpy="0 0 0"/>
            <mass value="1" />
            <inertia ixx="100" ixy="0" ixz="0" iyy="100" iyz="0" izz="100" />
        </inertial>
        <visual>
            <origin xyz="0 0.5099787550389243 0" rpy="0 0 0"/>
            <geometry>
                <box size="1.967969903808092 1.0199575100778486 1.4952324116633835" />
            </geometry>
            <material name="Blue">
                <color rgba="0 1.0 1.0 1.0"/>
            </material>
        </visual>
        <collision>
            <origin xyz="0 0.5099787550389243 0" rpy="0 0 0"/>
            <geometry>
                <box size="1.967969903808092 1.0199575100778486 1.4952324116633835" />
            </geometry>
        </collision>
    </link>
    <link name="Leg21">
        <inertial>
            <origin xyz="1.0450099258592944 0 0" rpy="0 0 0"/>
            <mass value="1" />
            <inertia ixx="100" ixy="0" ixz="0" iyy="100" iyz="0" izz="100" />
        </inertial>
        <visual>
            <origin xyz="1.0450099258592944 0 0" rpy="0 0 0"/>
            <geometry>
                <box size="2.090019851718589 2.5942891153653544 2.4064100787388756" />
            </geometry>
            <material name="Green">
                <color rgba="0 180.0 0.0 1.0"/>
            </material>
        </visual>
        <collision>
            <origin xyz="1.0450099258592944 0 0" rpy="0 0 0"/>
            <geometry>
                <box size="2.090019851718589 2.5942891153653544 2.4064100787388756" />
            </geometry>
        </collision>
    </link>
    <link name="Leg22">
        <inertial>
            <origin xyz="0 0 1.362022476467611" rpy="0 0 0"/>
            <mass value="1" />
            <inertia ixx="100" ixy="0" ixz="0" iyy="100" iyz="0" izz="100" />
        </inertial>
        <visual>
            <origin xyz="0 0 1.362022476467611" rpy="0 0 0"/>
            <geometry>
                <box size="1.0708438180170443 1.0000593553557562 2.724044952935222" />
            </geometry>
            <material name="Green">
                <color rgba="0 180.0 0.0 1.0"/>
            </material>
        </visual>
        <collision>
            <origin xyz="0 0 1.362022476467611" rpy="0 0 0"/>
            <geometry>
                <box size="1.0708438180170443 1.0000593553557562 2.724044952935222" />
            </geometry>
        </collision>
    </link>
    <link name="Leg23">
        <inertial>
            <origin xyz="0 0.7934639317766217 0" rpy="0 0 0"/>
            <mass value="1" />
            <inertia ixx="100" ixy="0" ixz="0" iyy="100" iyz="0" izz="100" />
        </inertial>
        <visual>
            <origin xyz="0 0.7934639317766217 0" rpy="0 0 0"/>
            <geometry>
                <box size="2.622878844103786 1.5869278635532433 1.3839160827110764" />
            </geometry>
            <material name="Green">
                <color rgba="0 180.0 0.0 1.0"/>
            </material>
        </visual>
        <collision>
            <origin xyz="0 0.7934639317766217 0" rpy="0 0 0"/>
            <geometry>
                <box size="2.622878844103786 1.5869278635532433 1.3839160827110764" />
            </geometry>
        </collision>
    </link>
    <link name="Leg24">
        <inertial>
            <origin xyz="0 1.366540387207804 0" rpy="0 0 0"/>
            <mass value="1" />
            <inertia ixx="100" ixy="0" ixz="0" iyy="100" iyz="0" izz="100" />
        </inertial>
        <visual>
            <origin xyz="0 1.366540387207804 0" rpy="0 0 0"/>
            <geometry>
                <box size="2.2746266360020595 2.733080774415608 2.2954889690339697" />
            </geometry>
            <material name="Blue">
                <color rgba="0 1.0 1.0 1.0"/>
            </material>
        </visual>
        <collision>
            <origin xyz="0 1.366540387207804 0" rpy="0 0 0"/>
            <geometry>
                <box size="2.2746266360020595 2.733080774415608 2.2954889690339697" />
            </geometry>
        </collision>
    </link>
    <link name="Leg25">
        <inertial>
            <origin xyz="0 0 0.5044560637102787" rpy="0 0 0"/>
            <mass value="1" />
            <inertia ixx="100" ixy="0" ixz="0" iyy="100" iyz="0" izz="100" />
        </inertial>
        <visual>
            <origin xyz="0 0 0.5044560637102787" rpy="0 0 0"/>
            <geometry>
                <box size="2.18341452363277 2.2630277380508836 1.0089121274205575" />
            </geometry>
            <material name="Blue">
                <color rgba="0 1.0 1.0 1.0"/>
            </material>
        </visual>
        <collision>
            <origin xyz="0 0 0.5044560637102787" rpy="0 0 0"/>
            <geometry>
                <box size="2.18341452363277 2.2630277380508836 1.0089121274205575" />
            </geometry>
        </collision>
    </link>
    <link name="Leg26">
        <inertial>
            <origin xyz="1.3539573564210379 0 0" rpy="0 0 0"/>
            <mass value="1" />
            <inertia ixx="100" ixy="0" ixz="0" iyy="100" iyz="0" izz="100" />
        </inertial>
        <visual>
            <origin xyz="1.3539573564210379 0 0" rpy="0 0 0"/>
            <geometry>
                <box size="2.7079147128420757 1.5664172170385162 2.077840779095849" />
            </geometry>
            <material name="Blue">
                <color rgba="0 1.0 1.0 1.0"/>
            </material>
        </visual>
        <collision>
            <origin xyz="1.3539573564210379 0 0" rpy="0 0 0"/>
            <geometry>
                <box size="2.7079147128420757 1.5664172170385162 2.077840779095849" />
            </geometry>
        </collision>
    </link>
    <link name="Leg27">
        <inertial>
            <origin xyz="0.9795473331442317 0 0" rpy="0 0 0"/>
            <mass value="1" />
            <inertia ixx="100" ixy="0" ixz="0" iyy="100" iyz="0" izz="100" />
        </inertial>
        <visual>
            <origin xyz="0.9795473331442317 0 0" rpy="0 0 0"/>
            <geometry>
                <box size="1.9590946662884634 2.113675307920995 1.0590074363460613" />
            </geometry>
            <material name="Green">
                <color rgba="0 180.0 0.0 1.0"/>
            </material>
        </visual>
        <collision>
            <origin xyz="0.9795473331442317 0 0" rpy="0 0 0"/>
            <geometry>
                <box size="1.9590946662884634 2.113675307920995 1.0590074363460613" />
            </geometry>
        </collision>
    </link>
    <link name="Leg28">
        <inertial>
            <origin xyz="0 1.099771930734701 0" rpy="0 0 0"/>
            <mass value="1" />
            <inertia ixx="100" ixy="0" ixz="0" iyy="100" iyz="0" izz="100" />
        </inertial>
        <visual>
            <origin xyz="0 1.099771930734701 0" rpy="0 0 0"/>
            <geometry>
                <box size="1.1249110148756787 2.199543861469402 2.855516487654832" />
            </geometry>
            <material name="Green">
                <color rgba="0 180.0 0.0 1.0"/>
            </material>
        </visual>
        <collision>
            <origin xyz="0 1.099771930734701 0" rpy="0 0 0"/>
            <geometry>
                <box size="1.1249110148756787 2.199543861469402 2.855516487654832" />
            </geometry>
        </collision>
    </link>
    <joint name="Torso_Leg1" type="revolute">
       <parent link="Torso"/>
       <child  link="Leg1"/>
       <origin rpy="0 0 0" xyz="1.2995348559174325 0 1.1905804517893512" />
     <axis xyz="1 0 0"/>
       <limit effort="0.0" lower="-3.14159" upper="3.14159" velocity="0.0"/>
    </joint>
    <joint name="Torso_Leg2" type="revolute">
       <parent link="Torso"/>
       <child  link="Leg2"/>
       <origin rpy="0 0 0" xyz="1.2653719880230174 0 1.426303070660109" />
     <axis xyz="1 0 0"/>
       <limit effort="0.0" lower="-3.14159" upper="3.14159" velocity="0.0"/>
    </joint>
    <joint name="Leg2_Leg3" type="revolute">
       <parent link="Leg2"/>
       <child  link="Leg3"/>
       <origin rpy="0 0 0" xyz="1.8170466259576294 0 0" />
     <axis xyz="1 0 0"/>
       <limit effort="0.0" lower="-3.14159" upper="3.14159" velocity="0.0"/>
    </joint>
    <joint name="Leg1_Leg4" type="revolute">
       <parent link="Leg1"/>
       <child  link="Leg4"/>
       <origin rpy="0 0 0" xyz="0.8073479637631105 0 1.3284665470275627" />
     <axis xyz="1 0 0"/>
       <limit effort="0.0" lower="-3.14159" upper="3.14159" velocity="0.0"/>
    </joint>
    <joint name="Leg4_Leg5" type="revolute">
       <parent link="Leg4"/>
       <child  link="Leg5"/>
       <origin rpy="0 0 0" xyz="0 2.287760424809507 0" />
     <axis xyz="1 0 0"/>
       <limit effort="0.0" lower="-3.14159" upper="3.14159" velocity="0.0"/>
    </joint>
    <joint name="Leg4_Leg6" type="revolute">
       <parent link="Leg4"/>
       <child  link="Leg6"/>
       <origin rpy="0 0 0" xyz="0.6793561502185114 2.287760424809507 0" />
     <axis xyz="1 0 0"/>
       <limit effort="0.0" lower="-3.14159" upper="3.14159" velocity="0.0"/>
    </joint>
    <joint name="Torso_Leg7" type="revolute">
       <parent link="Torso"/>
       <child  link="Leg7"/>
       <origin rpy="0 0 0" xyz="1.2653719880230174 1.2008383570164147 1.426303070660109" />
     <axis xyz="1 0 0"/>
       <limit effort="0.0" lower="-3.14159" upper="3.14159" velocity="0.0"/>
    </joint>
    <joint name="Leg4_Leg8" type="revolute">
       <parent link="Leg4"/>
       <child  link="Leg8"/>
       <origin rpy="0 0 0" xyz="0.6793561502185114 2.287760424809507 0.9649153241761564" />
     <axis xyz="1 0 0"/>
       <limit effort="0.0" lower="-3.14159" upper="3.14159" velocity="0.0"/>
    </joint>
    <joint name="Leg6_Leg9" type="revolute">
       <parent link="Leg6"/>
       <child  link="Leg9"/>
       <origin rpy="0 0 0" xyz="0 0.7677500417030145 0.5915987173648912" />
     <axis xyz="1 0 0"/>
       <limit effort="0.0" lower="-3.14159" upper="3.14159" velocity="0.0"/>
    </joint>
    <joint name="Leg2_Leg10" type="revolute">
       <parent link="Leg2"/>
       <child  link="Leg10"/>
       <origin rpy="0 0 0" xyz="1.8170466259576294 1.3676065710107264 0" />
     <axis xyz="1 0 0"/>
       <limit effort="0.0" lower="-3.14159" upper="3.14159" velocity="0.0"/>
    </joint>
    <joint name="Leg3_Leg11" type="revolute">
       <parent link="Leg3"/>
       <child  link="Leg11"/>
       <origin rpy="0 0 0" xyz="2.8653605787013388 0 0" />
     <axis xyz="1 0 0"/>
       <limit effort="0.0" lower="-3.14159" upper="3.14159" velocity="0.0"/>
    </joint>
    <joint name="Leg8_Leg12" type="revolute">
       <parent link="Leg8"/>
       <child  link="Leg12"/>
       <origin rpy="0 0 0" xyz="1.373824414066737 0 1.4605372880595382" />
     <axis xyz="1 0 0"/>
       <limit effort="0.0" lower="-3.14159" upper="3.14159" velocity="0.0"/>
    </joint>
    <joint name="Leg7_Leg13" type="revolute">
       <parent link="Leg7"/>
       <child  link="Leg13"/>
       <origin rpy="0 0 0" xyz="0 0 2.0353898764223604" />
     <axis xyz="1 0 0"/>
       <limit effort="0.0" lower="-3.14159" upper="3.14159" velocity="0.0"/>
    </joint>
    <joint name="Leg8_Leg14" type="revolute">
       <parent link="Leg8"/>
       <child  link="Leg14"/>
       <origin rpy="0 0 0" xyz="1.373824414066737 1.243050156362398 1.4605372880595382" />
     <axis xyz="1 0 0"/>
       <limit effort="0.0" lower="-3.14159" upper="3.14159" velocity="0.0"/>
    </joint>
    <joint name="Leg11_Leg15" type="revolute">
       <parent link="Leg11"/>
       <child  link="Leg15"/>
       <origin rpy="0 0 0" xyz="2.0002130892583723 0 0" />
     <axis xyz="1 0 0"/>
       <limit effort="0.0" lower="-3.14159" upper="3.14159" velocity="0.0"/>
    </joint>
    <joint name="Leg1_Leg16" type="revolute">
       <parent link="Leg1"/>
       <child  link="Leg16"/>
       <origin rpy="0 0 0" xyz="0.8073479637631105 0.7125125777762334 1.3284665470275627" />
     <axis xyz="1 0 0"/>
       <limit effort="0.0" lower="-3.14159" upper="3.14159" velocity="0.0"/>
    </joint>
    <joint name="Leg6_Leg17" type="revolute">
       <parent link="Leg6"/>
       <child  link="Leg17"/>
       <origin rpy="0 0 0" xyz="1.2610125648765016 0.7677500417030145 0.5915987173648912" />
     <axis xyz="1 0 0"/>
       <limit effort="0.0" lower="-3.14159" upper="3.14159" velocity="0.0"/>
    </joint>
    <joint name="Leg10_Leg18" type="revolute">
       <parent link="Leg10"/>
       <child  link="Leg18"/>
       <origin rpy="0 0 0" xyz="1.3126679391538154 0 0" />
     <axis xyz="1 0 0"/>
       <limit effort="0.0" lower="-3.14159" upper="3.14159" velocity="0.0"/>
    </joint>
    <joint name="Leg3_Leg19" type="revolute">
       <parent link="Leg3"/>
       <child  link="Leg19"/>
       <origin rpy="0 0 0" xyz="2.8653605787013388 0.9184313458724314 0" />
     <axis xyz="1 0 0"/>
       <limit effort="0.0" lower="-3.14159" upper="3.14159" velocity="0.0"/>
    </joint>
    <joint name="Leg13_Leg20" type="revolute">
       <parent link="Leg13"/>
       <child  link="Leg20"/>
       <origin rpy="0 0 0" xyz="0 1.944450459243833 0" />
     <axis xyz="1 0 0"/>
       <limit effort="0.0" lower="-3.14159" upper="3.14159" velocity="0.0"/>
    </joint>
    <joint name="Leg18_Leg21" type="revolute">
       <parent link="Leg18"/>
       <child  link="Leg21"/>
       <origin rpy="0 0 0" xyz="1.0094653006224772 1.0735921300793287 0" />
     <axis xyz="1 0 0"/>
       <limit effort="0.0" lower="-3.14159" upper="3.14159" velocity="0.0"/>
    </joint>
    <joint name="Leg20_Leg22" type="revolute">
       <parent link="Leg20"/>
       <child  link="Leg22"/>
       <origin rpy="0 0 0" xyz="1.0450099258592944 0 1.2032050393694378" />
     <axis xyz="1 0 0"/>
       <limit effort="0.0" lower="-3.14159" upper="3.14159" velocity="0.0"/>
    </joint>
    <joint name="Leg7_Leg23" type="revolute">
       <parent link="Leg7"/>
       <child  link="Leg23"/>
       <origin rpy="0 0 0" xyz="0 0.8605967111160935 2.0353898764223604" />
     <axis xyz="1 0 0"/>
       <limit effort="0.0" lower="-3.14159" upper="3.14159" velocity="0.0"/>
    </joint>
    <joint name="Leg16_Leg24" type="revolute">
       <parent link="Leg16"/>
       <child  link="Leg24"/>
       <origin rpy="0 0 0" xyz="0.6458027281199717 1.3520782925151904 0" />
     <axis xyz="1 0 0"/>
       <limit effort="0.0" lower="-3.14159" upper="3.14159" velocity="0.0"/>
    </joint>
    <joint name="Leg17_Leg25" type="revolute">
       <parent link="Leg17"/>
       <child  link="Leg25"/>
       <origin rpy="0 0 0" xyz="0.839994885490772 0 1.2385408677202197" />
     <axis xyz="1 0 0"/>
       <limit effort="0.0" lower="-3.14159" upper="3.14159" velocity="0.0"/>
    </joint>
    <joint name="Leg24_Leg26" type="revolute">
       <parent link="Leg24"/>
       <child  link="Leg26"/>
       <origin rpy="0 0 0" xyz="1.091707261816385 0 0.5044560637102787" />
     <axis xyz="1 0 0"/>
       <limit effort="0.0" lower="-3.14159" upper="3.14159" velocity="0.0"/>
    </joint>
    <joint name="Leg26_Leg27" type="revolute">
       <parent link="Leg26"/>
       <child  link="Leg27"/>
       <origin rpy="0 0 0" xyz="1.9590946662884634 0 0" />
     <axis xyz="1 0 0"/>
       <limit effort="0.0" lower="-3.14159" upper="3.14159" velocity="0.0"/>
    </joint>
    <joint name="Leg20_Leg28" type="revolute">
       <parent link="Leg20"/>
       <child  link="Leg28"/>
       <origin rpy="0 0 0" xyz="1.0450099258592944 1.2971445576826772 1.2032050393694378" />
     <axis xyz="1 0 0"/>
       <limit effort="0.0" lower="-3.14159" upper="3.14159" velocity="0.0"/>
    </joint>
</robot>