<robot name = "robot">
    <link name="Torso">
        <inertial>
            <origin xyz="0 0 0.6474550447790163" rpy="0 0 0"/>
            <mass value="1" />
            <inertia ixx="100" ixy="0" ixz="0" iyy="100" iyz="0" izz="100" />
        </inertial>
        <visual>
            <origin xyz="0 0 0.6474550447790163" rpy="0 0 0"/>
            <geometry>
                <box size="1.232118075026162 1.7588846641134988 1.2949100895580326" />
            </geometry>
            <material name="Green">
                <color rgba="0 180.0 0.0 1.0"/>
            </material>
        </visual>
        <collision>
            <origin xyz="0 0 0.6474550447790163" rpy="0 0 0"/>
            <geometry>
                <box size="1.232118075026162 1.7588846641134988 1.2949100895580326" />
            </geometry>
        </collision>
    </link>
    <link name="Leg1">
        <inertial>
            <origin xyz="1.3817162793870752 0 0" rpy="0 0 0"/>
            <mass value="1" />
            <inertia ixx="100" ixy="0" ixz="0" iyy="100" iyz="0" izz="100" />
        </inertial>
        <visual>
            <origin xyz="1.3817162793870752 0 0" rpy="0 0 0"/>
            <geometry>
                <box size="2.7634325587741504 2.608315951674159 2.5434056719083413" />
            </geometry>
            <material name="Blue">
                <color rgba="0 1.0 1.0 1.0"/>
            </material>
        </visual>
        <collision>
            <origin xyz="1.3817162793870752 0 0" rpy="0 0 0"/>
            <geometry>
                <box size="2.7634325587741504 2.608315951674159 2.5434056719083413" />
            </geometry>
        </collision>
    </link>
    <link name="Leg2">
        <inertial>
            <origin xyz="0 0 1.3128138308761557" rpy="0 0 0"/>
            <mass value="1" />
            <inertia ixx="100" ixy="0" ixz="0" iyy="100" iyz="0" izz="100" />
        </inertial>
        <visual>
            <origin xyz="0 0 1.3128138308761557" rpy="0 0 0"/>
            <geometry>
                <box size="1.0355500828585598 1.847085164705017 2.6256276617523113" />
            </geometry>
            <material name="Blue">
                <color rgba="0 1.0 1.0 1.0"/>
            </material>
        </visual>
        <collision>
            <origin xyz="0 0 1.3128138308761557" rpy="0 0 0"/>
            <geometry>
                <box size="1.0355500828585598 1.847085164705017 2.6256276617523113" />
            </geometry>
        </collision>
    </link>
    <link name="Leg3">
        <inertial>
            <origin xyz="0.9182648742487526 0 0" rpy="0 0 0"/>
            <mass value="1" />
            <inertia ixx="100" ixy="0" ixz="0" iyy="100" iyz="0" izz="100" />
        </inertial>
        <visual>
            <origin xyz="0.9182648742487526 0 0" rpy="0 0 0"/>
            <geometry>
                <box size="1.8365297484975052 2.7535783318776295 2.6359296310815266" />
            </geometry>
            <material name="Green">
                <color rgba="0 180.0 0.0 1.0"/>
            </material>
        </visual>
        <collision>
            <origin xyz="0.9182648742487526 0 0" rpy="0 0 0"/>
            <geometry>
                <box size="1.8365297484975052 2.7535783318776295 2.6359296310815266" />
            </geometry>
        </collision>
    </link>
    <link name="Leg4">
        <inertial>
            <origin xyz="0 1.4445759071417776 0" rpy="0 0 0"/>
            <mass value="1" />
            <inertia ixx="100" ixy="0" ixz="0" iyy="100" iyz="0" izz="100" />
        </inertial>
        <visual>
            <origin xyz="0 1.4445759071417776 0" rpy="0 0 0"/>
            <geometry>
                <box size="2.81175758132966 2.8891518142835553 2.6253325781062755" />
            </geometry>
            <material name="Blue">
                <color rgba="0 1.0 1.0 1.0"/>
            </material>
        </visual>
        <collision>
            <origin xyz="0 1.4445759071417776 0" rpy="0 0 0"/>
            <geometry>
                <box size="2.81175758132966 2.8891518142835553 2.6253325781062755" />
            </geometry>
        </collision>
    </link>
    <link name="Leg5">
        <inertial>
            <origin xyz="0.5201532287940555 0 0" rpy="0 0 0"/>
            <mass value="1" />
            <inertia ixx="100" ixy="0" ixz="0" iyy="100" iyz="0" izz="100" />
        </inertial>
        <visual>
            <origin xyz="0.5201532287940555 0 0" rpy="0 0 0"/>
            <geometry>
                <box size="1.040306457588111 2.702279720380033 2.838427394376054" />
            </geometry>
            <material name="Blue">
                <color rgba="0 1.0 1.0 1.0"/>
            </material>
        </visual>
        <collision>
            <origin xyz="0.5201532287940555 0 0" rpy="0 0 0"/>
            <geometry>
                <box size="1.040306457588111 2.702279720380033 2.838427394376054" />
            </geometry>
        </collision>
    </link>
    <link name="Leg6">
        <inertial>
            <origin xyz="0.5769823992335016 0 0" rpy="0 0 0"/>
            <mass value="1" />
            <inertia ixx="100" ixy="0" ixz="0" iyy="100" iyz="0" izz="100" />
        </inertial>
        <visual>
            <origin xyz="0.5769823992335016 0 0" rpy="0 0 0"/>
            <geometry>
                <box size="1.1539647984670032 1.2157912154298844 2.272995509432522" />
            </geometry>
            <material name="Blue">
                <color rgba="0 1.0 1.0 1.0"/>
            </material>
        </visual>
        <collision>
            <origin xyz="0.5769823992335016 0 0" rpy="0 0 0"/>
            <geometry>
                <box size="1.1539647984670032 1.2157912154298844 2.272995509432522" />
            </geometry>
        </collision>
    </link>
    <link name="Leg7">
        <inertial>
            <origin xyz="0.5465448454309416 0 0" rpy="0 0 0"/>
            <mass value="1" />
            <inertia ixx="100" ixy="0" ixz="0" iyy="100" iyz="0" izz="100" />
        </inertial>
        <visual>
            <origin xyz="0.5465448454309416 0 0" rpy="0 0 0"/>
            <geometry>
                <box size="1.0930896908618832 2.1910271843779796 1.7270190362975306" />
            </geometry>
            <material name="Green">
                <color rgba="0 180.0 0.0 1.0"/>
            </material>
        </visual>
        <collision>
            <origin xyz="0.5465448454309416 0 0" rpy="0 0 0"/>
            <geometry>
                <box size="1.0930896908618832 2.1910271843779796 1.7270190362975306" />
            </geometry>
        </collision>
    </link>
    <link name="Leg8">
        <inertial>
            <origin xyz="0 0 1.2530161650968599" rpy="0 0 0"/>
            <mass value="1" />
            <inertia ixx="100" ixy="0" ixz="0" iyy="100" iyz="0" izz="100" />
        </inertial>
        <visual>
            <origin xyz="0 0 1.2530161650968599" rpy="0 0 0"/>
            <geometry>
                <box size="2.870543574550548 2.382615857138554 2.5060323301937197" />
            </geometry>
            <material name="Green">
                <color rgba="0 180.0 0.0 1.0"/>
            </material>
        </visual>
        <collision>
            <origin xyz="0 0 1.2530161650968599" rpy="0 0 0"/>
            <geometry>
                <box size="2.870543574550548 2.382615857138554 2.5060323301937197" />
            </geometry>
        </collision>
    </link>
    <link name="Leg9">
        <inertial>
            <origin xyz="0 0 1.4688554186689162" rpy="0 0 0"/>
            <mass value="1" />
            <inertia ixx="100" ixy="0" ixz="0" iyy="100" iyz="0" izz="100" />
        </inertial>
        <visual>
            <origin xyz="0 0 1.4688554186689162" rpy="0 0 0"/>
            <geometry>
                <box size="1.2767722561202146 1.1049863635105002 2.9377108373378324" />
            </geometry>
            <material name="Green">
                <color rgba="0 180.0 0.0 1.0"/>
            </material>
        </visual>
        <collision>
            <origin xyz="0 0 1.4688554186689162" rpy="0 0 0"/>
            <geometry>
                <box size="1.2767722561202146 1.1049863635105002 2.9377108373378324" />
            </geometry>
        </collision>
    </link>
    <link name="Leg10">
        <inertial>
            <origin xyz="1.4862751118461248 0 0" rpy="0 0 0"/>
            <mass value="1" />
            <inertia ixx="100" ixy="0" ixz="0" iyy="100" iyz="0" izz="100" />
        </inertial>
        <visual>
            <origin xyz="1.4862751118461248 0 0" rpy="0 0 0"/>
            <geometry>
                <box size="2.9725502236922496 1.5719424331288498 1.935942673907064" />
            </geometry>
            <material name="Green">
                <color rgba="0 180.0 0.0 1.0"/>
            </material>
        </visual>
        <collision>
            <origin xyz="1.4862751118461248 0 0" rpy="0 0 0"/>
            <geometry>
                <box size="2.9725502236922496 1.5719424331288498 1.935942673907064" />
            </geometry>
        </collision>
    </link>
    <link name="Leg11">
        <inertial>
            <origin xyz="0 1.1964133448482936 0" rpy="0 0 0"/>
            <mass value="1" />
            <inertia ixx="100" ixy="0" ixz="0" iyy="100" iyz="0" izz="100" />
        </inertial>
        <visual>
            <origin xyz="0 1.1964133448482936 0" rpy="0 0 0"/>
            <geometry>
                <box size="1.7892607824349662 2.3928266896965873 1.9977873925125276" />
            </geometry>
            <material name="Green">
                <color rgba="0 180.0 0.0 1.0"/>
            </material>
        </visual>
        <collision>
            <origin xyz="0 1.1964133448482936 0" rpy="0 0 0"/>
            <geometry>
                <box size="1.7892607824349662 2.3928266896965873 1.9977873925125276" />
            </geometry>
        </collision>
    </link>
    <link name="Leg12">
        <inertial>
            <origin xyz="0.6786699780666146 0 0" rpy="0 0 0"/>
            <mass value="1" />
            <inertia ixx="100" ixy="0" ixz="0" iyy="100" iyz="0" izz="100" />
        </inertial>
        <visual>
            <origin xyz="0.6786699780666146 0 0" rpy="0 0 0"/>
            <geometry>
                <box size="1.357339956133229 1.0599773797839784 1.5205862167646944" />
            </geometry>
            <material name="Green">
                <color rgba="0 180.0 0.0 1.0"/>
            </material>
        </visual>
        <collision>
            <origin xyz="0.6786699780666146 0 0" rpy="0 0 0"/>
            <geometry>
                <box size="1.357339956133229 1.0599773797839784 1.5205862167646944" />
            </geometry>
        </collision>
    </link>
    <link name="Leg13">
        <inertial>
            <origin xyz="1.099590214877203 0 0" rpy="0 0 0"/>
            <mass value="1" />
            <inertia ixx="100" ixy="0" ixz="0" iyy="100" iyz="0" izz="100" />
        </inertial>
        <visual>
            <origin xyz="1.099590214877203 0 0" rpy="0 0 0"/>
            <geometry>
                <box size="2.199180429754406 2.953324540737401 1.0117320769146048" />
            </geometry>
            <material name="Green">
                <color rgba="0 180.0 0.0 1.0"/>
            </material>
        </visual>
        <collision>
            <origin xyz="1.099590214877203 0 0" rpy="0 0 0"/>
            <geometry>
                <box size="2.199180429754406 2.953324540737401 1.0117320769146048" />
            </geometry>
        </collision>
    </link>
    <link name="Leg14">
        <inertial>
            <origin xyz="0 1.3018644867872862 0" rpy="0 0 0"/>
            <mass value="1" />
            <inertia ixx="100" ixy="0" ixz="0" iyy="100" iyz="0" izz="100" />
        </inertial>
        <visual>
            <origin xyz="0 1.3018644867872862 0" rpy="0 0 0"/>
            <geometry>
                <box size="1.9096552627893002 2.6037289735745723 2.316553062006025" />
            </geometry>
            <material name="Green">
                <color rgba="0 180.0 0.0 1.0"/>
            </material>
        </visual>
        <collision>
            <origin xyz="0 1.3018644867872862 0" rpy="0 0 0"/>
            <geometry>
                <box size="1.9096552627893002 2.6037289735745723 2.316553062006025" />
            </geometry>
        </collision>
    </link>
    <link name="Leg15">
        <inertial>
            <origin xyz="1.3084411693107398 0 0" rpy="0 0 0"/>
            <mass value="1" />
            <inertia ixx="100" ixy="0" ixz="0" iyy="100" iyz="0" izz="100" />
        </inertial>
        <visual>
            <origin xyz="1.3084411693107398 0 0" rpy="0 0 0"/>
            <geometry>
                <box size="2.6168823386214797 1.0605810809673122 2.766233683684927" />
            </geometry>
            <material name="Blue">
                <color rgba="0 1.0 1.0 1.0"/>
            </material>
        </visual>
        <collision>
            <origin xyz="1.3084411693107398 0 0" rpy="0 0 0"/>
            <geometry>
                <box size="2.6168823386214797 1.0605810809673122 2.766233683684927" />
            </geometry>
        </collision>
    </link>
    <link name="Leg16">
        <inertial>
            <origin xyz="0 1.1194843888656676 0" rpy="0 0 0"/>
            <mass value="1" />
            <inertia ixx="100" ixy="0" ixz="0" iyy="100" iyz="0" izz="100" />
        </inertial>
        <visual>
            <origin xyz="0 1.1194843888656676 0" rpy="0 0 0"/>
            <geometry>
                <box size="1.403778418897876 2.238968777731335 2.29334874453684" />
            </geometry>
            <material name="Green">
                <color rgba="0 180.0 0.0 1.0"/>
            </material>
        </visual>
        <collision>
            <origin xyz="0 1.1194843888656676 0" rpy="0 0 0"/>
            <geometry>
                <box size="1.403778418897876 2.238968777731335 2.29334874453684" />
            </geometry>
        </collision>
    </link>
    <link name="Leg17">
        <inertial>
            <origin xyz="1.114764331526466 0 0" rpy="0 0 0"/>
            <mass value="1" />
            <inertia ixx="100" ixy="0" ixz="0" iyy="100" iyz="0" izz="100" />
        </inertial>
        <visual>
            <origin xyz="1.114764331526466 0 0" rpy="0 0 0"/>
            <geometry>
                <box size="2.229528663052932 2.1630001890237383 1.0438849496299982" />
            </geometry>
            <material name="Green">
                <color rgba="0 180.0 0.0 1.0"/>
            </material>
        </visual>
        <collision>
            <origin xyz="1.114764331526466 0 0" rpy="0 0 0"/>
            <geometry>
                <box size="2.229528663052932 2.1630001890237383 1.0438849496299982" />
            </geometry>
        </collision>
    </link>
    <link name="Leg18">
        <inertial>
            <origin xyz="0 0 1.154827795820279" rpy="0 0 0"/>
            <mass value="1" />
            <inertia ixx="100" ixy="0" ixz="0" iyy="100" iyz="0" izz="100" />
        </inertial>
        <visual>
            <origin xyz="0 0 1.154827795820279" rpy="0 0 0"/>
            <geometry>
                <box size="1.402929235156537 2.5539970107177243 2.309655591640558" />
            </geometry>
            <material name="Blue">
                <color rgba="0 1.0 1.0 1.0"/>
            </material>
        </visual>
        <collision>
            <origin xyz="0 0 1.154827795820279" rpy="0 0 0"/>
            <geometry>
                <box size="1.402929235156537 2.5539970107177243 2.309655591640558" />
            </geometry>
        </collision>
    </link>
    <link name="Leg19">
        <inertial>
            <origin xyz="0 0.634500515068212 0" rpy="0 0 0"/>
            <mass value="1" />
            <inertia ixx="100" ixy="0" ixz="0" iyy="100" iyz="0" izz="100" />
        </inertial>
        <visual>
            <origin xyz="0 0.634500515068212 0" rpy="0 0 0"/>
            <geometry>
                <box size="1.437613753616415 1.269001030136424 2.7012345667893625" />
            </geometry>
            <material name="Green">
                <color rgba="0 180.0 0.0 1.0"/>
            </material>
        </visual>
        <collision>
            <origin xyz="0 0.634500515068212 0" rpy="0 0 0"/>
            <geometry>
                <box size="1.437613753616415 1.269001030136424 2.7012345667893625" />
            </geometry>
        </collision>
    </link>
    <link name="Leg20">
        <inertial>
            <origin xyz="0 0 1.0910839724380548" rpy="0 0 0"/>
            <mass value="1" />
            <inertia ixx="100" ixy="0" ixz="0" iyy="100" iyz="0" izz="100" />
        </inertial>
        <visual>
            <origin xyz="0 0 1.0910839724380548" rpy="0 0 0"/>
            <geometry>
                <box size="2.099015105113824 1.7433781818570657 2.1821679448761095" />
            </geometry>
            <material name="Green">
                <color rgba="0 180.0 0.0 1.0"/>
            </material>
        </visual>
        <collision>
            <origin xyz="0 0 1.0910839724380548" rpy="0 0 0"/>
            <geometry>
                <box size="2.099015105113824 1.7433781818570657 2.1821679448761095" />
            </geometry>
        </collision>
    </link>
    <link name="Leg21">
        <inertial>
            <origin xyz="0 1.0706210634110667 0" rpy="0 0 0"/>
            <mass value="1" />
            <inertia ixx="100" ixy="0" ixz="0" iyy="100" iyz="0" izz="100" />
        </inertial>
        <visual>
            <origin xyz="0 1.0706210634110667 0" rpy="0 0 0"/>
            <geometry>
                <box size="1.047243632314801 2.1412421268221333 1.8242382476618326" />
            </geometry>
            <material name="Blue">
                <color rgba="0 1.0 1.0 1.0"/>
            </material>
        </visual>
        <collision>
            <origin xyz="0 1.0706210634110667 0" rpy="0 0 0"/>
            <geometry>
                <box size="1.047243632314801 2.1412421268221333 1.8242382476618326" />
            </geometry>
        </collision>
    </link>
    <link name="Leg22">
        <inertial>
            <origin xyz="0 0 0.7507813634951672" rpy="0 0 0"/>
            <mass value="1" />
            <inertia ixx="100" ixy="0" ixz="0" iyy="100" iyz="0" izz="100" />
        </inertial>
        <visual>
            <origin xyz="0 0 0.7507813634951672" rpy="0 0 0"/>
            <geometry>
                <box size="1.7270692711552869 1.1429535657772791 1.5015627269903344" />
            </geometry>
            <material name="Green">
                <color rgba="0 180.0 0.0 1.0"/>
            </material>
        </visual>
        <collision>
            <origin xyz="0 0 0.7507813634951672" rpy="0 0 0"/>
            <geometry>
                <box size="1.7270692711552869 1.1429535657772791 1.5015627269903344" />
            </geometry>
        </collision>
    </link>
    <link name="Leg23">
        <inertial>
            <origin xyz="0 1.0921072384126504 0" rpy="0 0 0"/>
            <mass value="1" />
            <inertia ixx="100" ixy="0" ixz="0" iyy="100" iyz="0" izz="100" />
        </inertial>
        <visual>
            <origin xyz="0 1.0921072384126504 0" rpy="0 0 0"/>
            <geometry>
                <box size="1.2262262800161232 2.184214476825301 2.087218464696905" />
            </geometry>
            <material name="Green">
                <color rgba="0 180.0 0.0 1.0"/>
            </material>
        </visual>
        <collision>
            <origin xyz="0 1.0921072384126504 0" rpy="0 0 0"/>
            <geometry>
                <box size="1.2262262800161232 2.184214476825301 2.087218464696905" />
            </geometry>
        </collision>
    </link>
    <link name="Leg24">
        <inertial>
            <origin xyz="0.8842997890993859 0 0" rpy="0 0 0"/>
            <mass value="1" />
            <inertia ixx="100" ixy="0" ixz="0" iyy="100" iyz="0" izz="100" />
        </inertial>
        <visual>
            <origin xyz="0.8842997890993859 0 0" rpy="0 0 0"/>
            <geometry>
                <box size="1.7685995781987718 1.2564061238497344 1.2930551155845975" />
            </geometry>
            <material name="Blue">
                <color rgba="0 1.0 1.0 1.0"/>
            </material>
        </visual>
        <collision>
            <origin xyz="0.8842997890993859 0 0" rpy="0 0 0"/>
            <geometry>
                <box size="1.7685995781987718 1.2564061238497344 1.2930551155845975" />
            </geometry>
        </collision>
    </link>
    <link name="Leg25">
        <inertial>
            <origin xyz="0 0 0.9864648322573051" rpy="0 0 0"/>
            <mass value="1" />
            <inertia ixx="100" ixy="0" ixz="0" iyy="100" iyz="0" izz="100" />
        </inertial>
        <visual>
            <origin xyz="0 0 0.9864648322573051" rpy="0 0 0"/>
            <geometry>
                <box size="1.443353026700383 2.2548459595116053 1.9729296645146102" />
            </geometry>
            <material name="Blue">
                <color rgba="0 1.0 1.0 1.0"/>
            </material>
        </visual>
        <collision>
            <origin xyz="0 0 0.9864648322573051" rpy="0 0 0"/>
            <geometry>
                <box size="1.443353026700383 2.2548459595116053 1.9729296645146102" />
            </geometry>
        </collision>
    </link>
    <link name="Leg26">
        <inertial>
            <origin xyz="0 1.1168558034605207 0" rpy="0 0 0"/>
            <mass value="1" />
            <inertia ixx="100" ixy="0" ixz="0" iyy="100" iyz="0" izz="100" />
        </inertial>
        <visual>
            <origin xyz="0 1.1168558034605207 0" rpy="0 0 0"/>
            <geometry>
                <box size="1.5394201453238496 2.2337116069210414 2.1783260371076008" />
            </geometry>
            <material name="Green">
                <color rgba="0 180.0 0.0 1.0"/>
            </material>
        </visual>
        <collision>
            <origin xyz="0 1.1168558034605207 0" rpy="0 0 0"/>
            <geometry>
                <box size="1.5394201453238496 2.2337116069210414 2.1783260371076008" />
            </geometry>
        </collision>
    </link>
    <joint name="Torso_Leg1" type="revolute">
       <parent link="Torso"/>
       <child  link="Leg1"/>
       <origin rpy="0 0 0" xyz="0.616059037513081 0 0.6474550447790163" />
     <axis xyz="1 0 0"/>
       <limit effort="0.0" lower="-3.14159" upper="3.14159" velocity="0.0"/>
    </joint>
    <joint name="Leg1_Leg2" type="revolute">
       <parent link="Leg1"/>
       <child  link="Leg2"/>
       <origin rpy="0 0 0" xyz="0 0 2.6256276617523113" />
     <axis xyz="1 0 0"/>
       <limit effort="0.0" lower="-3.14159" upper="3.14159" velocity="0.0"/>
    </joint>
    <joint name="Leg1_Leg3" type="revolute">
       <parent link="Leg1"/>
       <child  link="Leg3"/>
       <origin rpy="0 0 0" xyz="0.5177750414292799 0 2.6256276617523113" />
     <axis xyz="1 0 0"/>
       <limit effort="0.0" lower="-3.14159" upper="3.14159" velocity="0.0"/>
    </joint>
    <joint name="Leg1_Leg4" type="revolute">
       <parent link="Leg1"/>
       <child  link="Leg4"/>
       <origin rpy="0 0 0" xyz="0.5177750414292799 0.9235425823525085 2.6256276617523113" />
     <axis xyz="1 0 0"/>
       <limit effort="0.0" lower="-3.14159" upper="3.14159" velocity="0.0"/>
    </joint>
    <joint name="Leg2_Leg5" type="revolute">
       <parent link="Leg2"/>
       <child  link="Leg5"/>
       <origin rpy="0 0 0" xyz="1.8365297484975052 0 0" />
     <axis xyz="1 0 0"/>
       <limit effort="0.0" lower="-3.14159" upper="3.14159" velocity="0.0"/>
    </joint>
    <joint name="Leg4_Leg6" type="revolute">
       <parent link="Leg4"/>
       <child  link="Leg6"/>
       <origin rpy="0 0 0" xyz="1.040306457588111 0 0" />
     <axis xyz="1 0 0"/>
       <limit effort="0.0" lower="-3.14159" upper="3.14159" velocity="0.0"/>
    </joint>
    <joint name="Leg3_Leg7" type="revolute">
       <parent link="Leg3"/>
       <child  link="Leg7"/>
       <origin rpy="0 0 0" xyz="1.40587879066483 1.4445759071417776 0" />
     <axis xyz="1 0 0"/>
       <limit effort="0.0" lower="-3.14159" upper="3.14159" velocity="0.0"/>
    </joint>
    <joint name="Leg5_Leg8" type="revolute">
       <parent link="Leg5"/>
       <child  link="Leg8"/>
       <origin rpy="0 0 0" xyz="0.5769823992335016 0 1.136497754716261" />
     <axis xyz="1 0 0"/>
       <limit effort="0.0" lower="-3.14159" upper="3.14159" velocity="0.0"/>
    </joint>
    <joint name="Leg6_Leg9" type="revolute">
       <parent link="Leg6"/>
       <child  link="Leg9"/>
       <origin rpy="0 0 0" xyz="0.5465448454309416 0 0.8635095181487653" />
     <axis xyz="1 0 0"/>
       <limit effort="0.0" lower="-3.14159" upper="3.14159" velocity="0.0"/>
    </joint>
    <joint name="Leg7_Leg10" type="revolute">
       <parent link="Leg7"/>
       <child  link="Leg10"/>
       <origin rpy="0 0 0" xyz="1.435271787275274 0 1.2530161650968599" />
     <axis xyz="1 0 0"/>
       <limit effort="0.0" lower="-3.14159" upper="3.14159" velocity="0.0"/>
    </joint>
    <joint name="Leg9_Leg11" type="revolute">
       <parent link="Leg9"/>
       <child  link="Leg11"/>
       <origin rpy="0 0 0" xyz="1.4862751118461248 0.7859712165644249 0" />
     <axis xyz="1 0 0"/>
       <limit effort="0.0" lower="-3.14159" upper="3.14159" velocity="0.0"/>
    </joint>
    <joint name="Leg11_Leg12" type="revolute">
       <parent link="Leg11"/>
       <child  link="Leg12"/>
       <origin rpy="0 0 0" xyz="1.357339956133229 0 0" />
     <axis xyz="1 0 0"/>
       <limit effort="0.0" lower="-3.14159" upper="3.14159" velocity="0.0"/>
    </joint>
    <joint name="Leg12_Leg13" type="revolute">
       <parent link="Leg12"/>
       <child  link="Leg13"/>
       <origin rpy="0 0 0" xyz="2.199180429754406 0 0" />
     <axis xyz="1 0 0"/>
       <limit effort="0.0" lower="-3.14159" upper="3.14159" velocity="0.0"/>
    </joint>
    <joint name="Leg12_Leg14" type="revolute">
       <parent link="Leg12"/>
       <child  link="Leg14"/>
       <origin rpy="0 0 0" xyz="2.199180429754406 1.4766622703687005 0" />
     <axis xyz="1 0 0"/>
       <limit effort="0.0" lower="-3.14159" upper="3.14159" velocity="0.0"/>
    </joint>
    <joint name="Leg10_Leg15" type="revolute">
       <parent link="Leg10"/>
       <child  link="Leg15"/>
       <origin rpy="0 0 0" xyz="0.8946303912174831 1.1964133448482936 0" />
     <axis xyz="1 0 0"/>
       <limit effort="0.0" lower="-3.14159" upper="3.14159" velocity="0.0"/>
    </joint>
    <joint name="Leg11_Leg16" type="revolute">
       <parent link="Leg11"/>
       <child  link="Leg16"/>
       <origin rpy="0 0 0" xyz="1.357339956133229 0.5299886898919892 0" />
     <axis xyz="1 0 0"/>
       <limit effort="0.0" lower="-3.14159" upper="3.14159" velocity="0.0"/>
    </joint>
    <joint name="Leg14_Leg17" type="revolute">
       <parent link="Leg14"/>
       <child  link="Leg17"/>
       <origin rpy="0 0 0" xyz="2.6168823386214797 0 0" />
     <axis xyz="1 0 0"/>
       <limit effort="0.0" lower="-3.14159" upper="3.14159" velocity="0.0"/>
    </joint>
    <joint name="Leg12_Leg18" type="revolute">
       <parent link="Leg12"/>
       <child  link="Leg18"/>
       <origin rpy="0 0 0" xyz="2.199180429754406 1.4766622703687005 0.5058660384573024" />
     <axis xyz="1 0 0"/>
       <limit effort="0.0" lower="-3.14159" upper="3.14159" velocity="0.0"/>
    </joint>
    <joint name="Leg6_Leg19" type="revolute">
       <parent link="Leg6"/>
       <child  link="Leg19"/>
       <origin rpy="0 0 0" xyz="0.5465448454309416 1.0955135921889898 0.8635095181487653" />
     <axis xyz="1 0 0"/>
       <limit effort="0.0" lower="-3.14159" upper="3.14159" velocity="0.0"/>
    </joint>
    <joint name="Leg18_Leg20" type="revolute">
       <parent link="Leg18"/>
       <child  link="Leg20"/>
       <origin rpy="0 0 0" xyz="0 0.634500515068212 1.3506172833946812" />
     <axis xyz="1 0 0"/>
       <limit effort="0.0" lower="-3.14159" upper="3.14159" velocity="0.0"/>
    </joint>
    <joint name="Leg2_Leg21" type="revolute">
       <parent link="Leg2"/>
       <child  link="Leg21"/>
       <origin rpy="0 0 0" xyz="1.8365297484975052 1.3767891659388147 0" />
     <axis xyz="1 0 0"/>
       <limit effort="0.0" lower="-3.14159" upper="3.14159" velocity="0.0"/>
    </joint>
    <joint name="Leg19_Leg22" type="revolute">
       <parent link="Leg19"/>
       <child  link="Leg22"/>
       <origin rpy="0 0 0" xyz="0 0 2.1821679448761095" />
     <axis xyz="1 0 0"/>
       <limit effort="0.0" lower="-3.14159" upper="3.14159" velocity="0.0"/>
    </joint>
    <joint name="Leg14_Leg23" type="revolute">
       <parent link="Leg14"/>
       <child  link="Leg23"/>
       <origin rpy="0 0 0" xyz="2.6168823386214797 0.5302905404836561 0" />
     <axis xyz="1 0 0"/>
       <limit effort="0.0" lower="-3.14159" upper="3.14159" velocity="0.0"/>
    </joint>
    <joint name="Leg21_Leg24" type="revolute">
       <parent link="Leg21"/>
       <child  link="Leg24"/>
       <origin rpy="0 0 0" xyz="0.8635346355776434 0 0.7507813634951672" />
     <axis xyz="1 0 0"/>
       <limit effort="0.0" lower="-3.14159" upper="3.14159" velocity="0.0"/>
    </joint>
    <joint name="Leg24_Leg25" type="revolute">
       <parent link="Leg24"/>
       <child  link="Leg25"/>
       <origin rpy="0 0 0" xyz="0 0 1.9729296645146102" />
     <axis xyz="1 0 0"/>
       <limit effort="0.0" lower="-3.14159" upper="3.14159" velocity="0.0"/>
    </joint>
    <joint name="Leg16_Leg26" type="revolute">
       <parent link="Leg16"/>
       <child  link="Leg26"/>
       <origin rpy="0 0 0" xyz="1.114764331526466 1.0815000945118691 0" />
     <axis xyz="1 0 0"/>
       <limit effort="0.0" lower="-3.14159" upper="3.14159" velocity="0.0"/>
    </joint>
</robot>