<robot name = "robot">
    <link name="Torso">
        <inertial>
            <origin xyz="0 0 1.121046221646707" rpy="0 0 0"/>
            <mass value="1" />
            <inertia ixx="100" ixy="0" ixz="0" iyy="100" iyz="0" izz="100" />
        </inertial>
        <visual>
            <origin xyz="0 0 1.121046221646707" rpy="0 0 0"/>
            <geometry>
                <box size="2.1932678382499127 1.5624404043770366 2.242092443293414" />
            </geometry>
            <material name="Green">
                <color rgba="0 180.0 0.0 1.0"/>
            </material>
        </visual>
        <collision>
            <origin xyz="0 0 1.121046221646707" rpy="0 0 0"/>
            <geometry>
                <box size="2.1932678382499127 1.5624404043770366 2.242092443293414" />
            </geometry>
        </collision>
    </link>
    <link name="Leg1">
        <inertial>
            <origin xyz="0 0 1.2139965860065765" rpy="0 0 0"/>
            <mass value="1" />
            <inertia ixx="100" ixy="0" ixz="0" iyy="100" iyz="0" izz="100" />
        </inertial>
        <visual>
            <origin xyz="0 0 1.2139965860065765" rpy="0 0 0"/>
            <geometry>
                <box size="1.4177766644933614 2.883585127102791 2.427993172013153" />
            </geometry>
            <material name="Blue">
                <color rgba="0 1.0 1.0 1.0"/>
            </material>
        </visual>
        <collision>
            <origin xyz="0 0 1.2139965860065765" rpy="0 0 0"/>
            <geometry>
                <box size="1.4177766644933614 2.883585127102791 2.427993172013153" />
            </geometry>
        </collision>
    </link>
    <link name="Leg2">
        <inertial>
            <origin xyz="0 0 0.6092965665057984" rpy="0 0 0"/>
            <mass value="1" />
            <inertia ixx="100" ixy="0" ixz="0" iyy="100" iyz="0" izz="100" />
        </inertial>
        <visual>
            <origin xyz="0 0 0.6092965665057984" rpy="0 0 0"/>
            <geometry>
                <box size="1.8378229025133204 1.5899419354511064 1.2185931330115969" />
            </geometry>
            <material name="Green">
                <color rgba="0 180.0 0.0 1.0"/>
            </material>
        </visual>
        <collision>
            <origin xyz="0 0 0.6092965665057984" rpy="0 0 0"/>
            <geometry>
                <box size="1.8378229025133204 1.5899419354511064 1.2185931330115969" />
            </geometry>
        </collision>
    </link>
    <link name="Leg3">
        <inertial>
            <origin xyz="0 0 1.3808142014452263" rpy="0 0 0"/>
            <mass value="1" />
            <inertia ixx="100" ixy="0" ixz="0" iyy="100" iyz="0" izz="100" />
        </inertial>
        <visual>
            <origin xyz="0 0 1.3808142014452263" rpy="0 0 0"/>
            <geometry>
                <box size="2.42171791721655 1.1647729388419057 2.7616284028904525" />
            </geometry>
            <material name="Green">
                <color rgba="0 180.0 0.0 1.0"/>
            </material>
        </visual>
        <collision>
            <origin xyz="0 0 1.3808142014452263" rpy="0 0 0"/>
            <geometry>
                <box size="2.42171791721655 1.1647729388419057 2.7616284028904525" />
            </geometry>
        </collision>
    </link>
    <link name="Leg4">
        <inertial>
            <origin xyz="0 0 1.2990691592040418" rpy="0 0 0"/>
            <mass value="1" />
            <inertia ixx="100" ixy="0" ixz="0" iyy="100" iyz="0" izz="100" />
        </inertial>
        <visual>
            <origin xyz="0 0 1.2990691592040418" rpy="0 0 0"/>
            <geometry>
                <box size="2.2531948410001927 2.32086292379296 2.5981383184080835" />
            </geometry>
            <material name="Blue">
                <color rgba="0 1.0 1.0 1.0"/>
            </material>
        </visual>
        <collision>
            <origin xyz="0 0 1.2990691592040418" rpy="0 0 0"/>
            <geometry>
                <box size="2.2531948410001927 2.32086292379296 2.5981383184080835" />
            </geometry>
        </collision>
    </link>
    <link name="Leg5">
        <inertial>
            <origin xyz="0 1.1407326898266414 0" rpy="0 0 0"/>
            <mass value="1" />
            <inertia ixx="100" ixy="0" ixz="0" iyy="100" iyz="0" izz="100" />
        </inertial>
        <visual>
            <origin xyz="0 1.1407326898266414 0" rpy="0 0 0"/>
            <geometry>
                <box size="1.1563802745440723 2.281465379653283 1.8425777805839687" />
            </geometry>
            <material name="Blue">
                <color rgba="0 1.0 1.0 1.0"/>
            </material>
        </visual>
        <collision>
            <origin xyz="0 1.1407326898266414 0" rpy="0 0 0"/>
            <geometry>
                <box size="1.1563802745440723 2.281465379653283 1.8425777805839687" />
            </geometry>
        </collision>
    </link>
    <link name="Leg6">
        <inertial>
            <origin xyz="1.12115922616446 0 0" rpy="0 0 0"/>
            <mass value="1" />
            <inertia ixx="100" ixy="0" ixz="0" iyy="100" iyz="0" izz="100" />
        </inertial>
        <visual>
            <origin xyz="1.12115922616446 0 0" rpy="0 0 0"/>
            <geometry>
                <box size="2.24231845232892 2.115393164050608 1.1528939713429078" />
            </geometry>
            <material name="Blue">
                <color rgba="0 1.0 1.0 1.0"/>
            </material>
        </visual>
        <collision>
            <origin xyz="1.12115922616446 0 0" rpy="0 0 0"/>
            <geometry>
                <box size="2.24231845232892 2.115393164050608 1.1528939713429078" />
            </geometry>
        </collision>
    </link>
    <link name="Leg7">
        <inertial>
            <origin xyz="0 0.761028320139432 0" rpy="0 0 0"/>
            <mass value="1" />
            <inertia ixx="100" ixy="0" ixz="0" iyy="100" iyz="0" izz="100" />
        </inertial>
        <visual>
            <origin xyz="0 0.761028320139432 0" rpy="0 0 0"/>
            <geometry>
                <box size="2.4636869784546365 1.522056640278864 1.4644032387309769" />
            </geometry>
            <material name="Blue">
                <color rgba="0 1.0 1.0 1.0"/>
            </material>
        </visual>
        <collision>
            <origin xyz="0 0.761028320139432 0" rpy="0 0 0"/>
            <geometry>
                <box size="2.4636869784546365 1.522056640278864 1.4644032387309769" />
            </geometry>
        </collision>
    </link>
    <link name="Leg8">
        <inertial>
            <origin xyz="0 1.0884522721598795 0" rpy="0 0 0"/>
            <mass value="1" />
            <inertia ixx="100" ixy="0" ixz="0" iyy="100" iyz="0" izz="100" />
        </inertial>
        <visual>
            <origin xyz="0 1.0884522721598795 0" rpy="0 0 0"/>
            <geometry>
                <box size="1.2059968537164356 2.176904544319759 2.3532898800156747" />
            </geometry>
            <material name="Green">
                <color rgba="0 180.0 0.0 1.0"/>
            </material>
        </visual>
        <collision>
            <origin xyz="0 1.0884522721598795 0" rpy="0 0 0"/>
            <geometry>
                <box size="1.2059968537164356 2.176904544319759 2.3532898800156747" />
            </geometry>
        </collision>
    </link>
    <link name="Leg9">
        <inertial>
            <origin xyz="0 0.5244686665406604 0" rpy="0 0 0"/>
            <mass value="1" />
            <inertia ixx="100" ixy="0" ixz="0" iyy="100" iyz="0" izz="100" />
        </inertial>
        <visual>
            <origin xyz="0 0.5244686665406604 0" rpy="0 0 0"/>
            <geometry>
                <box size="2.4995232977359754 1.0489373330813208 1.2301465063410113" />
            </geometry>
            <material name="Blue">
                <color rgba="0 1.0 1.0 1.0"/>
            </material>
        </visual>
        <collision>
            <origin xyz="0 0.5244686665406604 0" rpy="0 0 0"/>
            <geometry>
                <box size="2.4995232977359754 1.0489373330813208 1.2301465063410113" />
            </geometry>
        </collision>
    </link>
    <link name="Leg10">
        <inertial>
            <origin xyz="0.6359912134826607 0 0" rpy="0 0 0"/>
            <mass value="1" />
            <inertia ixx="100" ixy="0" ixz="0" iyy="100" iyz="0" izz="100" />
        </inertial>
        <visual>
            <origin xyz="0.6359912134826607 0 0" rpy="0 0 0"/>
            <geometry>
                <box size="1.2719824269653215 1.8844810419692808 2.7516969484104843" />
            </geometry>
            <material name="Blue">
                <color rgba="0 1.0 1.0 1.0"/>
            </material>
        </visual>
        <collision>
            <origin xyz="0.6359912134826607 0 0" rpy="0 0 0"/>
            <geometry>
                <box size="1.2719824269653215 1.8844810419692808 2.7516969484104843" />
            </geometry>
        </collision>
    </link>
    <link name="Leg11">
        <inertial>
            <origin xyz="0 1.0006390239506673 0" rpy="0 0 0"/>
            <mass value="1" />
            <inertia ixx="100" ixy="0" ixz="0" iyy="100" iyz="0" izz="100" />
        </inertial>
        <visual>
            <origin xyz="0 1.0006390239506673 0" rpy="0 0 0"/>
            <geometry>
                <box size="2.590400053210018 2.0012780479013346 1.0109004631973977" />
            </geometry>
            <material name="Green">
                <color rgba="0 180.0 0.0 1.0"/>
            </material>
        </visual>
        <collision>
            <origin xyz="0 1.0006390239506673 0" rpy="0 0 0"/>
            <geometry>
                <box size="2.590400053210018 2.0012780479013346 1.0109004631973977" />
            </geometry>
        </collision>
    </link>
    <link name="Leg12">
        <inertial>
            <origin xyz="0 1.1646478107286915 0" rpy="0 0 0"/>
            <mass value="1" />
            <inertia ixx="100" ixy="0" ixz="0" iyy="100" iyz="0" izz="100" />
        </inertial>
        <visual>
            <origin xyz="0 1.1646478107286915 0" rpy="0 0 0"/>
            <geometry>
                <box size="2.653009244434092 2.329295621457383 2.2628017268810416" />
            </geometry>
            <material name="Blue">
                <color rgba="0 1.0 1.0 1.0"/>
            </material>
        </visual>
        <collision>
            <origin xyz="0 1.1646478107286915 0" rpy="0 0 0"/>
            <geometry>
                <box size="2.653009244434092 2.329295621457383 2.2628017268810416" />
            </geometry>
        </collision>
    </link>
    <link name="Leg13">
        <inertial>
            <origin xyz="0.8538227121748644 0 0" rpy="0 0 0"/>
            <mass value="1" />
            <inertia ixx="100" ixy="0" ixz="0" iyy="100" iyz="0" izz="100" />
        </inertial>
        <visual>
            <origin xyz="0.8538227121748644 0 0" rpy="0 0 0"/>
            <geometry>
                <box size="1.7076454243497288 1.9859079867557203 2.713326412760588" />
            </geometry>
            <material name="Blue">
                <color rgba="0 1.0 1.0 1.0"/>
            </material>
        </visual>
        <collision>
            <origin xyz="0.8538227121748644 0 0" rpy="0 0 0"/>
            <geometry>
                <box size="1.7076454243497288 1.9859079867557203 2.713326412760588" />
            </geometry>
        </collision>
    </link>
    <link name="Leg14">
        <inertial>
            <origin xyz="0 0 1.001152978982765" rpy="0 0 0"/>
            <mass value="1" />
            <inertia ixx="100" ixy="0" ixz="0" iyy="100" iyz="0" izz="100" />
        </inertial>
        <visual>
            <origin xyz="0 0 1.001152978982765" rpy="0 0 0"/>
            <geometry>
                <box size="2.4656754956043705 2.503969151405787 2.00230595796553" />
            </geometry>
            <material name="Blue">
                <color rgba="0 1.0 1.0 1.0"/>
            </material>
        </visual>
        <collision>
            <origin xyz="0 0 1.001152978982765" rpy="0 0 0"/>
            <geometry>
                <box size="2.4656754956043705 2.503969151405787 2.00230595796553" />
            </geometry>
        </collision>
    </link>
    <link name="Leg15">
        <inertial>
            <origin xyz="0 1.4467237339400185 0" rpy="0 0 0"/>
            <mass value="1" />
            <inertia ixx="100" ixy="0" ixz="0" iyy="100" iyz="0" izz="100" />
        </inertial>
        <visual>
            <origin xyz="0 1.4467237339400185 0" rpy="0 0 0"/>
            <geometry>
                <box size="1.7012293697787877 2.893447467880037 2.6055682703759704" />
            </geometry>
            <material name="Green">
                <color rgba="0 180.0 0.0 1.0"/>
            </material>
        </visual>
        <collision>
            <origin xyz="0 1.4467237339400185 0" rpy="0 0 0"/>
            <geometry>
                <box size="1.7012293697787877 2.893447467880037 2.6055682703759704" />
            </geometry>
        </collision>
    </link>
    <link name="Leg16">
        <inertial>
            <origin xyz="0 1.424442732990917 0" rpy="0 0 0"/>
            <mass value="1" />
            <inertia ixx="100" ixy="0" ixz="0" iyy="100" iyz="0" izz="100" />
        </inertial>
        <visual>
            <origin xyz="0 1.424442732990917 0" rpy="0 0 0"/>
            <geometry>
                <box size="1.2120873883718732 2.848885465981834 1.5159547697180475" />
            </geometry>
            <material name="Green">
                <color rgba="0 180.0 0.0 1.0"/>
            </material>
        </visual>
        <collision>
            <origin xyz="0 1.424442732990917 0" rpy="0 0 0"/>
            <geometry>
                <box size="1.2120873883718732 2.848885465981834 1.5159547697180475" />
            </geometry>
        </collision>
    </link>
    <link name="Leg17">
        <inertial>
            <origin xyz="0 0 1.1197439097160915" rpy="0 0 0"/>
            <mass value="1" />
            <inertia ixx="100" ixy="0" ixz="0" iyy="100" iyz="0" izz="100" />
        </inertial>
        <visual>
            <origin xyz="0 0 1.1197439097160915" rpy="0 0 0"/>
            <geometry>
                <box size="1.703111525145155 2.8962466092823345 2.239487819432183" />
            </geometry>
            <material name="Blue">
                <color rgba="0 1.0 1.0 1.0"/>
            </material>
        </visual>
        <collision>
            <origin xyz="0 0 1.1197439097160915" rpy="0 0 0"/>
            <geometry>
                <box size="1.703111525145155 2.8962466092823345 2.239487819432183" />
            </geometry>
        </collision>
    </link>
    <link name="Leg18">
        <inertial>
            <origin xyz="0 0 1.4610663055657067" rpy="0 0 0"/>
            <mass value="1" />
            <inertia ixx="100" ixy="0" ixz="0" iyy="100" iyz="0" izz="100" />
        </inertial>
        <visual>
            <origin xyz="0 0 1.4610663055657067" rpy="0 0 0"/>
            <geometry>
                <box size="1.5273581158171794 1.3203176208981373 2.9221326111314134" />
            </geometry>
            <material name="Blue">
                <color rgba="0 1.0 1.0 1.0"/>
            </material>
        </visual>
        <collision>
            <origin xyz="0 0 1.4610663055657067" rpy="0 0 0"/>
            <geometry>
                <box size="1.5273581158171794 1.3203176208981373 2.9221326111314134" />
            </geometry>
        </collision>
    </link>
    <link name="Leg19">
        <inertial>
            <origin xyz="0 1.2096251276879681 0" rpy="0 0 0"/>
            <mass value="1" />
            <inertia ixx="100" ixy="0" ixz="0" iyy="100" iyz="0" izz="100" />
        </inertial>
        <visual>
            <origin xyz="0 1.2096251276879681 0" rpy="0 0 0"/>
            <geometry>
                <box size="2.2996054565657564 2.4192502553759363 1.8674557081084533" />
            </geometry>
            <material name="Green">
                <color rgba="0 180.0 0.0 1.0"/>
            </material>
        </visual>
        <collision>
            <origin xyz="0 1.2096251276879681 0" rpy="0 0 0"/>
            <geometry>
                <box size="2.2996054565657564 2.4192502553759363 1.8674557081084533" />
            </geometry>
        </collision>
    </link>
    <link name="Leg20">
        <inertial>
            <origin xyz="0.5465418303939086 0 0" rpy="0 0 0"/>
            <mass value="1" />
            <inertia ixx="100" ixy="0" ixz="0" iyy="100" iyz="0" izz="100" />
        </inertial>
        <visual>
            <origin xyz="0.5465418303939086 0 0" rpy="0 0 0"/>
            <geometry>
                <box size="1.0930836607878172 2.7633312810982167 2.1114094768346963" />
            </geometry>
            <material name="Green">
                <color rgba="0 180.0 0.0 1.0"/>
            </material>
        </visual>
        <collision>
            <origin xyz="0.5465418303939086 0 0" rpy="0 0 0"/>
            <geometry>
                <box size="1.0930836607878172 2.7633312810982167 2.1114094768346963" />
            </geometry>
        </collision>
    </link>
    <link name="Leg21">
        <inertial>
            <origin xyz="0 0.8033406930300496 0" rpy="0 0 0"/>
            <mass value="1" />
            <inertia ixx="100" ixy="0" ixz="0" iyy="100" iyz="0" izz="100" />
        </inertial>
        <visual>
            <origin xyz="0 0.8033406930300496 0" rpy="0 0 0"/>
            <geometry>
                <box size="2.138872594738121 1.6066813860600992 1.7958250516894387" />
            </geometry>
            <material name="Blue">
                <color rgba="0 1.0 1.0 1.0"/>
            </material>
        </visual>
        <collision>
            <origin xyz="0 0.8033406930300496 0" rpy="0 0 0"/>
            <geometry>
                <box size="2.138872594738121 1.6066813860600992 1.7958250516894387" />
            </geometry>
        </collision>
    </link>
    <link name="Leg22">
        <inertial>
            <origin xyz="0.9604580828787883 0 0" rpy="0 0 0"/>
            <mass value="1" />
            <inertia ixx="100" ixy="0" ixz="0" iyy="100" iyz="0" izz="100" />
        </inertial>
        <visual>
            <origin xyz="0.9604580828787883 0 0" rpy="0 0 0"/>
            <geometry>
                <box size="1.9209161657575766 2.6355378039071438 1.503306887597128" />
            </geometry>
            <material name="Green">
                <color rgba="0 180.0 0.0 1.0"/>
            </material>
        </visual>
        <collision>
            <origin xyz="0.9604580828787883 0 0" rpy="0 0 0"/>
            <geometry>
                <box size="1.9209161657575766 2.6355378039071438 1.503306887597128" />
            </geometry>
        </collision>
    </link>
    <link name="Leg23">
        <inertial>
            <origin xyz="0 0 0.7345347838639401" rpy="0 0 0"/>
            <mass value="1" />
            <inertia ixx="100" ixy="0" ixz="0" iyy="100" iyz="0" izz="100" />
        </inertial>
        <visual>
            <origin xyz="0 0 0.7345347838639401" rpy="0 0 0"/>
            <geometry>
                <box size="2.5266293955834738 1.0901592636988386 1.4690695677278802" />
            </geometry>
            <material name="Blue">
                <color rgba="0 1.0 1.0 1.0"/>
            </material>
        </visual>
        <collision>
            <origin xyz="0 0 0.7345347838639401" rpy="0 0 0"/>
            <geometry>
                <box size="2.5266293955834738 1.0901592636988386 1.4690695677278802" />
            </geometry>
        </collision>
    </link>
    <link name="Leg24">
        <inertial>
            <origin xyz="0 0 0.5720351014594143" rpy="0 0 0"/>
            <mass value="1" />
            <inertia ixx="100" ixy="0" ixz="0" iyy="100" iyz="0" izz="100" />
        </inertial>
        <visual>
            <origin xyz="0 0 0.5720351014594143" rpy="0 0 0"/>
            <geometry>
                <box size="1.8438345890251877 1.1994767236027541 1.1440702029188285" />
            </geometry>
            <material name="Blue">
                <color rgba="0 1.0 1.0 1.0"/>
            </material>
        </visual>
        <collision>
            <origin xyz="0 0 0.5720351014594143" rpy="0 0 0"/>
            <geometry>
                <box size="1.8438345890251877 1.1994767236027541 1.1440702029188285" />
            </geometry>
        </collision>
    </link>
    <link name="Leg25">
        <inertial>
            <origin xyz="0 0 0.8890444297329005" rpy="0 0 0"/>
            <mass value="1" />
            <inertia ixx="100" ixy="0" ixz="0" iyy="100" iyz="0" izz="100" />
        </inertial>
        <visual>
            <origin xyz="0 0 0.8890444297329005" rpy="0 0 0"/>
            <geometry>
                <box size="2.164916264320395 1.8445122014474533 1.778088859465801" />
            </geometry>
            <material name="Green">
                <color rgba="0 180.0 0.0 1.0"/>
            </material>
        </visual>
        <collision>
            <origin xyz="0 0 0.8890444297329005" rpy="0 0 0"/>
            <geometry>
                <box size="2.164916264320395 1.8445122014474533 1.778088859465801" />
            </geometry>
        </collision>
    </link>
    <link name="Leg26">
        <inertial>
            <origin xyz="0.6537232754913849 0 0" rpy="0 0 0"/>
            <mass value="1" />
            <inertia ixx="100" ixy="0" ixz="0" iyy="100" iyz="0" izz="100" />
        </inertial>
        <visual>
            <origin xyz="0.6537232754913849 0 0" rpy="0 0 0"/>
            <geometry>
                <box size="1.3074465509827697 2.171183633327985 1.1718500902599471" />
            </geometry>
            <material name="Green">
                <color rgba="0 180.0 0.0 1.0"/>
            </material>
        </visual>
        <collision>
            <origin xyz="0.6537232754913849 0 0" rpy="0 0 0"/>
            <geometry>
                <box size="1.3074465509827697 2.171183633327985 1.1718500902599471" />
            </geometry>
        </collision>
    </link>
    <link name="Leg27">
        <inertial>
            <origin xyz="0.553428497761482 0 0" rpy="0 0 0"/>
            <mass value="1" />
            <inertia ixx="100" ixy="0" ixz="0" iyy="100" iyz="0" izz="100" />
        </inertial>
        <visual>
            <origin xyz="0.553428497761482 0 0" rpy="0 0 0"/>
            <geometry>
                <box size="1.106856995522964 2.3769087826194877 1.9946518454246156" />
            </geometry>
            <material name="Blue">
                <color rgba="0 1.0 1.0 1.0"/>
            </material>
        </visual>
        <collision>
            <origin xyz="0.553428497761482 0 0" rpy="0 0 0"/>
            <geometry>
                <box size="1.106856995522964 2.3769087826194877 1.9946518454246156" />
            </geometry>
        </collision>
    </link>
    <joint name="Torso_Leg1" type="revolute">
       <parent link="Torso"/>
       <child  link="Leg1"/>
       <origin rpy="0 0 0" xyz="0 0 2.242092443293414" />
     <axis xyz="1 0 0"/>
       <limit effort="0.0" lower="-3.14159" upper="3.14159" velocity="0.0"/>
    </joint>
    <joint name="Leg1_Leg2" type="revolute">
       <parent link="Leg1"/>
       <child  link="Leg2"/>
       <origin rpy="0 0 0" xyz="0 0 1.2185931330115969" />
     <axis xyz="1 0 0"/>
       <limit effort="0.0" lower="-3.14159" upper="3.14159" velocity="0.0"/>
    </joint>
    <joint name="Leg2_Leg3" type="revolute">
       <parent link="Leg2"/>
       <child  link="Leg3"/>
       <origin rpy="0 0 0" xyz="0 0 2.7616284028904525" />
     <axis xyz="1 0 0"/>
       <limit effort="0.0" lower="-3.14159" upper="3.14159" velocity="0.0"/>
    </joint>
    <joint name="Leg3_Leg4" type="revolute">
       <parent link="Leg3"/>
       <child  link="Leg4"/>
       <origin rpy="0 0 0" xyz="0 0 2.5981383184080835" />
     <axis xyz="1 0 0"/>
       <limit effort="0.0" lower="-3.14159" upper="3.14159" velocity="0.0"/>
    </joint>
    <joint name="Leg4_Leg5" type="revolute">
       <parent link="Leg4"/>
       <child  link="Leg5"/>
       <origin rpy="0 0 0" xyz="0 2.281465379653283 0" />
     <axis xyz="1 0 0"/>
       <limit effort="0.0" lower="-3.14159" upper="3.14159" velocity="0.0"/>
    </joint>
    <joint name="Leg2_Leg6" type="revolute">
       <parent link="Leg2"/>
       <child  link="Leg6"/>
       <origin rpy="0 0 0" xyz="1.210858958608275 0 2.7616284028904525" />
     <axis xyz="1 0 0"/>
       <limit effort="0.0" lower="-3.14159" upper="3.14159" velocity="0.0"/>
    </joint>
    <joint name="Torso_Leg7" type="revolute">
       <parent link="Torso"/>
       <child  link="Leg7"/>
       <origin rpy="0 0 0" xyz="0 1.4417925635513955 1.2139965860065765" />
     <axis xyz="1 0 0"/>
       <limit effort="0.0" lower="-3.14159" upper="3.14159" velocity="0.0"/>
    </joint>
    <joint name="Leg5_Leg8" type="revolute">
       <parent link="Leg5"/>
       <child  link="Leg8"/>
       <origin rpy="0 0 0" xyz="1.12115922616446 1.057696582025304 0" />
     <axis xyz="1 0 0"/>
       <limit effort="0.0" lower="-3.14159" upper="3.14159" velocity="0.0"/>
    </joint>
    <joint name="Leg8_Leg9" type="revolute">
       <parent link="Leg8"/>
       <child  link="Leg9"/>
       <origin rpy="0 0 0" xyz="0 1.0489373330813208 0" />
     <axis xyz="1 0 0"/>
       <limit effort="0.0" lower="-3.14159" upper="3.14159" velocity="0.0"/>
    </joint>
    <joint name="Leg6_Leg10" type="revolute">
       <parent link="Leg6"/>
       <child  link="Leg10"/>
       <origin rpy="0 0 0" xyz="1.2318434892273182 0.761028320139432 0" />
     <axis xyz="1 0 0"/>
       <limit effort="0.0" lower="-3.14159" upper="3.14159" velocity="0.0"/>
    </joint>
    <joint name="Leg10_Leg11" type="revolute">
       <parent link="Leg10"/>
       <child  link="Leg11"/>
       <origin rpy="0 0 0" xyz="0 2.0012780479013346 0" />
     <axis xyz="1 0 0"/>
       <limit effort="0.0" lower="-3.14159" upper="3.14159" velocity="0.0"/>
    </joint>
    <joint name="Leg6_Leg12" type="revolute">
       <parent link="Leg6"/>
       <child  link="Leg12"/>
       <origin rpy="0 0 0" xyz="1.2318434892273182 1.522056640278864 0" />
     <axis xyz="1 0 0"/>
       <limit effort="0.0" lower="-3.14159" upper="3.14159" velocity="0.0"/>
    </joint>
    <joint name="Leg10_Leg13" type="revolute">
       <parent link="Leg10"/>
       <child  link="Leg13"/>
       <origin rpy="0 0 0" xyz="1.295200026605009 2.0012780479013346 0" />
     <axis xyz="1 0 0"/>
       <limit effort="0.0" lower="-3.14159" upper="3.14159" velocity="0.0"/>
    </joint>
    <joint name="Leg11_Leg14" type="revolute">
       <parent link="Leg11"/>
       <child  link="Leg14"/>
       <origin rpy="0 0 0" xyz="0 1.1646478107286915 1.1314008634405208" />
     <axis xyz="1 0 0"/>
       <limit effort="0.0" lower="-3.14159" upper="3.14159" velocity="0.0"/>
    </joint>
    <joint name="Leg3_Leg15" type="revolute">
       <parent link="Leg3"/>
       <child  link="Leg15"/>
       <origin rpy="0 0 0" xyz="0 1.16043146189648 2.5981383184080835" />
     <axis xyz="1 0 0"/>
       <limit effort="0.0" lower="-3.14159" upper="3.14159" velocity="0.0"/>
    </joint>
    <joint name="Leg2_Leg16" type="revolute">
       <parent link="Leg2"/>
       <child  link="Leg16"/>
       <origin rpy="0 0 0" xyz="1.210858958608275 0.5823864694209528 2.7616284028904525" />
     <axis xyz="1 0 0"/>
       <limit effort="0.0" lower="-3.14159" upper="3.14159" velocity="0.0"/>
    </joint>
    <joint name="Leg4_Leg17" type="revolute">
       <parent link="Leg4"/>
       <child  link="Leg17"/>
       <origin rpy="0 0 0" xyz="0 2.281465379653283 0.9212888902919844" />
     <axis xyz="1 0 0"/>
       <limit effort="0.0" lower="-3.14159" upper="3.14159" velocity="0.0"/>
    </joint>
    <joint name="Leg14_Leg18" type="revolute">
       <parent link="Leg14"/>
       <child  link="Leg18"/>
       <origin rpy="0 0 0" xyz="0 1.4467237339400185 1.3027841351879852" />
     <axis xyz="1 0 0"/>
       <limit effort="0.0" lower="-3.14159" upper="3.14159" velocity="0.0"/>
    </joint>
    <joint name="Leg7_Leg19" type="revolute">
       <parent link="Leg7"/>
       <child  link="Leg19"/>
       <origin rpy="0 0 0" xyz="0 2.176904544319759 0" />
     <axis xyz="1 0 0"/>
       <limit effort="0.0" lower="-3.14159" upper="3.14159" velocity="0.0"/>
    </joint>
    <joint name="Leg12_Leg20" type="revolute">
       <parent link="Leg12"/>
       <child  link="Leg20"/>
       <origin rpy="0 0 0" xyz="1.7076454243497288 0 0" />
     <axis xyz="1 0 0"/>
       <limit effort="0.0" lower="-3.14159" upper="3.14159" velocity="0.0"/>
    </joint>
    <joint name="Leg15_Leg21" type="revolute">
       <parent link="Leg15"/>
       <child  link="Leg21"/>
       <origin rpy="0 0 0" xyz="0 2.848885465981834 0" />
     <axis xyz="1 0 0"/>
       <limit effort="0.0" lower="-3.14159" upper="3.14159" velocity="0.0"/>
    </joint>
    <joint name="Leg8_Leg22" type="revolute">
       <parent link="Leg8"/>
       <child  link="Leg22"/>
       <origin rpy="0 0 0" xyz="1.2497616488679877 1.0489373330813208 0" />
     <axis xyz="1 0 0"/>
       <limit effort="0.0" lower="-3.14159" upper="3.14159" velocity="0.0"/>
    </joint>
    <joint name="Leg10_Leg23" type="revolute">
       <parent link="Leg10"/>
       <child  link="Leg23"/>
       <origin rpy="0 0 0" xyz="1.295200026605009 2.0012780479013346 0.5054502315986988" />
     <axis xyz="1 0 0"/>
       <limit effort="0.0" lower="-3.14159" upper="3.14159" velocity="0.0"/>
    </joint>
    <joint name="Leg16_Leg24" type="revolute">
       <parent link="Leg16"/>
       <child  link="Leg24"/>
       <origin rpy="0 0 0" xyz="0 0 2.239487819432183" />
     <axis xyz="1 0 0"/>
       <limit effort="0.0" lower="-3.14159" upper="3.14159" velocity="0.0"/>
    </joint>
    <joint name="Leg22_Leg25" type="revolute">
       <parent link="Leg22"/>
       <child  link="Leg25"/>
       <origin rpy="0 0 0" xyz="0 0 1.4690695677278802" />
     <axis xyz="1 0 0"/>
       <limit effort="0.0" lower="-3.14159" upper="3.14159" velocity="0.0"/>
    </joint>
    <joint name="Leg14_Leg26" type="revolute">
       <parent link="Leg14"/>
       <child  link="Leg26"/>
       <origin rpy="0 0 0" xyz="0.8506146848893938 1.4467237339400185 1.3027841351879852" />
     <axis xyz="1 0 0"/>
       <limit effort="0.0" lower="-3.14159" upper="3.14159" velocity="0.0"/>
    </joint>
    <joint name="Torso_Leg27" type="revolute">
       <parent link="Torso"/>
       <child  link="Leg27"/>
       <origin rpy="0 0 0" xyz="0.7088883322466807 1.4417925635513955 1.2139965860065765" />
     <axis xyz="1 0 0"/>
       <limit effort="0.0" lower="-3.14159" upper="3.14159" velocity="0.0"/>
    </joint>
</robot>