<robot name = "robot">
    <link name="Torso">
        <inertial>
            <origin xyz="0 0 1.2351574003852979" rpy="0 0 0"/>
            <mass value="1" />
            <inertia ixx="100" ixy="0" ixz="0" iyy="100" iyz="0" izz="100" />
        </inertial>
        <visual>
            <origin xyz="0 0 1.2351574003852979" rpy="0 0 0"/>
            <geometry>
                <box size="2.5750196557634375 1.8363577754887523 2.4703148007705957" />
            </geometry>
            <material name="Green">
                <color rgba="0 180.0 0.0 1.0"/>
            </material>
        </visual>
        <collision>
            <origin xyz="0 0 1.2351574003852979" rpy="0 0 0"/>
            <geometry>
                <box size="2.5750196557634375 1.8363577754887523 2.4703148007705957" />
            </geometry>
        </collision>
    </link>
    <link name="Leg1">
        <inertial>
            <origin xyz="1.0842408782976811 0 0" rpy="0 0 0"/>
            <mass value="1" />
            <inertia ixx="100" ixy="0" ixz="0" iyy="100" iyz="0" izz="100" />
        </inertial>
        <visual>
            <origin xyz="1.0842408782976811 0 0" rpy="0 0 0"/>
            <geometry>
                <box size="2.1684817565953622 2.7674020384674356 2.6588067473630894" />
            </geometry>
            <material name="Green">
                <color rgba="0 180.0 0.0 1.0"/>
            </material>
        </visual>
        <collision>
            <origin xyz="1.0842408782976811 0 0" rpy="0 0 0"/>
            <geometry>
                <box size="2.1684817565953622 2.7674020384674356 2.6588067473630894" />
            </geometry>
        </collision>
    </link>
    <link name="Leg2">
        <inertial>
            <origin xyz="1.1563080066453573 0 0" rpy="0 0 0"/>
            <mass value="1" />
            <inertia ixx="100" ixy="0" ixz="0" iyy="100" iyz="0" izz="100" />
        </inertial>
        <visual>
            <origin xyz="1.1563080066453573 0 0" rpy="0 0 0"/>
            <geometry>
                <box size="2.3126160132907145 2.9047740791276895 1.7589593443743199" />
            </geometry>
            <material name="Green">
                <color rgba="0 180.0 0.0 1.0"/>
            </material>
        </visual>
        <collision>
            <origin xyz="1.1563080066453573 0 0" rpy="0 0 0"/>
            <geometry>
                <box size="2.3126160132907145 2.9047740791276895 1.7589593443743199" />
            </geometry>
        </collision>
    </link>
    <link name="Leg3">
        <inertial>
            <origin xyz="0 0 0.656433784714461" rpy="0 0 0"/>
            <mass value="1" />
            <inertia ixx="100" ixy="0" ixz="0" iyy="100" iyz="0" izz="100" />
        </inertial>
        <visual>
            <origin xyz="0 0 0.656433784714461" rpy="0 0 0"/>
            <geometry>
                <box size="1.537112133486014 1.2251603972766485 1.312867569428922" />
            </geometry>
            <material name="Blue">
                <color rgba="0 1.0 1.0 1.0"/>
            </material>
        </visual>
        <collision>
            <origin xyz="0 0 0.656433784714461" rpy="0 0 0"/>
            <geometry>
                <box size="1.537112133486014 1.2251603972766485 1.312867569428922" />
            </geometry>
        </collision>
    </link>
    <link name="Leg4">
        <inertial>
            <origin xyz="0 0 0.8116175524265137" rpy="0 0 0"/>
            <mass value="1" />
            <inertia ixx="100" ixy="0" ixz="0" iyy="100" iyz="0" izz="100" />
        </inertial>
        <visual>
            <origin xyz="0 0 0.8116175524265137" rpy="0 0 0"/>
            <geometry>
                <box size="1.6255827546912216 1.8990219422110404 1.6232351048530274" />
            </geometry>
            <material name="Green">
                <color rgba="0 180.0 0.0 1.0"/>
            </material>
        </visual>
        <collision>
            <origin xyz="0 0 0.8116175524265137" rpy="0 0 0"/>
            <geometry>
                <box size="1.6255827546912216 1.8990219422110404 1.6232351048530274" />
            </geometry>
        </collision>
    </link>
    <link name="Leg5">
        <inertial>
            <origin xyz="0.7946207572678335 0 0" rpy="0 0 0"/>
            <mass value="1" />
            <inertia ixx="100" ixy="0" ixz="0" iyy="100" iyz="0" izz="100" />
        </inertial>
        <visual>
            <origin xyz="0.7946207572678335 0 0" rpy="0 0 0"/>
            <geometry>
                <box size="1.589241514535667 2.5794759656986157 2.446647956512515" />
            </geometry>
            <material name="Blue">
                <color rgba="0 1.0 1.0 1.0"/>
            </material>
        </visual>
        <collision>
            <origin xyz="0.7946207572678335 0 0" rpy="0 0 0"/>
            <geometry>
                <box size="1.589241514535667 2.5794759656986157 2.446647956512515" />
            </geometry>
        </collision>
    </link>
    <link name="Leg6">
        <inertial>
            <origin xyz="0.8569532331950549 0 0" rpy="0 0 0"/>
            <mass value="1" />
            <inertia ixx="100" ixy="0" ixz="0" iyy="100" iyz="0" izz="100" />
        </inertial>
        <visual>
            <origin xyz="0.8569532331950549 0 0" rpy="0 0 0"/>
            <geometry>
                <box size="1.7139064663901098 2.862509242556989 2.520682772931932" />
            </geometry>
            <material name="Blue">
                <color rgba="0 1.0 1.0 1.0"/>
            </material>
        </visual>
        <collision>
            <origin xyz="0.8569532331950549 0 0" rpy="0 0 0"/>
            <geometry>
                <box size="1.7139064663901098 2.862509242556989 2.520682772931932" />
            </geometry>
        </collision>
    </link>
    <link name="Leg7">
        <inertial>
            <origin xyz="0 1.1381621289044004 0" rpy="0 0 0"/>
            <mass value="1" />
            <inertia ixx="100" ixy="0" ixz="0" iyy="100" iyz="0" izz="100" />
        </inertial>
        <visual>
            <origin xyz="0 1.1381621289044004 0" rpy="0 0 0"/>
            <geometry>
                <box size="2.0247375509943706 2.2763242578088008 2.594103915384899" />
            </geometry>
            <material name="Blue">
                <color rgba="0 1.0 1.0 1.0"/>
            </material>
        </visual>
        <collision>
            <origin xyz="0 1.1381621289044004 0" rpy="0 0 0"/>
            <geometry>
                <box size="2.0247375509943706 2.2763242578088008 2.594103915384899" />
            </geometry>
        </collision>
    </link>
    <link name="Leg8">
        <inertial>
            <origin xyz="0 0.8501294506618573 0" rpy="0 0 0"/>
            <mass value="1" />
            <inertia ixx="100" ixy="0" ixz="0" iyy="100" iyz="0" izz="100" />
        </inertial>
        <visual>
            <origin xyz="0 0.8501294506618573 0" rpy="0 0 0"/>
            <geometry>
                <box size="2.472975525949438 1.7002589013237146 1.9200709238551683" />
            </geometry>
            <material name="Blue">
                <color rgba="0 1.0 1.0 1.0"/>
            </material>
        </visual>
        <collision>
            <origin xyz="0 0.8501294506618573 0" rpy="0 0 0"/>
            <geometry>
                <box size="2.472975525949438 1.7002589013237146 1.9200709238551683" />
            </geometry>
        </collision>
    </link>
    <link name="Leg9">
        <inertial>
            <origin xyz="0 0.724046188097243 0" rpy="0 0 0"/>
            <mass value="1" />
            <inertia ixx="100" ixy="0" ixz="0" iyy="100" iyz="0" izz="100" />
        </inertial>
        <visual>
            <origin xyz="0 0.724046188097243 0" rpy="0 0 0"/>
            <geometry>
                <box size="2.902609857446347 1.448092376194486 2.3049749370980965" />
            </geometry>
            <material name="Green">
                <color rgba="0 180.0 0.0 1.0"/>
            </material>
        </visual>
        <collision>
            <origin xyz="0 0.724046188097243 0" rpy="0 0 0"/>
            <geometry>
                <box size="2.902609857446347 1.448092376194486 2.3049749370980965" />
            </geometry>
        </collision>
    </link>
    <link name="Leg10">
        <inertial>
            <origin xyz="0 0.6605517958538498 0" rpy="0 0 0"/>
            <mass value="1" />
            <inertia ixx="100" ixy="0" ixz="0" iyy="100" iyz="0" izz="100" />
        </inertial>
        <visual>
            <origin xyz="0 0.6605517958538498 0" rpy="0 0 0"/>
            <geometry>
                <box size="2.647466799276084 1.3211035917076996 2.1577167899325036" />
            </geometry>
            <material name="Green">
                <color rgba="0 180.0 0.0 1.0"/>
            </material>
        </visual>
        <collision>
            <origin xyz="0 0.6605517958538498 0" rpy="0 0 0"/>
            <geometry>
                <box size="2.647466799276084 1.3211035917076996 2.1577167899325036" />
            </geometry>
        </collision>
    </link>
    <link name="Leg11">
        <inertial>
            <origin xyz="0 1.25957656853507 0" rpy="0 0 0"/>
            <mass value="1" />
            <inertia ixx="100" ixy="0" ixz="0" iyy="100" iyz="0" izz="100" />
        </inertial>
        <visual>
            <origin xyz="0 1.25957656853507 0" rpy="0 0 0"/>
            <geometry>
                <box size="1.7687774785507333 2.51915313707014 2.208460583596392" />
            </geometry>
            <material name="Blue">
                <color rgba="0 1.0 1.0 1.0"/>
            </material>
        </visual>
        <collision>
            <origin xyz="0 1.25957656853507 0" rpy="0 0 0"/>
            <geometry>
                <box size="1.7687774785507333 2.51915313707014 2.208460583596392" />
            </geometry>
        </collision>
    </link>
    <link name="Leg12">
        <inertial>
            <origin xyz="0 0 0.6839787651529212" rpy="0 0 0"/>
            <mass value="1" />
            <inertia ixx="100" ixy="0" ixz="0" iyy="100" iyz="0" izz="100" />
        </inertial>
        <visual>
            <origin xyz="0 0 0.6839787651529212" rpy="0 0 0"/>
            <geometry>
                <box size="2.4160643889090725 1.3731595264648064 1.3679575303058424" />
            </geometry>
            <material name="Blue">
                <color rgba="0 1.0 1.0 1.0"/>
            </material>
        </visual>
        <collision>
            <origin xyz="0 0 0.6839787651529212" rpy="0 0 0"/>
            <geometry>
                <box size="2.4160643889090725 1.3731595264648064 1.3679575303058424" />
            </geometry>
        </collision>
    </link>
    <link name="Leg13">
        <inertial>
            <origin xyz="0 0 1.2283321370718308" rpy="0 0 0"/>
            <mass value="1" />
            <inertia ixx="100" ixy="0" ixz="0" iyy="100" iyz="0" izz="100" />
        </inertial>
        <visual>
            <origin xyz="0 0 1.2283321370718308" rpy="0 0 0"/>
            <geometry>
                <box size="1.6116304092106148 2.1134401607820505 2.4566642741436615" />
            </geometry>
            <material name="Blue">
                <color rgba="0 1.0 1.0 1.0"/>
            </material>
        </visual>
        <collision>
            <origin xyz="0 0 1.2283321370718308" rpy="0 0 0"/>
            <geometry>
                <box size="1.6116304092106148 2.1134401607820505 2.4566642741436615" />
            </geometry>
        </collision>
    </link>
    <link name="Leg14">
        <inertial>
            <origin xyz="1.1659702198438353 0 0" rpy="0 0 0"/>
            <mass value="1" />
            <inertia ixx="100" ixy="0" ixz="0" iyy="100" iyz="0" izz="100" />
        </inertial>
        <visual>
            <origin xyz="1.1659702198438353 0 0" rpy="0 0 0"/>
            <geometry>
                <box size="2.3319404396876706 2.5493391324656693 2.6728558044642456" />
            </geometry>
            <material name="Blue">
                <color rgba="0 1.0 1.0 1.0"/>
            </material>
        </visual>
        <collision>
            <origin xyz="1.1659702198438353 0 0" rpy="0 0 0"/>
            <geometry>
                <box size="2.3319404396876706 2.5493391324656693 2.6728558044642456" />
            </geometry>
        </collision>
    </link>
    <link name="Leg15">
        <inertial>
            <origin xyz="0 0 1.0896601388133071" rpy="0 0 0"/>
            <mass value="1" />
            <inertia ixx="100" ixy="0" ixz="0" iyy="100" iyz="0" izz="100" />
        </inertial>
        <visual>
            <origin xyz="0 0 1.0896601388133071" rpy="0 0 0"/>
            <geometry>
                <box size="2.8753262828719537 2.948061848482603 2.1793202776266143" />
            </geometry>
            <material name="Green">
                <color rgba="0 180.0 0.0 1.0"/>
            </material>
        </visual>
        <collision>
            <origin xyz="0 0 1.0896601388133071" rpy="0 0 0"/>
            <geometry>
                <box size="2.8753262828719537 2.948061848482603 2.1793202776266143" />
            </geometry>
        </collision>
    </link>
    <link name="Leg16">
        <inertial>
            <origin xyz="0.5275869399054035 0 0" rpy="0 0 0"/>
            <mass value="1" />
            <inertia ixx="100" ixy="0" ixz="0" iyy="100" iyz="0" izz="100" />
        </inertial>
        <visual>
            <origin xyz="0.5275869399054035 0 0" rpy="0 0 0"/>
            <geometry>
                <box size="1.055173879810807 2.9674774248784077 1.3432403508682829" />
            </geometry>
            <material name="Green">
                <color rgba="0 180.0 0.0 1.0"/>
            </material>
        </visual>
        <collision>
            <origin xyz="0.5275869399054035 0 0" rpy="0 0 0"/>
            <geometry>
                <box size="1.055173879810807 2.9674774248784077 1.3432403508682829" />
            </geometry>
        </collision>
    </link>
    <link name="Leg17">
        <inertial>
            <origin xyz="0 0 1.3153834290055877" rpy="0 0 0"/>
            <mass value="1" />
            <inertia ixx="100" ixy="0" ixz="0" iyy="100" iyz="0" izz="100" />
        </inertial>
        <visual>
            <origin xyz="0 0 1.3153834290055877" rpy="0 0 0"/>
            <geometry>
                <box size="2.587753708769201 2.6853670993787246 2.6307668580111754" />
            </geometry>
            <material name="Blue">
                <color rgba="0 1.0 1.0 1.0"/>
            </material>
        </visual>
        <collision>
            <origin xyz="0 0 1.3153834290055877" rpy="0 0 0"/>
            <geometry>
                <box size="2.587753708769201 2.6853670993787246 2.6307668580111754" />
            </geometry>
        </collision>
    </link>
    <link name="Leg18">
        <inertial>
            <origin xyz="0 1.2927740048706848 0" rpy="0 0 0"/>
            <mass value="1" />
            <inertia ixx="100" ixy="0" ixz="0" iyy="100" iyz="0" izz="100" />
        </inertial>
        <visual>
            <origin xyz="0 1.2927740048706848 0" rpy="0 0 0"/>
            <geometry>
                <box size="1.4401359498252702 2.5855480097413697 2.5559893437606003" />
            </geometry>
            <material name="Green">
                <color rgba="0 180.0 0.0 1.0"/>
            </material>
        </visual>
        <collision>
            <origin xyz="0 1.2927740048706848 0" rpy="0 0 0"/>
            <geometry>
                <box size="1.4401359498252702 2.5855480097413697 2.5559893437606003" />
            </geometry>
        </collision>
    </link>
    <link name="Leg19">
        <inertial>
            <origin xyz="0 1.0641065330150266 0" rpy="0 0 0"/>
            <mass value="1" />
            <inertia ixx="100" ixy="0" ixz="0" iyy="100" iyz="0" izz="100" />
        </inertial>
        <visual>
            <origin xyz="0 1.0641065330150266 0" rpy="0 0 0"/>
            <geometry>
                <box size="2.3921536718521628 2.128213066030053 1.877194293986789" />
            </geometry>
            <material name="Blue">
                <color rgba="0 1.0 1.0 1.0"/>
            </material>
        </visual>
        <collision>
            <origin xyz="0 1.0641065330150266 0" rpy="0 0 0"/>
            <geometry>
                <box size="2.3921536718521628 2.128213066030053 1.877194293986789" />
            </geometry>
        </collision>
    </link>
    <link name="Leg20">
        <inertial>
            <origin xyz="0 1.1314773243953276 0" rpy="0 0 0"/>
            <mass value="1" />
            <inertia ixx="100" ixy="0" ixz="0" iyy="100" iyz="0" izz="100" />
        </inertial>
        <visual>
            <origin xyz="0 1.1314773243953276 0" rpy="0 0 0"/>
            <geometry>
                <box size="2.1841321577711947 2.262954648790655 1.2857966510324594" />
            </geometry>
            <material name="Green">
                <color rgba="0 180.0 0.0 1.0"/>
            </material>
        </visual>
        <collision>
            <origin xyz="0 1.1314773243953276 0" rpy="0 0 0"/>
            <geometry>
                <box size="2.1841321577711947 2.262954648790655 1.2857966510324594" />
            </geometry>
        </collision>
    </link>
    <link name="Leg21">
        <inertial>
            <origin xyz="0 0 1.2395259681114388" rpy="0 0 0"/>
            <mass value="1" />
            <inertia ixx="100" ixy="0" ixz="0" iyy="100" iyz="0" izz="100" />
        </inertial>
        <visual>
            <origin xyz="0 0 1.2395259681114388" rpy="0 0 0"/>
            <geometry>
                <box size="1.5241554174451917 1.9972291135597386 2.4790519362228776" />
            </geometry>
            <material name="Green">
                <color rgba="0 180.0 0.0 1.0"/>
            </material>
        </visual>
        <collision>
            <origin xyz="0 0 1.2395259681114388" rpy="0 0 0"/>
            <geometry>
                <box size="1.5241554174451917 1.9972291135597386 2.4790519362228776" />
            </geometry>
        </collision>
    </link>
    <link name="Leg22">
        <inertial>
            <origin xyz="1.2970719060517903 0 0" rpy="0 0 0"/>
            <mass value="1" />
            <inertia ixx="100" ixy="0" ixz="0" iyy="100" iyz="0" izz="100" />
        </inertial>
        <visual>
            <origin xyz="1.2970719060517903 0 0" rpy="0 0 0"/>
            <geometry>
                <box size="2.5941438121035807 2.380340653195511 1.588876607011839" />
            </geometry>
            <material name="Blue">
                <color rgba="0 1.0 1.0 1.0"/>
            </material>
        </visual>
        <collision>
            <origin xyz="1.2970719060517903 0 0" rpy="0 0 0"/>
            <geometry>
                <box size="2.5941438121035807 2.380340653195511 1.588876607011839" />
            </geometry>
        </collision>
    </link>
    <link name="Leg23">
        <inertial>
            <origin xyz="0 0 1.478949538828299" rpy="0 0 0"/>
            <mass value="1" />
            <inertia ixx="100" ixy="0" ixz="0" iyy="100" iyz="0" izz="100" />
        </inertial>
        <visual>
            <origin xyz="0 0 1.478949538828299" rpy="0 0 0"/>
            <geometry>
                <box size="1.3404618434188424 2.0679509241814826 2.957899077656598" />
            </geometry>
            <material name="Green">
                <color rgba="0 180.0 0.0 1.0"/>
            </material>
        </visual>
        <collision>
            <origin xyz="0 0 1.478949538828299" rpy="0 0 0"/>
            <geometry>
                <box size="1.3404618434188424 2.0679509241814826 2.957899077656598" />
            </geometry>
        </collision>
    </link>
    <link name="Leg24">
        <inertial>
            <origin xyz="0.8774016991291578 0 0" rpy="0 0 0"/>
            <mass value="1" />
            <inertia ixx="100" ixy="0" ixz="0" iyy="100" iyz="0" izz="100" />
        </inertial>
        <visual>
            <origin xyz="0.8774016991291578 0 0" rpy="0 0 0"/>
            <geometry>
                <box size="1.7548033982583155 2.0467726603679353 1.4318607006951034" />
            </geometry>
            <material name="Blue">
                <color rgba="0 1.0 1.0 1.0"/>
            </material>
        </visual>
        <collision>
            <origin xyz="0.8774016991291578 0 0" rpy="0 0 0"/>
            <geometry>
                <box size="1.7548033982583155 2.0467726603679353 1.4318607006951034" />
            </geometry>
        </collision>
    </link>
    <link name="Leg25">
        <inertial>
            <origin xyz="0 0 0.6656353405532939" rpy="0 0 0"/>
            <mass value="1" />
            <inertia ixx="100" ixy="0" ixz="0" iyy="100" iyz="0" izz="100" />
        </inertial>
        <visual>
            <origin xyz="0 0 0.6656353405532939" rpy="0 0 0"/>
            <geometry>
                <box size="2.1614457873302273 2.5735260152146937 1.3312706811065877" />
            </geometry>
            <material name="Green">
                <color rgba="0 180.0 0.0 1.0"/>
            </material>
        </visual>
        <collision>
            <origin xyz="0 0 0.6656353405532939" rpy="0 0 0"/>
            <geometry>
                <box size="2.1614457873302273 2.5735260152146937 1.3312706811065877" />
            </geometry>
        </collision>
    </link>
    <joint name="Torso_Leg1" type="revolute">
       <parent link="Torso"/>
       <child  link="Leg1"/>
       <origin rpy="0 0 0" xyz="1.2875098278817187 0 1.2351574003852979" />
     <axis xyz="1 0 0"/>
       <limit effort="0.0" lower="-3.14159" upper="3.14159" velocity="0.0"/>
    </joint>
    <joint name="Leg1_Leg2" type="revolute">
       <parent link="Leg1"/>
       <child  link="Leg2"/>
       <origin rpy="0 0 0" xyz="2.3126160132907145 0 0" />
     <axis xyz="1 0 0"/>
       <limit effort="0.0" lower="-3.14159" upper="3.14159" velocity="0.0"/>
    </joint>
    <joint name="Torso_Leg3" type="revolute">
       <parent link="Torso"/>
       <child  link="Leg3"/>
       <origin rpy="0 0 0" xyz="1.0842408782976811 0 1.3294033736815447" />
     <axis xyz="1 0 0"/>
       <limit effort="0.0" lower="-3.14159" upper="3.14159" velocity="0.0"/>
    </joint>
    <joint name="Leg3_Leg4" type="revolute">
       <parent link="Leg3"/>
       <child  link="Leg4"/>
       <origin rpy="0 0 0" xyz="0 0 1.6232351048530274" />
     <axis xyz="1 0 0"/>
       <limit effort="0.0" lower="-3.14159" upper="3.14159" velocity="0.0"/>
    </joint>
    <joint name="Leg3_Leg5" type="revolute">
       <parent link="Leg3"/>
       <child  link="Leg5"/>
       <origin rpy="0 0 0" xyz="0.8127913773456108 0 1.6232351048530274" />
     <axis xyz="1 0 0"/>
       <limit effort="0.0" lower="-3.14159" upper="3.14159" velocity="0.0"/>
    </joint>
    <joint name="Leg5_Leg6" type="revolute">
       <parent link="Leg5"/>
       <child  link="Leg6"/>
       <origin rpy="0 0 0" xyz="1.7139064663901098 0 0" />
     <axis xyz="1 0 0"/>
       <limit effort="0.0" lower="-3.14159" upper="3.14159" velocity="0.0"/>
    </joint>
    <joint name="Leg4_Leg7" type="revolute">
       <parent link="Leg4"/>
       <child  link="Leg7"/>
       <origin rpy="0 0 0" xyz="0.7946207572678335 1.2897379828493079 0" />
     <axis xyz="1 0 0"/>
       <limit effort="0.0" lower="-3.14159" upper="3.14159" velocity="0.0"/>
    </joint>
    <joint name="Torso_Leg8" type="revolute">
       <parent link="Torso"/>
       <child  link="Leg8"/>
       <origin rpy="0 0 0" xyz="1.0842408782976811 1.3837010192337178 1.3294033736815447" />
     <axis xyz="1 0 0"/>
       <limit effort="0.0" lower="-3.14159" upper="3.14159" velocity="0.0"/>
    </joint>
    <joint name="Leg1_Leg9" type="revolute">
       <parent link="Leg1"/>
       <child  link="Leg9"/>
       <origin rpy="0 0 0" xyz="2.3126160132907145 1.4523870395638447 0" />
     <axis xyz="1 0 0"/>
       <limit effort="0.0" lower="-3.14159" upper="3.14159" velocity="0.0"/>
    </joint>
    <joint name="Leg5_Leg10" type="revolute">
       <parent link="Leg5"/>
       <child  link="Leg10"/>
       <origin rpy="0 0 0" xyz="1.7139064663901098 1.4312546212784945 0" />
     <axis xyz="1 0 0"/>
       <limit effort="0.0" lower="-3.14159" upper="3.14159" velocity="0.0"/>
    </joint>
    <joint name="Leg2_Leg11" type="revolute">
       <parent link="Leg2"/>
       <child  link="Leg11"/>
       <origin rpy="0 0 0" xyz="0 0.6125801986383242 0.656433784714461" />
     <axis xyz="1 0 0"/>
       <limit effort="0.0" lower="-3.14159" upper="3.14159" velocity="0.0"/>
    </joint>
    <joint name="Leg10_Leg12" type="revolute">
       <parent link="Leg10"/>
       <child  link="Leg12"/>
       <origin rpy="0 0 0" xyz="0 1.25957656853507 1.104230291798196" />
     <axis xyz="1 0 0"/>
       <limit effort="0.0" lower="-3.14159" upper="3.14159" velocity="0.0"/>
    </joint>
    <joint name="Leg9_Leg13" type="revolute">
       <parent link="Leg9"/>
       <child  link="Leg13"/>
       <origin rpy="0 0 0" xyz="0 0.6605517958538498 1.0788583949662518" />
     <axis xyz="1 0 0"/>
       <limit effort="0.0" lower="-3.14159" upper="3.14159" velocity="0.0"/>
    </joint>
    <joint name="Leg12_Leg14" type="revolute">
       <parent link="Leg12"/>
       <child  link="Leg14"/>
       <origin rpy="0 0 0" xyz="0.8058152046053074 0 1.2283321370718308" />
     <axis xyz="1 0 0"/>
       <limit effort="0.0" lower="-3.14159" upper="3.14159" velocity="0.0"/>
    </joint>
    <joint name="Leg12_Leg15" type="revolute">
       <parent link="Leg12"/>
       <child  link="Leg15"/>
       <origin rpy="0 0 0" xyz="0.8058152046053074 0 2.4566642741436615" />
     <axis xyz="1 0 0"/>
       <limit effort="0.0" lower="-3.14159" upper="3.14159" velocity="0.0"/>
    </joint>
    <joint name="Leg7_Leg16" type="revolute">
       <parent link="Leg7"/>
       <child  link="Leg16"/>
       <origin rpy="0 0 0" xyz="1.236487762974719 0.8501294506618573 0" />
     <axis xyz="1 0 0"/>
       <limit effort="0.0" lower="-3.14159" upper="3.14159" velocity="0.0"/>
    </joint>
    <joint name="Leg16_Leg17" type="revolute">
       <parent link="Leg16"/>
       <child  link="Leg17"/>
       <origin rpy="0 0 0" xyz="0 0 2.6307668580111754" />
     <axis xyz="1 0 0"/>
       <limit effort="0.0" lower="-3.14159" upper="3.14159" velocity="0.0"/>
    </joint>
    <joint name="Leg10_Leg18" type="revolute">
       <parent link="Leg10"/>
       <child  link="Leg18"/>
       <origin rpy="0 0 0" xyz="0 2.51915313707014 1.104230291798196" />
     <axis xyz="1 0 0"/>
       <limit effort="0.0" lower="-3.14159" upper="3.14159" velocity="0.0"/>
    </joint>
    <joint name="Leg11_Leg19" type="revolute">
       <parent link="Leg11"/>
       <child  link="Leg19"/>
       <origin rpy="0 0 0" xyz="0 0.6865797632324032 0.6839787651529212" />
     <axis xyz="1 0 0"/>
       <limit effort="0.0" lower="-3.14159" upper="3.14159" velocity="0.0"/>
    </joint>
    <joint name="Leg9_Leg20" type="revolute">
       <parent link="Leg9"/>
       <child  link="Leg20"/>
       <origin rpy="0 0 0" xyz="0 1.3211035917076996 1.0788583949662518" />
     <axis xyz="1 0 0"/>
       <limit effort="0.0" lower="-3.14159" upper="3.14159" velocity="0.0"/>
    </joint>
    <joint name="Leg7_Leg21" type="revolute">
       <parent link="Leg7"/>
       <child  link="Leg21"/>
       <origin rpy="0 0 0" xyz="1.236487762974719 0.8501294506618573 0.9600354619275842" />
     <axis xyz="1 0 0"/>
       <limit effort="0.0" lower="-3.14159" upper="3.14159" velocity="0.0"/>
    </joint>
    <joint name="Leg20_Leg22" type="revolute">
       <parent link="Leg20"/>
       <child  link="Leg22"/>
       <origin rpy="0 0 0" xyz="0.7620777087225958 0 1.2395259681114388" />
     <axis xyz="1 0 0"/>
       <limit effort="0.0" lower="-3.14159" upper="3.14159" velocity="0.0"/>
    </joint>
    <joint name="Leg2_Leg23" type="revolute">
       <parent link="Leg2"/>
       <child  link="Leg23"/>
       <origin rpy="0 0 0" xyz="0 0.6125801986383242 1.312867569428922" />
     <axis xyz="1 0 0"/>
       <limit effort="0.0" lower="-3.14159" upper="3.14159" velocity="0.0"/>
    </joint>
    <joint name="Leg11_Leg24" type="revolute">
       <parent link="Leg11"/>
       <child  link="Leg24"/>
       <origin rpy="0 0 0" xyz="1.2080321944545362 0.6865797632324032 0.6839787651529212" />
     <axis xyz="1 0 0"/>
       <limit effort="0.0" lower="-3.14159" upper="3.14159" velocity="0.0"/>
    </joint>
    <joint name="Leg8_Leg25" type="revolute">
       <parent link="Leg8"/>
       <child  link="Leg25"/>
       <origin rpy="0 0 0" xyz="0 0.724046188097243 1.1524874685490483" />
     <axis xyz="1 0 0"/>
       <limit effort="0.0" lower="-3.14159" upper="3.14159" velocity="0.0"/>
    </joint>
</robot>