<robot name = "robot">
    <link name="Torso">
        <inertial>
            <origin xyz="0 0 1.1239873846067208" rpy="0 0 0"/>
            <mass value="1" />
            <inertia ixx="100" ixy="0" ixz="0" iyy="100" iyz="0" izz="100" />
        </inertial>
        <visual>
            <origin xyz="0 0 1.1239873846067208" rpy="0 0 0"/>
            <geometry>
                <box size="2.579692967138806 1.3443878800240376 2.2479747692134415" />
            </geometry>
            <material name="Green">
                <color rgba="0 180.0 0.0 1.0"/>
            </material>
        </visual>
        <collision>
            <origin xyz="0 0 1.1239873846067208" rpy="0 0 0"/>
            <geometry>
                <box size="2.579692967138806 1.3443878800240376 2.2479747692134415" />
            </geometry>
        </collision>
    </link>
    <link name="Leg1">
        <inertial>
            <origin xyz="0 0 0.6284543491505544" rpy="0 0 0"/>
            <mass value="1" />
            <inertia ixx="100" ixy="0" ixz="0" iyy="100" iyz="0" izz="100" />
        </inertial>
        <visual>
            <origin xyz="0 0 0.6284543491505544" rpy="0 0 0"/>
            <geometry>
                <box size="1.9271047207611258 1.479657512573226 1.2569086983011089" />
            </geometry>
            <material name="Blue">
                <color rgba="0 1.0 1.0 1.0"/>
            </material>
        </visual>
        <collision>
            <origin xyz="0 0 0.6284543491505544" rpy="0 0 0"/>
            <geometry>
                <box size="1.9271047207611258 1.479657512573226 1.2569086983011089" />
            </geometry>
        </collision>
    </link>
    <link name="Leg2">
        <inertial>
            <origin xyz="0 0.5668999471748265 0" rpy="0 0 0"/>
            <mass value="1" />
            <inertia ixx="100" ixy="0" ixz="0" iyy="100" iyz="0" izz="100" />
        </inertial>
        <visual>
            <origin xyz="0 0.5668999471748265 0" rpy="0 0 0"/>
            <geometry>
                <box size="2.298471175970362 1.133799894349653 2.5640419290732552" />
            </geometry>
            <material name="Green">
                <color rgba="0 180.0 0.0 1.0"/>
            </material>
        </visual>
        <collision>
            <origin xyz="0 0.5668999471748265 0" rpy="0 0 0"/>
            <geometry>
                <box size="2.298471175970362 1.133799894349653 2.5640419290732552" />
            </geometry>
        </collision>
    </link>
    <link name="Leg3">
        <inertial>
            <origin xyz="0 0 0.5720849623740578" rpy="0 0 0"/>
            <mass value="1" />
            <inertia ixx="100" ixy="0" ixz="0" iyy="100" iyz="0" izz="100" />
        </inertial>
        <visual>
            <origin xyz="0 0 0.5720849623740578" rpy="0 0 0"/>
            <geometry>
                <box size="1.328993305740591 1.077912795303257 1.1441699247481156" />
            </geometry>
            <material name="Blue">
                <color rgba="0 1.0 1.0 1.0"/>
            </material>
        </visual>
        <collision>
            <origin xyz="0 0 0.5720849623740578" rpy="0 0 0"/>
            <geometry>
                <box size="1.328993305740591 1.077912795303257 1.1441699247481156" />
            </geometry>
        </collision>
    </link>
    <link name="Leg4">
        <inertial>
            <origin xyz="1.2744057157732558 0 0" rpy="0 0 0"/>
            <mass value="1" />
            <inertia ixx="100" ixy="0" ixz="0" iyy="100" iyz="0" izz="100" />
        </inertial>
        <visual>
            <origin xyz="1.2744057157732558 0 0" rpy="0 0 0"/>
            <geometry>
                <box size="2.5488114315465116 1.7457179863891286 2.108365436324879" />
            </geometry>
            <material name="Blue">
                <color rgba="0 1.0 1.0 1.0"/>
            </material>
        </visual>
        <collision>
            <origin xyz="1.2744057157732558 0 0" rpy="0 0 0"/>
            <geometry>
                <box size="2.5488114315465116 1.7457179863891286 2.108365436324879" />
            </geometry>
        </collision>
    </link>
    <link name="Leg5">
        <inertial>
            <origin xyz="0 0 0.7918831528908217" rpy="0 0 0"/>
            <mass value="1" />
            <inertia ixx="100" ixy="0" ixz="0" iyy="100" iyz="0" izz="100" />
        </inertial>
        <visual>
            <origin xyz="0 0 0.7918831528908217" rpy="0 0 0"/>
            <geometry>
                <box size="2.030503283332432 2.1176274034722966 1.5837663057816433" />
            </geometry>
            <material name="Green">
                <color rgba="0 180.0 0.0 1.0"/>
            </material>
        </visual>
        <collision>
            <origin xyz="0 0 0.7918831528908217" rpy="0 0 0"/>
            <geometry>
                <box size="2.030503283332432 2.1176274034722966 1.5837663057816433" />
            </geometry>
        </collision>
    </link>
    <link name="Leg6">
        <inertial>
            <origin xyz="0 0 1.3990576796814618" rpy="0 0 0"/>
            <mass value="1" />
            <inertia ixx="100" ixy="0" ixz="0" iyy="100" iyz="0" izz="100" />
        </inertial>
        <visual>
            <origin xyz="0 0 1.3990576796814618" rpy="0 0 0"/>
            <geometry>
                <box size="2.814351055474294 2.351967139642112 2.7981153593629235" />
            </geometry>
            <material name="Blue">
                <color rgba="0 1.0 1.0 1.0"/>
            </material>
        </visual>
        <collision>
            <origin xyz="0 0 1.3990576796814618" rpy="0 0 0"/>
            <geometry>
                <box size="2.814351055474294 2.351967139642112 2.7981153593629235" />
            </geometry>
        </collision>
    </link>
    <link name="Leg7">
        <inertial>
            <origin xyz="0 0 0.83475710460095" rpy="0 0 0"/>
            <mass value="1" />
            <inertia ixx="100" ixy="0" ixz="0" iyy="100" iyz="0" izz="100" />
        </inertial>
        <visual>
            <origin xyz="0 0 0.83475710460095" rpy="0 0 0"/>
            <geometry>
                <box size="1.8225881058364302 2.4783192095230673 1.6695142092019" />
            </geometry>
            <material name="Green">
                <color rgba="0 180.0 0.0 1.0"/>
            </material>
        </visual>
        <collision>
            <origin xyz="0 0 0.83475710460095" rpy="0 0 0"/>
            <geometry>
                <box size="1.8225881058364302 2.4783192095230673 1.6695142092019" />
            </geometry>
        </collision>
    </link>
    <link name="Leg8">
        <inertial>
            <origin xyz="0 0 1.043820946066953" rpy="0 0 0"/>
            <mass value="1" />
            <inertia ixx="100" ixy="0" ixz="0" iyy="100" iyz="0" izz="100" />
        </inertial>
        <visual>
            <origin xyz="0 0 1.043820946066953" rpy="0 0 0"/>
            <geometry>
                <box size="1.2340020552872264 2.832584043369732 2.087641892133906" />
            </geometry>
            <material name="Blue">
                <color rgba="0 1.0 1.0 1.0"/>
            </material>
        </visual>
        <collision>
            <origin xyz="0 0 1.043820946066953" rpy="0 0 0"/>
            <geometry>
                <box size="1.2340020552872264 2.832584043369732 2.087641892133906" />
            </geometry>
        </collision>
    </link>
    <link name="Leg9">
        <inertial>
            <origin xyz="0 0 0.520468633703484" rpy="0 0 0"/>
            <mass value="1" />
            <inertia ixx="100" ixy="0" ixz="0" iyy="100" iyz="0" izz="100" />
        </inertial>
        <visual>
            <origin xyz="0 0 0.520468633703484" rpy="0 0 0"/>
            <geometry>
                <box size="2.276343414554602 1.6453356166504196 1.040937267406968" />
            </geometry>
            <material name="Green">
                <color rgba="0 180.0 0.0 1.0"/>
            </material>
        </visual>
        <collision>
            <origin xyz="0 0 0.520468633703484" rpy="0 0 0"/>
            <geometry>
                <box size="2.276343414554602 1.6453356166504196 1.040937267406968" />
            </geometry>
        </collision>
    </link>
    <link name="Leg10">
        <inertial>
            <origin xyz="1.3520164332054514 0 0" rpy="0 0 0"/>
            <mass value="1" />
            <inertia ixx="100" ixy="0" ixz="0" iyy="100" iyz="0" izz="100" />
        </inertial>
        <visual>
            <origin xyz="1.3520164332054514 0 0" rpy="0 0 0"/>
            <geometry>
                <box size="2.704032866410903 2.314904887200602 2.461999790194354" />
            </geometry>
            <material name="Blue">
                <color rgba="0 1.0 1.0 1.0"/>
            </material>
        </visual>
        <collision>
            <origin xyz="1.3520164332054514 0 0" rpy="0 0 0"/>
            <geometry>
                <box size="2.704032866410903 2.314904887200602 2.461999790194354" />
            </geometry>
        </collision>
    </link>
    <link name="Leg11">
        <inertial>
            <origin xyz="0 0 0.9397486688749916" rpy="0 0 0"/>
            <mass value="1" />
            <inertia ixx="100" ixy="0" ixz="0" iyy="100" iyz="0" izz="100" />
        </inertial>
        <visual>
            <origin xyz="0 0 0.9397486688749916" rpy="0 0 0"/>
            <geometry>
                <box size="1.4036193452713785 2.2242116316166207 1.8794973377499833" />
            </geometry>
            <material name="Green">
                <color rgba="0 180.0 0.0 1.0"/>
            </material>
        </visual>
        <collision>
            <origin xyz="0 0 0.9397486688749916" rpy="0 0 0"/>
            <geometry>
                <box size="1.4036193452713785 2.2242116316166207 1.8794973377499833" />
            </geometry>
        </collision>
    </link>
    <link name="Leg12">
        <inertial>
            <origin xyz="0 0 1.2284282073310928" rpy="0 0 0"/>
            <mass value="1" />
            <inertia ixx="100" ixy="0" ixz="0" iyy="100" iyz="0" izz="100" />
        </inertial>
        <visual>
            <origin xyz="0 0 1.2284282073310928" rpy="0 0 0"/>
            <geometry>
                <box size="2.5814787746503844 1.3036815334559484 2.4568564146621856" />
            </geometry>
            <material name="Blue">
                <color rgba="0 1.0 1.0 1.0"/>
            </material>
        </visual>
        <collision>
            <origin xyz="0 0 1.2284282073310928" rpy="0 0 0"/>
            <geometry>
                <box size="2.5814787746503844 1.3036815334559484 2.4568564146621856" />
            </geometry>
        </collision>
    </link>
    <link name="Leg13">
        <inertial>
            <origin xyz="0 0 0.9325672210749034" rpy="0 0 0"/>
            <mass value="1" />
            <inertia ixx="100" ixy="0" ixz="0" iyy="100" iyz="0" izz="100" />
        </inertial>
        <visual>
            <origin xyz="0 0 0.9325672210749034" rpy="0 0 0"/>
            <geometry>
                <box size="1.5687679577939004 1.1076513733314333 1.8651344421498068" />
            </geometry>
            <material name="Blue">
                <color rgba="0 1.0 1.0 1.0"/>
            </material>
        </visual>
        <collision>
            <origin xyz="0 0 0.9325672210749034" rpy="0 0 0"/>
            <geometry>
                <box size="1.5687679577939004 1.1076513733314333 1.8651344421498068" />
            </geometry>
        </collision>
    </link>
    <link name="Leg14">
        <inertial>
            <origin xyz="0 0 0.7192574547894872" rpy="0 0 0"/>
            <mass value="1" />
            <inertia ixx="100" ixy="0" ixz="0" iyy="100" iyz="0" izz="100" />
        </inertial>
        <visual>
            <origin xyz="0 0 0.7192574547894872" rpy="0 0 0"/>
            <geometry>
                <box size="1.3826663943370237 2.2308107787552327 1.4385149095789744" />
            </geometry>
            <material name="Blue">
                <color rgba="0 1.0 1.0 1.0"/>
            </material>
        </visual>
        <collision>
            <origin xyz="0 0 0.7192574547894872" rpy="0 0 0"/>
            <geometry>
                <box size="1.3826663943370237 2.2308107787552327 1.4385149095789744" />
            </geometry>
        </collision>
    </link>
    <link name="Leg15">
        <inertial>
            <origin xyz="1.4752455859115752 0 0" rpy="0 0 0"/>
            <mass value="1" />
            <inertia ixx="100" ixy="0" ixz="0" iyy="100" iyz="0" izz="100" />
        </inertial>
        <visual>
            <origin xyz="1.4752455859115752 0 0" rpy="0 0 0"/>
            <geometry>
                <box size="2.9504911718231503 2.7869936943186637 2.2834018893799075" />
            </geometry>
            <material name="Green">
                <color rgba="0 180.0 0.0 1.0"/>
            </material>
        </visual>
        <collision>
            <origin xyz="1.4752455859115752 0 0" rpy="0 0 0"/>
            <geometry>
                <box size="2.9504911718231503 2.7869936943186637 2.2834018893799075" />
            </geometry>
        </collision>
    </link>
    <link name="Leg16">
        <inertial>
            <origin xyz="0 0 1.2739764485092144" rpy="0 0 0"/>
            <mass value="1" />
            <inertia ixx="100" ixy="0" ixz="0" iyy="100" iyz="0" izz="100" />
        </inertial>
        <visual>
            <origin xyz="0 0 1.2739764485092144" rpy="0 0 0"/>
            <geometry>
                <box size="2.4594569655311185 1.1967928948315072 2.547952897018429" />
            </geometry>
            <material name="Blue">
                <color rgba="0 1.0 1.0 1.0"/>
            </material>
        </visual>
        <collision>
            <origin xyz="0 0 1.2739764485092144" rpy="0 0 0"/>
            <geometry>
                <box size="2.4594569655311185 1.1967928948315072 2.547952897018429" />
            </geometry>
        </collision>
    </link>
    <link name="Leg17">
        <inertial>
            <origin xyz="0 0.8788070583429717 0" rpy="0 0 0"/>
            <mass value="1" />
            <inertia ixx="100" ixy="0" ixz="0" iyy="100" iyz="0" izz="100" />
        </inertial>
        <visual>
            <origin xyz="0 0.8788070583429717 0" rpy="0 0 0"/>
            <geometry>
                <box size="1.1406881745217032 1.7576141166859434 2.282144658589739" />
            </geometry>
            <material name="Green">
                <color rgba="0 180.0 0.0 1.0"/>
            </material>
        </visual>
        <collision>
            <origin xyz="0 0.8788070583429717 0" rpy="0 0 0"/>
            <geometry>
                <box size="1.1406881745217032 1.7576141166859434 2.282144658589739" />
            </geometry>
        </collision>
    </link>
    <link name="Leg18">
        <inertial>
            <origin xyz="0 0 0.9316000680627726" rpy="0 0 0"/>
            <mass value="1" />
            <inertia ixx="100" ixy="0" ixz="0" iyy="100" iyz="0" izz="100" />
        </inertial>
        <visual>
            <origin xyz="0 0 0.9316000680627726" rpy="0 0 0"/>
            <geometry>
                <box size="1.358013344514829 1.6940613409403193 1.8632001361255452" />
            </geometry>
            <material name="Green">
                <color rgba="0 180.0 0.0 1.0"/>
            </material>
        </visual>
        <collision>
            <origin xyz="0 0 0.9316000680627726" rpy="0 0 0"/>
            <geometry>
                <box size="1.358013344514829 1.6940613409403193 1.8632001361255452" />
            </geometry>
        </collision>
    </link>
    <link name="Leg19">
        <inertial>
            <origin xyz="0.784248922691868 0 0" rpy="0 0 0"/>
            <mass value="1" />
            <inertia ixx="100" ixy="0" ixz="0" iyy="100" iyz="0" izz="100" />
        </inertial>
        <visual>
            <origin xyz="0.784248922691868 0 0" rpy="0 0 0"/>
            <geometry>
                <box size="1.568497845383736 2.9384282191938023 2.287864413865343" />
            </geometry>
            <material name="Green">
                <color rgba="0 180.0 0.0 1.0"/>
            </material>
        </visual>
        <collision>
            <origin xyz="0.784248922691868 0 0" rpy="0 0 0"/>
            <geometry>
                <box size="1.568497845383736 2.9384282191938023 2.287864413865343" />
            </geometry>
        </collision>
    </link>
    <link name="Leg20">
        <inertial>
            <origin xyz="0 0 1.098063186352594" rpy="0 0 0"/>
            <mass value="1" />
            <inertia ixx="100" ixy="0" ixz="0" iyy="100" iyz="0" izz="100" />
        </inertial>
        <visual>
            <origin xyz="0 0 1.098063186352594" rpy="0 0 0"/>
            <geometry>
                <box size="2.929031926934214 2.1062306699170392 2.196126372705188" />
            </geometry>
            <material name="Blue">
                <color rgba="0 1.0 1.0 1.0"/>
            </material>
        </visual>
        <collision>
            <origin xyz="0 0 1.098063186352594" rpy="0 0 0"/>
            <geometry>
                <box size="2.929031926934214 2.1062306699170392 2.196126372705188" />
            </geometry>
        </collision>
    </link>
    <link name="Leg21">
        <inertial>
            <origin xyz="0 0 1.4539765347988127" rpy="0 0 0"/>
            <mass value="1" />
            <inertia ixx="100" ixy="0" ixz="0" iyy="100" iyz="0" izz="100" />
        </inertial>
        <visual>
            <origin xyz="0 0 1.4539765347988127" rpy="0 0 0"/>
            <geometry>
                <box size="1.5569301804399953 2.445298215656802 2.9079530695976255" />
            </geometry>
            <material name="Green">
                <color rgba="0 180.0 0.0 1.0"/>
            </material>
        </visual>
        <collision>
            <origin xyz="0 0 1.4539765347988127" rpy="0 0 0"/>
            <geometry>
                <box size="1.5569301804399953 2.445298215656802 2.9079530695976255" />
            </geometry>
        </collision>
    </link>
    <link name="Leg22">
        <inertial>
            <origin xyz="0 0 1.2614147270021203" rpy="0 0 0"/>
            <mass value="1" />
            <inertia ixx="100" ixy="0" ixz="0" iyy="100" iyz="0" izz="100" />
        </inertial>
        <visual>
            <origin xyz="0 0 1.2614147270021203" rpy="0 0 0"/>
            <geometry>
                <box size="1.5277596639793203 1.8071810687473624 2.5228294540042406" />
            </geometry>
            <material name="Blue">
                <color rgba="0 1.0 1.0 1.0"/>
            </material>
        </visual>
        <collision>
            <origin xyz="0 0 1.2614147270021203" rpy="0 0 0"/>
            <geometry>
                <box size="1.5277596639793203 1.8071810687473624 2.5228294540042406" />
            </geometry>
        </collision>
    </link>
    <link name="Leg23">
        <inertial>
            <origin xyz="0 0.6730982618794755 0" rpy="0 0 0"/>
            <mass value="1" />
            <inertia ixx="100" ixy="0" ixz="0" iyy="100" iyz="0" izz="100" />
        </inertial>
        <visual>
            <origin xyz="0 0.6730982618794755 0" rpy="0 0 0"/>
            <geometry>
                <box size="2.90429941398593 1.346196523758951 1.0465048541839668" />
            </geometry>
            <material name="Blue">
                <color rgba="0 1.0 1.0 1.0"/>
            </material>
        </visual>
        <collision>
            <origin xyz="0 0.6730982618794755 0" rpy="0 0 0"/>
            <geometry>
                <box size="2.90429941398593 1.346196523758951 1.0465048541839668" />
            </geometry>
        </collision>
    </link>
    <link name="Leg24">
        <inertial>
            <origin xyz="0.7696745555311685 0 0" rpy="0 0 0"/>
            <mass value="1" />
            <inertia ixx="100" ixy="0" ixz="0" iyy="100" iyz="0" izz="100" />
        </inertial>
        <visual>
            <origin xyz="0.7696745555311685 0 0" rpy="0 0 0"/>
            <geometry>
                <box size="1.539349111062337 1.121089495712957 1.9794642462345877" />
            </geometry>
            <material name="Blue">
                <color rgba="0 1.0 1.0 1.0"/>
            </material>
        </visual>
        <collision>
            <origin xyz="0.7696745555311685 0 0" rpy="0 0 0"/>
            <geometry>
                <box size="1.539349111062337 1.121089495712957 1.9794642462345877" />
            </geometry>
        </collision>
    </link>
    <link name="Leg25">
        <inertial>
            <origin xyz="0 0 0.7409015535109855" rpy="0 0 0"/>
            <mass value="1" />
            <inertia ixx="100" ixy="0" ixz="0" iyy="100" iyz="0" izz="100" />
        </inertial>
        <visual>
            <origin xyz="0 0 0.7409015535109855" rpy="0 0 0"/>
            <geometry>
                <box size="2.340877833290068 2.655912026433777 1.481803107021971" />
            </geometry>
            <material name="Blue">
                <color rgba="0 1.0 1.0 1.0"/>
            </material>
        </visual>
        <collision>
            <origin xyz="0 0 0.7409015535109855" rpy="0 0 0"/>
            <geometry>
                <box size="2.340877833290068 2.655912026433777 1.481803107021971" />
            </geometry>
        </collision>
    </link>
    <link name="Leg26">
        <inertial>
            <origin xyz="0 0.6550746518971815 0" rpy="0 0 0"/>
            <mass value="1" />
            <inertia ixx="100" ixy="0" ixz="0" iyy="100" iyz="0" izz="100" />
        </inertial>
        <visual>
            <origin xyz="0 0.6550746518971815 0" rpy="0 0 0"/>
            <geometry>
                <box size="2.571424825020313 1.310149303794363 2.9919882478795627" />
            </geometry>
            <material name="Green">
                <color rgba="0 180.0 0.0 1.0"/>
            </material>
        </visual>
        <collision>
            <origin xyz="0 0.6550746518971815 0" rpy="0 0 0"/>
            <geometry>
                <box size="2.571424825020313 1.310149303794363 2.9919882478795627" />
            </geometry>
        </collision>
    </link>
    <joint name="Torso_Leg1" type="revolute">
       <parent link="Torso"/>
       <child  link="Leg1"/>
       <origin rpy="0 0 0" xyz="0 0 2.2479747692134415" />
     <axis xyz="1 0 0"/>
       <limit effort="0.0" lower="-3.14159" upper="3.14159" velocity="0.0"/>
    </joint>
    <joint name="Leg1_Leg2" type="revolute">
       <parent link="Leg1"/>
       <child  link="Leg2"/>
       <origin rpy="0 0 0" xyz="0 1.133799894349653 0" />
     <axis xyz="1 0 0"/>
       <limit effort="0.0" lower="-3.14159" upper="3.14159" velocity="0.0"/>
    </joint>
    <joint name="Leg2_Leg3" type="revolute">
       <parent link="Leg2"/>
       <child  link="Leg3"/>
       <origin rpy="0 0 0" xyz="0 0 1.1441699247481156" />
     <axis xyz="1 0 0"/>
       <limit effort="0.0" lower="-3.14159" upper="3.14159" velocity="0.0"/>
    </joint>
    <joint name="Leg2_Leg4" type="revolute">
       <parent link="Leg2"/>
       <child  link="Leg4"/>
       <origin rpy="0 0 0" xyz="0.6644966528702955 0 1.1441699247481156" />
     <axis xyz="1 0 0"/>
       <limit effort="0.0" lower="-3.14159" upper="3.14159" velocity="0.0"/>
    </joint>
    <joint name="Leg1_Leg5" type="revolute">
       <parent link="Leg1"/>
       <child  link="Leg5"/>
       <origin rpy="0 0 0" xyz="0 1.133799894349653 1.2820209645366276" />
     <axis xyz="1 0 0"/>
       <limit effort="0.0" lower="-3.14159" upper="3.14159" velocity="0.0"/>
    </joint>
    <joint name="Leg4_Leg6" type="revolute">
       <parent link="Leg4"/>
       <child  link="Leg6"/>
       <origin rpy="0 0 0" xyz="0 0 1.5837663057816433" />
     <axis xyz="1 0 0"/>
       <limit effort="0.0" lower="-3.14159" upper="3.14159" velocity="0.0"/>
    </joint>
    <joint name="Leg6_Leg7" type="revolute">
       <parent link="Leg6"/>
       <child  link="Leg7"/>
       <origin rpy="0 0 0" xyz="0 0 1.6695142092019" />
     <axis xyz="1 0 0"/>
       <limit effort="0.0" lower="-3.14159" upper="3.14159" velocity="0.0"/>
    </joint>
    <joint name="Leg5_Leg8" type="revolute">
       <parent link="Leg5"/>
       <child  link="Leg8"/>
       <origin rpy="0 0 0" xyz="0 0 2.7981153593629235" />
     <axis xyz="1 0 0"/>
       <limit effort="0.0" lower="-3.14159" upper="3.14159" velocity="0.0"/>
    </joint>
    <joint name="Leg8_Leg9" type="revolute">
       <parent link="Leg8"/>
       <child  link="Leg9"/>
       <origin rpy="0 0 0" xyz="0 0 1.040937267406968" />
     <axis xyz="1 0 0"/>
       <limit effort="0.0" lower="-3.14159" upper="3.14159" velocity="0.0"/>
    </joint>
    <joint name="Leg3_Leg10" type="revolute">
       <parent link="Leg3"/>
       <child  link="Leg10"/>
       <origin rpy="0 0 0" xyz="2.5488114315465116 0 0" />
     <axis xyz="1 0 0"/>
       <limit effort="0.0" lower="-3.14159" upper="3.14159" velocity="0.0"/>
    </joint>
    <joint name="Leg10_Leg11" type="revolute">
       <parent link="Leg10"/>
       <child  link="Leg11"/>
       <origin rpy="0 0 0" xyz="0 0 1.8794973377499833" />
     <axis xyz="1 0 0"/>
       <limit effort="0.0" lower="-3.14159" upper="3.14159" velocity="0.0"/>
    </joint>
    <joint name="Leg9_Leg12" type="revolute">
       <parent link="Leg9"/>
       <child  link="Leg12"/>
       <origin rpy="0 0 0" xyz="1.3520164332054514 0 1.230999895097177" />
     <axis xyz="1 0 0"/>
       <limit effort="0.0" lower="-3.14159" upper="3.14159" velocity="0.0"/>
    </joint>
    <joint name="Leg11_Leg13" type="revolute">
       <parent link="Leg11"/>
       <child  link="Leg13"/>
       <origin rpy="0 0 0" xyz="0 0 2.4568564146621856" />
     <axis xyz="1 0 0"/>
       <limit effort="0.0" lower="-3.14159" upper="3.14159" velocity="0.0"/>
    </joint>
    <joint name="Leg12_Leg14" type="revolute">
       <parent link="Leg12"/>
       <child  link="Leg14"/>
       <origin rpy="0 0 0" xyz="0 0 1.8651344421498068" />
     <axis xyz="1 0 0"/>
       <limit effort="0.0" lower="-3.14159" upper="3.14159" velocity="0.0"/>
    </joint>
    <joint name="Leg9_Leg15" type="revolute">
       <parent link="Leg9"/>
       <child  link="Leg15"/>
       <origin rpy="0 0 0" xyz="2.704032866410903 0 1.230999895097177" />
     <axis xyz="1 0 0"/>
       <limit effort="0.0" lower="-3.14159" upper="3.14159" velocity="0.0"/>
    </joint>
    <joint name="Leg15_Leg16" type="revolute">
       <parent link="Leg15"/>
       <child  link="Leg16"/>
       <origin rpy="0 0 0" xyz="0 0 2.547952897018429" />
     <axis xyz="1 0 0"/>
       <limit effort="0.0" lower="-3.14159" upper="3.14159" velocity="0.0"/>
    </joint>
    <joint name="Leg9_Leg17" type="revolute">
       <parent link="Leg9"/>
       <child  link="Leg17"/>
       <origin rpy="0 0 0" xyz="2.704032866410903 1.157452443600301 1.230999895097177" />
     <axis xyz="1 0 0"/>
       <limit effort="0.0" lower="-3.14159" upper="3.14159" velocity="0.0"/>
    </joint>
    <joint name="Leg7_Leg18" type="revolute">
       <parent link="Leg7"/>
       <child  link="Leg18"/>
       <origin rpy="0 0 0" xyz="0 0 2.087641892133906" />
     <axis xyz="1 0 0"/>
       <limit effort="0.0" lower="-3.14159" upper="3.14159" velocity="0.0"/>
    </joint>
    <joint name="Leg6_Leg19" type="revolute">
       <parent link="Leg6"/>
       <child  link="Leg19"/>
       <origin rpy="0 0 0" xyz="0.9112940529182151 0 1.6695142092019" />
     <axis xyz="1 0 0"/>
       <limit effort="0.0" lower="-3.14159" upper="3.14159" velocity="0.0"/>
    </joint>
    <joint name="Leg13_Leg20" type="revolute">
       <parent link="Leg13"/>
       <child  link="Leg20"/>
       <origin rpy="0 0 0" xyz="0 0 1.4385149095789744" />
     <axis xyz="1 0 0"/>
       <limit effort="0.0" lower="-3.14159" upper="3.14159" velocity="0.0"/>
    </joint>
    <joint name="Leg19_Leg21" type="revolute">
       <parent link="Leg19"/>
       <child  link="Leg21"/>
       <origin rpy="0 0 0" xyz="0 0 2.196126372705188" />
     <axis xyz="1 0 0"/>
       <limit effort="0.0" lower="-3.14159" upper="3.14159" velocity="0.0"/>
    </joint>
    <joint name="Leg20_Leg22" type="revolute">
       <parent link="Leg20"/>
       <child  link="Leg22"/>
       <origin rpy="0 0 0" xyz="0 0 2.9079530695976255" />
     <axis xyz="1 0 0"/>
       <limit effort="0.0" lower="-3.14159" upper="3.14159" velocity="0.0"/>
    </joint>
    <joint name="Leg20_Leg23" type="revolute">
       <parent link="Leg20"/>
       <child  link="Leg23"/>
       <origin rpy="0 0 0" xyz="0 1.222649107828401 2.9079530695976255" />
     <axis xyz="1 0 0"/>
       <limit effort="0.0" lower="-3.14159" upper="3.14159" velocity="0.0"/>
    </joint>
    <joint name="Leg7_Leg24" type="revolute">
       <parent link="Leg7"/>
       <child  link="Leg24"/>
       <origin rpy="0 0 0" xyz="0.6170010276436132 0 2.087641892133906" />
     <axis xyz="1 0 0"/>
       <limit effort="0.0" lower="-3.14159" upper="3.14159" velocity="0.0"/>
    </joint>
    <joint name="Leg16_Leg25" type="revolute">
       <parent link="Leg16"/>
       <child  link="Leg25"/>
       <origin rpy="0 0 0" xyz="0 0.8788070583429717 1.1410723292948695" />
     <axis xyz="1 0 0"/>
       <limit effort="0.0" lower="-3.14159" upper="3.14159" velocity="0.0"/>
    </joint>
    <joint name="Leg2_Leg26" type="revolute">
       <parent link="Leg2"/>
       <child  link="Leg26"/>
       <origin rpy="0 0 0" xyz="0.6644966528702955 0.5389563976516285 1.1441699247481156" />
     <axis xyz="1 0 0"/>
       <limit effort="0.0" lower="-3.14159" upper="3.14159" velocity="0.0"/>
    </joint>
</robot>