<robot name = "robot">
    <link name="Torso">
        <inertial>
            <origin xyz="0 0 1.2797544236939764" rpy="0 0 0"/>
            <mass value="1" />
            <inertia ixx="100" ixy="0" ixz="0" iyy="100" iyz="0" izz="100" />
        </inertial>
        <visual>
            <origin xyz="0 0 1.2797544236939764" rpy="0 0 0"/>
            <geometry>
                <box size="1.6601349661298248 1.446221217806661 2.559508847387953" />
            </geometry>
            <material name="Green">
                <color rgba="0 180.0 0.0 1.0"/>
            </material>
        </visual>
        <collision>
            <origin xyz="0 0 1.2797544236939764" rpy="0 0 0"/>
            <geometry>
                <box size="1.6601349661298248 1.446221217806661 2.559508847387953" />
            </geometry>
        </collision>
    </link>
    <link name="Leg1">
        <inertial>
            <origin xyz="0 0.6112441743296918 0" rpy="0 0 0"/>
            <mass value="1" />
            <inertia ixx="100" ixy="0" ixz="0" iyy="100" iyz="0" izz="100" />
        </inertial>
        <visual>
            <origin xyz="0 0.6112441743296918 0" rpy="0 0 0"/>
            <geometry>
                <box size="2.845578863264664 1.2224883486593836 1.3268528122864214" />
            </geometry>
            <material name="Blue">
                <color rgba="0 1.0 1.0 1.0"/>
            </material>
        </visual>
        <collision>
            <origin xyz="0 0.6112441743296918 0" rpy="0 0 0"/>
            <geometry>
                <box size="2.845578863264664 1.2224883486593836 1.3268528122864214" />
            </geometry>
        </collision>
    </link>
    <link name="Leg2">
        <inertial>
            <origin xyz="0.6634327526064179 0 0" rpy="0 0 0"/>
            <mass value="1" />
            <inertia ixx="100" ixy="0" ixz="0" iyy="100" iyz="0" izz="100" />
        </inertial>
        <visual>
            <origin xyz="0.6634327526064179 0 0" rpy="0 0 0"/>
            <geometry>
                <box size="1.3268655052128357 2.412468682690661 1.8892789645777042" />
            </geometry>
            <material name="Green">
                <color rgba="0 180.0 0.0 1.0"/>
            </material>
        </visual>
        <collision>
            <origin xyz="0.6634327526064179 0 0" rpy="0 0 0"/>
            <geometry>
                <box size="1.3268655052128357 2.412468682690661 1.8892789645777042" />
            </geometry>
        </collision>
    </link>
    <link name="Leg3">
        <inertial>
            <origin xyz="0 0.6282896758427894 0" rpy="0 0 0"/>
            <mass value="1" />
            <inertia ixx="100" ixy="0" ixz="0" iyy="100" iyz="0" izz="100" />
        </inertial>
        <visual>
            <origin xyz="0 0.6282896758427894 0" rpy="0 0 0"/>
            <geometry>
                <box size="2.3898911701821284 1.2565793516855788 2.5035895664784684" />
            </geometry>
            <material name="Blue">
                <color rgba="0 1.0 1.0 1.0"/>
            </material>
        </visual>
        <collision>
            <origin xyz="0 0.6282896758427894 0" rpy="0 0 0"/>
            <geometry>
                <box size="2.3898911701821284 1.2565793516855788 2.5035895664784684" />
            </geometry>
        </collision>
    </link>
    <link name="Leg4">
        <inertial>
            <origin xyz="1.18374566972598 0 0" rpy="0 0 0"/>
            <mass value="1" />
            <inertia ixx="100" ixy="0" ixz="0" iyy="100" iyz="0" izz="100" />
        </inertial>
        <visual>
            <origin xyz="1.18374566972598 0 0" rpy="0 0 0"/>
            <geometry>
                <box size="2.36749133945196 2.430880591192573 2.511899179062544" />
            </geometry>
            <material name="Blue">
                <color rgba="0 1.0 1.0 1.0"/>
            </material>
        </visual>
        <collision>
            <origin xyz="1.18374566972598 0 0" rpy="0 0 0"/>
            <geometry>
                <box size="2.36749133945196 2.430880591192573 2.511899179062544" />
            </geometry>
        </collision>
    </link>
    <link name="Leg5">
        <inertial>
            <origin xyz="0 0 1.0718532446487439" rpy="0 0 0"/>
            <mass value="1" />
            <inertia ixx="100" ixy="0" ixz="0" iyy="100" iyz="0" izz="100" />
        </inertial>
        <visual>
            <origin xyz="0 0 1.0718532446487439" rpy="0 0 0"/>
            <geometry>
                <box size="1.365147540111929 1.432579863836209 2.1437064892974877" />
            </geometry>
            <material name="Green">
                <color rgba="0 180.0 0.0 1.0"/>
            </material>
        </visual>
        <collision>
            <origin xyz="0 0 1.0718532446487439" rpy="0 0 0"/>
            <geometry>
                <box size="1.365147540111929 1.432579863836209 2.1437064892974877" />
            </geometry>
        </collision>
    </link>
    <link name="Leg6">
        <inertial>
            <origin xyz="1.3636553105914433 0 0" rpy="0 0 0"/>
            <mass value="1" />
            <inertia ixx="100" ixy="0" ixz="0" iyy="100" iyz="0" izz="100" />
        </inertial>
        <visual>
            <origin xyz="1.3636553105914433 0 0" rpy="0 0 0"/>
            <geometry>
                <box size="2.7273106211828866 2.115885590114623 1.367542492502517" />
            </geometry>
            <material name="Blue">
                <color rgba="0 1.0 1.0 1.0"/>
            </material>
        </visual>
        <collision>
            <origin xyz="1.3636553105914433 0 0" rpy="0 0 0"/>
            <geometry>
                <box size="2.7273106211828866 2.115885590114623 1.367542492502517" />
            </geometry>
        </collision>
    </link>
    <link name="Leg7">
        <inertial>
            <origin xyz="0 0 1.123745669075628" rpy="0 0 0"/>
            <mass value="1" />
            <inertia ixx="100" ixy="0" ixz="0" iyy="100" iyz="0" izz="100" />
        </inertial>
        <visual>
            <origin xyz="0 0 1.123745669075628" rpy="0 0 0"/>
            <geometry>
                <box size="1.178993027469521 1.3025855779294586 2.247491338151256" />
            </geometry>
            <material name="Green">
                <color rgba="0 180.0 0.0 1.0"/>
            </material>
        </visual>
        <collision>
            <origin xyz="0 0 1.123745669075628" rpy="0 0 0"/>
            <geometry>
                <box size="1.178993027469521 1.3025855779294586 2.247491338151256" />
            </geometry>
        </collision>
    </link>
    <link name="Leg8">
        <inertial>
            <origin xyz="1.282540643947971 0 0" rpy="0 0 0"/>
            <mass value="1" />
            <inertia ixx="100" ixy="0" ixz="0" iyy="100" iyz="0" izz="100" />
        </inertial>
        <visual>
            <origin xyz="1.282540643947971 0 0" rpy="0 0 0"/>
            <geometry>
                <box size="2.565081287895942 2.8925645881864277 1.927220803934481" />
            </geometry>
            <material name="Blue">
                <color rgba="0 1.0 1.0 1.0"/>
            </material>
        </visual>
        <collision>
            <origin xyz="1.282540643947971 0 0" rpy="0 0 0"/>
            <geometry>
                <box size="2.565081287895942 2.8925645881864277 1.927220803934481" />
            </geometry>
        </collision>
    </link>
    <link name="Leg9">
        <inertial>
            <origin xyz="0.6836097430323456 0 0" rpy="0 0 0"/>
            <mass value="1" />
            <inertia ixx="100" ixy="0" ixz="0" iyy="100" iyz="0" izz="100" />
        </inertial>
        <visual>
            <origin xyz="0.6836097430323456 0 0" rpy="0 0 0"/>
            <geometry>
                <box size="1.3672194860646911 1.5107720434713328 1.7389376505502572" />
            </geometry>
            <material name="Green">
                <color rgba="0 180.0 0.0 1.0"/>
            </material>
        </visual>
        <collision>
            <origin xyz="0.6836097430323456 0 0" rpy="0 0 0"/>
            <geometry>
                <box size="1.3672194860646911 1.5107720434713328 1.7389376505502572" />
            </geometry>
        </collision>
    </link>
    <link name="Leg10">
        <inertial>
            <origin xyz="0 0 0.6994595556168043" rpy="0 0 0"/>
            <mass value="1" />
            <inertia ixx="100" ixy="0" ixz="0" iyy="100" iyz="0" izz="100" />
        </inertial>
        <visual>
            <origin xyz="0 0 0.6994595556168043" rpy="0 0 0"/>
            <geometry>
                <box size="1.6064703450572269 2.09758722526146 1.3989191112336086" />
            </geometry>
            <material name="Blue">
                <color rgba="0 1.0 1.0 1.0"/>
            </material>
        </visual>
        <collision>
            <origin xyz="0 0 0.6994595556168043" rpy="0 0 0"/>
            <geometry>
                <box size="1.6064703450572269 2.09758722526146 1.3989191112336086" />
            </geometry>
        </collision>
    </link>
    <link name="Leg11">
        <inertial>
            <origin xyz="0 0 0.9743227671014595" rpy="0 0 0"/>
            <mass value="1" />
            <inertia ixx="100" ixy="0" ixz="0" iyy="100" iyz="0" izz="100" />
        </inertial>
        <visual>
            <origin xyz="0 0 0.9743227671014595" rpy="0 0 0"/>
            <geometry>
                <box size="2.0095114748058256 1.3822390396828443 1.948645534202919" />
            </geometry>
            <material name="Blue">
                <color rgba="0 1.0 1.0 1.0"/>
            </material>
        </visual>
        <collision>
            <origin xyz="0 0 0.9743227671014595" rpy="0 0 0"/>
            <geometry>
                <box size="2.0095114748058256 1.3822390396828443 1.948645534202919" />
            </geometry>
        </collision>
    </link>
    <link name="Leg12">
        <inertial>
            <origin xyz="0 1.1007356081970279 0" rpy="0 0 0"/>
            <mass value="1" />
            <inertia ixx="100" ixy="0" ixz="0" iyy="100" iyz="0" izz="100" />
        </inertial>
        <visual>
            <origin xyz="0 1.1007356081970279 0" rpy="0 0 0"/>
            <geometry>
                <box size="2.316728165658372 2.2014712163940557 1.9384926441221257" />
            </geometry>
            <material name="Green">
                <color rgba="0 180.0 0.0 1.0"/>
            </material>
        </visual>
        <collision>
            <origin xyz="0 1.1007356081970279 0" rpy="0 0 0"/>
            <geometry>
                <box size="2.316728165658372 2.2014712163940557 1.9384926441221257" />
            </geometry>
        </collision>
    </link>
    <link name="Leg13">
        <inertial>
            <origin xyz="0.9929948461405095 0 0" rpy="0 0 0"/>
            <mass value="1" />
            <inertia ixx="100" ixy="0" ixz="0" iyy="100" iyz="0" izz="100" />
        </inertial>
        <visual>
            <origin xyz="0.9929948461405095 0 0" rpy="0 0 0"/>
            <geometry>
                <box size="1.985989692281019 1.006583128231071 2.3259443243531166" />
            </geometry>
            <material name="Blue">
                <color rgba="0 1.0 1.0 1.0"/>
            </material>
        </visual>
        <collision>
            <origin xyz="0.9929948461405095 0 0" rpy="0 0 0"/>
            <geometry>
                <box size="1.985989692281019 1.006583128231071 2.3259443243531166" />
            </geometry>
        </collision>
    </link>
    <link name="Leg14">
        <inertial>
            <origin xyz="0 0 0.8700866224524768" rpy="0 0 0"/>
            <mass value="1" />
            <inertia ixx="100" ixy="0" ixz="0" iyy="100" iyz="0" izz="100" />
        </inertial>
        <visual>
            <origin xyz="0 0 0.8700866224524768" rpy="0 0 0"/>
            <geometry>
                <box size="1.6401618280712875 1.2192020226884601 1.7401732449049536" />
            </geometry>
            <material name="Green">
                <color rgba="0 180.0 0.0 1.0"/>
            </material>
        </visual>
        <collision>
            <origin xyz="0 0 0.8700866224524768" rpy="0 0 0"/>
            <geometry>
                <box size="1.6401618280712875 1.2192020226884601 1.7401732449049536" />
            </geometry>
        </collision>
    </link>
    <link name="Leg15">
        <inertial>
            <origin xyz="0 0.5651708647360393 0" rpy="0 0 0"/>
            <mass value="1" />
            <inertia ixx="100" ixy="0" ixz="0" iyy="100" iyz="0" izz="100" />
        </inertial>
        <visual>
            <origin xyz="0 0.5651708647360393 0" rpy="0 0 0"/>
            <geometry>
                <box size="2.2061118417103653 1.1303417294720786 2.1899306715513736" />
            </geometry>
            <material name="Blue">
                <color rgba="0 1.0 1.0 1.0"/>
            </material>
        </visual>
        <collision>
            <origin xyz="0 0.5651708647360393 0" rpy="0 0 0"/>
            <geometry>
                <box size="2.2061118417103653 1.1303417294720786 2.1899306715513736" />
            </geometry>
        </collision>
    </link>
    <link name="Leg16">
        <inertial>
            <origin xyz="0 0.5439219038218193 0" rpy="0 0 0"/>
            <mass value="1" />
            <inertia ixx="100" ixy="0" ixz="0" iyy="100" iyz="0" izz="100" />
        </inertial>
        <visual>
            <origin xyz="0 0.5439219038218193 0" rpy="0 0 0"/>
            <geometry>
                <box size="2.524745159150747 1.0878438076436385 2.2908660206871296" />
            </geometry>
            <material name="Green">
                <color rgba="0 180.0 0.0 1.0"/>
            </material>
        </visual>
        <collision>
            <origin xyz="0 0.5439219038218193 0" rpy="0 0 0"/>
            <geometry>
                <box size="2.524745159150747 1.0878438076436385 2.2908660206871296" />
            </geometry>
        </collision>
    </link>
    <link name="Leg17">
        <inertial>
            <origin xyz="0 1.4740653344997012 0" rpy="0 0 0"/>
            <mass value="1" />
            <inertia ixx="100" ixy="0" ixz="0" iyy="100" iyz="0" izz="100" />
        </inertial>
        <visual>
            <origin xyz="0 1.4740653344997012 0" rpy="0 0 0"/>
            <geometry>
                <box size="1.478962265257059 2.9481306689994025 2.6062903934421033" />
            </geometry>
            <material name="Blue">
                <color rgba="0 1.0 1.0 1.0"/>
            </material>
        </visual>
        <collision>
            <origin xyz="0 1.4740653344997012 0" rpy="0 0 0"/>
            <geometry>
                <box size="1.478962265257059 2.9481306689994025 2.6062903934421033" />
            </geometry>
        </collision>
    </link>
    <link name="Leg18">
        <inertial>
            <origin xyz="0 0 0.965866849898078" rpy="0 0 0"/>
            <mass value="1" />
            <inertia ixx="100" ixy="0" ixz="0" iyy="100" iyz="0" izz="100" />
        </inertial>
        <visual>
            <origin xyz="0 0 0.965866849898078" rpy="0 0 0"/>
            <geometry>
                <box size="2.8434750488068685 1.9942837907487612 1.931733699796156" />
            </geometry>
            <material name="Blue">
                <color rgba="0 1.0 1.0 1.0"/>
            </material>
        </visual>
        <collision>
            <origin xyz="0 0 0.965866849898078" rpy="0 0 0"/>
            <geometry>
                <box size="2.8434750488068685 1.9942837907487612 1.931733699796156" />
            </geometry>
        </collision>
    </link>
    <link name="Leg19">
        <inertial>
            <origin xyz="1.263205769904968 0 0" rpy="0 0 0"/>
            <mass value="1" />
            <inertia ixx="100" ixy="0" ixz="0" iyy="100" iyz="0" izz="100" />
        </inertial>
        <visual>
            <origin xyz="1.263205769904968 0 0" rpy="0 0 0"/>
            <geometry>
                <box size="2.526411539809936 2.8542950386180617 2.375254055895204" />
            </geometry>
            <material name="Blue">
                <color rgba="0 1.0 1.0 1.0"/>
            </material>
        </visual>
        <collision>
            <origin xyz="1.263205769904968 0 0" rpy="0 0 0"/>
            <geometry>
                <box size="2.526411539809936 2.8542950386180617 2.375254055895204" />
            </geometry>
        </collision>
    </link>
    <link name="Leg20">
        <inertial>
            <origin xyz="0 1.0283632144771373 0" rpy="0 0 0"/>
            <mass value="1" />
            <inertia ixx="100" ixy="0" ixz="0" iyy="100" iyz="0" izz="100" />
        </inertial>
        <visual>
            <origin xyz="0 1.0283632144771373 0" rpy="0 0 0"/>
            <geometry>
                <box size="2.149067490102701 2.0567264289542746 2.3385024621492825" />
            </geometry>
            <material name="Blue">
                <color rgba="0 1.0 1.0 1.0"/>
            </material>
        </visual>
        <collision>
            <origin xyz="0 1.0283632144771373 0" rpy="0 0 0"/>
            <geometry>
                <box size="2.149067490102701 2.0567264289542746 2.3385024621492825" />
            </geometry>
        </collision>
    </link>
    <link name="Leg21">
        <inertial>
            <origin xyz="0 0 1.4723079571353592" rpy="0 0 0"/>
            <mass value="1" />
            <inertia ixx="100" ixy="0" ixz="0" iyy="100" iyz="0" izz="100" />
        </inertial>
        <visual>
            <origin xyz="0 0 1.4723079571353592" rpy="0 0 0"/>
            <geometry>
                <box size="1.9883138618096292 1.3018514830005512 2.9446159142707184" />
            </geometry>
            <material name="Blue">
                <color rgba="0 1.0 1.0 1.0"/>
            </material>
        </visual>
        <collision>
            <origin xyz="0 0 1.4723079571353592" rpy="0 0 0"/>
            <geometry>
                <box size="1.9883138618096292 1.3018514830005512 2.9446159142707184" />
            </geometry>
        </collision>
    </link>
    <link name="Leg22">
        <inertial>
            <origin xyz="0 0 0.7333737453389195" rpy="0 0 0"/>
            <mass value="1" />
            <inertia ixx="100" ixy="0" ixz="0" iyy="100" iyz="0" izz="100" />
        </inertial>
        <visual>
            <origin xyz="0 0 0.7333737453389195" rpy="0 0 0"/>
            <geometry>
                <box size="1.0723521818929407 2.874438725149798 1.466747490677839" />
            </geometry>
            <material name="Blue">
                <color rgba="0 1.0 1.0 1.0"/>
            </material>
        </visual>
        <collision>
            <origin xyz="0 0 0.7333737453389195" rpy="0 0 0"/>
            <geometry>
                <box size="1.0723521818929407 2.874438725149798 1.466747490677839" />
            </geometry>
        </collision>
    </link>
    <link name="Leg23">
        <inertial>
            <origin xyz="1.3620762967038367 0 0" rpy="0 0 0"/>
            <mass value="1" />
            <inertia ixx="100" ixy="0" ixz="0" iyy="100" iyz="0" izz="100" />
        </inertial>
        <visual>
            <origin xyz="1.3620762967038367 0 0" rpy="0 0 0"/>
            <geometry>
                <box size="2.7241525934076734 2.7029082186838536 2.852451285896392" />
            </geometry>
            <material name="Blue">
                <color rgba="0 1.0 1.0 1.0"/>
            </material>
        </visual>
        <collision>
            <origin xyz="1.3620762967038367 0 0" rpy="0 0 0"/>
            <geometry>
                <box size="2.7241525934076734 2.7029082186838536 2.852451285896392" />
            </geometry>
        </collision>
    </link>
    <link name="Leg24">
        <inertial>
            <origin xyz="0 0 0.9717059455577848" rpy="0 0 0"/>
            <mass value="1" />
            <inertia ixx="100" ixy="0" ixz="0" iyy="100" iyz="0" izz="100" />
        </inertial>
        <visual>
            <origin xyz="0 0 0.9717059455577848" rpy="0 0 0"/>
            <geometry>
                <box size="1.306193157086795 2.153423565181391 1.9434118911155696" />
            </geometry>
            <material name="Blue">
                <color rgba="0 1.0 1.0 1.0"/>
            </material>
        </visual>
        <collision>
            <origin xyz="0 0 0.9717059455577848" rpy="0 0 0"/>
            <geometry>
                <box size="1.306193157086795 2.153423565181391 1.9434118911155696" />
            </geometry>
        </collision>
    </link>
    <link name="Leg25">
        <inertial>
            <origin xyz="0 0 0.8169347297665167" rpy="0 0 0"/>
            <mass value="1" />
            <inertia ixx="100" ixy="0" ixz="0" iyy="100" iyz="0" izz="100" />
        </inertial>
        <visual>
            <origin xyz="0 0 0.8169347297665167" rpy="0 0 0"/>
            <geometry>
                <box size="2.2060948588985156 1.6725344491825567 1.6338694595330334" />
            </geometry>
            <material name="Green">
                <color rgba="0 180.0 0.0 1.0"/>
            </material>
        </visual>
        <collision>
            <origin xyz="0 0 0.8169347297665167" rpy="0 0 0"/>
            <geometry>
                <box size="2.2060948588985156 1.6725344491825567 1.6338694595330334" />
            </geometry>
        </collision>
    </link>
    <link name="Leg26">
        <inertial>
            <origin xyz="0 0 0.6824590069208091" rpy="0 0 0"/>
            <mass value="1" />
            <inertia ixx="100" ixy="0" ixz="0" iyy="100" iyz="0" izz="100" />
        </inertial>
        <visual>
            <origin xyz="0 0 0.6824590069208091" rpy="0 0 0"/>
            <geometry>
                <box size="1.7464422127519592 1.8168908004304065 1.3649180138416181" />
            </geometry>
            <material name="Green">
                <color rgba="0 180.0 0.0 1.0"/>
            </material>
        </visual>
        <collision>
            <origin xyz="0 0 0.6824590069208091" rpy="0 0 0"/>
            <geometry>
                <box size="1.7464422127519592 1.8168908004304065 1.3649180138416181" />
            </geometry>
        </collision>
    </link>
    <joint name="Torso_Leg1" type="revolute">
       <parent link="Torso"/>
       <child  link="Leg1"/>
       <origin rpy="0 0 0" xyz="0 0.7231106089033305 1.2797544236939764" />
     <axis xyz="1 0 0"/>
       <limit effort="0.0" lower="-3.14159" upper="3.14159" velocity="0.0"/>
    </joint>
    <joint name="Torso_Leg2" type="revolute">
       <parent link="Torso"/>
       <child  link="Leg2"/>
       <origin rpy="0 0 0" xyz="1.422789431632332 0.6112441743296918 0" />
     <axis xyz="1 0 0"/>
       <limit effort="0.0" lower="-3.14159" upper="3.14159" velocity="0.0"/>
    </joint>
    <joint name="Leg1_Leg3" type="revolute">
       <parent link="Leg1"/>
       <child  link="Leg3"/>
       <origin rpy="0 0 0" xyz="0.6634327526064179 1.2062343413453305 0" />
     <axis xyz="1 0 0"/>
       <limit effort="0.0" lower="-3.14159" upper="3.14159" velocity="0.0"/>
    </joint>
    <joint name="Leg2_Leg4" type="revolute">
       <parent link="Leg2"/>
       <child  link="Leg4"/>
       <origin rpy="0 0 0" xyz="1.1949455850910642 0.6282896758427894 0" />
     <axis xyz="1 0 0"/>
       <limit effort="0.0" lower="-3.14159" upper="3.14159" velocity="0.0"/>
    </joint>
    <joint name="Leg4_Leg5" type="revolute">
       <parent link="Leg4"/>
       <child  link="Leg5"/>
       <origin rpy="0 0 0" xyz="0 0 2.1437064892974877" />
     <axis xyz="1 0 0"/>
       <limit effort="0.0" lower="-3.14159" upper="3.14159" velocity="0.0"/>
    </joint>
    <joint name="Leg1_Leg6" type="revolute">
       <parent link="Leg1"/>
       <child  link="Leg6"/>
       <origin rpy="0 0 0" xyz="1.3268655052128357 1.2062343413453305 0" />
     <axis xyz="1 0 0"/>
       <limit effort="0.0" lower="-3.14159" upper="3.14159" velocity="0.0"/>
    </joint>
    <joint name="Leg2_Leg7" type="revolute">
       <parent link="Leg2"/>
       <child  link="Leg7"/>
       <origin rpy="0 0 0" xyz="1.1949455850910642 0.6282896758427894 1.2517947832392342" />
     <axis xyz="1 0 0"/>
       <limit effort="0.0" lower="-3.14159" upper="3.14159" velocity="0.0"/>
    </joint>
    <joint name="Leg4_Leg8" type="revolute">
       <parent link="Leg4"/>
       <child  link="Leg8"/>
       <origin rpy="0 0 0" xyz="0.6825737700559645 0 2.1437064892974877" />
     <axis xyz="1 0 0"/>
       <limit effort="0.0" lower="-3.14159" upper="3.14159" velocity="0.0"/>
    </joint>
    <joint name="Leg3_Leg9" type="revolute">
       <parent link="Leg3"/>
       <child  link="Leg9"/>
       <origin rpy="0 0 0" xyz="2.36749133945196 0 0" />
     <axis xyz="1 0 0"/>
       <limit effort="0.0" lower="-3.14159" upper="3.14159" velocity="0.0"/>
    </joint>
    <joint name="Leg8_Leg10" type="revolute">
       <parent link="Leg8"/>
       <child  link="Leg10"/>
       <origin rpy="0 0 0" xyz="0.6836097430323456 0 0.8694688252751286" />
     <axis xyz="1 0 0"/>
       <limit effort="0.0" lower="-3.14159" upper="3.14159" velocity="0.0"/>
    </joint>
    <joint name="Leg10_Leg11" type="revolute">
       <parent link="Leg10"/>
       <child  link="Leg11"/>
       <origin rpy="0 0 0" xyz="0 0 1.948645534202919" />
     <axis xyz="1 0 0"/>
       <limit effort="0.0" lower="-3.14159" upper="3.14159" velocity="0.0"/>
    </joint>
    <joint name="Leg5_Leg12" type="revolute">
       <parent link="Leg5"/>
       <child  link="Leg12"/>
       <origin rpy="0 0 0" xyz="1.3636553105914433 1.0579427950573115 0" />
     <axis xyz="1 0 0"/>
       <limit effort="0.0" lower="-3.14159" upper="3.14159" velocity="0.0"/>
    </joint>
    <joint name="Leg11_Leg13" type="revolute">
       <parent link="Leg11"/>
       <child  link="Leg13"/>
       <origin rpy="0 0 0" xyz="1.158364082829186 1.1007356081970279 0" />
     <axis xyz="1 0 0"/>
       <limit effort="0.0" lower="-3.14159" upper="3.14159" velocity="0.0"/>
    </joint>
    <joint name="Leg11_Leg14" type="revolute">
       <parent link="Leg11"/>
       <child  link="Leg14"/>
       <origin rpy="0 0 0" xyz="1.158364082829186 1.1007356081970279 0.9692463220610629" />
     <axis xyz="1 0 0"/>
       <limit effort="0.0" lower="-3.14159" upper="3.14159" velocity="0.0"/>
    </joint>
    <joint name="Leg9_Leg15" type="revolute">
       <parent link="Leg9"/>
       <child  link="Leg15"/>
       <origin rpy="0 0 0" xyz="0 1.04879361263073 0.6994595556168043" />
     <axis xyz="1 0 0"/>
       <limit effort="0.0" lower="-3.14159" upper="3.14159" velocity="0.0"/>
    </joint>
    <joint name="Leg3_Leg16" type="revolute">
       <parent link="Leg3"/>
       <child  link="Leg16"/>
       <origin rpy="0 0 0" xyz="2.36749133945196 1.2154402955962864 0" />
     <axis xyz="1 0 0"/>
       <limit effort="0.0" lower="-3.14159" upper="3.14159" velocity="0.0"/>
    </joint>
    <joint name="Leg16_Leg17" type="revolute">
       <parent link="Leg16"/>
       <child  link="Leg17"/>
       <origin rpy="0 0 0" xyz="0 2.9481306689994025 0" />
     <axis xyz="1 0 0"/>
       <limit effort="0.0" lower="-3.14159" upper="3.14159" velocity="0.0"/>
    </joint>
    <joint name="Leg15_Leg18" type="revolute">
       <parent link="Leg15"/>
       <child  link="Leg18"/>
       <origin rpy="0 0 0" xyz="0 0.5439219038218193 1.1454330103435648" />
     <axis xyz="1 0 0"/>
       <limit effort="0.0" lower="-3.14159" upper="3.14159" velocity="0.0"/>
    </joint>
    <joint name="Leg6_Leg19" type="revolute">
       <parent link="Leg6"/>
       <child  link="Leg19"/>
       <origin rpy="0 0 0" xyz="0.5894965137347605 0 1.123745669075628" />
     <axis xyz="1 0 0"/>
       <limit effort="0.0" lower="-3.14159" upper="3.14159" velocity="0.0"/>
    </joint>
    <joint name="Leg15_Leg20" type="revolute">
       <parent link="Leg15"/>
       <child  link="Leg20"/>
       <origin rpy="0 0 0" xyz="0 1.0878438076436385 1.1454330103435648" />
     <axis xyz="1 0 0"/>
       <limit effort="0.0" lower="-3.14159" upper="3.14159" velocity="0.0"/>
    </joint>
    <joint name="Leg6_Leg21" type="revolute">
       <parent link="Leg6"/>
       <child  link="Leg21"/>
       <origin rpy="0 0 0" xyz="0.5894965137347605 0 2.247491338151256" />
     <axis xyz="1 0 0"/>
       <limit effort="0.0" lower="-3.14159" upper="3.14159" velocity="0.0"/>
    </joint>
    <joint name="Leg3_Leg22" type="revolute">
       <parent link="Leg3"/>
       <child  link="Leg22"/>
       <origin rpy="0 0 0" xyz="2.36749133945196 1.2154402955962864 1.255949589531272" />
     <axis xyz="1 0 0"/>
       <limit effort="0.0" lower="-3.14159" upper="3.14159" velocity="0.0"/>
    </joint>
    <joint name="Leg16_Leg23" type="revolute">
       <parent link="Leg16"/>
       <child  link="Leg23"/>
       <origin rpy="0 0 0" xyz="0.7394811326285295 2.9481306689994025 0" />
     <axis xyz="1 0 0"/>
       <limit effort="0.0" lower="-3.14159" upper="3.14159" velocity="0.0"/>
    </joint>
    <joint name="Leg18_Leg24" type="revolute">
       <parent link="Leg18"/>
       <child  link="Leg24"/>
       <origin rpy="0 0 0" xyz="1.263205769904968 0 1.187627027947602" />
     <axis xyz="1 0 0"/>
       <limit effort="0.0" lower="-3.14159" upper="3.14159" velocity="0.0"/>
    </joint>
    <joint name="Leg17_Leg25" type="revolute">
       <parent link="Leg17"/>
       <child  link="Leg25"/>
       <origin rpy="0 0 0" xyz="0 0 1.931733699796156" />
     <axis xyz="1 0 0"/>
       <limit effort="0.0" lower="-3.14159" upper="3.14159" velocity="0.0"/>
    </joint>
    <joint name="Leg5_Leg26" type="revolute">
       <parent link="Leg5"/>
       <child  link="Leg26"/>
       <origin rpy="0 0 0" xyz="1.3636553105914433 1.0579427950573115 0.6837712462512585" />
     <axis xyz="1 0 0"/>
       <limit effort="0.0" lower="-3.14159" upper="3.14159" velocity="0.0"/>
    </joint>
</robot>