<robot name = "robot">
    <link name="Torso">
        <inertial>
            <origin xyz="0 0 0.9616600172557571" rpy="0 0 0"/>
            <mass value="1" />
            <inertia ixx="100" ixy="0" ixz="0" iyy="100" iyz="0" izz="100" />
        </inertial>
        <visual>
            <origin xyz="0 0 0.9616600172557571" rpy="0 0 0"/>
            <geometry>
                <box size="2.4225275448268375 2.1662896710621538 1.9233200345115142" />
            </geometry>
            <material name="Green">
                <color rgba="0 180.0 0.0 1.0"/>
            </material>
        </visual>
        <collision>
            <origin xyz="0 0 0.9616600172557571" rpy="0 0 0"/>
            <geometry>
                <box size="2.4225275448268375 2.1662896710621538 1.9233200345115142" />
            </geometry>
        </collision>
    </link>
    <link name="Leg1">
        <inertial>
            <origin xyz="0 0 1.3813115970421905" rpy="0 0 0"/>
            <mass value="1" />
            <inertia ixx="100" ixy="0" ixz="0" iyy="100" iyz="0" izz="100" />
        </inertial>
        <visual>
            <origin xyz="0 0 1.3813115970421905" rpy="0 0 0"/>
            <geometry>
                <box size="2.2711821984853837 1.7976778531531932 2.762623194084381" />
            </geometry>
            <material name="Blue">
                <color rgba="0 1.0 1.0 1.0"/>
            </material>
        </visual>
        <collision>
            <origin xyz="0 0 1.3813115970421905" rpy="0 0 0"/>
            <geometry>
                <box size="2.2711821984853837 1.7976778531531932 2.762623194084381" />
            </geometry>
        </collision>
    </link>
    <link name="Leg2">
        <inertial>
            <origin xyz="1.3121467571838485 0 0" rpy="0 0 0"/>
            <mass value="1" />
            <inertia ixx="100" ixy="0" ixz="0" iyy="100" iyz="0" izz="100" />
        </inertial>
        <visual>
            <origin xyz="1.3121467571838485 0 0" rpy="0 0 0"/>
            <geometry>
                <box size="2.624293514367697 2.9541269731456126 1.137255765213043" />
            </geometry>
            <material name="Green">
                <color rgba="0 180.0 0.0 1.0"/>
            </material>
        </visual>
        <collision>
            <origin xyz="1.3121467571838485 0 0" rpy="0 0 0"/>
            <geometry>
                <box size="2.624293514367697 2.9541269731456126 1.137255765213043" />
            </geometry>
        </collision>
    </link>
    <link name="Leg3">
        <inertial>
            <origin xyz="0.8336560832411787 0 0" rpy="0 0 0"/>
            <mass value="1" />
            <inertia ixx="100" ixy="0" ixz="0" iyy="100" iyz="0" izz="100" />
        </inertial>
        <visual>
            <origin xyz="0.8336560832411787 0 0" rpy="0 0 0"/>
            <geometry>
                <box size="1.6673121664823574 2.950443403380402 1.6945845026515811" />
            </geometry>
            <material name="Green">
                <color rgba="0 180.0 0.0 1.0"/>
            </material>
        </visual>
        <collision>
            <origin xyz="0.8336560832411787 0 0" rpy="0 0 0"/>
            <geometry>
                <box size="1.6673121664823574 2.950443403380402 1.6945845026515811" />
            </geometry>
        </collision>
    </link>
    <link name="Leg4">
        <inertial>
            <origin xyz="0 0 1.302547317069808" rpy="0 0 0"/>
            <mass value="1" />
            <inertia ixx="100" ixy="0" ixz="0" iyy="100" iyz="0" izz="100" />
        </inertial>
        <visual>
            <origin xyz="0 0 1.302547317069808" rpy="0 0 0"/>
            <geometry>
                <box size="1.0592664623218502 2.3830820113658517 2.605094634139616" />
            </geometry>
            <material name="Green">
                <color rgba="0 180.0 0.0 1.0"/>
            </material>
        </visual>
        <collision>
            <origin xyz="0 0 1.302547317069808" rpy="0 0 0"/>
            <geometry>
                <box size="1.0592664623218502 2.3830820113658517 2.605094634139616" />
            </geometry>
        </collision>
    </link>
    <link name="Leg5">
        <inertial>
            <origin xyz="0 0 0.5523234426161461" rpy="0 0 0"/>
            <mass value="1" />
            <inertia ixx="100" ixy="0" ixz="0" iyy="100" iyz="0" izz="100" />
        </inertial>
        <visual>
            <origin xyz="0 0 0.5523234426161461" rpy="0 0 0"/>
            <geometry>
                <box size="2.5760918173301075 1.3103675283198062 1.1046468852322922" />
            </geometry>
            <material name="Green">
                <color rgba="0 180.0 0.0 1.0"/>
            </material>
        </visual>
        <collision>
            <origin xyz="0 0 0.5523234426161461" rpy="0 0 0"/>
            <geometry>
                <box size="2.5760918173301075 1.3103675283198062 1.1046468852322922" />
            </geometry>
        </collision>
    </link>
    <link name="Leg6">
        <inertial>
            <origin xyz="1.2061569978486915 0 0" rpy="0 0 0"/>
            <mass value="1" />
            <inertia ixx="100" ixy="0" ixz="0" iyy="100" iyz="0" izz="100" />
        </inertial>
        <visual>
            <origin xyz="1.2061569978486915 0 0" rpy="0 0 0"/>
            <geometry>
                <box size="2.412313995697383 2.236605247593642 2.1055619578920153" />
            </geometry>
            <material name="Blue">
                <color rgba="0 1.0 1.0 1.0"/>
            </material>
        </visual>
        <collision>
            <origin xyz="1.2061569978486915 0 0" rpy="0 0 0"/>
            <geometry>
                <box size="2.412313995697383 2.236605247593642 2.1055619578920153" />
            </geometry>
        </collision>
    </link>
    <link name="Leg7">
        <inertial>
            <origin xyz="0.8909840791811008 0 0" rpy="0 0 0"/>
            <mass value="1" />
            <inertia ixx="100" ixy="0" ixz="0" iyy="100" iyz="0" izz="100" />
        </inertial>
        <visual>
            <origin xyz="0.8909840791811008 0 0" rpy="0 0 0"/>
            <geometry>
                <box size="1.7819681583622016 2.730463114158092 2.529094794021204" />
            </geometry>
            <material name="Green">
                <color rgba="0 180.0 0.0 1.0"/>
            </material>
        </visual>
        <collision>
            <origin xyz="0.8909840791811008 0 0" rpy="0 0 0"/>
            <geometry>
                <box size="1.7819681583622016 2.730463114158092 2.529094794021204" />
            </geometry>
        </collision>
    </link>
    <link name="Leg8">
        <inertial>
            <origin xyz="0 0.8374866998047883 0" rpy="0 0 0"/>
            <mass value="1" />
            <inertia ixx="100" ixy="0" ixz="0" iyy="100" iyz="0" izz="100" />
        </inertial>
        <visual>
            <origin xyz="0 0.8374866998047883 0" rpy="0 0 0"/>
            <geometry>
                <box size="2.160666479103949 1.6749733996095766 2.6962593994360136" />
            </geometry>
            <material name="Blue">
                <color rgba="0 1.0 1.0 1.0"/>
            </material>
        </visual>
        <collision>
            <origin xyz="0 0.8374866998047883 0" rpy="0 0 0"/>
            <geometry>
                <box size="2.160666479103949 1.6749733996095766 2.6962593994360136" />
            </geometry>
        </collision>
    </link>
    <link name="Leg9">
        <inertial>
            <origin xyz="0.6787986203996861 0 0" rpy="0 0 0"/>
            <mass value="1" />
            <inertia ixx="100" ixy="0" ixz="0" iyy="100" iyz="0" izz="100" />
        </inertial>
        <visual>
            <origin xyz="0.6787986203996861 0 0" rpy="0 0 0"/>
            <geometry>
                <box size="1.3575972407993722 2.5353039383151836 1.7630161484616422" />
            </geometry>
            <material name="Green">
                <color rgba="0 180.0 0.0 1.0"/>
            </material>
        </visual>
        <collision>
            <origin xyz="0.6787986203996861 0 0" rpy="0 0 0"/>
            <geometry>
                <box size="1.3575972407993722 2.5353039383151836 1.7630161484616422" />
            </geometry>
        </collision>
    </link>
    <link name="Leg10">
        <inertial>
            <origin xyz="0.6480546701659742 0 0" rpy="0 0 0"/>
            <mass value="1" />
            <inertia ixx="100" ixy="0" ixz="0" iyy="100" iyz="0" izz="100" />
        </inertial>
        <visual>
            <origin xyz="0.6480546701659742 0 0" rpy="0 0 0"/>
            <geometry>
                <box size="1.2961093403319484 2.5270237592962776 2.766227357919614" />
            </geometry>
            <material name="Blue">
                <color rgba="0 1.0 1.0 1.0"/>
            </material>
        </visual>
        <collision>
            <origin xyz="0.6480546701659742 0 0" rpy="0 0 0"/>
            <geometry>
                <box size="1.2961093403319484 2.5270237592962776 2.766227357919614" />
            </geometry>
        </collision>
    </link>
    <link name="Leg11">
        <inertial>
            <origin xyz="0 0 0.8586437281988425" rpy="0 0 0"/>
            <mass value="1" />
            <inertia ixx="100" ixy="0" ixz="0" iyy="100" iyz="0" izz="100" />
        </inertial>
        <visual>
            <origin xyz="0 0 0.8586437281988425" rpy="0 0 0"/>
            <geometry>
                <box size="1.8761396698052992 2.134119123556653 1.717287456397685" />
            </geometry>
            <material name="Green">
                <color rgba="0 180.0 0.0 1.0"/>
            </material>
        </visual>
        <collision>
            <origin xyz="0 0 0.8586437281988425" rpy="0 0 0"/>
            <geometry>
                <box size="1.8761396698052992 2.134119123556653 1.717287456397685" />
            </geometry>
        </collision>
    </link>
    <link name="Leg12">
        <inertial>
            <origin xyz="0 0 0.7180112499099385" rpy="0 0 0"/>
            <mass value="1" />
            <inertia ixx="100" ixy="0" ixz="0" iyy="100" iyz="0" izz="100" />
        </inertial>
        <visual>
            <origin xyz="0 0 0.7180112499099385" rpy="0 0 0"/>
            <geometry>
                <box size="2.84708021945527 2.4907767287871128 1.436022499819877" />
            </geometry>
            <material name="Green">
                <color rgba="0 180.0 0.0 1.0"/>
            </material>
        </visual>
        <collision>
            <origin xyz="0 0 0.7180112499099385" rpy="0 0 0"/>
            <geometry>
                <box size="2.84708021945527 2.4907767287871128 1.436022499819877" />
            </geometry>
        </collision>
    </link>
    <link name="Leg13">
        <inertial>
            <origin xyz="0 0 0.5526270029921747" rpy="0 0 0"/>
            <mass value="1" />
            <inertia ixx="100" ixy="0" ixz="0" iyy="100" iyz="0" izz="100" />
        </inertial>
        <visual>
            <origin xyz="0 0 0.5526270029921747" rpy="0 0 0"/>
            <geometry>
                <box size="2.795358355319389 2.906399027195988 1.1052540059843494" />
            </geometry>
            <material name="Green">
                <color rgba="0 180.0 0.0 1.0"/>
            </material>
        </visual>
        <collision>
            <origin xyz="0 0 0.5526270029921747" rpy="0 0 0"/>
            <geometry>
                <box size="2.795358355319389 2.906399027195988 1.1052540059843494" />
            </geometry>
        </collision>
    </link>
    <link name="Leg14">
        <inertial>
            <origin xyz="1.4977961579466526 0 0" rpy="0 0 0"/>
            <mass value="1" />
            <inertia ixx="100" ixy="0" ixz="0" iyy="100" iyz="0" izz="100" />
        </inertial>
        <visual>
            <origin xyz="1.4977961579466526 0 0" rpy="0 0 0"/>
            <geometry>
                <box size="2.995592315893305 1.8407148354293925 2.8038331110960275" />
            </geometry>
            <material name="Green">
                <color rgba="0 180.0 0.0 1.0"/>
            </material>
        </visual>
        <collision>
            <origin xyz="1.4977961579466526 0 0" rpy="0 0 0"/>
            <geometry>
                <box size="2.995592315893305 1.8407148354293925 2.8038331110960275" />
            </geometry>
        </collision>
    </link>
    <link name="Leg15">
        <inertial>
            <origin xyz="0 0.6402478197397757 0" rpy="0 0 0"/>
            <mass value="1" />
            <inertia ixx="100" ixy="0" ixz="0" iyy="100" iyz="0" izz="100" />
        </inertial>
        <visual>
            <origin xyz="0 0.6402478197397757 0" rpy="0 0 0"/>
            <geometry>
                <box size="2.6919571974591445 1.2804956394795515 1.9179128029229686" />
            </geometry>
            <material name="Blue">
                <color rgba="0 1.0 1.0 1.0"/>
            </material>
        </visual>
        <collision>
            <origin xyz="0 0.6402478197397757 0" rpy="0 0 0"/>
            <geometry>
                <box size="2.6919571974591445 1.2804956394795515 1.9179128029229686" />
            </geometry>
        </collision>
    </link>
    <link name="Leg16">
        <inertial>
            <origin xyz="0 0 1.0119591195533708" rpy="0 0 0"/>
            <mass value="1" />
            <inertia ixx="100" ixy="0" ixz="0" iyy="100" iyz="0" izz="100" />
        </inertial>
        <visual>
            <origin xyz="0 0 1.0119591195533708" rpy="0 0 0"/>
            <geometry>
                <box size="2.4659613305758397 2.3960417563419694 2.0239182391067416" />
            </geometry>
            <material name="Blue">
                <color rgba="0 1.0 1.0 1.0"/>
            </material>
        </visual>
        <collision>
            <origin xyz="0 0 1.0119591195533708" rpy="0 0 0"/>
            <geometry>
                <box size="2.4659613305758397 2.3960417563419694 2.0239182391067416" />
            </geometry>
        </collision>
    </link>
    <link name="Leg17">
        <inertial>
            <origin xyz="0.8265715135660308 0 0" rpy="0 0 0"/>
            <mass value="1" />
            <inertia ixx="100" ixy="0" ixz="0" iyy="100" iyz="0" izz="100" />
        </inertial>
        <visual>
            <origin xyz="0.8265715135660308 0 0" rpy="0 0 0"/>
            <geometry>
                <box size="1.6531430271320615 1.7905656583464113 1.813968994178148" />
            </geometry>
            <material name="Green">
                <color rgba="0 180.0 0.0 1.0"/>
            </material>
        </visual>
        <collision>
            <origin xyz="0.8265715135660308 0 0" rpy="0 0 0"/>
            <geometry>
                <box size="1.6531430271320615 1.7905656583464113 1.813968994178148" />
            </geometry>
        </collision>
    </link>
    <link name="Leg18">
        <inertial>
            <origin xyz="0 0 1.032368169774212" rpy="0 0 0"/>
            <mass value="1" />
            <inertia ixx="100" ixy="0" ixz="0" iyy="100" iyz="0" izz="100" />
        </inertial>
        <visual>
            <origin xyz="0 0 1.032368169774212" rpy="0 0 0"/>
            <geometry>
                <box size="2.780689179520829 2.5133812179510837 2.064736339548424" />
            </geometry>
            <material name="Blue">
                <color rgba="0 1.0 1.0 1.0"/>
            </material>
        </visual>
        <collision>
            <origin xyz="0 0 1.032368169774212" rpy="0 0 0"/>
            <geometry>
                <box size="2.780689179520829 2.5133812179510837 2.064736339548424" />
            </geometry>
        </collision>
    </link>
    <link name="Leg19">
        <inertial>
            <origin xyz="0 0 0.9521629010148709" rpy="0 0 0"/>
            <mass value="1" />
            <inertia ixx="100" ixy="0" ixz="0" iyy="100" iyz="0" izz="100" />
        </inertial>
        <visual>
            <origin xyz="0 0 0.9521629010148709" rpy="0 0 0"/>
            <geometry>
                <box size="2.1272044626757562 1.3726839033615446 1.9043258020297418" />
            </geometry>
            <material name="Blue">
                <color rgba="0 1.0 1.0 1.0"/>
            </material>
        </visual>
        <collision>
            <origin xyz="0 0 0.9521629010148709" rpy="0 0 0"/>
            <geometry>
                <box size="2.1272044626757562 1.3726839033615446 1.9043258020297418" />
            </geometry>
        </collision>
    </link>
    <link name="Leg20">
        <inertial>
            <origin xyz="0 0.6713315310665798 0" rpy="0 0 0"/>
            <mass value="1" />
            <inertia ixx="100" ixy="0" ixz="0" iyy="100" iyz="0" izz="100" />
        </inertial>
        <visual>
            <origin xyz="0 0.6713315310665798 0" rpy="0 0 0"/>
            <geometry>
                <box size="2.352747302430202 1.3426630621331597 2.1599132330237296" />
            </geometry>
            <material name="Green">
                <color rgba="0 180.0 0.0 1.0"/>
            </material>
        </visual>
        <collision>
            <origin xyz="0 0.6713315310665798 0" rpy="0 0 0"/>
            <geometry>
                <box size="2.352747302430202 1.3426630621331597 2.1599132330237296" />
            </geometry>
        </collision>
    </link>
    <link name="Leg21">
        <inertial>
            <origin xyz="0 0.9751239363870846 0" rpy="0 0 0"/>
            <mass value="1" />
            <inertia ixx="100" ixy="0" ixz="0" iyy="100" iyz="0" izz="100" />
        </inertial>
        <visual>
            <origin xyz="0 0.9751239363870846 0" rpy="0 0 0"/>
            <geometry>
                <box size="1.2839352304135145 1.9502478727741692 2.9928226802215336" />
            </geometry>
            <material name="Green">
                <color rgba="0 180.0 0.0 1.0"/>
            </material>
        </visual>
        <collision>
            <origin xyz="0 0.9751239363870846 0" rpy="0 0 0"/>
            <geometry>
                <box size="1.2839352304135145 1.9502478727741692 2.9928226802215336" />
            </geometry>
        </collision>
    </link>
    <link name="Leg22">
        <inertial>
            <origin xyz="0 0 0.9449796254515154" rpy="0 0 0"/>
            <mass value="1" />
            <inertia ixx="100" ixy="0" ixz="0" iyy="100" iyz="0" izz="100" />
        </inertial>
        <visual>
            <origin xyz="0 0 0.9449796254515154" rpy="0 0 0"/>
            <geometry>
                <box size="2.865658484227295 2.7785091038589202 1.8899592509030307" />
            </geometry>
            <material name="Green">
                <color rgba="0 180.0 0.0 1.0"/>
            </material>
        </visual>
        <collision>
            <origin xyz="0 0 0.9449796254515154" rpy="0 0 0"/>
            <geometry>
                <box size="2.865658484227295 2.7785091038589202 1.8899592509030307" />
            </geometry>
        </collision>
    </link>
    <link name="Leg23">
        <inertial>
            <origin xyz="0 0 1.2440120477109913" rpy="0 0 0"/>
            <mass value="1" />
            <inertia ixx="100" ixy="0" ixz="0" iyy="100" iyz="0" izz="100" />
        </inertial>
        <visual>
            <origin xyz="0 0 1.2440120477109913" rpy="0 0 0"/>
            <geometry>
                <box size="2.3989049856052937 2.967433273296888 2.4880240954219826" />
            </geometry>
            <material name="Blue">
                <color rgba="0 1.0 1.0 1.0"/>
            </material>
        </visual>
        <collision>
            <origin xyz="0 0 1.2440120477109913" rpy="0 0 0"/>
            <geometry>
                <box size="2.3989049856052937 2.967433273296888 2.4880240954219826" />
            </geometry>
        </collision>
    </link>
    <link name="Leg24">
        <inertial>
            <origin xyz="0 0.551265869275528 0" rpy="0 0 0"/>
            <mass value="1" />
            <inertia ixx="100" ixy="0" ixz="0" iyy="100" iyz="0" izz="100" />
        </inertial>
        <visual>
            <origin xyz="0 0.551265869275528 0" rpy="0 0 0"/>
            <geometry>
                <box size="2.6514700289469255 1.102531738551056 2.495691996354156" />
            </geometry>
            <material name="Blue">
                <color rgba="0 1.0 1.0 1.0"/>
            </material>
        </visual>
        <collision>
            <origin xyz="0 0.551265869275528 0" rpy="0 0 0"/>
            <geometry>
                <box size="2.6514700289469255 1.102531738551056 2.495691996354156" />
            </geometry>
        </collision>
    </link>
    <link name="Leg25">
        <inertial>
            <origin xyz="0.5462459963272415 0 0" rpy="0 0 0"/>
            <mass value="1" />
            <inertia ixx="100" ixy="0" ixz="0" iyy="100" iyz="0" izz="100" />
        </inertial>
        <visual>
            <origin xyz="0.5462459963272415 0 0" rpy="0 0 0"/>
            <geometry>
                <box size="1.092491992654483 1.2903950727075575 2.363364064956272" />
            </geometry>
            <material name="Blue">
                <color rgba="0 1.0 1.0 1.0"/>
            </material>
        </visual>
        <collision>
            <origin xyz="0.5462459963272415 0 0" rpy="0 0 0"/>
            <geometry>
                <box size="1.092491992654483 1.2903950727075575 2.363364064956272" />
            </geometry>
        </collision>
    </link>
    <link name="Leg26">
        <inertial>
            <origin xyz="0 0.7093112521738986 0" rpy="0 0 0"/>
            <mass value="1" />
            <inertia ixx="100" ixy="0" ixz="0" iyy="100" iyz="0" izz="100" />
        </inertial>
        <visual>
            <origin xyz="0 0.7093112521738986 0" rpy="0 0 0"/>
            <geometry>
                <box size="2.7849182606146083 1.4186225043477971 1.2678402655269814" />
            </geometry>
            <material name="Blue">
                <color rgba="0 1.0 1.0 1.0"/>
            </material>
        </visual>
        <collision>
            <origin xyz="0 0.7093112521738986 0" rpy="0 0 0"/>
            <geometry>
                <box size="2.7849182606146083 1.4186225043477971 1.2678402655269814" />
            </geometry>
        </collision>
    </link>
    <joint name="Torso_Leg1" type="revolute">
       <parent link="Torso"/>
       <child  link="Leg1"/>
       <origin rpy="0 0 0" xyz="0 0 1.9233200345115142" />
     <axis xyz="1 0 0"/>
       <limit effort="0.0" lower="-3.14159" upper="3.14159" velocity="0.0"/>
    </joint>
    <joint name="Leg1_Leg2" type="revolute">
       <parent link="Leg1"/>
       <child  link="Leg2"/>
       <origin rpy="0 0 0" xyz="2.624293514367697 0 0" />
     <axis xyz="1 0 0"/>
       <limit effort="0.0" lower="-3.14159" upper="3.14159" velocity="0.0"/>
    </joint>
    <joint name="Leg2_Leg3" type="revolute">
       <parent link="Leg2"/>
       <child  link="Leg3"/>
       <origin rpy="0 0 0" xyz="1.6673121664823574 0 0" />
     <axis xyz="1 0 0"/>
       <limit effort="0.0" lower="-3.14159" upper="3.14159" velocity="0.0"/>
    </joint>
    <joint name="Leg2_Leg4" type="revolute">
       <parent link="Leg2"/>
       <child  link="Leg4"/>
       <origin rpy="0 0 0" xyz="1.6673121664823574 0 0.8472922513257906" />
     <axis xyz="1 0 0"/>
       <limit effort="0.0" lower="-3.14159" upper="3.14159" velocity="0.0"/>
    </joint>
    <joint name="Leg4_Leg5" type="revolute">
       <parent link="Leg4"/>
       <child  link="Leg5"/>
       <origin rpy="0 0 0" xyz="0 0 1.1046468852322922" />
     <axis xyz="1 0 0"/>
       <limit effort="0.0" lower="-3.14159" upper="3.14159" velocity="0.0"/>
    </joint>
    <joint name="Leg5_Leg6" type="revolute">
       <parent link="Leg5"/>
       <child  link="Leg6"/>
       <origin rpy="0 0 0" xyz="2.412313995697383 0 0" />
     <axis xyz="1 0 0"/>
       <limit effort="0.0" lower="-3.14159" upper="3.14159" velocity="0.0"/>
    </joint>
    <joint name="Torso_Leg7" type="revolute">
       <parent link="Torso"/>
       <child  link="Leg7"/>
       <origin rpy="0 0 0" xyz="1.1355910992426919 0 1.3813115970421905" />
     <axis xyz="1 0 0"/>
       <limit effort="0.0" lower="-3.14159" upper="3.14159" velocity="0.0"/>
    </joint>
    <joint name="Torso_Leg8" type="revolute">
       <parent link="Torso"/>
       <child  link="Leg8"/>
       <origin rpy="0 0 0" xyz="1.1355910992426919 0.8988389265765966 1.3813115970421905" />
     <axis xyz="1 0 0"/>
       <limit effort="0.0" lower="-3.14159" upper="3.14159" velocity="0.0"/>
    </joint>
    <joint name="Leg6_Leg9" type="revolute">
       <parent link="Leg6"/>
       <child  link="Leg9"/>
       <origin rpy="0 0 0" xyz="1.7819681583622016 0 0" />
     <axis xyz="1 0 0"/>
       <limit effort="0.0" lower="-3.14159" upper="3.14159" velocity="0.0"/>
    </joint>
    <joint name="Leg7_Leg10" type="revolute">
       <parent link="Leg7"/>
       <child  link="Leg10"/>
       <origin rpy="0 0 0" xyz="1.0803332395519745 0.8374866998047883 0" />
     <axis xyz="1 0 0"/>
       <limit effort="0.0" lower="-3.14159" upper="3.14159" velocity="0.0"/>
    </joint>
    <joint name="Leg5_Leg11" type="revolute">
       <parent link="Leg5"/>
       <child  link="Leg11"/>
       <origin rpy="0 0 0" xyz="2.412313995697383 0 1.0527809789460076" />
     <axis xyz="1 0 0"/>
       <limit effort="0.0" lower="-3.14159" upper="3.14159" velocity="0.0"/>
    </joint>
    <joint name="Leg10_Leg12" type="revolute">
       <parent link="Leg10"/>
       <child  link="Leg12"/>
       <origin rpy="0 0 0" xyz="0 0 1.717287456397685" />
     <axis xyz="1 0 0"/>
       <limit effort="0.0" lower="-3.14159" upper="3.14159" velocity="0.0"/>
    </joint>
    <joint name="Leg8_Leg13" type="revolute">
       <parent link="Leg8"/>
       <child  link="Leg13"/>
       <origin rpy="0 0 0" xyz="0.6787986203996861 0 0.8815080742308211" />
     <axis xyz="1 0 0"/>
       <limit effort="0.0" lower="-3.14159" upper="3.14159" velocity="0.0"/>
    </joint>
    <joint name="Leg4_Leg14" type="revolute">
       <parent link="Leg4"/>
       <child  link="Leg14"/>
       <origin rpy="0 0 0" xyz="1.2880459086650538 0 1.1046468852322922" />
     <axis xyz="1 0 0"/>
       <limit effort="0.0" lower="-3.14159" upper="3.14159" velocity="0.0"/>
    </joint>
    <joint name="Leg13_Leg15" type="revolute">
       <parent link="Leg13"/>
       <child  link="Leg15"/>
       <origin rpy="0 0 0" xyz="1.4977961579466526 0.9203574177146963 0" />
     <axis xyz="1 0 0"/>
       <limit effort="0.0" lower="-3.14159" upper="3.14159" velocity="0.0"/>
    </joint>
    <joint name="Leg14_Leg16" type="revolute">
       <parent link="Leg14"/>
       <child  link="Leg16"/>
       <origin rpy="0 0 0" xyz="0 0.6402478197397757 0.9589564014614843" />
     <axis xyz="1 0 0"/>
       <limit effort="0.0" lower="-3.14159" upper="3.14159" velocity="0.0"/>
    </joint>
    <joint name="Leg13_Leg17" type="revolute">
       <parent link="Leg13"/>
       <child  link="Leg17"/>
       <origin rpy="0 0 0" xyz="2.995592315893305 0.9203574177146963 0" />
     <axis xyz="1 0 0"/>
       <limit effort="0.0" lower="-3.14159" upper="3.14159" velocity="0.0"/>
    </joint>
    <joint name="Leg7_Leg18" type="revolute">
       <parent link="Leg7"/>
       <child  link="Leg18"/>
       <origin rpy="0 0 0" xyz="1.0803332395519745 0.8374866998047883 1.3481296997180068" />
     <axis xyz="1 0 0"/>
       <limit effort="0.0" lower="-3.14159" upper="3.14159" velocity="0.0"/>
    </joint>
    <joint name="Leg18_Leg19" type="revolute">
       <parent link="Leg18"/>
       <child  link="Leg19"/>
       <origin rpy="0 0 0" xyz="0 0 1.9043258020297418" />
     <axis xyz="1 0 0"/>
       <limit effort="0.0" lower="-3.14159" upper="3.14159" velocity="0.0"/>
    </joint>
    <joint name="Leg16_Leg20" type="revolute">
       <parent link="Leg16"/>
       <child  link="Leg20"/>
       <origin rpy="0 0 0" xyz="0.8265715135660308 0.8952828291732057 0" />
     <axis xyz="1 0 0"/>
       <limit effort="0.0" lower="-3.14159" upper="3.14159" velocity="0.0"/>
    </joint>
    <joint name="Leg6_Leg21" type="revolute">
       <parent link="Leg6"/>
       <child  link="Leg21"/>
       <origin rpy="0 0 0" xyz="1.7819681583622016 1.365231557079046 0" />
     <axis xyz="1 0 0"/>
       <limit effort="0.0" lower="-3.14159" upper="3.14159" velocity="0.0"/>
    </joint>
    <joint name="Leg17_Leg22" type="revolute">
       <parent link="Leg17"/>
       <child  link="Leg22"/>
       <origin rpy="0 0 0" xyz="0 0 2.064736339548424" />
     <axis xyz="1 0 0"/>
       <limit effort="0.0" lower="-3.14159" upper="3.14159" velocity="0.0"/>
    </joint>
    <joint name="Leg9_Leg23" type="revolute">
       <parent link="Leg9"/>
       <child  link="Leg23"/>
       <origin rpy="0 0 0" xyz="0.6480546701659742 0 1.383113678959807" />
     <axis xyz="1 0 0"/>
       <limit effort="0.0" lower="-3.14159" upper="3.14159" velocity="0.0"/>
    </joint>
    <joint name="Leg4_Leg24" type="revolute">
       <parent link="Leg4"/>
       <child  link="Leg24"/>
       <origin rpy="0 0 0" xyz="1.2880459086650538 0.6551837641599031 1.1046468852322922" />
     <axis xyz="1 0 0"/>
       <limit effort="0.0" lower="-3.14159" upper="3.14159" velocity="0.0"/>
    </joint>
    <joint name="Leg17_Leg25" type="revolute">
       <parent link="Leg17"/>
       <child  link="Leg25"/>
       <origin rpy="0 0 0" xyz="1.3903445897604145 0 2.064736339548424" />
     <axis xyz="1 0 0"/>
       <limit effort="0.0" lower="-3.14159" upper="3.14159" velocity="0.0"/>
    </joint>
    <joint name="Leg23_Leg26" type="revolute">
       <parent link="Leg23"/>
       <child  link="Leg26"/>
       <origin rpy="0 0 0" xyz="0 1.102531738551056 0" />
     <axis xyz="1 0 0"/>
       <limit effort="0.0" lower="-3.14159" upper="3.14159" velocity="0.0"/>
    </joint>
</robot>