<robot name = "robot">
    <link name="Torso">
        <inertial>
            <origin xyz="0 0 1.0309910367833919" rpy="0 0 0"/>
            <mass value="1" />
            <inertia ixx="100" ixy="0" ixz="0" iyy="100" iyz="0" izz="100" />
        </inertial>
        <visual>
            <origin xyz="0 0 1.0309910367833919" rpy="0 0 0"/>
            <geometry>
                <box size="1.7794614358549061 1.8085463393184327 2.0619820735667838" />
            </geometry>
            <material name="Green">
                <color rgba="0 180.0 0.0 1.0"/>
            </material>
        </visual>
        <collision>
            <origin xyz="0 0 1.0309910367833919" rpy="0 0 0"/>
            <geometry>
                <box size="1.7794614358549061 1.8085463393184327 2.0619820735667838" />
            </geometry>
        </collision>
    </link>
    <link name="Leg1">
        <inertial>
            <origin xyz="0 0 1.202188705129537" rpy="0 0 0"/>
            <mass value="1" />
            <inertia ixx="100" ixy="0" ixz="0" iyy="100" iyz="0" izz="100" />
        </inertial>
        <visual>
            <origin xyz="0 0 1.202188705129537" rpy="0 0 0"/>
            <geometry>
                <box size="2.2778343573585307 1.6786158088650989 2.404377410259074" />
            </geometry>
            <material name="Green">
                <color rgba="0 180.0 0.0 1.0"/>
            </material>
        </visual>
        <collision>
            <origin xyz="0 0 1.202188705129537" rpy="0 0 0"/>
            <geometry>
                <box size="2.2778343573585307 1.6786158088650989 2.404377410259074" />
            </geometry>
        </collision>
    </link>
    <link name="Leg2">
        <inertial>
            <origin xyz="0 1.206715856125164 0" rpy="0 0 0"/>
            <mass value="1" />
            <inertia ixx="100" ixy="0" ixz="0" iyy="100" iyz="0" izz="100" />
        </inertial>
        <visual>
            <origin xyz="0 1.206715856125164 0" rpy="0 0 0"/>
            <geometry>
                <box size="1.2323511657713897 2.413431712250328 2.4860295112323607" />
            </geometry>
            <material name="Green">
                <color rgba="0 180.0 0.0 1.0"/>
            </material>
        </visual>
        <collision>
            <origin xyz="0 1.206715856125164 0" rpy="0 0 0"/>
            <geometry>
                <box size="1.2323511657713897 2.413431712250328 2.4860295112323607" />
            </geometry>
        </collision>
    </link>
    <link name="Leg3">
        <inertial>
            <origin xyz="0 1.113160209821666 0" rpy="0 0 0"/>
            <mass value="1" />
            <inertia ixx="100" ixy="0" ixz="0" iyy="100" iyz="0" izz="100" />
        </inertial>
        <visual>
            <origin xyz="0 1.113160209821666 0" rpy="0 0 0"/>
            <geometry>
                <box size="2.6804157604549204 2.226320419643332 2.517013664642578" />
            </geometry>
            <material name="Green">
                <color rgba="0 180.0 0.0 1.0"/>
            </material>
        </visual>
        <collision>
            <origin xyz="0 1.113160209821666 0" rpy="0 0 0"/>
            <geometry>
                <box size="2.6804157604549204 2.226320419643332 2.517013664642578" />
            </geometry>
        </collision>
    </link>
    <link name="Leg4">
        <inertial>
            <origin xyz="0 0 1.158245653936131" rpy="0 0 0"/>
            <mass value="1" />
            <inertia ixx="100" ixy="0" ixz="0" iyy="100" iyz="0" izz="100" />
        </inertial>
        <visual>
            <origin xyz="0 0 1.158245653936131" rpy="0 0 0"/>
            <geometry>
                <box size="2.1079753548250943 2.4177739753333745 2.316491307872262" />
            </geometry>
            <material name="Green">
                <color rgba="0 180.0 0.0 1.0"/>
            </material>
        </visual>
        <collision>
            <origin xyz="0 0 1.158245653936131" rpy="0 0 0"/>
            <geometry>
                <box size="2.1079753548250943 2.4177739753333745 2.316491307872262" />
            </geometry>
        </collision>
    </link>
    <link name="Leg5">
        <inertial>
            <origin xyz="1.4603264897155 0 0" rpy="0 0 0"/>
            <mass value="1" />
            <inertia ixx="100" ixy="0" ixz="0" iyy="100" iyz="0" izz="100" />
        </inertial>
        <visual>
            <origin xyz="1.4603264897155 0 0" rpy="0 0 0"/>
            <geometry>
                <box size="2.920652979431 1.1302797843306862 1.2375239936435678" />
            </geometry>
            <material name="Blue">
                <color rgba="0 1.0 1.0 1.0"/>
            </material>
        </visual>
        <collision>
            <origin xyz="1.4603264897155 0 0" rpy="0 0 0"/>
            <geometry>
                <box size="2.920652979431 1.1302797843306862 1.2375239936435678" />
            </geometry>
        </collision>
    </link>
    <link name="Leg6">
        <inertial>
            <origin xyz="0.8706656681361636 0 0" rpy="0 0 0"/>
            <mass value="1" />
            <inertia ixx="100" ixy="0" ixz="0" iyy="100" iyz="0" izz="100" />
        </inertial>
        <visual>
            <origin xyz="0.8706656681361636 0 0" rpy="0 0 0"/>
            <geometry>
                <box size="1.7413313362723273 1.9936058265885717 2.3990664174062664" />
            </geometry>
            <material name="Blue">
                <color rgba="0 1.0 1.0 1.0"/>
            </material>
        </visual>
        <collision>
            <origin xyz="0.8706656681361636 0 0" rpy="0 0 0"/>
            <geometry>
                <box size="1.7413313362723273 1.9936058265885717 2.3990664174062664" />
            </geometry>
        </collision>
    </link>
    <link name="Leg7">
        <inertial>
            <origin xyz="0 0.6191667588784242 0" rpy="0 0 0"/>
            <mass value="1" />
            <inertia ixx="100" ixy="0" ixz="0" iyy="100" iyz="0" izz="100" />
        </inertial>
        <visual>
            <origin xyz="0 0.6191667588784242 0" rpy="0 0 0"/>
            <geometry>
                <box size="2.2566675519959425 1.2383335177568484 1.0196974603472784" />
            </geometry>
            <material name="Blue">
                <color rgba="0 1.0 1.0 1.0"/>
            </material>
        </visual>
        <collision>
            <origin xyz="0 0.6191667588784242 0" rpy="0 0 0"/>
            <geometry>
                <box size="2.2566675519959425 1.2383335177568484 1.0196974603472784" />
            </geometry>
        </collision>
    </link>
    <link name="Leg8">
        <inertial>
            <origin xyz="0 0.9358956743791024 0" rpy="0 0 0"/>
            <mass value="1" />
            <inertia ixx="100" ixy="0" ixz="0" iyy="100" iyz="0" izz="100" />
        </inertial>
        <visual>
            <origin xyz="0 0.9358956743791024 0" rpy="0 0 0"/>
            <geometry>
                <box size="1.3582183356609294 1.8717913487582047 2.4996374301860502" />
            </geometry>
            <material name="Blue">
                <color rgba="0 1.0 1.0 1.0"/>
            </material>
        </visual>
        <collision>
            <origin xyz="0 0.9358956743791024 0" rpy="0 0 0"/>
            <geometry>
                <box size="1.3582183356609294 1.8717913487582047 2.4996374301860502" />
            </geometry>
        </collision>
    </link>
    <link name="Leg9">
        <inertial>
            <origin xyz="0.7584009062033905 0 0" rpy="0 0 0"/>
            <mass value="1" />
            <inertia ixx="100" ixy="0" ixz="0" iyy="100" iyz="0" izz="100" />
        </inertial>
        <visual>
            <origin xyz="0.7584009062033905 0 0" rpy="0 0 0"/>
            <geometry>
                <box size="1.516801812406781 1.559926834392322 1.784432182923164" />
            </geometry>
            <material name="Green">
                <color rgba="0 180.0 0.0 1.0"/>
            </material>
        </visual>
        <collision>
            <origin xyz="0.7584009062033905 0 0" rpy="0 0 0"/>
            <geometry>
                <box size="1.516801812406781 1.559926834392322 1.784432182923164" />
            </geometry>
        </collision>
    </link>
    <link name="Leg10">
        <inertial>
            <origin xyz="0 0.7743431567915638 0" rpy="0 0 0"/>
            <mass value="1" />
            <inertia ixx="100" ixy="0" ixz="0" iyy="100" iyz="0" izz="100" />
        </inertial>
        <visual>
            <origin xyz="0 0.7743431567915638 0" rpy="0 0 0"/>
            <geometry>
                <box size="2.346995989196733 1.5486863135831277 2.748518851816314" />
            </geometry>
            <material name="Blue">
                <color rgba="0 1.0 1.0 1.0"/>
            </material>
        </visual>
        <collision>
            <origin xyz="0 0.7743431567915638 0" rpy="0 0 0"/>
            <geometry>
                <box size="2.346995989196733 1.5486863135831277 2.748518851816314" />
            </geometry>
        </collision>
    </link>
    <link name="Leg11">
        <inertial>
            <origin xyz="0 0 1.376059349041913" rpy="0 0 0"/>
            <mass value="1" />
            <inertia ixx="100" ixy="0" ixz="0" iyy="100" iyz="0" izz="100" />
        </inertial>
        <visual>
            <origin xyz="0 0 1.376059349041913" rpy="0 0 0"/>
            <geometry>
                <box size="1.4391745173940853 1.9312408458314807 2.752118698083826" />
            </geometry>
            <material name="Green">
                <color rgba="0 180.0 0.0 1.0"/>
            </material>
        </visual>
        <collision>
            <origin xyz="0 0 1.376059349041913" rpy="0 0 0"/>
            <geometry>
                <box size="1.4391745173940853 1.9312408458314807 2.752118698083826" />
            </geometry>
        </collision>
    </link>
    <link name="Leg12">
        <inertial>
            <origin xyz="0 0.6805664209570071 0" rpy="0 0 0"/>
            <mass value="1" />
            <inertia ixx="100" ixy="0" ixz="0" iyy="100" iyz="0" izz="100" />
        </inertial>
        <visual>
            <origin xyz="0 0.6805664209570071 0" rpy="0 0 0"/>
            <geometry>
                <box size="2.77835565243394 1.3611328419140143 2.0017977376234874" />
            </geometry>
            <material name="Blue">
                <color rgba="0 1.0 1.0 1.0"/>
            </material>
        </visual>
        <collision>
            <origin xyz="0 0.6805664209570071 0" rpy="0 0 0"/>
            <geometry>
                <box size="2.77835565243394 1.3611328419140143 2.0017977376234874" />
            </geometry>
        </collision>
    </link>
    <link name="Leg13">
        <inertial>
            <origin xyz="0 0.9694630617739197 0" rpy="0 0 0"/>
            <mass value="1" />
            <inertia ixx="100" ixy="0" ixz="0" iyy="100" iyz="0" izz="100" />
        </inertial>
        <visual>
            <origin xyz="0 0.9694630617739197 0" rpy="0 0 0"/>
            <geometry>
                <box size="2.8643709267897046 1.9389261235478394 1.2898047910582824" />
            </geometry>
            <material name="Green">
                <color rgba="0 180.0 0.0 1.0"/>
            </material>
        </visual>
        <collision>
            <origin xyz="0 0.9694630617739197 0" rpy="0 0 0"/>
            <geometry>
                <box size="2.8643709267897046 1.9389261235478394 1.2898047910582824" />
            </geometry>
        </collision>
    </link>
    <link name="Leg14">
        <inertial>
            <origin xyz="0 0 0.7607743511255098" rpy="0 0 0"/>
            <mass value="1" />
            <inertia ixx="100" ixy="0" ixz="0" iyy="100" iyz="0" izz="100" />
        </inertial>
        <visual>
            <origin xyz="0 0 0.7607743511255098" rpy="0 0 0"/>
            <geometry>
                <box size="1.485500425330216 2.591485728287049 1.5215487022510197" />
            </geometry>
            <material name="Blue">
                <color rgba="0 1.0 1.0 1.0"/>
            </material>
        </visual>
        <collision>
            <origin xyz="0 0 0.7607743511255098" rpy="0 0 0"/>
            <geometry>
                <box size="1.485500425330216 2.591485728287049 1.5215487022510197" />
            </geometry>
        </collision>
    </link>
    <link name="Leg15">
        <inertial>
            <origin xyz="0 0 0.9513695338583074" rpy="0 0 0"/>
            <mass value="1" />
            <inertia ixx="100" ixy="0" ixz="0" iyy="100" iyz="0" izz="100" />
        </inertial>
        <visual>
            <origin xyz="0 0 0.9513695338583074" rpy="0 0 0"/>
            <geometry>
                <box size="1.6953517534513438 1.546607569862258 1.9027390677166147" />
            </geometry>
            <material name="Green">
                <color rgba="0 180.0 0.0 1.0"/>
            </material>
        </visual>
        <collision>
            <origin xyz="0 0 0.9513695338583074" rpy="0 0 0"/>
            <geometry>
                <box size="1.6953517534513438 1.546607569862258 1.9027390677166147" />
            </geometry>
        </collision>
    </link>
    <link name="Leg16">
        <inertial>
            <origin xyz="0 1.2311596933597553 0" rpy="0 0 0"/>
            <mass value="1" />
            <inertia ixx="100" ixy="0" ixz="0" iyy="100" iyz="0" izz="100" />
        </inertial>
        <visual>
            <origin xyz="0 1.2311596933597553 0" rpy="0 0 0"/>
            <geometry>
                <box size="2.486132290527459 2.4623193867195106 1.2975413226502903" />
            </geometry>
            <material name="Blue">
                <color rgba="0 1.0 1.0 1.0"/>
            </material>
        </visual>
        <collision>
            <origin xyz="0 1.2311596933597553 0" rpy="0 0 0"/>
            <geometry>
                <box size="2.486132290527459 2.4623193867195106 1.2975413226502903" />
            </geometry>
        </collision>
    </link>
    <link name="Leg17">
        <inertial>
            <origin xyz="0 1.3699313660521757 0" rpy="0 0 0"/>
            <mass value="1" />
            <inertia ixx="100" ixy="0" ixz="0" iyy="100" iyz="0" izz="100" />
        </inertial>
        <visual>
            <origin xyz="0 1.3699313660521757 0" rpy="0 0 0"/>
            <geometry>
                <box size="1.3499072620982795 2.7398627321043514 2.1334230260429266" />
            </geometry>
            <material name="Blue">
                <color rgba="0 1.0 1.0 1.0"/>
            </material>
        </visual>
        <collision>
            <origin xyz="0 1.3699313660521757 0" rpy="0 0 0"/>
            <geometry>
                <box size="1.3499072620982795 2.7398627321043514 2.1334230260429266" />
            </geometry>
        </collision>
    </link>
    <link name="Leg18">
        <inertial>
            <origin xyz="1.2201097561618397 0 0" rpy="0 0 0"/>
            <mass value="1" />
            <inertia ixx="100" ixy="0" ixz="0" iyy="100" iyz="0" izz="100" />
        </inertial>
        <visual>
            <origin xyz="1.2201097561618397 0 0" rpy="0 0 0"/>
            <geometry>
                <box size="2.4402195123236794 2.1825112461478877 2.1274132627246405" />
            </geometry>
            <material name="Blue">
                <color rgba="0 1.0 1.0 1.0"/>
            </material>
        </visual>
        <collision>
            <origin xyz="1.2201097561618397 0 0" rpy="0 0 0"/>
            <geometry>
                <box size="2.4402195123236794 2.1825112461478877 2.1274132627246405" />
            </geometry>
        </collision>
    </link>
    <link name="Leg19">
        <inertial>
            <origin xyz="0 0 0.9025288049746111" rpy="0 0 0"/>
            <mass value="1" />
            <inertia ixx="100" ixy="0" ixz="0" iyy="100" iyz="0" izz="100" />
        </inertial>
        <visual>
            <origin xyz="0 0 0.9025288049746111" rpy="0 0 0"/>
            <geometry>
                <box size="2.5651038216035547 1.0548320280522114 1.8050576099492222" />
            </geometry>
            <material name="Green">
                <color rgba="0 180.0 0.0 1.0"/>
            </material>
        </visual>
        <collision>
            <origin xyz="0 0 0.9025288049746111" rpy="0 0 0"/>
            <geometry>
                <box size="2.5651038216035547 1.0548320280522114 1.8050576099492222" />
            </geometry>
        </collision>
    </link>
    <link name="Leg20">
        <inertial>
            <origin xyz="0 0 0.87695126272182" rpy="0 0 0"/>
            <mass value="1" />
            <inertia ixx="100" ixy="0" ixz="0" iyy="100" iyz="0" izz="100" />
        </inertial>
        <visual>
            <origin xyz="0 0 0.87695126272182" rpy="0 0 0"/>
            <geometry>
                <box size="1.1867637550808152 1.4978358275927905 1.75390252544364" />
            </geometry>
            <material name="Blue">
                <color rgba="0 1.0 1.0 1.0"/>
            </material>
        </visual>
        <collision>
            <origin xyz="0 0 0.87695126272182" rpy="0 0 0"/>
            <geometry>
                <box size="1.1867637550808152 1.4978358275927905 1.75390252544364" />
            </geometry>
        </collision>
    </link>
    <link name="Leg21">
        <inertial>
            <origin xyz="0 0 1.0185713924854782" rpy="0 0 0"/>
            <mass value="1" />
            <inertia ixx="100" ixy="0" ixz="0" iyy="100" iyz="0" izz="100" />
        </inertial>
        <visual>
            <origin xyz="0 0 1.0185713924854782" rpy="0 0 0"/>
            <geometry>
                <box size="1.594989998161754 2.074996864445928 2.0371427849709565" />
            </geometry>
            <material name="Blue">
                <color rgba="0 1.0 1.0 1.0"/>
            </material>
        </visual>
        <collision>
            <origin xyz="0 0 1.0185713924854782" rpy="0 0 0"/>
            <geometry>
                <box size="1.594989998161754 2.074996864445928 2.0371427849709565" />
            </geometry>
        </collision>
    </link>
    <link name="Leg22">
        <inertial>
            <origin xyz="0 1.278580265446415 0" rpy="0 0 0"/>
            <mass value="1" />
            <inertia ixx="100" ixy="0" ixz="0" iyy="100" iyz="0" izz="100" />
        </inertial>
        <visual>
            <origin xyz="0 1.278580265446415 0" rpy="0 0 0"/>
            <geometry>
                <box size="1.3872176915923204 2.55716053089283 1.1876147259644914" />
            </geometry>
            <material name="Green">
                <color rgba="0 180.0 0.0 1.0"/>
            </material>
        </visual>
        <collision>
            <origin xyz="0 1.278580265446415 0" rpy="0 0 0"/>
            <geometry>
                <box size="1.3872176915923204 2.55716053089283 1.1876147259644914" />
            </geometry>
        </collision>
    </link>
    <link name="Leg23">
        <inertial>
            <origin xyz="0 1.3547248908205218 0" rpy="0 0 0"/>
            <mass value="1" />
            <inertia ixx="100" ixy="0" ixz="0" iyy="100" iyz="0" izz="100" />
        </inertial>
        <visual>
            <origin xyz="0 1.3547248908205218 0" rpy="0 0 0"/>
            <geometry>
                <box size="2.605557050585334 2.7094497816410437 1.8719639399665484" />
            </geometry>
            <material name="Blue">
                <color rgba="0 1.0 1.0 1.0"/>
            </material>
        </visual>
        <collision>
            <origin xyz="0 1.3547248908205218 0" rpy="0 0 0"/>
            <geometry>
                <box size="2.605557050585334 2.7094497816410437 1.8719639399665484" />
            </geometry>
        </collision>
    </link>
    <link name="Leg24">
        <inertial>
            <origin xyz="0 1.4188397233055163 0" rpy="0 0 0"/>
            <mass value="1" />
            <inertia ixx="100" ixy="0" ixz="0" iyy="100" iyz="0" izz="100" />
        </inertial>
        <visual>
            <origin xyz="0 1.4188397233055163 0" rpy="0 0 0"/>
            <geometry>
                <box size="2.7210316824181433 2.8376794466110327 2.724714699686844" />
            </geometry>
            <material name="Blue">
                <color rgba="0 1.0 1.0 1.0"/>
            </material>
        </visual>
        <collision>
            <origin xyz="0 1.4188397233055163 0" rpy="0 0 0"/>
            <geometry>
                <box size="2.7210316824181433 2.8376794466110327 2.724714699686844" />
            </geometry>
        </collision>
    </link>
    <link name="Leg25">
        <inertial>
            <origin xyz="0 0 0.5494783402298049" rpy="0 0 0"/>
            <mass value="1" />
            <inertia ixx="100" ixy="0" ixz="0" iyy="100" iyz="0" izz="100" />
        </inertial>
        <visual>
            <origin xyz="0 0 0.5494783402298049" rpy="0 0 0"/>
            <geometry>
                <box size="1.949625323014166 2.4927824071337383 1.0989566804596098" />
            </geometry>
            <material name="Green">
                <color rgba="0 180.0 0.0 1.0"/>
            </material>
        </visual>
        <collision>
            <origin xyz="0 0 0.5494783402298049" rpy="0 0 0"/>
            <geometry>
                <box size="1.949625323014166 2.4927824071337383 1.0989566804596098" />
            </geometry>
        </collision>
    </link>
    <link name="Leg26">
        <inertial>
            <origin xyz="1.4064803861736284 0 0" rpy="0 0 0"/>
            <mass value="1" />
            <inertia ixx="100" ixy="0" ixz="0" iyy="100" iyz="0" izz="100" />
        </inertial>
        <visual>
            <origin xyz="1.4064803861736284 0 0" rpy="0 0 0"/>
            <geometry>
                <box size="2.8129607723472567 2.4623013783602614 1.9725093752368013" />
            </geometry>
            <material name="Blue">
                <color rgba="0 1.0 1.0 1.0"/>
            </material>
        </visual>
        <collision>
            <origin xyz="1.4064803861736284 0 0" rpy="0 0 0"/>
            <geometry>
                <box size="2.8129607723472567 2.4623013783602614 1.9725093752368013" />
            </geometry>
        </collision>
    </link>
    <link name="Leg27">
        <inertial>
            <origin xyz="0 0 1.2073546547880496" rpy="0 0 0"/>
            <mass value="1" />
            <inertia ixx="100" ixy="0" ixz="0" iyy="100" iyz="0" izz="100" />
        </inertial>
        <visual>
            <origin xyz="0 0 1.2073546547880496" rpy="0 0 0"/>
            <geometry>
                <box size="2.889237714723328 1.000358647557889 2.414709309576099" />
            </geometry>
            <material name="Blue">
                <color rgba="0 1.0 1.0 1.0"/>
            </material>
        </visual>
        <collision>
            <origin xyz="0 0 1.2073546547880496" rpy="0 0 0"/>
            <geometry>
                <box size="2.889237714723328 1.000358647557889 2.414709309576099" />
            </geometry>
        </collision>
    </link>
    <link name="Leg28">
        <inertial>
            <origin xyz="0 0 0.6808730397490518" rpy="0 0 0"/>
            <mass value="1" />
            <inertia ixx="100" ixy="0" ixz="0" iyy="100" iyz="0" izz="100" />
        </inertial>
        <visual>
            <origin xyz="0 0 0.6808730397490518" rpy="0 0 0"/>
            <geometry>
                <box size="1.9589007222340216 2.310731465073328 1.3617460794981036" />
            </geometry>
            <material name="Blue">
                <color rgba="0 1.0 1.0 1.0"/>
            </material>
        </visual>
        <collision>
            <origin xyz="0 0 0.6808730397490518" rpy="0 0 0"/>
            <geometry>
                <box size="1.9589007222340216 2.310731465073328 1.3617460794981036" />
            </geometry>
        </collision>
    </link>
    <joint name="Torso_Leg1" type="revolute">
       <parent link="Torso"/>
       <child  link="Leg1"/>
       <origin rpy="0 0 0" xyz="0 0 2.0619820735667838" />
     <axis xyz="1 0 0"/>
       <limit effort="0.0" lower="-3.14159" upper="3.14159" velocity="0.0"/>
    </joint>
    <joint name="Leg1_Leg2" type="revolute">
       <parent link="Leg1"/>
       <child  link="Leg2"/>
       <origin rpy="0 0 0" xyz="0 2.413431712250328 0" />
     <axis xyz="1 0 0"/>
       <limit effort="0.0" lower="-3.14159" upper="3.14159" velocity="0.0"/>
    </joint>
    <joint name="Torso_Leg3" type="revolute">
       <parent link="Torso"/>
       <child  link="Leg3"/>
       <origin rpy="0 0 0" xyz="0 0.8393079044325494 1.202188705129537" />
     <axis xyz="1 0 0"/>
       <limit effort="0.0" lower="-3.14159" upper="3.14159" velocity="0.0"/>
    </joint>
    <joint name="Leg3_Leg4" type="revolute">
       <parent link="Leg3"/>
       <child  link="Leg4"/>
       <origin rpy="0 0 0" xyz="0 0 2.316491307872262" />
     <axis xyz="1 0 0"/>
       <limit effort="0.0" lower="-3.14159" upper="3.14159" velocity="0.0"/>
    </joint>
    <joint name="Leg3_Leg5" type="revolute">
       <parent link="Leg3"/>
       <child  link="Leg5"/>
       <origin rpy="0 0 0" xyz="1.0539876774125472 0 2.316491307872262" />
     <axis xyz="1 0 0"/>
       <limit effort="0.0" lower="-3.14159" upper="3.14159" velocity="0.0"/>
    </joint>
    <joint name="Leg1_Leg6" type="revolute">
       <parent link="Leg1"/>
       <child  link="Leg6"/>
       <origin rpy="0 0 0" xyz="0.6161755828856949 2.413431712250328 0" />
     <axis xyz="1 0 0"/>
       <limit effort="0.0" lower="-3.14159" upper="3.14159" velocity="0.0"/>
    </joint>
    <joint name="Leg4_Leg7" type="revolute">
       <parent link="Leg4"/>
       <child  link="Leg7"/>
       <origin rpy="0 0 0" xyz="1.4603264897155 0.5651398921653431 0" />
     <axis xyz="1 0 0"/>
       <limit effort="0.0" lower="-3.14159" upper="3.14159" velocity="0.0"/>
    </joint>
    <joint name="Leg7_Leg8" type="revolute">
       <parent link="Leg7"/>
       <child  link="Leg8"/>
       <origin rpy="0 0 0" xyz="0 1.8717913487582047 0" />
     <axis xyz="1 0 0"/>
       <limit effort="0.0" lower="-3.14159" upper="3.14159" velocity="0.0"/>
    </joint>
    <joint name="Torso_Leg9" type="revolute">
       <parent link="Torso"/>
       <child  link="Leg9"/>
       <origin rpy="0 0 0" xyz="1.1389171786792653 0.8393079044325494 1.202188705129537" />
     <axis xyz="1 0 0"/>
       <limit effort="0.0" lower="-3.14159" upper="3.14159" velocity="0.0"/>
    </joint>
    <joint name="Leg9_Leg10" type="revolute">
       <parent link="Leg9"/>
       <child  link="Leg10"/>
       <origin rpy="0 0 0" xyz="0 1.5486863135831277 0" />
     <axis xyz="1 0 0"/>
       <limit effort="0.0" lower="-3.14159" upper="3.14159" velocity="0.0"/>
    </joint>
    <joint name="Leg4_Leg11" type="revolute">
       <parent link="Leg4"/>
       <child  link="Leg11"/>
       <origin rpy="0 0 0" xyz="1.4603264897155 0.5651398921653431 0.6187619968217839" />
     <axis xyz="1 0 0"/>
       <limit effort="0.0" lower="-3.14159" upper="3.14159" velocity="0.0"/>
    </joint>
    <joint name="Leg11_Leg12" type="revolute">
       <parent link="Leg11"/>
       <child  link="Leg12"/>
       <origin rpy="0 0 0" xyz="0 1.3611328419140143 0" />
     <axis xyz="1 0 0"/>
       <limit effort="0.0" lower="-3.14159" upper="3.14159" velocity="0.0"/>
    </joint>
    <joint name="Leg6_Leg13" type="revolute">
       <parent link="Leg6"/>
       <child  link="Leg13"/>
       <origin rpy="0 0 0" xyz="0 1.2383335177568484 0" />
     <axis xyz="1 0 0"/>
       <limit effort="0.0" lower="-3.14159" upper="3.14159" velocity="0.0"/>
    </joint>
    <joint name="Leg5_Leg14" type="revolute">
       <parent link="Leg5"/>
       <child  link="Leg14"/>
       <origin rpy="0 0 0" xyz="0.8706656681361636 0 1.1995332087031332" />
     <axis xyz="1 0 0"/>
       <limit effort="0.0" lower="-3.14159" upper="3.14159" velocity="0.0"/>
    </joint>
    <joint name="Leg6_Leg15" type="revolute">
       <parent link="Leg6"/>
       <child  link="Leg15"/>
       <origin rpy="0 0 0" xyz="0 1.2383335177568484 0.5098487301736392" />
     <axis xyz="1 0 0"/>
       <limit effort="0.0" lower="-3.14159" upper="3.14159" velocity="0.0"/>
    </joint>
    <joint name="Leg12_Leg16" type="revolute">
       <parent link="Leg12"/>
       <child  link="Leg16"/>
       <origin rpy="0 0 0" xyz="0 1.9389261235478394 0" />
     <axis xyz="1 0 0"/>
       <limit effort="0.0" lower="-3.14159" upper="3.14159" velocity="0.0"/>
    </joint>
    <joint name="Leg16_Leg17" type="revolute">
       <parent link="Leg16"/>
       <child  link="Leg17"/>
       <origin rpy="0 0 0" xyz="0 2.7398627321043514 0" />
     <axis xyz="1 0 0"/>
       <limit effort="0.0" lower="-3.14159" upper="3.14159" velocity="0.0"/>
    </joint>
    <joint name="Leg11_Leg18" type="revolute">
       <parent link="Leg11"/>
       <child  link="Leg18"/>
       <origin rpy="0 0 0" xyz="1.38917782621697 1.3611328419140143 0" />
     <axis xyz="1 0 0"/>
       <limit effort="0.0" lower="-3.14159" upper="3.14159" velocity="0.0"/>
    </joint>
    <joint name="Leg11_Leg19" type="revolute">
       <parent link="Leg11"/>
       <child  link="Leg19"/>
       <origin rpy="0 0 0" xyz="1.38917782621697 1.3611328419140143 1.0008988688117437" />
     <axis xyz="1 0 0"/>
       <limit effort="0.0" lower="-3.14159" upper="3.14159" velocity="0.0"/>
    </joint>
    <joint name="Leg17_Leg20" type="revolute">
       <parent link="Leg17"/>
       <child  link="Leg20"/>
       <origin rpy="0 0 0" xyz="1.2201097561618397 0 1.0637066313623202" />
     <axis xyz="1 0 0"/>
       <limit effort="0.0" lower="-3.14159" upper="3.14159" velocity="0.0"/>
    </joint>
    <joint name="Leg19_Leg21" type="revolute">
       <parent link="Leg19"/>
       <child  link="Leg21"/>
       <origin rpy="0 0 0" xyz="0 0 1.75390252544364" />
     <axis xyz="1 0 0"/>
       <limit effort="0.0" lower="-3.14159" upper="3.14159" velocity="0.0"/>
    </joint>
    <joint name="Leg20_Leg22" type="revolute">
       <parent link="Leg20"/>
       <child  link="Leg22"/>
       <origin rpy="0 0 0" xyz="0 1.037498432222964 1.0185713924854782" />
     <axis xyz="1 0 0"/>
       <limit effort="0.0" lower="-3.14159" upper="3.14159" velocity="0.0"/>
    </joint>
    <joint name="Leg21_Leg23" type="revolute">
       <parent link="Leg21"/>
       <child  link="Leg23"/>
       <origin rpy="0 0 0" xyz="0 2.55716053089283 0" />
     <axis xyz="1 0 0"/>
       <limit effort="0.0" lower="-3.14159" upper="3.14159" velocity="0.0"/>
    </joint>
    <joint name="Leg5_Leg24" type="revolute">
       <parent link="Leg5"/>
       <child  link="Leg24"/>
       <origin rpy="0 0 0" xyz="0.8706656681361636 0.9968029132942858 1.1995332087031332" />
     <axis xyz="1 0 0"/>
       <limit effort="0.0" lower="-3.14159" upper="3.14159" velocity="0.0"/>
    </joint>
    <joint name="Leg16_Leg25" type="revolute">
       <parent link="Leg16"/>
       <child  link="Leg25"/>
       <origin rpy="0 0 0" xyz="0 2.7398627321043514 1.0667115130214633" />
     <axis xyz="1 0 0"/>
       <limit effort="0.0" lower="-3.14159" upper="3.14159" velocity="0.0"/>
    </joint>
    <joint name="Leg9_Leg26" type="revolute">
       <parent link="Leg9"/>
       <child  link="Leg26"/>
       <origin rpy="0 0 0" xyz="1.1734979945983666 1.5486863135831277 0" />
     <axis xyz="1 0 0"/>
       <limit effort="0.0" lower="-3.14159" upper="3.14159" velocity="0.0"/>
    </joint>
    <joint name="Leg23_Leg27" type="revolute">
       <parent link="Leg23"/>
       <child  link="Leg27"/>
       <origin rpy="0 0 0" xyz="0 1.4188397233055163 1.362357349843422" />
     <axis xyz="1 0 0"/>
       <limit effort="0.0" lower="-3.14159" upper="3.14159" velocity="0.0"/>
    </joint>
    <joint name="Leg1_Leg28" type="revolute">
       <parent link="Leg1"/>
       <child  link="Leg28"/>
       <origin rpy="0 0 0" xyz="0.6161755828856949 2.413431712250328 1.2430147556161804" />
     <axis xyz="1 0 0"/>
       <limit effort="0.0" lower="-3.14159" upper="3.14159" velocity="0.0"/>
    </joint>
</robot>