<robot name = "robot">
    <link name="Torso">
        <inertial>
            <origin xyz="0 0 0.9275687424606586" rpy="0 0 0"/>
            <mass value="1" />
            <inertia ixx="100" ixy="0" ixz="0" iyy="100" iyz="0" izz="100" />
        </inertial>
        <visual>
            <origin xyz="0 0 0.9275687424606586" rpy="0 0 0"/>
            <geometry>
                <box size="2.189596206675268 1.7398667950990903 1.8551374849213171" />
            </geometry>
            <material name="Green">
                <color rgba="0 180.0 0.0 1.0"/>
            </material>
        </visual>
        <collision>
            <origin xyz="0 0 0.9275687424606586" rpy="0 0 0"/>
            <geometry>
                <box size="2.189596206675268 1.7398667950990903 1.8551374849213171" />
            </geometry>
        </collision>
    </link>
    <link name="Leg1">
        <inertial>
            <origin xyz="1.0431775784293724 0 0" rpy="0 0 0"/>
            <mass value="1" />
            <inertia ixx="100" ixy="0" ixz="0" iyy="100" iyz="0" izz="100" />
        </inertial>
        <visual>
            <origin xyz="1.0431775784293724 0 0" rpy="0 0 0"/>
            <geometry>
                <box size="2.086355156858745 1.807927733219625 1.9449067802665156" />
            </geometry>
            <material name="Blue">
                <color rgba="0 1.0 1.0 1.0"/>
            </material>
        </visual>
        <collision>
            <origin xyz="1.0431775784293724 0 0" rpy="0 0 0"/>
            <geometry>
                <box size="2.086355156858745 1.807927733219625 1.9449067802665156" />
            </geometry>
        </collision>
    </link>
    <link name="Leg2">
        <inertial>
            <origin xyz="0 0 1.466800821352921" rpy="0 0 0"/>
            <mass value="1" />
            <inertia ixx="100" ixy="0" ixz="0" iyy="100" iyz="0" izz="100" />
        </inertial>
        <visual>
            <origin xyz="0 0 1.466800821352921" rpy="0 0 0"/>
            <geometry>
                <box size="2.0092758156141604 1.9683455165312524 2.933601642705842" />
            </geometry>
            <material name="Green">
                <color rgba="0 180.0 0.0 1.0"/>
            </material>
        </visual>
        <collision>
            <origin xyz="0 0 1.466800821352921" rpy="0 0 0"/>
            <geometry>
                <box size="2.0092758156141604 1.9683455165312524 2.933601642705842" />
            </geometry>
        </collision>
    </link>
    <link name="Leg3">
        <inertial>
            <origin xyz="0 1.2653435279452498 0" rpy="0 0 0"/>
            <mass value="1" />
            <inertia ixx="100" ixy="0" ixz="0" iyy="100" iyz="0" izz="100" />
        </inertial>
        <visual>
            <origin xyz="0 1.2653435279452498 0" rpy="0 0 0"/>
            <geometry>
                <box size="1.4482418048081358 2.5306870558904997 1.7356084158350389" />
            </geometry>
            <material name="Green">
                <color rgba="0 180.0 0.0 1.0"/>
            </material>
        </visual>
        <collision>
            <origin xyz="0 1.2653435279452498 0" rpy="0 0 0"/>
            <geometry>
                <box size="1.4482418048081358 2.5306870558904997 1.7356084158350389" />
            </geometry>
        </collision>
    </link>
    <link name="Leg4">
        <inertial>
            <origin xyz="0 0.5782836229836833 0" rpy="0 0 0"/>
            <mass value="1" />
            <inertia ixx="100" ixy="0" ixz="0" iyy="100" iyz="0" izz="100" />
        </inertial>
        <visual>
            <origin xyz="0 0.5782836229836833 0" rpy="0 0 0"/>
            <geometry>
                <box size="2.3492832243642066 1.1565672459673666 2.69819478254539" />
            </geometry>
            <material name="Blue">
                <color rgba="0 1.0 1.0 1.0"/>
            </material>
        </visual>
        <collision>
            <origin xyz="0 0.5782836229836833 0" rpy="0 0 0"/>
            <geometry>
                <box size="2.3492832243642066 1.1565672459673666 2.69819478254539" />
            </geometry>
        </collision>
    </link>
    <link name="Leg5">
        <inertial>
            <origin xyz="0 0.7740727251279488 0" rpy="0 0 0"/>
            <mass value="1" />
            <inertia ixx="100" ixy="0" ixz="0" iyy="100" iyz="0" izz="100" />
        </inertial>
        <visual>
            <origin xyz="0 0.7740727251279488 0" rpy="0 0 0"/>
            <geometry>
                <box size="1.3119184435610123 1.5481454502558976 1.2600937085094415" />
            </geometry>
            <material name="Blue">
                <color rgba="0 1.0 1.0 1.0"/>
            </material>
        </visual>
        <collision>
            <origin xyz="0 0.7740727251279488 0" rpy="0 0 0"/>
            <geometry>
                <box size="1.3119184435610123 1.5481454502558976 1.2600937085094415" />
            </geometry>
        </collision>
    </link>
    <link name="Leg6">
        <inertial>
            <origin xyz="1.3556590572573688 0 0" rpy="0 0 0"/>
            <mass value="1" />
            <inertia ixx="100" ixy="0" ixz="0" iyy="100" iyz="0" izz="100" />
        </inertial>
        <visual>
            <origin xyz="1.3556590572573688 0 0" rpy="0 0 0"/>
            <geometry>
                <box size="2.7113181145147376 1.816347976372355 2.2961173071063534" />
            </geometry>
            <material name="Green">
                <color rgba="0 180.0 0.0 1.0"/>
            </material>
        </visual>
        <collision>
            <origin xyz="1.3556590572573688 0 0" rpy="0 0 0"/>
            <geometry>
                <box size="2.7113181145147376 1.816347976372355 2.2961173071063534" />
            </geometry>
        </collision>
    </link>
    <link name="Leg7">
        <inertial>
            <origin xyz="0 0.6146222789266418 0" rpy="0 0 0"/>
            <mass value="1" />
            <inertia ixx="100" ixy="0" ixz="0" iyy="100" iyz="0" izz="100" />
        </inertial>
        <visual>
            <origin xyz="0 0.6146222789266418 0" rpy="0 0 0"/>
            <geometry>
                <box size="2.324081789562938 1.2292445578532836 1.6251507311684101" />
            </geometry>
            <material name="Green">
                <color rgba="0 180.0 0.0 1.0"/>
            </material>
        </visual>
        <collision>
            <origin xyz="0 0.6146222789266418 0" rpy="0 0 0"/>
            <geometry>
                <box size="2.324081789562938 1.2292445578532836 1.6251507311684101" />
            </geometry>
        </collision>
    </link>
    <link name="Leg8">
        <inertial>
            <origin xyz="0.9315609852969103 0 0" rpy="0 0 0"/>
            <mass value="1" />
            <inertia ixx="100" ixy="0" ixz="0" iyy="100" iyz="0" izz="100" />
        </inertial>
        <visual>
            <origin xyz="0.9315609852969103 0 0" rpy="0 0 0"/>
            <geometry>
                <box size="1.8631219705938207 2.602280075468694 2.038663075862883" />
            </geometry>
            <material name="Blue">
                <color rgba="0 1.0 1.0 1.0"/>
            </material>
        </visual>
        <collision>
            <origin xyz="0.9315609852969103 0 0" rpy="0 0 0"/>
            <geometry>
                <box size="1.8631219705938207 2.602280075468694 2.038663075862883" />
            </geometry>
        </collision>
    </link>
    <link name="Leg9">
        <inertial>
            <origin xyz="0 0 0.8345658245303907" rpy="0 0 0"/>
            <mass value="1" />
            <inertia ixx="100" ixy="0" ixz="0" iyy="100" iyz="0" izz="100" />
        </inertial>
        <visual>
            <origin xyz="0 0 0.8345658245303907" rpy="0 0 0"/>
            <geometry>
                <box size="1.3194590173448142 1.4560058203538149 1.6691316490607815" />
            </geometry>
            <material name="Green">
                <color rgba="0 180.0 0.0 1.0"/>
            </material>
        </visual>
        <collision>
            <origin xyz="0 0 0.8345658245303907" rpy="0 0 0"/>
            <geometry>
                <box size="1.3194590173448142 1.4560058203538149 1.6691316490607815" />
            </geometry>
        </collision>
    </link>
    <link name="Leg10">
        <inertial>
            <origin xyz="0 0.6600392378143071 0" rpy="0 0 0"/>
            <mass value="1" />
            <inertia ixx="100" ixy="0" ixz="0" iyy="100" iyz="0" izz="100" />
        </inertial>
        <visual>
            <origin xyz="0 0.6600392378143071 0" rpy="0 0 0"/>
            <geometry>
                <box size="1.497031220619577 1.3200784756286141 1.5789360080219426" />
            </geometry>
            <material name="Green">
                <color rgba="0 180.0 0.0 1.0"/>
            </material>
        </visual>
        <collision>
            <origin xyz="0 0.6600392378143071 0" rpy="0 0 0"/>
            <geometry>
                <box size="1.497031220619577 1.3200784756286141 1.5789360080219426" />
            </geometry>
        </collision>
    </link>
    <link name="Leg11">
        <inertial>
            <origin xyz="0 1.3827400238663028 0" rpy="0 0 0"/>
            <mass value="1" />
            <inertia ixx="100" ixy="0" ixz="0" iyy="100" iyz="0" izz="100" />
        </inertial>
        <visual>
            <origin xyz="0 1.3827400238663028 0" rpy="0 0 0"/>
            <geometry>
                <box size="2.2291924862455734 2.7654800477326056 2.131329773117561" />
            </geometry>
            <material name="Green">
                <color rgba="0 180.0 0.0 1.0"/>
            </material>
        </visual>
        <collision>
            <origin xyz="0 1.3827400238663028 0" rpy="0 0 0"/>
            <geometry>
                <box size="2.2291924862455734 2.7654800477326056 2.131329773117561" />
            </geometry>
        </collision>
    </link>
    <link name="Leg12">
        <inertial>
            <origin xyz="0 0 0.7968623593482466" rpy="0 0 0"/>
            <mass value="1" />
            <inertia ixx="100" ixy="0" ixz="0" iyy="100" iyz="0" izz="100" />
        </inertial>
        <visual>
            <origin xyz="0 0 0.7968623593482466" rpy="0 0 0"/>
            <geometry>
                <box size="2.973791417715475 1.7559723622256418 1.5937247186964931" />
            </geometry>
            <material name="Blue">
                <color rgba="0 1.0 1.0 1.0"/>
            </material>
        </visual>
        <collision>
            <origin xyz="0 0 0.7968623593482466" rpy="0 0 0"/>
            <geometry>
                <box size="2.973791417715475 1.7559723622256418 1.5937247186964931" />
            </geometry>
        </collision>
    </link>
    <link name="Leg13">
        <inertial>
            <origin xyz="0 0 0.7082801737666234" rpy="0 0 0"/>
            <mass value="1" />
            <inertia ixx="100" ixy="0" ixz="0" iyy="100" iyz="0" izz="100" />
        </inertial>
        <visual>
            <origin xyz="0 0 0.7082801737666234" rpy="0 0 0"/>
            <geometry>
                <box size="2.203399602412297 1.9257075598673625 1.4165603475332469" />
            </geometry>
            <material name="Green">
                <color rgba="0 180.0 0.0 1.0"/>
            </material>
        </visual>
        <collision>
            <origin xyz="0 0 0.7082801737666234" rpy="0 0 0"/>
            <geometry>
                <box size="2.203399602412297 1.9257075598673625 1.4165603475332469" />
            </geometry>
        </collision>
    </link>
    <link name="Leg14">
        <inertial>
            <origin xyz="0.6178955479855139 0 0" rpy="0 0 0"/>
            <mass value="1" />
            <inertia ixx="100" ixy="0" ixz="0" iyy="100" iyz="0" izz="100" />
        </inertial>
        <visual>
            <origin xyz="0.6178955479855139 0 0" rpy="0 0 0"/>
            <geometry>
                <box size="1.2357910959710279 2.2114346836332697 2.611580226566649" />
            </geometry>
            <material name="Blue">
                <color rgba="0 1.0 1.0 1.0"/>
            </material>
        </visual>
        <collision>
            <origin xyz="0.6178955479855139 0 0" rpy="0 0 0"/>
            <geometry>
                <box size="1.2357910959710279 2.2114346836332697 2.611580226566649" />
            </geometry>
        </collision>
    </link>
    <link name="Leg15">
        <inertial>
            <origin xyz="0 0 0.7095391543467862" rpy="0 0 0"/>
            <mass value="1" />
            <inertia ixx="100" ixy="0" ixz="0" iyy="100" iyz="0" izz="100" />
        </inertial>
        <visual>
            <origin xyz="0 0 0.7095391543467862" rpy="0 0 0"/>
            <geometry>
                <box size="2.3000174456529563 2.700127087455259 1.4190783086935723" />
            </geometry>
            <material name="Green">
                <color rgba="0 180.0 0.0 1.0"/>
            </material>
        </visual>
        <collision>
            <origin xyz="0 0 0.7095391543467862" rpy="0 0 0"/>
            <geometry>
                <box size="2.3000174456529563 2.700127087455259 1.4190783086935723" />
            </geometry>
        </collision>
    </link>
    <link name="Leg16">
        <inertial>
            <origin xyz="0 0 1.0785218033099104" rpy="0 0 0"/>
            <mass value="1" />
            <inertia ixx="100" ixy="0" ixz="0" iyy="100" iyz="0" izz="100" />
        </inertial>
        <visual>
            <origin xyz="0 0 1.0785218033099104" rpy="0 0 0"/>
            <geometry>
                <box size="2.8258122249675055 2.0591099785967466 2.157043606619821" />
            </geometry>
            <material name="Green">
                <color rgba="0 180.0 0.0 1.0"/>
            </material>
        </visual>
        <collision>
            <origin xyz="0 0 1.0785218033099104" rpy="0 0 0"/>
            <geometry>
                <box size="2.8258122249675055 2.0591099785967466 2.157043606619821" />
            </geometry>
        </collision>
    </link>
    <link name="Leg17">
        <inertial>
            <origin xyz="0 0 1.105011179070707" rpy="0 0 0"/>
            <mass value="1" />
            <inertia ixx="100" ixy="0" ixz="0" iyy="100" iyz="0" izz="100" />
        </inertial>
        <visual>
            <origin xyz="0 0 1.105011179070707" rpy="0 0 0"/>
            <geometry>
                <box size="2.4490483838773245 2.8293712466509184 2.210022358141414" />
            </geometry>
            <material name="Green">
                <color rgba="0 180.0 0.0 1.0"/>
            </material>
        </visual>
        <collision>
            <origin xyz="0 0 1.105011179070707" rpy="0 0 0"/>
            <geometry>
                <box size="2.4490483838773245 2.8293712466509184 2.210022358141414" />
            </geometry>
        </collision>
    </link>
    <link name="Leg18">
        <inertial>
            <origin xyz="0 0.951336932529339 0" rpy="0 0 0"/>
            <mass value="1" />
            <inertia ixx="100" ixy="0" ixz="0" iyy="100" iyz="0" izz="100" />
        </inertial>
        <visual>
            <origin xyz="0 0.951336932529339 0" rpy="0 0 0"/>
            <geometry>
                <box size="2.107039859591592 1.902673865058678 1.655666444351568" />
            </geometry>
            <material name="Blue">
                <color rgba="0 1.0 1.0 1.0"/>
            </material>
        </visual>
        <collision>
            <origin xyz="0 0.951336932529339 0" rpy="0 0 0"/>
            <geometry>
                <box size="2.107039859591592 1.902673865058678 1.655666444351568" />
            </geometry>
        </collision>
    </link>
    <link name="Leg19">
        <inertial>
            <origin xyz="0 0 1.0613288548497342" rpy="0 0 0"/>
            <mass value="1" />
            <inertia ixx="100" ixy="0" ixz="0" iyy="100" iyz="0" izz="100" />
        </inertial>
        <visual>
            <origin xyz="0 0 1.0613288548497342" rpy="0 0 0"/>
            <geometry>
                <box size="1.3777559070746364 1.324205733726062 2.1226577096994683" />
            </geometry>
            <material name="Blue">
                <color rgba="0 1.0 1.0 1.0"/>
            </material>
        </visual>
        <collision>
            <origin xyz="0 0 1.0613288548497342" rpy="0 0 0"/>
            <geometry>
                <box size="1.3777559070746364 1.324205733726062 2.1226577096994683" />
            </geometry>
        </collision>
    </link>
    <link name="Leg20">
        <inertial>
            <origin xyz="0 0.6958420498444087 0" rpy="0 0 0"/>
            <mass value="1" />
            <inertia ixx="100" ixy="0" ixz="0" iyy="100" iyz="0" izz="100" />
        </inertial>
        <visual>
            <origin xyz="0 0.6958420498444087 0" rpy="0 0 0"/>
            <geometry>
                <box size="1.03660574283131 1.3916840996888173 2.4388418867896986" />
            </geometry>
            <material name="Green">
                <color rgba="0 180.0 0.0 1.0"/>
            </material>
        </visual>
        <collision>
            <origin xyz="0 0.6958420498444087 0" rpy="0 0 0"/>
            <geometry>
                <box size="1.03660574283131 1.3916840996888173 2.4388418867896986" />
            </geometry>
        </collision>
    </link>
    <link name="Leg21">
        <inertial>
            <origin xyz="0 0 0.6725529092986537" rpy="0 0 0"/>
            <mass value="1" />
            <inertia ixx="100" ixy="0" ixz="0" iyy="100" iyz="0" izz="100" />
        </inertial>
        <visual>
            <origin xyz="0 0 0.6725529092986537" rpy="0 0 0"/>
            <geometry>
                <box size="2.703355061932668 1.1199692805831716 1.3451058185973075" />
            </geometry>
            <material name="Green">
                <color rgba="0 180.0 0.0 1.0"/>
            </material>
        </visual>
        <collision>
            <origin xyz="0 0 0.6725529092986537" rpy="0 0 0"/>
            <geometry>
                <box size="2.703355061932668 1.1199692805831716 1.3451058185973075" />
            </geometry>
        </collision>
    </link>
    <link name="Leg22">
        <inertial>
            <origin xyz="0 0 1.4241684180016847" rpy="0 0 0"/>
            <mass value="1" />
            <inertia ixx="100" ixy="0" ixz="0" iyy="100" iyz="0" izz="100" />
        </inertial>
        <visual>
            <origin xyz="0 0 1.4241684180016847" rpy="0 0 0"/>
            <geometry>
                <box size="2.302447035100771 1.8224705872016278 2.8483368360033694" />
            </geometry>
            <material name="Green">
                <color rgba="0 180.0 0.0 1.0"/>
            </material>
        </visual>
        <collision>
            <origin xyz="0 0 1.4241684180016847" rpy="0 0 0"/>
            <geometry>
                <box size="2.302447035100771 1.8224705872016278 2.8483368360033694" />
            </geometry>
        </collision>
    </link>
    <link name="Leg23">
        <inertial>
            <origin xyz="1.1953389438375321 0 0" rpy="0 0 0"/>
            <mass value="1" />
            <inertia ixx="100" ixy="0" ixz="0" iyy="100" iyz="0" izz="100" />
        </inertial>
        <visual>
            <origin xyz="1.1953389438375321 0 0" rpy="0 0 0"/>
            <geometry>
                <box size="2.3906778876750643 2.157451516865603 2.103411855031273" />
            </geometry>
            <material name="Blue">
                <color rgba="0 1.0 1.0 1.0"/>
            </material>
        </visual>
        <collision>
            <origin xyz="1.1953389438375321 0 0" rpy="0 0 0"/>
            <geometry>
                <box size="2.3906778876750643 2.157451516865603 2.103411855031273" />
            </geometry>
        </collision>
    </link>
    <link name="Leg24">
        <inertial>
            <origin xyz="0 1.182400356381422 0" rpy="0 0 0"/>
            <mass value="1" />
            <inertia ixx="100" ixy="0" ixz="0" iyy="100" iyz="0" izz="100" />
        </inertial>
        <visual>
            <origin xyz="0 1.182400356381422 0" rpy="0 0 0"/>
            <geometry>
                <box size="2.2595051256185217 2.364800712762844 1.8585553726446544" />
            </geometry>
            <material name="Green">
                <color rgba="0 180.0 0.0 1.0"/>
            </material>
        </visual>
        <collision>
            <origin xyz="0 1.182400356381422 0" rpy="0 0 0"/>
            <geometry>
                <box size="2.2595051256185217 2.364800712762844 1.8585553726446544" />
            </geometry>
        </collision>
    </link>
    <link name="Leg25">
        <inertial>
            <origin xyz="0 1.275685518223481 0" rpy="0 0 0"/>
            <mass value="1" />
            <inertia ixx="100" ixy="0" ixz="0" iyy="100" iyz="0" izz="100" />
        </inertial>
        <visual>
            <origin xyz="0 1.275685518223481 0" rpy="0 0 0"/>
            <geometry>
                <box size="2.5272572916704483 2.551371036446962 2.5408117942827166" />
            </geometry>
            <material name="Green">
                <color rgba="0 180.0 0.0 1.0"/>
            </material>
        </visual>
        <collision>
            <origin xyz="0 1.275685518223481 0" rpy="0 0 0"/>
            <geometry>
                <box size="2.5272572916704483 2.551371036446962 2.5408117942827166" />
            </geometry>
        </collision>
    </link>
    <link name="Leg26">
        <inertial>
            <origin xyz="0 0 1.187527705401948" rpy="0 0 0"/>
            <mass value="1" />
            <inertia ixx="100" ixy="0" ixz="0" iyy="100" iyz="0" izz="100" />
        </inertial>
        <visual>
            <origin xyz="0 0 1.187527705401948" rpy="0 0 0"/>
            <geometry>
                <box size="1.1541463003242047 2.192181242897684 2.375055410803896" />
            </geometry>
            <material name="Blue">
                <color rgba="0 1.0 1.0 1.0"/>
            </material>
        </visual>
        <collision>
            <origin xyz="0 0 1.187527705401948" rpy="0 0 0"/>
            <geometry>
                <box size="1.1541463003242047 2.192181242897684 2.375055410803896" />
            </geometry>
        </collision>
    </link>
    <link name="Leg27">
        <inertial>
            <origin xyz="1.2504859056130997 0 0" rpy="0 0 0"/>
            <mass value="1" />
            <inertia ixx="100" ixy="0" ixz="0" iyy="100" iyz="0" izz="100" />
        </inertial>
        <visual>
            <origin xyz="1.2504859056130997 0 0" rpy="0 0 0"/>
            <geometry>
                <box size="2.5009718112261994 1.5306088054708906 2.850658849843803" />
            </geometry>
            <material name="Green">
                <color rgba="0 180.0 0.0 1.0"/>
            </material>
        </visual>
        <collision>
            <origin xyz="1.2504859056130997 0 0" rpy="0 0 0"/>
            <geometry>
                <box size="2.5009718112261994 1.5306088054708906 2.850658849843803" />
            </geometry>
        </collision>
    </link>
    <joint name="Torso_Leg1" type="revolute">
       <parent link="Torso"/>
       <child  link="Leg1"/>
       <origin rpy="0 0 0" xyz="1.094798103337634 0 0.9275687424606586" />
     <axis xyz="1 0 0"/>
       <limit effort="0.0" lower="-3.14159" upper="3.14159" velocity="0.0"/>
    </joint>
    <joint name="Leg1_Leg2" type="revolute">
       <parent link="Leg1"/>
       <child  link="Leg2"/>
       <origin rpy="0 0 0" xyz="0 0 2.933601642705842" />
     <axis xyz="1 0 0"/>
       <limit effort="0.0" lower="-3.14159" upper="3.14159" velocity="0.0"/>
    </joint>
    <joint name="Torso_Leg3" type="revolute">
       <parent link="Torso"/>
       <child  link="Leg3"/>
       <origin rpy="0 0 0" xyz="1.0431775784293724 0.9039638666098125 0" />
     <axis xyz="1 0 0"/>
       <limit effort="0.0" lower="-3.14159" upper="3.14159" velocity="0.0"/>
    </joint>
    <joint name="Leg2_Leg4" type="revolute">
       <parent link="Leg2"/>
       <child  link="Leg4"/>
       <origin rpy="0 0 0" xyz="0 2.5306870558904997 0" />
     <axis xyz="1 0 0"/>
       <limit effort="0.0" lower="-3.14159" upper="3.14159" velocity="0.0"/>
    </joint>
    <joint name="Leg4_Leg5" type="revolute">
       <parent link="Leg4"/>
       <child  link="Leg5"/>
       <origin rpy="0 0 0" xyz="0 1.5481454502558976 0" />
     <axis xyz="1 0 0"/>
       <limit effort="0.0" lower="-3.14159" upper="3.14159" velocity="0.0"/>
    </joint>
    <joint name="Leg5_Leg6" type="revolute">
       <parent link="Leg5"/>
       <child  link="Leg6"/>
       <origin rpy="0 0 0" xyz="2.7113181145147376 0 0" />
     <axis xyz="1 0 0"/>
       <limit effort="0.0" lower="-3.14159" upper="3.14159" velocity="0.0"/>
    </joint>
    <joint name="Leg6_Leg7" type="revolute">
       <parent link="Leg6"/>
       <child  link="Leg7"/>
       <origin rpy="0 0 0" xyz="0 1.2292445578532836 0" />
     <axis xyz="1 0 0"/>
       <limit effort="0.0" lower="-3.14159" upper="3.14159" velocity="0.0"/>
    </joint>
    <joint name="Leg2_Leg8" type="revolute">
       <parent link="Leg2"/>
       <child  link="Leg8"/>
       <origin rpy="0 0 0" xyz="0.7241209024040679 2.5306870558904997 0" />
     <axis xyz="1 0 0"/>
       <limit effort="0.0" lower="-3.14159" upper="3.14159" velocity="0.0"/>
    </joint>
    <joint name="Leg3_Leg9" type="revolute">
       <parent link="Leg3"/>
       <child  link="Leg9"/>
       <origin rpy="0 0 0" xyz="0 0.5782836229836833 1.349097391272695" />
     <axis xyz="1 0 0"/>
       <limit effort="0.0" lower="-3.14159" upper="3.14159" velocity="0.0"/>
    </joint>
    <joint name="Leg1_Leg10" type="revolute">
       <parent link="Leg1"/>
       <child  link="Leg10"/>
       <origin rpy="0 0 0" xyz="0 0.9841727582656262 2.933601642705842" />
     <axis xyz="1 0 0"/>
       <limit effort="0.0" lower="-3.14159" upper="3.14159" velocity="0.0"/>
    </joint>
    <joint name="Leg8_Leg11" type="revolute">
       <parent link="Leg8"/>
       <child  link="Leg11"/>
       <origin rpy="0 0 0" xyz="0 0.7280029101769074 0.8345658245303907" />
     <axis xyz="1 0 0"/>
       <limit effort="0.0" lower="-3.14159" upper="3.14159" velocity="0.0"/>
    </joint>
    <joint name="Leg7_Leg12" type="revolute">
       <parent link="Leg7"/>
       <child  link="Leg12"/>
       <origin rpy="0 0 0" xyz="0.9315609852969103 0 1.0193315379314416" />
     <axis xyz="1 0 0"/>
       <limit effort="0.0" lower="-3.14159" upper="3.14159" velocity="0.0"/>
    </joint>
    <joint name="Leg9_Leg13" type="revolute">
       <parent link="Leg9"/>
       <child  link="Leg13"/>
       <origin rpy="0 0 0" xyz="0 0.6600392378143071 0.7894680040109713" />
     <axis xyz="1 0 0"/>
       <limit effort="0.0" lower="-3.14159" upper="3.14159" velocity="0.0"/>
    </joint>
    <joint name="Leg10_Leg14" type="revolute">
       <parent link="Leg10"/>
       <child  link="Leg14"/>
       <origin rpy="0 0 0" xyz="1.1145962431227867 1.3827400238663028 0" />
     <axis xyz="1 0 0"/>
       <limit effort="0.0" lower="-3.14159" upper="3.14159" velocity="0.0"/>
    </joint>
    <joint name="Leg2_Leg15" type="revolute">
       <parent link="Leg2"/>
       <child  link="Leg15"/>
       <origin rpy="0 0 0" xyz="0.7241209024040679 2.5306870558904997 0.8678042079175194" />
     <axis xyz="1 0 0"/>
       <limit effort="0.0" lower="-3.14159" upper="3.14159" velocity="0.0"/>
    </joint>
    <joint name="Leg5_Leg16" type="revolute">
       <parent link="Leg5"/>
       <child  link="Leg16"/>
       <origin rpy="0 0 0" xyz="2.7113181145147376 0 1.1480586535531767" />
     <axis xyz="1 0 0"/>
       <limit effort="0.0" lower="-3.14159" upper="3.14159" velocity="0.0"/>
    </joint>
    <joint name="Leg4_Leg17" type="revolute">
       <parent link="Leg4"/>
       <child  link="Leg17"/>
       <origin rpy="0 0 0" xyz="0 1.5481454502558976 0.6300468542547207" />
     <axis xyz="1 0 0"/>
       <limit effort="0.0" lower="-3.14159" upper="3.14159" velocity="0.0"/>
    </joint>
    <joint name="Leg10_Leg18" type="revolute">
       <parent link="Leg10"/>
       <child  link="Leg18"/>
       <origin rpy="0 0 0" xyz="1.1145962431227867 2.7654800477326056 0" />
     <axis xyz="1 0 0"/>
       <limit effort="0.0" lower="-3.14159" upper="3.14159" velocity="0.0"/>
    </joint>
    <joint name="Leg16_Leg19" type="revolute">
       <parent link="Leg16"/>
       <child  link="Leg19"/>
       <origin rpy="0 0 0" xyz="0 0 2.210022358141414" />
     <axis xyz="1 0 0"/>
       <limit effort="0.0" lower="-3.14159" upper="3.14159" velocity="0.0"/>
    </joint>
    <joint name="Leg13_Leg20" type="revolute">
       <parent link="Leg13"/>
       <child  link="Leg20"/>
       <origin rpy="0 0 0" xyz="0.6178955479855139 1.1057173418166348 0" />
     <axis xyz="1 0 0"/>
       <limit effort="0.0" lower="-3.14159" upper="3.14159" velocity="0.0"/>
    </joint>
    <joint name="Leg15_Leg21" type="revolute">
       <parent link="Leg15"/>
       <child  link="Leg21"/>
       <origin rpy="0 0 0" xyz="0 0 2.157043606619821" />
     <axis xyz="1 0 0"/>
       <limit effort="0.0" lower="-3.14159" upper="3.14159" velocity="0.0"/>
    </joint>
    <joint name="Leg13_Leg22" type="revolute">
       <parent link="Leg13"/>
       <child  link="Leg22"/>
       <origin rpy="0 0 0" xyz="0.6178955479855139 1.1057173418166348 1.3057901132833245" />
     <axis xyz="1 0 0"/>
       <limit effort="0.0" lower="-3.14159" upper="3.14159" velocity="0.0"/>
    </joint>
    <joint name="Leg11_Leg23" type="revolute">
       <parent link="Leg11"/>
       <child  link="Leg23"/>
       <origin rpy="0 0 0" xyz="1.4868957088577375 0 0.7968623593482466" />
     <axis xyz="1 0 0"/>
       <limit effort="0.0" lower="-3.14159" upper="3.14159" velocity="0.0"/>
    </joint>
    <joint name="Leg17_Leg24" type="revolute">
       <parent link="Leg17"/>
       <child  link="Leg24"/>
       <origin rpy="0 0 0" xyz="0 1.902673865058678 0" />
     <axis xyz="1 0 0"/>
       <limit effort="0.0" lower="-3.14159" upper="3.14159" velocity="0.0"/>
    </joint>
    <joint name="Leg7_Leg25" type="revolute">
       <parent link="Leg7"/>
       <child  link="Leg25"/>
       <origin rpy="0 0 0" xyz="0.9315609852969103 1.301140037734347 1.0193315379314416" />
     <axis xyz="1 0 0"/>
       <limit effort="0.0" lower="-3.14159" upper="3.14159" velocity="0.0"/>
    </joint>
    <joint name="Leg22_Leg26" type="revolute">
       <parent link="Leg22"/>
       <child  link="Leg26"/>
       <origin rpy="0 0 0" xyz="1.1953389438375321 0 1.0517059275156364" />
     <axis xyz="1 0 0"/>
       <limit effort="0.0" lower="-3.14159" upper="3.14159" velocity="0.0"/>
    </joint>
    <joint name="Leg15_Leg27" type="revolute">
       <parent link="Leg15"/>
       <child  link="Leg27"/>
       <origin rpy="0 0 0" xyz="1.4129061124837528 0 2.157043606619821" />
     <axis xyz="1 0 0"/>
       <limit effort="0.0" lower="-3.14159" upper="3.14159" velocity="0.0"/>
    </joint>
</robot>