<robot name = "robot">
    <link name="Torso">
        <inertial>
            <origin xyz="0 0 0.797239748535896" rpy="0 0 0"/>
            <mass value="1" />
            <inertia ixx="100" ixy="0" ixz="0" iyy="100" iyz="0" izz="100" />
        </inertial>
        <visual>
            <origin xyz="0 0 0.797239748535896" rpy="0 0 0"/>
            <geometry>
                <box size="1.0598853384208606 1.540962352775558 1.594479497071792" />
            </geometry>
            <material name="Green">
                <color rgba="0 180.0 0.0 1.0"/>
            </material>
        </visual>
        <collision>
            <origin xyz="0 0 0.797239748535896" rpy="0 0 0"/>
            <geometry>
                <box size="1.0598853384208606 1.540962352775558 1.594479497071792" />
            </geometry>
        </collision>
    </link>
    <link name="Leg1">
        <inertial>
            <origin xyz="0 0 1.3869154538286468" rpy="0 0 0"/>
            <mass value="1" />
            <inertia ixx="100" ixy="0" ixz="0" iyy="100" iyz="0" izz="100" />
        </inertial>
        <visual>
            <origin xyz="0 0 1.3869154538286468" rpy="0 0 0"/>
            <geometry>
                <box size="2.8355429912333565 2.1527050944272927 2.7738309076572936" />
            </geometry>
            <material name="Green">
                <color rgba="0 180.0 0.0 1.0"/>
            </material>
        </visual>
        <collision>
            <origin xyz="0 0 1.3869154538286468" rpy="0 0 0"/>
            <geometry>
                <box size="2.8355429912333565 2.1527050944272927 2.7738309076572936" />
            </geometry>
        </collision>
    </link>
    <link name="Leg2">
        <inertial>
            <origin xyz="0 0 0.8737068922335425" rpy="0 0 0"/>
            <mass value="1" />
            <inertia ixx="100" ixy="0" ixz="0" iyy="100" iyz="0" izz="100" />
        </inertial>
        <visual>
            <origin xyz="0 0 0.8737068922335425" rpy="0 0 0"/>
            <geometry>
                <box size="2.999321326647438 1.3397629445755062 1.747413784467085" />
            </geometry>
            <material name="Green">
                <color rgba="0 180.0 0.0 1.0"/>
            </material>
        </visual>
        <collision>
            <origin xyz="0 0 0.8737068922335425" rpy="0 0 0"/>
            <geometry>
                <box size="2.999321326647438 1.3397629445755062 1.747413784467085" />
            </geometry>
        </collision>
    </link>
    <link name="Leg3">
        <inertial>
            <origin xyz="0 0.9400019536443766 0" rpy="0 0 0"/>
            <mass value="1" />
            <inertia ixx="100" ixy="0" ixz="0" iyy="100" iyz="0" izz="100" />
        </inertial>
        <visual>
            <origin xyz="0 0.9400019536443766 0" rpy="0 0 0"/>
            <geometry>
                <box size="2.221596474828565 1.880003907288753 1.5727075766139271" />
            </geometry>
            <material name="Green">
                <color rgba="0 180.0 0.0 1.0"/>
            </material>
        </visual>
        <collision>
            <origin xyz="0 0.9400019536443766 0" rpy="0 0 0"/>
            <geometry>
                <box size="2.221596474828565 1.880003907288753 1.5727075766139271" />
            </geometry>
        </collision>
    </link>
    <link name="Leg4">
        <inertial>
            <origin xyz="0 1.0393630550962247 0" rpy="0 0 0"/>
            <mass value="1" />
            <inertia ixx="100" ixy="0" ixz="0" iyy="100" iyz="0" izz="100" />
        </inertial>
        <visual>
            <origin xyz="0 1.0393630550962247 0" rpy="0 0 0"/>
            <geometry>
                <box size="1.2569628668336768 2.0787261101924495 2.0144115209308255" />
            </geometry>
            <material name="Blue">
                <color rgba="0 1.0 1.0 1.0"/>
            </material>
        </visual>
        <collision>
            <origin xyz="0 1.0393630550962247 0" rpy="0 0 0"/>
            <geometry>
                <box size="1.2569628668336768 2.0787261101924495 2.0144115209308255" />
            </geometry>
        </collision>
    </link>
    <link name="Leg5">
        <inertial>
            <origin xyz="0 0.6096350103608628 0" rpy="0 0 0"/>
            <mass value="1" />
            <inertia ixx="100" ixy="0" ixz="0" iyy="100" iyz="0" izz="100" />
        </inertial>
        <visual>
            <origin xyz="0 0.6096350103608628 0" rpy="0 0 0"/>
            <geometry>
                <box size="2.5131849093216503 1.2192700207217255 2.627088632146976" />
            </geometry>
            <material name="Green">
                <color rgba="0 180.0 0.0 1.0"/>
            </material>
        </visual>
        <collision>
            <origin xyz="0 0.6096350103608628 0" rpy="0 0 0"/>
            <geometry>
                <box size="2.5131849093216503 1.2192700207217255 2.627088632146976" />
            </geometry>
        </collision>
    </link>
    <link name="Leg6">
        <inertial>
            <origin xyz="0 1.340228323749939 0" rpy="0 0 0"/>
            <mass value="1" />
            <inertia ixx="100" ixy="0" ixz="0" iyy="100" iyz="0" izz="100" />
        </inertial>
        <visual>
            <origin xyz="0 1.340228323749939 0" rpy="0 0 0"/>
            <geometry>
                <box size="1.048292345145541 2.680456647499878 2.1549546238105868" />
            </geometry>
            <material name="Blue">
                <color rgba="0 1.0 1.0 1.0"/>
            </material>
        </visual>
        <collision>
            <origin xyz="0 1.340228323749939 0" rpy="0 0 0"/>
            <geometry>
                <box size="1.048292345145541 2.680456647499878 2.1549546238105868" />
            </geometry>
        </collision>
    </link>
    <link name="Leg7">
        <inertial>
            <origin xyz="0 1.154957124037773 0" rpy="0 0 0"/>
            <mass value="1" />
            <inertia ixx="100" ixy="0" ixz="0" iyy="100" iyz="0" izz="100" />
        </inertial>
        <visual>
            <origin xyz="0 1.154957124037773 0" rpy="0 0 0"/>
            <geometry>
                <box size="1.2752711330366837 2.309914248075546 1.183511758627296" />
            </geometry>
            <material name="Blue">
                <color rgba="0 1.0 1.0 1.0"/>
            </material>
        </visual>
        <collision>
            <origin xyz="0 1.154957124037773 0" rpy="0 0 0"/>
            <geometry>
                <box size="1.2752711330366837 2.309914248075546 1.183511758627296" />
            </geometry>
        </collision>
    </link>
    <link name="Leg8">
        <inertial>
            <origin xyz="1.3030839113867656 0 0" rpy="0 0 0"/>
            <mass value="1" />
            <inertia ixx="100" ixy="0" ixz="0" iyy="100" iyz="0" izz="100" />
        </inertial>
        <visual>
            <origin xyz="1.3030839113867656 0 0" rpy="0 0 0"/>
            <geometry>
                <box size="2.606167822773531 2.9868385632963403 2.4842068393936723" />
            </geometry>
            <material name="Green">
                <color rgba="0 180.0 0.0 1.0"/>
            </material>
        </visual>
        <collision>
            <origin xyz="1.3030839113867656 0 0" rpy="0 0 0"/>
            <geometry>
                <box size="2.606167822773531 2.9868385632963403 2.4842068393936723" />
            </geometry>
        </collision>
    </link>
    <link name="Leg9">
        <inertial>
            <origin xyz="1.3112843753799 0 0" rpy="0 0 0"/>
            <mass value="1" />
            <inertia ixx="100" ixy="0" ixz="0" iyy="100" iyz="0" izz="100" />
        </inertial>
        <visual>
            <origin xyz="1.3112843753799 0 0" rpy="0 0 0"/>
            <geometry>
                <box size="2.6225687507598 2.5570172388651375 2.2825416679242982" />
            </geometry>
            <material name="Green">
                <color rgba="0 180.0 0.0 1.0"/>
            </material>
        </visual>
        <collision>
            <origin xyz="1.3112843753799 0 0" rpy="0 0 0"/>
            <geometry>
                <box size="2.6225687507598 2.5570172388651375 2.2825416679242982" />
            </geometry>
        </collision>
    </link>
    <link name="Leg10">
        <inertial>
            <origin xyz="0 1.2476924391204418 0" rpy="0 0 0"/>
            <mass value="1" />
            <inertia ixx="100" ixy="0" ixz="0" iyy="100" iyz="0" izz="100" />
        </inertial>
        <visual>
            <origin xyz="0 1.2476924391204418 0" rpy="0 0 0"/>
            <geometry>
                <box size="2.0559707494555366 2.4953848782408836 1.1432197127846755" />
            </geometry>
            <material name="Green">
                <color rgba="0 180.0 0.0 1.0"/>
            </material>
        </visual>
        <collision>
            <origin xyz="0 1.2476924391204418 0" rpy="0 0 0"/>
            <geometry>
                <box size="2.0559707494555366 2.4953848782408836 1.1432197127846755" />
            </geometry>
        </collision>
    </link>
    <link name="Leg11">
        <inertial>
            <origin xyz="0 1.1966543047829683 0" rpy="0 0 0"/>
            <mass value="1" />
            <inertia ixx="100" ixy="0" ixz="0" iyy="100" iyz="0" izz="100" />
        </inertial>
        <visual>
            <origin xyz="0 1.1966543047829683 0" rpy="0 0 0"/>
            <geometry>
                <box size="1.2535953705007101 2.3933086095659366 1.2435244200359878" />
            </geometry>
            <material name="Blue">
                <color rgba="0 1.0 1.0 1.0"/>
            </material>
        </visual>
        <collision>
            <origin xyz="0 1.1966543047829683 0" rpy="0 0 0"/>
            <geometry>
                <box size="1.2535953705007101 2.3933086095659366 1.2435244200359878" />
            </geometry>
        </collision>
    </link>
    <link name="Leg12">
        <inertial>
            <origin xyz="0 0 0.5893321068698998" rpy="0 0 0"/>
            <mass value="1" />
            <inertia ixx="100" ixy="0" ixz="0" iyy="100" iyz="0" izz="100" />
        </inertial>
        <visual>
            <origin xyz="0 0 0.5893321068698998" rpy="0 0 0"/>
            <geometry>
                <box size="2.123459916769466 1.7662542184023982 1.1786642137397996" />
            </geometry>
            <material name="Blue">
                <color rgba="0 1.0 1.0 1.0"/>
            </material>
        </visual>
        <collision>
            <origin xyz="0 0 0.5893321068698998" rpy="0 0 0"/>
            <geometry>
                <box size="2.123459916769466 1.7662542184023982 1.1786642137397996" />
            </geometry>
        </collision>
    </link>
    <link name="Leg13">
        <inertial>
            <origin xyz="0 0.7813654859726277 0" rpy="0 0 0"/>
            <mass value="1" />
            <inertia ixx="100" ixy="0" ixz="0" iyy="100" iyz="0" izz="100" />
        </inertial>
        <visual>
            <origin xyz="0 0.7813654859726277 0" rpy="0 0 0"/>
            <geometry>
                <box size="2.6473247741139523 1.5627309719452553 2.174435491397767" />
            </geometry>
            <material name="Blue">
                <color rgba="0 1.0 1.0 1.0"/>
            </material>
        </visual>
        <collision>
            <origin xyz="0 0.7813654859726277 0" rpy="0 0 0"/>
            <geometry>
                <box size="2.6473247741139523 1.5627309719452553 2.174435491397767" />
            </geometry>
        </collision>
    </link>
    <link name="Leg14">
        <inertial>
            <origin xyz="0 0.5288870089659432 0" rpy="0 0 0"/>
            <mass value="1" />
            <inertia ixx="100" ixy="0" ixz="0" iyy="100" iyz="0" izz="100" />
        </inertial>
        <visual>
            <origin xyz="0 0.5288870089659432 0" rpy="0 0 0"/>
            <geometry>
                <box size="1.3252981842402818 1.0577740179318864 1.1146524859232763" />
            </geometry>
            <material name="Blue">
                <color rgba="0 1.0 1.0 1.0"/>
            </material>
        </visual>
        <collision>
            <origin xyz="0 0.5288870089659432 0" rpy="0 0 0"/>
            <geometry>
                <box size="1.3252981842402818 1.0577740179318864 1.1146524859232763" />
            </geometry>
        </collision>
    </link>
    <link name="Leg15">
        <inertial>
            <origin xyz="0 0 1.4926654056532778" rpy="0 0 0"/>
            <mass value="1" />
            <inertia ixx="100" ixy="0" ixz="0" iyy="100" iyz="0" izz="100" />
        </inertial>
        <visual>
            <origin xyz="0 0 1.4926654056532778" rpy="0 0 0"/>
            <geometry>
                <box size="1.9176788493545374 2.1690594289152902 2.9853308113065555" />
            </geometry>
            <material name="Blue">
                <color rgba="0 1.0 1.0 1.0"/>
            </material>
        </visual>
        <collision>
            <origin xyz="0 0 1.4926654056532778" rpy="0 0 0"/>
            <geometry>
                <box size="1.9176788493545374 2.1690594289152902 2.9853308113065555" />
            </geometry>
        </collision>
    </link>
    <link name="Leg16">
        <inertial>
            <origin xyz="0.9606718217922223 0 0" rpy="0 0 0"/>
            <mass value="1" />
            <inertia ixx="100" ixy="0" ixz="0" iyy="100" iyz="0" izz="100" />
        </inertial>
        <visual>
            <origin xyz="0.9606718217922223 0 0" rpy="0 0 0"/>
            <geometry>
                <box size="1.9213436435844446 1.8438132792698139 2.9792815441391687" />
            </geometry>
            <material name="Green">
                <color rgba="0 180.0 0.0 1.0"/>
            </material>
        </visual>
        <collision>
            <origin xyz="0.9606718217922223 0 0" rpy="0 0 0"/>
            <geometry>
                <box size="1.9213436435844446 1.8438132792698139 2.9792815441391687" />
            </geometry>
        </collision>
    </link>
    <link name="Leg17">
        <inertial>
            <origin xyz="0 0 1.286806987510117" rpy="0 0 0"/>
            <mass value="1" />
            <inertia ixx="100" ixy="0" ixz="0" iyy="100" iyz="0" izz="100" />
        </inertial>
        <visual>
            <origin xyz="0 0 1.286806987510117" rpy="0 0 0"/>
            <geometry>
                <box size="1.0768547635563797 2.7841875792465585 2.573613975020234" />
            </geometry>
            <material name="Blue">
                <color rgba="0 1.0 1.0 1.0"/>
            </material>
        </visual>
        <collision>
            <origin xyz="0 0 1.286806987510117" rpy="0 0 0"/>
            <geometry>
                <box size="1.0768547635563797 2.7841875792465585 2.573613975020234" />
            </geometry>
        </collision>
    </link>
    <link name="Leg18">
        <inertial>
            <origin xyz="0.6165730297689637 0 0" rpy="0 0 0"/>
            <mass value="1" />
            <inertia ixx="100" ixy="0" ixz="0" iyy="100" iyz="0" izz="100" />
        </inertial>
        <visual>
            <origin xyz="0.6165730297689637 0 0" rpy="0 0 0"/>
            <geometry>
                <box size="1.2331460595379273 2.000964959058532 1.6424197958072566" />
            </geometry>
            <material name="Green">
                <color rgba="0 180.0 0.0 1.0"/>
            </material>
        </visual>
        <collision>
            <origin xyz="0.6165730297689637 0 0" rpy="0 0 0"/>
            <geometry>
                <box size="1.2331460595379273 2.000964959058532 1.6424197958072566" />
            </geometry>
        </collision>
    </link>
    <link name="Leg19">
        <inertial>
            <origin xyz="0 0 0.8979726876226918" rpy="0 0 0"/>
            <mass value="1" />
            <inertia ixx="100" ixy="0" ixz="0" iyy="100" iyz="0" izz="100" />
        </inertial>
        <visual>
            <origin xyz="0 0 0.8979726876226918" rpy="0 0 0"/>
            <geometry>
                <box size="1.7765866395031022 2.713488724670132 1.7959453752453836" />
            </geometry>
            <material name="Green">
                <color rgba="0 180.0 0.0 1.0"/>
            </material>
        </visual>
        <collision>
            <origin xyz="0 0 0.8979726876226918" rpy="0 0 0"/>
            <geometry>
                <box size="1.7765866395031022 2.713488724670132 1.7959453752453836" />
            </geometry>
        </collision>
    </link>
    <link name="Leg20">
        <inertial>
            <origin xyz="0 0 1.3664296522983617" rpy="0 0 0"/>
            <mass value="1" />
            <inertia ixx="100" ixy="0" ixz="0" iyy="100" iyz="0" izz="100" />
        </inertial>
        <visual>
            <origin xyz="0 0 1.3664296522983617" rpy="0 0 0"/>
            <geometry>
                <box size="2.85280946391836 1.0137253260230514 2.7328593045967233" />
            </geometry>
            <material name="Blue">
                <color rgba="0 1.0 1.0 1.0"/>
            </material>
        </visual>
        <collision>
            <origin xyz="0 0 1.3664296522983617" rpy="0 0 0"/>
            <geometry>
                <box size="2.85280946391836 1.0137253260230514 2.7328593045967233" />
            </geometry>
        </collision>
    </link>
    <link name="Leg21">
        <inertial>
            <origin xyz="0 0 1.1498856448021617" rpy="0 0 0"/>
            <mass value="1" />
            <inertia ixx="100" ixy="0" ixz="0" iyy="100" iyz="0" izz="100" />
        </inertial>
        <visual>
            <origin xyz="0 0 1.1498856448021617" rpy="0 0 0"/>
            <geometry>
                <box size="2.618548595296536 1.5365209298637192 2.2997712896043234" />
            </geometry>
            <material name="Blue">
                <color rgba="0 1.0 1.0 1.0"/>
            </material>
        </visual>
        <collision>
            <origin xyz="0 0 1.1498856448021617" rpy="0 0 0"/>
            <geometry>
                <box size="2.618548595296536 1.5365209298637192 2.2997712896043234" />
            </geometry>
        </collision>
    </link>
    <link name="Leg22">
        <inertial>
            <origin xyz="0 0 0.7372952228237937" rpy="0 0 0"/>
            <mass value="1" />
            <inertia ixx="100" ixy="0" ixz="0" iyy="100" iyz="0" izz="100" />
        </inertial>
        <visual>
            <origin xyz="0 0 0.7372952228237937" rpy="0 0 0"/>
            <geometry>
                <box size="1.3226898068752215 1.4805009757538166 1.4745904456475873" />
            </geometry>
            <material name="Green">
                <color rgba="0 180.0 0.0 1.0"/>
            </material>
        </visual>
        <collision>
            <origin xyz="0 0 0.7372952228237937" rpy="0 0 0"/>
            <geometry>
                <box size="1.3226898068752215 1.4805009757538166 1.4745904456475873" />
            </geometry>
        </collision>
    </link>
    <link name="Leg23">
        <inertial>
            <origin xyz="0 0.9955767598626704 0" rpy="0 0 0"/>
            <mass value="1" />
            <inertia ixx="100" ixy="0" ixz="0" iyy="100" iyz="0" izz="100" />
        </inertial>
        <visual>
            <origin xyz="0 0.9955767598626704 0" rpy="0 0 0"/>
            <geometry>
                <box size="1.880329983107056 1.9911535197253407 1.694283890098597" />
            </geometry>
            <material name="Blue">
                <color rgba="0 1.0 1.0 1.0"/>
            </material>
        </visual>
        <collision>
            <origin xyz="0 0.9955767598626704 0" rpy="0 0 0"/>
            <geometry>
                <box size="1.880329983107056 1.9911535197253407 1.694283890098597" />
            </geometry>
        </collision>
    </link>
    <link name="Leg24">
        <inertial>
            <origin xyz="0 1.001337082530485 0" rpy="0 0 0"/>
            <mass value="1" />
            <inertia ixx="100" ixy="0" ixz="0" iyy="100" iyz="0" izz="100" />
        </inertial>
        <visual>
            <origin xyz="0 1.001337082530485 0" rpy="0 0 0"/>
            <geometry>
                <box size="2.028326195676615 2.00267416506097 2.3703850580754926" />
            </geometry>
            <material name="Blue">
                <color rgba="0 1.0 1.0 1.0"/>
            </material>
        </visual>
        <collision>
            <origin xyz="0 1.001337082530485 0" rpy="0 0 0"/>
            <geometry>
                <box size="2.028326195676615 2.00267416506097 2.3703850580754926" />
            </geometry>
        </collision>
    </link>
    <link name="Leg25">
        <inertial>
            <origin xyz="1.0027611392784292 0 0" rpy="0 0 0"/>
            <mass value="1" />
            <inertia ixx="100" ixy="0" ixz="0" iyy="100" iyz="0" izz="100" />
        </inertial>
        <visual>
            <origin xyz="1.0027611392784292 0 0" rpy="0 0 0"/>
            <geometry>
                <box size="2.0055222785568585 1.1577177782973662 2.540847906177997" />
            </geometry>
            <material name="Green">
                <color rgba="0 180.0 0.0 1.0"/>
            </material>
        </visual>
        <collision>
            <origin xyz="1.0027611392784292 0 0" rpy="0 0 0"/>
            <geometry>
                <box size="2.0055222785568585 1.1577177782973662 2.540847906177997" />
            </geometry>
        </collision>
    </link>
    <link name="Leg26">
        <inertial>
            <origin xyz="0 1.4080696432400384 0" rpy="0 0 0"/>
            <mass value="1" />
            <inertia ixx="100" ixy="0" ixz="0" iyy="100" iyz="0" izz="100" />
        </inertial>
        <visual>
            <origin xyz="0 1.4080696432400384 0" rpy="0 0 0"/>
            <geometry>
                <box size="1.6475341847758755 2.8161392864800767 2.2925027988206717" />
            </geometry>
            <material name="Blue">
                <color rgba="0 1.0 1.0 1.0"/>
            </material>
        </visual>
        <collision>
            <origin xyz="0 1.4080696432400384 0" rpy="0 0 0"/>
            <geometry>
                <box size="1.6475341847758755 2.8161392864800767 2.2925027988206717" />
            </geometry>
        </collision>
    </link>
    <joint name="Torso_Leg1" type="revolute">
       <parent link="Torso"/>
       <child  link="Leg1"/>
       <origin rpy="0 0 0" xyz="0 0 1.594479497071792" />
     <axis xyz="1 0 0"/>
       <limit effort="0.0" lower="-3.14159" upper="3.14159" velocity="0.0"/>
    </joint>
    <joint name="Leg1_Leg2" type="revolute">
       <parent link="Leg1"/>
       <child  link="Leg2"/>
       <origin rpy="0 0 0" xyz="0 0 1.747413784467085" />
     <axis xyz="1 0 0"/>
       <limit effort="0.0" lower="-3.14159" upper="3.14159" velocity="0.0"/>
    </joint>
    <joint name="Torso_Leg3" type="revolute">
       <parent link="Torso"/>
       <child  link="Leg3"/>
       <origin rpy="0 0 0" xyz="0 1.0763525472136464 1.3869154538286468" />
     <axis xyz="1 0 0"/>
       <limit effort="0.0" lower="-3.14159" upper="3.14159" velocity="0.0"/>
    </joint>
    <joint name="Leg1_Leg4" type="revolute">
       <parent link="Leg1"/>
       <child  link="Leg4"/>
       <origin rpy="0 0 0" xyz="0 0.6698814722877531 1.747413784467085" />
     <axis xyz="1 0 0"/>
       <limit effort="0.0" lower="-3.14159" upper="3.14159" velocity="0.0"/>
    </joint>
    <joint name="Leg4_Leg5" type="revolute">
       <parent link="Leg4"/>
       <child  link="Leg5"/>
       <origin rpy="0 0 0" xyz="0 1.2192700207217255 0" />
     <axis xyz="1 0 0"/>
       <limit effort="0.0" lower="-3.14159" upper="3.14159" velocity="0.0"/>
    </joint>
    <joint name="Leg5_Leg6" type="revolute">
       <parent link="Leg5"/>
       <child  link="Leg6"/>
       <origin rpy="0 0 0" xyz="0 2.680456647499878 0" />
     <axis xyz="1 0 0"/>
       <limit effort="0.0" lower="-3.14159" upper="3.14159" velocity="0.0"/>
    </joint>
    <joint name="Leg3_Leg7" type="revolute">
       <parent link="Leg3"/>
       <child  link="Leg7"/>
       <origin rpy="0 0 0" xyz="0 2.0787261101924495 0" />
     <axis xyz="1 0 0"/>
       <limit effort="0.0" lower="-3.14159" upper="3.14159" velocity="0.0"/>
    </joint>
    <joint name="Leg6_Leg8" type="revolute">
       <parent link="Leg6"/>
       <child  link="Leg8"/>
       <origin rpy="0 0 0" xyz="0.6376355665183419 1.154957124037773 0" />
     <axis xyz="1 0 0"/>
       <limit effort="0.0" lower="-3.14159" upper="3.14159" velocity="0.0"/>
    </joint>
    <joint name="Leg4_Leg9" type="revolute">
       <parent link="Leg4"/>
       <child  link="Leg9"/>
       <origin rpy="0 0 0" xyz="1.2565924546608251 1.2192700207217255 0" />
     <axis xyz="1 0 0"/>
       <limit effort="0.0" lower="-3.14159" upper="3.14159" velocity="0.0"/>
    </joint>
    <joint name="Leg2_Leg10" type="revolute">
       <parent link="Leg2"/>
       <child  link="Leg10"/>
       <origin rpy="0 0 0" xyz="0 1.880003907288753 0" />
     <axis xyz="1 0 0"/>
       <limit effort="0.0" lower="-3.14159" upper="3.14159" velocity="0.0"/>
    </joint>
    <joint name="Leg7_Leg11" type="revolute">
       <parent link="Leg7"/>
       <child  link="Leg11"/>
       <origin rpy="0 0 0" xyz="1.3030839113867656 1.4934192816481702 0" />
     <axis xyz="1 0 0"/>
       <limit effort="0.0" lower="-3.14159" upper="3.14159" velocity="0.0"/>
    </joint>
    <joint name="Leg7_Leg12" type="revolute">
       <parent link="Leg7"/>
       <child  link="Leg12"/>
       <origin rpy="0 0 0" xyz="1.3030839113867656 1.4934192816481702 1.2421034196968361" />
     <axis xyz="1 0 0"/>
       <limit effort="0.0" lower="-3.14159" upper="3.14159" velocity="0.0"/>
    </joint>
    <joint name="Leg8_Leg13" type="revolute">
       <parent link="Leg8"/>
       <child  link="Leg13"/>
       <origin rpy="0 0 0" xyz="1.3112843753799 1.2785086194325688 0" />
     <axis xyz="1 0 0"/>
       <limit effort="0.0" lower="-3.14159" upper="3.14159" velocity="0.0"/>
    </joint>
    <joint name="Leg12_Leg14" type="revolute">
       <parent link="Leg12"/>
       <child  link="Leg14"/>
       <origin rpy="0 0 0" xyz="0 1.5627309719452553 0" />
     <axis xyz="1 0 0"/>
       <limit effort="0.0" lower="-3.14159" upper="3.14159" velocity="0.0"/>
    </joint>
    <joint name="Leg11_Leg15" type="revolute">
       <parent link="Leg11"/>
       <child  link="Leg15"/>
       <origin rpy="0 0 0" xyz="0 0 1.1786642137397996" />
     <axis xyz="1 0 0"/>
       <limit effort="0.0" lower="-3.14159" upper="3.14159" velocity="0.0"/>
    </joint>
    <joint name="Leg15_Leg16" type="revolute">
       <parent link="Leg15"/>
       <child  link="Leg16"/>
       <origin rpy="0 0 0" xyz="1.9213436435844446 0 0" />
     <axis xyz="1 0 0"/>
       <limit effort="0.0" lower="-3.14159" upper="3.14159" velocity="0.0"/>
    </joint>
    <joint name="Leg13_Leg17" type="revolute">
       <parent link="Leg13"/>
       <child  link="Leg17"/>
       <origin rpy="0 0 0" xyz="0 0.5288870089659432 0.5573262429616381" />
     <axis xyz="1 0 0"/>
       <limit effort="0.0" lower="-3.14159" upper="3.14159" velocity="0.0"/>
    </joint>
    <joint name="Leg2_Leg18" type="revolute">
       <parent link="Leg2"/>
       <child  link="Leg18"/>
       <origin rpy="0 0 0" xyz="1.1107982374142824 1.880003907288753 0" />
     <axis xyz="1 0 0"/>
       <limit effort="0.0" lower="-3.14159" upper="3.14159" velocity="0.0"/>
    </joint>
    <joint name="Leg12_Leg19" type="revolute">
       <parent link="Leg12"/>
       <child  link="Leg19"/>
       <origin rpy="0 0 0" xyz="0 1.5627309719452553 1.0872177456988834" />
     <axis xyz="1 0 0"/>
       <limit effort="0.0" lower="-3.14159" upper="3.14159" velocity="0.0"/>
    </joint>
    <joint name="Leg5_Leg20" type="revolute">
       <parent link="Leg5"/>
       <child  link="Leg20"/>
       <origin rpy="0 0 0" xyz="0 2.680456647499878 1.0774773119052934" />
     <axis xyz="1 0 0"/>
       <limit effort="0.0" lower="-3.14159" upper="3.14159" velocity="0.0"/>
    </joint>
    <joint name="Leg14_Leg21" type="revolute">
       <parent link="Leg14"/>
       <child  link="Leg21"/>
       <origin rpy="0 0 0" xyz="0 0 2.9853308113065555" />
     <axis xyz="1 0 0"/>
       <limit effort="0.0" lower="-3.14159" upper="3.14159" velocity="0.0"/>
    </joint>
    <joint name="Leg19_Leg22" type="revolute">
       <parent link="Leg19"/>
       <child  link="Leg22"/>
       <origin rpy="0 0 0" xyz="0 0 2.7328593045967233" />
     <axis xyz="1 0 0"/>
       <limit effort="0.0" lower="-3.14159" upper="3.14159" velocity="0.0"/>
    </joint>
    <joint name="Leg6_Leg23" type="revolute">
       <parent link="Leg6"/>
       <child  link="Leg23"/>
       <origin rpy="0 0 0" xyz="0.6376355665183419 2.309914248075546 0" />
     <axis xyz="1 0 0"/>
       <limit effort="0.0" lower="-3.14159" upper="3.14159" velocity="0.0"/>
    </joint>
    <joint name="Leg18_Leg24" type="revolute">
       <parent link="Leg18"/>
       <child  link="Leg24"/>
       <origin rpy="0 0 0" xyz="0 1.356744362335066 0.8979726876226918" />
     <axis xyz="1 0 0"/>
       <limit effort="0.0" lower="-3.14159" upper="3.14159" velocity="0.0"/>
    </joint>
    <joint name="Leg18_Leg25" type="revolute">
       <parent link="Leg18"/>
       <child  link="Leg25"/>
       <origin rpy="0 0 0" xyz="0.8882933197515511 1.356744362335066 0.8979726876226918" />
     <axis xyz="1 0 0"/>
       <limit effort="0.0" lower="-3.14159" upper="3.14159" velocity="0.0"/>
    </joint>
    <joint name="Leg15_Leg26" type="revolute">
       <parent link="Leg15"/>
       <child  link="Leg26"/>
       <origin rpy="0 0 0" xyz="1.9213436435844446 0.9219066396349069 0" />
     <axis xyz="1 0 0"/>
       <limit effort="0.0" lower="-3.14159" upper="3.14159" velocity="0.0"/>
    </joint>
</robot>