<robot name = "robot">
    <link name="Torso">
        <inertial>
            <origin xyz="0 0 1.379744604760853" rpy="0 0 0"/>
            <mass value="1" />
            <inertia ixx="100" ixy="0" ixz="0" iyy="100" iyz="0" izz="100" />
        </inertial>
        <visual>
            <origin xyz="0 0 1.379744604760853" rpy="0 0 0"/>
            <geometry>
                <box size="2.3950954821277763 1.9359869552106084 2.759489209521706" />
            </geometry>
            <material name="Green">
                <color rgba="0 180.0 0.0 1.0"/>
            </material>
        </visual>
        <collision>
            <origin xyz="0 0 1.379744604760853" rpy="0 0 0"/>
            <geometry>
                <box size="2.3950954821277763 1.9359869552106084 2.759489209521706" />
            </geometry>
        </collision>
    </link>
    <link name="Leg1">
        <inertial>
            <origin xyz="0.9018129564493852 0 0" rpy="0 0 0"/>
            <mass value="1" />
            <inertia ixx="100" ixy="0" ixz="0" iyy="100" iyz="0" izz="100" />
        </inertial>
        <visual>
            <origin xyz="0.9018129564493852 0 0" rpy="0 0 0"/>
            <geometry>
                <box size="1.8036259128987704 1.9855823151209893 1.6999806610076658" />
            </geometry>
            <material name="Green">
                <color rgba="0 180.0 0.0 1.0"/>
            </material>
        </visual>
        <collision>
            <origin xyz="0.9018129564493852 0 0" rpy="0 0 0"/>
            <geometry>
                <box size="1.8036259128987704 1.9855823151209893 1.6999806610076658" />
            </geometry>
        </collision>
    </link>
    <link name="Leg2">
        <inertial>
            <origin xyz="1.2893138043792258 0 0" rpy="0 0 0"/>
            <mass value="1" />
            <inertia ixx="100" ixy="0" ixz="0" iyy="100" iyz="0" izz="100" />
        </inertial>
        <visual>
            <origin xyz="1.2893138043792258 0 0" rpy="0 0 0"/>
            <geometry>
                <box size="2.5786276087584517 1.085705505915875 1.7148467377707288" />
            </geometry>
            <material name="Blue">
                <color rgba="0 1.0 1.0 1.0"/>
            </material>
        </visual>
        <collision>
            <origin xyz="1.2893138043792258 0 0" rpy="0 0 0"/>
            <geometry>
                <box size="2.5786276087584517 1.085705505915875 1.7148467377707288" />
            </geometry>
        </collision>
    </link>
    <link name="Leg3">
        <inertial>
            <origin xyz="1.4015690651317656 0 0" rpy="0 0 0"/>
            <mass value="1" />
            <inertia ixx="100" ixy="0" ixz="0" iyy="100" iyz="0" izz="100" />
        </inertial>
        <visual>
            <origin xyz="1.4015690651317656 0 0" rpy="0 0 0"/>
            <geometry>
                <box size="2.803138130263531 1.4198337840243858 2.235818798093782" />
            </geometry>
            <material name="Green">
                <color rgba="0 180.0 0.0 1.0"/>
            </material>
        </visual>
        <collision>
            <origin xyz="1.4015690651317656 0 0" rpy="0 0 0"/>
            <geometry>
                <box size="2.803138130263531 1.4198337840243858 2.235818798093782" />
            </geometry>
        </collision>
    </link>
    <link name="Leg4">
        <inertial>
            <origin xyz="0 0.8902255204344711 0" rpy="0 0 0"/>
            <mass value="1" />
            <inertia ixx="100" ixy="0" ixz="0" iyy="100" iyz="0" izz="100" />
        </inertial>
        <visual>
            <origin xyz="0 0.8902255204344711 0" rpy="0 0 0"/>
            <geometry>
                <box size="2.0963786064006658 1.7804510408689422 2.627654574924827" />
            </geometry>
            <material name="Green">
                <color rgba="0 180.0 0.0 1.0"/>
            </material>
        </visual>
        <collision>
            <origin xyz="0 0.8902255204344711 0" rpy="0 0 0"/>
            <geometry>
                <box size="2.0963786064006658 1.7804510408689422 2.627654574924827" />
            </geometry>
        </collision>
    </link>
    <link name="Leg5">
        <inertial>
            <origin xyz="0 0 1.0459414563171623" rpy="0 0 0"/>
            <mass value="1" />
            <inertia ixx="100" ixy="0" ixz="0" iyy="100" iyz="0" izz="100" />
        </inertial>
        <visual>
            <origin xyz="0 0 1.0459414563171623" rpy="0 0 0"/>
            <geometry>
                <box size="2.5791165113562915 2.2446498485030255 2.0918829126343246" />
            </geometry>
            <material name="Green">
                <color rgba="0 180.0 0.0 1.0"/>
            </material>
        </visual>
        <collision>
            <origin xyz="0 0 1.0459414563171623" rpy="0 0 0"/>
            <geometry>
                <box size="2.5791165113562915 2.2446498485030255 2.0918829126343246" />
            </geometry>
        </collision>
    </link>
    <link name="Leg6">
        <inertial>
            <origin xyz="0 1.3833768507578914 0" rpy="0 0 0"/>
            <mass value="1" />
            <inertia ixx="100" ixy="0" ixz="0" iyy="100" iyz="0" izz="100" />
        </inertial>
        <visual>
            <origin xyz="0 1.3833768507578914 0" rpy="0 0 0"/>
            <geometry>
                <box size="1.720130933972336 2.766753701515783 2.6237531447177918" />
            </geometry>
            <material name="Green">
                <color rgba="0 180.0 0.0 1.0"/>
            </material>
        </visual>
        <collision>
            <origin xyz="0 1.3833768507578914 0" rpy="0 0 0"/>
            <geometry>
                <box size="1.720130933972336 2.766753701515783 2.6237531447177918" />
            </geometry>
        </collision>
    </link>
    <link name="Leg7">
        <inertial>
            <origin xyz="0 1.0720610189916777 0" rpy="0 0 0"/>
            <mass value="1" />
            <inertia ixx="100" ixy="0" ixz="0" iyy="100" iyz="0" izz="100" />
        </inertial>
        <visual>
            <origin xyz="0 1.0720610189916777 0" rpy="0 0 0"/>
            <geometry>
                <box size="2.8921308196020497 2.1441220379833554 1.792857856414459" />
            </geometry>
            <material name="Green">
                <color rgba="0 180.0 0.0 1.0"/>
            </material>
        </visual>
        <collision>
            <origin xyz="0 1.0720610189916777 0" rpy="0 0 0"/>
            <geometry>
                <box size="2.8921308196020497 2.1441220379833554 1.792857856414459" />
            </geometry>
        </collision>
    </link>
    <link name="Leg8">
        <inertial>
            <origin xyz="1.0561619601076153 0 0" rpy="0 0 0"/>
            <mass value="1" />
            <inertia ixx="100" ixy="0" ixz="0" iyy="100" iyz="0" izz="100" />
        </inertial>
        <visual>
            <origin xyz="1.0561619601076153 0 0" rpy="0 0 0"/>
            <geometry>
                <box size="2.1123239202152306 2.565249113492311 1.8157519817136107" />
            </geometry>
            <material name="Blue">
                <color rgba="0 1.0 1.0 1.0"/>
            </material>
        </visual>
        <collision>
            <origin xyz="1.0561619601076153 0 0" rpy="0 0 0"/>
            <geometry>
                <box size="2.1123239202152306 2.565249113492311 1.8157519817136107" />
            </geometry>
        </collision>
    </link>
    <link name="Leg9">
        <inertial>
            <origin xyz="0 1.1724738017977874 0" rpy="0 0 0"/>
            <mass value="1" />
            <inertia ixx="100" ixy="0" ixz="0" iyy="100" iyz="0" izz="100" />
        </inertial>
        <visual>
            <origin xyz="0 1.1724738017977874 0" rpy="0 0 0"/>
            <geometry>
                <box size="1.118909139961933 2.3449476035955747 1.2627843996099342" />
            </geometry>
            <material name="Blue">
                <color rgba="0 1.0 1.0 1.0"/>
            </material>
        </visual>
        <collision>
            <origin xyz="0 1.1724738017977874 0" rpy="0 0 0"/>
            <geometry>
                <box size="1.118909139961933 2.3449476035955747 1.2627843996099342" />
            </geometry>
        </collision>
    </link>
    <link name="Leg10">
        <inertial>
            <origin xyz="0 1.1408424729684483 0" rpy="0 0 0"/>
            <mass value="1" />
            <inertia ixx="100" ixy="0" ixz="0" iyy="100" iyz="0" izz="100" />
        </inertial>
        <visual>
            <origin xyz="0 1.1408424729684483 0" rpy="0 0 0"/>
            <geometry>
                <box size="1.390511124488045 2.2816849459368966 2.68100482828795" />
            </geometry>
            <material name="Green">
                <color rgba="0 180.0 0.0 1.0"/>
            </material>
        </visual>
        <collision>
            <origin xyz="0 1.1408424729684483 0" rpy="0 0 0"/>
            <geometry>
                <box size="1.390511124488045 2.2816849459368966 2.68100482828795" />
            </geometry>
        </collision>
    </link>
    <link name="Leg11">
        <inertial>
            <origin xyz="0 0 0.8117766024863874" rpy="0 0 0"/>
            <mass value="1" />
            <inertia ixx="100" ixy="0" ixz="0" iyy="100" iyz="0" izz="100" />
        </inertial>
        <visual>
            <origin xyz="0 0 0.8117766024863874" rpy="0 0 0"/>
            <geometry>
                <box size="1.1196354796904069 1.3298783208268141 1.6235532049727748" />
            </geometry>
            <material name="Blue">
                <color rgba="0 1.0 1.0 1.0"/>
            </material>
        </visual>
        <collision>
            <origin xyz="0 0 0.8117766024863874" rpy="0 0 0"/>
            <geometry>
                <box size="1.1196354796904069 1.3298783208268141 1.6235532049727748" />
            </geometry>
        </collision>
    </link>
    <link name="Leg12">
        <inertial>
            <origin xyz="1.4900643918723695 0 0" rpy="0 0 0"/>
            <mass value="1" />
            <inertia ixx="100" ixy="0" ixz="0" iyy="100" iyz="0" izz="100" />
        </inertial>
        <visual>
            <origin xyz="1.4900643918723695 0 0" rpy="0 0 0"/>
            <geometry>
                <box size="2.980128783744739 2.691223029530864 1.400420555944149" />
            </geometry>
            <material name="Green">
                <color rgba="0 180.0 0.0 1.0"/>
            </material>
        </visual>
        <collision>
            <origin xyz="1.4900643918723695 0 0" rpy="0 0 0"/>
            <geometry>
                <box size="2.980128783744739 2.691223029530864 1.400420555944149" />
            </geometry>
        </collision>
    </link>
    <link name="Leg13">
        <inertial>
            <origin xyz="0 0 1.3984252028829607" rpy="0 0 0"/>
            <mass value="1" />
            <inertia ixx="100" ixy="0" ixz="0" iyy="100" iyz="0" izz="100" />
        </inertial>
        <visual>
            <origin xyz="0 0 1.3984252028829607" rpy="0 0 0"/>
            <geometry>
                <box size="1.739760685628071 1.4806721091453898 2.7968504057659214" />
            </geometry>
            <material name="Green">
                <color rgba="0 180.0 0.0 1.0"/>
            </material>
        </visual>
        <collision>
            <origin xyz="0 0 1.3984252028829607" rpy="0 0 0"/>
            <geometry>
                <box size="1.739760685628071 1.4806721091453898 2.7968504057659214" />
            </geometry>
        </collision>
    </link>
    <link name="Leg14">
        <inertial>
            <origin xyz="1.3464712726656571 0 0" rpy="0 0 0"/>
            <mass value="1" />
            <inertia ixx="100" ixy="0" ixz="0" iyy="100" iyz="0" izz="100" />
        </inertial>
        <visual>
            <origin xyz="1.3464712726656571 0 0" rpy="0 0 0"/>
            <geometry>
                <box size="2.6929425453313143 2.040102849148648 2.382821044476838" />
            </geometry>
            <material name="Green">
                <color rgba="0 180.0 0.0 1.0"/>
            </material>
        </visual>
        <collision>
            <origin xyz="1.3464712726656571 0 0" rpy="0 0 0"/>
            <geometry>
                <box size="2.6929425453313143 2.040102849148648 2.382821044476838" />
            </geometry>
        </collision>
    </link>
    <link name="Leg15">
        <inertial>
            <origin xyz="0 0.5405234612166044 0" rpy="0 0 0"/>
            <mass value="1" />
            <inertia ixx="100" ixy="0" ixz="0" iyy="100" iyz="0" izz="100" />
        </inertial>
        <visual>
            <origin xyz="0 0.5405234612166044 0" rpy="0 0 0"/>
            <geometry>
                <box size="2.8356667594512315 1.0810469224332089 1.328103140432187" />
            </geometry>
            <material name="Blue">
                <color rgba="0 1.0 1.0 1.0"/>
            </material>
        </visual>
        <collision>
            <origin xyz="0 0.5405234612166044 0" rpy="0 0 0"/>
            <geometry>
                <box size="2.8356667594512315 1.0810469224332089 1.328103140432187" />
            </geometry>
        </collision>
    </link>
    <link name="Leg16">
        <inertial>
            <origin xyz="0 0.5867544066989544 0" rpy="0 0 0"/>
            <mass value="1" />
            <inertia ixx="100" ixy="0" ixz="0" iyy="100" iyz="0" izz="100" />
        </inertial>
        <visual>
            <origin xyz="0 0.5867544066989544 0" rpy="0 0 0"/>
            <geometry>
                <box size="1.191228118206187 1.1735088133979088 1.1427259460572248" />
            </geometry>
            <material name="Blue">
                <color rgba="0 1.0 1.0 1.0"/>
            </material>
        </visual>
        <collision>
            <origin xyz="0 0.5867544066989544 0" rpy="0 0 0"/>
            <geometry>
                <box size="1.191228118206187 1.1735088133979088 1.1427259460572248" />
            </geometry>
        </collision>
    </link>
    <link name="Leg17">
        <inertial>
            <origin xyz="0 1.4430048377620515 0" rpy="0 0 0"/>
            <mass value="1" />
            <inertia ixx="100" ixy="0" ixz="0" iyy="100" iyz="0" izz="100" />
        </inertial>
        <visual>
            <origin xyz="0 1.4430048377620515 0" rpy="0 0 0"/>
            <geometry>
                <box size="1.7942692513574994 2.886009675524103 1.6975038717669015" />
            </geometry>
            <material name="Green">
                <color rgba="0 180.0 0.0 1.0"/>
            </material>
        </visual>
        <collision>
            <origin xyz="0 1.4430048377620515 0" rpy="0 0 0"/>
            <geometry>
                <box size="1.7942692513574994 2.886009675524103 1.6975038717669015" />
            </geometry>
        </collision>
    </link>
    <link name="Leg18">
        <inertial>
            <origin xyz="1.1265834512695363 0 0" rpy="0 0 0"/>
            <mass value="1" />
            <inertia ixx="100" ixy="0" ixz="0" iyy="100" iyz="0" izz="100" />
        </inertial>
        <visual>
            <origin xyz="1.1265834512695363 0 0" rpy="0 0 0"/>
            <geometry>
                <box size="2.2531669025390726 1.8351716251261514 2.452616721741534" />
            </geometry>
            <material name="Green">
                <color rgba="0 180.0 0.0 1.0"/>
            </material>
        </visual>
        <collision>
            <origin xyz="1.1265834512695363 0 0" rpy="0 0 0"/>
            <geometry>
                <box size="2.2531669025390726 1.8351716251261514 2.452616721741534" />
            </geometry>
        </collision>
    </link>
    <link name="Leg19">
        <inertial>
            <origin xyz="0 0.8972330130230258 0" rpy="0 0 0"/>
            <mass value="1" />
            <inertia ixx="100" ixy="0" ixz="0" iyy="100" iyz="0" izz="100" />
        </inertial>
        <visual>
            <origin xyz="0 0.8972330130230258 0" rpy="0 0 0"/>
            <geometry>
                <box size="2.3745712781285944 1.7944660260460517 2.5628621605054223" />
            </geometry>
            <material name="Green">
                <color rgba="0 180.0 0.0 1.0"/>
            </material>
        </visual>
        <collision>
            <origin xyz="0 0.8972330130230258 0" rpy="0 0 0"/>
            <geometry>
                <box size="2.3745712781285944 1.7944660260460517 2.5628621605054223" />
            </geometry>
        </collision>
    </link>
    <link name="Leg20">
        <inertial>
            <origin xyz="0 0 1.3598154287614228" rpy="0 0 0"/>
            <mass value="1" />
            <inertia ixx="100" ixy="0" ixz="0" iyy="100" iyz="0" izz="100" />
        </inertial>
        <visual>
            <origin xyz="0 0 1.3598154287614228" rpy="0 0 0"/>
            <geometry>
                <box size="2.2392474828250224 1.8887731216276171 2.7196308575228456" />
            </geometry>
            <material name="Blue">
                <color rgba="0 1.0 1.0 1.0"/>
            </material>
        </visual>
        <collision>
            <origin xyz="0 0 1.3598154287614228" rpy="0 0 0"/>
            <geometry>
                <box size="2.2392474828250224 1.8887731216276171 2.7196308575228456" />
            </geometry>
        </collision>
    </link>
    <link name="Leg21">
        <inertial>
            <origin xyz="0 0 1.1818815465200012" rpy="0 0 0"/>
            <mass value="1" />
            <inertia ixx="100" ixy="0" ixz="0" iyy="100" iyz="0" izz="100" />
        </inertial>
        <visual>
            <origin xyz="0 0 1.1818815465200012" rpy="0 0 0"/>
            <geometry>
                <box size="2.2495272462688565 2.734210824698488 2.3637630930400024" />
            </geometry>
            <material name="Blue">
                <color rgba="0 1.0 1.0 1.0"/>
            </material>
        </visual>
        <collision>
            <origin xyz="0 0 1.1818815465200012" rpy="0 0 0"/>
            <geometry>
                <box size="2.2495272462688565 2.734210824698488 2.3637630930400024" />
            </geometry>
        </collision>
    </link>
    <link name="Leg22">
        <inertial>
            <origin xyz="1.3580886501603797 0 0" rpy="0 0 0"/>
            <mass value="1" />
            <inertia ixx="100" ixy="0" ixz="0" iyy="100" iyz="0" izz="100" />
        </inertial>
        <visual>
            <origin xyz="1.3580886501603797 0 0" rpy="0 0 0"/>
            <geometry>
                <box size="2.7161773003207594 1.880112036123306 1.5837177592076035" />
            </geometry>
            <material name="Blue">
                <color rgba="0 1.0 1.0 1.0"/>
            </material>
        </visual>
        <collision>
            <origin xyz="1.3580886501603797 0 0" rpy="0 0 0"/>
            <geometry>
                <box size="2.7161773003207594 1.880112036123306 1.5837177592076035" />
            </geometry>
        </collision>
    </link>
    <link name="Leg23">
        <inertial>
            <origin xyz="0 0 0.5507023021445208" rpy="0 0 0"/>
            <mass value="1" />
            <inertia ixx="100" ixy="0" ixz="0" iyy="100" iyz="0" izz="100" />
        </inertial>
        <visual>
            <origin xyz="0 0 0.5507023021445208" rpy="0 0 0"/>
            <geometry>
                <box size="2.723339228013056 1.2299003346660753 1.1014046042890415" />
            </geometry>
            <material name="Blue">
                <color rgba="0 1.0 1.0 1.0"/>
            </material>
        </visual>
        <collision>
            <origin xyz="0 0 0.5507023021445208" rpy="0 0 0"/>
            <geometry>
                <box size="2.723339228013056 1.2299003346660753 1.1014046042890415" />
            </geometry>
        </collision>
    </link>
    <link name="Leg24">
        <inertial>
            <origin xyz="0 0 0.527250036958865" rpy="0 0 0"/>
            <mass value="1" />
            <inertia ixx="100" ixy="0" ixz="0" iyy="100" iyz="0" izz="100" />
        </inertial>
        <visual>
            <origin xyz="0 0 0.527250036958865" rpy="0 0 0"/>
            <geometry>
                <box size="2.8327935269956237 2.9336290411153283 1.05450007391773" />
            </geometry>
            <material name="Green">
                <color rgba="0 180.0 0.0 1.0"/>
            </material>
        </visual>
        <collision>
            <origin xyz="0 0 0.527250036958865" rpy="0 0 0"/>
            <geometry>
                <box size="2.8327935269956237 2.9336290411153283 1.05450007391773" />
            </geometry>
        </collision>
    </link>
    <link name="Leg25">
        <inertial>
            <origin xyz="1.3087131437450914 0 0" rpy="0 0 0"/>
            <mass value="1" />
            <inertia ixx="100" ixy="0" ixz="0" iyy="100" iyz="0" izz="100" />
        </inertial>
        <visual>
            <origin xyz="1.3087131437450914 0 0" rpy="0 0 0"/>
            <geometry>
                <box size="2.617426287490183 2.7873229642143214 1.5397446008730462" />
            </geometry>
            <material name="Green">
                <color rgba="0 180.0 0.0 1.0"/>
            </material>
        </visual>
        <collision>
            <origin xyz="1.3087131437450914 0 0" rpy="0 0 0"/>
            <geometry>
                <box size="2.617426287490183 2.7873229642143214 1.5397446008730462" />
            </geometry>
        </collision>
    </link>
    <link name="Leg26">
        <inertial>
            <origin xyz="0.921839058589974 0 0" rpy="0 0 0"/>
            <mass value="1" />
            <inertia ixx="100" ixy="0" ixz="0" iyy="100" iyz="0" izz="100" />
        </inertial>
        <visual>
            <origin xyz="0.921839058589974 0 0" rpy="0 0 0"/>
            <geometry>
                <box size="1.843678117179948 2.176463788851112 2.6598928066378376" />
            </geometry>
            <material name="Blue">
                <color rgba="0 1.0 1.0 1.0"/>
            </material>
        </visual>
        <collision>
            <origin xyz="0.921839058589974 0 0" rpy="0 0 0"/>
            <geometry>
                <box size="1.843678117179948 2.176463788851112 2.6598928066378376" />
            </geometry>
        </collision>
    </link>
    <link name="Leg27">
        <inertial>
            <origin xyz="1.4077456852826153 0 0" rpy="0 0 0"/>
            <mass value="1" />
            <inertia ixx="100" ixy="0" ixz="0" iyy="100" iyz="0" izz="100" />
        </inertial>
        <visual>
            <origin xyz="1.4077456852826153 0 0" rpy="0 0 0"/>
            <geometry>
                <box size="2.8154913705652307 1.294520985218866 1.006124720924914" />
            </geometry>
            <material name="Green">
                <color rgba="0 180.0 0.0 1.0"/>
            </material>
        </visual>
        <collision>
            <origin xyz="1.4077456852826153 0 0" rpy="0 0 0"/>
            <geometry>
                <box size="2.8154913705652307 1.294520985218866 1.006124720924914" />
            </geometry>
        </collision>
    </link>
    <joint name="Torso_Leg1" type="revolute">
       <parent link="Torso"/>
       <child  link="Leg1"/>
       <origin rpy="0 0 0" xyz="1.1975477410638882 0 1.379744604760853" />
     <axis xyz="1 0 0"/>
       <limit effort="0.0" lower="-3.14159" upper="3.14159" velocity="0.0"/>
    </joint>
    <joint name="Leg1_Leg2" type="revolute">
       <parent link="Leg1"/>
       <child  link="Leg2"/>
       <origin rpy="0 0 0" xyz="2.5786276087584517 0 0" />
     <axis xyz="1 0 0"/>
       <limit effort="0.0" lower="-3.14159" upper="3.14159" velocity="0.0"/>
    </joint>
    <joint name="Leg2_Leg3" type="revolute">
       <parent link="Leg2"/>
       <child  link="Leg3"/>
       <origin rpy="0 0 0" xyz="2.803138130263531 0 0" />
     <axis xyz="1 0 0"/>
       <limit effort="0.0" lower="-3.14159" upper="3.14159" velocity="0.0"/>
    </joint>
    <joint name="Leg1_Leg4" type="revolute">
       <parent link="Leg1"/>
       <child  link="Leg4"/>
       <origin rpy="0 0 0" xyz="2.5786276087584517 0.5428527529579374 0" />
     <axis xyz="1 0 0"/>
       <limit effort="0.0" lower="-3.14159" upper="3.14159" velocity="0.0"/>
    </joint>
    <joint name="Leg1_Leg5" type="revolute">
       <parent link="Leg1"/>
       <child  link="Leg5"/>
       <origin rpy="0 0 0" xyz="2.5786276087584517 0.5428527529579374 0.8574233688853644" />
     <axis xyz="1 0 0"/>
       <limit effort="0.0" lower="-3.14159" upper="3.14159" velocity="0.0"/>
    </joint>
    <joint name="Leg2_Leg6" type="revolute">
       <parent link="Leg2"/>
       <child  link="Leg6"/>
       <origin rpy="0 0 0" xyz="2.803138130263531 0.7099168920121929 0" />
     <axis xyz="1 0 0"/>
       <limit effort="0.0" lower="-3.14159" upper="3.14159" velocity="0.0"/>
    </joint>
    <joint name="Leg6_Leg7" type="revolute">
       <parent link="Leg6"/>
       <child  link="Leg7"/>
       <origin rpy="0 0 0" xyz="0 2.1441220379833554 0" />
     <axis xyz="1 0 0"/>
       <limit effort="0.0" lower="-3.14159" upper="3.14159" velocity="0.0"/>
    </joint>
    <joint name="Leg5_Leg8" type="revolute">
       <parent link="Leg5"/>
       <child  link="Leg8"/>
       <origin rpy="0 0 0" xyz="0.860065466986168 1.3833768507578914 0" />
     <axis xyz="1 0 0"/>
       <limit effort="0.0" lower="-3.14159" upper="3.14159" velocity="0.0"/>
    </joint>
    <joint name="Torso_Leg9" type="revolute">
       <parent link="Torso"/>
       <child  link="Leg9"/>
       <origin rpy="0 0 0" xyz="0.9018129564493852 0.9927911575604946 0" />
     <axis xyz="1 0 0"/>
       <limit effort="0.0" lower="-3.14159" upper="3.14159" velocity="0.0"/>
    </joint>
    <joint name="Leg9_Leg10" type="revolute">
       <parent link="Leg9"/>
       <child  link="Leg10"/>
       <origin rpy="0 0 0" xyz="0 2.2816849459368966 0" />
     <axis xyz="1 0 0"/>
       <limit effort="0.0" lower="-3.14159" upper="3.14159" velocity="0.0"/>
    </joint>
    <joint name="Leg8_Leg11" type="revolute">
       <parent link="Leg8"/>
       <child  link="Leg11"/>
       <origin rpy="0 0 0" xyz="0 1.1724738017977874 0.6313921998049671" />
     <axis xyz="1 0 0"/>
       <limit effort="0.0" lower="-3.14159" upper="3.14159" velocity="0.0"/>
    </joint>
    <joint name="Leg10_Leg12" type="revolute">
       <parent link="Leg10"/>
       <child  link="Leg12"/>
       <origin rpy="0 0 0" xyz="0.5598177398452034 0 0.8117766024863874" />
     <axis xyz="1 0 0"/>
       <limit effort="0.0" lower="-3.14159" upper="3.14159" velocity="0.0"/>
    </joint>
    <joint name="Leg3_Leg13" type="revolute">
       <parent link="Leg3"/>
       <child  link="Leg13"/>
       <origin rpy="0 0 0" xyz="0 0.8902255204344711 1.3138272874624135" />
     <axis xyz="1 0 0"/>
       <limit effort="0.0" lower="-3.14159" upper="3.14159" velocity="0.0"/>
    </joint>
    <joint name="Leg4_Leg14" type="revolute">
       <parent link="Leg4"/>
       <child  link="Leg14"/>
       <origin rpy="0 0 0" xyz="1.2895582556781457 0 1.0459414563171623" />
     <axis xyz="1 0 0"/>
       <limit effort="0.0" lower="-3.14159" upper="3.14159" velocity="0.0"/>
    </joint>
    <joint name="Leg11_Leg15" type="revolute">
       <parent link="Leg11"/>
       <child  link="Leg15"/>
       <origin rpy="0 0 0" xyz="1.4900643918723695 1.345611514765432 0" />
     <axis xyz="1 0 0"/>
       <limit effort="0.0" lower="-3.14159" upper="3.14159" velocity="0.0"/>
    </joint>
    <joint name="Leg7_Leg16" type="revolute">
       <parent link="Leg7"/>
       <child  link="Leg16"/>
       <origin rpy="0 0 0" xyz="1.0561619601076153 1.2826245567461556 0" />
     <axis xyz="1 0 0"/>
       <limit effort="0.0" lower="-3.14159" upper="3.14159" velocity="0.0"/>
    </joint>
    <joint name="Leg8_Leg17" type="revolute">
       <parent link="Leg8"/>
       <child  link="Leg17"/>
       <origin rpy="0 0 0" xyz="0 2.3449476035955747 0.6313921998049671" />
     <axis xyz="1 0 0"/>
       <limit effort="0.0" lower="-3.14159" upper="3.14159" velocity="0.0"/>
    </joint>
    <joint name="Leg13_Leg18" type="revolute">
       <parent link="Leg13"/>
       <child  link="Leg18"/>
       <origin rpy="0 0 0" xyz="2.6929425453313143 0 0" />
     <axis xyz="1 0 0"/>
       <limit effort="0.0" lower="-3.14159" upper="3.14159" velocity="0.0"/>
    </joint>
    <joint name="Leg5_Leg19" type="revolute">
       <parent link="Leg5"/>
       <child  link="Leg19"/>
       <origin rpy="0 0 0" xyz="0.860065466986168 2.766753701515783 0" />
     <axis xyz="1 0 0"/>
       <limit effort="0.0" lower="-3.14159" upper="3.14159" velocity="0.0"/>
    </joint>
    <joint name="Leg13_Leg20" type="revolute">
       <parent link="Leg13"/>
       <child  link="Leg20"/>
       <origin rpy="0 0 0" xyz="2.6929425453313143 0 1.191410522238419" />
     <axis xyz="1 0 0"/>
       <limit effort="0.0" lower="-3.14159" upper="3.14159" velocity="0.0"/>
    </joint>
    <joint name="Leg10_Leg21" type="revolute">
       <parent link="Leg10"/>
       <child  link="Leg21"/>
       <origin rpy="0 0 0" xyz="0.5598177398452034 0 1.6235532049727748" />
     <axis xyz="1 0 0"/>
       <limit effort="0.0" lower="-3.14159" upper="3.14159" velocity="0.0"/>
    </joint>
    <joint name="Leg11_Leg22" type="revolute">
       <parent link="Leg11"/>
       <child  link="Leg22"/>
       <origin rpy="0 0 0" xyz="2.980128783744739 1.345611514765432 0" />
     <axis xyz="1 0 0"/>
       <limit effort="0.0" lower="-3.14159" upper="3.14159" velocity="0.0"/>
    </joint>
    <joint name="Leg7_Leg23" type="revolute">
       <parent link="Leg7"/>
       <child  link="Leg23"/>
       <origin rpy="0 0 0" xyz="1.0561619601076153 1.2826245567461556 0.9078759908568054" />
     <axis xyz="1 0 0"/>
       <limit effort="0.0" lower="-3.14159" upper="3.14159" velocity="0.0"/>
    </joint>
    <joint name="Leg2_Leg24" type="revolute">
       <parent link="Leg2"/>
       <child  link="Leg24"/>
       <origin rpy="0 0 0" xyz="2.803138130263531 0.7099168920121929 1.117909399046891" />
     <axis xyz="1 0 0"/>
       <limit effort="0.0" lower="-3.14159" upper="3.14159" velocity="0.0"/>
    </joint>
    <joint name="Leg9_Leg25" type="revolute">
       <parent link="Leg9"/>
       <child  link="Leg25"/>
       <origin rpy="0 0 0" xyz="0.6952555622440225 2.2816849459368966 0" />
     <axis xyz="1 0 0"/>
       <limit effort="0.0" lower="-3.14159" upper="3.14159" velocity="0.0"/>
    </joint>
    <joint name="Leg24_Leg26" type="revolute">
       <parent link="Leg24"/>
       <child  link="Leg26"/>
       <origin rpy="0 0 0" xyz="2.617426287490183 0 0" />
     <axis xyz="1 0 0"/>
       <limit effort="0.0" lower="-3.14159" upper="3.14159" velocity="0.0"/>
    </joint>
    <joint name="Leg20_Leg27" type="revolute">
       <parent link="Leg20"/>
       <child  link="Leg27"/>
       <origin rpy="0 0 0" xyz="1.1247636231344282 0 1.1818815465200012" />
     <axis xyz="1 0 0"/>
       <limit effort="0.0" lower="-3.14159" upper="3.14159" velocity="0.0"/>
    </joint>
</robot>