<robot name = "robot">
    <link name="Torso">
        <inertial>
            <origin xyz="0 0 0.9496854567871653" rpy="0 0 0"/>
            <mass value="1" />
            <inertia ixx="100" ixy="0" ixz="0" iyy="100" iyz="0" izz="100" />
        </inertial>
        <visual>
            <origin xyz="0 0 0.9496854567871653" rpy="0 0 0"/>
            <geometry>
                <box size="1.1328707998274112 1.3728570799429443 1.8993709135743306" />
            </geometry>
            <material name="Green">
                <color rgba="0 180.0 0.0 1.0"/>
            </material>
        </visual>
        <collision>
            <origin xyz="0 0 0.9496854567871653" rpy="0 0 0"/>
            <geometry>
                <box size="1.1328707998274112 1.3728570799429443 1.8993709135743306" />
            </geometry>
        </collision>
    </link>
    <link name="Leg1">
        <inertial>
            <origin xyz="0.8825350415674043 0 0" rpy="0 0 0"/>
            <mass value="1" />
            <inertia ixx="100" ixy="0" ixz="0" iyy="100" iyz="0" izz="100" />
        </inertial>
        <visual>
            <origin xyz="0.8825350415674043 0 0" rpy="0 0 0"/>
            <geometry>
                <box size="1.7650700831348085 2.6867490492597383 2.4372031537433383" />
            </geometry>
            <material name="Blue">
                <color rgba="0 1.0 1.0 1.0"/>
            </material>
        </visual>
        <collision>
            <origin xyz="0.8825350415674043 0 0" rpy="0 0 0"/>
            <geometry>
                <box size="1.7650700831348085 2.6867490492597383 2.4372031537433383" />
            </geometry>
        </collision>
    </link>
    <link name="Leg2">
        <inertial>
            <origin xyz="0.8260950276650847 0 0" rpy="0 0 0"/>
            <mass value="1" />
            <inertia ixx="100" ixy="0" ixz="0" iyy="100" iyz="0" izz="100" />
        </inertial>
        <visual>
            <origin xyz="0.8260950276650847 0 0" rpy="0 0 0"/>
            <geometry>
                <box size="1.6521900553301694 1.1961604004007507 1.6826359746258008" />
            </geometry>
            <material name="Green">
                <color rgba="0 180.0 0.0 1.0"/>
            </material>
        </visual>
        <collision>
            <origin xyz="0.8260950276650847 0 0" rpy="0 0 0"/>
            <geometry>
                <box size="1.6521900553301694 1.1961604004007507 1.6826359746258008" />
            </geometry>
        </collision>
    </link>
    <link name="Leg3">
        <inertial>
            <origin xyz="0.5719311297653682 0 0" rpy="0 0 0"/>
            <mass value="1" />
            <inertia ixx="100" ixy="0" ixz="0" iyy="100" iyz="0" izz="100" />
        </inertial>
        <visual>
            <origin xyz="0.5719311297653682 0 0" rpy="0 0 0"/>
            <geometry>
                <box size="1.1438622595307364 2.2892445809548896 1.4320172672148106" />
            </geometry>
            <material name="Blue">
                <color rgba="0 1.0 1.0 1.0"/>
            </material>
        </visual>
        <collision>
            <origin xyz="0.5719311297653682 0 0" rpy="0 0 0"/>
            <geometry>
                <box size="1.1438622595307364 2.2892445809548896 1.4320172672148106" />
            </geometry>
        </collision>
    </link>
    <link name="Leg4">
        <inertial>
            <origin xyz="0 1.0748076832708975 0" rpy="0 0 0"/>
            <mass value="1" />
            <inertia ixx="100" ixy="0" ixz="0" iyy="100" iyz="0" izz="100" />
        </inertial>
        <visual>
            <origin xyz="0 1.0748076832708975 0" rpy="0 0 0"/>
            <geometry>
                <box size="2.82798078515029 2.149615366541795 1.5483739399942515" />
            </geometry>
            <material name="Blue">
                <color rgba="0 1.0 1.0 1.0"/>
            </material>
        </visual>
        <collision>
            <origin xyz="0 1.0748076832708975 0" rpy="0 0 0"/>
            <geometry>
                <box size="2.82798078515029 2.149615366541795 1.5483739399942515" />
            </geometry>
        </collision>
    </link>
    <link name="Leg5">
        <inertial>
            <origin xyz="0 0 0.8516032723165982" rpy="0 0 0"/>
            <mass value="1" />
            <inertia ixx="100" ixy="0" ixz="0" iyy="100" iyz="0" izz="100" />
        </inertial>
        <visual>
            <origin xyz="0 0 0.8516032723165982" rpy="0 0 0"/>
            <geometry>
                <box size="1.8370022666743275 2.8319292978966066 1.7032065446331963" />
            </geometry>
            <material name="Green">
                <color rgba="0 180.0 0.0 1.0"/>
            </material>
        </visual>
        <collision>
            <origin xyz="0 0 0.8516032723165982" rpy="0 0 0"/>
            <geometry>
                <box size="1.8370022666743275 2.8319292978966066 1.7032065446331963" />
            </geometry>
        </collision>
    </link>
    <link name="Leg6">
        <inertial>
            <origin xyz="1.0753306557527056 0 0" rpy="0 0 0"/>
            <mass value="1" />
            <inertia ixx="100" ixy="0" ixz="0" iyy="100" iyz="0" izz="100" />
        </inertial>
        <visual>
            <origin xyz="1.0753306557527056 0 0" rpy="0 0 0"/>
            <geometry>
                <box size="2.150661311505411 2.1654282084384686 2.8213948635061925" />
            </geometry>
            <material name="Blue">
                <color rgba="0 1.0 1.0 1.0"/>
            </material>
        </visual>
        <collision>
            <origin xyz="1.0753306557527056 0 0" rpy="0 0 0"/>
            <geometry>
                <box size="2.150661311505411 2.1654282084384686 2.8213948635061925" />
            </geometry>
        </collision>
    </link>
    <link name="Leg7">
        <inertial>
            <origin xyz="0.8077156301440626 0 0" rpy="0 0 0"/>
            <mass value="1" />
            <inertia ixx="100" ixy="0" ixz="0" iyy="100" iyz="0" izz="100" />
        </inertial>
        <visual>
            <origin xyz="0.8077156301440626 0 0" rpy="0 0 0"/>
            <geometry>
                <box size="1.6154312602881251 2.8438581647918304 1.907101913041253" />
            </geometry>
            <material name="Green">
                <color rgba="0 180.0 0.0 1.0"/>
            </material>
        </visual>
        <collision>
            <origin xyz="0.8077156301440626 0 0" rpy="0 0 0"/>
            <geometry>
                <box size="1.6154312602881251 2.8438581647918304 1.907101913041253" />
            </geometry>
        </collision>
    </link>
    <link name="Leg8">
        <inertial>
            <origin xyz="0 0.9081679222725912 0" rpy="0 0 0"/>
            <mass value="1" />
            <inertia ixx="100" ixy="0" ixz="0" iyy="100" iyz="0" izz="100" />
        </inertial>
        <visual>
            <origin xyz="0 0.9081679222725912 0" rpy="0 0 0"/>
            <geometry>
                <box size="2.857870331636027 1.8163358445451825 1.798306886132569" />
            </geometry>
            <material name="Blue">
                <color rgba="0 1.0 1.0 1.0"/>
            </material>
        </visual>
        <collision>
            <origin xyz="0 0.9081679222725912 0" rpy="0 0 0"/>
            <geometry>
                <box size="2.857870331636027 1.8163358445451825 1.798306886132569" />
            </geometry>
        </collision>
    </link>
    <link name="Leg9">
        <inertial>
            <origin xyz="0 0 1.0162649650397657" rpy="0 0 0"/>
            <mass value="1" />
            <inertia ixx="100" ixy="0" ixz="0" iyy="100" iyz="0" izz="100" />
        </inertial>
        <visual>
            <origin xyz="0 0 1.0162649650397657" rpy="0 0 0"/>
            <geometry>
                <box size="2.460576768039606 2.358248003191924 2.0325299300795314" />
            </geometry>
            <material name="Green">
                <color rgba="0 180.0 0.0 1.0"/>
            </material>
        </visual>
        <collision>
            <origin xyz="0 0 1.0162649650397657" rpy="0 0 0"/>
            <geometry>
                <box size="2.460576768039606 2.358248003191924 2.0325299300795314" />
            </geometry>
        </collision>
    </link>
    <link name="Leg10">
        <inertial>
            <origin xyz="0 0.7183052476307145 0" rpy="0 0 0"/>
            <mass value="1" />
            <inertia ixx="100" ixy="0" ixz="0" iyy="100" iyz="0" izz="100" />
        </inertial>
        <visual>
            <origin xyz="0 0.7183052476307145 0" rpy="0 0 0"/>
            <geometry>
                <box size="2.915320837608772 1.436610495261429 2.739836229246669" />
            </geometry>
            <material name="Blue">
                <color rgba="0 1.0 1.0 1.0"/>
            </material>
        </visual>
        <collision>
            <origin xyz="0 0.7183052476307145 0" rpy="0 0 0"/>
            <geometry>
                <box size="2.915320837608772 1.436610495261429 2.739836229246669" />
            </geometry>
        </collision>
    </link>
    <link name="Leg11">
        <inertial>
            <origin xyz="0 0 0.9838961645965446" rpy="0 0 0"/>
            <mass value="1" />
            <inertia ixx="100" ixy="0" ixz="0" iyy="100" iyz="0" izz="100" />
        </inertial>
        <visual>
            <origin xyz="0 0 0.9838961645965446" rpy="0 0 0"/>
            <geometry>
                <box size="2.9353570505640594 2.39112318437891 1.9677923291930892" />
            </geometry>
            <material name="Green">
                <color rgba="0 180.0 0.0 1.0"/>
            </material>
        </visual>
        <collision>
            <origin xyz="0 0 0.9838961645965446" rpy="0 0 0"/>
            <geometry>
                <box size="2.9353570505640594 2.39112318437891 1.9677923291930892" />
            </geometry>
        </collision>
    </link>
    <link name="Leg12">
        <inertial>
            <origin xyz="1.3568765126417128 0 0" rpy="0 0 0"/>
            <mass value="1" />
            <inertia ixx="100" ixy="0" ixz="0" iyy="100" iyz="0" izz="100" />
        </inertial>
        <visual>
            <origin xyz="1.3568765126417128 0 0" rpy="0 0 0"/>
            <geometry>
                <box size="2.7137530252834257 2.3858646018835525 1.2054897885841995" />
            </geometry>
            <material name="Green">
                <color rgba="0 180.0 0.0 1.0"/>
            </material>
        </visual>
        <collision>
            <origin xyz="1.3568765126417128 0 0" rpy="0 0 0"/>
            <geometry>
                <box size="2.7137530252834257 2.3858646018835525 1.2054897885841995" />
            </geometry>
        </collision>
    </link>
    <link name="Leg13">
        <inertial>
            <origin xyz="0 1.2807316670413331 0" rpy="0 0 0"/>
            <mass value="1" />
            <inertia ixx="100" ixy="0" ixz="0" iyy="100" iyz="0" izz="100" />
        </inertial>
        <visual>
            <origin xyz="0 1.2807316670413331 0" rpy="0 0 0"/>
            <geometry>
                <box size="1.7360168806676497 2.5614633340826662 1.8270006593659036" />
            </geometry>
            <material name="Green">
                <color rgba="0 180.0 0.0 1.0"/>
            </material>
        </visual>
        <collision>
            <origin xyz="0 1.2807316670413331 0" rpy="0 0 0"/>
            <geometry>
                <box size="1.7360168806676497 2.5614633340826662 1.8270006593659036" />
            </geometry>
        </collision>
    </link>
    <link name="Leg14">
        <inertial>
            <origin xyz="0 0.8962055091357942 0" rpy="0 0 0"/>
            <mass value="1" />
            <inertia ixx="100" ixy="0" ixz="0" iyy="100" iyz="0" izz="100" />
        </inertial>
        <visual>
            <origin xyz="0 0.8962055091357942 0" rpy="0 0 0"/>
            <geometry>
                <box size="2.8536732209914595 1.7924110182715884 2.663191577847501" />
            </geometry>
            <material name="Blue">
                <color rgba="0 1.0 1.0 1.0"/>
            </material>
        </visual>
        <collision>
            <origin xyz="0 0.8962055091357942 0" rpy="0 0 0"/>
            <geometry>
                <box size="2.8536732209914595 1.7924110182715884 2.663191577847501" />
            </geometry>
        </collision>
    </link>
    <link name="Leg15">
        <inertial>
            <origin xyz="0 1.4710561412207306 0" rpy="0 0 0"/>
            <mass value="1" />
            <inertia ixx="100" ixy="0" ixz="0" iyy="100" iyz="0" izz="100" />
        </inertial>
        <visual>
            <origin xyz="0 1.4710561412207306 0" rpy="0 0 0"/>
            <geometry>
                <box size="2.052906363296871 2.942112282441461 1.657808858593549" />
            </geometry>
            <material name="Blue">
                <color rgba="0 1.0 1.0 1.0"/>
            </material>
        </visual>
        <collision>
            <origin xyz="0 1.4710561412207306 0" rpy="0 0 0"/>
            <geometry>
                <box size="2.052906363296871 2.942112282441461 1.657808858593549" />
            </geometry>
        </collision>
    </link>
    <link name="Leg16">
        <inertial>
            <origin xyz="0 0.8520736566314342 0" rpy="0 0 0"/>
            <mass value="1" />
            <inertia ixx="100" ixy="0" ixz="0" iyy="100" iyz="0" izz="100" />
        </inertial>
        <visual>
            <origin xyz="0 0.8520736566314342 0" rpy="0 0 0"/>
            <geometry>
                <box size="1.2647419102098134 1.7041473132628684 2.4322257629523865" />
            </geometry>
            <material name="Blue">
                <color rgba="0 1.0 1.0 1.0"/>
            </material>
        </visual>
        <collision>
            <origin xyz="0 0.8520736566314342 0" rpy="0 0 0"/>
            <geometry>
                <box size="1.2647419102098134 1.7041473132628684 2.4322257629523865" />
            </geometry>
        </collision>
    </link>
    <link name="Leg17">
        <inertial>
            <origin xyz="0 0.5217510269230234 0" rpy="0 0 0"/>
            <mass value="1" />
            <inertia ixx="100" ixy="0" ixz="0" iyy="100" iyz="0" izz="100" />
        </inertial>
        <visual>
            <origin xyz="0 0.5217510269230234 0" rpy="0 0 0"/>
            <geometry>
                <box size="2.52144309224688 1.0435020538460469 2.1972121660649573" />
            </geometry>
            <material name="Green">
                <color rgba="0 180.0 0.0 1.0"/>
            </material>
        </visual>
        <collision>
            <origin xyz="0 0.5217510269230234 0" rpy="0 0 0"/>
            <geometry>
                <box size="2.52144309224688 1.0435020538460469 2.1972121660649573" />
            </geometry>
        </collision>
    </link>
    <link name="Leg18">
        <inertial>
            <origin xyz="0 0 0.9207712922187336" rpy="0 0 0"/>
            <mass value="1" />
            <inertia ixx="100" ixy="0" ixz="0" iyy="100" iyz="0" izz="100" />
        </inertial>
        <visual>
            <origin xyz="0 0 0.9207712922187336" rpy="0 0 0"/>
            <geometry>
                <box size="2.409559058746185 2.504739689095432 1.841542584437467" />
            </geometry>
            <material name="Blue">
                <color rgba="0 1.0 1.0 1.0"/>
            </material>
        </visual>
        <collision>
            <origin xyz="0 0 0.9207712922187336" rpy="0 0 0"/>
            <geometry>
                <box size="2.409559058746185 2.504739689095432 1.841542584437467" />
            </geometry>
        </collision>
    </link>
    <link name="Leg19">
        <inertial>
            <origin xyz="0 1.3469784567987761 0" rpy="0 0 0"/>
            <mass value="1" />
            <inertia ixx="100" ixy="0" ixz="0" iyy="100" iyz="0" izz="100" />
        </inertial>
        <visual>
            <origin xyz="0 1.3469784567987761 0" rpy="0 0 0"/>
            <geometry>
                <box size="1.4665750958389892 2.6939569135975523 1.4579315270773567" />
            </geometry>
            <material name="Green">
                <color rgba="0 180.0 0.0 1.0"/>
            </material>
        </visual>
        <collision>
            <origin xyz="0 1.3469784567987761 0" rpy="0 0 0"/>
            <geometry>
                <box size="1.4665750958389892 2.6939569135975523 1.4579315270773567" />
            </geometry>
        </collision>
    </link>
    <link name="Leg20">
        <inertial>
            <origin xyz="0 0 0.6509623974624879" rpy="0 0 0"/>
            <mass value="1" />
            <inertia ixx="100" ixy="0" ixz="0" iyy="100" iyz="0" izz="100" />
        </inertial>
        <visual>
            <origin xyz="0 0 0.6509623974624879" rpy="0 0 0"/>
            <geometry>
                <box size="2.7930672744862233 1.0976695998637649 1.3019247949249757" />
            </geometry>
            <material name="Green">
                <color rgba="0 180.0 0.0 1.0"/>
            </material>
        </visual>
        <collision>
            <origin xyz="0 0 0.6509623974624879" rpy="0 0 0"/>
            <geometry>
                <box size="2.7930672744862233 1.0976695998637649 1.3019247949249757" />
            </geometry>
        </collision>
    </link>
    <link name="Leg21">
        <inertial>
            <origin xyz="0.9966015256324274 0 0" rpy="0 0 0"/>
            <mass value="1" />
            <inertia ixx="100" ixy="0" ixz="0" iyy="100" iyz="0" izz="100" />
        </inertial>
        <visual>
            <origin xyz="0.9966015256324274 0 0" rpy="0 0 0"/>
            <geometry>
                <box size="1.9932030512648549 1.8127412295225256 2.1217811090459193" />
            </geometry>
            <material name="Green">
                <color rgba="0 180.0 0.0 1.0"/>
            </material>
        </visual>
        <collision>
            <origin xyz="0.9966015256324274 0 0" rpy="0 0 0"/>
            <geometry>
                <box size="1.9932030512648549 1.8127412295225256 2.1217811090459193" />
            </geometry>
        </collision>
    </link>
    <link name="Leg22">
        <inertial>
            <origin xyz="0 0 0.6136825356661639" rpy="0 0 0"/>
            <mass value="1" />
            <inertia ixx="100" ixy="0" ixz="0" iyy="100" iyz="0" izz="100" />
        </inertial>
        <visual>
            <origin xyz="0 0 0.6136825356661639" rpy="0 0 0"/>
            <geometry>
                <box size="1.5678071464927703 2.346601998034606 1.2273650713323279" />
            </geometry>
            <material name="Blue">
                <color rgba="0 1.0 1.0 1.0"/>
            </material>
        </visual>
        <collision>
            <origin xyz="0 0 0.6136825356661639" rpy="0 0 0"/>
            <geometry>
                <box size="1.5678071464927703 2.346601998034606 1.2273650713323279" />
            </geometry>
        </collision>
    </link>
    <link name="Leg23">
        <inertial>
            <origin xyz="0 0 0.6586216859573413" rpy="0 0 0"/>
            <mass value="1" />
            <inertia ixx="100" ixy="0" ixz="0" iyy="100" iyz="0" izz="100" />
        </inertial>
        <visual>
            <origin xyz="0 0 0.6586216859573413" rpy="0 0 0"/>
            <geometry>
                <box size="1.5805046904407525 1.6174699473397551 1.3172433719146825" />
            </geometry>
            <material name="Green">
                <color rgba="0 180.0 0.0 1.0"/>
            </material>
        </visual>
        <collision>
            <origin xyz="0 0 0.6586216859573413" rpy="0 0 0"/>
            <geometry>
                <box size="1.5805046904407525 1.6174699473397551 1.3172433719146825" />
            </geometry>
        </collision>
    </link>
    <link name="Leg24">
        <inertial>
            <origin xyz="0 0.6052510332384539 0" rpy="0 0 0"/>
            <mass value="1" />
            <inertia ixx="100" ixy="0" ixz="0" iyy="100" iyz="0" izz="100" />
        </inertial>
        <visual>
            <origin xyz="0 0.6052510332384539 0" rpy="0 0 0"/>
            <geometry>
                <box size="1.555526094526824 1.2105020664769077 1.096375923264648" />
            </geometry>
            <material name="Green">
                <color rgba="0 180.0 0.0 1.0"/>
            </material>
        </visual>
        <collision>
            <origin xyz="0 0.6052510332384539 0" rpy="0 0 0"/>
            <geometry>
                <box size="1.555526094526824 1.2105020664769077 1.096375923264648" />
            </geometry>
        </collision>
    </link>
    <link name="Leg25">
        <inertial>
            <origin xyz="0 0.5135416309690775 0" rpy="0 0 0"/>
            <mass value="1" />
            <inertia ixx="100" ixy="0" ixz="0" iyy="100" iyz="0" izz="100" />
        </inertial>
        <visual>
            <origin xyz="0 0.5135416309690775 0" rpy="0 0 0"/>
            <geometry>
                <box size="2.7446599015334945 1.027083261938155 1.4872091333228201" />
            </geometry>
            <material name="Blue">
                <color rgba="0 1.0 1.0 1.0"/>
            </material>
        </visual>
        <collision>
            <origin xyz="0 0.5135416309690775 0" rpy="0 0 0"/>
            <geometry>
                <box size="2.7446599015334945 1.027083261938155 1.4872091333228201" />
            </geometry>
        </collision>
    </link>
    <link name="Leg26">
        <inertial>
            <origin xyz="0 0.7547233218228621 0" rpy="0 0 0"/>
            <mass value="1" />
            <inertia ixx="100" ixy="0" ixz="0" iyy="100" iyz="0" izz="100" />
        </inertial>
        <visual>
            <origin xyz="0 0.7547233218228621 0" rpy="0 0 0"/>
            <geometry>
                <box size="2.695035825709465 1.5094466436457241 1.8198127476574564" />
            </geometry>
            <material name="Green">
                <color rgba="0 180.0 0.0 1.0"/>
            </material>
        </visual>
        <collision>
            <origin xyz="0 0.7547233218228621 0" rpy="0 0 0"/>
            <geometry>
                <box size="2.695035825709465 1.5094466436457241 1.8198127476574564" />
            </geometry>
        </collision>
    </link>
    <joint name="Torso_Leg1" type="revolute">
       <parent link="Torso"/>
       <child  link="Leg1"/>
       <origin rpy="0 0 0" xyz="0.5664353999137056 0 0.9496854567871653" />
     <axis xyz="1 0 0"/>
       <limit effort="0.0" lower="-3.14159" upper="3.14159" velocity="0.0"/>
    </joint>
    <joint name="Leg1_Leg2" type="revolute">
       <parent link="Leg1"/>
       <child  link="Leg2"/>
       <origin rpy="0 0 0" xyz="1.6521900553301694 0 0" />
     <axis xyz="1 0 0"/>
       <limit effort="0.0" lower="-3.14159" upper="3.14159" velocity="0.0"/>
    </joint>
    <joint name="Leg2_Leg3" type="revolute">
       <parent link="Leg2"/>
       <child  link="Leg3"/>
       <origin rpy="0 0 0" xyz="1.1438622595307364 0 0" />
     <axis xyz="1 0 0"/>
       <limit effort="0.0" lower="-3.14159" upper="3.14159" velocity="0.0"/>
    </joint>
    <joint name="Leg3_Leg4" type="revolute">
       <parent link="Leg3"/>
       <child  link="Leg4"/>
       <origin rpy="0 0 0" xyz="0 2.149615366541795 0" />
     <axis xyz="1 0 0"/>
       <limit effort="0.0" lower="-3.14159" upper="3.14159" velocity="0.0"/>
    </joint>
    <joint name="Torso_Leg5" type="revolute">
       <parent link="Torso"/>
       <child  link="Leg5"/>
       <origin rpy="0 0 0" xyz="0.8825350415674043 0 1.2186015768716691" />
     <axis xyz="1 0 0"/>
       <limit effort="0.0" lower="-3.14159" upper="3.14159" velocity="0.0"/>
    </joint>
    <joint name="Leg3_Leg6" type="revolute">
       <parent link="Leg3"/>
       <child  link="Leg6"/>
       <origin rpy="0 0 0" xyz="1.413990392575145 2.149615366541795 0" />
     <axis xyz="1 0 0"/>
       <limit effort="0.0" lower="-3.14159" upper="3.14159" velocity="0.0"/>
    </joint>
    <joint name="Leg6_Leg7" type="revolute">
       <parent link="Leg6"/>
       <child  link="Leg7"/>
       <origin rpy="0 0 0" xyz="1.6154312602881251 0 0" />
     <axis xyz="1 0 0"/>
       <limit effort="0.0" lower="-3.14159" upper="3.14159" velocity="0.0"/>
    </joint>
    <joint name="Leg6_Leg8" type="revolute">
       <parent link="Leg6"/>
       <child  link="Leg8"/>
       <origin rpy="0 0 0" xyz="1.6154312602881251 1.4219290823959152 0" />
     <axis xyz="1 0 0"/>
       <limit effort="0.0" lower="-3.14159" upper="3.14159" velocity="0.0"/>
    </joint>
    <joint name="Leg2_Leg9" type="revolute">
       <parent link="Leg2"/>
       <child  link="Leg9"/>
       <origin rpy="0 0 0" xyz="1.1438622595307364 0 0.7160086336074053" />
     <axis xyz="1 0 0"/>
       <limit effort="0.0" lower="-3.14159" upper="3.14159" velocity="0.0"/>
    </joint>
    <joint name="Leg5_Leg10" type="revolute">
       <parent link="Leg5"/>
       <child  link="Leg10"/>
       <origin rpy="0 0 0" xyz="1.0753306557527056 1.0827141042192343 0" />
     <axis xyz="1 0 0"/>
       <limit effort="0.0" lower="-3.14159" upper="3.14159" velocity="0.0"/>
    </joint>
    <joint name="Leg4_Leg11" type="revolute">
       <parent link="Leg4"/>
       <child  link="Leg11"/>
       <origin rpy="0 0 0" xyz="0 0 1.7032065446331963" />
     <axis xyz="1 0 0"/>
       <limit effort="0.0" lower="-3.14159" upper="3.14159" velocity="0.0"/>
    </joint>
    <joint name="Leg9_Leg12" type="revolute">
       <parent link="Leg9"/>
       <child  link="Leg12"/>
       <origin rpy="0 0 0" xyz="1.457660418804386 0.7183052476307145 0" />
     <axis xyz="1 0 0"/>
       <limit effort="0.0" lower="-3.14159" upper="3.14159" velocity="0.0"/>
    </joint>
    <joint name="Leg1_Leg13" type="revolute">
       <parent link="Leg1"/>
       <child  link="Leg13"/>
       <origin rpy="0 0 0" xyz="1.6521900553301694 0.5980802002003753 0" />
     <axis xyz="1 0 0"/>
       <limit effort="0.0" lower="-3.14159" upper="3.14159" velocity="0.0"/>
    </joint>
    <joint name="Torso_Leg14" type="revolute">
       <parent link="Torso"/>
       <child  link="Leg14"/>
       <origin rpy="0 0 0" xyz="0.8825350415674043 1.3433745246298692 1.2186015768716691" />
     <axis xyz="1 0 0"/>
       <limit effort="0.0" lower="-3.14159" upper="3.14159" velocity="0.0"/>
    </joint>
    <joint name="Leg2_Leg15" type="revolute">
       <parent link="Leg2"/>
       <child  link="Leg15"/>
       <origin rpy="0 0 0" xyz="1.1438622595307364 1.1446222904774448 0.7160086336074053" />
     <axis xyz="1 0 0"/>
       <limit effort="0.0" lower="-3.14159" upper="3.14159" velocity="0.0"/>
    </joint>
    <joint name="Leg12_Leg16" type="revolute">
       <parent link="Leg12"/>
       <child  link="Leg16"/>
       <origin rpy="0 0 0" xyz="0 2.5614633340826662 0" />
     <axis xyz="1 0 0"/>
       <limit effort="0.0" lower="-3.14159" upper="3.14159" velocity="0.0"/>
    </joint>
    <joint name="Leg8_Leg17" type="revolute">
       <parent link="Leg8"/>
       <child  link="Leg17"/>
       <origin rpy="0 0 0" xyz="0 1.179124001595962 1.0162649650397657" />
     <axis xyz="1 0 0"/>
       <limit effort="0.0" lower="-3.14159" upper="3.14159" velocity="0.0"/>
    </joint>
    <joint name="Leg3_Leg18" type="revolute">
       <parent link="Leg3"/>
       <child  link="Leg18"/>
       <origin rpy="0 0 0" xyz="1.413990392575145 2.149615366541795 0.7741869699971258" />
     <axis xyz="1 0 0"/>
       <limit effort="0.0" lower="-3.14159" upper="3.14159" velocity="0.0"/>
    </joint>
    <joint name="Leg17_Leg19" type="revolute">
       <parent link="Leg17"/>
       <child  link="Leg19"/>
       <origin rpy="0 0 0" xyz="0 1.252369844547716 0.9207712922187336" />
     <axis xyz="1 0 0"/>
       <limit effort="0.0" lower="-3.14159" upper="3.14159" velocity="0.0"/>
    </joint>
    <joint name="Leg5_Leg20" type="revolute">
       <parent link="Leg5"/>
       <child  link="Leg20"/>
       <origin rpy="0 0 0" xyz="1.0753306557527056 1.0827141042192343 1.4106974317530963" />
     <axis xyz="1 0 0"/>
       <limit effort="0.0" lower="-3.14159" upper="3.14159" velocity="0.0"/>
    </joint>
    <joint name="Leg14_Leg21" type="revolute">
       <parent link="Leg14"/>
       <child  link="Leg21"/>
       <origin rpy="0 0 0" xyz="1.0264531816484355 1.4710561412207306 0" />
     <axis xyz="1 0 0"/>
       <limit effort="0.0" lower="-3.14159" upper="3.14159" velocity="0.0"/>
    </joint>
    <joint name="Leg1_Leg22" type="revolute">
       <parent link="Leg1"/>
       <child  link="Leg22"/>
       <origin rpy="0 0 0" xyz="1.6521900553301694 0.5980802002003753 0.8413179873129004" />
     <axis xyz="1 0 0"/>
       <limit effort="0.0" lower="-3.14159" upper="3.14159" velocity="0.0"/>
    </joint>
    <joint name="Leg19_Leg23" type="revolute">
       <parent link="Leg19"/>
       <child  link="Leg23"/>
       <origin rpy="0 0 0" xyz="0 0 1.3019247949249757" />
     <axis xyz="1 0 0"/>
       <limit effort="0.0" lower="-3.14159" upper="3.14159" velocity="0.0"/>
    </joint>
    <joint name="Leg10_Leg24" type="revolute">
       <parent link="Leg10"/>
       <child  link="Leg24"/>
       <origin rpy="0 0 0" xyz="0 1.195561592189455 0.9838961645965446" />
     <axis xyz="1 0 0"/>
       <limit effort="0.0" lower="-3.14159" upper="3.14159" velocity="0.0"/>
    </joint>
    <joint name="Leg16_Leg25" type="revolute">
       <parent link="Leg16"/>
       <child  link="Leg25"/>
       <origin rpy="0 0 0" xyz="0 1.0435020538460469 0" />
     <axis xyz="1 0 0"/>
       <limit effort="0.0" lower="-3.14159" upper="3.14159" velocity="0.0"/>
    </joint>
    <joint name="Leg15_Leg26" type="revolute">
       <parent link="Leg15"/>
       <child  link="Leg26"/>
       <origin rpy="0 0 0" xyz="0 1.7041473132628684 0" />
     <axis xyz="1 0 0"/>
       <limit effort="0.0" lower="-3.14159" upper="3.14159" velocity="0.0"/>
    </joint>
</robot>