<robot name = "robot">
    <link name="Torso">
        <inertial>
            <origin xyz="0 0 2.0993249557574183" rpy="0 0 0"/>
            <mass value="1" />
            <inertia ixx="100" ixy="0" ixz="0" iyy="100" iyz="0" izz="100" />
        </inertial>
        <visual>
            <origin xyz="0 0 2.0993249557574183" rpy="0 0 0"/>
            <geometry>
                <box size="1.8719898042840075 1.0518524636557827 2.0993249557574183" />
            </geometry>
            <material name="Green">
                <color rgba="0 180.0 0.0 1.0"/>
            </material>
        </visual>
        <collision>
            <origin xyz="0 0 2.0993249557574183" rpy="0 0 0"/>
            <geometry>
                <box size="1.8719898042840075 1.0518524636557827 2.0993249557574183" />
            </geometry>
        </collision>
    </link>
    <link name="Leg1">
        <inertial>
            <origin xyz="0.8205364371116073 0 1.1988626913672014" rpy="0 0 0"/>
            <mass value="1" />
            <inertia ixx="100" ixy="0" ixz="0" iyy="100" iyz="0" izz="100" />
        </inertial>
        <visual>
            <origin xyz="0.8205364371116073 0 1.1988626913672014" rpy="0 0 0"/>
            <geometry>
                <box size="1.6410728742232146 1.3088533461786602 2.3977253827344027" />
            </geometry>
            <material name="Blue">
                <color rgba="0 1.0 1.0 1.0"/>
            </material>
        </visual>
        <collision>
            <origin xyz="0.8205364371116073 0 1.1988626913672014" rpy="0 0 0"/>
            <geometry>
                <box size="1.6410728742232146 1.3088533461786602 2.3977253827344027" />
            </geometry>
        </collision>
    </link>
    <link name="Leg2">
        <inertial>
            <origin xyz="2.2654754612018735 0 1.1830259944094714" rpy="0 0 0"/>
            <mass value="1" />
            <inertia ixx="100" ixy="0" ixz="0" iyy="100" iyz="0" izz="100" />
        </inertial>
        <visual>
            <origin xyz="2.2654754612018735 0 1.1830259944094714" rpy="0 0 0"/>
            <geometry>
                <box size="2.2654754612018735 2.636453442709775 2.366051988818943" />
            </geometry>
            <material name="Blue">
                <color rgba="0 1.0 1.0 1.0"/>
            </material>
        </visual>
        <collision>
            <origin xyz="2.2654754612018735 0 1.1830259944094714" rpy="0 0 0"/>
            <geometry>
                <box size="2.2654754612018735 2.636453442709775 2.366051988818943" />
            </geometry>
        </collision>
    </link>
    <link name="Leg3">
        <inertial>
            <origin xyz="0 0 1.5169961728747976" rpy="0 0 0"/>
            <mass value="1" />
            <inertia ixx="100" ixy="0" ixz="0" iyy="100" iyz="0" izz="100" />
        </inertial>
        <visual>
            <origin xyz="0 0 1.5169961728747976" rpy="0 0 0"/>
            <geometry>
                <box size="2.1735939560002064 2.439508464713918 1.5169961728747976" />
            </geometry>
            <material name="Blue">
                <color rgba="0 1.0 1.0 1.0"/>
            </material>
        </visual>
        <collision>
            <origin xyz="0 0 1.5169961728747976" rpy="0 0 0"/>
            <geometry>
                <box size="2.1735939560002064 2.439508464713918 1.5169961728747976" />
            </geometry>
        </collision>
    </link>
    <link name="Leg4">
        <inertial>
            <origin xyz="0 0 2.9392648116535858" rpy="0 0 0"/>
            <mass value="1" />
            <inertia ixx="100" ixy="0" ixz="0" iyy="100" iyz="0" izz="100" />
        </inertial>
        <visual>
            <origin xyz="0 0 2.9392648116535858" rpy="0 0 0"/>
            <geometry>
                <box size="1.8146156645798903 1.353969247335873 2.9392648116535858" />
            </geometry>
            <material name="Blue">
                <color rgba="0 1.0 1.0 1.0"/>
            </material>
        </visual>
        <collision>
            <origin xyz="0 0 2.9392648116535858" rpy="0 0 0"/>
            <geometry>
                <box size="1.8146156645798903 1.353969247335873 2.9392648116535858" />
            </geometry>
        </collision>
    </link>
    <link name="Leg5">
        <inertial>
            <origin xyz="0 0 1.3634540755623574" rpy="0 0 0"/>
            <mass value="1" />
            <inertia ixx="100" ixy="0" ixz="0" iyy="100" iyz="0" izz="100" />
        </inertial>
        <visual>
            <origin xyz="0 0 1.3634540755623574" rpy="0 0 0"/>
            <geometry>
                <box size="1.5757376317400087 1.2323866351921993 1.3634540755623574" />
            </geometry>
            <material name="Blue">
                <color rgba="0 1.0 1.0 1.0"/>
            </material>
        </visual>
        <collision>
            <origin xyz="0 0 1.3634540755623574" rpy="0 0 0"/>
            <geometry>
                <box size="1.5757376317400087 1.2323866351921993 1.3634540755623574" />
            </geometry>
        </collision>
    </link>
    <link name="Leg6">
        <inertial>
            <origin xyz="0 0 1.2674911709152625" rpy="0 0 0"/>
            <mass value="1" />
            <inertia ixx="100" ixy="0" ixz="0" iyy="100" iyz="0" izz="100" />
        </inertial>
        <visual>
            <origin xyz="0 0 1.2674911709152625" rpy="0 0 0"/>
            <geometry>
                <box size="2.1315302584471105 1.443670334025408 2.534982341830525" />
            </geometry>
            <material name="Blue">
                <color rgba="0 1.0 1.0 1.0"/>
            </material>
        </visual>
        <collision>
            <origin xyz="0 0 1.2674911709152625" rpy="0 0 0"/>
            <geometry>
                <box size="2.1315302584471105 1.443670334025408 2.534982341830525" />
            </geometry>
        </collision>
    </link>
    <link name="Leg7">
        <inertial>
            <origin xyz="0.8674713686238469 0 0" rpy="0 0 0"/>
            <mass value="1" />
            <inertia ixx="100" ixy="0" ixz="0" iyy="100" iyz="0" izz="100" />
        </inertial>
        <visual>
            <origin xyz="0.8674713686238469 0 0" rpy="0 0 0"/>
            <geometry>
                <box size="1.7349427372476938 1.9373471683324384 2.308532364414183" />
            </geometry>
            <material name="Blue">
                <color rgba="0 1.0 1.0 1.0"/>
            </material>
        </visual>
        <collision>
            <origin xyz="0.8674713686238469 0 0" rpy="0 0 0"/>
            <geometry>
                <box size="1.7349427372476938 1.9373471683324384 2.308532364414183" />
            </geometry>
        </collision>
    </link>
    <link name="Leg8">
        <inertial>
            <origin xyz="0.8557536288902531 0 0" rpy="0 0 0"/>
            <mass value="1" />
            <inertia ixx="100" ixy="0" ixz="0" iyy="100" iyz="0" izz="100" />
        </inertial>
        <visual>
            <origin xyz="0.8557536288902531 0 0" rpy="0 0 0"/>
            <geometry>
                <box size="1.7115072577805062 1.4258664737550735 1.724054822067691" />
            </geometry>
            <material name="Green">
                <color rgba="0 180.0 100.0 1.0"/>
            </material>
        </visual>
        <collision>
            <origin xyz="0.8557536288902531 0 0" rpy="0 0 0"/>
            <geometry>
                <box size="1.7115072577805062 1.4258664737550735 1.724054822067691" />
            </geometry>
        </collision>
    </link>
    <joint name="Torso_Leg1" type="revolute">
       <parent link="Torso"/>
       <child  link="Leg1"/>
       <origin rpy="0 0 0" xyz="0 0 2.0993249557574183" />
     <axis xyz="1 0 0"/>
       <limit effort="0.0" lower="-3.14159" upper="3.14159" velocity="0.0"/>
    </joint>
    <joint name="Leg1_Leg2" type="revolute">
       <parent link="Leg1"/>
       <child  link="Leg2"/>
       <origin rpy="0 0 0" xyz="2.2654754612018735 0 1.1830259944094714" />
     <axis xyz="1 0 0"/>
       <limit effort="0.0" lower="-3.14159" upper="3.14159" velocity="0.0"/>
    </joint>
    <joint name="Leg1_Leg3" type="revolute">
       <parent link="Leg1"/>
       <child  link="Leg3"/>
       <origin rpy="0 0 0" xyz="2.2654754612018735 0 1.1830259944094714" />
     <axis xyz="1 0 0"/>
       <limit effort="0.0" lower="-3.14159" upper="3.14159" velocity="0.0"/>
    </joint>
    <joint name="Leg2_Leg4" type="revolute">
       <parent link="Leg2"/>
       <child  link="Leg4"/>
       <origin rpy="0 0 0" xyz="0 0 1.5169961728747976" />
     <axis xyz="1 0 0"/>
       <limit effort="0.0" lower="-3.14159" upper="3.14159" velocity="0.0"/>
    </joint>
    <joint name="Leg4_Leg5" type="revolute">
       <parent link="Leg4"/>
       <child  link="Leg5"/>
       <origin rpy="0 0 0" xyz="0 0 1.3634540755623574" />
     <axis xyz="1 0 0"/>
       <limit effort="0.0" lower="-3.14159" upper="3.14159" velocity="0.0"/>
    </joint>
    <joint name="Leg3_Leg6" type="revolute">
       <parent link="Leg3"/>
       <child  link="Leg6"/>
       <origin rpy="0 0 0" xyz="0 0 2.9392648116535858" />
     <axis xyz="1 0 0"/>
       <limit effort="0.0" lower="-3.14159" upper="3.14159" velocity="0.0"/>
    </joint>
    <joint name="Torso_Leg7" type="revolute">
       <parent link="Torso"/>
       <child  link="Leg7"/>
       <origin rpy="0 0 0" xyz="0.8205364371116073 0 1.1988626913672014" />
     <axis xyz="1 0 0"/>
       <limit effort="0.0" lower="-3.14159" upper="3.14159" velocity="0.0"/>
    </joint>
    <joint name="Leg7_Leg8" type="revolute">
       <parent link="Leg7"/>
       <child  link="Leg7"/>
       <origin rpy="0 0 0" xyz="1.7349427372476938 0 0" />
     <axis xyz="1 0 0"/>
       <limit effort="0.0" lower="-3.14159" upper="3.14159" velocity="0.0"/>
    </joint>
</robot>