<robot name = "robot">
    <link name="Torso">
        <inertial>
            <origin xyz="0 0 1.4100325709167278" rpy="0 0 0"/>
            <mass value="1" />
            <inertia ixx="100" ixy="0" ixz="0" iyy="100" iyz="0" izz="100" />
        </inertial>
        <visual>
            <origin xyz="0 0 1.4100325709167278" rpy="0 0 0"/>
            <geometry>
                <box size="1.310736463697761 2.2510262358974478 2.8200651418334557" />
            </geometry>
            <material name="Green">
                <color rgba="0 180.0 0.0 1.0"/>
            </material>
        </visual>
        <collision>
            <origin xyz="0 0 1.4100325709167278" rpy="0 0 0"/>
            <geometry>
                <box size="1.310736463697761 2.2510262358974478 2.8200651418334557" />
            </geometry>
        </collision>
    </link>
    <link name="Leg1">
        <inertial>
            <origin xyz="0 0 1.2229828570759222" rpy="0 0 0"/>
            <mass value="1" />
            <inertia ixx="100" ixy="0" ixz="0" iyy="100" iyz="0" izz="100" />
        </inertial>
        <visual>
            <origin xyz="0 0 1.2229828570759222" rpy="0 0 0"/>
            <geometry>
                <box size="1.4740083665402712 1.9300523376402423 2.4459657141518445" />
            </geometry>
            <material name="Green">
                <color rgba="0 180.0 0.0 1.0"/>
            </material>
        </visual>
        <collision>
            <origin xyz="0 0 1.2229828570759222" rpy="0 0 0"/>
            <geometry>
                <box size="1.4740083665402712 1.9300523376402423 2.4459657141518445" />
            </geometry>
        </collision>
    </link>
    <link name="Leg2">
        <inertial>
            <origin xyz="0 0 1.2773599886715146" rpy="0 0 0"/>
            <mass value="1" />
            <inertia ixx="100" ixy="0" ixz="0" iyy="100" iyz="0" izz="100" />
        </inertial>
        <visual>
            <origin xyz="0 0 1.2773599886715146" rpy="0 0 0"/>
            <geometry>
                <box size="2.154764588907547 2.7165856136604516 2.554719977343029" />
            </geometry>
            <material name="Blue">
                <color rgba="0 1.0 1.0 1.0"/>
            </material>
        </visual>
        <collision>
            <origin xyz="0 0 1.2773599886715146" rpy="0 0 0"/>
            <geometry>
                <box size="2.154764588907547 2.7165856136604516 2.554719977343029" />
            </geometry>
        </collision>
    </link>
    <link name="Leg3">
        <inertial>
            <origin xyz="0 0 0.8931980454241009" rpy="0 0 0"/>
            <mass value="1" />
            <inertia ixx="100" ixy="0" ixz="0" iyy="100" iyz="0" izz="100" />
        </inertial>
        <visual>
            <origin xyz="0 0 0.8931980454241009" rpy="0 0 0"/>
            <geometry>
                <box size="1.2276941145050817 2.958479745840548 1.7863960908482017" />
            </geometry>
            <material name="Green">
                <color rgba="0 180.0 0.0 1.0"/>
            </material>
        </visual>
        <collision>
            <origin xyz="0 0 0.8931980454241009" rpy="0 0 0"/>
            <geometry>
                <box size="1.2276941145050817 2.958479745840548 1.7863960908482017" />
            </geometry>
        </collision>
    </link>
    <link name="Leg4">
        <inertial>
            <origin xyz="0 1.1012440619543127 0" rpy="0 0 0"/>
            <mass value="1" />
            <inertia ixx="100" ixy="0" ixz="0" iyy="100" iyz="0" izz="100" />
        </inertial>
        <visual>
            <origin xyz="0 1.1012440619543127 0" rpy="0 0 0"/>
            <geometry>
                <box size="2.8886302621936446 2.2024881239086254 2.0293001261092423" />
            </geometry>
            <material name="Blue">
                <color rgba="0 1.0 1.0 1.0"/>
            </material>
        </visual>
        <collision>
            <origin xyz="0 1.1012440619543127 0" rpy="0 0 0"/>
            <geometry>
                <box size="2.8886302621936446 2.2024881239086254 2.0293001261092423" />
            </geometry>
        </collision>
    </link>
    <link name="Leg5">
        <inertial>
            <origin xyz="1.2682278949849533 0 0" rpy="0 0 0"/>
            <mass value="1" />
            <inertia ixx="100" ixy="0" ixz="0" iyy="100" iyz="0" izz="100" />
        </inertial>
        <visual>
            <origin xyz="1.2682278949849533 0 0" rpy="0 0 0"/>
            <geometry>
                <box size="2.5364557899699065 1.5427997470317591 2.9186173463302536" />
            </geometry>
            <material name="Green">
                <color rgba="0 180.0 0.0 1.0"/>
            </material>
        </visual>
        <collision>
            <origin xyz="1.2682278949849533 0 0" rpy="0 0 0"/>
            <geometry>
                <box size="2.5364557899699065 1.5427997470317591 2.9186173463302536" />
            </geometry>
        </collision>
    </link>
    <link name="Leg6">
        <inertial>
            <origin xyz="0 1.325367611291182 0" rpy="0 0 0"/>
            <mass value="1" />
            <inertia ixx="100" ixy="0" ixz="0" iyy="100" iyz="0" izz="100" />
        </inertial>
        <visual>
            <origin xyz="0 1.325367611291182 0" rpy="0 0 0"/>
            <geometry>
                <box size="2.2109833463146833 2.650735222582364 1.0564771415197105" />
            </geometry>
            <material name="Blue">
                <color rgba="0 1.0 1.0 1.0"/>
            </material>
        </visual>
        <collision>
            <origin xyz="0 1.325367611291182 0" rpy="0 0 0"/>
            <geometry>
                <box size="2.2109833463146833 2.650735222582364 1.0564771415197105" />
            </geometry>
        </collision>
    </link>
    <link name="Leg7">
        <inertial>
            <origin xyz="0 0 0.5846534787347171" rpy="0 0 0"/>
            <mass value="1" />
            <inertia ixx="100" ixy="0" ixz="0" iyy="100" iyz="0" izz="100" />
        </inertial>
        <visual>
            <origin xyz="0 0 0.5846534787347171" rpy="0 0 0"/>
            <geometry>
                <box size="2.5026788489697256 1.8683188604967709 1.1693069574694341" />
            </geometry>
            <material name="Green">
                <color rgba="0 180.0 0.0 1.0"/>
            </material>
        </visual>
        <collision>
            <origin xyz="0 0 0.5846534787347171" rpy="0 0 0"/>
            <geometry>
                <box size="2.5026788489697256 1.8683188604967709 1.1693069574694341" />
            </geometry>
        </collision>
    </link>
    <link name="Leg8">
        <inertial>
            <origin xyz="0 0 0.9177406066674201" rpy="0 0 0"/>
            <mass value="1" />
            <inertia ixx="100" ixy="0" ixz="0" iyy="100" iyz="0" izz="100" />
        </inertial>
        <visual>
            <origin xyz="0 0 0.9177406066674201" rpy="0 0 0"/>
            <geometry>
                <box size="2.4998653279991814 1.9474947891936856 1.8354812133348402" />
            </geometry>
            <material name="Blue">
                <color rgba="0 1.0 1.0 1.0"/>
            </material>
        </visual>
        <collision>
            <origin xyz="0 0 0.9177406066674201" rpy="0 0 0"/>
            <geometry>
                <box size="2.4998653279991814 1.9474947891936856 1.8354812133348402" />
            </geometry>
        </collision>
    </link>
    <link name="Leg9">
        <inertial>
            <origin xyz="0.7079513683241794 0 0" rpy="0 0 0"/>
            <mass value="1" />
            <inertia ixx="100" ixy="0" ixz="0" iyy="100" iyz="0" izz="100" />
        </inertial>
        <visual>
            <origin xyz="0.7079513683241794 0 0" rpy="0 0 0"/>
            <geometry>
                <box size="1.4159027366483588 1.7231942279441832 2.858973461101969" />
            </geometry>
            <material name="Blue">
                <color rgba="0 1.0 1.0 1.0"/>
            </material>
        </visual>
        <collision>
            <origin xyz="0.7079513683241794 0 0" rpy="0 0 0"/>
            <geometry>
                <box size="1.4159027366483588 1.7231942279441832 2.858973461101969" />
            </geometry>
        </collision>
    </link>
    <link name="Leg10">
        <inertial>
            <origin xyz="0 0 1.3601714153780442" rpy="0 0 0"/>
            <mass value="1" />
            <inertia ixx="100" ixy="0" ixz="0" iyy="100" iyz="0" izz="100" />
        </inertial>
        <visual>
            <origin xyz="0 0 1.3601714153780442" rpy="0 0 0"/>
            <geometry>
                <box size="2.5519771907835147 1.4616283299802462 2.7203428307560884" />
            </geometry>
            <material name="Blue">
                <color rgba="0 1.0 1.0 1.0"/>
            </material>
        </visual>
        <collision>
            <origin xyz="0 0 1.3601714153780442" rpy="0 0 0"/>
            <geometry>
                <box size="2.5519771907835147 1.4616283299802462 2.7203428307560884" />
            </geometry>
        </collision>
    </link>
    <link name="Leg11">
        <inertial>
            <origin xyz="0 0 1.1367536954408939" rpy="0 0 0"/>
            <mass value="1" />
            <inertia ixx="100" ixy="0" ixz="0" iyy="100" iyz="0" izz="100" />
        </inertial>
        <visual>
            <origin xyz="0 0 1.1367536954408939" rpy="0 0 0"/>
            <geometry>
                <box size="2.971302098255099 1.3548398594261197 2.2735073908817878" />
            </geometry>
            <material name="Blue">
                <color rgba="0 1.0 1.0 1.0"/>
            </material>
        </visual>
        <collision>
            <origin xyz="0 0 1.1367536954408939" rpy="0 0 0"/>
            <geometry>
                <box size="2.971302098255099 1.3548398594261197 2.2735073908817878" />
            </geometry>
        </collision>
    </link>
    <link name="Leg12">
        <inertial>
            <origin xyz="1.1185408228612022 0 0" rpy="0 0 0"/>
            <mass value="1" />
            <inertia ixx="100" ixy="0" ixz="0" iyy="100" iyz="0" izz="100" />
        </inertial>
        <visual>
            <origin xyz="1.1185408228612022 0 0" rpy="0 0 0"/>
            <geometry>
                <box size="2.2370816457224043 1.80620021143365 1.0236340847306045" />
            </geometry>
            <material name="Blue">
                <color rgba="0 1.0 1.0 1.0"/>
            </material>
        </visual>
        <collision>
            <origin xyz="1.1185408228612022 0 0" rpy="0 0 0"/>
            <geometry>
                <box size="2.2370816457224043 1.80620021143365 1.0236340847306045" />
            </geometry>
        </collision>
    </link>
    <link name="Leg13">
        <inertial>
            <origin xyz="0 0.8848804933707412 0" rpy="0 0 0"/>
            <mass value="1" />
            <inertia ixx="100" ixy="0" ixz="0" iyy="100" iyz="0" izz="100" />
        </inertial>
        <visual>
            <origin xyz="0 0.8848804933707412 0" rpy="0 0 0"/>
            <geometry>
                <box size="2.4777249294406714 1.7697609867414823 1.0314654826518788" />
            </geometry>
            <material name="Blue">
                <color rgba="0 1.0 1.0 1.0"/>
            </material>
        </visual>
        <collision>
            <origin xyz="0 0.8848804933707412 0" rpy="0 0 0"/>
            <geometry>
                <box size="2.4777249294406714 1.7697609867414823 1.0314654826518788" />
            </geometry>
        </collision>
    </link>
    <link name="Leg14">
        <inertial>
            <origin xyz="0 0.907065603663368 0" rpy="0 0 0"/>
            <mass value="1" />
            <inertia ixx="100" ixy="0" ixz="0" iyy="100" iyz="0" izz="100" />
        </inertial>
        <visual>
            <origin xyz="0 0.907065603663368 0" rpy="0 0 0"/>
            <geometry>
                <box size="1.8823645024289237 1.814131207326736 2.2014212715058443" />
            </geometry>
            <material name="Blue">
                <color rgba="0 1.0 1.0 1.0"/>
            </material>
        </visual>
        <collision>
            <origin xyz="0 0.907065603663368 0" rpy="0 0 0"/>
            <geometry>
                <box size="1.8823645024289237 1.814131207326736 2.2014212715058443" />
            </geometry>
        </collision>
    </link>
    <link name="Leg15">
        <inertial>
            <origin xyz="0.7871972783270195 0 0" rpy="0 0 0"/>
            <mass value="1" />
            <inertia ixx="100" ixy="0" ixz="0" iyy="100" iyz="0" izz="100" />
        </inertial>
        <visual>
            <origin xyz="0.7871972783270195 0 0" rpy="0 0 0"/>
            <geometry>
                <box size="1.574394556654039 2.0397596948580663 2.6722458843834467" />
            </geometry>
            <material name="Blue">
                <color rgba="0 1.0 1.0 1.0"/>
            </material>
        </visual>
        <collision>
            <origin xyz="0.7871972783270195 0 0" rpy="0 0 0"/>
            <geometry>
                <box size="1.574394556654039 2.0397596948580663 2.6722458843834467" />
            </geometry>
        </collision>
    </link>
    <link name="Leg16">
        <inertial>
            <origin xyz="0 1.1685639701499766 0" rpy="0 0 0"/>
            <mass value="1" />
            <inertia ixx="100" ixy="0" ixz="0" iyy="100" iyz="0" izz="100" />
        </inertial>
        <visual>
            <origin xyz="0 1.1685639701499766 0" rpy="0 0 0"/>
            <geometry>
                <box size="1.8855226726050232 2.337127940299953 1.7511924877546738" />
            </geometry>
            <material name="Green">
                <color rgba="0 180.0 0.0 1.0"/>
            </material>
        </visual>
        <collision>
            <origin xyz="0 1.1685639701499766 0" rpy="0 0 0"/>
            <geometry>
                <box size="1.8855226726050232 2.337127940299953 1.7511924877546738" />
            </geometry>
        </collision>
    </link>
    <link name="Leg17">
        <inertial>
            <origin xyz="0 0 0.5374811517773628" rpy="0 0 0"/>
            <mass value="1" />
            <inertia ixx="100" ixy="0" ixz="0" iyy="100" iyz="0" izz="100" />
        </inertial>
        <visual>
            <origin xyz="0 0 0.5374811517773628" rpy="0 0 0"/>
            <geometry>
                <box size="1.160904783903301 1.4141961167544965 1.0749623035547256" />
            </geometry>
            <material name="Green">
                <color rgba="0 180.0 0.0 1.0"/>
            </material>
        </visual>
        <collision>
            <origin xyz="0 0 0.5374811517773628" rpy="0 0 0"/>
            <geometry>
                <box size="1.160904783903301 1.4141961167544965 1.0749623035547256" />
            </geometry>
        </collision>
    </link>
    <link name="Leg18">
        <inertial>
            <origin xyz="0 0 0.8840418840438665" rpy="0 0 0"/>
            <mass value="1" />
            <inertia ixx="100" ixy="0" ixz="0" iyy="100" iyz="0" izz="100" />
        </inertial>
        <visual>
            <origin xyz="0 0 0.8840418840438665" rpy="0 0 0"/>
            <geometry>
                <box size="1.1050571750356966 2.8363240595834025 1.768083768087733" />
            </geometry>
            <material name="Blue">
                <color rgba="0 1.0 1.0 1.0"/>
            </material>
        </visual>
        <collision>
            <origin xyz="0 0 0.8840418840438665" rpy="0 0 0"/>
            <geometry>
                <box size="1.1050571750356966 2.8363240595834025 1.768083768087733" />
            </geometry>
        </collision>
    </link>
    <link name="Leg19">
        <inertial>
            <origin xyz="0 0 0.8882850390337225" rpy="0 0 0"/>
            <mass value="1" />
            <inertia ixx="100" ixy="0" ixz="0" iyy="100" iyz="0" izz="100" />
        </inertial>
        <visual>
            <origin xyz="0 0 0.8882850390337225" rpy="0 0 0"/>
            <geometry>
                <box size="1.1694650379718783 1.4812661592530718 1.776570078067445" />
            </geometry>
            <material name="Green">
                <color rgba="0 180.0 0.0 1.0"/>
            </material>
        </visual>
        <collision>
            <origin xyz="0 0 0.8882850390337225" rpy="0 0 0"/>
            <geometry>
                <box size="1.1694650379718783 1.4812661592530718 1.776570078067445" />
            </geometry>
        </collision>
    </link>
    <link name="Leg20">
        <inertial>
            <origin xyz="0 0.5273466405742797 0" rpy="0 0 0"/>
            <mass value="1" />
            <inertia ixx="100" ixy="0" ixz="0" iyy="100" iyz="0" izz="100" />
        </inertial>
        <visual>
            <origin xyz="0 0.5273466405742797 0" rpy="0 0 0"/>
            <geometry>
                <box size="1.0359141470752757 1.0546932811485594 1.7261017381074977" />
            </geometry>
            <material name="Blue">
                <color rgba="0 1.0 1.0 1.0"/>
            </material>
        </visual>
        <collision>
            <origin xyz="0 0.5273466405742797 0" rpy="0 0 0"/>
            <geometry>
                <box size="1.0359141470752757 1.0546932811485594 1.7261017381074977" />
            </geometry>
        </collision>
    </link>
    <link name="Leg21">
        <inertial>
            <origin xyz="0 0 0.6105432351491467" rpy="0 0 0"/>
            <mass value="1" />
            <inertia ixx="100" ixy="0" ixz="0" iyy="100" iyz="0" izz="100" />
        </inertial>
        <visual>
            <origin xyz="0 0 0.6105432351491467" rpy="0 0 0"/>
            <geometry>
                <box size="2.0219563456213128 1.733559683713991 1.2210864702982933" />
            </geometry>
            <material name="Blue">
                <color rgba="0 1.0 1.0 1.0"/>
            </material>
        </visual>
        <collision>
            <origin xyz="0 0 0.6105432351491467" rpy="0 0 0"/>
            <geometry>
                <box size="2.0219563456213128 1.733559683713991 1.2210864702982933" />
            </geometry>
        </collision>
    </link>
    <link name="Leg22">
        <inertial>
            <origin xyz="0 0 0.6575376056340722" rpy="0 0 0"/>
            <mass value="1" />
            <inertia ixx="100" ixy="0" ixz="0" iyy="100" iyz="0" izz="100" />
        </inertial>
        <visual>
            <origin xyz="0 0 0.6575376056340722" rpy="0 0 0"/>
            <geometry>
                <box size="2.3529866174068204 2.8406488846007965 1.3150752112681443" />
            </geometry>
            <material name="Green">
                <color rgba="0 180.0 0.0 1.0"/>
            </material>
        </visual>
        <collision>
            <origin xyz="0 0 0.6575376056340722" rpy="0 0 0"/>
            <geometry>
                <box size="2.3529866174068204 2.8406488846007965 1.3150752112681443" />
            </geometry>
        </collision>
    </link>
    <link name="Leg23">
        <inertial>
            <origin xyz="0 0.6411174739372622 0" rpy="0 0 0"/>
            <mass value="1" />
            <inertia ixx="100" ixy="0" ixz="0" iyy="100" iyz="0" izz="100" />
        </inertial>
        <visual>
            <origin xyz="0 0.6411174739372622 0" rpy="0 0 0"/>
            <geometry>
                <box size="2.590435787831554 1.2822349478745243 1.3546887327314512" />
            </geometry>
            <material name="Green">
                <color rgba="0 180.0 0.0 1.0"/>
            </material>
        </visual>
        <collision>
            <origin xyz="0 0.6411174739372622 0" rpy="0 0 0"/>
            <geometry>
                <box size="2.590435787831554 1.2822349478745243 1.3546887327314512" />
            </geometry>
        </collision>
    </link>
    <link name="Leg24">
        <inertial>
            <origin xyz="0 0 1.1471801213277928" rpy="0 0 0"/>
            <mass value="1" />
            <inertia ixx="100" ixy="0" ixz="0" iyy="100" iyz="0" izz="100" />
        </inertial>
        <visual>
            <origin xyz="0 0 1.1471801213277928" rpy="0 0 0"/>
            <geometry>
                <box size="1.525699709052024 1.9840890367346666 2.2943602426555856" />
            </geometry>
            <material name="Blue">
                <color rgba="0 1.0 1.0 1.0"/>
            </material>
        </visual>
        <collision>
            <origin xyz="0 0 1.1471801213277928" rpy="0 0 0"/>
            <geometry>
                <box size="1.525699709052024 1.9840890367346666 2.2943602426555856" />
            </geometry>
        </collision>
    </link>
    <joint name="Torso_Leg1" type="revolute">
       <parent link="Torso"/>
       <child  link="Leg1"/>
       <origin rpy="0 0 0" xyz="0 0 2.8200651418334557" />
     <axis xyz="1 0 0"/>
       <limit effort="0.0" lower="-3.14159" upper="3.14159" velocity="0.0"/>
    </joint>
    <joint name="Leg1_Leg2" type="revolute">
       <parent link="Leg1"/>
       <child  link="Leg2"/>
       <origin rpy="0 0 0" xyz="0 0 2.554719977343029" />
     <axis xyz="1 0 0"/>
       <limit effort="0.0" lower="-3.14159" upper="3.14159" velocity="0.0"/>
    </joint>
    <joint name="Leg2_Leg3" type="revolute">
       <parent link="Leg2"/>
       <child  link="Leg3"/>
       <origin rpy="0 0 0" xyz="0 0 1.7863960908482017" />
     <axis xyz="1 0 0"/>
       <limit effort="0.0" lower="-3.14159" upper="3.14159" velocity="0.0"/>
    </joint>
    <joint name="Leg1_Leg4" type="revolute">
       <parent link="Leg1"/>
       <child  link="Leg4"/>
       <origin rpy="0 0 0" xyz="0 1.3582928068302258 2.554719977343029" />
     <axis xyz="1 0 0"/>
       <limit effort="0.0" lower="-3.14159" upper="3.14159" velocity="0.0"/>
    </joint>
    <joint name="Leg3_Leg5" type="revolute">
       <parent link="Leg3"/>
       <child  link="Leg5"/>
       <origin rpy="0 0 0" xyz="1.4443151310968223 1.1012440619543127 0" />
     <axis xyz="1 0 0"/>
       <limit effort="0.0" lower="-3.14159" upper="3.14159" velocity="0.0"/>
    </joint>
    <joint name="Leg2_Leg6" type="revolute">
       <parent link="Leg2"/>
       <child  link="Leg6"/>
       <origin rpy="0 0 0" xyz="0 1.479239872920274 1.7863960908482017" />
     <axis xyz="1 0 0"/>
       <limit effort="0.0" lower="-3.14159" upper="3.14159" velocity="0.0"/>
    </joint>
    <joint name="Leg3_Leg7" type="revolute">
       <parent link="Leg3"/>
       <child  link="Leg7"/>
       <origin rpy="0 0 0" xyz="1.4443151310968223 1.1012440619543127 1.0146500630546211" />
     <axis xyz="1 0 0"/>
       <limit effort="0.0" lower="-3.14159" upper="3.14159" velocity="0.0"/>
    </joint>
    <joint name="Leg6_Leg8" type="revolute">
       <parent link="Leg6"/>
       <child  link="Leg8"/>
       <origin rpy="0 0 0" xyz="0 0 1.1693069574694341" />
     <axis xyz="1 0 0"/>
       <limit effort="0.0" lower="-3.14159" upper="3.14159" velocity="0.0"/>
    </joint>
    <joint name="Torso_Leg9" type="revolute">
       <parent link="Torso"/>
       <child  link="Leg9"/>
       <origin rpy="0 0 0" xyz="0.7370041832701356 0 1.2229828570759222" />
     <axis xyz="1 0 0"/>
       <limit effort="0.0" lower="-3.14159" upper="3.14159" velocity="0.0"/>
    </joint>
    <joint name="Leg7_Leg10" type="revolute">
       <parent link="Leg7"/>
       <child  link="Leg10"/>
       <origin rpy="0 0 0" xyz="0 0 1.8354812133348402" />
     <axis xyz="1 0 0"/>
       <limit effort="0.0" lower="-3.14159" upper="3.14159" velocity="0.0"/>
    </joint>
    <joint name="Leg9_Leg11" type="revolute">
       <parent link="Leg9"/>
       <child  link="Leg11"/>
       <origin rpy="0 0 0" xyz="0 0 2.7203428307560884" />
     <axis xyz="1 0 0"/>
       <limit effort="0.0" lower="-3.14159" upper="3.14159" velocity="0.0"/>
    </joint>
    <joint name="Leg4_Leg12" type="revolute">
       <parent link="Leg4"/>
       <child  link="Leg12"/>
       <origin rpy="0 0 0" xyz="2.5364557899699065 0 0" />
     <axis xyz="1 0 0"/>
       <limit effort="0.0" lower="-3.14159" upper="3.14159" velocity="0.0"/>
    </joint>
    <joint name="Leg3_Leg13" type="revolute">
       <parent link="Leg3"/>
       <child  link="Leg13"/>
       <origin rpy="0 0 0" xyz="1.4443151310968223 2.2024881239086254 1.0146500630546211" />
     <axis xyz="1 0 0"/>
       <limit effort="0.0" lower="-3.14159" upper="3.14159" velocity="0.0"/>
    </joint>
    <joint name="Leg5_Leg14" type="revolute">
       <parent link="Leg5"/>
       <child  link="Leg14"/>
       <origin rpy="0 0 0" xyz="0 2.650735222582364 0" />
     <axis xyz="1 0 0"/>
       <limit effort="0.0" lower="-3.14159" upper="3.14159" velocity="0.0"/>
    </joint>
    <joint name="Leg7_Leg15" type="revolute">
       <parent link="Leg7"/>
       <child  link="Leg15"/>
       <origin rpy="0 0 0" xyz="1.2499326639995907 0 1.8354812133348402" />
     <axis xyz="1 0 0"/>
       <limit effort="0.0" lower="-3.14159" upper="3.14159" velocity="0.0"/>
    </joint>
    <joint name="Leg11_Leg16" type="revolute">
       <parent link="Leg11"/>
       <child  link="Leg16"/>
       <origin rpy="0 0 0" xyz="1.1185408228612022 0.903100105716825 0" />
     <axis xyz="1 0 0"/>
       <limit effort="0.0" lower="-3.14159" upper="3.14159" velocity="0.0"/>
    </joint>
    <joint name="Leg13_Leg17" type="revolute">
       <parent link="Leg13"/>
       <child  link="Leg17"/>
       <origin rpy="0 0 0" xyz="0 0.907065603663368 1.1007106357529222" />
     <axis xyz="1 0 0"/>
       <limit effort="0.0" lower="-3.14159" upper="3.14159" velocity="0.0"/>
    </joint>
    <joint name="Leg12_Leg18" type="revolute">
       <parent link="Leg12"/>
       <child  link="Leg18"/>
       <origin rpy="0 0 0" xyz="0 0.8848804933707412 0.5157327413259394" />
     <axis xyz="1 0 0"/>
       <limit effort="0.0" lower="-3.14159" upper="3.14159" velocity="0.0"/>
    </joint>
    <joint name="Leg10_Leg19" type="revolute">
       <parent link="Leg10"/>
       <child  link="Leg19"/>
       <origin rpy="0 0 0" xyz="0 0 2.2735073908817878" />
     <axis xyz="1 0 0"/>
       <limit effort="0.0" lower="-3.14159" upper="3.14159" velocity="0.0"/>
    </joint>
    <joint name="Leg14_Leg20" type="revolute">
       <parent link="Leg14"/>
       <child  link="Leg20"/>
       <origin rpy="0 0 0" xyz="0.7871972783270195 1.0198798474290331 0" />
     <axis xyz="1 0 0"/>
       <limit effort="0.0" lower="-3.14159" upper="3.14159" velocity="0.0"/>
    </joint>
    <joint name="Leg18_Leg21" type="revolute">
       <parent link="Leg18"/>
       <child  link="Leg21"/>
       <origin rpy="0 0 0" xyz="0 0 1.776570078067445" />
     <axis xyz="1 0 0"/>
       <limit effort="0.0" lower="-3.14159" upper="3.14159" velocity="0.0"/>
    </joint>
    <joint name="Leg15_Leg22" type="revolute">
       <parent link="Leg15"/>
       <child  link="Leg22"/>
       <origin rpy="0 0 0" xyz="0 1.1685639701499766 0.8755962438773369" />
     <axis xyz="1 0 0"/>
       <limit effort="0.0" lower="-3.14159" upper="3.14159" velocity="0.0"/>
    </joint>
    <joint name="Leg16_Leg23" type="revolute">
       <parent link="Leg16"/>
       <child  link="Leg23"/>
       <origin rpy="0 0 0" xyz="0 0.7070980583772483 0.5374811517773628" />
     <axis xyz="1 0 0"/>
       <limit effort="0.0" lower="-3.14159" upper="3.14159" velocity="0.0"/>
    </joint>
    <joint name="Leg11_Leg24" type="revolute">
       <parent link="Leg11"/>
       <child  link="Leg24"/>
       <origin rpy="0 0 0" xyz="1.1185408228612022 0.903100105716825 0.5118170423653022" />
     <axis xyz="1 0 0"/>
       <limit effort="0.0" lower="-3.14159" upper="3.14159" velocity="0.0"/>
    </joint>
</robot>