<robot name = "robot">
    <link name="Torso">
        <inertial>
            <origin xyz="0 0 0.8371267590759776" rpy="0 0 0"/>
            <mass value="1" />
            <inertia ixx="100" ixy="0" ixz="0" iyy="100" iyz="0" izz="100" />
        </inertial>
        <visual>
            <origin xyz="0 0 0.8371267590759776" rpy="0 0 0"/>
            <geometry>
                <box size="1.3968214605745246 1.2756283310017074 1.6742535181519551" />
            </geometry>
            <material name="Green">
                <color rgba="0 180.0 0.0 1.0"/>
            </material>
        </visual>
        <collision>
            <origin xyz="0 0 0.8371267590759776" rpy="0 0 0"/>
            <geometry>
                <box size="1.3968214605745246 1.2756283310017074 1.6742535181519551" />
            </geometry>
        </collision>
    </link>
    <link name="Leg1">
        <inertial>
            <origin xyz="0 1.3201528801279396 0" rpy="0 0 0"/>
            <mass value="1" />
            <inertia ixx="100" ixy="0" ixz="0" iyy="100" iyz="0" izz="100" />
        </inertial>
        <visual>
            <origin xyz="0 1.3201528801279396 0" rpy="0 0 0"/>
            <geometry>
                <box size="2.530648560984056 2.6403057602558793 2.1280911060736365" />
            </geometry>
            <material name="Blue">
                <color rgba="0 1.0 1.0 1.0"/>
            </material>
        </visual>
        <collision>
            <origin xyz="0 1.3201528801279396 0" rpy="0 0 0"/>
            <geometry>
                <box size="2.530648560984056 2.6403057602558793 2.1280911060736365" />
            </geometry>
        </collision>
    </link>
    <link name="Leg2">
        <inertial>
            <origin xyz="0 0.6648945964695319 0" rpy="0 0 0"/>
            <mass value="1" />
            <inertia ixx="100" ixy="0" ixz="0" iyy="100" iyz="0" izz="100" />
        </inertial>
        <visual>
            <origin xyz="0 0.6648945964695319 0" rpy="0 0 0"/>
            <geometry>
                <box size="1.6615273142567935 1.3297891929390637 2.0073928032068724" />
            </geometry>
            <material name="Blue">
                <color rgba="0 1.0 1.0 1.0"/>
            </material>
        </visual>
        <collision>
            <origin xyz="0 0.6648945964695319 0" rpy="0 0 0"/>
            <geometry>
                <box size="1.6615273142567935 1.3297891929390637 2.0073928032068724" />
            </geometry>
        </collision>
    </link>
    <link name="Leg3">
        <inertial>
            <origin xyz="0 0 1.1547350249961013" rpy="0 0 0"/>
            <mass value="1" />
            <inertia ixx="100" ixy="0" ixz="0" iyy="100" iyz="0" izz="100" />
        </inertial>
        <visual>
            <origin xyz="0 0 1.1547350249961013" rpy="0 0 0"/>
            <geometry>
                <box size="1.7393696598525241 1.6678966131302981 2.3094700499922025" />
            </geometry>
            <material name="Green">
                <color rgba="0 180.0 0.0 1.0"/>
            </material>
        </visual>
        <collision>
            <origin xyz="0 0 1.1547350249961013" rpy="0 0 0"/>
            <geometry>
                <box size="1.7393696598525241 1.6678966131302981 2.3094700499922025" />
            </geometry>
        </collision>
    </link>
    <link name="Leg4">
        <inertial>
            <origin xyz="1.2914925331281815 0 0" rpy="0 0 0"/>
            <mass value="1" />
            <inertia ixx="100" ixy="0" ixz="0" iyy="100" iyz="0" izz="100" />
        </inertial>
        <visual>
            <origin xyz="1.2914925331281815 0 0" rpy="0 0 0"/>
            <geometry>
                <box size="2.582985066256363 2.836584219049852 2.3552863191848967" />
            </geometry>
            <material name="Blue">
                <color rgba="0 1.0 1.0 1.0"/>
            </material>
        </visual>
        <collision>
            <origin xyz="1.2914925331281815 0 0" rpy="0 0 0"/>
            <geometry>
                <box size="2.582985066256363 2.836584219049852 2.3552863191848967" />
            </geometry>
        </collision>
    </link>
    <link name="Leg5">
        <inertial>
            <origin xyz="0.6531392251572067 0 0" rpy="0 0 0"/>
            <mass value="1" />
            <inertia ixx="100" ixy="0" ixz="0" iyy="100" iyz="0" izz="100" />
        </inertial>
        <visual>
            <origin xyz="0.6531392251572067 0 0" rpy="0 0 0"/>
            <geometry>
                <box size="1.3062784503144134 1.283340854076724 2.8576587159464983" />
            </geometry>
            <material name="Blue">
                <color rgba="0 1.0 1.0 1.0"/>
            </material>
        </visual>
        <collision>
            <origin xyz="0.6531392251572067 0 0" rpy="0 0 0"/>
            <geometry>
                <box size="1.3062784503144134 1.283340854076724 2.8576587159464983" />
            </geometry>
        </collision>
    </link>
    <link name="Leg6">
        <inertial>
            <origin xyz="0 0 0.95987024580068" rpy="0 0 0"/>
            <mass value="1" />
            <inertia ixx="100" ixy="0" ixz="0" iyy="100" iyz="0" izz="100" />
        </inertial>
        <visual>
            <origin xyz="0 0 0.95987024580068" rpy="0 0 0"/>
            <geometry>
                <box size="1.241003557044552 1.7558768218296732 1.91974049160136" />
            </geometry>
            <material name="Green">
                <color rgba="0 180.0 0.0 1.0"/>
            </material>
        </visual>
        <collision>
            <origin xyz="0 0 0.95987024580068" rpy="0 0 0"/>
            <geometry>
                <box size="1.241003557044552 1.7558768218296732 1.91974049160136" />
            </geometry>
        </collision>
    </link>
    <link name="Leg7">
        <inertial>
            <origin xyz="0.9989615051448058 0 0" rpy="0 0 0"/>
            <mass value="1" />
            <inertia ixx="100" ixy="0" ixz="0" iyy="100" iyz="0" izz="100" />
        </inertial>
        <visual>
            <origin xyz="0.9989615051448058 0 0" rpy="0 0 0"/>
            <geometry>
                <box size="1.9979230102896115 1.3978999042118905 1.0062253947769237" />
            </geometry>
            <material name="Green">
                <color rgba="0 180.0 0.0 1.0"/>
            </material>
        </visual>
        <collision>
            <origin xyz="0.9989615051448058 0 0" rpy="0 0 0"/>
            <geometry>
                <box size="1.9979230102896115 1.3978999042118905 1.0062253947769237" />
            </geometry>
        </collision>
    </link>
    <link name="Leg8">
        <inertial>
            <origin xyz="0 0 1.3488738958152884" rpy="0 0 0"/>
            <mass value="1" />
            <inertia ixx="100" ixy="0" ixz="0" iyy="100" iyz="0" izz="100" />
        </inertial>
        <visual>
            <origin xyz="0 0 1.3488738958152884" rpy="0 0 0"/>
            <geometry>
                <box size="2.4834317164967423 1.6657315661293368 2.6977477916305768" />
            </geometry>
            <material name="Blue">
                <color rgba="0 1.0 1.0 1.0"/>
            </material>
        </visual>
        <collision>
            <origin xyz="0 0 1.3488738958152884" rpy="0 0 0"/>
            <geometry>
                <box size="2.4834317164967423 1.6657315661293368 2.6977477916305768" />
            </geometry>
        </collision>
    </link>
    <link name="Leg9">
        <inertial>
            <origin xyz="0 0 0.6369040629320744" rpy="0 0 0"/>
            <mass value="1" />
            <inertia ixx="100" ixy="0" ixz="0" iyy="100" iyz="0" izz="100" />
        </inertial>
        <visual>
            <origin xyz="0 0 0.6369040629320744" rpy="0 0 0"/>
            <geometry>
                <box size="1.9230837273666157 1.8937740689880838 1.2738081258641487" />
            </geometry>
            <material name="Blue">
                <color rgba="0 1.0 1.0 1.0"/>
            </material>
        </visual>
        <collision>
            <origin xyz="0 0 0.6369040629320744" rpy="0 0 0"/>
            <geometry>
                <box size="1.9230837273666157 1.8937740689880838 1.2738081258641487" />
            </geometry>
        </collision>
    </link>
    <link name="Leg10">
        <inertial>
            <origin xyz="0 0 1.0233172625294054" rpy="0 0 0"/>
            <mass value="1" />
            <inertia ixx="100" ixy="0" ixz="0" iyy="100" iyz="0" izz="100" />
        </inertial>
        <visual>
            <origin xyz="0 0 1.0233172625294054" rpy="0 0 0"/>
            <geometry>
                <box size="2.737081946421657 2.2587027756623437 2.0466345250588107" />
            </geometry>
            <material name="Blue">
                <color rgba="0 1.0 1.0 1.0"/>
            </material>
        </visual>
        <collision>
            <origin xyz="0 0 1.0233172625294054" rpy="0 0 0"/>
            <geometry>
                <box size="2.737081946421657 2.2587027756623437 2.0466345250588107" />
            </geometry>
        </collision>
    </link>
    <link name="Leg11">
        <inertial>
            <origin xyz="0 1.3155241207129083 0" rpy="0 0 0"/>
            <mass value="1" />
            <inertia ixx="100" ixy="0" ixz="0" iyy="100" iyz="0" izz="100" />
        </inertial>
        <visual>
            <origin xyz="0 1.3155241207129083 0" rpy="0 0 0"/>
            <geometry>
                <box size="2.684509253744242 2.6310482414258165 2.841406240440425" />
            </geometry>
            <material name="Blue">
                <color rgba="0 1.0 1.0 1.0"/>
            </material>
        </visual>
        <collision>
            <origin xyz="0 1.3155241207129083 0" rpy="0 0 0"/>
            <geometry>
                <box size="2.684509253744242 2.6310482414258165 2.841406240440425" />
            </geometry>
        </collision>
    </link>
    <link name="Leg12">
        <inertial>
            <origin xyz="1.0992409544570396 0 0" rpy="0 0 0"/>
            <mass value="1" />
            <inertia ixx="100" ixy="0" ixz="0" iyy="100" iyz="0" izz="100" />
        </inertial>
        <visual>
            <origin xyz="1.0992409544570396 0 0" rpy="0 0 0"/>
            <geometry>
                <box size="2.1984819089140792 1.7315580176944811 2.1585922300208384" />
            </geometry>
            <material name="Green">
                <color rgba="0 180.0 0.0 1.0"/>
            </material>
        </visual>
        <collision>
            <origin xyz="1.0992409544570396 0 0" rpy="0 0 0"/>
            <geometry>
                <box size="2.1984819089140792 1.7315580176944811 2.1585922300208384" />
            </geometry>
        </collision>
    </link>
    <link name="Leg13">
        <inertial>
            <origin xyz="0.8025359208001931 0 0" rpy="0 0 0"/>
            <mass value="1" />
            <inertia ixx="100" ixy="0" ixz="0" iyy="100" iyz="0" izz="100" />
        </inertial>
        <visual>
            <origin xyz="0.8025359208001931 0 0" rpy="0 0 0"/>
            <geometry>
                <box size="1.6050718416003862 1.0419735762033902 2.0046135564025573" />
            </geometry>
            <material name="Blue">
                <color rgba="0 1.0 1.0 1.0"/>
            </material>
        </visual>
        <collision>
            <origin xyz="0.8025359208001931 0 0" rpy="0 0 0"/>
            <geometry>
                <box size="1.6050718416003862 1.0419735762033902 2.0046135564025573" />
            </geometry>
        </collision>
    </link>
    <link name="Leg14">
        <inertial>
            <origin xyz="0.8582971436921989 0 0" rpy="0 0 0"/>
            <mass value="1" />
            <inertia ixx="100" ixy="0" ixz="0" iyy="100" iyz="0" izz="100" />
        </inertial>
        <visual>
            <origin xyz="0.8582971436921989 0 0" rpy="0 0 0"/>
            <geometry>
                <box size="1.7165942873843978 2.89215704048509 1.9409443420152608" />
            </geometry>
            <material name="Green">
                <color rgba="0 180.0 0.0 1.0"/>
            </material>
        </visual>
        <collision>
            <origin xyz="0.8582971436921989 0 0" rpy="0 0 0"/>
            <geometry>
                <box size="1.7165942873843978 2.89215704048509 1.9409443420152608" />
            </geometry>
        </collision>
    </link>
    <link name="Leg15">
        <inertial>
            <origin xyz="0 0 1.0714120547222141" rpy="0 0 0"/>
            <mass value="1" />
            <inertia ixx="100" ixy="0" ixz="0" iyy="100" iyz="0" izz="100" />
        </inertial>
        <visual>
            <origin xyz="0 0 1.0714120547222141" rpy="0 0 0"/>
            <geometry>
                <box size="1.0242818905605777 1.8689338758654768 2.1428241094444282" />
            </geometry>
            <material name="Blue">
                <color rgba="0 1.0 1.0 1.0"/>
            </material>
        </visual>
        <collision>
            <origin xyz="0 0 1.0714120547222141" rpy="0 0 0"/>
            <geometry>
                <box size="1.0242818905605777 1.8689338758654768 2.1428241094444282" />
            </geometry>
        </collision>
    </link>
    <link name="Leg16">
        <inertial>
            <origin xyz="0 0 1.2626848198099538" rpy="0 0 0"/>
            <mass value="1" />
            <inertia ixx="100" ixy="0" ixz="0" iyy="100" iyz="0" izz="100" />
        </inertial>
        <visual>
            <origin xyz="0 0 1.2626848198099538" rpy="0 0 0"/>
            <geometry>
                <box size="2.4618037641103285 2.4334796143181068 2.5253696396199077" />
            </geometry>
            <material name="Blue">
                <color rgba="0 1.0 1.0 1.0"/>
            </material>
        </visual>
        <collision>
            <origin xyz="0 0 1.2626848198099538" rpy="0 0 0"/>
            <geometry>
                <box size="2.4618037641103285 2.4334796143181068 2.5253696396199077" />
            </geometry>
        </collision>
    </link>
    <link name="Leg17">
        <inertial>
            <origin xyz="0 1.043889264005096 0" rpy="0 0 0"/>
            <mass value="1" />
            <inertia ixx="100" ixy="0" ixz="0" iyy="100" iyz="0" izz="100" />
        </inertial>
        <visual>
            <origin xyz="0 1.043889264005096 0" rpy="0 0 0"/>
            <geometry>
                <box size="2.7228474659732465 2.087778528010192 2.2603446386991166" />
            </geometry>
            <material name="Green">
                <color rgba="0 180.0 0.0 1.0"/>
            </material>
        </visual>
        <collision>
            <origin xyz="0 1.043889264005096 0" rpy="0 0 0"/>
            <geometry>
                <box size="2.7228474659732465 2.087778528010192 2.2603446386991166" />
            </geometry>
        </collision>
    </link>
    <link name="Leg18">
        <inertial>
            <origin xyz="0.6951873308208562 0 0" rpy="0 0 0"/>
            <mass value="1" />
            <inertia ixx="100" ixy="0" ixz="0" iyy="100" iyz="0" izz="100" />
        </inertial>
        <visual>
            <origin xyz="0.6951873308208562 0 0" rpy="0 0 0"/>
            <geometry>
                <box size="1.3903746616417123 2.3905570853451734 2.7426173499552675" />
            </geometry>
            <material name="Green">
                <color rgba="0 180.0 0.0 1.0"/>
            </material>
        </visual>
        <collision>
            <origin xyz="0.6951873308208562 0 0" rpy="0 0 0"/>
            <geometry>
                <box size="1.3903746616417123 2.3905570853451734 2.7426173499552675" />
            </geometry>
        </collision>
    </link>
    <link name="Leg19">
        <inertial>
            <origin xyz="1.2528306260466988 0 0" rpy="0 0 0"/>
            <mass value="1" />
            <inertia ixx="100" ixy="0" ixz="0" iyy="100" iyz="0" izz="100" />
        </inertial>
        <visual>
            <origin xyz="1.2528306260466988 0 0" rpy="0 0 0"/>
            <geometry>
                <box size="2.5056612520933976 2.5239691738255585 1.6622207076192808" />
            </geometry>
            <material name="Blue">
                <color rgba="0 1.0 1.0 1.0"/>
            </material>
        </visual>
        <collision>
            <origin xyz="1.2528306260466988 0 0" rpy="0 0 0"/>
            <geometry>
                <box size="2.5056612520933976 2.5239691738255585 1.6622207076192808" />
            </geometry>
        </collision>
    </link>
    <link name="Leg20">
        <inertial>
            <origin xyz="0 1.2505276608994675 0" rpy="0 0 0"/>
            <mass value="1" />
            <inertia ixx="100" ixy="0" ixz="0" iyy="100" iyz="0" izz="100" />
        </inertial>
        <visual>
            <origin xyz="0 1.2505276608994675 0" rpy="0 0 0"/>
            <geometry>
                <box size="2.8287644351143317 2.501055321798935 1.7570798147690478" />
            </geometry>
            <material name="Green">
                <color rgba="0 180.0 0.0 1.0"/>
            </material>
        </visual>
        <collision>
            <origin xyz="0 1.2505276608994675 0" rpy="0 0 0"/>
            <geometry>
                <box size="2.8287644351143317 2.501055321798935 1.7570798147690478" />
            </geometry>
        </collision>
    </link>
    <link name="Leg21">
        <inertial>
            <origin xyz="0 0.9108986625803097 0" rpy="0 0 0"/>
            <mass value="1" />
            <inertia ixx="100" ixy="0" ixz="0" iyy="100" iyz="0" izz="100" />
        </inertial>
        <visual>
            <origin xyz="0 0.9108986625803097 0" rpy="0 0 0"/>
            <geometry>
                <box size="2.010378250353455 1.8217973251606194 2.4716497478776027" />
            </geometry>
            <material name="Blue">
                <color rgba="0 1.0 1.0 1.0"/>
            </material>
        </visual>
        <collision>
            <origin xyz="0 0.9108986625803097 0" rpy="0 0 0"/>
            <geometry>
                <box size="2.010378250353455 1.8217973251606194 2.4716497478776027" />
            </geometry>
        </collision>
    </link>
    <link name="Leg22">
        <inertial>
            <origin xyz="0 0 0.8150096546038446" rpy="0 0 0"/>
            <mass value="1" />
            <inertia ixx="100" ixy="0" ixz="0" iyy="100" iyz="0" izz="100" />
        </inertial>
        <visual>
            <origin xyz="0 0 0.8150096546038446" rpy="0 0 0"/>
            <geometry>
                <box size="2.088774612574265 2.0891544949232697 1.6300193092076891" />
            </geometry>
            <material name="Green">
                <color rgba="0 180.0 0.0 1.0"/>
            </material>
        </visual>
        <collision>
            <origin xyz="0 0 0.8150096546038446" rpy="0 0 0"/>
            <geometry>
                <box size="2.088774612574265 2.0891544949232697 1.6300193092076891" />
            </geometry>
        </collision>
    </link>
    <link name="Leg23">
        <inertial>
            <origin xyz="0 0 1.481534306375214" rpy="0 0 0"/>
            <mass value="1" />
            <inertia ixx="100" ixy="0" ixz="0" iyy="100" iyz="0" izz="100" />
        </inertial>
        <visual>
            <origin xyz="0 0 1.481534306375214" rpy="0 0 0"/>
            <geometry>
                <box size="1.941764259682502 1.82042700513693 2.963068612750428" />
            </geometry>
            <material name="Blue">
                <color rgba="0 1.0 1.0 1.0"/>
            </material>
        </visual>
        <collision>
            <origin xyz="0 0 1.481534306375214" rpy="0 0 0"/>
            <geometry>
                <box size="1.941764259682502 1.82042700513693 2.963068612750428" />
            </geometry>
        </collision>
    </link>
    <link name="Leg24">
        <inertial>
            <origin xyz="0 0.5026403688809225 0" rpy="0 0 0"/>
            <mass value="1" />
            <inertia ixx="100" ixy="0" ixz="0" iyy="100" iyz="0" izz="100" />
        </inertial>
        <visual>
            <origin xyz="0 0.5026403688809225 0" rpy="0 0 0"/>
            <geometry>
                <box size="2.0593087685875986 1.005280737761845 1.21279276019675" />
            </geometry>
            <material name="Blue">
                <color rgba="0 1.0 1.0 1.0"/>
            </material>
        </visual>
        <collision>
            <origin xyz="0 0.5026403688809225 0" rpy="0 0 0"/>
            <geometry>
                <box size="2.0593087685875986 1.005280737761845 1.21279276019675" />
            </geometry>
        </collision>
    </link>
    <link name="Leg25">
        <inertial>
            <origin xyz="0 0 1.2466895292785556" rpy="0 0 0"/>
            <mass value="1" />
            <inertia ixx="100" ixy="0" ixz="0" iyy="100" iyz="0" izz="100" />
        </inertial>
        <visual>
            <origin xyz="0 0 1.2466895292785556" rpy="0 0 0"/>
            <geometry>
                <box size="1.8754211798388887 1.2945729750510033 2.493379058557111" />
            </geometry>
            <material name="Blue">
                <color rgba="0 1.0 1.0 1.0"/>
            </material>
        </visual>
        <collision>
            <origin xyz="0 0 1.2466895292785556" rpy="0 0 0"/>
            <geometry>
                <box size="1.8754211798388887 1.2945729750510033 2.493379058557111" />
            </geometry>
        </collision>
    </link>
    <joint name="Torso_Leg1" type="revolute">
       <parent link="Torso"/>
       <child  link="Leg1"/>
       <origin rpy="0 0 0" xyz="0 0.6378141655008537 0.8371267590759776" />
     <axis xyz="1 0 0"/>
       <limit effort="0.0" lower="-3.14159" upper="3.14159" velocity="0.0"/>
    </joint>
    <joint name="Leg1_Leg2" type="revolute">
       <parent link="Leg1"/>
       <child  link="Leg2"/>
       <origin rpy="0 0 0" xyz="0 1.3297891929390637 0" />
     <axis xyz="1 0 0"/>
       <limit effort="0.0" lower="-3.14159" upper="3.14159" velocity="0.0"/>
    </joint>
    <joint name="Torso_Leg3" type="revolute">
       <parent link="Torso"/>
       <child  link="Leg3"/>
       <origin rpy="0 0 0" xyz="0 1.3201528801279396 1.0640455530368182" />
     <axis xyz="1 0 0"/>
       <limit effort="0.0" lower="-3.14159" upper="3.14159" velocity="0.0"/>
    </joint>
    <joint name="Leg1_Leg4" type="revolute">
       <parent link="Leg1"/>
       <child  link="Leg4"/>
       <origin rpy="0 0 0" xyz="0.8307636571283967 1.3297891929390637 0" />
     <axis xyz="1 0 0"/>
       <limit effort="0.0" lower="-3.14159" upper="3.14159" velocity="0.0"/>
    </joint>
    <joint name="Leg2_Leg5" type="revolute">
       <parent link="Leg2"/>
       <child  link="Leg5"/>
       <origin rpy="0 0 0" xyz="0.8696848299262621 0 1.1547350249961013" />
     <axis xyz="1 0 0"/>
       <limit effort="0.0" lower="-3.14159" upper="3.14159" velocity="0.0"/>
    </joint>
    <joint name="Leg1_Leg6" type="revolute">
       <parent link="Leg1"/>
       <child  link="Leg6"/>
       <origin rpy="0 0 0" xyz="0.8307636571283967 1.3297891929390637 1.0036964016034362" />
     <axis xyz="1 0 0"/>
       <limit effort="0.0" lower="-3.14159" upper="3.14159" velocity="0.0"/>
    </joint>
    <joint name="Leg5_Leg7" type="revolute">
       <parent link="Leg5"/>
       <child  link="Leg7"/>
       <origin rpy="0 0 0" xyz="0.620501778522276 0 0.95987024580068" />
     <axis xyz="1 0 0"/>
       <limit effort="0.0" lower="-3.14159" upper="3.14159" velocity="0.0"/>
    </joint>
    <joint name="Leg5_Leg8" type="revolute">
       <parent link="Leg5"/>
       <child  link="Leg8"/>
       <origin rpy="0 0 0" xyz="0.620501778522276 0 1.91974049160136" />
     <axis xyz="1 0 0"/>
       <limit effort="0.0" lower="-3.14159" upper="3.14159" velocity="0.0"/>
    </joint>
    <joint name="Leg4_Leg9" type="revolute">
       <parent link="Leg4"/>
       <child  link="Leg9"/>
       <origin rpy="0 0 0" xyz="0.6531392251572067 0 1.4288293579732492" />
     <axis xyz="1 0 0"/>
       <limit effort="0.0" lower="-3.14159" upper="3.14159" velocity="0.0"/>
    </joint>
    <joint name="Leg7_Leg10" type="revolute">
       <parent link="Leg7"/>
       <child  link="Leg10"/>
       <origin rpy="0 0 0" xyz="0 0 2.6977477916305768" />
     <axis xyz="1 0 0"/>
       <limit effort="0.0" lower="-3.14159" upper="3.14159" velocity="0.0"/>
    </joint>
    <joint name="Leg8_Leg11" type="revolute">
       <parent link="Leg8"/>
       <child  link="Leg11"/>
       <origin rpy="0 0 0" xyz="0 0.9468870344940419 0.6369040629320744" />
     <axis xyz="1 0 0"/>
       <limit effort="0.0" lower="-3.14159" upper="3.14159" velocity="0.0"/>
    </joint>
    <joint name="Torso_Leg12" type="revolute">
       <parent link="Torso"/>
       <child  link="Leg12"/>
       <origin rpy="0 0 0" xyz="1.265324280492028 1.3201528801279396 1.0640455530368182" />
     <axis xyz="1 0 0"/>
       <limit effort="0.0" lower="-3.14159" upper="3.14159" velocity="0.0"/>
    </joint>
    <joint name="Leg7_Leg13" type="revolute">
       <parent link="Leg7"/>
       <child  link="Leg13"/>
       <origin rpy="0 0 0" xyz="1.2417158582483712 0 2.6977477916305768" />
     <axis xyz="1 0 0"/>
       <limit effort="0.0" lower="-3.14159" upper="3.14159" velocity="0.0"/>
    </joint>
    <joint name="Leg8_Leg14" type="revolute">
       <parent link="Leg8"/>
       <child  link="Leg14"/>
       <origin rpy="0 0 0" xyz="0.9615418636833079 0.9468870344940419 0.6369040629320744" />
     <axis xyz="1 0 0"/>
       <limit effort="0.0" lower="-3.14159" upper="3.14159" velocity="0.0"/>
    </joint>
    <joint name="Leg10_Leg15" type="revolute">
       <parent link="Leg10"/>
       <child  link="Leg15"/>
       <origin rpy="0 0 0" xyz="0 1.3155241207129083 1.4207031202202125" />
     <axis xyz="1 0 0"/>
       <limit effort="0.0" lower="-3.14159" upper="3.14159" velocity="0.0"/>
    </joint>
    <joint name="Leg12_Leg16" type="revolute">
       <parent link="Leg12"/>
       <child  link="Leg16"/>
       <origin rpy="0 0 0" xyz="0.8025359208001931 0 1.0023067782012787" />
     <axis xyz="1 0 0"/>
       <limit effort="0.0" lower="-3.14159" upper="3.14159" velocity="0.0"/>
    </joint>
    <joint name="Leg5_Leg17" type="revolute">
       <parent link="Leg5"/>
       <child  link="Leg17"/>
       <origin rpy="0 0 0" xyz="0.620501778522276 0.8779384109148366 1.91974049160136" />
     <axis xyz="1 0 0"/>
       <limit effort="0.0" lower="-3.14159" upper="3.14159" velocity="0.0"/>
    </joint>
    <joint name="Leg10_Leg18" type="revolute">
       <parent link="Leg10"/>
       <child  link="Leg18"/>
       <origin rpy="0 0 0" xyz="1.342254626872121 1.3155241207129083 1.4207031202202125" />
     <axis xyz="1 0 0"/>
       <limit effort="0.0" lower="-3.14159" upper="3.14159" velocity="0.0"/>
    </joint>
    <joint name="Leg4_Leg19" type="revolute">
       <parent link="Leg4"/>
       <child  link="Leg19"/>
       <origin rpy="0 0 0" xyz="1.3062784503144134 0 1.4288293579732492" />
     <axis xyz="1 0 0"/>
       <limit effort="0.0" lower="-3.14159" upper="3.14159" velocity="0.0"/>
    </joint>
    <joint name="Leg7_Leg20" type="revolute">
       <parent link="Leg7"/>
       <child  link="Leg20"/>
       <origin rpy="0 0 0" xyz="1.2417158582483712 0.8328657830646684 2.6977477916305768" />
     <axis xyz="1 0 0"/>
       <limit effort="0.0" lower="-3.14159" upper="3.14159" velocity="0.0"/>
    </joint>
    <joint name="Leg13_Leg21" type="revolute">
       <parent link="Leg13"/>
       <child  link="Leg21"/>
       <origin rpy="0 0 0" xyz="0.8582971436921989 1.446078520242545 0" />
     <axis xyz="1 0 0"/>
       <limit effort="0.0" lower="-3.14159" upper="3.14159" velocity="0.0"/>
    </joint>
    <joint name="Leg18_Leg22" type="revolute">
       <parent link="Leg18"/>
       <child  link="Leg22"/>
       <origin rpy="0 0 0" xyz="1.2528306260466988 0 0.8311103538096404" />
     <axis xyz="1 0 0"/>
       <limit effort="0.0" lower="-3.14159" upper="3.14159" velocity="0.0"/>
    </joint>
    <joint name="Leg20_Leg23" type="revolute">
       <parent link="Leg20"/>
       <child  link="Leg23"/>
       <origin rpy="0 0 0" xyz="0 0.9108986625803097 1.2358248739388014" />
     <axis xyz="1 0 0"/>
       <limit effort="0.0" lower="-3.14159" upper="3.14159" velocity="0.0"/>
    </joint>
    <joint name="Leg19_Leg24" type="revolute">
       <parent link="Leg19"/>
       <child  link="Leg24"/>
       <origin rpy="0 0 0" xyz="0 2.501055321798935 0" />
     <axis xyz="1 0 0"/>
       <limit effort="0.0" lower="-3.14159" upper="3.14159" velocity="0.0"/>
    </joint>
    <joint name="Leg6_Leg25" type="revolute">
       <parent link="Leg6"/>
       <child  link="Leg25"/>
       <origin rpy="0 0 0" xyz="0.9989615051448058 0 0.5031126973884619" />
     <axis xyz="1 0 0"/>
       <limit effort="0.0" lower="-3.14159" upper="3.14159" velocity="0.0"/>
    </joint>
</robot>