<robot name = "robot">
    <link name="Torso">
        <inertial>
            <origin xyz="0 0 0.598281162348159" rpy="0 0 0"/>
            <mass value="1" />
            <inertia ixx="100" ixy="0" ixz="0" iyy="100" iyz="0" izz="100" />
        </inertial>
        <visual>
            <origin xyz="0 0 0.598281162348159" rpy="0 0 0"/>
            <geometry>
                <box size="2.996068290855825 2.312292871678041 1.196562324696318" />
            </geometry>
            <material name="Green">
                <color rgba="0 180.0 0.0 1.0"/>
            </material>
        </visual>
        <collision>
            <origin xyz="0 0 0.598281162348159" rpy="0 0 0"/>
            <geometry>
                <box size="2.996068290855825 2.312292871678041 1.196562324696318" />
            </geometry>
        </collision>
    </link>
    <link name="Leg1">
        <inertial>
            <origin xyz="0 1.2211561441584051 0" rpy="0 0 0"/>
            <mass value="1" />
            <inertia ixx="100" ixy="0" ixz="0" iyy="100" iyz="0" izz="100" />
        </inertial>
        <visual>
            <origin xyz="0 1.2211561441584051 0" rpy="0 0 0"/>
            <geometry>
                <box size="1.6640816092463206 2.4423122883168102 1.9164489552831838" />
            </geometry>
            <material name="Blue">
                <color rgba="0 1.0 1.0 1.0"/>
            </material>
        </visual>
        <collision>
            <origin xyz="0 1.2211561441584051 0" rpy="0 0 0"/>
            <geometry>
                <box size="1.6640816092463206 2.4423122883168102 1.9164489552831838" />
            </geometry>
        </collision>
    </link>
    <link name="Leg2">
        <inertial>
            <origin xyz="0 0 0.6652253194333816" rpy="0 0 0"/>
            <mass value="1" />
            <inertia ixx="100" ixy="0" ixz="0" iyy="100" iyz="0" izz="100" />
        </inertial>
        <visual>
            <origin xyz="0 0 0.6652253194333816" rpy="0 0 0"/>
            <geometry>
                <box size="2.165055968815065 1.6773829121586312 1.3304506388667632" />
            </geometry>
            <material name="Blue">
                <color rgba="0 1.0 1.0 1.0"/>
            </material>
        </visual>
        <collision>
            <origin xyz="0 0 0.6652253194333816" rpy="0 0 0"/>
            <geometry>
                <box size="2.165055968815065 1.6773829121586312 1.3304506388667632" />
            </geometry>
        </collision>
    </link>
    <link name="Leg3">
        <inertial>
            <origin xyz="0 0 0.6068952776865977" rpy="0 0 0"/>
            <mass value="1" />
            <inertia ixx="100" ixy="0" ixz="0" iyy="100" iyz="0" izz="100" />
        </inertial>
        <visual>
            <origin xyz="0 0 0.6068952776865977" rpy="0 0 0"/>
            <geometry>
                <box size="1.1065471923151886 1.1724505235044895 1.2137905553731954" />
            </geometry>
            <material name="Blue">
                <color rgba="0 1.0 1.0 1.0"/>
            </material>
        </visual>
        <collision>
            <origin xyz="0 0 0.6068952776865977" rpy="0 0 0"/>
            <geometry>
                <box size="1.1065471923151886 1.1724505235044895 1.2137905553731954" />
            </geometry>
        </collision>
    </link>
    <link name="Leg4">
        <inertial>
            <origin xyz="0 0.9630526421047069 0" rpy="0 0 0"/>
            <mass value="1" />
            <inertia ixx="100" ixy="0" ixz="0" iyy="100" iyz="0" izz="100" />
        </inertial>
        <visual>
            <origin xyz="0 0.9630526421047069 0" rpy="0 0 0"/>
            <geometry>
                <box size="2.4842430001494025 1.9261052842094137 2.330938624177074" />
            </geometry>
            <material name="Green">
                <color rgba="0 180.0 0.0 1.0"/>
            </material>
        </visual>
        <collision>
            <origin xyz="0 0.9630526421047069 0" rpy="0 0 0"/>
            <geometry>
                <box size="2.4842430001494025 1.9261052842094137 2.330938624177074" />
            </geometry>
        </collision>
    </link>
    <link name="Leg5">
        <inertial>
            <origin xyz="0.6910773117314238 0 0" rpy="0 0 0"/>
            <mass value="1" />
            <inertia ixx="100" ixy="0" ixz="0" iyy="100" iyz="0" izz="100" />
        </inertial>
        <visual>
            <origin xyz="0.6910773117314238 0 0" rpy="0 0 0"/>
            <geometry>
                <box size="1.3821546234628477 1.7852201257540241 2.1568564786267705" />
            </geometry>
            <material name="Green">
                <color rgba="0 180.0 0.0 1.0"/>
            </material>
        </visual>
        <collision>
            <origin xyz="0.6910773117314238 0 0" rpy="0 0 0"/>
            <geometry>
                <box size="1.3821546234628477 1.7852201257540241 2.1568564786267705" />
            </geometry>
        </collision>
    </link>
    <link name="Leg6">
        <inertial>
            <origin xyz="0.6256742586701983 0 0" rpy="0 0 0"/>
            <mass value="1" />
            <inertia ixx="100" ixy="0" ixz="0" iyy="100" iyz="0" izz="100" />
        </inertial>
        <visual>
            <origin xyz="0.6256742586701983 0 0" rpy="0 0 0"/>
            <geometry>
                <box size="1.2513485173403966 1.837293562624765 2.47752600448848" />
            </geometry>
            <material name="Blue">
                <color rgba="0 1.0 1.0 1.0"/>
            </material>
        </visual>
        <collision>
            <origin xyz="0.6256742586701983 0 0" rpy="0 0 0"/>
            <geometry>
                <box size="1.2513485173403966 1.837293562624765 2.47752600448848" />
            </geometry>
        </collision>
    </link>
    <link name="Leg7">
        <inertial>
            <origin xyz="0 0.7344807224564983 0" rpy="0 0 0"/>
            <mass value="1" />
            <inertia ixx="100" ixy="0" ixz="0" iyy="100" iyz="0" izz="100" />
        </inertial>
        <visual>
            <origin xyz="0 0.7344807224564983 0" rpy="0 0 0"/>
            <geometry>
                <box size="2.277906230871194 1.4689614449129966 1.6412920635183705" />
            </geometry>
            <material name="Blue">
                <color rgba="0 1.0 1.0 1.0"/>
            </material>
        </visual>
        <collision>
            <origin xyz="0 0.7344807224564983 0" rpy="0 0 0"/>
            <geometry>
                <box size="2.277906230871194 1.4689614449129966 1.6412920635183705" />
            </geometry>
        </collision>
    </link>
    <link name="Leg8">
        <inertial>
            <origin xyz="0 0 0.7056026334447186" rpy="0 0 0"/>
            <mass value="1" />
            <inertia ixx="100" ixy="0" ixz="0" iyy="100" iyz="0" izz="100" />
        </inertial>
        <visual>
            <origin xyz="0 0 0.7056026334447186" rpy="0 0 0"/>
            <geometry>
                <box size="2.5832248210460493 1.0991253352455208 1.4112052668894373" />
            </geometry>
            <material name="Blue">
                <color rgba="0 1.0 1.0 1.0"/>
            </material>
        </visual>
        <collision>
            <origin xyz="0 0 0.7056026334447186" rpy="0 0 0"/>
            <geometry>
                <box size="2.5832248210460493 1.0991253352455208 1.4112052668894373" />
            </geometry>
        </collision>
    </link>
    <link name="Leg9">
        <inertial>
            <origin xyz="1.3373402540268144 0 0" rpy="0 0 0"/>
            <mass value="1" />
            <inertia ixx="100" ixy="0" ixz="0" iyy="100" iyz="0" izz="100" />
        </inertial>
        <visual>
            <origin xyz="1.3373402540268144 0 0" rpy="0 0 0"/>
            <geometry>
                <box size="2.674680508053629 2.727982875102868 2.3570289247389162" />
            </geometry>
            <material name="Green">
                <color rgba="0 180.0 0.0 1.0"/>
            </material>
        </visual>
        <collision>
            <origin xyz="1.3373402540268144 0 0" rpy="0 0 0"/>
            <geometry>
                <box size="2.674680508053629 2.727982875102868 2.3570289247389162" />
            </geometry>
        </collision>
    </link>
    <link name="Leg10">
        <inertial>
            <origin xyz="0 0 1.3978754924864047" rpy="0 0 0"/>
            <mass value="1" />
            <inertia ixx="100" ixy="0" ixz="0" iyy="100" iyz="0" izz="100" />
        </inertial>
        <visual>
            <origin xyz="0 0 1.3978754924864047" rpy="0 0 0"/>
            <geometry>
                <box size="2.004696328863284 2.2304938696037264 2.7957509849728095" />
            </geometry>
            <material name="Green">
                <color rgba="0 180.0 0.0 1.0"/>
            </material>
        </visual>
        <collision>
            <origin xyz="0 0 1.3978754924864047" rpy="0 0 0"/>
            <geometry>
                <box size="2.004696328863284 2.2304938696037264 2.7957509849728095" />
            </geometry>
        </collision>
    </link>
    <link name="Leg11">
        <inertial>
            <origin xyz="0 0.7057597666952196 0" rpy="0 0 0"/>
            <mass value="1" />
            <inertia ixx="100" ixy="0" ixz="0" iyy="100" iyz="0" izz="100" />
        </inertial>
        <visual>
            <origin xyz="0 0.7057597666952196 0" rpy="0 0 0"/>
            <geometry>
                <box size="1.1246785376493873 1.4115195333904391 1.4145372644016343" />
            </geometry>
            <material name="Blue">
                <color rgba="0 1.0 1.0 1.0"/>
            </material>
        </visual>
        <collision>
            <origin xyz="0 0.7057597666952196 0" rpy="0 0 0"/>
            <geometry>
                <box size="1.1246785376493873 1.4115195333904391 1.4145372644016343" />
            </geometry>
        </collision>
    </link>
    <link name="Leg12">
        <inertial>
            <origin xyz="0 0 1.0378579976537774" rpy="0 0 0"/>
            <mass value="1" />
            <inertia ixx="100" ixy="0" ixz="0" iyy="100" iyz="0" izz="100" />
        </inertial>
        <visual>
            <origin xyz="0 0 1.0378579976537774" rpy="0 0 0"/>
            <geometry>
                <box size="1.0362135811157496 1.3100878937207165 2.075715995307555" />
            </geometry>
            <material name="Blue">
                <color rgba="0 1.0 1.0 1.0"/>
            </material>
        </visual>
        <collision>
            <origin xyz="0 0 1.0378579976537774" rpy="0 0 0"/>
            <geometry>
                <box size="1.0362135811157496 1.3100878937207165 2.075715995307555" />
            </geometry>
        </collision>
    </link>
    <link name="Leg13">
        <inertial>
            <origin xyz="0 0 0.8990364795673433" rpy="0 0 0"/>
            <mass value="1" />
            <inertia ixx="100" ixy="0" ixz="0" iyy="100" iyz="0" izz="100" />
        </inertial>
        <visual>
            <origin xyz="0 0 0.8990364795673433" rpy="0 0 0"/>
            <geometry>
                <box size="1.3898380337462952 1.0148379767296287 1.7980729591346867" />
            </geometry>
            <material name="Blue">
                <color rgba="0 1.0 1.0 1.0"/>
            </material>
        </visual>
        <collision>
            <origin xyz="0 0 0.8990364795673433" rpy="0 0 0"/>
            <geometry>
                <box size="1.3898380337462952 1.0148379767296287 1.7980729591346867" />
            </geometry>
        </collision>
    </link>
    <link name="Leg14">
        <inertial>
            <origin xyz="0 1.0936230794602708 0" rpy="0 0 0"/>
            <mass value="1" />
            <inertia ixx="100" ixy="0" ixz="0" iyy="100" iyz="0" izz="100" />
        </inertial>
        <visual>
            <origin xyz="0 1.0936230794602708 0" rpy="0 0 0"/>
            <geometry>
                <box size="2.8545995285182384 2.1872461589205416 2.9817115132895537" />
            </geometry>
            <material name="Blue">
                <color rgba="0 1.0 1.0 1.0"/>
            </material>
        </visual>
        <collision>
            <origin xyz="0 1.0936230794602708 0" rpy="0 0 0"/>
            <geometry>
                <box size="2.8545995285182384 2.1872461589205416 2.9817115132895537" />
            </geometry>
        </collision>
    </link>
    <link name="Leg15">
        <inertial>
            <origin xyz="0 1.002491359270518 0" rpy="0 0 0"/>
            <mass value="1" />
            <inertia ixx="100" ixy="0" ixz="0" iyy="100" iyz="0" izz="100" />
        </inertial>
        <visual>
            <origin xyz="0 1.002491359270518 0" rpy="0 0 0"/>
            <geometry>
                <box size="1.2292277898758506 2.004982718541036 2.3875216536006527" />
            </geometry>
            <material name="Green">
                <color rgba="0 180.0 0.0 1.0"/>
            </material>
        </visual>
        <collision>
            <origin xyz="0 1.002491359270518 0" rpy="0 0 0"/>
            <geometry>
                <box size="1.2292277898758506 2.004982718541036 2.3875216536006527" />
            </geometry>
        </collision>
    </link>
    <link name="Leg16">
        <inertial>
            <origin xyz="0 0 0.5799932063954342" rpy="0 0 0"/>
            <mass value="1" />
            <inertia ixx="100" ixy="0" ixz="0" iyy="100" iyz="0" izz="100" />
        </inertial>
        <visual>
            <origin xyz="0 0 0.5799932063954342" rpy="0 0 0"/>
            <geometry>
                <box size="2.9373522965376466 2.1753630083021083 1.1599864127908683" />
            </geometry>
            <material name="Blue">
                <color rgba="0 1.0 1.0 1.0"/>
            </material>
        </visual>
        <collision>
            <origin xyz="0 0 0.5799932063954342" rpy="0 0 0"/>
            <geometry>
                <box size="2.9373522965376466 2.1753630083021083 1.1599864127908683" />
            </geometry>
        </collision>
    </link>
    <link name="Leg17">
        <inertial>
            <origin xyz="0.6995827392649989 0 0" rpy="0 0 0"/>
            <mass value="1" />
            <inertia ixx="100" ixy="0" ixz="0" iyy="100" iyz="0" izz="100" />
        </inertial>
        <visual>
            <origin xyz="0.6995827392649989 0 0" rpy="0 0 0"/>
            <geometry>
                <box size="1.3991654785299978 2.2763361976336327 2.968737611007832" />
            </geometry>
            <material name="Green">
                <color rgba="0 180.0 0.0 1.0"/>
            </material>
        </visual>
        <collision>
            <origin xyz="0.6995827392649989 0 0" rpy="0 0 0"/>
            <geometry>
                <box size="1.3991654785299978 2.2763361976336327 2.968737611007832" />
            </geometry>
        </collision>
    </link>
    <link name="Leg18">
        <inertial>
            <origin xyz="0 0 1.0167991602751392" rpy="0 0 0"/>
            <mass value="1" />
            <inertia ixx="100" ixy="0" ixz="0" iyy="100" iyz="0" izz="100" />
        </inertial>
        <visual>
            <origin xyz="0 0 1.0167991602751392" rpy="0 0 0"/>
            <geometry>
                <box size="2.53760707036198 2.369640433771572 2.0335983205502783" />
            </geometry>
            <material name="Green">
                <color rgba="0 180.0 0.0 1.0"/>
            </material>
        </visual>
        <collision>
            <origin xyz="0 0 1.0167991602751392" rpy="0 0 0"/>
            <geometry>
                <box size="2.53760707036198 2.369640433771572 2.0335983205502783" />
            </geometry>
        </collision>
    </link>
    <link name="Leg19">
        <inertial>
            <origin xyz="0 0 1.0645648673742518" rpy="0 0 0"/>
            <mass value="1" />
            <inertia ixx="100" ixy="0" ixz="0" iyy="100" iyz="0" izz="100" />
        </inertial>
        <visual>
            <origin xyz="0 0 1.0645648673742518" rpy="0 0 0"/>
            <geometry>
                <box size="2.168990926216692 2.931082065356243 2.1291297347485036" />
            </geometry>
            <material name="Blue">
                <color rgba="0 1.0 1.0 1.0"/>
            </material>
        </visual>
        <collision>
            <origin xyz="0 0 1.0645648673742518" rpy="0 0 0"/>
            <geometry>
                <box size="2.168990926216692 2.931082065356243 2.1291297347485036" />
            </geometry>
        </collision>
    </link>
    <link name="Leg20">
        <inertial>
            <origin xyz="0 0 0.5691053672597224" rpy="0 0 0"/>
            <mass value="1" />
            <inertia ixx="100" ixy="0" ixz="0" iyy="100" iyz="0" izz="100" />
        </inertial>
        <visual>
            <origin xyz="0 0 0.5691053672597224" rpy="0 0 0"/>
            <geometry>
                <box size="2.181789581790805 2.984850557043406 1.1382107345194448" />
            </geometry>
            <material name="Blue">
                <color rgba="0 1.0 1.0 1.0"/>
            </material>
        </visual>
        <collision>
            <origin xyz="0 0 0.5691053672597224" rpy="0 0 0"/>
            <geometry>
                <box size="2.181789581790805 2.984850557043406 1.1382107345194448" />
            </geometry>
        </collision>
    </link>
    <link name="Leg21">
        <inertial>
            <origin xyz="0 1.1934046696251155 0" rpy="0 0 0"/>
            <mass value="1" />
            <inertia ixx="100" ixy="0" ixz="0" iyy="100" iyz="0" izz="100" />
        </inertial>
        <visual>
            <origin xyz="0 1.1934046696251155 0" rpy="0 0 0"/>
            <geometry>
                <box size="1.7752332256846153 2.386809339250231 1.163795995417686" />
            </geometry>
            <material name="Green">
                <color rgba="0 180.0 0.0 1.0"/>
            </material>
        </visual>
        <collision>
            <origin xyz="0 1.1934046696251155 0" rpy="0 0 0"/>
            <geometry>
                <box size="1.7752332256846153 2.386809339250231 1.163795995417686" />
            </geometry>
        </collision>
    </link>
    <link name="Leg22">
        <inertial>
            <origin xyz="0 0.7940939528813533 0" rpy="0 0 0"/>
            <mass value="1" />
            <inertia ixx="100" ixy="0" ixz="0" iyy="100" iyz="0" izz="100" />
        </inertial>
        <visual>
            <origin xyz="0 0.7940939528813533 0" rpy="0 0 0"/>
            <geometry>
                <box size="2.783065635915762 1.5881879057627066 2.4750411094756037" />
            </geometry>
            <material name="Green">
                <color rgba="0 180.0 0.0 1.0"/>
            </material>
        </visual>
        <collision>
            <origin xyz="0 0.7940939528813533 0" rpy="0 0 0"/>
            <geometry>
                <box size="2.783065635915762 1.5881879057627066 2.4750411094756037" />
            </geometry>
        </collision>
    </link>
    <link name="Leg23">
        <inertial>
            <origin xyz="1.3038843385812755 0 0" rpy="0 0 0"/>
            <mass value="1" />
            <inertia ixx="100" ixy="0" ixz="0" iyy="100" iyz="0" izz="100" />
        </inertial>
        <visual>
            <origin xyz="1.3038843385812755 0 0" rpy="0 0 0"/>
            <geometry>
                <box size="2.607768677162551 2.3416783175759988 1.8881712502649548" />
            </geometry>
            <material name="Blue">
                <color rgba="0 1.0 1.0 1.0"/>
            </material>
        </visual>
        <collision>
            <origin xyz="1.3038843385812755 0 0" rpy="0 0 0"/>
            <geometry>
                <box size="2.607768677162551 2.3416783175759988 1.8881712502649548" />
            </geometry>
        </collision>
    </link>
    <link name="Leg24">
        <inertial>
            <origin xyz="0 1.3848207613489372 0" rpy="0 0 0"/>
            <mass value="1" />
            <inertia ixx="100" ixy="0" ixz="0" iyy="100" iyz="0" izz="100" />
        </inertial>
        <visual>
            <origin xyz="0 1.3848207613489372 0" rpy="0 0 0"/>
            <geometry>
                <box size="2.280204446435727 2.7696415226978743 1.4983635742542658" />
            </geometry>
            <material name="Green">
                <color rgba="0 180.0 0.0 1.0"/>
            </material>
        </visual>
        <collision>
            <origin xyz="0 1.3848207613489372 0" rpy="0 0 0"/>
            <geometry>
                <box size="2.280204446435727 2.7696415226978743 1.4983635742542658" />
            </geometry>
        </collision>
    </link>
    <link name="Leg25">
        <inertial>
            <origin xyz="1.4588341395270907 0 0" rpy="0 0 0"/>
            <mass value="1" />
            <inertia ixx="100" ixy="0" ixz="0" iyy="100" iyz="0" izz="100" />
        </inertial>
        <visual>
            <origin xyz="1.4588341395270907 0 0" rpy="0 0 0"/>
            <geometry>
                <box size="2.9176682790541815 2.721635707010664 1.3869906556052622" />
            </geometry>
            <material name="Green">
                <color rgba="0 180.0 0.0 1.0"/>
            </material>
        </visual>
        <collision>
            <origin xyz="1.4588341395270907 0 0" rpy="0 0 0"/>
            <geometry>
                <box size="2.9176682790541815 2.721635707010664 1.3869906556052622" />
            </geometry>
        </collision>
    </link>
    <link name="Leg26">
        <inertial>
            <origin xyz="0 0.9097966842077031 0" rpy="0 0 0"/>
            <mass value="1" />
            <inertia ixx="100" ixy="0" ixz="0" iyy="100" iyz="0" izz="100" />
        </inertial>
        <visual>
            <origin xyz="0 0.9097966842077031 0" rpy="0 0 0"/>
            <geometry>
                <box size="1.0733685232877854 1.8195933684154062 1.630215289124741" />
            </geometry>
            <material name="Blue">
                <color rgba="0 1.0 1.0 1.0"/>
            </material>
        </visual>
        <collision>
            <origin xyz="0 0.9097966842077031 0" rpy="0 0 0"/>
            <geometry>
                <box size="1.0733685232877854 1.8195933684154062 1.630215289124741" />
            </geometry>
        </collision>
    </link>
    <joint name="Torso_Leg1" type="revolute">
       <parent link="Torso"/>
       <child  link="Leg1"/>
       <origin rpy="0 0 0" xyz="0 1.1561464358390205 0.598281162348159" />
     <axis xyz="1 0 0"/>
       <limit effort="0.0" lower="-3.14159" upper="3.14159" velocity="0.0"/>
    </joint>
    <joint name="Leg1_Leg2" type="revolute">
       <parent link="Leg1"/>
       <child  link="Leg2"/>
       <origin rpy="0 0 0" xyz="0 0 1.3304506388667632" />
     <axis xyz="1 0 0"/>
       <limit effort="0.0" lower="-3.14159" upper="3.14159" velocity="0.0"/>
    </joint>
    <joint name="Torso_Leg3" type="revolute">
       <parent link="Torso"/>
       <child  link="Leg3"/>
       <origin rpy="0 0 0" xyz="0 1.2211561441584051 0.9582244776415919" />
     <axis xyz="1 0 0"/>
       <limit effort="0.0" lower="-3.14159" upper="3.14159" velocity="0.0"/>
    </joint>
    <joint name="Leg3_Leg4" type="revolute">
       <parent link="Leg3"/>
       <child  link="Leg4"/>
       <origin rpy="0 0 0" xyz="0 1.9261052842094137 0" />
     <axis xyz="1 0 0"/>
       <limit effort="0.0" lower="-3.14159" upper="3.14159" velocity="0.0"/>
    </joint>
    <joint name="Leg3_Leg5" type="revolute">
       <parent link="Leg3"/>
       <child  link="Leg5"/>
       <origin rpy="0 0 0" xyz="1.2421215000747012 1.9261052842094137 0" />
     <axis xyz="1 0 0"/>
       <limit effort="0.0" lower="-3.14159" upper="3.14159" velocity="0.0"/>
    </joint>
    <joint name="Leg2_Leg6" type="revolute">
       <parent link="Leg2"/>
       <child  link="Leg6"/>
       <origin rpy="0 0 0" xyz="0.5532735961575943 0 0.6068952776865977" />
     <axis xyz="1 0 0"/>
       <limit effort="0.0" lower="-3.14159" upper="3.14159" velocity="0.0"/>
    </joint>
    <joint name="Leg6_Leg7" type="revolute">
       <parent link="Leg6"/>
       <child  link="Leg7"/>
       <origin rpy="0 0 0" xyz="0 1.4689614449129966 0" />
     <axis xyz="1 0 0"/>
       <limit effort="0.0" lower="-3.14159" upper="3.14159" velocity="0.0"/>
    </joint>
    <joint name="Leg4_Leg8" type="revolute">
       <parent link="Leg4"/>
       <child  link="Leg8"/>
       <origin rpy="0 0 0" xyz="0.6910773117314238 0 1.0784282393133853" />
     <axis xyz="1 0 0"/>
       <limit effort="0.0" lower="-3.14159" upper="3.14159" velocity="0.0"/>
    </joint>
    <joint name="Leg4_Leg9" type="revolute">
       <parent link="Leg4"/>
       <child  link="Leg9"/>
       <origin rpy="0 0 0" xyz="1.3821546234628477 0 1.0784282393133853" />
     <axis xyz="1 0 0"/>
       <limit effort="0.0" lower="-3.14159" upper="3.14159" velocity="0.0"/>
    </joint>
    <joint name="Leg5_Leg10" type="revolute">
       <parent link="Leg5"/>
       <child  link="Leg10"/>
       <origin rpy="0 0 0" xyz="0.6256742586701983 0 1.23876300224424" />
     <axis xyz="1 0 0"/>
       <limit effort="0.0" lower="-3.14159" upper="3.14159" velocity="0.0"/>
    </joint>
    <joint name="Leg5_Leg11" type="revolute">
       <parent link="Leg5"/>
       <child  link="Leg11"/>
       <origin rpy="0 0 0" xyz="0.6256742586701983 0.9186467813123825 1.23876300224424" />
     <axis xyz="1 0 0"/>
       <limit effort="0.0" lower="-3.14159" upper="3.14159" velocity="0.0"/>
    </joint>
    <joint name="Leg10_Leg12" type="revolute">
       <parent link="Leg10"/>
       <child  link="Leg12"/>
       <origin rpy="0 0 0" xyz="0 0.7057597666952196 0.7072686322008171" />
     <axis xyz="1 0 0"/>
       <limit effort="0.0" lower="-3.14159" upper="3.14159" velocity="0.0"/>
    </joint>
    <joint name="Leg7_Leg13" type="revolute">
       <parent link="Leg7"/>
       <child  link="Leg13"/>
       <origin rpy="0 0 0" xyz="0 0 1.4112052668894373" />
     <axis xyz="1 0 0"/>
       <limit effort="0.0" lower="-3.14159" upper="3.14159" velocity="0.0"/>
    </joint>
    <joint name="Leg8_Leg14" type="revolute">
       <parent link="Leg8"/>
       <child  link="Leg14"/>
       <origin rpy="0 0 0" xyz="1.3373402540268144 1.363991437551434 0" />
     <axis xyz="1 0 0"/>
       <limit effort="0.0" lower="-3.14159" upper="3.14159" velocity="0.0"/>
    </joint>
    <joint name="Leg14_Leg15" type="revolute">
       <parent link="Leg14"/>
       <child  link="Leg15"/>
       <origin rpy="0 0 0" xyz="0 2.004982718541036 0" />
     <axis xyz="1 0 0"/>
       <limit effort="0.0" lower="-3.14159" upper="3.14159" velocity="0.0"/>
    </joint>
    <joint name="Leg6_Leg16" type="revolute">
       <parent link="Leg6"/>
       <child  link="Leg16"/>
       <origin rpy="0 0 0" xyz="0 1.4689614449129966 0.8206460317591853" />
     <axis xyz="1 0 0"/>
       <limit effort="0.0" lower="-3.14159" upper="3.14159" velocity="0.0"/>
    </joint>
    <joint name="Leg7_Leg17" type="revolute">
       <parent link="Leg7"/>
       <child  link="Leg17"/>
       <origin rpy="0 0 0" xyz="1.2916124105230247 0 1.4112052668894373" />
     <axis xyz="1 0 0"/>
       <limit effort="0.0" lower="-3.14159" upper="3.14159" velocity="0.0"/>
    </joint>
    <joint name="Leg8_Leg18" type="revolute">
       <parent link="Leg8"/>
       <child  link="Leg18"/>
       <origin rpy="0 0 0" xyz="1.3373402540268144 1.363991437551434 1.1785144623694581" />
     <axis xyz="1 0 0"/>
       <limit effort="0.0" lower="-3.14159" upper="3.14159" velocity="0.0"/>
    </joint>
    <joint name="Leg9_Leg19" type="revolute">
       <parent link="Leg9"/>
       <child  link="Leg19"/>
       <origin rpy="0 0 0" xyz="0 0 2.7957509849728095" />
     <axis xyz="1 0 0"/>
       <limit effort="0.0" lower="-3.14159" upper="3.14159" velocity="0.0"/>
    </joint>
    <joint name="Leg14_Leg20" type="revolute">
       <parent link="Leg14"/>
       <child  link="Leg20"/>
       <origin rpy="0 0 0" xyz="0 2.004982718541036 1.1937608268003264" />
     <axis xyz="1 0 0"/>
       <limit effort="0.0" lower="-3.14159" upper="3.14159" velocity="0.0"/>
    </joint>
    <joint name="Leg7_Leg21" type="revolute">
       <parent link="Leg7"/>
       <child  link="Leg21"/>
       <origin rpy="0 0 0" xyz="1.2916124105230247 0.5495626676227604 1.4112052668894373" />
     <axis xyz="1 0 0"/>
       <limit effort="0.0" lower="-3.14159" upper="3.14159" velocity="0.0"/>
    </joint>
    <joint name="Leg15_Leg22" type="revolute">
       <parent link="Leg15"/>
       <child  link="Leg22"/>
       <origin rpy="0 0 0" xyz="0 1.0876815041510541 0.5799932063954342" />
     <axis xyz="1 0 0"/>
       <limit effort="0.0" lower="-3.14159" upper="3.14159" velocity="0.0"/>
    </joint>
    <joint name="Leg20_Leg23" type="revolute">
       <parent link="Leg20"/>
       <child  link="Leg23"/>
       <origin rpy="0 0 0" xyz="0.8876166128423076 1.1934046696251155 0" />
     <axis xyz="1 0 0"/>
       <limit effort="0.0" lower="-3.14159" upper="3.14159" velocity="0.0"/>
    </joint>
    <joint name="Leg9_Leg24" type="revolute">
       <parent link="Leg9"/>
       <child  link="Leg24"/>
       <origin rpy="0 0 0" xyz="0 1.1152469348018632 2.7957509849728095" />
     <axis xyz="1 0 0"/>
       <limit effort="0.0" lower="-3.14159" upper="3.14159" velocity="0.0"/>
    </joint>
    <joint name="Leg21_Leg25" type="revolute">
       <parent link="Leg21"/>
       <child  link="Leg25"/>
       <origin rpy="0 0 0" xyz="1.391532817957881 0.7940939528813533 0" />
     <axis xyz="1 0 0"/>
       <limit effort="0.0" lower="-3.14159" upper="3.14159" velocity="0.0"/>
    </joint>
    <joint name="Leg18_Leg26" type="revolute">
       <parent link="Leg18"/>
       <child  link="Leg26"/>
       <origin rpy="0 0 0" xyz="0 1.4655410326781215 1.0645648673742518" />
     <axis xyz="1 0 0"/>
       <limit effort="0.0" lower="-3.14159" upper="3.14159" velocity="0.0"/>
    </joint>
</robot>