<robot name = "robot">
    <link name="Torso">
        <inertial>
            <origin xyz="0 0 1.4028707779441048" rpy="0 0 0"/>
            <mass value="1" />
            <inertia ixx="100" ixy="0" ixz="0" iyy="100" iyz="0" izz="100" />
        </inertial>
        <visual>
            <origin xyz="0 0 1.4028707779441048" rpy="0 0 0"/>
            <geometry>
                <box size="1.8106409857857124 2.4250620639059544 2.8057415558882095" />
            </geometry>
            <material name="Green">
                <color rgba="0 180.0 0.0 1.0"/>
            </material>
        </visual>
        <collision>
            <origin xyz="0 0 1.4028707779441048" rpy="0 0 0"/>
            <geometry>
                <box size="1.8106409857857124 2.4250620639059544 2.8057415558882095" />
            </geometry>
        </collision>
    </link>
    <link name="Leg1">
        <inertial>
            <origin xyz="1.1720833508333999 0 0" rpy="0 0 0"/>
            <mass value="1" />
            <inertia ixx="100" ixy="0" ixz="0" iyy="100" iyz="0" izz="100" />
        </inertial>
        <visual>
            <origin xyz="1.1720833508333999 0 0" rpy="0 0 0"/>
            <geometry>
                <box size="2.3441667016667997 1.2871536425857941 2.3656239676119486" />
            </geometry>
            <material name="Blue">
                <color rgba="0 1.0 1.0 1.0"/>
            </material>
        </visual>
        <collision>
            <origin xyz="1.1720833508333999 0 0" rpy="0 0 0"/>
            <geometry>
                <box size="2.3441667016667997 1.2871536425857941 2.3656239676119486" />
            </geometry>
        </collision>
    </link>
    <link name="Leg2">
        <inertial>
            <origin xyz="0.7482572606970908 0 0" rpy="0 0 0"/>
            <mass value="1" />
            <inertia ixx="100" ixy="0" ixz="0" iyy="100" iyz="0" izz="100" />
        </inertial>
        <visual>
            <origin xyz="0.7482572606970908 0 0" rpy="0 0 0"/>
            <geometry>
                <box size="1.4965145213941815 2.1544700824862826 1.5715275610929722" />
            </geometry>
            <material name="Blue">
                <color rgba="0 1.0 1.0 1.0"/>
            </material>
        </visual>
        <collision>
            <origin xyz="0.7482572606970908 0 0" rpy="0 0 0"/>
            <geometry>
                <box size="1.4965145213941815 2.1544700824862826 1.5715275610929722" />
            </geometry>
        </collision>
    </link>
    <link name="Leg3">
        <inertial>
            <origin xyz="0 0 0.5576619720315251" rpy="0 0 0"/>
            <mass value="1" />
            <inertia ixx="100" ixy="0" ixz="0" iyy="100" iyz="0" izz="100" />
        </inertial>
        <visual>
            <origin xyz="0 0 0.5576619720315251" rpy="0 0 0"/>
            <geometry>
                <box size="2.138211234425611 1.6545837685575702 1.1153239440630502" />
            </geometry>
            <material name="Blue">
                <color rgba="0 1.0 1.0 1.0"/>
            </material>
        </visual>
        <collision>
            <origin xyz="0 0 0.5576619720315251" rpy="0 0 0"/>
            <geometry>
                <box size="2.138211234425611 1.6545837685575702 1.1153239440630502" />
            </geometry>
        </collision>
    </link>
    <link name="Leg4">
        <inertial>
            <origin xyz="0 0 1.2742965871958019" rpy="0 0 0"/>
            <mass value="1" />
            <inertia ixx="100" ixy="0" ixz="0" iyy="100" iyz="0" izz="100" />
        </inertial>
        <visual>
            <origin xyz="0 0 1.2742965871958019" rpy="0 0 0"/>
            <geometry>
                <box size="2.6348807854863407 1.033730025902949 2.5485931743916037" />
            </geometry>
            <material name="Blue">
                <color rgba="0 1.0 1.0 1.0"/>
            </material>
        </visual>
        <collision>
            <origin xyz="0 0 1.2742965871958019" rpy="0 0 0"/>
            <geometry>
                <box size="2.6348807854863407 1.033730025902949 2.5485931743916037" />
            </geometry>
        </collision>
    </link>
    <link name="Leg5">
        <inertial>
            <origin xyz="0 0 0.9220527655400922" rpy="0 0 0"/>
            <mass value="1" />
            <inertia ixx="100" ixy="0" ixz="0" iyy="100" iyz="0" izz="100" />
        </inertial>
        <visual>
            <origin xyz="0 0 0.9220527655400922" rpy="0 0 0"/>
            <geometry>
                <box size="1.73743402969523 1.0548706356166455 1.8441055310801844" />
            </geometry>
            <material name="Green">
                <color rgba="0 180.0 0.0 1.0"/>
            </material>
        </visual>
        <collision>
            <origin xyz="0 0 0.9220527655400922" rpy="0 0 0"/>
            <geometry>
                <box size="1.73743402969523 1.0548706356166455 1.8441055310801844" />
            </geometry>
        </collision>
    </link>
    <link name="Leg6">
        <inertial>
            <origin xyz="0.6288963767643412 0 0" rpy="0 0 0"/>
            <mass value="1" />
            <inertia ixx="100" ixy="0" ixz="0" iyy="100" iyz="0" izz="100" />
        </inertial>
        <visual>
            <origin xyz="0.6288963767643412 0 0" rpy="0 0 0"/>
            <geometry>
                <box size="1.2577927535286824 2.54514396336441 1.1631817868444998" />
            </geometry>
            <material name="Blue">
                <color rgba="0 1.0 1.0 1.0"/>
            </material>
        </visual>
        <collision>
            <origin xyz="0.6288963767643412 0 0" rpy="0 0 0"/>
            <geometry>
                <box size="1.2577927535286824 2.54514396336441 1.1631817868444998" />
            </geometry>
        </collision>
    </link>
    <link name="Leg7">
        <inertial>
            <origin xyz="0 0 0.654894950830188" rpy="0 0 0"/>
            <mass value="1" />
            <inertia ixx="100" ixy="0" ixz="0" iyy="100" iyz="0" izz="100" />
        </inertial>
        <visual>
            <origin xyz="0 0 0.654894950830188" rpy="0 0 0"/>
            <geometry>
                <box size="1.108065872705219 1.1568275936929462 1.309789901660376" />
            </geometry>
            <material name="Green">
                <color rgba="0 180.0 0.0 1.0"/>
            </material>
        </visual>
        <collision>
            <origin xyz="0 0 0.654894950830188" rpy="0 0 0"/>
            <geometry>
                <box size="1.108065872705219 1.1568275936929462 1.309789901660376" />
            </geometry>
        </collision>
    </link>
    <link name="Leg8">
        <inertial>
            <origin xyz="0.8427072923530867 0 0" rpy="0 0 0"/>
            <mass value="1" />
            <inertia ixx="100" ixy="0" ixz="0" iyy="100" iyz="0" izz="100" />
        </inertial>
        <visual>
            <origin xyz="0.8427072923530867 0 0" rpy="0 0 0"/>
            <geometry>
                <box size="1.6854145847061734 2.1685345252453825 1.7342924909688007" />
            </geometry>
            <material name="Blue">
                <color rgba="0 1.0 1.0 1.0"/>
            </material>
        </visual>
        <collision>
            <origin xyz="0.8427072923530867 0 0" rpy="0 0 0"/>
            <geometry>
                <box size="1.6854145847061734 2.1685345252453825 1.7342924909688007" />
            </geometry>
        </collision>
    </link>
    <link name="Leg9">
        <inertial>
            <origin xyz="0 1.2214772274891794 0" rpy="0 0 0"/>
            <mass value="1" />
            <inertia ixx="100" ixy="0" ixz="0" iyy="100" iyz="0" izz="100" />
        </inertial>
        <visual>
            <origin xyz="0 1.2214772274891794 0" rpy="0 0 0"/>
            <geometry>
                <box size="2.004020552686634 2.442954454978359 1.7963075227989533" />
            </geometry>
            <material name="Green">
                <color rgba="0 180.0 0.0 1.0"/>
            </material>
        </visual>
        <collision>
            <origin xyz="0 1.2214772274891794 0" rpy="0 0 0"/>
            <geometry>
                <box size="2.004020552686634 2.442954454978359 1.7963075227989533" />
            </geometry>
        </collision>
    </link>
    <link name="Leg10">
        <inertial>
            <origin xyz="1.4371886809670125 0 0" rpy="0 0 0"/>
            <mass value="1" />
            <inertia ixx="100" ixy="0" ixz="0" iyy="100" iyz="0" izz="100" />
        </inertial>
        <visual>
            <origin xyz="1.4371886809670125 0 0" rpy="0 0 0"/>
            <geometry>
                <box size="2.874377361934025 2.068163080198465 2.0188765549695225" />
            </geometry>
            <material name="Green">
                <color rgba="0 180.0 0.0 1.0"/>
            </material>
        </visual>
        <collision>
            <origin xyz="1.4371886809670125 0 0" rpy="0 0 0"/>
            <geometry>
                <box size="2.874377361934025 2.068163080198465 2.0188765549695225" />
            </geometry>
        </collision>
    </link>
    <link name="Leg11">
        <inertial>
            <origin xyz="0 0 1.349045089539187" rpy="0 0 0"/>
            <mass value="1" />
            <inertia ixx="100" ixy="0" ixz="0" iyy="100" iyz="0" izz="100" />
        </inertial>
        <visual>
            <origin xyz="0 0 1.349045089539187" rpy="0 0 0"/>
            <geometry>
                <box size="2.5161233824340723 2.590003758554229 2.698090179078374" />
            </geometry>
            <material name="Green">
                <color rgba="0 180.0 0.0 1.0"/>
            </material>
        </visual>
        <collision>
            <origin xyz="0 0 1.349045089539187" rpy="0 0 0"/>
            <geometry>
                <box size="2.5161233824340723 2.590003758554229 2.698090179078374" />
            </geometry>
        </collision>
    </link>
    <link name="Leg12">
        <inertial>
            <origin xyz="0.5937622358847887 0 0" rpy="0 0 0"/>
            <mass value="1" />
            <inertia ixx="100" ixy="0" ixz="0" iyy="100" iyz="0" izz="100" />
        </inertial>
        <visual>
            <origin xyz="0.5937622358847887 0 0" rpy="0 0 0"/>
            <geometry>
                <box size="1.1875244717695774 2.5965657721289648 2.1201080828441006" />
            </geometry>
            <material name="Green">
                <color rgba="0 180.0 0.0 1.0"/>
            </material>
        </visual>
        <collision>
            <origin xyz="0.5937622358847887 0 0" rpy="0 0 0"/>
            <geometry>
                <box size="1.1875244717695774 2.5965657721289648 2.1201080828441006" />
            </geometry>
        </collision>
    </link>
    <link name="Leg13">
        <inertial>
            <origin xyz="1.3252310265018343 0 0" rpy="0 0 0"/>
            <mass value="1" />
            <inertia ixx="100" ixy="0" ixz="0" iyy="100" iyz="0" izz="100" />
        </inertial>
        <visual>
            <origin xyz="1.3252310265018343 0 0" rpy="0 0 0"/>
            <geometry>
                <box size="2.6504620530036687 1.8321902121597953 2.337391045061418" />
            </geometry>
            <material name="Green">
                <color rgba="0 180.0 0.0 1.0"/>
            </material>
        </visual>
        <collision>
            <origin xyz="1.3252310265018343 0 0" rpy="0 0 0"/>
            <geometry>
                <box size="2.6504620530036687 1.8321902121597953 2.337391045061418" />
            </geometry>
        </collision>
    </link>
    <link name="Leg14">
        <inertial>
            <origin xyz="0 0 1.0859761252128508" rpy="0 0 0"/>
            <mass value="1" />
            <inertia ixx="100" ixy="0" ixz="0" iyy="100" iyz="0" izz="100" />
        </inertial>
        <visual>
            <origin xyz="0 0 1.0859761252128508" rpy="0 0 0"/>
            <geometry>
                <box size="1.400857889718226 2.66106849514264 2.1719522504257016" />
            </geometry>
            <material name="Green">
                <color rgba="0 180.0 0.0 1.0"/>
            </material>
        </visual>
        <collision>
            <origin xyz="0 0 1.0859761252128508" rpy="0 0 0"/>
            <geometry>
                <box size="1.400857889718226 2.66106849514264 2.1719522504257016" />
            </geometry>
        </collision>
    </link>
    <link name="Leg15">
        <inertial>
            <origin xyz="0 0.5179050633848733 0" rpy="0 0 0"/>
            <mass value="1" />
            <inertia ixx="100" ixy="0" ixz="0" iyy="100" iyz="0" izz="100" />
        </inertial>
        <visual>
            <origin xyz="0 0.5179050633848733 0" rpy="0 0 0"/>
            <geometry>
                <box size="1.122287212393337 1.0358101267697466 2.7534266200250195" />
            </geometry>
            <material name="Green">
                <color rgba="0 180.0 0.0 1.0"/>
            </material>
        </visual>
        <collision>
            <origin xyz="0 0.5179050633848733 0" rpy="0 0 0"/>
            <geometry>
                <box size="1.122287212393337 1.0358101267697466 2.7534266200250195" />
            </geometry>
        </collision>
    </link>
    <link name="Leg16">
        <inertial>
            <origin xyz="0 1.3308073285207045 0" rpy="0 0 0"/>
            <mass value="1" />
            <inertia ixx="100" ixy="0" ixz="0" iyy="100" iyz="0" izz="100" />
        </inertial>
        <visual>
            <origin xyz="0 1.3308073285207045 0" rpy="0 0 0"/>
            <geometry>
                <box size="1.3076713614616795 2.661614657041409 2.876861438174453" />
            </geometry>
            <material name="Blue">
                <color rgba="0 1.0 1.0 1.0"/>
            </material>
        </visual>
        <collision>
            <origin xyz="0 1.3308073285207045 0" rpy="0 0 0"/>
            <geometry>
                <box size="1.3076713614616795 2.661614657041409 2.876861438174453" />
            </geometry>
        </collision>
    </link>
    <link name="Leg17">
        <inertial>
            <origin xyz="0 0.534090773462461 0" rpy="0 0 0"/>
            <mass value="1" />
            <inertia ixx="100" ixy="0" ixz="0" iyy="100" iyz="0" izz="100" />
        </inertial>
        <visual>
            <origin xyz="0 0.534090773462461 0" rpy="0 0 0"/>
            <geometry>
                <box size="1.634605736578214 1.068181546924922 2.1490335506724265" />
            </geometry>
            <material name="Green">
                <color rgba="0 180.0 0.0 1.0"/>
            </material>
        </visual>
        <collision>
            <origin xyz="0 0.534090773462461 0" rpy="0 0 0"/>
            <geometry>
                <box size="1.634605736578214 1.068181546924922 2.1490335506724265" />
            </geometry>
        </collision>
    </link>
    <link name="Leg18">
        <inertial>
            <origin xyz="0 0 0.723555291741639" rpy="0 0 0"/>
            <mass value="1" />
            <inertia ixx="100" ixy="0" ixz="0" iyy="100" iyz="0" izz="100" />
        </inertial>
        <visual>
            <origin xyz="0 0 0.723555291741639" rpy="0 0 0"/>
            <geometry>
                <box size="1.130567545184125 1.709537853786382 1.447110583483278" />
            </geometry>
            <material name="Blue">
                <color rgba="0 1.0 1.0 1.0"/>
            </material>
        </visual>
        <collision>
            <origin xyz="0 0 0.723555291741639" rpy="0 0 0"/>
            <geometry>
                <box size="1.130567545184125 1.709537853786382 1.447110583483278" />
            </geometry>
        </collision>
    </link>
    <link name="Leg19">
        <inertial>
            <origin xyz="0 0 0.6312135308708317" rpy="0 0 0"/>
            <mass value="1" />
            <inertia ixx="100" ixy="0" ixz="0" iyy="100" iyz="0" izz="100" />
        </inertial>
        <visual>
            <origin xyz="0 0 0.6312135308708317" rpy="0 0 0"/>
            <geometry>
                <box size="2.4668308710432267 1.0444072028639972 1.2624270617416633" />
            </geometry>
            <material name="Blue">
                <color rgba="0 1.0 1.0 1.0"/>
            </material>
        </visual>
        <collision>
            <origin xyz="0 0 0.6312135308708317" rpy="0 0 0"/>
            <geometry>
                <box size="2.4668308710432267 1.0444072028639972 1.2624270617416633" />
            </geometry>
        </collision>
    </link>
    <link name="Leg20">
        <inertial>
            <origin xyz="0 0.6239971820856036 0" rpy="0 0 0"/>
            <mass value="1" />
            <inertia ixx="100" ixy="0" ixz="0" iyy="100" iyz="0" izz="100" />
        </inertial>
        <visual>
            <origin xyz="0 0.6239971820856036 0" rpy="0 0 0"/>
            <geometry>
                <box size="1.9515914602139142 1.2479943641712072 1.206711186121869" />
            </geometry>
            <material name="Green">
                <color rgba="0 180.0 0.0 1.0"/>
            </material>
        </visual>
        <collision>
            <origin xyz="0 0.6239971820856036 0" rpy="0 0 0"/>
            <geometry>
                <box size="1.9515914602139142 1.2479943641712072 1.206711186121869" />
            </geometry>
        </collision>
    </link>
    <link name="Leg21">
        <inertial>
            <origin xyz="0 1.3507453553949305 0" rpy="0 0 0"/>
            <mass value="1" />
            <inertia ixx="100" ixy="0" ixz="0" iyy="100" iyz="0" izz="100" />
        </inertial>
        <visual>
            <origin xyz="0 1.3507453553949305 0" rpy="0 0 0"/>
            <geometry>
                <box size="2.8234446397502855 2.701490710789861 2.3433936403654236" />
            </geometry>
            <material name="Green">
                <color rgba="0 180.0 0.0 1.0"/>
            </material>
        </visual>
        <collision>
            <origin xyz="0 1.3507453553949305 0" rpy="0 0 0"/>
            <geometry>
                <box size="2.8234446397502855 2.701490710789861 2.3433936403654236" />
            </geometry>
        </collision>
    </link>
    <link name="Leg22">
        <inertial>
            <origin xyz="1.2377917515098988 0 0" rpy="0 0 0"/>
            <mass value="1" />
            <inertia ixx="100" ixy="0" ixz="0" iyy="100" iyz="0" izz="100" />
        </inertial>
        <visual>
            <origin xyz="1.2377917515098988 0 0" rpy="0 0 0"/>
            <geometry>
                <box size="2.4755835030197977 1.0755931709414965 1.4972084288088532" />
            </geometry>
            <material name="Blue">
                <color rgba="0 1.0 1.0 1.0"/>
            </material>
        </visual>
        <collision>
            <origin xyz="1.2377917515098988 0 0" rpy="0 0 0"/>
            <geometry>
                <box size="2.4755835030197977 1.0755931709414965 1.4972084288088532" />
            </geometry>
        </collision>
    </link>
    <link name="Leg23">
        <inertial>
            <origin xyz="0 0 1.028634539323702" rpy="0 0 0"/>
            <mass value="1" />
            <inertia ixx="100" ixy="0" ixz="0" iyy="100" iyz="0" izz="100" />
        </inertial>
        <visual>
            <origin xyz="0 0 1.028634539323702" rpy="0 0 0"/>
            <geometry>
                <box size="2.755966597952191 1.860594098672281 2.057269078647404" />
            </geometry>
            <material name="Green">
                <color rgba="0 180.0 0.0 1.0"/>
            </material>
        </visual>
        <collision>
            <origin xyz="0 0 1.028634539323702" rpy="0 0 0"/>
            <geometry>
                <box size="2.755966597952191 1.860594098672281 2.057269078647404" />
            </geometry>
        </collision>
    </link>
    <link name="Leg24">
        <inertial>
            <origin xyz="0 0.808344320134332 0" rpy="0 0 0"/>
            <mass value="1" />
            <inertia ixx="100" ixy="0" ixz="0" iyy="100" iyz="0" izz="100" />
        </inertial>
        <visual>
            <origin xyz="0 0.808344320134332 0" rpy="0 0 0"/>
            <geometry>
                <box size="2.4160114731806575 1.616688640268664 1.1015113926221785" />
            </geometry>
            <material name="Green">
                <color rgba="0 180.0 0.0 1.0"/>
            </material>
        </visual>
        <collision>
            <origin xyz="0 0.808344320134332 0" rpy="0 0 0"/>
            <geometry>
                <box size="2.4160114731806575 1.616688640268664 1.1015113926221785" />
            </geometry>
        </collision>
    </link>
    <link name="Leg25">
        <inertial>
            <origin xyz="0 1.2036449487167493 0" rpy="0 0 0"/>
            <mass value="1" />
            <inertia ixx="100" ixy="0" ixz="0" iyy="100" iyz="0" izz="100" />
        </inertial>
        <visual>
            <origin xyz="0 1.2036449487167493 0" rpy="0 0 0"/>
            <geometry>
                <box size="2.8445460921006553 2.4072898974334986 2.158241896330188" />
            </geometry>
            <material name="Blue">
                <color rgba="0 1.0 1.0 1.0"/>
            </material>
        </visual>
        <collision>
            <origin xyz="0 1.2036449487167493 0" rpy="0 0 0"/>
            <geometry>
                <box size="2.8445460921006553 2.4072898974334986 2.158241896330188" />
            </geometry>
        </collision>
    </link>
    <joint name="Torso_Leg1" type="revolute">
       <parent link="Torso"/>
       <child  link="Leg1"/>
       <origin rpy="0 0 0" xyz="0.9053204928928562 0 1.4028707779441048" />
     <axis xyz="1 0 0"/>
       <limit effort="0.0" lower="-3.14159" upper="3.14159" velocity="0.0"/>
    </joint>
    <joint name="Leg1_Leg2" type="revolute">
       <parent link="Leg1"/>
       <child  link="Leg2"/>
       <origin rpy="0 0 0" xyz="1.4965145213941815 0 0" />
     <axis xyz="1 0 0"/>
       <limit effort="0.0" lower="-3.14159" upper="3.14159" velocity="0.0"/>
    </joint>
    <joint name="Leg2_Leg3" type="revolute">
       <parent link="Leg2"/>
       <child  link="Leg3"/>
       <origin rpy="0 0 0" xyz="0 0 1.1153239440630502" />
     <axis xyz="1 0 0"/>
       <limit effort="0.0" lower="-3.14159" upper="3.14159" velocity="0.0"/>
    </joint>
    <joint name="Leg1_Leg4" type="revolute">
       <parent link="Leg1"/>
       <child  link="Leg4"/>
       <origin rpy="0 0 0" xyz="1.4965145213941815 0 0.7857637805464861" />
     <axis xyz="1 0 0"/>
       <limit effort="0.0" lower="-3.14159" upper="3.14159" velocity="0.0"/>
    </joint>
    <joint name="Torso_Leg5" type="revolute">
       <parent link="Torso"/>
       <child  link="Leg5"/>
       <origin rpy="0 0 0" xyz="1.1720833508333999 0 1.1828119838059743" />
     <axis xyz="1 0 0"/>
       <limit effort="0.0" lower="-3.14159" upper="3.14159" velocity="0.0"/>
    </joint>
    <joint name="Leg2_Leg6" type="revolute">
       <parent link="Leg2"/>
       <child  link="Leg6"/>
       <origin rpy="0 0 0" xyz="1.0691056172128055 0 1.1153239440630502" />
     <axis xyz="1 0 0"/>
       <limit effort="0.0" lower="-3.14159" upper="3.14159" velocity="0.0"/>
    </joint>
    <joint name="Leg6_Leg7" type="revolute">
       <parent link="Leg6"/>
       <child  link="Leg7"/>
       <origin rpy="0 0 0" xyz="0 0 1.309789901660376" />
     <axis xyz="1 0 0"/>
       <limit effort="0.0" lower="-3.14159" upper="3.14159" velocity="0.0"/>
    </joint>
    <joint name="Leg6_Leg8" type="revolute">
       <parent link="Leg6"/>
       <child  link="Leg8"/>
       <origin rpy="0 0 0" xyz="0.5540329363526095 0 1.309789901660376" />
     <axis xyz="1 0 0"/>
       <limit effort="0.0" lower="-3.14159" upper="3.14159" velocity="0.0"/>
    </joint>
    <joint name="Leg4_Leg9" type="revolute">
       <parent link="Leg4"/>
       <child  link="Leg9"/>
       <origin rpy="0 0 0" xyz="0 0.5274353178083228 0.9220527655400922" />
     <axis xyz="1 0 0"/>
       <limit effort="0.0" lower="-3.14159" upper="3.14159" velocity="0.0"/>
    </joint>
    <joint name="Leg9_Leg10" type="revolute">
       <parent link="Leg9"/>
       <child  link="Leg10"/>
       <origin rpy="0 0 0" xyz="2.874377361934025 0 0" />
     <axis xyz="1 0 0"/>
       <limit effort="0.0" lower="-3.14159" upper="3.14159" velocity="0.0"/>
    </joint>
    <joint name="Leg5_Leg11" type="revolute">
       <parent link="Leg5"/>
       <child  link="Leg11"/>
       <origin rpy="0 0 0" xyz="0.6288963767643412 0 0.5815908934222499" />
     <axis xyz="1 0 0"/>
       <limit effort="0.0" lower="-3.14159" upper="3.14159" velocity="0.0"/>
    </joint>
    <joint name="Leg11_Leg12" type="revolute">
       <parent link="Leg11"/>
       <child  link="Leg12"/>
       <origin rpy="0 0 0" xyz="1.1875244717695774 0 0" />
     <axis xyz="1 0 0"/>
       <limit effort="0.0" lower="-3.14159" upper="3.14159" velocity="0.0"/>
    </joint>
    <joint name="Leg7_Leg13" type="revolute">
       <parent link="Leg7"/>
       <child  link="Leg13"/>
       <origin rpy="0 0 0" xyz="1.6854145847061734 0 0" />
     <axis xyz="1 0 0"/>
       <limit effort="0.0" lower="-3.14159" upper="3.14159" velocity="0.0"/>
    </joint>
    <joint name="Leg9_Leg14" type="revolute">
       <parent link="Leg9"/>
       <child  link="Leg14"/>
       <origin rpy="0 0 0" xyz="2.874377361934025 0 1.0094382774847612" />
     <axis xyz="1 0 0"/>
       <limit effort="0.0" lower="-3.14159" upper="3.14159" velocity="0.0"/>
    </joint>
    <joint name="Leg14_Leg15" type="revolute">
       <parent link="Leg14"/>
       <child  link="Leg15"/>
       <origin rpy="0 0 0" xyz="0 1.0358101267697466 0" />
     <axis xyz="1 0 0"/>
       <limit effort="0.0" lower="-3.14159" upper="3.14159" velocity="0.0"/>
    </joint>
    <joint name="Leg6_Leg16" type="revolute">
       <parent link="Leg6"/>
       <child  link="Leg16"/>
       <origin rpy="0 0 0" xyz="0.5540329363526095 0.5784137968464731 1.309789901660376" />
     <axis xyz="1 0 0"/>
       <limit effort="0.0" lower="-3.14159" upper="3.14159" velocity="0.0"/>
    </joint>
    <joint name="Leg7_Leg17" type="revolute">
       <parent link="Leg7"/>
       <child  link="Leg17"/>
       <origin rpy="0 0 0" xyz="1.6854145847061734 1.0842672626226912 0" />
     <axis xyz="1 0 0"/>
       <limit effort="0.0" lower="-3.14159" upper="3.14159" velocity="0.0"/>
    </joint>
    <joint name="Leg16_Leg18" type="revolute">
       <parent link="Leg16"/>
       <child  link="Leg18"/>
       <origin rpy="0 0 0" xyz="0 0.534090773462461 1.0745167753362133" />
     <axis xyz="1 0 0"/>
       <limit effort="0.0" lower="-3.14159" upper="3.14159" velocity="0.0"/>
    </joint>
    <joint name="Leg3_Leg19" type="revolute">
       <parent link="Leg3"/>
       <child  link="Leg19"/>
       <origin rpy="0 0 0" xyz="0 0 2.5485931743916037" />
     <axis xyz="1 0 0"/>
       <limit effort="0.0" lower="-3.14159" upper="3.14159" velocity="0.0"/>
    </joint>
    <joint name="Leg15_Leg20" type="revolute">
       <parent link="Leg15"/>
       <child  link="Leg20"/>
       <origin rpy="0 0 0" xyz="0 2.661614657041409 0" />
     <axis xyz="1 0 0"/>
       <limit effort="0.0" lower="-3.14159" upper="3.14159" velocity="0.0"/>
    </joint>
    <joint name="Leg17_Leg21" type="revolute">
       <parent link="Leg17"/>
       <child  link="Leg21"/>
       <origin rpy="0 0 0" xyz="0 0.854768926893191 0.723555291741639" />
     <axis xyz="1 0 0"/>
       <limit effort="0.0" lower="-3.14159" upper="3.14159" velocity="0.0"/>
    </joint>
    <joint name="Leg20_Leg22" type="revolute">
       <parent link="Leg20"/>
       <child  link="Leg22"/>
       <origin rpy="0 0 0" xyz="1.4117223198751427 1.3507453553949305 0" />
     <axis xyz="1 0 0"/>
       <limit effort="0.0" lower="-3.14159" upper="3.14159" velocity="0.0"/>
    </joint>
    <joint name="Leg4_Leg23" type="revolute">
       <parent link="Leg4"/>
       <child  link="Leg23"/>
       <origin rpy="0 0 0" xyz="0 0.5274353178083228 1.8441055310801844" />
     <axis xyz="1 0 0"/>
       <limit effort="0.0" lower="-3.14159" upper="3.14159" velocity="0.0"/>
    </joint>
    <joint name="Leg22_Leg24" type="revolute">
       <parent link="Leg22"/>
       <child  link="Leg24"/>
       <origin rpy="0 0 0" xyz="0 0.9302970493361405 1.028634539323702" />
     <axis xyz="1 0 0"/>
       <limit effort="0.0" lower="-3.14159" upper="3.14159" velocity="0.0"/>
    </joint>
    <joint name="Leg5_Leg25" type="revolute">
       <parent link="Leg5"/>
       <child  link="Leg25"/>
       <origin rpy="0 0 0" xyz="0.6288963767643412 1.272571981682205 0.5815908934222499" />
     <axis xyz="1 0 0"/>
       <limit effort="0.0" lower="-3.14159" upper="3.14159" velocity="0.0"/>
    </joint>
</robot>