<robot name = "robot">
    <link name="Torso">
        <inertial>
            <origin xyz="0 0 0.6443155886290777" rpy="0 0 0"/>
            <mass value="1" />
            <inertia ixx="100" ixy="0" ixz="0" iyy="100" iyz="0" izz="100" />
        </inertial>
        <visual>
            <origin xyz="0 0 0.6443155886290777" rpy="0 0 0"/>
            <geometry>
                <box size="2.336656499182296 2.4783590354011515 1.2886311772581553" />
            </geometry>
            <material name="Green">
                <color rgba="0 180.0 0.0 1.0"/>
            </material>
        </visual>
        <collision>
            <origin xyz="0 0 0.6443155886290777" rpy="0 0 0"/>
            <geometry>
                <box size="2.336656499182296 2.4783590354011515 1.2886311772581553" />
            </geometry>
        </collision>
    </link>
    <link name="Leg1">
        <inertial>
            <origin xyz="0 0 1.0243860521773867" rpy="0 0 0"/>
            <mass value="1" />
            <inertia ixx="100" ixy="0" ixz="0" iyy="100" iyz="0" izz="100" />
        </inertial>
        <visual>
            <origin xyz="0 0 1.0243860521773867" rpy="0 0 0"/>
            <geometry>
                <box size="2.7171238968964158 1.5605131179278875 2.0487721043547733" />
            </geometry>
            <material name="Green">
                <color rgba="0 180.0 0.0 1.0"/>
            </material>
        </visual>
        <collision>
            <origin xyz="0 0 1.0243860521773867" rpy="0 0 0"/>
            <geometry>
                <box size="2.7171238968964158 1.5605131179278875 2.0487721043547733" />
            </geometry>
        </collision>
    </link>
    <link name="Leg2">
        <inertial>
            <origin xyz="0 0.5383102626051709 0" rpy="0 0 0"/>
            <mass value="1" />
            <inertia ixx="100" ixy="0" ixz="0" iyy="100" iyz="0" izz="100" />
        </inertial>
        <visual>
            <origin xyz="0 0.5383102626051709 0" rpy="0 0 0"/>
            <geometry>
                <box size="1.8334758210006907 1.0766205252103418 2.8011627125171286" />
            </geometry>
            <material name="Blue">
                <color rgba="0 1.0 1.0 1.0"/>
            </material>
        </visual>
        <collision>
            <origin xyz="0 0.5383102626051709 0" rpy="0 0 0"/>
            <geometry>
                <box size="1.8334758210006907 1.0766205252103418 2.8011627125171286" />
            </geometry>
        </collision>
    </link>
    <link name="Leg3">
        <inertial>
            <origin xyz="0.9001628513035239 0 0" rpy="0 0 0"/>
            <mass value="1" />
            <inertia ixx="100" ixy="0" ixz="0" iyy="100" iyz="0" izz="100" />
        </inertial>
        <visual>
            <origin xyz="0.9001628513035239 0 0" rpy="0 0 0"/>
            <geometry>
                <box size="1.8003257026070478 2.7443087626650557 2.690846637309494" />
            </geometry>
            <material name="Green">
                <color rgba="0 180.0 0.0 1.0"/>
            </material>
        </visual>
        <collision>
            <origin xyz="0.9001628513035239 0 0" rpy="0 0 0"/>
            <geometry>
                <box size="1.8003257026070478 2.7443087626650557 2.690846637309494" />
            </geometry>
        </collision>
    </link>
    <link name="Leg4">
        <inertial>
            <origin xyz="0 1.2971055967333962 0" rpy="0 0 0"/>
            <mass value="1" />
            <inertia ixx="100" ixy="0" ixz="0" iyy="100" iyz="0" izz="100" />
        </inertial>
        <visual>
            <origin xyz="0 1.2971055967333962 0" rpy="0 0 0"/>
            <geometry>
                <box size="1.5556375005259486 2.5942111934667924 2.211715438721912" />
            </geometry>
            <material name="Green">
                <color rgba="0 180.0 0.0 1.0"/>
            </material>
        </visual>
        <collision>
            <origin xyz="0 1.2971055967333962 0" rpy="0 0 0"/>
            <geometry>
                <box size="1.5556375005259486 2.5942111934667924 2.211715438721912" />
            </geometry>
        </collision>
    </link>
    <link name="Leg5">
        <inertial>
            <origin xyz="0 0 0.934509831124543" rpy="0 0 0"/>
            <mass value="1" />
            <inertia ixx="100" ixy="0" ixz="0" iyy="100" iyz="0" izz="100" />
        </inertial>
        <visual>
            <origin xyz="0 0 0.934509831124543" rpy="0 0 0"/>
            <geometry>
                <box size="1.344686433778733 2.845139390380367 1.869019662249086" />
            </geometry>
            <material name="Blue">
                <color rgba="0 1.0 1.0 1.0"/>
            </material>
        </visual>
        <collision>
            <origin xyz="0 0 0.934509831124543" rpy="0 0 0"/>
            <geometry>
                <box size="1.344686433778733 2.845139390380367 1.869019662249086" />
            </geometry>
        </collision>
    </link>
    <link name="Leg6">
        <inertial>
            <origin xyz="0 0.6545208987214092 0" rpy="0 0 0"/>
            <mass value="1" />
            <inertia ixx="100" ixy="0" ixz="0" iyy="100" iyz="0" izz="100" />
        </inertial>
        <visual>
            <origin xyz="0 0.6545208987214092 0" rpy="0 0 0"/>
            <geometry>
                <box size="2.5376211644325997 1.3090417974428183 2.697372495861501" />
            </geometry>
            <material name="Blue">
                <color rgba="0 1.0 1.0 1.0"/>
            </material>
        </visual>
        <collision>
            <origin xyz="0 0.6545208987214092 0" rpy="0 0 0"/>
            <geometry>
                <box size="2.5376211644325997 1.3090417974428183 2.697372495861501" />
            </geometry>
        </collision>
    </link>
    <link name="Leg7">
        <inertial>
            <origin xyz="0.9827126467834122 0 0" rpy="0 0 0"/>
            <mass value="1" />
            <inertia ixx="100" ixy="0" ixz="0" iyy="100" iyz="0" izz="100" />
        </inertial>
        <visual>
            <origin xyz="0.9827126467834122 0 0" rpy="0 0 0"/>
            <geometry>
                <box size="1.9654252935668244 2.3904433976083497 2.675234574602417" />
            </geometry>
            <material name="Green">
                <color rgba="0 180.0 0.0 1.0"/>
            </material>
        </visual>
        <collision>
            <origin xyz="0.9827126467834122 0 0" rpy="0 0 0"/>
            <geometry>
                <box size="1.9654252935668244 2.3904433976083497 2.675234574602417" />
            </geometry>
        </collision>
    </link>
    <link name="Leg8">
        <inertial>
            <origin xyz="0.824373246487506 0 0" rpy="0 0 0"/>
            <mass value="1" />
            <inertia ixx="100" ixy="0" ixz="0" iyy="100" iyz="0" izz="100" />
        </inertial>
        <visual>
            <origin xyz="0.824373246487506 0 0" rpy="0 0 0"/>
            <geometry>
                <box size="1.648746492975012 2.117453724008002 1.0455751336933432" />
            </geometry>
            <material name="Blue">
                <color rgba="0 1.0 1.0 1.0"/>
            </material>
        </visual>
        <collision>
            <origin xyz="0.824373246487506 0 0" rpy="0 0 0"/>
            <geometry>
                <box size="1.648746492975012 2.117453724008002 1.0455751336933432" />
            </geometry>
        </collision>
    </link>
    <link name="Leg9">
        <inertial>
            <origin xyz="0.9690554247746077 0 0" rpy="0 0 0"/>
            <mass value="1" />
            <inertia ixx="100" ixy="0" ixz="0" iyy="100" iyz="0" izz="100" />
        </inertial>
        <visual>
            <origin xyz="0.9690554247746077 0 0" rpy="0 0 0"/>
            <geometry>
                <box size="1.9381108495492154 1.4020364519890773 2.9915454744379884" />
            </geometry>
            <material name="Green">
                <color rgba="0 180.0 0.0 1.0"/>
            </material>
        </visual>
        <collision>
            <origin xyz="0.9690554247746077 0 0" rpy="0 0 0"/>
            <geometry>
                <box size="1.9381108495492154 1.4020364519890773 2.9915454744379884" />
            </geometry>
        </collision>
    </link>
    <link name="Leg10">
        <inertial>
            <origin xyz="0 1.2293761385975006 0" rpy="0 0 0"/>
            <mass value="1" />
            <inertia ixx="100" ixy="0" ixz="0" iyy="100" iyz="0" izz="100" />
        </inertial>
        <visual>
            <origin xyz="0 1.2293761385975006 0" rpy="0 0 0"/>
            <geometry>
                <box size="1.175235445180067 2.4587522771950012 1.2874741444623015" />
            </geometry>
            <material name="Green">
                <color rgba="0 180.0 0.0 1.0"/>
            </material>
        </visual>
        <collision>
            <origin xyz="0 1.2293761385975006 0" rpy="0 0 0"/>
            <geometry>
                <box size="1.175235445180067 2.4587522771950012 1.2874741444623015" />
            </geometry>
        </collision>
    </link>
    <link name="Leg11">
        <inertial>
            <origin xyz="1.233064765133657 0 0" rpy="0 0 0"/>
            <mass value="1" />
            <inertia ixx="100" ixy="0" ixz="0" iyy="100" iyz="0" izz="100" />
        </inertial>
        <visual>
            <origin xyz="1.233064765133657 0 0" rpy="0 0 0"/>
            <geometry>
                <box size="2.466129530267314 1.0311868454964908 1.4249007600278354" />
            </geometry>
            <material name="Blue">
                <color rgba="0 1.0 1.0 1.0"/>
            </material>
        </visual>
        <collision>
            <origin xyz="1.233064765133657 0 0" rpy="0 0 0"/>
            <geometry>
                <box size="2.466129530267314 1.0311868454964908 1.4249007600278354" />
            </geometry>
        </collision>
    </link>
    <link name="Leg12">
        <inertial>
            <origin xyz="0.7765019583186851 0 0" rpy="0 0 0"/>
            <mass value="1" />
            <inertia ixx="100" ixy="0" ixz="0" iyy="100" iyz="0" izz="100" />
        </inertial>
        <visual>
            <origin xyz="0.7765019583186851 0 0" rpy="0 0 0"/>
            <geometry>
                <box size="1.5530039166373701 2.9856101755036626 1.9369169537569972" />
            </geometry>
            <material name="Green">
                <color rgba="0 180.0 0.0 1.0"/>
            </material>
        </visual>
        <collision>
            <origin xyz="0.7765019583186851 0 0" rpy="0 0 0"/>
            <geometry>
                <box size="1.5530039166373701 2.9856101755036626 1.9369169537569972" />
            </geometry>
        </collision>
    </link>
    <link name="Leg13">
        <inertial>
            <origin xyz="0 1.3599565971996743 0" rpy="0 0 0"/>
            <mass value="1" />
            <inertia ixx="100" ixy="0" ixz="0" iyy="100" iyz="0" izz="100" />
        </inertial>
        <visual>
            <origin xyz="0 1.3599565971996743 0" rpy="0 0 0"/>
            <geometry>
                <box size="1.8930604944405653 2.7199131943993486 1.0594361792908278" />
            </geometry>
            <material name="Blue">
                <color rgba="0 1.0 1.0 1.0"/>
            </material>
        </visual>
        <collision>
            <origin xyz="0 1.3599565971996743 0" rpy="0 0 0"/>
            <geometry>
                <box size="1.8930604944405653 2.7199131943993486 1.0594361792908278" />
            </geometry>
        </collision>
    </link>
    <link name="Leg14">
        <inertial>
            <origin xyz="0.9862648263430857 0 0" rpy="0 0 0"/>
            <mass value="1" />
            <inertia ixx="100" ixy="0" ixz="0" iyy="100" iyz="0" izz="100" />
        </inertial>
        <visual>
            <origin xyz="0.9862648263430857 0 0" rpy="0 0 0"/>
            <geometry>
                <box size="1.9725296526861713 1.7816182264545881 1.968557577328906" />
            </geometry>
            <material name="Blue">
                <color rgba="0 1.0 1.0 1.0"/>
            </material>
        </visual>
        <collision>
            <origin xyz="0.9862648263430857 0 0" rpy="0 0 0"/>
            <geometry>
                <box size="1.9725296526861713 1.7816182264545881 1.968557577328906" />
            </geometry>
        </collision>
    </link>
    <link name="Leg15">
        <inertial>
            <origin xyz="0 0.9158759542844539 0" rpy="0 0 0"/>
            <mass value="1" />
            <inertia ixx="100" ixy="0" ixz="0" iyy="100" iyz="0" izz="100" />
        </inertial>
        <visual>
            <origin xyz="0 0.9158759542844539 0" rpy="0 0 0"/>
            <geometry>
                <box size="2.2290826109780597 1.8317519085689078 1.6716679562286845" />
            </geometry>
            <material name="Green">
                <color rgba="0 180.0 0.0 1.0"/>
            </material>
        </visual>
        <collision>
            <origin xyz="0 0.9158759542844539 0" rpy="0 0 0"/>
            <geometry>
                <box size="2.2290826109780597 1.8317519085689078 1.6716679562286845" />
            </geometry>
        </collision>
    </link>
    <link name="Leg16">
        <inertial>
            <origin xyz="0 0 1.4447913122799996" rpy="0 0 0"/>
            <mass value="1" />
            <inertia ixx="100" ixy="0" ixz="0" iyy="100" iyz="0" izz="100" />
        </inertial>
        <visual>
            <origin xyz="0 0 1.4447913122799996" rpy="0 0 0"/>
            <geometry>
                <box size="1.3949300303755452 2.890693740540205 2.889582624559999" />
            </geometry>
            <material name="Green">
                <color rgba="0 180.0 0.0 1.0"/>
            </material>
        </visual>
        <collision>
            <origin xyz="0 0 1.4447913122799996" rpy="0 0 0"/>
            <geometry>
                <box size="1.3949300303755452 2.890693740540205 2.889582624559999" />
            </geometry>
        </collision>
    </link>
    <link name="Leg17">
        <inertial>
            <origin xyz="1.409858079600059 0 0" rpy="0 0 0"/>
            <mass value="1" />
            <inertia ixx="100" ixy="0" ixz="0" iyy="100" iyz="0" izz="100" />
        </inertial>
        <visual>
            <origin xyz="1.409858079600059 0 0" rpy="0 0 0"/>
            <geometry>
                <box size="2.819716159200118 1.0790366619761425 1.6571499270444048" />
            </geometry>
            <material name="Blue">
                <color rgba="0 1.0 1.0 1.0"/>
            </material>
        </visual>
        <collision>
            <origin xyz="1.409858079600059 0 0" rpy="0 0 0"/>
            <geometry>
                <box size="2.819716159200118 1.0790366619761425 1.6571499270444048" />
            </geometry>
        </collision>
    </link>
    <link name="Leg18">
        <inertial>
            <origin xyz="0 0 0.892803942086425" rpy="0 0 0"/>
            <mass value="1" />
            <inertia ixx="100" ixy="0" ixz="0" iyy="100" iyz="0" izz="100" />
        </inertial>
        <visual>
            <origin xyz="0 0 0.892803942086425" rpy="0 0 0"/>
            <geometry>
                <box size="1.7840839278425895 2.7077599130691854 1.78560788417285" />
            </geometry>
            <material name="Green">
                <color rgba="0 180.0 0.0 1.0"/>
            </material>
        </visual>
        <collision>
            <origin xyz="0 0 0.892803942086425" rpy="0 0 0"/>
            <geometry>
                <box size="1.7840839278425895 2.7077599130691854 1.78560788417285" />
            </geometry>
        </collision>
    </link>
    <link name="Leg19">
        <inertial>
            <origin xyz="0 0.7570693774758483 0" rpy="0 0 0"/>
            <mass value="1" />
            <inertia ixx="100" ixy="0" ixz="0" iyy="100" iyz="0" izz="100" />
        </inertial>
        <visual>
            <origin xyz="0 0.7570693774758483 0" rpy="0 0 0"/>
            <geometry>
                <box size="2.9811474868385224 1.5141387549516967 1.0315703638547895" />
            </geometry>
            <material name="Green">
                <color rgba="0 180.0 0.0 1.0"/>
            </material>
        </visual>
        <collision>
            <origin xyz="0 0.7570693774758483 0" rpy="0 0 0"/>
            <geometry>
                <box size="2.9811474868385224 1.5141387549516967 1.0315703638547895" />
            </geometry>
        </collision>
    </link>
    <link name="Leg20">
        <inertial>
            <origin xyz="0.7323551196844682 0 0" rpy="0 0 0"/>
            <mass value="1" />
            <inertia ixx="100" ixy="0" ixz="0" iyy="100" iyz="0" izz="100" />
        </inertial>
        <visual>
            <origin xyz="0.7323551196844682 0 0" rpy="0 0 0"/>
            <geometry>
                <box size="1.4647102393689364 1.4911746481693515 2.7568114422297665" />
            </geometry>
            <material name="Blue">
                <color rgba="0 1.0 1.0 1.0"/>
            </material>
        </visual>
        <collision>
            <origin xyz="0.7323551196844682 0 0" rpy="0 0 0"/>
            <geometry>
                <box size="1.4647102393689364 1.4911746481693515 2.7568114422297665" />
            </geometry>
        </collision>
    </link>
    <link name="Leg21">
        <inertial>
            <origin xyz="0 0 1.1983354466969478" rpy="0 0 0"/>
            <mass value="1" />
            <inertia ixx="100" ixy="0" ixz="0" iyy="100" iyz="0" izz="100" />
        </inertial>
        <visual>
            <origin xyz="0 0 1.1983354466969478" rpy="0 0 0"/>
            <geometry>
                <box size="1.703831439472522 2.383704713310338 2.3966708933938956" />
            </geometry>
            <material name="Green">
                <color rgba="0 180.0 0.0 1.0"/>
            </material>
        </visual>
        <collision>
            <origin xyz="0 0 1.1983354466969478" rpy="0 0 0"/>
            <geometry>
                <box size="1.703831439472522 2.383704713310338 2.3966708933938956" />
            </geometry>
        </collision>
    </link>
    <link name="Leg22">
        <inertial>
            <origin xyz="0 1.0388849749366054 0" rpy="0 0 0"/>
            <mass value="1" />
            <inertia ixx="100" ixy="0" ixz="0" iyy="100" iyz="0" izz="100" />
        </inertial>
        <visual>
            <origin xyz="0 1.0388849749366054 0" rpy="0 0 0"/>
            <geometry>
                <box size="1.7860370043086529 2.0777699498732107 2.0135588876314987" />
            </geometry>
            <material name="Green">
                <color rgba="0 180.0 0.0 1.0"/>
            </material>
        </visual>
        <collision>
            <origin xyz="0 1.0388849749366054 0" rpy="0 0 0"/>
            <geometry>
                <box size="1.7860370043086529 2.0777699498732107 2.0135588876314987" />
            </geometry>
        </collision>
    </link>
    <link name="Leg23">
        <inertial>
            <origin xyz="0 0 1.415531447174126" rpy="0 0 0"/>
            <mass value="1" />
            <inertia ixx="100" ixy="0" ixz="0" iyy="100" iyz="0" izz="100" />
        </inertial>
        <visual>
            <origin xyz="0 0 1.415531447174126" rpy="0 0 0"/>
            <geometry>
                <box size="1.2860281920770558 2.4277742553705703 2.831062894348252" />
            </geometry>
            <material name="Green">
                <color rgba="0 180.0 0.0 1.0"/>
            </material>
        </visual>
        <collision>
            <origin xyz="0 0 1.415531447174126" rpy="0 0 0"/>
            <geometry>
                <box size="1.2860281920770558 2.4277742553705703 2.831062894348252" />
            </geometry>
        </collision>
    </link>
    <link name="Leg24">
        <inertial>
            <origin xyz="0 0.7435676014566869 0" rpy="0 0 0"/>
            <mass value="1" />
            <inertia ixx="100" ixy="0" ixz="0" iyy="100" iyz="0" izz="100" />
        </inertial>
        <visual>
            <origin xyz="0 0.7435676014566869 0" rpy="0 0 0"/>
            <geometry>
                <box size="2.7610053993402297 1.4871352029133738 1.1159428860677676" />
            </geometry>
            <material name="Blue">
                <color rgba="0 1.0 1.0 1.0"/>
            </material>
        </visual>
        <collision>
            <origin xyz="0 0.7435676014566869 0" rpy="0 0 0"/>
            <geometry>
                <box size="2.7610053993402297 1.4871352029133738 1.1159428860677676" />
            </geometry>
        </collision>
    </link>
    <link name="Leg25">
        <inertial>
            <origin xyz="1.04888722990709 0 0" rpy="0 0 0"/>
            <mass value="1" />
            <inertia ixx="100" ixy="0" ixz="0" iyy="100" iyz="0" izz="100" />
        </inertial>
        <visual>
            <origin xyz="1.04888722990709 0 0" rpy="0 0 0"/>
            <geometry>
                <box size="2.09777445981418 2.5394024566001683 1.9372432067450862" />
            </geometry>
            <material name="Green">
                <color rgba="0 180.0 0.0 1.0"/>
            </material>
        </visual>
        <collision>
            <origin xyz="1.04888722990709 0 0" rpy="0 0 0"/>
            <geometry>
                <box size="2.09777445981418 2.5394024566001683 1.9372432067450862" />
            </geometry>
        </collision>
    </link>
    <link name="Leg26">
        <inertial>
            <origin xyz="0 0 0.8378286531811525" rpy="0 0 0"/>
            <mass value="1" />
            <inertia ixx="100" ixy="0" ixz="0" iyy="100" iyz="0" izz="100" />
        </inertial>
        <visual>
            <origin xyz="0 0 0.8378286531811525" rpy="0 0 0"/>
            <geometry>
                <box size="2.60779511432065 1.580455092735826 1.675657306362305" />
            </geometry>
            <material name="Blue">
                <color rgba="0 1.0 1.0 1.0"/>
            </material>
        </visual>
        <collision>
            <origin xyz="0 0 0.8378286531811525" rpy="0 0 0"/>
            <geometry>
                <box size="2.60779511432065 1.580455092735826 1.675657306362305" />
            </geometry>
        </collision>
    </link>
    <joint name="Torso_Leg1" type="revolute">
       <parent link="Torso"/>
       <child  link="Leg1"/>
       <origin rpy="0 0 0" xyz="0 0 1.2886311772581553" />
     <axis xyz="1 0 0"/>
       <limit effort="0.0" lower="-3.14159" upper="3.14159" velocity="0.0"/>
    </joint>
    <joint name="Torso_Leg2" type="revolute">
       <parent link="Torso"/>
       <child  link="Leg2"/>
       <origin rpy="0 0 0" xyz="0 0.7802565589639437 1.0243860521773867" />
     <axis xyz="1 0 0"/>
       <limit effort="0.0" lower="-3.14159" upper="3.14159" velocity="0.0"/>
    </joint>
    <joint name="Leg1_Leg3" type="revolute">
       <parent link="Leg1"/>
       <child  link="Leg3"/>
       <origin rpy="0 0 0" xyz="0.9167379105003454 0.5383102626051709 0" />
     <axis xyz="1 0 0"/>
       <limit effort="0.0" lower="-3.14159" upper="3.14159" velocity="0.0"/>
    </joint>
    <joint name="Leg3_Leg4" type="revolute">
       <parent link="Leg3"/>
       <child  link="Leg4"/>
       <origin rpy="0 0 0" xyz="0 2.5942111934667924 0" />
     <axis xyz="1 0 0"/>
       <limit effort="0.0" lower="-3.14159" upper="3.14159" velocity="0.0"/>
    </joint>
    <joint name="Leg3_Leg5" type="revolute">
       <parent link="Leg3"/>
       <child  link="Leg5"/>
       <origin rpy="0 0 0" xyz="0 2.5942111934667924 1.105857719360956" />
     <axis xyz="1 0 0"/>
       <limit effort="0.0" lower="-3.14159" upper="3.14159" velocity="0.0"/>
    </joint>
    <joint name="Leg1_Leg6" type="revolute">
       <parent link="Leg1"/>
       <child  link="Leg6"/>
       <origin rpy="0 0 0" xyz="0.9167379105003454 1.0766205252103418 0" />
     <axis xyz="1 0 0"/>
       <limit effort="0.0" lower="-3.14159" upper="3.14159" velocity="0.0"/>
    </joint>
    <joint name="Leg6_Leg7" type="revolute">
       <parent link="Leg6"/>
       <child  link="Leg7"/>
       <origin rpy="0 0 0" xyz="1.9654252935668244 0 0" />
     <axis xyz="1 0 0"/>
       <limit effort="0.0" lower="-3.14159" upper="3.14159" velocity="0.0"/>
    </joint>
    <joint name="Leg3_Leg8" type="revolute">
       <parent link="Leg3"/>
       <child  link="Leg8"/>
       <origin rpy="0 0 0" xyz="0.7778187502629743 2.5942111934667924 1.105857719360956" />
     <axis xyz="1 0 0"/>
       <limit effort="0.0" lower="-3.14159" upper="3.14159" velocity="0.0"/>
    </joint>
    <joint name="Leg5_Leg9" type="revolute">
       <parent link="Leg5"/>
       <child  link="Leg9"/>
       <origin rpy="0 0 0" xyz="1.2688105822162998 0.6545208987214092 0" />
     <axis xyz="1 0 0"/>
       <limit effort="0.0" lower="-3.14159" upper="3.14159" velocity="0.0"/>
    </joint>
    <joint name="Leg7_Leg10" type="revolute">
       <parent link="Leg7"/>
       <child  link="Leg10"/>
       <origin rpy="0 0 0" xyz="0.824373246487506 1.058726862004001 0" />
     <axis xyz="1 0 0"/>
       <limit effort="0.0" lower="-3.14159" upper="3.14159" velocity="0.0"/>
    </joint>
    <joint name="Leg9_Leg11" type="revolute">
       <parent link="Leg9"/>
       <child  link="Leg11"/>
       <origin rpy="0 0 0" xyz="0.5876177225900335 1.2293761385975006 0" />
     <axis xyz="1 0 0"/>
       <limit effort="0.0" lower="-3.14159" upper="3.14159" velocity="0.0"/>
    </joint>
    <joint name="Torso_Leg12" type="revolute">
       <parent link="Torso"/>
       <child  link="Leg12"/>
       <origin rpy="0 0 0" xyz="1.3585619484482079 0.7802565589639437 1.0243860521773867" />
     <axis xyz="1 0 0"/>
       <limit effort="0.0" lower="-3.14159" upper="3.14159" velocity="0.0"/>
    </joint>
    <joint name="Leg5_Leg13" type="revolute">
       <parent link="Leg5"/>
       <child  link="Leg13"/>
       <origin rpy="0 0 0" xyz="1.2688105822162998 1.3090417974428183 0" />
     <axis xyz="1 0 0"/>
       <limit effort="0.0" lower="-3.14159" upper="3.14159" velocity="0.0"/>
    </joint>
    <joint name="Leg10_Leg14" type="revolute">
       <parent link="Leg10"/>
       <child  link="Leg14"/>
       <origin rpy="0 0 0" xyz="2.466129530267314 0 0" />
     <axis xyz="1 0 0"/>
       <limit effort="0.0" lower="-3.14159" upper="3.14159" velocity="0.0"/>
    </joint>
    <joint name="Leg6_Leg15" type="revolute">
       <parent link="Leg6"/>
       <child  link="Leg15"/>
       <origin rpy="0 0 0" xyz="1.9654252935668244 1.1952216988041748 0" />
     <axis xyz="1 0 0"/>
       <limit effort="0.0" lower="-3.14159" upper="3.14159" velocity="0.0"/>
    </joint>
    <joint name="Leg4_Leg16" type="revolute">
       <parent link="Leg4"/>
       <child  link="Leg16"/>
       <origin rpy="0 0 0" xyz="0 0 1.869019662249086" />
     <axis xyz="1 0 0"/>
       <limit effort="0.0" lower="-3.14159" upper="3.14159" velocity="0.0"/>
    </joint>
    <joint name="Leg4_Leg17" type="revolute">
       <parent link="Leg4"/>
       <child  link="Leg17"/>
       <origin rpy="0 0 0" xyz="0.6723432168893665 0 1.869019662249086" />
     <axis xyz="1 0 0"/>
       <limit effort="0.0" lower="-3.14159" upper="3.14159" velocity="0.0"/>
    </joint>
    <joint name="Leg6_Leg18" type="revolute">
       <parent link="Leg6"/>
       <child  link="Leg18"/>
       <origin rpy="0 0 0" xyz="1.9654252935668244 1.1952216988041748 1.3376172873012084" />
     <axis xyz="1 0 0"/>
       <limit effort="0.0" lower="-3.14159" upper="3.14159" velocity="0.0"/>
    </joint>
    <joint name="Leg8_Leg19" type="revolute">
       <parent link="Leg8"/>
       <child  link="Leg19"/>
       <origin rpy="0 0 0" xyz="0.9690554247746077 0.7010182259945387 0" />
     <axis xyz="1 0 0"/>
       <limit effort="0.0" lower="-3.14159" upper="3.14159" velocity="0.0"/>
    </joint>
    <joint name="Leg14_Leg20" type="revolute">
       <parent link="Leg14"/>
       <child  link="Leg20"/>
       <origin rpy="0 0 0" xyz="1.1145413054890299 0.9158759542844539 0" />
     <axis xyz="1 0 0"/>
       <limit effort="0.0" lower="-3.14159" upper="3.14159" velocity="0.0"/>
    </joint>
    <joint name="Leg19_Leg21" type="revolute">
       <parent link="Leg19"/>
       <child  link="Leg21"/>
       <origin rpy="0 0 0" xyz="0.7323551196844682 0 1.3784057211148832" />
     <axis xyz="1 0 0"/>
       <limit effort="0.0" lower="-3.14159" upper="3.14159" velocity="0.0"/>
    </joint>
    <joint name="Leg10_Leg22" type="revolute">
       <parent link="Leg10"/>
       <child  link="Leg22"/>
       <origin rpy="0 0 0" xyz="2.466129530267314 0.5155934227482454 0" />
     <axis xyz="1 0 0"/>
       <limit effort="0.0" lower="-3.14159" upper="3.14159" velocity="0.0"/>
    </joint>
    <joint name="Leg13_Leg23" type="revolute">
       <parent link="Leg13"/>
       <child  link="Leg23"/>
       <origin rpy="0 0 0" xyz="0.9862648263430857 0 0.984278788664453" />
     <axis xyz="1 0 0"/>
       <limit effort="0.0" lower="-3.14159" upper="3.14159" velocity="0.0"/>
    </joint>
    <joint name="Leg11_Leg24" type="revolute">
       <parent link="Leg11"/>
       <child  link="Leg24"/>
       <origin rpy="0 0 0" xyz="0.7765019583186851 1.4928050877518313 0" />
     <axis xyz="1 0 0"/>
       <limit effort="0.0" lower="-3.14159" upper="3.14159" velocity="0.0"/>
    </joint>
    <joint name="Leg15_Leg25" type="revolute">
       <parent link="Leg15"/>
       <child  link="Leg25"/>
       <origin rpy="0 0 0" xyz="0.6974650151877726 0 1.4447913122799996" />
     <axis xyz="1 0 0"/>
       <limit effort="0.0" lower="-3.14159" upper="3.14159" velocity="0.0"/>
    </joint>
    <joint name="Leg11_Leg26" type="revolute">
       <parent link="Leg11"/>
       <child  link="Leg26"/>
       <origin rpy="0 0 0" xyz="0.7765019583186851 1.4928050877518313 0.9684584768784986" />
     <axis xyz="1 0 0"/>
       <limit effort="0.0" lower="-3.14159" upper="3.14159" velocity="0.0"/>
    </joint>
</robot>