<robot name = "robot">
    <link name="Torso">
        <inertial>
            <origin xyz="0 0 0.6885520085765885" rpy="0 0 0"/>
            <mass value="1" />
            <inertia ixx="100" ixy="0" ixz="0" iyy="100" iyz="0" izz="100" />
        </inertial>
        <visual>
            <origin xyz="0 0 0.6885520085765885" rpy="0 0 0"/>
            <geometry>
                <box size="1.1972503787867208 1.097225470665786 1.377104017153177" />
            </geometry>
            <material name="Green">
                <color rgba="0 180.0 0.0 1.0"/>
            </material>
        </visual>
        <collision>
            <origin xyz="0 0 0.6885520085765885" rpy="0 0 0"/>
            <geometry>
                <box size="1.1972503787867208 1.097225470665786 1.377104017153177" />
            </geometry>
        </collision>
    </link>
    <link name="Leg1">
        <inertial>
            <origin xyz="0 0 1.4898582754515597" rpy="0 0 0"/>
            <mass value="1" />
            <inertia ixx="100" ixy="0" ixz="0" iyy="100" iyz="0" izz="100" />
        </inertial>
        <visual>
            <origin xyz="0 0 1.4898582754515597" rpy="0 0 0"/>
            <geometry>
                <box size="2.5221654945603813 1.0908947875099853 2.9797165509031194" />
            </geometry>
            <material name="Blue">
                <color rgba="0 1.0 1.0 1.0"/>
            </material>
        </visual>
        <collision>
            <origin xyz="0 0 1.4898582754515597" rpy="0 0 0"/>
            <geometry>
                <box size="2.5221654945603813 1.0908947875099853 2.9797165509031194" />
            </geometry>
        </collision>
    </link>
    <link name="Leg2">
        <inertial>
            <origin xyz="1.2219887132179013 0 0" rpy="0 0 0"/>
            <mass value="1" />
            <inertia ixx="100" ixy="0" ixz="0" iyy="100" iyz="0" izz="100" />
        </inertial>
        <visual>
            <origin xyz="1.2219887132179013 0 0" rpy="0 0 0"/>
            <geometry>
                <box size="2.4439774264358025 1.0480049272904153 1.8722956207582535" />
            </geometry>
            <material name="Green">
                <color rgba="0 180.0 0.0 1.0"/>
            </material>
        </visual>
        <collision>
            <origin xyz="1.2219887132179013 0 0" rpy="0 0 0"/>
            <geometry>
                <box size="2.4439774264358025 1.0480049272904153 1.8722956207582535" />
            </geometry>
        </collision>
    </link>
    <link name="Leg3">
        <inertial>
            <origin xyz="0 0 0.6980500137453749" rpy="0 0 0"/>
            <mass value="1" />
            <inertia ixx="100" ixy="0" ixz="0" iyy="100" iyz="0" izz="100" />
        </inertial>
        <visual>
            <origin xyz="0 0 0.6980500137453749" rpy="0 0 0"/>
            <geometry>
                <box size="2.6294515883932865 1.6673541546645303 1.3961000274907498" />
            </geometry>
            <material name="Green">
                <color rgba="0 180.0 0.0 1.0"/>
            </material>
        </visual>
        <collision>
            <origin xyz="0 0 0.6980500137453749" rpy="0 0 0"/>
            <geometry>
                <box size="2.6294515883932865 1.6673541546645303 1.3961000274907498" />
            </geometry>
        </collision>
    </link>
    <link name="Leg4">
        <inertial>
            <origin xyz="0 1.0302434456462926 0" rpy="0 0 0"/>
            <mass value="1" />
            <inertia ixx="100" ixy="0" ixz="0" iyy="100" iyz="0" izz="100" />
        </inertial>
        <visual>
            <origin xyz="0 1.0302434456462926 0" rpy="0 0 0"/>
            <geometry>
                <box size="1.7126546480566045 2.060486891292585 2.4146211940638187" />
            </geometry>
            <material name="Green">
                <color rgba="0 180.0 0.0 1.0"/>
            </material>
        </visual>
        <collision>
            <origin xyz="0 1.0302434456462926 0" rpy="0 0 0"/>
            <geometry>
                <box size="1.7126546480566045 2.060486891292585 2.4146211940638187" />
            </geometry>
        </collision>
    </link>
    <link name="Leg5">
        <inertial>
            <origin xyz="0 0 0.7421887465365892" rpy="0 0 0"/>
            <mass value="1" />
            <inertia ixx="100" ixy="0" ixz="0" iyy="100" iyz="0" izz="100" />
        </inertial>
        <visual>
            <origin xyz="0 0 0.7421887465365892" rpy="0 0 0"/>
            <geometry>
                <box size="2.2877207981280527 1.3809317681154414 1.4843774930731783" />
            </geometry>
            <material name="Blue">
                <color rgba="0 1.0 1.0 1.0"/>
            </material>
        </visual>
        <collision>
            <origin xyz="0 0 0.7421887465365892" rpy="0 0 0"/>
            <geometry>
                <box size="2.2877207981280527 1.3809317681154414 1.4843774930731783" />
            </geometry>
        </collision>
    </link>
    <link name="Leg6">
        <inertial>
            <origin xyz="0 1.256534572837588 0" rpy="0 0 0"/>
            <mass value="1" />
            <inertia ixx="100" ixy="0" ixz="0" iyy="100" iyz="0" izz="100" />
        </inertial>
        <visual>
            <origin xyz="0 1.256534572837588 0" rpy="0 0 0"/>
            <geometry>
                <box size="2.777068635040323 2.513069145675176 2.026842017519326" />
            </geometry>
            <material name="Green">
                <color rgba="0 180.0 0.0 1.0"/>
            </material>
        </visual>
        <collision>
            <origin xyz="0 1.256534572837588 0" rpy="0 0 0"/>
            <geometry>
                <box size="2.777068635040323 2.513069145675176 2.026842017519326" />
            </geometry>
        </collision>
    </link>
    <link name="Leg7">
        <inertial>
            <origin xyz="0 1.0140679945033142 0" rpy="0 0 0"/>
            <mass value="1" />
            <inertia ixx="100" ixy="0" ixz="0" iyy="100" iyz="0" izz="100" />
        </inertial>
        <visual>
            <origin xyz="0 1.0140679945033142 0" rpy="0 0 0"/>
            <geometry>
                <box size="1.1986536070682967 2.0281359890066284 1.406924070857196" />
            </geometry>
            <material name="Green">
                <color rgba="0 180.0 0.0 1.0"/>
            </material>
        </visual>
        <collision>
            <origin xyz="0 1.0140679945033142 0" rpy="0 0 0"/>
            <geometry>
                <box size="1.1986536070682967 2.0281359890066284 1.406924070857196" />
            </geometry>
        </collision>
    </link>
    <link name="Leg8">
        <inertial>
            <origin xyz="1.288100432817167 0 0" rpy="0 0 0"/>
            <mass value="1" />
            <inertia ixx="100" ixy="0" ixz="0" iyy="100" iyz="0" izz="100" />
        </inertial>
        <visual>
            <origin xyz="1.288100432817167 0 0" rpy="0 0 0"/>
            <geometry>
                <box size="2.576200865634334 1.396428701892388 1.1217066552933699" />
            </geometry>
            <material name="Blue">
                <color rgba="0 1.0 1.0 1.0"/>
            </material>
        </visual>
        <collision>
            <origin xyz="1.288100432817167 0 0" rpy="0 0 0"/>
            <geometry>
                <box size="2.576200865634334 1.396428701892388 1.1217066552933699" />
            </geometry>
        </collision>
    </link>
    <link name="Leg9">
        <inertial>
            <origin xyz="1.3553752784253263 0 0" rpy="0 0 0"/>
            <mass value="1" />
            <inertia ixx="100" ixy="0" ixz="0" iyy="100" iyz="0" izz="100" />
        </inertial>
        <visual>
            <origin xyz="1.3553752784253263 0 0" rpy="0 0 0"/>
            <geometry>
                <box size="2.7107505568506527 1.19953872367894 1.2779513742974073" />
            </geometry>
            <material name="Blue">
                <color rgba="0 1.0 1.0 1.0"/>
            </material>
        </visual>
        <collision>
            <origin xyz="1.3553752784253263 0 0" rpy="0 0 0"/>
            <geometry>
                <box size="2.7107505568506527 1.19953872367894 1.2779513742974073" />
            </geometry>
        </collision>
    </link>
    <link name="Leg10">
        <inertial>
            <origin xyz="0.8405751850977393 0 0" rpy="0 0 0"/>
            <mass value="1" />
            <inertia ixx="100" ixy="0" ixz="0" iyy="100" iyz="0" izz="100" />
        </inertial>
        <visual>
            <origin xyz="0.8405751850977393 0 0" rpy="0 0 0"/>
            <geometry>
                <box size="1.6811503701954786 2.3485657891053395 2.851122339296306" />
            </geometry>
            <material name="Green">
                <color rgba="0 180.0 0.0 1.0"/>
            </material>
        </visual>
        <collision>
            <origin xyz="0.8405751850977393 0 0" rpy="0 0 0"/>
            <geometry>
                <box size="1.6811503701954786 2.3485657891053395 2.851122339296306" />
            </geometry>
        </collision>
    </link>
    <link name="Leg11">
        <inertial>
            <origin xyz="0 0 1.356725591237443" rpy="0 0 0"/>
            <mass value="1" />
            <inertia ixx="100" ixy="0" ixz="0" iyy="100" iyz="0" izz="100" />
        </inertial>
        <visual>
            <origin xyz="0 0 1.356725591237443" rpy="0 0 0"/>
            <geometry>
                <box size="1.8700949970193106 2.3090801373830736 2.713451182474886" />
            </geometry>
            <material name="Blue">
                <color rgba="0 1.0 1.0 1.0"/>
            </material>
        </visual>
        <collision>
            <origin xyz="0 0 1.356725591237443" rpy="0 0 0"/>
            <geometry>
                <box size="1.8700949970193106 2.3090801373830736 2.713451182474886" />
            </geometry>
        </collision>
    </link>
    <link name="Leg12">
        <inertial>
            <origin xyz="0 0 0.7686955489425846" rpy="0 0 0"/>
            <mass value="1" />
            <inertia ixx="100" ixy="0" ixz="0" iyy="100" iyz="0" izz="100" />
        </inertial>
        <visual>
            <origin xyz="0 0 0.7686955489425846" rpy="0 0 0"/>
            <geometry>
                <box size="1.1131326929206313 2.4558796280304493 1.5373910978851693" />
            </geometry>
            <material name="Blue">
                <color rgba="0 1.0 1.0 1.0"/>
            </material>
        </visual>
        <collision>
            <origin xyz="0 0 0.7686955489425846" rpy="0 0 0"/>
            <geometry>
                <box size="1.1131326929206313 2.4558796280304493 1.5373910978851693" />
            </geometry>
        </collision>
    </link>
    <link name="Leg13">
        <inertial>
            <origin xyz="0 0 1.4928843734141195" rpy="0 0 0"/>
            <mass value="1" />
            <inertia ixx="100" ixy="0" ixz="0" iyy="100" iyz="0" izz="100" />
        </inertial>
        <visual>
            <origin xyz="0 0 1.4928843734141195" rpy="0 0 0"/>
            <geometry>
                <box size="2.6492396382504504 1.1038133716066487 2.985768746828239" />
            </geometry>
            <material name="Green">
                <color rgba="0 180.0 0.0 1.0"/>
            </material>
        </visual>
        <collision>
            <origin xyz="0 0 1.4928843734141195" rpy="0 0 0"/>
            <geometry>
                <box size="2.6492396382504504 1.1038133716066487 2.985768746828239" />
            </geometry>
        </collision>
    </link>
    <link name="Leg14">
        <inertial>
            <origin xyz="0 1.2929981908731745 0" rpy="0 0 0"/>
            <mass value="1" />
            <inertia ixx="100" ixy="0" ixz="0" iyy="100" iyz="0" izz="100" />
        </inertial>
        <visual>
            <origin xyz="0 1.2929981908731745 0" rpy="0 0 0"/>
            <geometry>
                <box size="2.9327548024627106 2.585996381746349 2.5915640120683157" />
            </geometry>
            <material name="Blue">
                <color rgba="0 1.0 1.0 1.0"/>
            </material>
        </visual>
        <collision>
            <origin xyz="0 1.2929981908731745 0" rpy="0 0 0"/>
            <geometry>
                <box size="2.9327548024627106 2.585996381746349 2.5915640120683157" />
            </geometry>
        </collision>
    </link>
    <link name="Leg15">
        <inertial>
            <origin xyz="0 0 1.498183551255978" rpy="0 0 0"/>
            <mass value="1" />
            <inertia ixx="100" ixy="0" ixz="0" iyy="100" iyz="0" izz="100" />
        </inertial>
        <visual>
            <origin xyz="0 0 1.498183551255978" rpy="0 0 0"/>
            <geometry>
                <box size="2.895861171878975 1.5029661931354437 2.996367102511956" />
            </geometry>
            <material name="Blue">
                <color rgba="0 1.0 1.0 1.0"/>
            </material>
        </visual>
        <collision>
            <origin xyz="0 0 1.498183551255978" rpy="0 0 0"/>
            <geometry>
                <box size="2.895861171878975 1.5029661931354437 2.996367102511956" />
            </geometry>
        </collision>
    </link>
    <link name="Leg16">
        <inertial>
            <origin xyz="1.027188914378935 0 0" rpy="0 0 0"/>
            <mass value="1" />
            <inertia ixx="100" ixy="0" ixz="0" iyy="100" iyz="0" izz="100" />
        </inertial>
        <visual>
            <origin xyz="1.027188914378935 0 0" rpy="0 0 0"/>
            <geometry>
                <box size="2.05437782875787 1.72663395145982 2.3095385824180883" />
            </geometry>
            <material name="Green">
                <color rgba="0 180.0 0.0 1.0"/>
            </material>
        </visual>
        <collision>
            <origin xyz="1.027188914378935 0 0" rpy="0 0 0"/>
            <geometry>
                <box size="2.05437782875787 1.72663395145982 2.3095385824180883" />
            </geometry>
        </collision>
    </link>
    <link name="Leg17">
        <inertial>
            <origin xyz="1.4840895246350019 0 0" rpy="0 0 0"/>
            <mass value="1" />
            <inertia ixx="100" ixy="0" ixz="0" iyy="100" iyz="0" izz="100" />
        </inertial>
        <visual>
            <origin xyz="1.4840895246350019 0 0" rpy="0 0 0"/>
            <geometry>
                <box size="2.9681790492700038 1.9750159163554661 1.5924788508133183" />
            </geometry>
            <material name="Blue">
                <color rgba="0 1.0 1.0 1.0"/>
            </material>
        </visual>
        <collision>
            <origin xyz="1.4840895246350019 0 0" rpy="0 0 0"/>
            <geometry>
                <box size="2.9681790492700038 1.9750159163554661 1.5924788508133183" />
            </geometry>
        </collision>
    </link>
    <link name="Leg18">
        <inertial>
            <origin xyz="1.1959571084473937 0 0" rpy="0 0 0"/>
            <mass value="1" />
            <inertia ixx="100" ixy="0" ixz="0" iyy="100" iyz="0" izz="100" />
        </inertial>
        <visual>
            <origin xyz="1.1959571084473937 0 0" rpy="0 0 0"/>
            <geometry>
                <box size="2.3919142168947873 2.2279458219492074 2.6749925256367018" />
            </geometry>
            <material name="Blue">
                <color rgba="0 1.0 1.0 1.0"/>
            </material>
        </visual>
        <collision>
            <origin xyz="1.1959571084473937 0 0" rpy="0 0 0"/>
            <geometry>
                <box size="2.3919142168947873 2.2279458219492074 2.6749925256367018" />
            </geometry>
        </collision>
    </link>
    <link name="Leg19">
        <inertial>
            <origin xyz="0 0 0.7642370282958613" rpy="0 0 0"/>
            <mass value="1" />
            <inertia ixx="100" ixy="0" ixz="0" iyy="100" iyz="0" izz="100" />
        </inertial>
        <visual>
            <origin xyz="0 0 0.7642370282958613" rpy="0 0 0"/>
            <geometry>
                <box size="2.8491133953714822 1.572659299714785 1.5284740565917225" />
            </geometry>
            <material name="Green">
                <color rgba="0 180.0 0.0 1.0"/>
            </material>
        </visual>
        <collision>
            <origin xyz="0 0 0.7642370282958613" rpy="0 0 0"/>
            <geometry>
                <box size="2.8491133953714822 1.572659299714785 1.5284740565917225" />
            </geometry>
        </collision>
    </link>
    <link name="Leg20">
        <inertial>
            <origin xyz="0.9735832374367335 0 0" rpy="0 0 0"/>
            <mass value="1" />
            <inertia ixx="100" ixy="0" ixz="0" iyy="100" iyz="0" izz="100" />
        </inertial>
        <visual>
            <origin xyz="0.9735832374367335 0 0" rpy="0 0 0"/>
            <geometry>
                <box size="1.947166474873467 1.930031555326712 1.4741631689509964" />
            </geometry>
            <material name="Blue">
                <color rgba="0 1.0 1.0 1.0"/>
            </material>
        </visual>
        <collision>
            <origin xyz="0.9735832374367335 0 0" rpy="0 0 0"/>
            <geometry>
                <box size="1.947166474873467 1.930031555326712 1.4741631689509964" />
            </geometry>
        </collision>
    </link>
    <link name="Leg21">
        <inertial>
            <origin xyz="0 0.866089651075658 0" rpy="0 0 0"/>
            <mass value="1" />
            <inertia ixx="100" ixy="0" ixz="0" iyy="100" iyz="0" izz="100" />
        </inertial>
        <visual>
            <origin xyz="0 0.866089651075658 0" rpy="0 0 0"/>
            <geometry>
                <box size="2.191132124416396 1.732179302151316 1.7450420883669924" />
            </geometry>
            <material name="Blue">
                <color rgba="0 1.0 1.0 1.0"/>
            </material>
        </visual>
        <collision>
            <origin xyz="0 0.866089651075658 0" rpy="0 0 0"/>
            <geometry>
                <box size="2.191132124416396 1.732179302151316 1.7450420883669924" />
            </geometry>
        </collision>
    </link>
    <link name="Leg22">
        <inertial>
            <origin xyz="0 0.6535473406742286 0" rpy="0 0 0"/>
            <mass value="1" />
            <inertia ixx="100" ixy="0" ixz="0" iyy="100" iyz="0" izz="100" />
        </inertial>
        <visual>
            <origin xyz="0 0.6535473406742286 0" rpy="0 0 0"/>
            <geometry>
                <box size="2.9599932077010296 1.3070946813484572 2.3534443925817623" />
            </geometry>
            <material name="Green">
                <color rgba="0 180.0 0.0 1.0"/>
            </material>
        </visual>
        <collision>
            <origin xyz="0 0.6535473406742286 0" rpy="0 0 0"/>
            <geometry>
                <box size="2.9599932077010296 1.3070946813484572 2.3534443925817623" />
            </geometry>
        </collision>
    </link>
    <link name="Leg23">
        <inertial>
            <origin xyz="0 0 1.4397354636269126" rpy="0 0 0"/>
            <mass value="1" />
            <inertia ixx="100" ixy="0" ixz="0" iyy="100" iyz="0" izz="100" />
        </inertial>
        <visual>
            <origin xyz="0 0 1.4397354636269126" rpy="0 0 0"/>
            <geometry>
                <box size="2.7937264028012967 1.1838759374545673 2.8794709272538253" />
            </geometry>
            <material name="Green">
                <color rgba="0 180.0 0.0 1.0"/>
            </material>
        </visual>
        <collision>
            <origin xyz="0 0 1.4397354636269126" rpy="0 0 0"/>
            <geometry>
                <box size="2.7937264028012967 1.1838759374545673 2.8794709272538253" />
            </geometry>
        </collision>
    </link>
    <link name="Leg24">
        <inertial>
            <origin xyz="0 0 0.747053097789261" rpy="0 0 0"/>
            <mass value="1" />
            <inertia ixx="100" ixy="0" ixz="0" iyy="100" iyz="0" izz="100" />
        </inertial>
        <visual>
            <origin xyz="0 0 0.747053097789261" rpy="0 0 0"/>
            <geometry>
                <box size="2.1209606166015478 1.9829413524889086 1.494106195578522" />
            </geometry>
            <material name="Blue">
                <color rgba="0 1.0 1.0 1.0"/>
            </material>
        </visual>
        <collision>
            <origin xyz="0 0 0.747053097789261" rpy="0 0 0"/>
            <geometry>
                <box size="2.1209606166015478 1.9829413524889086 1.494106195578522" />
            </geometry>
        </collision>
    </link>
    <link name="Leg25">
        <inertial>
            <origin xyz="0 0 0.553044277931433" rpy="0 0 0"/>
            <mass value="1" />
            <inertia ixx="100" ixy="0" ixz="0" iyy="100" iyz="0" izz="100" />
        </inertial>
        <visual>
            <origin xyz="0 0 0.553044277931433" rpy="0 0 0"/>
            <geometry>
                <box size="2.747303657632367 2.080842080918126 1.106088555862866" />
            </geometry>
            <material name="Blue">
                <color rgba="0 1.0 1.0 1.0"/>
            </material>
        </visual>
        <collision>
            <origin xyz="0 0 0.553044277931433" rpy="0 0 0"/>
            <geometry>
                <box size="2.747303657632367 2.080842080918126 1.106088555862866" />
            </geometry>
        </collision>
    </link>
    <link name="Leg26">
        <inertial>
            <origin xyz="0 0 1.2479732662772243" rpy="0 0 0"/>
            <mass value="1" />
            <inertia ixx="100" ixy="0" ixz="0" iyy="100" iyz="0" izz="100" />
        </inertial>
        <visual>
            <origin xyz="0 0 1.2479732662772243" rpy="0 0 0"/>
            <geometry>
                <box size="2.977924014353005 1.4296462490363209 2.4959465325544485" />
            </geometry>
            <material name="Blue">
                <color rgba="0 1.0 1.0 1.0"/>
            </material>
        </visual>
        <collision>
            <origin xyz="0 0 1.2479732662772243" rpy="0 0 0"/>
            <geometry>
                <box size="2.977924014353005 1.4296462490363209 2.4959465325544485" />
            </geometry>
        </collision>
    </link>
    <joint name="Torso_Leg1" type="revolute">
       <parent link="Torso"/>
       <child  link="Leg1"/>
       <origin rpy="0 0 0" xyz="0 0 1.377104017153177" />
     <axis xyz="1 0 0"/>
       <limit effort="0.0" lower="-3.14159" upper="3.14159" velocity="0.0"/>
    </joint>
    <joint name="Torso_Leg2" type="revolute">
       <parent link="Torso"/>
       <child  link="Leg2"/>
       <origin rpy="0 0 0" xyz="1.2610827472801907 0 1.4898582754515597" />
     <axis xyz="1 0 0"/>
       <limit effort="0.0" lower="-3.14159" upper="3.14159" velocity="0.0"/>
    </joint>
    <joint name="Leg1_Leg3" type="revolute">
       <parent link="Leg1"/>
       <child  link="Leg3"/>
       <origin rpy="0 0 0" xyz="1.2219887132179013 0 0.9361478103791268" />
     <axis xyz="1 0 0"/>
       <limit effort="0.0" lower="-3.14159" upper="3.14159" velocity="0.0"/>
    </joint>
    <joint name="Torso_Leg4" type="revolute">
       <parent link="Torso"/>
       <child  link="Leg4"/>
       <origin rpy="0 0 0" xyz="1.2610827472801907 0.5454473937549926 1.4898582754515597" />
     <axis xyz="1 0 0"/>
       <limit effort="0.0" lower="-3.14159" upper="3.14159" velocity="0.0"/>
    </joint>
    <joint name="Leg2_Leg5" type="revolute">
       <parent link="Leg2"/>
       <child  link="Leg5"/>
       <origin rpy="0 0 0" xyz="0 0 1.3961000274907498" />
     <axis xyz="1 0 0"/>
       <limit effort="0.0" lower="-3.14159" upper="3.14159" velocity="0.0"/>
    </joint>
    <joint name="Leg4_Leg6" type="revolute">
       <parent link="Leg4"/>
       <child  link="Leg6"/>
       <origin rpy="0 0 0" xyz="0 0.6904658840577207 0.7421887465365892" />
     <axis xyz="1 0 0"/>
       <limit effort="0.0" lower="-3.14159" upper="3.14159" velocity="0.0"/>
    </joint>
    <joint name="Leg6_Leg7" type="revolute">
       <parent link="Leg6"/>
       <child  link="Leg7"/>
       <origin rpy="0 0 0" xyz="0 2.0281359890066284 0" />
     <axis xyz="1 0 0"/>
       <limit effort="0.0" lower="-3.14159" upper="3.14159" velocity="0.0"/>
    </joint>
    <joint name="Leg7_Leg8" type="revolute">
       <parent link="Leg7"/>
       <child  link="Leg8"/>
       <origin rpy="0 0 0" xyz="2.576200865634334 0 0" />
     <axis xyz="1 0 0"/>
       <limit effort="0.0" lower="-3.14159" upper="3.14159" velocity="0.0"/>
    </joint>
    <joint name="Leg8_Leg9" type="revolute">
       <parent link="Leg8"/>
       <child  link="Leg9"/>
       <origin rpy="0 0 0" xyz="2.7107505568506527 0 0" />
     <axis xyz="1 0 0"/>
       <limit effort="0.0" lower="-3.14159" upper="3.14159" velocity="0.0"/>
    </joint>
    <joint name="Leg3_Leg10" type="revolute">
       <parent link="Leg3"/>
       <child  link="Leg10"/>
       <origin rpy="0 0 0" xyz="0.8563273240283023 1.0302434456462926 0" />
     <axis xyz="1 0 0"/>
       <limit effort="0.0" lower="-3.14159" upper="3.14159" velocity="0.0"/>
    </joint>
    <joint name="Leg6_Leg11" type="revolute">
       <parent link="Leg6"/>
       <child  link="Leg11"/>
       <origin rpy="0 0 0" xyz="0 2.0281359890066284 0.703462035428598" />
     <axis xyz="1 0 0"/>
       <limit effort="0.0" lower="-3.14159" upper="3.14159" velocity="0.0"/>
    </joint>
    <joint name="Leg8_Leg12" type="revolute">
       <parent link="Leg8"/>
       <child  link="Leg12"/>
       <origin rpy="0 0 0" xyz="2.7107505568506527 0 0.6389756871487037" />
     <axis xyz="1 0 0"/>
       <limit effort="0.0" lower="-3.14159" upper="3.14159" velocity="0.0"/>
    </joint>
    <joint name="Leg7_Leg13" type="revolute">
       <parent link="Leg7"/>
       <child  link="Leg13"/>
       <origin rpy="0 0 0" xyz="2.576200865634334 0 0.5608533276466849" />
     <axis xyz="1 0 0"/>
       <limit effort="0.0" lower="-3.14159" upper="3.14159" velocity="0.0"/>
    </joint>
    <joint name="Leg2_Leg14" type="revolute">
       <parent link="Leg2"/>
       <child  link="Leg14"/>
       <origin rpy="0 0 0" xyz="0 0.8336770773322651 1.3961000274907498" />
     <axis xyz="1 0 0"/>
       <limit effort="0.0" lower="-3.14159" upper="3.14159" velocity="0.0"/>
    </joint>
    <joint name="Leg3_Leg15" type="revolute">
       <parent link="Leg3"/>
       <child  link="Leg15"/>
       <origin rpy="0 0 0" xyz="0.8563273240283023 1.0302434456462926 1.2073105970319093" />
     <axis xyz="1 0 0"/>
       <limit effort="0.0" lower="-3.14159" upper="3.14159" velocity="0.0"/>
    </joint>
    <joint name="Leg10_Leg16" type="revolute">
       <parent link="Leg10"/>
       <child  link="Leg16"/>
       <origin rpy="0 0 0" xyz="0.9350474985096553 0 1.356725591237443" />
     <axis xyz="1 0 0"/>
       <limit effort="0.0" lower="-3.14159" upper="3.14159" velocity="0.0"/>
    </joint>
    <joint name="Leg2_Leg17" type="revolute">
       <parent link="Leg2"/>
       <child  link="Leg17"/>
       <origin rpy="0 0 0" xyz="1.3147257941966433 0.8336770773322651 1.3961000274907498" />
     <axis xyz="1 0 0"/>
       <limit effort="0.0" lower="-3.14159" upper="3.14159" velocity="0.0"/>
    </joint>
    <joint name="Leg12_Leg18" type="revolute">
       <parent link="Leg12"/>
       <child  link="Leg18"/>
       <origin rpy="0 0 0" xyz="1.3246198191252252 0 1.4928843734141195" />
     <axis xyz="1 0 0"/>
       <limit effort="0.0" lower="-3.14159" upper="3.14159" velocity="0.0"/>
    </joint>
    <joint name="Leg17_Leg19" type="revolute">
       <parent link="Leg17"/>
       <child  link="Leg19"/>
       <origin rpy="0 0 0" xyz="1.1959571084473937 0 1.3374962628183509" />
     <axis xyz="1 0 0"/>
       <limit effort="0.0" lower="-3.14159" upper="3.14159" velocity="0.0"/>
    </joint>
    <joint name="Leg6_Leg20" type="revolute">
       <parent link="Leg6"/>
       <child  link="Leg20"/>
       <origin rpy="0 0 0" xyz="0.5993268035341484 2.0281359890066284 0.703462035428598" />
     <axis xyz="1 0 0"/>
       <limit effort="0.0" lower="-3.14159" upper="3.14159" velocity="0.0"/>
    </joint>
    <joint name="Leg3_Leg21" type="revolute">
       <parent link="Leg3"/>
       <child  link="Leg21"/>
       <origin rpy="0 0 0" xyz="0.8563273240283023 2.060486891292585 1.2073105970319093" />
     <axis xyz="1 0 0"/>
       <limit effort="0.0" lower="-3.14159" upper="3.14159" velocity="0.0"/>
    </joint>
    <joint name="Leg9_Leg22" type="revolute">
       <parent link="Leg9"/>
       <child  link="Leg22"/>
       <origin rpy="0 0 0" xyz="0.8405751850977393 1.1742828945526698 0" />
     <axis xyz="1 0 0"/>
       <limit effort="0.0" lower="-3.14159" upper="3.14159" velocity="0.0"/>
    </joint>
    <joint name="Leg19_Leg23" type="revolute">
       <parent link="Leg19"/>
       <child  link="Leg23"/>
       <origin rpy="0 0 0" xyz="0.9735832374367335 0 0.7370815844754982" />
     <axis xyz="1 0 0"/>
       <limit effort="0.0" lower="-3.14159" upper="3.14159" velocity="0.0"/>
    </joint>
    <joint name="Leg12_Leg24" type="revolute">
       <parent link="Leg12"/>
       <child  link="Leg24"/>
       <origin rpy="0 0 0" xyz="1.3246198191252252 0 2.985768746828239" />
     <axis xyz="1 0 0"/>
       <limit effort="0.0" lower="-3.14159" upper="3.14159" velocity="0.0"/>
    </joint>
    <joint name="Leg10_Leg25" type="revolute">
       <parent link="Leg10"/>
       <child  link="Leg25"/>
       <origin rpy="0 0 0" xyz="0.9350474985096553 0 2.713451182474886" />
     <axis xyz="1 0 0"/>
       <limit effort="0.0" lower="-3.14159" upper="3.14159" velocity="0.0"/>
    </joint>
    <joint name="Leg22_Leg26" type="revolute">
       <parent link="Leg22"/>
       <child  link="Leg26"/>
       <origin rpy="0 0 0" xyz="0 0 2.8794709272538253" />
     <axis xyz="1 0 0"/>
       <limit effort="0.0" lower="-3.14159" upper="3.14159" velocity="0.0"/>
    </joint>
</robot>