<robot name = "robot">
    <link name="Torso">
        <inertial>
            <origin xyz="0 0 1.2520107538704908" rpy="0 0 0"/>
            <mass value="1" />
            <inertia ixx="100" ixy="0" ixz="0" iyy="100" iyz="0" izz="100" />
        </inertial>
        <visual>
            <origin xyz="0 0 1.2520107538704908" rpy="0 0 0"/>
            <geometry>
                <box size="1.3218280958870665 2.6016091387486187 2.5040215077409815" />
            </geometry>
            <material name="Green">
                <color rgba="0 180.0 0.0 1.0"/>
            </material>
        </visual>
        <collision>
            <origin xyz="0 0 1.2520107538704908" rpy="0 0 0"/>
            <geometry>
                <box size="1.3218280958870665 2.6016091387486187 2.5040215077409815" />
            </geometry>
        </collision>
    </link>
    <link name="Leg1">
        <inertial>
            <origin xyz="1.4642020200144832 0 0" rpy="0 0 0"/>
            <mass value="1" />
            <inertia ixx="100" ixy="0" ixz="0" iyy="100" iyz="0" izz="100" />
        </inertial>
        <visual>
            <origin xyz="1.4642020200144832 0 0" rpy="0 0 0"/>
            <geometry>
                <box size="2.9284040400289664 1.8746206519831101 2.019372653156317" />
            </geometry>
            <material name="Blue">
                <color rgba="0 1.0 1.0 1.0"/>
            </material>
        </visual>
        <collision>
            <origin xyz="1.4642020200144832 0 0" rpy="0 0 0"/>
            <geometry>
                <box size="2.9284040400289664 1.8746206519831101 2.019372653156317" />
            </geometry>
        </collision>
    </link>
    <link name="Leg2">
        <inertial>
            <origin xyz="0.5751495601940027 0 0" rpy="0 0 0"/>
            <mass value="1" />
            <inertia ixx="100" ixy="0" ixz="0" iyy="100" iyz="0" izz="100" />
        </inertial>
        <visual>
            <origin xyz="0.5751495601940027 0 0" rpy="0 0 0"/>
            <geometry>
                <box size="1.1502991203880053 2.0415521393965586 1.369870611130707" />
            </geometry>
            <material name="Green">
                <color rgba="0 180.0 0.0 1.0"/>
            </material>
        </visual>
        <collision>
            <origin xyz="0.5751495601940027 0 0" rpy="0 0 0"/>
            <geometry>
                <box size="1.1502991203880053 2.0415521393965586 1.369870611130707" />
            </geometry>
        </collision>
    </link>
    <link name="Leg3">
        <inertial>
            <origin xyz="0 1.3710586125053148 0" rpy="0 0 0"/>
            <mass value="1" />
            <inertia ixx="100" ixy="0" ixz="0" iyy="100" iyz="0" izz="100" />
        </inertial>
        <visual>
            <origin xyz="0 1.3710586125053148 0" rpy="0 0 0"/>
            <geometry>
                <box size="2.792741270316829 2.7421172250106296 1.0168586515850198" />
            </geometry>
            <material name="Blue">
                <color rgba="0 1.0 1.0 1.0"/>
            </material>
        </visual>
        <collision>
            <origin xyz="0 1.3710586125053148 0" rpy="0 0 0"/>
            <geometry>
                <box size="2.792741270316829 2.7421172250106296 1.0168586515850198" />
            </geometry>
        </collision>
    </link>
    <link name="Leg4">
        <inertial>
            <origin xyz="0 0 1.346232622354786" rpy="0 0 0"/>
            <mass value="1" />
            <inertia ixx="100" ixy="0" ixz="0" iyy="100" iyz="0" izz="100" />
        </inertial>
        <visual>
            <origin xyz="0 0 1.346232622354786" rpy="0 0 0"/>
            <geometry>
                <box size="1.307189630533233 2.556010688328934 2.692465244709572" />
            </geometry>
            <material name="Blue">
                <color rgba="0 1.0 1.0 1.0"/>
            </material>
        </visual>
        <collision>
            <origin xyz="0 0 1.346232622354786" rpy="0 0 0"/>
            <geometry>
                <box size="1.307189630533233 2.556010688328934 2.692465244709572" />
            </geometry>
        </collision>
    </link>
    <link name="Leg5">
        <inertial>
            <origin xyz="0 1.2109408329803835 0" rpy="0 0 0"/>
            <mass value="1" />
            <inertia ixx="100" ixy="0" ixz="0" iyy="100" iyz="0" izz="100" />
        </inertial>
        <visual>
            <origin xyz="0 1.2109408329803835 0" rpy="0 0 0"/>
            <geometry>
                <box size="2.6118173899117942 2.421881665960767 2.6052831533536374" />
            </geometry>
            <material name="Green">
                <color rgba="0 180.0 0.0 1.0"/>
            </material>
        </visual>
        <collision>
            <origin xyz="0 1.2109408329803835 0" rpy="0 0 0"/>
            <geometry>
                <box size="2.6118173899117942 2.421881665960767 2.6052831533536374" />
            </geometry>
        </collision>
    </link>
    <link name="Leg6">
        <inertial>
            <origin xyz="1.3019294035772955 0 0" rpy="0 0 0"/>
            <mass value="1" />
            <inertia ixx="100" ixy="0" ixz="0" iyy="100" iyz="0" izz="100" />
        </inertial>
        <visual>
            <origin xyz="1.3019294035772955 0 0" rpy="0 0 0"/>
            <geometry>
                <box size="2.603858807154591 1.865996687346731 2.5817374771043298" />
            </geometry>
            <material name="Blue">
                <color rgba="0 1.0 1.0 1.0"/>
            </material>
        </visual>
        <collision>
            <origin xyz="1.3019294035772955 0 0" rpy="0 0 0"/>
            <geometry>
                <box size="2.603858807154591 1.865996687346731 2.5817374771043298" />
            </geometry>
        </collision>
    </link>
    <link name="Leg7">
        <inertial>
            <origin xyz="0 0 1.4169787270663394" rpy="0 0 0"/>
            <mass value="1" />
            <inertia ixx="100" ixy="0" ixz="0" iyy="100" iyz="0" izz="100" />
        </inertial>
        <visual>
            <origin xyz="0 0 1.4169787270663394" rpy="0 0 0"/>
            <geometry>
                <box size="2.8540935716303775 1.1936444774316222 2.833957454132679" />
            </geometry>
            <material name="Blue">
                <color rgba="0 1.0 1.0 1.0"/>
            </material>
        </visual>
        <collision>
            <origin xyz="0 0 1.4169787270663394" rpy="0 0 0"/>
            <geometry>
                <box size="2.8540935716303775 1.1936444774316222 2.833957454132679" />
            </geometry>
        </collision>
    </link>
    <link name="Leg8">
        <inertial>
            <origin xyz="0 0.7410290707584486 0" rpy="0 0 0"/>
            <mass value="1" />
            <inertia ixx="100" ixy="0" ixz="0" iyy="100" iyz="0" izz="100" />
        </inertial>
        <visual>
            <origin xyz="0 0.7410290707584486 0" rpy="0 0 0"/>
            <geometry>
                <box size="2.7463268865717194 1.4820581415168972 2.19354199666715" />
            </geometry>
            <material name="Blue">
                <color rgba="0 1.0 1.0 1.0"/>
            </material>
        </visual>
        <collision>
            <origin xyz="0 0.7410290707584486 0" rpy="0 0 0"/>
            <geometry>
                <box size="2.7463268865717194 1.4820581415168972 2.19354199666715" />
            </geometry>
        </collision>
    </link>
    <link name="Leg9">
        <inertial>
            <origin xyz="0 0.6893927099156659 0" rpy="0 0 0"/>
            <mass value="1" />
            <inertia ixx="100" ixy="0" ixz="0" iyy="100" iyz="0" izz="100" />
        </inertial>
        <visual>
            <origin xyz="0 0.6893927099156659 0" rpy="0 0 0"/>
            <geometry>
                <box size="1.6498036591870548 1.3787854198313318 1.1490307216028175" />
            </geometry>
            <material name="Blue">
                <color rgba="0 1.0 1.0 1.0"/>
            </material>
        </visual>
        <collision>
            <origin xyz="0 0.6893927099156659 0" rpy="0 0 0"/>
            <geometry>
                <box size="1.6498036591870548 1.3787854198313318 1.1490307216028175" />
            </geometry>
        </collision>
    </link>
    <link name="Leg10">
        <inertial>
            <origin xyz="0.8115819461308464 0 0" rpy="0 0 0"/>
            <mass value="1" />
            <inertia ixx="100" ixy="0" ixz="0" iyy="100" iyz="0" izz="100" />
        </inertial>
        <visual>
            <origin xyz="0.8115819461308464 0 0" rpy="0 0 0"/>
            <geometry>
                <box size="1.6231638922616929 2.2968023341645063 2.4307929532949677" />
            </geometry>
            <material name="Blue">
                <color rgba="0 1.0 1.0 1.0"/>
            </material>
        </visual>
        <collision>
            <origin xyz="0.8115819461308464 0 0" rpy="0 0 0"/>
            <geometry>
                <box size="1.6231638922616929 2.2968023341645063 2.4307929532949677" />
            </geometry>
        </collision>
    </link>
    <link name="Leg11">
        <inertial>
            <origin xyz="0.9283884164368963 0 0" rpy="0 0 0"/>
            <mass value="1" />
            <inertia ixx="100" ixy="0" ixz="0" iyy="100" iyz="0" izz="100" />
        </inertial>
        <visual>
            <origin xyz="0.9283884164368963 0 0" rpy="0 0 0"/>
            <geometry>
                <box size="1.8567768328737926 1.56737161753977 1.5128135296128782" />
            </geometry>
            <material name="Blue">
                <color rgba="0 1.0 1.0 1.0"/>
            </material>
        </visual>
        <collision>
            <origin xyz="0.9283884164368963 0 0" rpy="0 0 0"/>
            <geometry>
                <box size="1.8567768328737926 1.56737161753977 1.5128135296128782" />
            </geometry>
        </collision>
    </link>
    <link name="Leg12">
        <inertial>
            <origin xyz="0 1.0145986847960131 0" rpy="0 0 0"/>
            <mass value="1" />
            <inertia ixx="100" ixy="0" ixz="0" iyy="100" iyz="0" izz="100" />
        </inertial>
        <visual>
            <origin xyz="0 1.0145986847960131 0" rpy="0 0 0"/>
            <geometry>
                <box size="1.6188441256468245 2.0291973695920262 2.0657474755955425" />
            </geometry>
            <material name="Blue">
                <color rgba="0 1.0 1.0 1.0"/>
            </material>
        </visual>
        <collision>
            <origin xyz="0 1.0145986847960131 0" rpy="0 0 0"/>
            <geometry>
                <box size="1.6188441256468245 2.0291973695920262 2.0657474755955425" />
            </geometry>
        </collision>
    </link>
    <link name="Leg13">
        <inertial>
            <origin xyz="0 1.136903192799025 0" rpy="0 0 0"/>
            <mass value="1" />
            <inertia ixx="100" ixy="0" ixz="0" iyy="100" iyz="0" izz="100" />
        </inertial>
        <visual>
            <origin xyz="0 1.136903192799025 0" rpy="0 0 0"/>
            <geometry>
                <box size="1.1601906827916986 2.27380638559805 2.3794407790889998" />
            </geometry>
            <material name="Blue">
                <color rgba="0 1.0 1.0 1.0"/>
            </material>
        </visual>
        <collision>
            <origin xyz="0 1.136903192799025 0" rpy="0 0 0"/>
            <geometry>
                <box size="1.1601906827916986 2.27380638559805 2.3794407790889998" />
            </geometry>
        </collision>
    </link>
    <link name="Leg14">
        <inertial>
            <origin xyz="0 1.4112469716296208 0" rpy="0 0 0"/>
            <mass value="1" />
            <inertia ixx="100" ixy="0" ixz="0" iyy="100" iyz="0" izz="100" />
        </inertial>
        <visual>
            <origin xyz="0 1.4112469716296208 0" rpy="0 0 0"/>
            <geometry>
                <box size="2.229852331283046 2.8224939432592415 1.3152306723697953" />
            </geometry>
            <material name="Blue">
                <color rgba="0 1.0 1.0 1.0"/>
            </material>
        </visual>
        <collision>
            <origin xyz="0 1.4112469716296208 0" rpy="0 0 0"/>
            <geometry>
                <box size="2.229852331283046 2.8224939432592415 1.3152306723697953" />
            </geometry>
        </collision>
    </link>
    <link name="Leg15">
        <inertial>
            <origin xyz="0 0 1.1036472136227928" rpy="0 0 0"/>
            <mass value="1" />
            <inertia ixx="100" ixy="0" ixz="0" iyy="100" iyz="0" izz="100" />
        </inertial>
        <visual>
            <origin xyz="0 0 1.1036472136227928" rpy="0 0 0"/>
            <geometry>
                <box size="1.5730912714200875 1.9635014690035124 2.2072944272455857" />
            </geometry>
            <material name="Blue">
                <color rgba="0 1.0 1.0 1.0"/>
            </material>
        </visual>
        <collision>
            <origin xyz="0 0 1.1036472136227928" rpy="0 0 0"/>
            <geometry>
                <box size="1.5730912714200875 1.9635014690035124 2.2072944272455857" />
            </geometry>
        </collision>
    </link>
    <link name="Leg16">
        <inertial>
            <origin xyz="0 0.8780748899192811 0" rpy="0 0 0"/>
            <mass value="1" />
            <inertia ixx="100" ixy="0" ixz="0" iyy="100" iyz="0" izz="100" />
        </inertial>
        <visual>
            <origin xyz="0 0.8780748899192811 0" rpy="0 0 0"/>
            <geometry>
                <box size="1.110820294326006 1.7561497798385621 1.5999978823808683" />
            </geometry>
            <material name="Green">
                <color rgba="0 180.0 0.0 1.0"/>
            </material>
        </visual>
        <collision>
            <origin xyz="0 0.8780748899192811 0" rpy="0 0 0"/>
            <geometry>
                <box size="1.110820294326006 1.7561497798385621 1.5999978823808683" />
            </geometry>
        </collision>
    </link>
    <link name="Leg17">
        <inertial>
            <origin xyz="0 0 0.5553032460314934" rpy="0 0 0"/>
            <mass value="1" />
            <inertia ixx="100" ixy="0" ixz="0" iyy="100" iyz="0" izz="100" />
        </inertial>
        <visual>
            <origin xyz="0 0 0.5553032460314934" rpy="0 0 0"/>
            <geometry>
                <box size="2.2166899023448066 1.8905536951914121 1.1106064920629868" />
            </geometry>
            <material name="Blue">
                <color rgba="0 1.0 1.0 1.0"/>
            </material>
        </visual>
        <collision>
            <origin xyz="0 0 0.5553032460314934" rpy="0 0 0"/>
            <geometry>
                <box size="2.2166899023448066 1.8905536951914121 1.1106064920629868" />
            </geometry>
        </collision>
    </link>
    <link name="Leg18">
        <inertial>
            <origin xyz="0 0 1.4752864148579148" rpy="0 0 0"/>
            <mass value="1" />
            <inertia ixx="100" ixy="0" ixz="0" iyy="100" iyz="0" izz="100" />
        </inertial>
        <visual>
            <origin xyz="0 0 1.4752864148579148" rpy="0 0 0"/>
            <geometry>
                <box size="1.0015626923017533 1.110818969623323 2.9505728297158296" />
            </geometry>
            <material name="Green">
                <color rgba="0 180.0 0.0 1.0"/>
            </material>
        </visual>
        <collision>
            <origin xyz="0 0 1.4752864148579148" rpy="0 0 0"/>
            <geometry>
                <box size="1.0015626923017533 1.110818969623323 2.9505728297158296" />
            </geometry>
        </collision>
    </link>
    <link name="Leg19">
        <inertial>
            <origin xyz="0.6650549660425055 0 0" rpy="0 0 0"/>
            <mass value="1" />
            <inertia ixx="100" ixy="0" ixz="0" iyy="100" iyz="0" izz="100" />
        </inertial>
        <visual>
            <origin xyz="0.6650549660425055 0 0" rpy="0 0 0"/>
            <geometry>
                <box size="1.330109932085011 1.8206310828090988 2.90610884883044" />
            </geometry>
            <material name="Green">
                <color rgba="0 180.0 0.0 1.0"/>
            </material>
        </visual>
        <collision>
            <origin xyz="0.6650549660425055 0 0" rpy="0 0 0"/>
            <geometry>
                <box size="1.330109932085011 1.8206310828090988 2.90610884883044" />
            </geometry>
        </collision>
    </link>
    <link name="Leg20">
        <inertial>
            <origin xyz="0.6585302093027166 0 0" rpy="0 0 0"/>
            <mass value="1" />
            <inertia ixx="100" ixy="0" ixz="0" iyy="100" iyz="0" izz="100" />
        </inertial>
        <visual>
            <origin xyz="0.6585302093027166 0 0" rpy="0 0 0"/>
            <geometry>
                <box size="1.317060418605433 1.5613814632155707 1.7962534188741723" />
            </geometry>
            <material name="Green">
                <color rgba="0 180.0 0.0 1.0"/>
            </material>
        </visual>
        <collision>
            <origin xyz="0.6585302093027166 0 0" rpy="0 0 0"/>
            <geometry>
                <box size="1.317060418605433 1.5613814632155707 1.7962534188741723" />
            </geometry>
        </collision>
    </link>
    <link name="Leg21">
        <inertial>
            <origin xyz="0 0 0.81795562899314" rpy="0 0 0"/>
            <mass value="1" />
            <inertia ixx="100" ixy="0" ixz="0" iyy="100" iyz="0" izz="100" />
        </inertial>
        <visual>
            <origin xyz="0 0 0.81795562899314" rpy="0 0 0"/>
            <geometry>
                <box size="1.7101725893930428 1.6243810753665238 1.63591125798628" />
            </geometry>
            <material name="Green">
                <color rgba="0 180.0 0.0 1.0"/>
            </material>
        </visual>
        <collision>
            <origin xyz="0 0 0.81795562899314" rpy="0 0 0"/>
            <geometry>
                <box size="1.7101725893930428 1.6243810753665238 1.63591125798628" />
            </geometry>
        </collision>
    </link>
    <link name="Leg22">
        <inertial>
            <origin xyz="0.5679561763049215 0 0" rpy="0 0 0"/>
            <mass value="1" />
            <inertia ixx="100" ixy="0" ixz="0" iyy="100" iyz="0" izz="100" />
        </inertial>
        <visual>
            <origin xyz="0.5679561763049215 0 0" rpy="0 0 0"/>
            <geometry>
                <box size="1.135912352609843 2.653366120552199 1.321058794582266" />
            </geometry>
            <material name="Green">
                <color rgba="0 180.0 0.0 1.0"/>
            </material>
        </visual>
        <collision>
            <origin xyz="0.5679561763049215 0 0" rpy="0 0 0"/>
            <geometry>
                <box size="1.135912352609843 2.653366120552199 1.321058794582266" />
            </geometry>
        </collision>
    </link>
    <link name="Leg23">
        <inertial>
            <origin xyz="0.9642731960149236 0 0" rpy="0 0 0"/>
            <mass value="1" />
            <inertia ixx="100" ixy="0" ixz="0" iyy="100" iyz="0" izz="100" />
        </inertial>
        <visual>
            <origin xyz="0.9642731960149236 0 0" rpy="0 0 0"/>
            <geometry>
                <box size="1.9285463920298471 1.170589502905717 2.7875688708913753" />
            </geometry>
            <material name="Green">
                <color rgba="0 180.0 0.0 1.0"/>
            </material>
        </visual>
        <collision>
            <origin xyz="0.9642731960149236 0 0" rpy="0 0 0"/>
            <geometry>
                <box size="1.9285463920298471 1.170589502905717 2.7875688708913753" />
            </geometry>
        </collision>
    </link>
    <link name="Leg24">
        <inertial>
            <origin xyz="1.08069750055418 0 0" rpy="0 0 0"/>
            <mass value="1" />
            <inertia ixx="100" ixy="0" ixz="0" iyy="100" iyz="0" izz="100" />
        </inertial>
        <visual>
            <origin xyz="1.08069750055418 0 0" rpy="0 0 0"/>
            <geometry>
                <box size="2.16139500110836 2.7747182172253524 1.418906195890696" />
            </geometry>
            <material name="Green">
                <color rgba="0 180.0 0.0 1.0"/>
            </material>
        </visual>
        <collision>
            <origin xyz="1.08069750055418 0 0" rpy="0 0 0"/>
            <geometry>
                <box size="2.16139500110836 2.7747182172253524 1.418906195890696" />
            </geometry>
        </collision>
    </link>
    <link name="Leg25">
        <inertial>
            <origin xyz="0 0.9982353369847895 0" rpy="0 0 0"/>
            <mass value="1" />
            <inertia ixx="100" ixy="0" ixz="0" iyy="100" iyz="0" izz="100" />
        </inertial>
        <visual>
            <origin xyz="0 0.9982353369847895 0" rpy="0 0 0"/>
            <geometry>
                <box size="1.6790781942824764 1.996470673969579 1.4803739507207876" />
            </geometry>
            <material name="Green">
                <color rgba="0 180.0 0.0 1.0"/>
            </material>
        </visual>
        <collision>
            <origin xyz="0 0.9982353369847895 0" rpy="0 0 0"/>
            <geometry>
                <box size="1.6790781942824764 1.996470673969579 1.4803739507207876" />
            </geometry>
        </collision>
    </link>
    <link name="Leg26">
        <inertial>
            <origin xyz="1.3345494060683671 0 0" rpy="0 0 0"/>
            <mass value="1" />
            <inertia ixx="100" ixy="0" ixz="0" iyy="100" iyz="0" izz="100" />
        </inertial>
        <visual>
            <origin xyz="1.3345494060683671 0 0" rpy="0 0 0"/>
            <geometry>
                <box size="2.6690988121367343 1.2443419518779524 1.210603850527685" />
            </geometry>
            <material name="Blue">
                <color rgba="0 1.0 1.0 1.0"/>
            </material>
        </visual>
        <collision>
            <origin xyz="1.3345494060683671 0 0" rpy="0 0 0"/>
            <geometry>
                <box size="2.6690988121367343 1.2443419518779524 1.210603850527685" />
            </geometry>
        </collision>
    </link>
    <link name="Leg27">
        <inertial>
            <origin xyz="0 0 0.9130698707126934" rpy="0 0 0"/>
            <mass value="1" />
            <inertia ixx="100" ixy="0" ixz="0" iyy="100" iyz="0" izz="100" />
        </inertial>
        <visual>
            <origin xyz="0 0 0.9130698707126934" rpy="0 0 0"/>
            <geometry>
                <box size="2.0721786251935086 1.2425205140755944 1.8261397414253868" />
            </geometry>
            <material name="Green">
                <color rgba="0 180.0 0.0 1.0"/>
            </material>
        </visual>
        <collision>
            <origin xyz="0 0 0.9130698707126934" rpy="0 0 0"/>
            <geometry>
                <box size="2.0721786251935086 1.2425205140755944 1.8261397414253868" />
            </geometry>
        </collision>
    </link>
    <link name="Leg28">
        <inertial>
            <origin xyz="0 0 1.3117196591425677" rpy="0 0 0"/>
            <mass value="1" />
            <inertia ixx="100" ixy="0" ixz="0" iyy="100" iyz="0" izz="100" />
        </inertial>
        <visual>
            <origin xyz="0 0 1.3117196591425677" rpy="0 0 0"/>
            <geometry>
                <box size="2.076960780808127 1.2647795346643627 2.6234393182851354" />
            </geometry>
            <material name="Green">
                <color rgba="0 180.0 0.0 1.0"/>
            </material>
        </visual>
        <collision>
            <origin xyz="0 0 1.3117196591425677" rpy="0 0 0"/>
            <geometry>
                <box size="2.076960780808127 1.2647795346643627 2.6234393182851354" />
            </geometry>
        </collision>
    </link>
    <joint name="Torso_Leg1" type="revolute">
       <parent link="Torso"/>
       <child  link="Leg1"/>
       <origin rpy="0 0 0" xyz="0.6609140479435333 0 1.2520107538704908" />
     <axis xyz="1 0 0"/>
       <limit effort="0.0" lower="-3.14159" upper="3.14159" velocity="0.0"/>
    </joint>
    <joint name="Leg1_Leg2" type="revolute">
       <parent link="Leg1"/>
       <child  link="Leg2"/>
       <origin rpy="0 0 0" xyz="1.1502991203880053 0 0" />
     <axis xyz="1 0 0"/>
       <limit effort="0.0" lower="-3.14159" upper="3.14159" velocity="0.0"/>
    </joint>
    <joint name="Leg1_Leg3" type="revolute">
       <parent link="Leg1"/>
       <child  link="Leg3"/>
       <origin rpy="0 0 0" xyz="1.1502991203880053 1.0207760696982793 0" />
     <axis xyz="1 0 0"/>
       <limit effort="0.0" lower="-3.14159" upper="3.14159" velocity="0.0"/>
    </joint>
    <joint name="Torso_Leg4" type="revolute">
       <parent link="Torso"/>
       <child  link="Leg4"/>
       <origin rpy="0 0 0" xyz="1.4642020200144832 0 1.0096863265781586" />
     <axis xyz="1 0 0"/>
       <limit effort="0.0" lower="-3.14159" upper="3.14159" velocity="0.0"/>
    </joint>
    <joint name="Torso_Leg5" type="revolute">
       <parent link="Torso"/>
       <child  link="Leg5"/>
       <origin rpy="0 0 0" xyz="1.4642020200144832 0.9373103259915551 1.0096863265781586" />
     <axis xyz="1 0 0"/>
       <limit effort="0.0" lower="-3.14159" upper="3.14159" velocity="0.0"/>
    </joint>
    <joint name="Leg5_Leg6" type="revolute">
       <parent link="Leg5"/>
       <child  link="Leg6"/>
       <origin rpy="0 0 0" xyz="2.603858807154591 0 0" />
     <axis xyz="1 0 0"/>
       <limit effort="0.0" lower="-3.14159" upper="3.14159" velocity="0.0"/>
    </joint>
    <joint name="Leg3_Leg7" type="revolute">
       <parent link="Leg3"/>
       <child  link="Leg7"/>
       <origin rpy="0 0 0" xyz="0 0 2.692465244709572" />
     <axis xyz="1 0 0"/>
       <limit effort="0.0" lower="-3.14159" upper="3.14159" velocity="0.0"/>
    </joint>
    <joint name="Leg6_Leg8" type="revolute">
       <parent link="Leg6"/>
       <child  link="Leg8"/>
       <origin rpy="0 0 0" xyz="0 0.5968222387158111 1.4169787270663394" />
     <axis xyz="1 0 0"/>
       <limit effort="0.0" lower="-3.14159" upper="3.14159" velocity="0.0"/>
    </joint>
    <joint name="Leg5_Leg9" type="revolute">
       <parent link="Leg5"/>
       <child  link="Leg9"/>
       <origin rpy="0 0 0" xyz="2.603858807154591 0.9329983436733655 0" />
     <axis xyz="1 0 0"/>
       <limit effort="0.0" lower="-3.14159" upper="3.14159" velocity="0.0"/>
    </joint>
    <joint name="Leg2_Leg10" type="revolute">
       <parent link="Leg2"/>
       <child  link="Leg10"/>
       <origin rpy="0 0 0" xyz="1.3963706351584144 1.3710586125053148 0" />
     <axis xyz="1 0 0"/>
       <limit effort="0.0" lower="-3.14159" upper="3.14159" velocity="0.0"/>
    </joint>
    <joint name="Leg7_Leg11" type="revolute">
       <parent link="Leg7"/>
       <child  link="Leg11"/>
       <origin rpy="0 0 0" xyz="1.3731634432858597 0.7410290707584486 0" />
     <axis xyz="1 0 0"/>
       <limit effort="0.0" lower="-3.14159" upper="3.14159" velocity="0.0"/>
    </joint>
    <joint name="Leg4_Leg12" type="revolute">
       <parent link="Leg4"/>
       <child  link="Leg12"/>
       <origin rpy="0 0 0" xyz="0 2.421881665960767 0" />
     <axis xyz="1 0 0"/>
       <limit effort="0.0" lower="-3.14159" upper="3.14159" velocity="0.0"/>
    </joint>
    <joint name="Leg11_Leg13" type="revolute">
       <parent link="Leg11"/>
       <child  link="Leg13"/>
       <origin rpy="0 0 0" xyz="0 2.0291973695920262 0" />
     <axis xyz="1 0 0"/>
       <limit effort="0.0" lower="-3.14159" upper="3.14159" velocity="0.0"/>
    </joint>
    <joint name="Leg2_Leg14" type="revolute">
       <parent link="Leg2"/>
       <child  link="Leg14"/>
       <origin rpy="0 0 0" xyz="1.3963706351584144 2.7421172250106296 0" />
     <axis xyz="1 0 0"/>
       <limit effort="0.0" lower="-3.14159" upper="3.14159" velocity="0.0"/>
    </joint>
    <joint name="Leg11_Leg15" type="revolute">
       <parent link="Leg11"/>
       <child  link="Leg15"/>
       <origin rpy="0 0 0" xyz="0 2.0291973695920262 1.0328737377977713" />
     <axis xyz="1 0 0"/>
       <limit effort="0.0" lower="-3.14159" upper="3.14159" velocity="0.0"/>
    </joint>
    <joint name="Leg14_Leg16" type="revolute">
       <parent link="Leg14"/>
       <child  link="Leg16"/>
       <origin rpy="0 0 0" xyz="0 0.9817507345017562 1.1036472136227928" />
     <axis xyz="1 0 0"/>
       <limit effort="0.0" lower="-3.14159" upper="3.14159" velocity="0.0"/>
    </joint>
    <joint name="Leg7_Leg17" type="revolute">
       <parent link="Leg7"/>
       <child  link="Leg17"/>
       <origin rpy="0 0 0" xyz="1.3731634432858597 0.7410290707584486 1.096770998333575" />
     <axis xyz="1 0 0"/>
       <limit effort="0.0" lower="-3.14159" upper="3.14159" velocity="0.0"/>
    </joint>
    <joint name="Leg15_Leg18" type="revolute">
       <parent link="Leg15"/>
       <child  link="Leg18"/>
       <origin rpy="0 0 0" xyz="0 0.8780748899192811 0.7999989411904341" />
     <axis xyz="1 0 0"/>
       <limit effort="0.0" lower="-3.14159" upper="3.14159" velocity="0.0"/>
    </joint>
    <joint name="Leg4_Leg19" type="revolute">
       <parent link="Leg4"/>
       <child  link="Leg19"/>
       <origin rpy="0 0 0" xyz="1.3059086949558971 2.421881665960767 0" />
     <axis xyz="1 0 0"/>
       <limit effort="0.0" lower="-3.14159" upper="3.14159" velocity="0.0"/>
    </joint>
    <joint name="Leg17_Leg20" type="revolute">
       <parent link="Leg17"/>
       <child  link="Leg20"/>
       <origin rpy="0 0 0" xyz="0.5007813461508767 0 1.4752864148579148" />
     <axis xyz="1 0 0"/>
       <limit effort="0.0" lower="-3.14159" upper="3.14159" velocity="0.0"/>
    </joint>
    <joint name="Leg4_Leg21" type="revolute">
       <parent link="Leg4"/>
       <child  link="Leg21"/>
       <origin rpy="0 0 0" xyz="1.3059086949558971 2.421881665960767 1.3026415766768187" />
     <axis xyz="1 0 0"/>
       <limit effort="0.0" lower="-3.14159" upper="3.14159" velocity="0.0"/>
    </joint>
    <joint name="Leg18_Leg22" type="revolute">
       <parent link="Leg18"/>
       <child  link="Leg22"/>
       <origin rpy="0 0 0" xyz="1.330109932085011 0 0" />
     <axis xyz="1 0 0"/>
       <limit effort="0.0" lower="-3.14159" upper="3.14159" velocity="0.0"/>
    </joint>
    <joint name="Leg22_Leg23" type="revolute">
       <parent link="Leg22"/>
       <child  link="Leg23"/>
       <origin rpy="0 0 0" xyz="1.9285463920298471 0 0" />
     <axis xyz="1 0 0"/>
       <limit effort="0.0" lower="-3.14159" upper="3.14159" velocity="0.0"/>
    </joint>
    <joint name="Leg9_Leg24" type="revolute">
       <parent link="Leg9"/>
       <child  link="Leg24"/>
       <origin rpy="0 0 0" xyz="1.6231638922616929 0 0" />
     <axis xyz="1 0 0"/>
       <limit effort="0.0" lower="-3.14159" upper="3.14159" velocity="0.0"/>
    </joint>
    <joint name="Leg16_Leg25" type="revolute">
       <parent link="Leg16"/>
       <child  link="Leg25"/>
       <origin rpy="0 0 0" xyz="0 0.9452768475957061 0.5553032460314934" />
     <axis xyz="1 0 0"/>
       <limit effort="0.0" lower="-3.14159" upper="3.14159" velocity="0.0"/>
    </joint>
    <joint name="Leg14_Leg26" type="revolute">
       <parent link="Leg14"/>
       <child  link="Leg26"/>
       <origin rpy="0 0 0" xyz="0.7865456357100438 0.9817507345017562 1.1036472136227928" />
     <axis xyz="1 0 0"/>
       <limit effort="0.0" lower="-3.14159" upper="3.14159" velocity="0.0"/>
    </joint>
    <joint name="Leg1_Leg27" type="revolute">
       <parent link="Leg1"/>
       <child  link="Leg27"/>
       <origin rpy="0 0 0" xyz="1.1502991203880053 1.0207760696982793 0.6849353055653535" />
     <axis xyz="1 0 0"/>
       <limit effort="0.0" lower="-3.14159" upper="3.14159" velocity="0.0"/>
    </joint>
    <joint name="Leg27_Leg28" type="revolute">
       <parent link="Leg27"/>
       <child  link="Leg28"/>
       <origin rpy="0 0 0" xyz="0 0 2.6234393182851354" />
     <axis xyz="1 0 0"/>
       <limit effort="0.0" lower="-3.14159" upper="3.14159" velocity="0.0"/>
    </joint>
</robot>