<robot name = "robot">
    <link name="Torso">
        <inertial>
            <origin xyz="0 0 1.012356185013994" rpy="0 0 0"/>
            <mass value="1" />
            <inertia ixx="100" ixy="0" ixz="0" iyy="100" iyz="0" izz="100" />
        </inertial>
        <visual>
            <origin xyz="0 0 1.012356185013994" rpy="0 0 0"/>
            <geometry>
                <box size="2.1718971977901775 2.4592669993346243 2.024712370027988" />
            </geometry>
            <material name="Green">
                <color rgba="0 180.0 0.0 1.0"/>
            </material>
        </visual>
        <collision>
            <origin xyz="0 0 1.012356185013994" rpy="0 0 0"/>
            <geometry>
                <box size="2.1718971977901775 2.4592669993346243 2.024712370027988" />
            </geometry>
        </collision>
    </link>
    <link name="Leg1">
        <inertial>
            <origin xyz="0.7126354529801938 0 0" rpy="0 0 0"/>
            <mass value="1" />
            <inertia ixx="100" ixy="0" ixz="0" iyy="100" iyz="0" izz="100" />
        </inertial>
        <visual>
            <origin xyz="0.7126354529801938 0 0" rpy="0 0 0"/>
            <geometry>
                <box size="1.4252709059603876 1.2690761703900941 2.6321771166970134" />
            </geometry>
            <material name="Blue">
                <color rgba="0 1.0 1.0 1.0"/>
            </material>
        </visual>
        <collision>
            <origin xyz="0.7126354529801938 0 0" rpy="0 0 0"/>
            <geometry>
                <box size="1.4252709059603876 1.2690761703900941 2.6321771166970134" />
            </geometry>
        </collision>
    </link>
    <link name="Leg2">
        <inertial>
            <origin xyz="0 0.5232140579528745 0" rpy="0 0 0"/>
            <mass value="1" />
            <inertia ixx="100" ixy="0" ixz="0" iyy="100" iyz="0" izz="100" />
        </inertial>
        <visual>
            <origin xyz="0 0.5232140579528745 0" rpy="0 0 0"/>
            <geometry>
                <box size="1.2212823327992202 1.046428115905749 2.110184180010218" />
            </geometry>
            <material name="Green">
                <color rgba="0 180.0 0.0 1.0"/>
            </material>
        </visual>
        <collision>
            <origin xyz="0 0.5232140579528745 0" rpy="0 0 0"/>
            <geometry>
                <box size="1.2212823327992202 1.046428115905749 2.110184180010218" />
            </geometry>
        </collision>
    </link>
    <link name="Leg3">
        <inertial>
            <origin xyz="1.037944980686318 0 0" rpy="0 0 0"/>
            <mass value="1" />
            <inertia ixx="100" ixy="0" ixz="0" iyy="100" iyz="0" izz="100" />
        </inertial>
        <visual>
            <origin xyz="1.037944980686318 0 0" rpy="0 0 0"/>
            <geometry>
                <box size="2.075889961372636 1.1120988012414679 2.9340051046757405" />
            </geometry>
            <material name="Green">
                <color rgba="0 180.0 0.0 1.0"/>
            </material>
        </visual>
        <collision>
            <origin xyz="1.037944980686318 0 0" rpy="0 0 0"/>
            <geometry>
                <box size="2.075889961372636 1.1120988012414679 2.9340051046757405" />
            </geometry>
        </collision>
    </link>
    <link name="Leg4">
        <inertial>
            <origin xyz="0 0.5885643618422932 0" rpy="0 0 0"/>
            <mass value="1" />
            <inertia ixx="100" ixy="0" ixz="0" iyy="100" iyz="0" izz="100" />
        </inertial>
        <visual>
            <origin xyz="0 0.5885643618422932 0" rpy="0 0 0"/>
            <geometry>
                <box size="2.3228982709186425 1.1771287236845864 2.9735949727267963" />
            </geometry>
            <material name="Green">
                <color rgba="0 180.0 0.0 1.0"/>
            </material>
        </visual>
        <collision>
            <origin xyz="0 0.5885643618422932 0" rpy="0 0 0"/>
            <geometry>
                <box size="2.3228982709186425 1.1771287236845864 2.9735949727267963" />
            </geometry>
        </collision>
    </link>
    <link name="Leg5">
        <inertial>
            <origin xyz="0 0 0.75598383640597" rpy="0 0 0"/>
            <mass value="1" />
            <inertia ixx="100" ixy="0" ixz="0" iyy="100" iyz="0" izz="100" />
        </inertial>
        <visual>
            <origin xyz="0 0 0.75598383640597" rpy="0 0 0"/>
            <geometry>
                <box size="1.4284167606266807 1.3391069952824903 1.51196767281194" />
            </geometry>
            <material name="Green">
                <color rgba="0 180.0 0.0 1.0"/>
            </material>
        </visual>
        <collision>
            <origin xyz="0 0 0.75598383640597" rpy="0 0 0"/>
            <geometry>
                <box size="1.4284167606266807 1.3391069952824903 1.51196767281194" />
            </geometry>
        </collision>
    </link>
    <link name="Leg6">
        <inertial>
            <origin xyz="0 1.0312764059523187 0" rpy="0 0 0"/>
            <mass value="1" />
            <inertia ixx="100" ixy="0" ixz="0" iyy="100" iyz="0" izz="100" />
        </inertial>
        <visual>
            <origin xyz="0 1.0312764059523187 0" rpy="0 0 0"/>
            <geometry>
                <box size="1.734048137203825 2.0625528119046375 2.162589006725329" />
            </geometry>
            <material name="Green">
                <color rgba="0 180.0 0.0 1.0"/>
            </material>
        </visual>
        <collision>
            <origin xyz="0 1.0312764059523187 0" rpy="0 0 0"/>
            <geometry>
                <box size="1.734048137203825 2.0625528119046375 2.162589006725329" />
            </geometry>
        </collision>
    </link>
    <link name="Leg7">
        <inertial>
            <origin xyz="1.1527851517278345 0 0" rpy="0 0 0"/>
            <mass value="1" />
            <inertia ixx="100" ixy="0" ixz="0" iyy="100" iyz="0" izz="100" />
        </inertial>
        <visual>
            <origin xyz="1.1527851517278345 0 0" rpy="0 0 0"/>
            <geometry>
                <box size="2.305570303455669 1.0543890582340003 1.0039835465852454" />
            </geometry>
            <material name="Blue">
                <color rgba="0 1.0 1.0 1.0"/>
            </material>
        </visual>
        <collision>
            <origin xyz="1.1527851517278345 0 0" rpy="0 0 0"/>
            <geometry>
                <box size="2.305570303455669 1.0543890582340003 1.0039835465852454" />
            </geometry>
        </collision>
    </link>
    <link name="Leg8">
        <inertial>
            <origin xyz="1.3023436512048465 0 0" rpy="0 0 0"/>
            <mass value="1" />
            <inertia ixx="100" ixy="0" ixz="0" iyy="100" iyz="0" izz="100" />
        </inertial>
        <visual>
            <origin xyz="1.3023436512048465 0 0" rpy="0 0 0"/>
            <geometry>
                <box size="2.604687302409693 1.483588262210135 2.78958279780232" />
            </geometry>
            <material name="Blue">
                <color rgba="0 1.0 1.0 1.0"/>
            </material>
        </visual>
        <collision>
            <origin xyz="1.3023436512048465 0 0" rpy="0 0 0"/>
            <geometry>
                <box size="2.604687302409693 1.483588262210135 2.78958279780232" />
            </geometry>
        </collision>
    </link>
    <link name="Leg9">
        <inertial>
            <origin xyz="1.4484215411452033 0 0" rpy="0 0 0"/>
            <mass value="1" />
            <inertia ixx="100" ixy="0" ixz="0" iyy="100" iyz="0" izz="100" />
        </inertial>
        <visual>
            <origin xyz="1.4484215411452033 0 0" rpy="0 0 0"/>
            <geometry>
                <box size="2.8968430822904065 1.2155656525836227 1.172911428756295" />
            </geometry>
            <material name="Green">
                <color rgba="0 180.0 0.0 1.0"/>
            </material>
        </visual>
        <collision>
            <origin xyz="1.4484215411452033 0 0" rpy="0 0 0"/>
            <geometry>
                <box size="2.8968430822904065 1.2155656525836227 1.172911428756295" />
            </geometry>
        </collision>
    </link>
    <link name="Leg10">
        <inertial>
            <origin xyz="1.3434982940907911 0 0" rpy="0 0 0"/>
            <mass value="1" />
            <inertia ixx="100" ixy="0" ixz="0" iyy="100" iyz="0" izz="100" />
        </inertial>
        <visual>
            <origin xyz="1.3434982940907911 0 0" rpy="0 0 0"/>
            <geometry>
                <box size="2.6869965881815823 2.4771198827731284 1.3319334470150848" />
            </geometry>
            <material name="Green">
                <color rgba="0 180.0 0.0 1.0"/>
            </material>
        </visual>
        <collision>
            <origin xyz="1.3434982940907911 0 0" rpy="0 0 0"/>
            <geometry>
                <box size="2.6869965881815823 2.4771198827731284 1.3319334470150848" />
            </geometry>
        </collision>
    </link>
    <link name="Leg11">
        <inertial>
            <origin xyz="0 0 1.410216848295954" rpy="0 0 0"/>
            <mass value="1" />
            <inertia ixx="100" ixy="0" ixz="0" iyy="100" iyz="0" izz="100" />
        </inertial>
        <visual>
            <origin xyz="0 0 1.410216848295954" rpy="0 0 0"/>
            <geometry>
                <box size="1.1667803868588091 1.9108528854696019 2.820433696591908" />
            </geometry>
            <material name="Green">
                <color rgba="0 180.0 0.0 1.0"/>
            </material>
        </visual>
        <collision>
            <origin xyz="0 0 1.410216848295954" rpy="0 0 0"/>
            <geometry>
                <box size="1.1667803868588091 1.9108528854696019 2.820433696591908" />
            </geometry>
        </collision>
    </link>
    <link name="Leg12">
        <inertial>
            <origin xyz="0 0 1.3857094031401391" rpy="0 0 0"/>
            <mass value="1" />
            <inertia ixx="100" ixy="0" ixz="0" iyy="100" iyz="0" izz="100" />
        </inertial>
        <visual>
            <origin xyz="0 0 1.3857094031401391" rpy="0 0 0"/>
            <geometry>
                <box size="1.6817408742926794 1.2404239995675956 2.7714188062802783" />
            </geometry>
            <material name="Green">
                <color rgba="0 180.0 0.0 1.0"/>
            </material>
        </visual>
        <collision>
            <origin xyz="0 0 1.3857094031401391" rpy="0 0 0"/>
            <geometry>
                <box size="1.6817408742926794 1.2404239995675956 2.7714188062802783" />
            </geometry>
        </collision>
    </link>
    <link name="Leg13">
        <inertial>
            <origin xyz="1.1994345091154281 0 0" rpy="0 0 0"/>
            <mass value="1" />
            <inertia ixx="100" ixy="0" ixz="0" iyy="100" iyz="0" izz="100" />
        </inertial>
        <visual>
            <origin xyz="1.1994345091154281 0 0" rpy="0 0 0"/>
            <geometry>
                <box size="2.3988690182308563 1.032314940568237 1.0701999993278133" />
            </geometry>
            <material name="Green">
                <color rgba="0 180.0 0.0 1.0"/>
            </material>
        </visual>
        <collision>
            <origin xyz="1.1994345091154281 0 0" rpy="0 0 0"/>
            <geometry>
                <box size="2.3988690182308563 1.032314940568237 1.0701999993278133" />
            </geometry>
        </collision>
    </link>
    <link name="Leg14">
        <inertial>
            <origin xyz="0 0 0.6694001618623696" rpy="0 0 0"/>
            <mass value="1" />
            <inertia ixx="100" ixy="0" ixz="0" iyy="100" iyz="0" izz="100" />
        </inertial>
        <visual>
            <origin xyz="0 0 0.6694001618623696" rpy="0 0 0"/>
            <geometry>
                <box size="2.6561822147153387 2.946269029839132 1.3388003237247392" />
            </geometry>
            <material name="Blue">
                <color rgba="0 1.0 1.0 1.0"/>
            </material>
        </visual>
        <collision>
            <origin xyz="0 0 0.6694001618623696" rpy="0 0 0"/>
            <geometry>
                <box size="2.6561822147153387 2.946269029839132 1.3388003237247392" />
            </geometry>
        </collision>
    </link>
    <link name="Leg15">
        <inertial>
            <origin xyz="0 0.544750286968729 0" rpy="0 0 0"/>
            <mass value="1" />
            <inertia ixx="100" ixy="0" ixz="0" iyy="100" iyz="0" izz="100" />
        </inertial>
        <visual>
            <origin xyz="0 0.544750286968729 0" rpy="0 0 0"/>
            <geometry>
                <box size="1.6336025865872648 1.089500573937458 1.8161603260045696" />
            </geometry>
            <material name="Green">
                <color rgba="0 180.0 0.0 1.0"/>
            </material>
        </visual>
        <collision>
            <origin xyz="0 0.544750286968729 0" rpy="0 0 0"/>
            <geometry>
                <box size="1.6336025865872648 1.089500573937458 1.8161603260045696" />
            </geometry>
        </collision>
    </link>
    <link name="Leg16">
        <inertial>
            <origin xyz="0 0.5490028552939875 0" rpy="0 0 0"/>
            <mass value="1" />
            <inertia ixx="100" ixy="0" ixz="0" iyy="100" iyz="0" izz="100" />
        </inertial>
        <visual>
            <origin xyz="0 0.5490028552939875 0" rpy="0 0 0"/>
            <geometry>
                <box size="2.867141962736871 1.098005710587975 1.453805284093293" />
            </geometry>
            <material name="Green">
                <color rgba="0 180.0 0.0 1.0"/>
            </material>
        </visual>
        <collision>
            <origin xyz="0 0.5490028552939875 0" rpy="0 0 0"/>
            <geometry>
                <box size="2.867141962736871 1.098005710587975 1.453805284093293" />
            </geometry>
        </collision>
    </link>
    <link name="Leg17">
        <inertial>
            <origin xyz="0 1.0667552581835007 0" rpy="0 0 0"/>
            <mass value="1" />
            <inertia ixx="100" ixy="0" ixz="0" iyy="100" iyz="0" izz="100" />
        </inertial>
        <visual>
            <origin xyz="0 1.0667552581835007 0" rpy="0 0 0"/>
            <geometry>
                <box size="1.5255397216994275 2.1335105163670014 2.6358144534038828" />
            </geometry>
            <material name="Blue">
                <color rgba="0 1.0 1.0 1.0"/>
            </material>
        </visual>
        <collision>
            <origin xyz="0 1.0667552581835007 0" rpy="0 0 0"/>
            <geometry>
                <box size="1.5255397216994275 2.1335105163670014 2.6358144534038828" />
            </geometry>
        </collision>
    </link>
    <link name="Leg18">
        <inertial>
            <origin xyz="0 0 0.8074350087999494" rpy="0 0 0"/>
            <mass value="1" />
            <inertia ixx="100" ixy="0" ixz="0" iyy="100" iyz="0" izz="100" />
        </inertial>
        <visual>
            <origin xyz="0 0 0.8074350087999494" rpy="0 0 0"/>
            <geometry>
                <box size="1.0151242671040843 2.2157357792455885 1.614870017599899" />
            </geometry>
            <material name="Blue">
                <color rgba="0 1.0 1.0 1.0"/>
            </material>
        </visual>
        <collision>
            <origin xyz="0 0 0.8074350087999494" rpy="0 0 0"/>
            <geometry>
                <box size="1.0151242671040843 2.2157357792455885 1.614870017599899" />
            </geometry>
        </collision>
    </link>
    <link name="Leg19">
        <inertial>
            <origin xyz="0 0 0.983059020899779" rpy="0 0 0"/>
            <mass value="1" />
            <inertia ixx="100" ixy="0" ixz="0" iyy="100" iyz="0" izz="100" />
        </inertial>
        <visual>
            <origin xyz="0 0 0.983059020899779" rpy="0 0 0"/>
            <geometry>
                <box size="2.9335473607708575 2.11607113087035 1.966118041799558" />
            </geometry>
            <material name="Green">
                <color rgba="0 180.0 0.0 1.0"/>
            </material>
        </visual>
        <collision>
            <origin xyz="0 0 0.983059020899779" rpy="0 0 0"/>
            <geometry>
                <box size="2.9335473607708575 2.11607113087035 1.966118041799558" />
            </geometry>
        </collision>
    </link>
    <link name="Leg20">
        <inertial>
            <origin xyz="0 0 0.6207572927360586" rpy="0 0 0"/>
            <mass value="1" />
            <inertia ixx="100" ixy="0" ixz="0" iyy="100" iyz="0" izz="100" />
        </inertial>
        <visual>
            <origin xyz="0 0 0.6207572927360586" rpy="0 0 0"/>
            <geometry>
                <box size="1.6769815154885854 1.2345711294608028 1.2415145854721172" />
            </geometry>
            <material name="Blue">
                <color rgba="0 1.0 1.0 1.0"/>
            </material>
        </visual>
        <collision>
            <origin xyz="0 0 0.6207572927360586" rpy="0 0 0"/>
            <geometry>
                <box size="1.6769815154885854 1.2345711294608028 1.2415145854721172" />
            </geometry>
        </collision>
    </link>
    <link name="Leg21">
        <inertial>
            <origin xyz="0 0.7403975224148469 0" rpy="0 0 0"/>
            <mass value="1" />
            <inertia ixx="100" ixy="0" ixz="0" iyy="100" iyz="0" izz="100" />
        </inertial>
        <visual>
            <origin xyz="0 0.7403975224148469 0" rpy="0 0 0"/>
            <geometry>
                <box size="2.42418263318401 1.4807950448296938 2.0548566911994746" />
            </geometry>
            <material name="Blue">
                <color rgba="0 1.0 1.0 1.0"/>
            </material>
        </visual>
        <collision>
            <origin xyz="0 0.7403975224148469 0" rpy="0 0 0"/>
            <geometry>
                <box size="2.42418263318401 1.4807950448296938 2.0548566911994746" />
            </geometry>
        </collision>
    </link>
    <link name="Leg22">
        <inertial>
            <origin xyz="0 0.5204087267514061 0" rpy="0 0 0"/>
            <mass value="1" />
            <inertia ixx="100" ixy="0" ixz="0" iyy="100" iyz="0" izz="100" />
        </inertial>
        <visual>
            <origin xyz="0 0.5204087267514061 0" rpy="0 0 0"/>
            <geometry>
                <box size="2.7656402878021193 1.0408174535028123 1.9407019989183658" />
            </geometry>
            <material name="Green">
                <color rgba="0 180.0 0.0 1.0"/>
            </material>
        </visual>
        <collision>
            <origin xyz="0 0.5204087267514061 0" rpy="0 0 0"/>
            <geometry>
                <box size="2.7656402878021193 1.0408174535028123 1.9407019989183658" />
            </geometry>
        </collision>
    </link>
    <link name="Leg23">
        <inertial>
            <origin xyz="1.1689839513507134 0 0" rpy="0 0 0"/>
            <mass value="1" />
            <inertia ixx="100" ixy="0" ixz="0" iyy="100" iyz="0" izz="100" />
        </inertial>
        <visual>
            <origin xyz="1.1689839513507134 0 0" rpy="0 0 0"/>
            <geometry>
                <box size="2.337967902701427 2.635168789368616 2.0199853115198865" />
            </geometry>
            <material name="Blue">
                <color rgba="0 1.0 1.0 1.0"/>
            </material>
        </visual>
        <collision>
            <origin xyz="1.1689839513507134 0 0" rpy="0 0 0"/>
            <geometry>
                <box size="2.337967902701427 2.635168789368616 2.0199853115198865" />
            </geometry>
        </collision>
    </link>
    <link name="Leg24">
        <inertial>
            <origin xyz="0 1.4438852075532835 0" rpy="0 0 0"/>
            <mass value="1" />
            <inertia ixx="100" ixy="0" ixz="0" iyy="100" iyz="0" izz="100" />
        </inertial>
        <visual>
            <origin xyz="0 1.4438852075532835 0" rpy="0 0 0"/>
            <geometry>
                <box size="1.2364837937846513 2.887770415106567 1.3100956720726378" />
            </geometry>
            <material name="Blue">
                <color rgba="0 1.0 1.0 1.0"/>
            </material>
        </visual>
        <collision>
            <origin xyz="0 1.4438852075532835 0" rpy="0 0 0"/>
            <geometry>
                <box size="1.2364837937846513 2.887770415106567 1.3100956720726378" />
            </geometry>
        </collision>
    </link>
    <joint name="Torso_Leg1" type="revolute">
       <parent link="Torso"/>
       <child  link="Leg1"/>
       <origin rpy="0 0 0" xyz="1.0859485988950888 0 1.012356185013994" />
     <axis xyz="1 0 0"/>
       <limit effort="0.0" lower="-3.14159" upper="3.14159" velocity="0.0"/>
    </joint>
    <joint name="Leg1_Leg2" type="revolute">
       <parent link="Leg1"/>
       <child  link="Leg2"/>
       <origin rpy="0 0 0" xyz="0 1.046428115905749 0" />
     <axis xyz="1 0 0"/>
       <limit effort="0.0" lower="-3.14159" upper="3.14159" velocity="0.0"/>
    </joint>
    <joint name="Leg1_Leg3" type="revolute">
       <parent link="Leg1"/>
       <child  link="Leg3"/>
       <origin rpy="0 0 0" xyz="0.6106411663996101 1.046428115905749 0" />
     <axis xyz="1 0 0"/>
       <limit effort="0.0" lower="-3.14159" upper="3.14159" velocity="0.0"/>
    </joint>
    <joint name="Leg3_Leg4" type="revolute">
       <parent link="Leg3"/>
       <child  link="Leg4"/>
       <origin rpy="0 0 0" xyz="0 1.1771287236845864 0" />
     <axis xyz="1 0 0"/>
       <limit effort="0.0" lower="-3.14159" upper="3.14159" velocity="0.0"/>
    </joint>
    <joint name="Leg4_Leg5" type="revolute">
       <parent link="Leg4"/>
       <child  link="Leg5"/>
       <origin rpy="0 0 0" xyz="0 0 1.51196767281194" />
     <axis xyz="1 0 0"/>
       <limit effort="0.0" lower="-3.14159" upper="3.14159" velocity="0.0"/>
    </joint>
    <joint name="Leg2_Leg6" type="revolute">
       <parent link="Leg2"/>
       <child  link="Leg6"/>
       <origin rpy="0 0 0" xyz="1.037944980686318 0.5560494006207339 0" />
     <axis xyz="1 0 0"/>
       <limit effort="0.0" lower="-3.14159" upper="3.14159" velocity="0.0"/>
    </joint>
    <joint name="Leg6_Leg7" type="revolute">
       <parent link="Leg6"/>
       <child  link="Leg7"/>
       <origin rpy="0 0 0" xyz="2.305570303455669 0 0" />
     <axis xyz="1 0 0"/>
       <limit effort="0.0" lower="-3.14159" upper="3.14159" velocity="0.0"/>
    </joint>
    <joint name="Leg3_Leg8" type="revolute">
       <parent link="Leg3"/>
       <child  link="Leg8"/>
       <origin rpy="0 0 0" xyz="1.1614491354593213 1.1771287236845864 0" />
     <axis xyz="1 0 0"/>
       <limit effort="0.0" lower="-3.14159" upper="3.14159" velocity="0.0"/>
    </joint>
    <joint name="Leg7_Leg9" type="revolute">
       <parent link="Leg7"/>
       <child  link="Leg9"/>
       <origin rpy="0 0 0" xyz="2.604687302409693 0 0" />
     <axis xyz="1 0 0"/>
       <limit effort="0.0" lower="-3.14159" upper="3.14159" velocity="0.0"/>
    </joint>
    <joint name="Leg5_Leg10" type="revolute">
       <parent link="Leg5"/>
       <child  link="Leg10"/>
       <origin rpy="0 0 0" xyz="0.8670240686019125 1.0312764059523187 0" />
     <axis xyz="1 0 0"/>
       <limit effort="0.0" lower="-3.14159" upper="3.14159" velocity="0.0"/>
    </joint>
    <joint name="Leg2_Leg11" type="revolute">
       <parent link="Leg2"/>
       <child  link="Leg11"/>
       <origin rpy="0 0 0" xyz="1.037944980686318 0.5560494006207339 1.4670025523378702" />
     <axis xyz="1 0 0"/>
       <limit effort="0.0" lower="-3.14159" upper="3.14159" velocity="0.0"/>
    </joint>
    <joint name="Leg7_Leg12" type="revolute">
       <parent link="Leg7"/>
       <child  link="Leg12"/>
       <origin rpy="0 0 0" xyz="2.604687302409693 0 1.39479139890116" />
     <axis xyz="1 0 0"/>
       <limit effort="0.0" lower="-3.14159" upper="3.14159" velocity="0.0"/>
    </joint>
    <joint name="Leg9_Leg13" type="revolute">
       <parent link="Leg9"/>
       <child  link="Leg13"/>
       <origin rpy="0 0 0" xyz="2.6869965881815823 0 0" />
     <axis xyz="1 0 0"/>
       <limit effort="0.0" lower="-3.14159" upper="3.14159" velocity="0.0"/>
    </joint>
    <joint name="Torso_Leg14" type="revolute">
       <parent link="Torso"/>
       <child  link="Leg14"/>
       <origin rpy="0 0 0" xyz="0.7126354529801938 0 1.3160885583485067" />
     <axis xyz="1 0 0"/>
       <limit effort="0.0" lower="-3.14159" upper="3.14159" velocity="0.0"/>
    </joint>
    <joint name="Leg7_Leg15" type="revolute">
       <parent link="Leg7"/>
       <child  link="Leg15"/>
       <origin rpy="0 0 0" xyz="2.604687302409693 0.7417941311050675 1.39479139890116" />
     <axis xyz="1 0 0"/>
       <limit effort="0.0" lower="-3.14159" upper="3.14159" velocity="0.0"/>
    </joint>
    <joint name="Torso_Leg16" type="revolute">
       <parent link="Torso"/>
       <child  link="Leg16"/>
       <origin rpy="0 0 0" xyz="0.7126354529801938 0.6345380851950471 1.3160885583485067" />
     <axis xyz="1 0 0"/>
       <limit effort="0.0" lower="-3.14159" upper="3.14159" velocity="0.0"/>
    </joint>
    <joint name="Leg5_Leg17" type="revolute">
       <parent link="Leg5"/>
       <child  link="Leg17"/>
       <origin rpy="0 0 0" xyz="0.8670240686019125 2.0625528119046375 0" />
     <axis xyz="1 0 0"/>
       <limit effort="0.0" lower="-3.14159" upper="3.14159" velocity="0.0"/>
    </joint>
    <joint name="Leg13_Leg18" type="revolute">
       <parent link="Leg13"/>
       <child  link="Leg18"/>
       <origin rpy="0 0 0" xyz="0 0 1.3388003237247392" />
     <axis xyz="1 0 0"/>
       <limit effort="0.0" lower="-3.14159" upper="3.14159" velocity="0.0"/>
    </joint>
    <joint name="Leg5_Leg19" type="revolute">
       <parent link="Leg5"/>
       <child  link="Leg19"/>
       <origin rpy="0 0 0" xyz="0.8670240686019125 2.0625528119046375 1.0812945033626644" />
     <axis xyz="1 0 0"/>
       <limit effort="0.0" lower="-3.14159" upper="3.14159" velocity="0.0"/>
    </joint>
    <joint name="Leg14_Leg20" type="revolute">
       <parent link="Leg14"/>
       <child  link="Leg20"/>
       <origin rpy="0 0 0" xyz="0 0.544750286968729 0.9080801630022848" />
     <axis xyz="1 0 0"/>
       <limit effort="0.0" lower="-3.14159" upper="3.14159" velocity="0.0"/>
    </joint>
    <joint name="Leg15_Leg21" type="revolute">
       <parent link="Leg15"/>
       <child  link="Leg21"/>
       <origin rpy="0 0 0" xyz="0 1.098005710587975 0" />
     <axis xyz="1 0 0"/>
       <limit effort="0.0" lower="-3.14159" upper="3.14159" velocity="0.0"/>
    </joint>
    <joint name="Leg12_Leg22" type="revolute">
       <parent link="Leg12"/>
       <child  link="Leg22"/>
       <origin rpy="0 0 0" xyz="1.1994345091154281 0.5161574702841185 0" />
     <axis xyz="1 0 0"/>
       <limit effort="0.0" lower="-3.14159" upper="3.14159" velocity="0.0"/>
    </joint>
    <joint name="Leg4_Leg23" type="revolute">
       <parent link="Leg4"/>
       <child  link="Leg23"/>
       <origin rpy="0 0 0" xyz="0.7142083803133403 0 1.51196767281194" />
     <axis xyz="1 0 0"/>
       <limit effort="0.0" lower="-3.14159" upper="3.14159" velocity="0.0"/>
    </joint>
    <joint name="Leg11_Leg24" type="revolute">
       <parent link="Leg11"/>
       <child  link="Leg24"/>
       <origin rpy="0 0 0" xyz="0 0.6202119997837978 1.3857094031401391" />
     <axis xyz="1 0 0"/>
       <limit effort="0.0" lower="-3.14159" upper="3.14159" velocity="0.0"/>
    </joint>
</robot>