<robot name = "robot">
    <link name="Torso">
        <inertial>
            <origin xyz="-6 4 3.639999287695758" rpy="0 0 0"/>
            <mass value="1" />
            <inertia ixx="100" ixy="0" ixz="0" iyy="100" iyz="0" izz="100" />
        </inertial>
        <visual>
            <origin xyz="-6 4 3.639999287695758" rpy="0 0 0"/>
            <geometry>
                <box size="5.564900641426167 3.741145020018287 3.8079339342711602" />
            </geometry>
            <material name="Blue">
                <color rgba="0 1.0 1.0 1.0"/>
            </material>
        </visual>
        <collision>
            <origin xyz="-6 4 3.639999287695758" rpy="0 0 0"/>
            <geometry>
                <box size="5.564900641426167 3.741145020018287 3.8079339342711602" />
            </geometry>
        </collision>
    </link>
    <link name="Leg1">
        <inertial>
            <origin xyz="0 0 -0.8680161602800889" rpy="0 0 0"/>
            <mass value="1" />
            <inertia ixx="100" ixy="0" ixz="0" iyy="100" iyz="0" izz="100" />
        </inertial>
        <visual>
            <origin xyz="0 0 -0.8680161602800889" rpy="0 0 0"/>
            <geometry>
                <box size="0.9712952282922673 1.1096413586273814 1.7360323205601778" />
            </geometry>
            <material name="Blue">
                <color rgba="0 1.0 1.0 1.0"/>
            </material>
        </visual>
        <collision>
            <origin xyz="0 0 -0.8680161602800889" rpy="0 0 0"/>
            <geometry>
                <box size="0.9712952282922673 1.1096413586273814 1.7360323205601778" />
            </geometry>
        </collision>
    </link>
    <link name="Leg2">
        <inertial>
            <origin xyz="0 0 -0.8680161602800889" rpy="0 0 0"/>
            <mass value="1" />
            <inertia ixx="100" ixy="0" ixz="0" iyy="100" iyz="0" izz="100" />
        </inertial>
        <visual>
            <origin xyz="0 0 -0.8680161602800889" rpy="0 0 0"/>
            <geometry>
                <box size="0.9712952282922673 1.1096413586273814 1.7360323205601778" />
            </geometry>
            <material name="Blue">
                <color rgba="0 1.0 1.0 1.0"/>
            </material>
        </visual>
        <collision>
            <origin xyz="0 0 -0.8680161602800889" rpy="0 0 0"/>
            <geometry>
                <box size="0.9712952282922673 1.1096413586273814 1.7360323205601778" />
            </geometry>
        </collision>
    </link>
    <link name="Leg3">
        <inertial>
            <origin xyz="0 0 -0.8680161602800889" rpy="0 0 0"/>
            <mass value="1" />
            <inertia ixx="100" ixy="0" ixz="0" iyy="100" iyz="0" izz="100" />
        </inertial>
        <visual>
            <origin xyz="0 0 -0.8680161602800889" rpy="0 0 0"/>
            <geometry>
                <box size="0.9712952282922673 1.1096413586273814 1.7360323205601778" />
            </geometry>
            <material name="Green">
                <color rgba="0 180.0 0.0 1.0"/>
            </material>
        </visual>
        <collision>
            <origin xyz="0 0 -0.8680161602800889" rpy="0 0 0"/>
            <geometry>
                <box size="0.9712952282922673 1.1096413586273814 1.7360323205601778" />
            </geometry>
        </collision>
    </link>
    <link name="Leg4">
        <inertial>
            <origin xyz="0 0 -0.8680161602800889" rpy="0 0 0"/>
            <mass value="1" />
            <inertia ixx="100" ixy="0" ixz="0" iyy="100" iyz="0" izz="100" />
        </inertial>
        <visual>
            <origin xyz="0 0 -0.8680161602800889" rpy="0 0 0"/>
            <geometry>
                <box size="0.9712952282922673 1.1096413586273814 1.7360323205601778" />
            </geometry>
            <material name="Blue">
                <color rgba="0 1.0 1.0 1.0"/>
            </material>
        </visual>
        <collision>
            <origin xyz="0 0 -0.8680161602800889" rpy="0 0 0"/>
            <geometry>
                <box size="0.9712952282922673 1.1096413586273814 1.7360323205601778" />
            </geometry>
        </collision>
    </link>
    <link name="Head">
        <inertial>
            <origin xyz="1.0266001983344202 0 1.2385767542283126" rpy="0 0 0"/>
            <mass value="1" />
            <inertia ixx="100" ixy="0" ixz="0" iyy="100" iyz="0" izz="100" />
        </inertial>
        <visual>
            <origin xyz="1.0266001983344202 0 1.2385767542283126" rpy="0 0 0"/>
            <geometry>
                <box size="2.0532003966688404 2.3251867266112005 2.477153508456625" />
            </geometry>
            <material name="Green">
                <color rgba="0 180.0 0.0 1.0"/>
            </material>
        </visual>
        <collision>
            <origin xyz="1.0266001983344202 0 1.2385767542283126" rpy="0 0 0"/>
            <geometry>
                <box size="2.0532003966688404 2.3251867266112005 2.477153508456625" />
            </geometry>
        </collision>
    </link>
    <joint name="Torso_Leg1" type="revolute">
       <parent link="Torso"/>
       <child  link="Leg1"/>
       <origin rpy="0 0 0" xyz="-8.782450320713084 5.8705725100091435 1.7360323205601778" />
     <axis xyz="1 0 0"/>
       <limit effort="0.0" lower="-3.14159" upper="3.14159" velocity="0.0"/>
    </joint>
    <joint name="Torso_Leg2" type="revolute">
       <parent link="Torso"/>
       <child  link="Leg2"/>
       <origin rpy="0 0 0" xyz="-3.2175496792869165 5.8705725100091435 1.7360323205601778" />
     <axis xyz="1 0 0"/>
       <limit effort="0.0" lower="-3.14159" upper="3.14159" velocity="0.0"/>
    </joint>
    <joint name="Torso_Leg3" type="revolute">
       <parent link="Torso"/>
       <child  link="Leg3"/>
       <origin rpy="0 0 0" xyz="-8.782450320713084 2.1294274899908565 1.7360323205601778" />
     <axis xyz="1 0 0"/>
       <limit effort="0.0" lower="-3.14159" upper="3.14159" velocity="0.0"/>
    </joint>
    <joint name="Torso_Leg4" type="revolute">
       <parent link="Torso"/>
       <child  link="Leg4"/>
       <origin rpy="0 0 0" xyz="-3.2175496792869165 2.1294274899908565 1.7360323205601778" />
     <axis xyz="1 0 0"/>
       <limit effort="0.0" lower="-3.14159" upper="3.14159" velocity="0.0"/>
    </joint>
    <joint name="Torso_Head" type="revolute">
       <parent link="Torso"/>
       <child  link="Head"/>
       <origin rpy="0 0 0" xyz="-3.2175496792869165 4 5.5439662548313375" />
     <axis xyz="1 0 0"/>
       <limit effort="0.0" lower="-3.14159" upper="3.14159" velocity="0.0"/>
    </joint>
</robot>