<robot name = "robot">
    <link name="Torso">
        <inertial>
            <origin xyz="0.9053622601902284 0 0.5210889755312093" rpy="0 0 0"/>
            <mass value="1" />
            <inertia ixx="100" ixy="0" ixz="0" iyy="100" iyz="0" izz="100" />
        </inertial>
        <visual>
            <origin xyz="0.9053622601902284 0 0.5210889755312093" rpy="0 0 0"/>
            <geometry>
                <box size="1.8107245203804567 2.89062771708054 1.0421779510624185" />
            </geometry>
            <material name="Green">
                <color rgba="0 180.0 0.0 1.0"/>
            </material>
        </visual>
        <collision>
            <origin xyz="0.9053622601902284 0 0.5210889755312093" rpy="0 0 0"/>
            <geometry>
                <box size="1.8107245203804567 2.89062771708054 1.0421779510624185" />
            </geometry>
        </collision>
    </link>
    <link name="Leg1">
        <inertial>
            <origin xyz="0.8202301296812087 0.8767659662163996 1.4352078637373016" rpy="0 0 0"/>
            <mass value="1" />
            <inertia ixx="100" ixy="0" ixz="0" iyy="100" iyz="0" izz="100" />
        </inertial>
        <visual>
            <origin xyz="0.8202301296812087 0.8767659662163996 1.4352078637373016" rpy="0 0 0"/>
            <geometry>
                <box size="1.6404602593624174 1.7535319324327991 2.870415727474603" />
            </geometry>
            <material name="Blue">
                <color rgba="0 1.0 1.0 1.0"/>
            </material>
        </visual>
        <collision>
            <origin xyz="0.8202301296812087 0.8767659662163996 1.4352078637373016" rpy="0 0 0"/>
            <geometry>
                <box size="1.6404602593624174 1.7535319324327991 2.870415727474603" />
            </geometry>
        </collision>
    </link>
    <link name="Leg2">
        <inertial>
            <origin xyz="2.0237757268194088 0.5205391788902219 0" rpy="0 0 0"/>
            <mass value="1" />
            <inertia ixx="100" ixy="0" ixz="0" iyy="100" iyz="0" izz="100" />
        </inertial>
        <visual>
            <origin xyz="2.0237757268194088 0.5205391788902219 0" rpy="0 0 0"/>
            <geometry>
                <box size="2.0237757268194088 1.0410783577804439 2.8608985341557194" />
            </geometry>
            <material name="Blue">
                <color rgba="0 1.0 1.0 1.0"/>
            </material>
        </visual>
        <collision>
            <origin xyz="2.0237757268194088 0.5205391788902219 0" rpy="0 0 0"/>
            <geometry>
                <box size="2.0237757268194088 1.0410783577804439 2.8608985341557194" />
            </geometry>
        </collision>
    </link>
    <link name="Leg3">
        <inertial>
            <origin xyz="1.9878666463314931 1.4595673588394384 0" rpy="0 0 0"/>
            <mass value="1" />
            <inertia ixx="100" ixy="0" ixz="0" iyy="100" iyz="0" izz="100" />
        </inertial>
        <visual>
            <origin xyz="1.9878666463314931 1.4595673588394384 0" rpy="0 0 0"/>
            <geometry>
                <box size="1.9878666463314931 2.919134717678877 1.771982062868968" />
            </geometry>
            <material name="Blue">
                <color rgba="0 1.0 1.0 1.0"/>
            </material>
        </visual>
        <collision>
            <origin xyz="1.9878666463314931 1.4595673588394384 0" rpy="0 0 0"/>
            <geometry>
                <box size="1.9878666463314931 2.919134717678877 1.771982062868968" />
            </geometry>
        </collision>
    </link>
    <link name="Leg4">
        <inertial>
            <origin xyz="0 0.7940557019067527 1.832970802824342" rpy="0 0 0"/>
            <mass value="1" />
            <inertia ixx="100" ixy="0" ixz="0" iyy="100" iyz="0" izz="100" />
        </inertial>
        <visual>
            <origin xyz="0 0.7940557019067527 1.832970802824342" rpy="0 0 0"/>
            <geometry>
                <box size="1.9104227024330345 1.5881114038135054 1.832970802824342" />
            </geometry>
            <material name="Blue">
                <color rgba="0 1.0 1.0 1.0"/>
            </material>
        </visual>
        <collision>
            <origin xyz="0 0.7940557019067527 1.832970802824342" rpy="0 0 0"/>
            <geometry>
                <box size="1.9104227024330345 1.5881114038135054 1.832970802824342" />
            </geometry>
        </collision>
    </link>
    <link name="Leg5">
        <inertial>
            <origin xyz="0.7781549580284958 1.8987447565208155 1.339199668182871" rpy="0 0 0"/>
            <mass value="1" />
            <inertia ixx="100" ixy="0" ixz="0" iyy="100" iyz="0" izz="100" />
        </inertial>
        <visual>
            <origin xyz="0.7781549580284958 1.8987447565208155 1.339199668182871" rpy="0 0 0"/>
            <geometry>
                <box size="1.5563099160569915 1.8987447565208155 2.678399336365742" />
            </geometry>
            <material name="Blue">
                <color rgba="0 1.0 1.0 1.0"/>
            </material>
        </visual>
        <collision>
            <origin xyz="0.7781549580284958 1.8987447565208155 1.339199668182871" rpy="0 0 0"/>
            <geometry>
                <box size="1.5563099160569915 1.8987447565208155 2.678399336365742" />
            </geometry>
        </collision>
    </link>
    <link name="Leg6">
        <inertial>
            <origin xyz="1.3196996849919582 1.074554291077526 0" rpy="0 0 0"/>
            <mass value="1" />
            <inertia ixx="100" ixy="0" ixz="0" iyy="100" iyz="0" izz="100" />
        </inertial>
        <visual>
            <origin xyz="1.3196996849919582 1.074554291077526 0" rpy="0 0 0"/>
            <geometry>
                <box size="2.6393993699839164 2.149108582155052 1.308531695848038" />
            </geometry>
            <material name="Blue">
                <color rgba="0 1.0 1.0 1.0"/>
            </material>
        </visual>
        <collision>
            <origin xyz="1.3196996849919582 1.074554291077526 0" rpy="0 0 0"/>
            <geometry>
                <box size="2.6393993699839164 2.149108582155052 1.308531695848038" />
            </geometry>
        </collision>
    </link>
    <link name="Leg7">
        <inertial>
            <origin xyz="0 2.6076234438473174 0.7680354544237684" rpy="0 0 0"/>
            <mass value="1" />
            <inertia ixx="100" ixy="0" ixz="0" iyy="100" iyz="0" izz="100" />
        </inertial>
        <visual>
            <origin xyz="0 2.6076234438473174 0.7680354544237684" rpy="0 0 0"/>
            <geometry>
                <box size="2.538447721571255 2.6076234438473174 1.5360709088475368" />
            </geometry>
            <material name="Blue">
                <color rgba="0 1.0 1.0 1.0"/>
            </material>
        </visual>
        <collision>
            <origin xyz="0 2.6076234438473174 0.7680354544237684" rpy="0 0 0"/>
            <geometry>
                <box size="2.538447721571255 2.6076234438473174 1.5360709088475368" />
            </geometry>
        </collision>
    </link>
    <link name="Leg8">
        <inertial>
            <origin xyz="0.5318243292144307 1.329247300308877 0" rpy="0 0 0"/>
            <mass value="1" />
            <inertia ixx="100" ixy="0" ixz="0" iyy="100" iyz="0" izz="100" />
        </inertial>
        <visual>
            <origin xyz="0.5318243292144307 1.329247300308877 0" rpy="0 0 0"/>
            <geometry>
                <box size="1.0636486584288614 2.658494600617754 2.844450781976323" />
            </geometry>
            <material name="Blue">
                <color rgba="0 1.0 1.0 1.0"/>
            </material>
        </visual>
        <collision>
            <origin xyz="0.5318243292144307 1.329247300308877 0" rpy="0 0 0"/>
            <geometry>
                <box size="1.0636486584288614 2.658494600617754 2.844450781976323" />
            </geometry>
        </collision>
    </link>
    <link name="Leg9">
        <inertial>
            <origin xyz="1.2306605061699654 0.738245753457401 1.1942507465189895" rpy="0 0 0"/>
            <mass value="1" />
            <inertia ixx="100" ixy="0" ixz="0" iyy="100" iyz="0" izz="100" />
        </inertial>
        <visual>
            <origin xyz="1.2306605061699654 0.738245753457401 1.1942507465189895" rpy="0 0 0"/>
            <geometry>
                <box size="2.4613210123399307 1.476491506914802 2.388501493037979" />
            </geometry>
            <material name="Blue">
                <color rgba="0 1.0 1.0 1.0"/>
            </material>
        </visual>
        <collision>
            <origin xyz="1.2306605061699654 0.738245753457401 1.1942507465189895" rpy="0 0 0"/>
            <geometry>
                <box size="2.4613210123399307 1.476491506914802 2.388501493037979" />
            </geometry>
        </collision>
    </link>
    <link name="Leg10">
        <inertial>
            <origin xyz="0 2.8475044764930235 0" rpy="0 0 0"/>
            <mass value="1" />
            <inertia ixx="100" ixy="0" ixz="0" iyy="100" iyz="0" izz="100" />
        </inertial>
        <visual>
            <origin xyz="0 2.8475044764930235 0" rpy="0 0 0"/>
            <geometry>
                <box size="2.3701480002554574 2.8475044764930235 2.240746550463004" />
            </geometry>
            <material name="Blue">
                <color rgba="0 1.0 1.0 1.0"/>
            </material>
        </visual>
        <collision>
            <origin xyz="0 2.8475044764930235 0" rpy="0 0 0"/>
            <geometry>
                <box size="2.3701480002554574 2.8475044764930235 2.240746550463004" />
            </geometry>
        </collision>
    </link>
    <link name="Leg11">
        <inertial>
            <origin xyz="0 0 1.403442816591772" rpy="0 0 0"/>
            <mass value="1" />
            <inertia ixx="100" ixy="0" ixz="0" iyy="100" iyz="0" izz="100" />
        </inertial>
        <visual>
            <origin xyz="0 0 1.403442816591772" rpy="0 0 0"/>
            <geometry>
                <box size="1.2602879953340567 1.324191126488058 2.806885633183544" />
            </geometry>
            <material name="Blue">
                <color rgba="0 1.0 1.0 1.0"/>
            </material>
        </visual>
        <collision>
            <origin xyz="0 0 1.403442816591772" rpy="0 0 0"/>
            <geometry>
                <box size="1.2602879953340567 1.324191126488058 2.806885633183544" />
            </geometry>
        </collision>
    </link>
    <link name="Leg12">
        <inertial>
            <origin xyz="0 2.715011177874415 0" rpy="0 0 0"/>
            <mass value="1" />
            <inertia ixx="100" ixy="0" ixz="0" iyy="100" iyz="0" izz="100" />
        </inertial>
        <visual>
            <origin xyz="0 2.715011177874415 0" rpy="0 0 0"/>
            <geometry>
                <box size="1.020512522749808 2.715011177874415 1.8958298395369841" />
            </geometry>
            <material name="Blue">
                <color rgba="0 1.0 1.0 1.0"/>
            </material>
        </visual>
        <collision>
            <origin xyz="0 2.715011177874415 0" rpy="0 0 0"/>
            <geometry>
                <box size="1.020512522749808 2.715011177874415 1.8958298395369841" />
            </geometry>
        </collision>
    </link>
    <link name="Leg13">
        <inertial>
            <origin xyz="1.4439050647475213 0.8075989881977389 0" rpy="0 0 0"/>
            <mass value="1" />
            <inertia ixx="100" ixy="0" ixz="0" iyy="100" iyz="0" izz="100" />
        </inertial>
        <visual>
            <origin xyz="1.4439050647475213 0.8075989881977389 0" rpy="0 0 0"/>
            <geometry>
                <box size="2.8878101294950427 1.6151979763954778 1.6195238563454641" />
            </geometry>
            <material name="Blue">
                <color rgba="0 1.0 1.0 1.0"/>
            </material>
        </visual>
        <collision>
            <origin xyz="1.4439050647475213 0.8075989881977389 0" rpy="0 0 0"/>
            <geometry>
                <box size="2.8878101294950427 1.6151979763954778 1.6195238563454641" />
            </geometry>
        </collision>
    </link>
    <link name="Leg14">
        <inertial>
            <origin xyz="2.2115744590802766 0 0" rpy="0 0 0"/>
            <mass value="1" />
            <inertia ixx="100" ixy="0" ixz="0" iyy="100" iyz="0" izz="100" />
        </inertial>
        <visual>
            <origin xyz="2.2115744590802766 0 0" rpy="0 0 0"/>
            <geometry>
                <box size="2.2115744590802766 2.921534434222074 2.531660903445704" />
            </geometry>
            <material name="Blue">
                <color rgba="0 1.0 1.0 1.0"/>
            </material>
        </visual>
        <collision>
            <origin xyz="2.2115744590802766 0 0" rpy="0 0 0"/>
            <geometry>
                <box size="2.2115744590802766 2.921534434222074 2.531660903445704" />
            </geometry>
        </collision>
    </link>
    <link name="Leg15">
        <inertial>
            <origin xyz="0 1.2868294124023967 0" rpy="0 0 0"/>
            <mass value="1" />
            <inertia ixx="100" ixy="0" ixz="0" iyy="100" iyz="0" izz="100" />
        </inertial>
        <visual>
            <origin xyz="0 1.2868294124023967 0" rpy="0 0 0"/>
            <geometry>
                <box size="2.12486042781844 2.5736588248047934 1.2764348942637003" />
            </geometry>
            <material name="Blue">
                <color rgba="0 1.0 1.0 1.0"/>
            </material>
        </visual>
        <collision>
            <origin xyz="0 1.2868294124023967 0" rpy="0 0 0"/>
            <geometry>
                <box size="2.12486042781844 2.5736588248047934 1.2764348942637003" />
            </geometry>
        </collision>
    </link>
    <link name="Leg16">
        <inertial>
            <origin xyz="0 1.4266950051240903 2.9279977258939223" rpy="0 0 0"/>
            <mass value="1" />
            <inertia ixx="100" ixy="0" ixz="0" iyy="100" iyz="0" izz="100" />
        </inertial>
        <visual>
            <origin xyz="0 1.4266950051240903 2.9279977258939223" rpy="0 0 0"/>
            <geometry>
                <box size="2.496053684621836 2.8533900102481806 2.9279977258939223" />
            </geometry>
            <material name="Blue">
                <color rgba="0 1.0 1.0 1.0"/>
            </material>
        </visual>
        <collision>
            <origin xyz="0 1.4266950051240903 2.9279977258939223" rpy="0 0 0"/>
            <geometry>
                <box size="2.496053684621836 2.8533900102481806 2.9279977258939223" />
            </geometry>
        </collision>
    </link>
    <link name="Leg17">
        <inertial>
            <origin xyz="0.6244325486574696 0 0.5781949854126592" rpy="0 0 0"/>
            <mass value="1" />
            <inertia ixx="100" ixy="0" ixz="0" iyy="100" iyz="0" izz="100" />
        </inertial>
        <visual>
            <origin xyz="0.6244325486574696 0 0.5781949854126592" rpy="0 0 0"/>
            <geometry>
                <box size="1.248865097314939 2.6354054969512477 1.1563899708253185" />
            </geometry>
            <material name="Blue">
                <color rgba="0 1.0 1.0 1.0"/>
            </material>
        </visual>
        <collision>
            <origin xyz="0.6244325486574696 0 0.5781949854126592" rpy="0 0 0"/>
            <geometry>
                <box size="1.248865097314939 2.6354054969512477 1.1563899708253185" />
            </geometry>
        </collision>
    </link>
    <link name="Leg18">
        <inertial>
            <origin xyz="0 0.6537087045135836 0" rpy="0 0 0"/>
            <mass value="1" />
            <inertia ixx="100" ixy="0" ixz="0" iyy="100" iyz="0" izz="100" />
        </inertial>
        <visual>
            <origin xyz="0 0.6537087045135836 0" rpy="0 0 0"/>
            <geometry>
                <box size="2.205644594507408 1.3074174090271673 2.9997016268733994" />
            </geometry>
            <material name="Blue">
                <color rgba="0 1.0 1.0 1.0"/>
            </material>
        </visual>
        <collision>
            <origin xyz="0 0.6537087045135836 0" rpy="0 0 0"/>
            <geometry>
                <box size="2.205644594507408 1.3074174090271673 2.9997016268733994" />
            </geometry>
        </collision>
    </link>
    <link name="Leg19">
        <inertial>
            <origin xyz="0 0 1.9100258203569818" rpy="0 0 0"/>
            <mass value="1" />
            <inertia ixx="100" ixy="0" ixz="0" iyy="100" iyz="0" izz="100" />
        </inertial>
        <visual>
            <origin xyz="0 0 1.9100258203569818" rpy="0 0 0"/>
            <geometry>
                <box size="1.620920067958327 2.1793922986289154 1.9100258203569818" />
            </geometry>
            <material name="Blue">
                <color rgba="0 1.0 1.0 1.0"/>
            </material>
        </visual>
        <collision>
            <origin xyz="0 0 1.9100258203569818" rpy="0 0 0"/>
            <geometry>
                <box size="1.620920067958327 2.1793922986289154 1.9100258203569818" />
            </geometry>
        </collision>
    </link>
    <link name="Leg20">
        <inertial>
            <origin xyz="1.0662257923274727 0 0" rpy="0 0 0"/>
            <mass value="1" />
            <inertia ixx="100" ixy="0" ixz="0" iyy="100" iyz="0" izz="100" />
        </inertial>
        <visual>
            <origin xyz="1.0662257923274727 0 0" rpy="0 0 0"/>
            <geometry>
                <box size="2.1324515846549454 1.3190361207356058 1.7200119228657964" />
            </geometry>
            <material name="Blue">
                <color rgba="0 1.0 1.0 1.0"/>
            </material>
        </visual>
        <collision>
            <origin xyz="1.0662257923274727 0 0" rpy="0 0 0"/>
            <geometry>
                <box size="2.1324515846549454 1.3190361207356058 1.7200119228657964" />
            </geometry>
        </collision>
    </link>
    <link name="Leg21">
        <inertial>
            <origin xyz="0 0.9513563282865566 0" rpy="0 0 0"/>
            <mass value="1" />
            <inertia ixx="100" ixy="0" ixz="0" iyy="100" iyz="0" izz="100" />
        </inertial>
        <visual>
            <origin xyz="0 0.9513563282865566 0" rpy="0 0 0"/>
            <geometry>
                <box size="2.6140001149527454 1.9027126565731132 2.250882011213993" />
            </geometry>
            <material name="Blue">
                <color rgba="0 1.0 1.0 1.0"/>
            </material>
        </visual>
        <collision>
            <origin xyz="0 0.9513563282865566 0" rpy="0 0 0"/>
            <geometry>
                <box size="2.6140001149527454 1.9027126565731132 2.250882011213993" />
            </geometry>
        </collision>
    </link>
    <link name="Leg22">
        <inertial>
            <origin xyz="0 0 2.1764355694220976" rpy="0 0 0"/>
            <mass value="1" />
            <inertia ixx="100" ixy="0" ixz="0" iyy="100" iyz="0" izz="100" />
        </inertial>
        <visual>
            <origin xyz="0 0 2.1764355694220976" rpy="0 0 0"/>
            <geometry>
                <box size="1.056506194728158 2.2520966470102177 2.1764355694220976" />
            </geometry>
            <material name="Blue">
                <color rgba="0 1.0 1.0 1.0"/>
            </material>
        </visual>
        <collision>
            <origin xyz="0 0 2.1764355694220976" rpy="0 0 0"/>
            <geometry>
                <box size="1.056506194728158 2.2520966470102177 2.1764355694220976" />
            </geometry>
        </collision>
    </link>
    <link name="Leg23">
        <inertial>
            <origin xyz="0 0 0.9585926077017392" rpy="0 0 0"/>
            <mass value="1" />
            <inertia ixx="100" ixy="0" ixz="0" iyy="100" iyz="0" izz="100" />
        </inertial>
        <visual>
            <origin xyz="0 0 0.9585926077017392" rpy="0 0 0"/>
            <geometry>
                <box size="2.8754855380473607 2.4461425144432374 1.9171852154034783" />
            </geometry>
            <material name="Blue">
                <color rgba="0 1.0 1.0 1.0"/>
            </material>
        </visual>
        <collision>
            <origin xyz="0 0 0.9585926077017392" rpy="0 0 0"/>
            <geometry>
                <box size="2.8754855380473607 2.4461425144432374 1.9171852154034783" />
            </geometry>
        </collision>
    </link>
    <link name="Leg24">
        <inertial>
            <origin xyz="0 0 1.4399143273414965" rpy="0 0 0"/>
            <mass value="1" />
            <inertia ixx="100" ixy="0" ixz="0" iyy="100" iyz="0" izz="100" />
        </inertial>
        <visual>
            <origin xyz="0 0 1.4399143273414965" rpy="0 0 0"/>
            <geometry>
                <box size="1.1732369044681517 2.3028135001715357 2.879828654682993" />
            </geometry>
            <material name="Blue">
                <color rgba="0 1.0 1.0 1.0"/>
            </material>
        </visual>
        <collision>
            <origin xyz="0 0 1.4399143273414965" rpy="0 0 0"/>
            <geometry>
                <box size="1.1732369044681517 2.3028135001715357 2.879828654682993" />
            </geometry>
        </collision>
    </link>
    <link name="Leg25">
        <inertial>
            <origin xyz="0.7127920463068195 0 0" rpy="0 0 0"/>
            <mass value="1" />
            <inertia ixx="100" ixy="0" ixz="0" iyy="100" iyz="0" izz="100" />
        </inertial>
        <visual>
            <origin xyz="0.7127920463068195 0 0" rpy="0 0 0"/>
            <geometry>
                <box size="1.425584092613639 2.894227866602323 2.3116973017810203" />
            </geometry>
            <material name="Blue">
                <color rgba="0 1.0 1.0 1.0"/>
            </material>
        </visual>
        <collision>
            <origin xyz="0.7127920463068195 0 0" rpy="0 0 0"/>
            <geometry>
                <box size="1.425584092613639 2.894227866602323 2.3116973017810203" />
            </geometry>
        </collision>
    </link>
    <link name="Leg26">
        <inertial>
            <origin xyz="0 0 0.7216058527837241" rpy="0 0 0"/>
            <mass value="1" />
            <inertia ixx="100" ixy="0" ixz="0" iyy="100" iyz="0" izz="100" />
        </inertial>
        <visual>
            <origin xyz="0 0 0.7216058527837241" rpy="0 0 0"/>
            <geometry>
                <box size="1.9479240936433575 2.6701243492022595 1.4432117055674483" />
            </geometry>
            <material name="Blue">
                <color rgba="0 1.0 1.0 1.0"/>
            </material>
        </visual>
        <collision>
            <origin xyz="0 0 0.7216058527837241" rpy="0 0 0"/>
            <geometry>
                <box size="1.9479240936433575 2.6701243492022595 1.4432117055674483" />
            </geometry>
        </collision>
    </link>
    <link name="Leg27">
        <inertial>
            <origin xyz="0 0 0.8796497361673935" rpy="0 0 0"/>
            <mass value="1" />
            <inertia ixx="100" ixy="0" ixz="0" iyy="100" iyz="0" izz="100" />
        </inertial>
        <visual>
            <origin xyz="0 0 0.8796497361673935" rpy="0 0 0"/>
            <geometry>
                <box size="1.831854618960017 2.215061925087599 1.759299472334787" />
            </geometry>
            <material name="Blue">
                <color rgba="0 1.0 1.0 1.0"/>
            </material>
        </visual>
        <collision>
            <origin xyz="0 0 0.8796497361673935" rpy="0 0 0"/>
            <geometry>
                <box size="1.831854618960017 2.215061925087599 1.759299472334787" />
            </geometry>
        </collision>
    </link>
    <link name="Leg28">
        <inertial>
            <origin xyz="0 0.8209690573209667 0" rpy="0 0 0"/>
            <mass value="1" />
            <inertia ixx="100" ixy="0" ixz="0" iyy="100" iyz="0" izz="100" />
        </inertial>
        <visual>
            <origin xyz="0 0.8209690573209667 0" rpy="0 0 0"/>
            <geometry>
                <box size="1.3515392320862312 1.6419381146419334 1.5693662206820178" />
            </geometry>
            <material name="Green">
                <color rgba="0 180.0 100.0 1.0"/>
            </material>
        </visual>
        <collision>
            <origin xyz="0 0.8209690573209667 0" rpy="0 0 0"/>
            <geometry>
                <box size="1.3515392320862312 1.6419381146419334 1.5693662206820178" />
            </geometry>
        </collision>
    </link>
    <joint name="Torso_Leg1" type="revolute">
       <parent link="Torso"/>
       <child  link="Leg1"/>
       <origin rpy="0 0 0" xyz="0.9053622601902284 0 0.5210889755312093" />
     <axis xyz="1 0 0"/>
       <limit effort="0.0" lower="-3.14159" upper="3.14159" velocity="0.0"/>
    </joint>
    <joint name="Leg1_Leg2" type="revolute">
       <parent link="Leg1"/>
       <child  link="Leg2"/>
       <origin rpy="0 0 0" xyz="2.0237757268194088 0.5205391788902219 0" />
     <axis xyz="1 0 0"/>
       <limit effort="0.0" lower="-3.14159" upper="3.14159" velocity="0.0"/>
    </joint>
    <joint name="Leg2_Leg3" type="revolute">
       <parent link="Leg2"/>
       <child  link="Leg3"/>
       <origin rpy="0 0 0" xyz="1.9878666463314931 1.4595673588394384 0" />
     <axis xyz="1 0 0"/>
       <limit effort="0.0" lower="-3.14159" upper="3.14159" velocity="0.0"/>
    </joint>
    <joint name="Leg3_Leg4" type="revolute">
       <parent link="Leg3"/>
       <child  link="Leg4"/>
       <origin rpy="0 0 0" xyz="0 0.7940557019067527 1.832970802824342" />
     <axis xyz="1 0 0"/>
       <limit effort="0.0" lower="-3.14159" upper="3.14159" velocity="0.0"/>
    </joint>
    <joint name="Leg4_Leg5" type="revolute">
       <parent link="Leg4"/>
       <child  link="Leg5"/>
       <origin rpy="0 0 0" xyz="0.7781549580284958 1.8987447565208155 1.339199668182871" />
     <axis xyz="1 0 0"/>
       <limit effort="0.0" lower="-3.14159" upper="3.14159" velocity="0.0"/>
    </joint>
    <joint name="Leg3_Leg6" type="revolute">
       <parent link="Leg3"/>
       <child  link="Leg6"/>
       <origin rpy="0 0 0" xyz="0 0.7940557019067527 1.832970802824342" />
     <axis xyz="1 0 0"/>
       <limit effort="0.0" lower="-3.14159" upper="3.14159" velocity="0.0"/>
    </joint>
    <joint name="Leg1_Leg7" type="revolute">
       <parent link="Leg1"/>
       <child  link="Leg7"/>
       <origin rpy="0 0 0" xyz="2.0237757268194088 0.5205391788902219 0" />
     <axis xyz="1 0 0"/>
       <limit effort="0.0" lower="-3.14159" upper="3.14159" velocity="0.0"/>
    </joint>
    <joint name="Torso_Leg8" type="revolute">
       <parent link="Torso"/>
       <child  link="Leg8"/>
       <origin rpy="0 0 0" xyz="0.8202301296812087 0.8767659662163996 1.4352078637373016" />
     <axis xyz="1 0 0"/>
       <limit effort="0.0" lower="-3.14159" upper="3.14159" velocity="0.0"/>
    </joint>
    <joint name="Leg4_Leg9" type="revolute">
       <parent link="Leg4"/>
       <child  link="Leg9"/>
       <origin rpy="0 0 0" xyz="0.7781549580284958 1.8987447565208155 1.339199668182871" />
     <axis xyz="1 0 0"/>
       <limit effort="0.0" lower="-3.14159" upper="3.14159" velocity="0.0"/>
    </joint>
    <joint name="Leg6_Leg10" type="revolute">
       <parent link="Leg6"/>
       <child  link="Leg10"/>
       <origin rpy="0 0 0" xyz="0 2.6076234438473174 0.7680354544237684" />
     <axis xyz="1 0 0"/>
       <limit effort="0.0" lower="-3.14159" upper="3.14159" velocity="0.0"/>
    </joint>
    <joint name="Leg6_Leg11" type="revolute">
       <parent link="Leg6"/>
       <child  link="Leg11"/>
       <origin rpy="0 0 0" xyz="0 2.6076234438473174 0.7680354544237684" />
     <axis xyz="1 0 0"/>
       <limit effort="0.0" lower="-3.14159" upper="3.14159" velocity="0.0"/>
    </joint>
    <joint name="Leg2_Leg12" type="revolute">
       <parent link="Leg2"/>
       <child  link="Leg12"/>
       <origin rpy="0 0 0" xyz="1.9878666463314931 1.4595673588394384 0" />
     <axis xyz="1 0 0"/>
       <limit effort="0.0" lower="-3.14159" upper="3.14159" velocity="0.0"/>
    </joint>
    <joint name="Leg11_Leg13" type="revolute">
       <parent link="Leg11"/>
       <child  link="Leg13"/>
       <origin rpy="0 0 0" xyz="0 2.715011177874415 0" />
     <axis xyz="1 0 0"/>
       <limit effort="0.0" lower="-3.14159" upper="3.14159" velocity="0.0"/>
    </joint>
    <joint name="Leg5_Leg14" type="revolute">
       <parent link="Leg5"/>
       <child  link="Leg14"/>
       <origin rpy="0 0 0" xyz="1.3196996849919582 1.074554291077526 0" />
     <axis xyz="1 0 0"/>
       <limit effort="0.0" lower="-3.14159" upper="3.14159" velocity="0.0"/>
    </joint>
    <joint name="Leg8_Leg15" type="revolute">
       <parent link="Leg8"/>
       <child  link="Leg15"/>
       <origin rpy="0 0 0" xyz="1.2306605061699654 0.738245753457401 1.1942507465189895" />
     <axis xyz="1 0 0"/>
       <limit effort="0.0" lower="-3.14159" upper="3.14159" velocity="0.0"/>
    </joint>
    <joint name="Leg4_Leg16" type="revolute">
       <parent link="Leg4"/>
       <child  link="Leg16"/>
       <origin rpy="0 0 0" xyz="0.7781549580284958 1.8987447565208155 1.339199668182871" />
     <axis xyz="1 0 0"/>
       <limit effort="0.0" lower="-3.14159" upper="3.14159" velocity="0.0"/>
    </joint>
    <joint name="Leg13_Leg17" type="revolute">
       <parent link="Leg13"/>
       <child  link="Leg17"/>
       <origin rpy="0 0 0" xyz="2.2115744590802766 0 0" />
     <axis xyz="1 0 0"/>
       <limit effort="0.0" lower="-3.14159" upper="3.14159" velocity="0.0"/>
    </joint>
    <joint name="Leg9_Leg18" type="revolute">
       <parent link="Leg9"/>
       <child  link="Leg18"/>
       <origin rpy="0 0 0" xyz="0 2.8475044764930235 0" />
     <axis xyz="1 0 0"/>
       <limit effort="0.0" lower="-3.14159" upper="3.14159" velocity="0.0"/>
    </joint>
    <joint name="Leg18_Leg19" type="revolute">
       <parent link="Leg18"/>
       <child  link="Leg19"/>
       <origin rpy="0 0 0" xyz="0 0 1.9100258203569818" />
     <axis xyz="1 0 0"/>
       <limit effort="0.0" lower="-3.14159" upper="3.14159" velocity="0.0"/>
    </joint>
    <joint name="Leg7_Leg20" type="revolute">
       <parent link="Leg7"/>
       <child  link="Leg20"/>
       <origin rpy="0 0 0" xyz="0.5318243292144307 1.329247300308877 0" />
     <axis xyz="1 0 0"/>
       <limit effort="0.0" lower="-3.14159" upper="3.14159" velocity="0.0"/>
    </joint>
    <joint name="Leg15_Leg21" type="revolute">
       <parent link="Leg15"/>
       <child  link="Leg21"/>
       <origin rpy="0 0 0" xyz="0 1.4266950051240903 2.9279977258939223" />
     <axis xyz="1 0 0"/>
       <limit effort="0.0" lower="-3.14159" upper="3.14159" velocity="0.0"/>
    </joint>
    <joint name="Leg21_Leg22" type="revolute">
       <parent link="Leg21"/>
       <child  link="Leg22"/>
       <origin rpy="0 0 0" xyz="0 0 2.1764355694220976" />
     <axis xyz="1 0 0"/>
       <limit effort="0.0" lower="-3.14159" upper="3.14159" velocity="0.0"/>
    </joint>
    <joint name="Torso_Leg23" type="revolute">
       <parent link="Torso"/>
       <child  link="Leg23"/>
       <origin rpy="0 0 0" xyz="0.8202301296812087 0.8767659662163996 1.4352078637373016" />
     <axis xyz="1 0 0"/>
       <limit effort="0.0" lower="-3.14159" upper="3.14159" velocity="0.0"/>
    </joint>
    <joint name="Leg8_Leg24" type="revolute">
       <parent link="Leg8"/>
       <child  link="Leg24"/>
       <origin rpy="0 0 0" xyz="1.2306605061699654 0.738245753457401 1.1942507465189895" />
     <axis xyz="1 0 0"/>
       <limit effort="0.0" lower="-3.14159" upper="3.14159" velocity="0.0"/>
    </joint>
    <joint name="Leg12_Leg25" type="revolute">
       <parent link="Leg12"/>
       <child  link="Leg25"/>
       <origin rpy="0 0 0" xyz="1.4439050647475213 0.8075989881977389 0" />
     <axis xyz="1 0 0"/>
       <limit effort="0.0" lower="-3.14159" upper="3.14159" velocity="0.0"/>
    </joint>
    <joint name="Leg16_Leg26" type="revolute">
       <parent link="Leg16"/>
       <child  link="Leg26"/>
       <origin rpy="0 0 0" xyz="0.6244325486574696 0 0.5781949854126592" />
     <axis xyz="1 0 0"/>
       <limit effort="0.0" lower="-3.14159" upper="3.14159" velocity="0.0"/>
    </joint>
    <joint name="Leg15_Leg27" type="revolute">
       <parent link="Leg15"/>
       <child  link="Leg27"/>
       <origin rpy="0 0 0" xyz="0 1.4266950051240903 2.9279977258939223" />
     <axis xyz="1 0 0"/>
       <limit effort="0.0" lower="-3.14159" upper="3.14159" velocity="0.0"/>
    </joint>
    <joint name="Leg27_Leg28" type="revolute">
       <parent link="Leg27"/>
       <child  link="Leg27"/>
       <origin rpy="0 0 0" xyz="0 1.1075309625437995 0.8796497361673935" />
     <axis xyz="1 0 0"/>
       <limit effort="0.0" lower="-3.14159" upper="3.14159" velocity="0.0"/>
    </joint>
</robot>