<robot name = "robot">
    <link name="Torso">
        <inertial>
            <origin xyz="0 0 1.3394993793403875" rpy="0 0 0"/>
            <mass value="1" />
            <inertia ixx="100" ixy="0" ixz="0" iyy="100" iyz="0" izz="100" />
        </inertial>
        <visual>
            <origin xyz="0 0 1.3394993793403875" rpy="0 0 0"/>
            <geometry>
                <box size="1.5868401811046475 2.4214537492915817 2.678998758680775" />
            </geometry>
            <material name="Green">
                <color rgba="0 180.0 0.0 1.0"/>
            </material>
        </visual>
        <collision>
            <origin xyz="0 0 1.3394993793403875" rpy="0 0 0"/>
            <geometry>
                <box size="1.5868401811046475 2.4214537492915817 2.678998758680775" />
            </geometry>
        </collision>
    </link>
    <link name="Leg1">
        <inertial>
            <origin xyz="0.9739164437989285 0 0" rpy="0 0 0"/>
            <mass value="1" />
            <inertia ixx="100" ixy="0" ixz="0" iyy="100" iyz="0" izz="100" />
        </inertial>
        <visual>
            <origin xyz="0.9739164437989285 0 0" rpy="0 0 0"/>
            <geometry>
                <box size="1.947832887597857 2.5291979414212498 2.33077028337228" />
            </geometry>
            <material name="Blue">
                <color rgba="0 1.0 1.0 1.0"/>
            </material>
        </visual>
        <collision>
            <origin xyz="0.9739164437989285 0 0" rpy="0 0 0"/>
            <geometry>
                <box size="1.947832887597857 2.5291979414212498 2.33077028337228" />
            </geometry>
        </collision>
    </link>
    <link name="Leg2">
        <inertial>
            <origin xyz="0 0 0.9127605739889804" rpy="0 0 0"/>
            <mass value="1" />
            <inertia ixx="100" ixy="0" ixz="0" iyy="100" iyz="0" izz="100" />
        </inertial>
        <visual>
            <origin xyz="0 0 0.9127605739889804" rpy="0 0 0"/>
            <geometry>
                <box size="2.5523749589484037 1.378092373120705 1.8255211479779607" />
            </geometry>
            <material name="Green">
                <color rgba="0 180.0 0.0 1.0"/>
            </material>
        </visual>
        <collision>
            <origin xyz="0 0 0.9127605739889804" rpy="0 0 0"/>
            <geometry>
                <box size="2.5523749589484037 1.378092373120705 1.8255211479779607" />
            </geometry>
        </collision>
    </link>
    <link name="Leg3">
        <inertial>
            <origin xyz="1.4046399648660999 0 0" rpy="0 0 0"/>
            <mass value="1" />
            <inertia ixx="100" ixy="0" ixz="0" iyy="100" iyz="0" izz="100" />
        </inertial>
        <visual>
            <origin xyz="1.4046399648660999 0 0" rpy="0 0 0"/>
            <geometry>
                <box size="2.8092799297321998 1.2703136256932095 2.731820073075059" />
            </geometry>
            <material name="Green">
                <color rgba="0 180.0 0.0 1.0"/>
            </material>
        </visual>
        <collision>
            <origin xyz="1.4046399648660999 0 0" rpy="0 0 0"/>
            <geometry>
                <box size="2.8092799297321998 1.2703136256932095 2.731820073075059" />
            </geometry>
        </collision>
    </link>
    <link name="Leg4">
        <inertial>
            <origin xyz="0 1.1352807892613392 0" rpy="0 0 0"/>
            <mass value="1" />
            <inertia ixx="100" ixy="0" ixz="0" iyy="100" iyz="0" izz="100" />
        </inertial>
        <visual>
            <origin xyz="0 1.1352807892613392 0" rpy="0 0 0"/>
            <geometry>
                <box size="2.9944378185203293 2.2705615785226785 1.1082343019479615" />
            </geometry>
            <material name="Green">
                <color rgba="0 180.0 0.0 1.0"/>
            </material>
        </visual>
        <collision>
            <origin xyz="0 1.1352807892613392 0" rpy="0 0 0"/>
            <geometry>
                <box size="2.9944378185203293 2.2705615785226785 1.1082343019479615" />
            </geometry>
        </collision>
    </link>
    <link name="Leg5">
        <inertial>
            <origin xyz="0 0 0.6208296078638438" rpy="0 0 0"/>
            <mass value="1" />
            <inertia ixx="100" ixy="0" ixz="0" iyy="100" iyz="0" izz="100" />
        </inertial>
        <visual>
            <origin xyz="0 0 0.6208296078638438" rpy="0 0 0"/>
            <geometry>
                <box size="2.5895929127880066 2.045325118377669 1.2416592157276876" />
            </geometry>
            <material name="Blue">
                <color rgba="0 1.0 1.0 1.0"/>
            </material>
        </visual>
        <collision>
            <origin xyz="0 0 0.6208296078638438" rpy="0 0 0"/>
            <geometry>
                <box size="2.5895929127880066 2.045325118377669 1.2416592157276876" />
            </geometry>
        </collision>
    </link>
    <link name="Leg6">
        <inertial>
            <origin xyz="0.9015754808081339 0 0" rpy="0 0 0"/>
            <mass value="1" />
            <inertia ixx="100" ixy="0" ixz="0" iyy="100" iyz="0" izz="100" />
        </inertial>
        <visual>
            <origin xyz="0.9015754808081339 0 0" rpy="0 0 0"/>
            <geometry>
                <box size="1.8031509616162678 2.2163803339943007 1.4919390641369639" />
            </geometry>
            <material name="Blue">
                <color rgba="0 1.0 1.0 1.0"/>
            </material>
        </visual>
        <collision>
            <origin xyz="0.9015754808081339 0 0" rpy="0 0 0"/>
            <geometry>
                <box size="1.8031509616162678 2.2163803339943007 1.4919390641369639" />
            </geometry>
        </collision>
    </link>
    <link name="Leg7">
        <inertial>
            <origin xyz="0 0 0.7986124209050776" rpy="0 0 0"/>
            <mass value="1" />
            <inertia ixx="100" ixy="0" ixz="0" iyy="100" iyz="0" izz="100" />
        </inertial>
        <visual>
            <origin xyz="0 0 0.7986124209050776" rpy="0 0 0"/>
            <geometry>
                <box size="1.5806100914442196 1.8354951639406123 1.5972248418101551" />
            </geometry>
            <material name="Blue">
                <color rgba="0 1.0 1.0 1.0"/>
            </material>
        </visual>
        <collision>
            <origin xyz="0 0 0.7986124209050776" rpy="0 0 0"/>
            <geometry>
                <box size="1.5806100914442196 1.8354951639406123 1.5972248418101551" />
            </geometry>
        </collision>
    </link>
    <link name="Leg8">
        <inertial>
            <origin xyz="0 0 0.6364555103815578" rpy="0 0 0"/>
            <mass value="1" />
            <inertia ixx="100" ixy="0" ixz="0" iyy="100" iyz="0" izz="100" />
        </inertial>
        <visual>
            <origin xyz="0 0 0.6364555103815578" rpy="0 0 0"/>
            <geometry>
                <box size="1.723686805404815 2.056733340011929 1.2729110207631156" />
            </geometry>
            <material name="Green">
                <color rgba="0 180.0 0.0 1.0"/>
            </material>
        </visual>
        <collision>
            <origin xyz="0 0 0.6364555103815578" rpy="0 0 0"/>
            <geometry>
                <box size="1.723686805404815 2.056733340011929 1.2729110207631156" />
            </geometry>
        </collision>
    </link>
    <link name="Leg9">
        <inertial>
            <origin xyz="0.6527262096349139 0 0" rpy="0 0 0"/>
            <mass value="1" />
            <inertia ixx="100" ixy="0" ixz="0" iyy="100" iyz="0" izz="100" />
        </inertial>
        <visual>
            <origin xyz="0.6527262096349139 0 0" rpy="0 0 0"/>
            <geometry>
                <box size="1.3054524192698278 1.1810697220407336 2.994765172641017" />
            </geometry>
            <material name="Green">
                <color rgba="0 180.0 0.0 1.0"/>
            </material>
        </visual>
        <collision>
            <origin xyz="0.6527262096349139 0 0" rpy="0 0 0"/>
            <geometry>
                <box size="1.3054524192698278 1.1810697220407336 2.994765172641017" />
            </geometry>
        </collision>
    </link>
    <link name="Leg10">
        <inertial>
            <origin xyz="1.4617129983914763 0 0" rpy="0 0 0"/>
            <mass value="1" />
            <inertia ixx="100" ixy="0" ixz="0" iyy="100" iyz="0" izz="100" />
        </inertial>
        <visual>
            <origin xyz="1.4617129983914763 0 0" rpy="0 0 0"/>
            <geometry>
                <box size="2.9234259967829526 2.1268423012488236 1.900989270496312" />
            </geometry>
            <material name="Blue">
                <color rgba="0 1.0 1.0 1.0"/>
            </material>
        </visual>
        <collision>
            <origin xyz="1.4617129983914763 0 0" rpy="0 0 0"/>
            <geometry>
                <box size="2.9234259967829526 2.1268423012488236 1.900989270496312" />
            </geometry>
        </collision>
    </link>
    <link name="Leg11">
        <inertial>
            <origin xyz="1.11482901860914 0 0" rpy="0 0 0"/>
            <mass value="1" />
            <inertia ixx="100" ixy="0" ixz="0" iyy="100" iyz="0" izz="100" />
        </inertial>
        <visual>
            <origin xyz="1.11482901860914 0 0" rpy="0 0 0"/>
            <geometry>
                <box size="2.22965803721828 1.168066767404467 1.1352612269835747" />
            </geometry>
            <material name="Green">
                <color rgba="0 180.0 0.0 1.0"/>
            </material>
        </visual>
        <collision>
            <origin xyz="1.11482901860914 0 0" rpy="0 0 0"/>
            <geometry>
                <box size="2.22965803721828 1.168066767404467 1.1352612269835747" />
            </geometry>
        </collision>
    </link>
    <link name="Leg12">
        <inertial>
            <origin xyz="1.380594817621519 0 0" rpy="0 0 0"/>
            <mass value="1" />
            <inertia ixx="100" ixy="0" ixz="0" iyy="100" iyz="0" izz="100" />
        </inertial>
        <visual>
            <origin xyz="1.380594817621519 0 0" rpy="0 0 0"/>
            <geometry>
                <box size="2.761189635243038 1.68848405520173 2.927260817212705" />
            </geometry>
            <material name="Blue">
                <color rgba="0 1.0 1.0 1.0"/>
            </material>
        </visual>
        <collision>
            <origin xyz="1.380594817621519 0 0" rpy="0 0 0"/>
            <geometry>
                <box size="2.761189635243038 1.68848405520173 2.927260817212705" />
            </geometry>
        </collision>
    </link>
    <link name="Leg13">
        <inertial>
            <origin xyz="1.3820237719429493 0 0" rpy="0 0 0"/>
            <mass value="1" />
            <inertia ixx="100" ixy="0" ixz="0" iyy="100" iyz="0" izz="100" />
        </inertial>
        <visual>
            <origin xyz="1.3820237719429493 0 0" rpy="0 0 0"/>
            <geometry>
                <box size="2.7640475438858987 2.589584171666996 1.1661995183556164" />
            </geometry>
            <material name="Blue">
                <color rgba="0 1.0 1.0 1.0"/>
            </material>
        </visual>
        <collision>
            <origin xyz="1.3820237719429493 0 0" rpy="0 0 0"/>
            <geometry>
                <box size="2.7640475438858987 2.589584171666996 1.1661995183556164" />
            </geometry>
        </collision>
    </link>
    <link name="Leg14">
        <inertial>
            <origin xyz="0 0.5872099812751024 0" rpy="0 0 0"/>
            <mass value="1" />
            <inertia ixx="100" ixy="0" ixz="0" iyy="100" iyz="0" izz="100" />
        </inertial>
        <visual>
            <origin xyz="0 0.5872099812751024 0" rpy="0 0 0"/>
            <geometry>
                <box size="2.6738889419288645 1.1744199625502048 1.9050466121712362" />
            </geometry>
            <material name="Blue">
                <color rgba="0 1.0 1.0 1.0"/>
            </material>
        </visual>
        <collision>
            <origin xyz="0 0.5872099812751024 0" rpy="0 0 0"/>
            <geometry>
                <box size="2.6738889419288645 1.1744199625502048 1.9050466121712362" />
            </geometry>
        </collision>
    </link>
    <link name="Leg15">
        <inertial>
            <origin xyz="0 1.2407753370749686 0" rpy="0 0 0"/>
            <mass value="1" />
            <inertia ixx="100" ixy="0" ixz="0" iyy="100" iyz="0" izz="100" />
        </inertial>
        <visual>
            <origin xyz="0 1.2407753370749686 0" rpy="0 0 0"/>
            <geometry>
                <box size="1.735219235916634 2.481550674149937 1.338715182753458" />
            </geometry>
            <material name="Blue">
                <color rgba="0 1.0 1.0 1.0"/>
            </material>
        </visual>
        <collision>
            <origin xyz="0 1.2407753370749686 0" rpy="0 0 0"/>
            <geometry>
                <box size="1.735219235916634 2.481550674149937 1.338715182753458" />
            </geometry>
        </collision>
    </link>
    <link name="Leg16">
        <inertial>
            <origin xyz="0 0 0.5946063640427777" rpy="0 0 0"/>
            <mass value="1" />
            <inertia ixx="100" ixy="0" ixz="0" iyy="100" iyz="0" izz="100" />
        </inertial>
        <visual>
            <origin xyz="0 0 0.5946063640427777" rpy="0 0 0"/>
            <geometry>
                <box size="1.3617251855388006 1.6907533352452944 1.1892127280855553" />
            </geometry>
            <material name="Blue">
                <color rgba="0 1.0 1.0 1.0"/>
            </material>
        </visual>
        <collision>
            <origin xyz="0 0 0.5946063640427777" rpy="0 0 0"/>
            <geometry>
                <box size="1.3617251855388006 1.6907533352452944 1.1892127280855553" />
            </geometry>
        </collision>
    </link>
    <link name="Leg17">
        <inertial>
            <origin xyz="0 0 1.388629524191181" rpy="0 0 0"/>
            <mass value="1" />
            <inertia ixx="100" ixy="0" ixz="0" iyy="100" iyz="0" izz="100" />
        </inertial>
        <visual>
            <origin xyz="0 0 1.388629524191181" rpy="0 0 0"/>
            <geometry>
                <box size="1.622650061242187 1.7529757521928166 2.777259048382362" />
            </geometry>
            <material name="Blue">
                <color rgba="0 1.0 1.0 1.0"/>
            </material>
        </visual>
        <collision>
            <origin xyz="0 0 1.388629524191181" rpy="0 0 0"/>
            <geometry>
                <box size="1.622650061242187 1.7529757521928166 2.777259048382362" />
            </geometry>
        </collision>
    </link>
    <link name="Leg18">
        <inertial>
            <origin xyz="0 0 0.7057147581699202" rpy="0 0 0"/>
            <mass value="1" />
            <inertia ixx="100" ixy="0" ixz="0" iyy="100" iyz="0" izz="100" />
        </inertial>
        <visual>
            <origin xyz="0 0 0.7057147581699202" rpy="0 0 0"/>
            <geometry>
                <box size="1.1739401588108138 1.4969738057132744 1.4114295163398405" />
            </geometry>
            <material name="Green">
                <color rgba="0 180.0 0.0 1.0"/>
            </material>
        </visual>
        <collision>
            <origin xyz="0 0 0.7057147581699202" rpy="0 0 0"/>
            <geometry>
                <box size="1.1739401588108138 1.4969738057132744 1.4114295163398405" />
            </geometry>
        </collision>
    </link>
    <link name="Leg19">
        <inertial>
            <origin xyz="0 1.325816830261311 0" rpy="0 0 0"/>
            <mass value="1" />
            <inertia ixx="100" ixy="0" ixz="0" iyy="100" iyz="0" izz="100" />
        </inertial>
        <visual>
            <origin xyz="0 1.325816830261311 0" rpy="0 0 0"/>
            <geometry>
                <box size="2.2806631722980684 2.651633660522622 1.716919327467305" />
            </geometry>
            <material name="Green">
                <color rgba="0 180.0 0.0 1.0"/>
            </material>
        </visual>
        <collision>
            <origin xyz="0 1.325816830261311 0" rpy="0 0 0"/>
            <geometry>
                <box size="2.2806631722980684 2.651633660522622 1.716919327467305" />
            </geometry>
        </collision>
    </link>
    <link name="Leg20">
        <inertial>
            <origin xyz="0 0.9535425348491703 0" rpy="0 0 0"/>
            <mass value="1" />
            <inertia ixx="100" ixy="0" ixz="0" iyy="100" iyz="0" izz="100" />
        </inertial>
        <visual>
            <origin xyz="0 0.9535425348491703 0" rpy="0 0 0"/>
            <geometry>
                <box size="1.5291937747262594 1.9070850696983406 1.5100098897006857" />
            </geometry>
            <material name="Blue">
                <color rgba="0 1.0 1.0 1.0"/>
            </material>
        </visual>
        <collision>
            <origin xyz="0 0.9535425348491703 0" rpy="0 0 0"/>
            <geometry>
                <box size="1.5291937747262594 1.9070850696983406 1.5100098897006857" />
            </geometry>
        </collision>
    </link>
    <link name="Leg21">
        <inertial>
            <origin xyz="0 0 0.9580671700647347" rpy="0 0 0"/>
            <mass value="1" />
            <inertia ixx="100" ixy="0" ixz="0" iyy="100" iyz="0" izz="100" />
        </inertial>
        <visual>
            <origin xyz="0 0 0.9580671700647347" rpy="0 0 0"/>
            <geometry>
                <box size="1.9425617554068757 1.426220299630444 1.9161343401294695" />
            </geometry>
            <material name="Blue">
                <color rgba="0 1.0 1.0 1.0"/>
            </material>
        </visual>
        <collision>
            <origin xyz="0 0 0.9580671700647347" rpy="0 0 0"/>
            <geometry>
                <box size="1.9425617554068757 1.426220299630444 1.9161343401294695" />
            </geometry>
        </collision>
    </link>
    <link name="Leg22">
        <inertial>
            <origin xyz="0 1.3303254499328714 0" rpy="0 0 0"/>
            <mass value="1" />
            <inertia ixx="100" ixy="0" ixz="0" iyy="100" iyz="0" izz="100" />
        </inertial>
        <visual>
            <origin xyz="0 1.3303254499328714 0" rpy="0 0 0"/>
            <geometry>
                <box size="1.0306729173486455 2.6606508998657428 2.805462786210689" />
            </geometry>
            <material name="Blue">
                <color rgba="0 1.0 1.0 1.0"/>
            </material>
        </visual>
        <collision>
            <origin xyz="0 1.3303254499328714 0" rpy="0 0 0"/>
            <geometry>
                <box size="1.0306729173486455 2.6606508998657428 2.805462786210689" />
            </geometry>
        </collision>
    </link>
    <link name="Leg23">
        <inertial>
            <origin xyz="0 0 1.0741936096427498" rpy="0 0 0"/>
            <mass value="1" />
            <inertia ixx="100" ixy="0" ixz="0" iyy="100" iyz="0" izz="100" />
        </inertial>
        <visual>
            <origin xyz="0 0 1.0741936096427498" rpy="0 0 0"/>
            <geometry>
                <box size="1.5734303478976608 2.925349004996712 2.1483872192854996" />
            </geometry>
            <material name="Green">
                <color rgba="0 180.0 0.0 1.0"/>
            </material>
        </visual>
        <collision>
            <origin xyz="0 0 1.0741936096427498" rpy="0 0 0"/>
            <geometry>
                <box size="1.5734303478976608 2.925349004996712 2.1483872192854996" />
            </geometry>
        </collision>
    </link>
    <link name="Leg24">
        <inertial>
            <origin xyz="0 0 0.6920709080343354" rpy="0 0 0"/>
            <mass value="1" />
            <inertia ixx="100" ixy="0" ixz="0" iyy="100" iyz="0" izz="100" />
        </inertial>
        <visual>
            <origin xyz="0 0 0.6920709080343354" rpy="0 0 0"/>
            <geometry>
                <box size="1.7943369406370913 1.8322673945779124 1.3841418160686707" />
            </geometry>
            <material name="Blue">
                <color rgba="0 1.0 1.0 1.0"/>
            </material>
        </visual>
        <collision>
            <origin xyz="0 0 0.6920709080343354" rpy="0 0 0"/>
            <geometry>
                <box size="1.7943369406370913 1.8322673945779124 1.3841418160686707" />
            </geometry>
        </collision>
    </link>
    <link name="Leg25">
        <inertial>
            <origin xyz="0 1.096668046487895 0" rpy="0 0 0"/>
            <mass value="1" />
            <inertia ixx="100" ixy="0" ixz="0" iyy="100" iyz="0" izz="100" />
        </inertial>
        <visual>
            <origin xyz="0 1.096668046487895 0" rpy="0 0 0"/>
            <geometry>
                <box size="1.4462024482087972 2.19333609297579 1.3808110421666897" />
            </geometry>
            <material name="Blue">
                <color rgba="0 1.0 1.0 1.0"/>
            </material>
        </visual>
        <collision>
            <origin xyz="0 1.096668046487895 0" rpy="0 0 0"/>
            <geometry>
                <box size="1.4462024482087972 2.19333609297579 1.3808110421666897" />
            </geometry>
        </collision>
    </link>
    <joint name="Torso_Leg1" type="revolute">
       <parent link="Torso"/>
       <child  link="Leg1"/>
       <origin rpy="0 0 0" xyz="0.7934200905523238 0 1.3394993793403875" />
     <axis xyz="1 0 0"/>
       <limit effort="0.0" lower="-3.14159" upper="3.14159" velocity="0.0"/>
    </joint>
    <joint name="Leg1_Leg2" type="revolute">
       <parent link="Leg1"/>
       <child  link="Leg2"/>
       <origin rpy="0 0 0" xyz="0 0 1.8255211479779607" />
     <axis xyz="1 0 0"/>
       <limit effort="0.0" lower="-3.14159" upper="3.14159" velocity="0.0"/>
    </joint>
    <joint name="Leg1_Leg3" type="revolute">
       <parent link="Leg1"/>
       <child  link="Leg3"/>
       <origin rpy="0 0 0" xyz="1.2761874794742019 0 1.8255211479779607" />
     <axis xyz="1 0 0"/>
       <limit effort="0.0" lower="-3.14159" upper="3.14159" velocity="0.0"/>
    </joint>
    <joint name="Leg2_Leg4" type="revolute">
       <parent link="Leg2"/>
       <child  link="Leg4"/>
       <origin rpy="0 0 0" xyz="1.4046399648660999 0.6351568128466047 0" />
     <axis xyz="1 0 0"/>
       <limit effort="0.0" lower="-3.14159" upper="3.14159" velocity="0.0"/>
    </joint>
    <joint name="Torso_Leg5" type="revolute">
       <parent link="Torso"/>
       <child  link="Leg5"/>
       <origin rpy="0 0 0" xyz="0.9739164437989285 0 1.16538514168614" />
     <axis xyz="1 0 0"/>
       <limit effort="0.0" lower="-3.14159" upper="3.14159" velocity="0.0"/>
    </joint>
    <joint name="Leg2_Leg6" type="revolute">
       <parent link="Leg2"/>
       <child  link="Leg6"/>
       <origin rpy="0 0 0" xyz="2.8092799297321998 0.6351568128466047 0" />
     <axis xyz="1 0 0"/>
       <limit effort="0.0" lower="-3.14159" upper="3.14159" velocity="0.0"/>
    </joint>
    <joint name="Leg6_Leg7" type="revolute">
       <parent link="Leg6"/>
       <child  link="Leg7"/>
       <origin rpy="0 0 0" xyz="0 0 1.5972248418101551" />
     <axis xyz="1 0 0"/>
       <limit effort="0.0" lower="-3.14159" upper="3.14159" velocity="0.0"/>
    </joint>
    <joint name="Leg3_Leg8" type="revolute">
       <parent link="Leg3"/>
       <child  link="Leg8"/>
       <origin rpy="0 0 0" xyz="0 1.1352807892613392 0.5541171509739807" />
     <axis xyz="1 0 0"/>
       <limit effort="0.0" lower="-3.14159" upper="3.14159" velocity="0.0"/>
    </joint>
    <joint name="Leg5_Leg9" type="revolute">
       <parent link="Leg5"/>
       <child  link="Leg9"/>
       <origin rpy="0 0 0" xyz="1.8031509616162678 0 0" />
     <axis xyz="1 0 0"/>
       <limit effort="0.0" lower="-3.14159" upper="3.14159" velocity="0.0"/>
    </joint>
    <joint name="Leg4_Leg10" type="revolute">
       <parent link="Leg4"/>
       <child  link="Leg10"/>
       <origin rpy="0 0 0" xyz="1.2947964563940033 0 0.6208296078638438" />
     <axis xyz="1 0 0"/>
       <limit effort="0.0" lower="-3.14159" upper="3.14159" velocity="0.0"/>
    </joint>
    <joint name="Leg10_Leg11" type="revolute">
       <parent link="Leg10"/>
       <child  link="Leg11"/>
       <origin rpy="0 0 0" xyz="2.22965803721828 0 0" />
     <axis xyz="1 0 0"/>
       <limit effort="0.0" lower="-3.14159" upper="3.14159" velocity="0.0"/>
    </joint>
    <joint name="Leg11_Leg12" type="revolute">
       <parent link="Leg11"/>
       <child  link="Leg12"/>
       <origin rpy="0 0 0" xyz="2.761189635243038 0 0" />
     <axis xyz="1 0 0"/>
       <limit effort="0.0" lower="-3.14159" upper="3.14159" velocity="0.0"/>
    </joint>
    <joint name="Leg9_Leg13" type="revolute">
       <parent link="Leg9"/>
       <child  link="Leg13"/>
       <origin rpy="0 0 0" xyz="2.9234259967829526 0 0" />
     <axis xyz="1 0 0"/>
       <limit effort="0.0" lower="-3.14159" upper="3.14159" velocity="0.0"/>
    </joint>
    <joint name="Leg7_Leg14" type="revolute">
       <parent link="Leg7"/>
       <child  link="Leg14"/>
       <origin rpy="0 0 0" xyz="0 1.0283666700059646 0.6364555103815578" />
     <axis xyz="1 0 0"/>
       <limit effort="0.0" lower="-3.14159" upper="3.14159" velocity="0.0"/>
    </joint>
    <joint name="Leg10_Leg15" type="revolute">
       <parent link="Leg10"/>
       <child  link="Leg15"/>
       <origin rpy="0 0 0" xyz="2.22965803721828 0.5840333837022335 0" />
     <axis xyz="1 0 0"/>
       <limit effort="0.0" lower="-3.14159" upper="3.14159" velocity="0.0"/>
    </joint>
    <joint name="Leg12_Leg16" type="revolute">
       <parent link="Leg12"/>
       <child  link="Leg16"/>
       <origin rpy="0 0 0" xyz="1.3820237719429493 0 0.5830997591778082" />
     <axis xyz="1 0 0"/>
       <limit effort="0.0" lower="-3.14159" upper="3.14159" velocity="0.0"/>
    </joint>
    <joint name="Leg14_Leg17" type="revolute">
       <parent link="Leg14"/>
       <child  link="Leg17"/>
       <origin rpy="0 0 0" xyz="0 1.2407753370749686 0.669357591376729" />
     <axis xyz="1 0 0"/>
       <limit effort="0.0" lower="-3.14159" upper="3.14159" velocity="0.0"/>
    </joint>
    <joint name="Leg10_Leg18" type="revolute">
       <parent link="Leg10"/>
       <child  link="Leg18"/>
       <origin rpy="0 0 0" xyz="2.22965803721828 0.5840333837022335 0.5676306134917873" />
     <axis xyz="1 0 0"/>
       <limit effort="0.0" lower="-3.14159" upper="3.14159" velocity="0.0"/>
    </joint>
    <joint name="Leg9_Leg19" type="revolute">
       <parent link="Leg9"/>
       <child  link="Leg19"/>
       <origin rpy="0 0 0" xyz="2.9234259967829526 1.0634211506244118 0" />
     <axis xyz="1 0 0"/>
       <limit effort="0.0" lower="-3.14159" upper="3.14159" velocity="0.0"/>
    </joint>
    <joint name="Leg8_Leg20" type="revolute">
       <parent link="Leg8"/>
       <child  link="Leg20"/>
       <origin rpy="0 0 0" xyz="0.6527262096349139 0.5905348610203668 0" />
     <axis xyz="1 0 0"/>
       <limit effort="0.0" lower="-3.14159" upper="3.14159" velocity="0.0"/>
    </joint>
    <joint name="Leg18_Leg21" type="revolute">
       <parent link="Leg18"/>
       <child  link="Leg21"/>
       <origin rpy="0 0 0" xyz="0 1.325816830261311 0.8584596637336525" />
     <axis xyz="1 0 0"/>
       <limit effort="0.0" lower="-3.14159" upper="3.14159" velocity="0.0"/>
    </joint>
    <joint name="Leg16_Leg22" type="revolute">
       <parent link="Leg16"/>
       <child  link="Leg22"/>
       <origin rpy="0 0 0" xyz="0 0.8764878760964083 1.388629524191181" />
     <axis xyz="1 0 0"/>
       <limit effort="0.0" lower="-3.14159" upper="3.14159" velocity="0.0"/>
    </joint>
    <joint name="Leg16_Leg23" type="revolute">
       <parent link="Leg16"/>
       <child  link="Leg23"/>
       <origin rpy="0 0 0" xyz="0 0.8764878760964083 2.777259048382362" />
     <axis xyz="1 0 0"/>
       <limit effort="0.0" lower="-3.14159" upper="3.14159" velocity="0.0"/>
    </joint>
    <joint name="Leg5_Leg24" type="revolute">
       <parent link="Leg5"/>
       <child  link="Leg24"/>
       <origin rpy="0 0 0" xyz="1.8031509616162678 0 0.7459695320684819" />
     <axis xyz="1 0 0"/>
       <limit effort="0.0" lower="-3.14159" upper="3.14159" velocity="0.0"/>
    </joint>
    <joint name="Leg19_Leg25" type="revolute">
       <parent link="Leg19"/>
       <child  link="Leg25"/>
       <origin rpy="0 0 0" xyz="0 1.9070850696983406 0" />
     <axis xyz="1 0 0"/>
       <limit effort="0.0" lower="-3.14159" upper="3.14159" velocity="0.0"/>
    </joint>
</robot>