<robot name = "robot">
    <link name="Torso">
        <inertial>
            <origin xyz="0 0 1.1075732128400007" rpy="0 0 0"/>
            <mass value="1" />
            <inertia ixx="100" ixy="0" ixz="0" iyy="100" iyz="0" izz="100" />
        </inertial>
        <visual>
            <origin xyz="0 0 1.1075732128400007" rpy="0 0 0"/>
            <geometry>
                <box size="2.0163563089288328 1.7237660686587413 2.2151464256800013" />
            </geometry>
            <material name="Green">
                <color rgba="0 180.0 0.0 1.0"/>
            </material>
        </visual>
        <collision>
            <origin xyz="0 0 1.1075732128400007" rpy="0 0 0"/>
            <geometry>
                <box size="2.0163563089288328 1.7237660686587413 2.2151464256800013" />
            </geometry>
        </collision>
    </link>
    <link name="Leg1">
        <inertial>
            <origin xyz="0.692014989622457 0 0" rpy="0 0 0"/>
            <mass value="1" />
            <inertia ixx="100" ixy="0" ixz="0" iyy="100" iyz="0" izz="100" />
        </inertial>
        <visual>
            <origin xyz="0.692014989622457 0 0" rpy="0 0 0"/>
            <geometry>
                <box size="1.384029979244914 2.07465765679319 2.2410767642395504" />
            </geometry>
            <material name="Green">
                <color rgba="0 180.0 0.0 1.0"/>
            </material>
        </visual>
        <collision>
            <origin xyz="0.692014989622457 0 0" rpy="0 0 0"/>
            <geometry>
                <box size="1.384029979244914 2.07465765679319 2.2410767642395504" />
            </geometry>
        </collision>
    </link>
    <link name="Leg2">
        <inertial>
            <origin xyz="0 1.2038397428629337 0" rpy="0 0 0"/>
            <mass value="1" />
            <inertia ixx="100" ixy="0" ixz="0" iyy="100" iyz="0" izz="100" />
        </inertial>
        <visual>
            <origin xyz="0 1.2038397428629337 0" rpy="0 0 0"/>
            <geometry>
                <box size="1.8772627726610216 2.4076794857258674 1.5499107319441419" />
            </geometry>
            <material name="Blue">
                <color rgba="0 1.0 1.0 1.0"/>
            </material>
        </visual>
        <collision>
            <origin xyz="0 1.2038397428629337 0" rpy="0 0 0"/>
            <geometry>
                <box size="1.8772627726610216 2.4076794857258674 1.5499107319441419" />
            </geometry>
        </collision>
    </link>
    <link name="Leg3">
        <inertial>
            <origin xyz="1.0309080502579848 0 0" rpy="0 0 0"/>
            <mass value="1" />
            <inertia ixx="100" ixy="0" ixz="0" iyy="100" iyz="0" izz="100" />
        </inertial>
        <visual>
            <origin xyz="1.0309080502579848 0 0" rpy="0 0 0"/>
            <geometry>
                <box size="2.0618161005159696 1.4663153816171068 1.6128505731703624" />
            </geometry>
            <material name="Blue">
                <color rgba="0 1.0 1.0 1.0"/>
            </material>
        </visual>
        <collision>
            <origin xyz="1.0309080502579848 0 0" rpy="0 0 0"/>
            <geometry>
                <box size="2.0618161005159696 1.4663153816171068 1.6128505731703624" />
            </geometry>
        </collision>
    </link>
    <link name="Leg4">
        <inertial>
            <origin xyz="0.7814334065792328 0 0" rpy="0 0 0"/>
            <mass value="1" />
            <inertia ixx="100" ixy="0" ixz="0" iyy="100" iyz="0" izz="100" />
        </inertial>
        <visual>
            <origin xyz="0.7814334065792328 0 0" rpy="0 0 0"/>
            <geometry>
                <box size="1.5628668131584655 1.175993012152595 1.40475521231756" />
            </geometry>
            <material name="Blue">
                <color rgba="0 1.0 1.0 1.0"/>
            </material>
        </visual>
        <collision>
            <origin xyz="0.7814334065792328 0 0" rpy="0 0 0"/>
            <geometry>
                <box size="1.5628668131584655 1.175993012152595 1.40475521231756" />
            </geometry>
        </collision>
    </link>
    <link name="Leg5">
        <inertial>
            <origin xyz="0 0 0.5077804138895268" rpy="0 0 0"/>
            <mass value="1" />
            <inertia ixx="100" ixy="0" ixz="0" iyy="100" iyz="0" izz="100" />
        </inertial>
        <visual>
            <origin xyz="0 0 0.5077804138895268" rpy="0 0 0"/>
            <geometry>
                <box size="2.9245513009630537 1.5375085415452427 1.0155608277790535" />
            </geometry>
            <material name="Green">
                <color rgba="0 180.0 0.0 1.0"/>
            </material>
        </visual>
        <collision>
            <origin xyz="0 0 0.5077804138895268" rpy="0 0 0"/>
            <geometry>
                <box size="2.9245513009630537 1.5375085415452427 1.0155608277790535" />
            </geometry>
        </collision>
    </link>
    <link name="Leg6">
        <inertial>
            <origin xyz="0 0 1.2066476277349807" rpy="0 0 0"/>
            <mass value="1" />
            <inertia ixx="100" ixy="0" ixz="0" iyy="100" iyz="0" izz="100" />
        </inertial>
        <visual>
            <origin xyz="0 0 1.2066476277349807" rpy="0 0 0"/>
            <geometry>
                <box size="2.246096114699645 2.9015615445450784 2.4132952554699614" />
            </geometry>
            <material name="Blue">
                <color rgba="0 1.0 1.0 1.0"/>
            </material>
        </visual>
        <collision>
            <origin xyz="0 0 1.2066476277349807" rpy="0 0 0"/>
            <geometry>
                <box size="2.246096114699645 2.9015615445450784 2.4132952554699614" />
            </geometry>
        </collision>
    </link>
    <link name="Leg7">
        <inertial>
            <origin xyz="0 0.6210307570341125 0" rpy="0 0 0"/>
            <mass value="1" />
            <inertia ixx="100" ixy="0" ixz="0" iyy="100" iyz="0" izz="100" />
        </inertial>
        <visual>
            <origin xyz="0 0.6210307570341125 0" rpy="0 0 0"/>
            <geometry>
                <box size="2.526458914806713 1.242061514068225 1.2862545283347957" />
            </geometry>
            <material name="Blue">
                <color rgba="0 1.0 1.0 1.0"/>
            </material>
        </visual>
        <collision>
            <origin xyz="0 0.6210307570341125 0" rpy="0 0 0"/>
            <geometry>
                <box size="2.526458914806713 1.242061514068225 1.2862545283347957" />
            </geometry>
        </collision>
    </link>
    <link name="Leg8">
        <inertial>
            <origin xyz="1.0564579475626696 0 0" rpy="0 0 0"/>
            <mass value="1" />
            <inertia ixx="100" ixy="0" ixz="0" iyy="100" iyz="0" izz="100" />
        </inertial>
        <visual>
            <origin xyz="1.0564579475626696 0 0" rpy="0 0 0"/>
            <geometry>
                <box size="2.1129158951253393 1.164024616279529 2.834814443462348" />
            </geometry>
            <material name="Blue">
                <color rgba="0 1.0 1.0 1.0"/>
            </material>
        </visual>
        <collision>
            <origin xyz="1.0564579475626696 0 0" rpy="0 0 0"/>
            <geometry>
                <box size="2.1129158951253393 1.164024616279529 2.834814443462348" />
            </geometry>
        </collision>
    </link>
    <link name="Leg9">
        <inertial>
            <origin xyz="1.2607186049253485 0 0" rpy="0 0 0"/>
            <mass value="1" />
            <inertia ixx="100" ixy="0" ixz="0" iyy="100" iyz="0" izz="100" />
        </inertial>
        <visual>
            <origin xyz="1.2607186049253485 0 0" rpy="0 0 0"/>
            <geometry>
                <box size="2.521437209850697 2.038483889353203 1.4784059524551607" />
            </geometry>
            <material name="Blue">
                <color rgba="0 1.0 1.0 1.0"/>
            </material>
        </visual>
        <collision>
            <origin xyz="1.2607186049253485 0 0" rpy="0 0 0"/>
            <geometry>
                <box size="2.521437209850697 2.038483889353203 1.4784059524551607" />
            </geometry>
        </collision>
    </link>
    <link name="Leg10">
        <inertial>
            <origin xyz="0 0.5907155923441112 0" rpy="0 0 0"/>
            <mass value="1" />
            <inertia ixx="100" ixy="0" ixz="0" iyy="100" iyz="0" izz="100" />
        </inertial>
        <visual>
            <origin xyz="0 0.5907155923441112 0" rpy="0 0 0"/>
            <geometry>
                <box size="1.613790204893089 1.1814311846882224 2.413109868245443" />
            </geometry>
            <material name="Blue">
                <color rgba="0 1.0 1.0 1.0"/>
            </material>
        </visual>
        <collision>
            <origin xyz="0 0.5907155923441112 0" rpy="0 0 0"/>
            <geometry>
                <box size="1.613790204893089 1.1814311846882224 2.413109868245443" />
            </geometry>
        </collision>
    </link>
    <link name="Leg11">
        <inertial>
            <origin xyz="0 0 1.2777507654008609" rpy="0 0 0"/>
            <mass value="1" />
            <inertia ixx="100" ixy="0" ixz="0" iyy="100" iyz="0" izz="100" />
        </inertial>
        <visual>
            <origin xyz="0 0 1.2777507654008609" rpy="0 0 0"/>
            <geometry>
                <box size="1.079362852184643 1.2888117575196476 2.5555015308017217" />
            </geometry>
            <material name="Green">
                <color rgba="0 180.0 0.0 1.0"/>
            </material>
        </visual>
        <collision>
            <origin xyz="0 0 1.2777507654008609" rpy="0 0 0"/>
            <geometry>
                <box size="1.079362852184643 1.2888117575196476 2.5555015308017217" />
            </geometry>
        </collision>
    </link>
    <link name="Leg12">
        <inertial>
            <origin xyz="0.681458531388638 0 0" rpy="0 0 0"/>
            <mass value="1" />
            <inertia ixx="100" ixy="0" ixz="0" iyy="100" iyz="0" izz="100" />
        </inertial>
        <visual>
            <origin xyz="0.681458531388638 0 0" rpy="0 0 0"/>
            <geometry>
                <box size="1.362917062777276 1.0052874560442526 2.1620171990505677" />
            </geometry>
            <material name="Green">
                <color rgba="0 180.0 0.0 1.0"/>
            </material>
        </visual>
        <collision>
            <origin xyz="0.681458531388638 0 0" rpy="0 0 0"/>
            <geometry>
                <box size="1.362917062777276 1.0052874560442526 2.1620171990505677" />
            </geometry>
        </collision>
    </link>
    <link name="Leg13">
        <inertial>
            <origin xyz="1.3689520002000846 0 0" rpy="0 0 0"/>
            <mass value="1" />
            <inertia ixx="100" ixy="0" ixz="0" iyy="100" iyz="0" izz="100" />
        </inertial>
        <visual>
            <origin xyz="1.3689520002000846 0 0" rpy="0 0 0"/>
            <geometry>
                <box size="2.737904000400169 1.8507596931527872 1.2154017700393058" />
            </geometry>
            <material name="Blue">
                <color rgba="0 1.0 1.0 1.0"/>
            </material>
        </visual>
        <collision>
            <origin xyz="1.3689520002000846 0 0" rpy="0 0 0"/>
            <geometry>
                <box size="2.737904000400169 1.8507596931527872 1.2154017700393058" />
            </geometry>
        </collision>
    </link>
    <link name="Leg14">
        <inertial>
            <origin xyz="0 0 0.7582765586049974" rpy="0 0 0"/>
            <mass value="1" />
            <inertia ixx="100" ixy="0" ixz="0" iyy="100" iyz="0" izz="100" />
        </inertial>
        <visual>
            <origin xyz="0 0 0.7582765586049974" rpy="0 0 0"/>
            <geometry>
                <box size="2.8296054123568046 2.164670924861399 1.5165531172099949" />
            </geometry>
            <material name="Green">
                <color rgba="0 180.0 0.0 1.0"/>
            </material>
        </visual>
        <collision>
            <origin xyz="0 0 0.7582765586049974" rpy="0 0 0"/>
            <geometry>
                <box size="2.8296054123568046 2.164670924861399 1.5165531172099949" />
            </geometry>
        </collision>
    </link>
    <link name="Leg15">
        <inertial>
            <origin xyz="0 0.773077306056909 0" rpy="0 0 0"/>
            <mass value="1" />
            <inertia ixx="100" ixy="0" ixz="0" iyy="100" iyz="0" izz="100" />
        </inertial>
        <visual>
            <origin xyz="0 0.773077306056909 0" rpy="0 0 0"/>
            <geometry>
                <box size="2.1397841729833704 1.546154612113818 1.307696494203237" />
            </geometry>
            <material name="Blue">
                <color rgba="0 1.0 1.0 1.0"/>
            </material>
        </visual>
        <collision>
            <origin xyz="0 0.773077306056909 0" rpy="0 0 0"/>
            <geometry>
                <box size="2.1397841729833704 1.546154612113818 1.307696494203237" />
            </geometry>
        </collision>
    </link>
    <link name="Leg16">
        <inertial>
            <origin xyz="0 1.4656186160225884 0" rpy="0 0 0"/>
            <mass value="1" />
            <inertia ixx="100" ixy="0" ixz="0" iyy="100" iyz="0" izz="100" />
        </inertial>
        <visual>
            <origin xyz="0 1.4656186160225884 0" rpy="0 0 0"/>
            <geometry>
                <box size="1.3439804620768514 2.9312372320451767 1.1175082678901243" />
            </geometry>
            <material name="Blue">
                <color rgba="0 1.0 1.0 1.0"/>
            </material>
        </visual>
        <collision>
            <origin xyz="0 1.4656186160225884 0" rpy="0 0 0"/>
            <geometry>
                <box size="1.3439804620768514 2.9312372320451767 1.1175082678901243" />
            </geometry>
        </collision>
    </link>
    <link name="Leg17">
        <inertial>
            <origin xyz="0 1.3686614245211484 0" rpy="0 0 0"/>
            <mass value="1" />
            <inertia ixx="100" ixy="0" ixz="0" iyy="100" iyz="0" izz="100" />
        </inertial>
        <visual>
            <origin xyz="0 1.3686614245211484 0" rpy="0 0 0"/>
            <geometry>
                <box size="1.1313665695904265 2.7373228490422967 2.7570979259742088" />
            </geometry>
            <material name="Green">
                <color rgba="0 180.0 0.0 1.0"/>
            </material>
        </visual>
        <collision>
            <origin xyz="0 1.3686614245211484 0" rpy="0 0 0"/>
            <geometry>
                <box size="1.1313665695904265 2.7373228490422967 2.7570979259742088" />
            </geometry>
        </collision>
    </link>
    <link name="Leg18">
        <inertial>
            <origin xyz="0.5493873074981482 0 0" rpy="0 0 0"/>
            <mass value="1" />
            <inertia ixx="100" ixy="0" ixz="0" iyy="100" iyz="0" izz="100" />
        </inertial>
        <visual>
            <origin xyz="0.5493873074981482 0 0" rpy="0 0 0"/>
            <geometry>
                <box size="1.0987746149962965 2.7266720157064617 2.213405427610882" />
            </geometry>
            <material name="Green">
                <color rgba="0 180.0 0.0 1.0"/>
            </material>
        </visual>
        <collision>
            <origin xyz="0.5493873074981482 0 0" rpy="0 0 0"/>
            <geometry>
                <box size="1.0987746149962965 2.7266720157064617 2.213405427610882" />
            </geometry>
        </collision>
    </link>
    <link name="Leg19">
        <inertial>
            <origin xyz="0.5254709110994529 0 0" rpy="0 0 0"/>
            <mass value="1" />
            <inertia ixx="100" ixy="0" ixz="0" iyy="100" iyz="0" izz="100" />
        </inertial>
        <visual>
            <origin xyz="0.5254709110994529 0 0" rpy="0 0 0"/>
            <geometry>
                <box size="1.0509418221989058 2.6983613540975764 2.70412957376295" />
            </geometry>
            <material name="Green">
                <color rgba="0 180.0 0.0 1.0"/>
            </material>
        </visual>
        <collision>
            <origin xyz="0.5254709110994529 0 0" rpy="0 0 0"/>
            <geometry>
                <box size="1.0509418221989058 2.6983613540975764 2.70412957376295" />
            </geometry>
        </collision>
    </link>
    <link name="Leg20">
        <inertial>
            <origin xyz="0 0 0.5474645048600356" rpy="0 0 0"/>
            <mass value="1" />
            <inertia ixx="100" ixy="0" ixz="0" iyy="100" iyz="0" izz="100" />
        </inertial>
        <visual>
            <origin xyz="0 0 0.5474645048600356" rpy="0 0 0"/>
            <geometry>
                <box size="1.5322120253083826 2.4898342280015453 1.0949290097200712" />
            </geometry>
            <material name="Blue">
                <color rgba="0 1.0 1.0 1.0"/>
            </material>
        </visual>
        <collision>
            <origin xyz="0 0 0.5474645048600356" rpy="0 0 0"/>
            <geometry>
                <box size="1.5322120253083826 2.4898342280015453 1.0949290097200712" />
            </geometry>
        </collision>
    </link>
    <link name="Leg21">
        <inertial>
            <origin xyz="0 1.2267914702118852 0" rpy="0 0 0"/>
            <mass value="1" />
            <inertia ixx="100" ixy="0" ixz="0" iyy="100" iyz="0" izz="100" />
        </inertial>
        <visual>
            <origin xyz="0 1.2267914702118852 0" rpy="0 0 0"/>
            <geometry>
                <box size="2.739047069769185 2.4535829404237703 1.4423038991798887" />
            </geometry>
            <material name="Blue">
                <color rgba="0 1.0 1.0 1.0"/>
            </material>
        </visual>
        <collision>
            <origin xyz="0 1.2267914702118852 0" rpy="0 0 0"/>
            <geometry>
                <box size="2.739047069769185 2.4535829404237703 1.4423038991798887" />
            </geometry>
        </collision>
    </link>
    <link name="Leg22">
        <inertial>
            <origin xyz="0 1.412003434454746 0" rpy="0 0 0"/>
            <mass value="1" />
            <inertia ixx="100" ixy="0" ixz="0" iyy="100" iyz="0" izz="100" />
        </inertial>
        <visual>
            <origin xyz="0 1.412003434454746 0" rpy="0 0 0"/>
            <geometry>
                <box size="1.7274072368455733 2.824006868909492 2.784831440642594" />
            </geometry>
            <material name="Blue">
                <color rgba="0 1.0 1.0 1.0"/>
            </material>
        </visual>
        <collision>
            <origin xyz="0 1.412003434454746 0" rpy="0 0 0"/>
            <geometry>
                <box size="1.7274072368455733 2.824006868909492 2.784831440642594" />
            </geometry>
        </collision>
    </link>
    <link name="Leg23">
        <inertial>
            <origin xyz="1.0937363530139197 0 0" rpy="0 0 0"/>
            <mass value="1" />
            <inertia ixx="100" ixy="0" ixz="0" iyy="100" iyz="0" izz="100" />
        </inertial>
        <visual>
            <origin xyz="1.0937363530139197 0 0" rpy="0 0 0"/>
            <geometry>
                <box size="2.1874727060278394 2.3117028337165513 2.5556334752279426" />
            </geometry>
            <material name="Green">
                <color rgba="0 180.0 0.0 1.0"/>
            </material>
        </visual>
        <collision>
            <origin xyz="1.0937363530139197 0 0" rpy="0 0 0"/>
            <geometry>
                <box size="2.1874727060278394 2.3117028337165513 2.5556334752279426" />
            </geometry>
        </collision>
    </link>
    <link name="Leg24">
        <inertial>
            <origin xyz="0 0.7580097769698466 0" rpy="0 0 0"/>
            <mass value="1" />
            <inertia ixx="100" ixy="0" ixz="0" iyy="100" iyz="0" izz="100" />
        </inertial>
        <visual>
            <origin xyz="0 0.7580097769698466 0" rpy="0 0 0"/>
            <geometry>
                <box size="2.44574351235923 1.5160195539396932 1.676007331243427" />
            </geometry>
            <material name="Green">
                <color rgba="0 180.0 0.0 1.0"/>
            </material>
        </visual>
        <collision>
            <origin xyz="0 0.7580097769698466 0" rpy="0 0 0"/>
            <geometry>
                <box size="2.44574351235923 1.5160195539396932 1.676007331243427" />
            </geometry>
        </collision>
    </link>
    <link name="Leg25">
        <inertial>
            <origin xyz="0 1.0001219244399329 0" rpy="0 0 0"/>
            <mass value="1" />
            <inertia ixx="100" ixy="0" ixz="0" iyy="100" iyz="0" izz="100" />
        </inertial>
        <visual>
            <origin xyz="0 1.0001219244399329 0" rpy="0 0 0"/>
            <geometry>
                <box size="1.3942862451401534 2.0002438488798657 2.0363626752372044" />
            </geometry>
            <material name="Blue">
                <color rgba="0 1.0 1.0 1.0"/>
            </material>
        </visual>
        <collision>
            <origin xyz="0 1.0001219244399329 0" rpy="0 0 0"/>
            <geometry>
                <box size="1.3942862451401534 2.0002438488798657 2.0363626752372044" />
            </geometry>
        </collision>
    </link>
    <joint name="Torso_Leg1" type="revolute">
       <parent link="Torso"/>
       <child  link="Leg1"/>
       <origin rpy="0 0 0" xyz="1.0081781544644164 0 1.1075732128400007" />
     <axis xyz="1 0 0"/>
       <limit effort="0.0" lower="-3.14159" upper="3.14159" velocity="0.0"/>
    </joint>
    <joint name="Torso_Leg2" type="revolute">
       <parent link="Torso"/>
       <child  link="Leg2"/>
       <origin rpy="0 0 0" xyz="0.692014989622457 1.037328828396595 0" />
     <axis xyz="1 0 0"/>
       <limit effort="0.0" lower="-3.14159" upper="3.14159" velocity="0.0"/>
    </joint>
    <joint name="Leg1_Leg3" type="revolute">
       <parent link="Leg1"/>
       <child  link="Leg3"/>
       <origin rpy="0 0 0" xyz="0.9386313863305108 1.2038397428629337 0" />
     <axis xyz="1 0 0"/>
       <limit effort="0.0" lower="-3.14159" upper="3.14159" velocity="0.0"/>
    </joint>
    <joint name="Leg2_Leg4" type="revolute">
       <parent link="Leg2"/>
       <child  link="Leg4"/>
       <origin rpy="0 0 0" xyz="2.0618161005159696 0 0" />
     <axis xyz="1 0 0"/>
       <limit effort="0.0" lower="-3.14159" upper="3.14159" velocity="0.0"/>
    </joint>
    <joint name="Leg2_Leg5" type="revolute">
       <parent link="Leg2"/>
       <child  link="Leg5"/>
       <origin rpy="0 0 0" xyz="2.0618161005159696 0 0.8064252865851812" />
     <axis xyz="1 0 0"/>
       <limit effort="0.0" lower="-3.14159" upper="3.14159" velocity="0.0"/>
    </joint>
    <joint name="Leg5_Leg6" type="revolute">
       <parent link="Leg5"/>
       <child  link="Leg6"/>
       <origin rpy="0 0 0" xyz="0 0 2.4132952554699614" />
     <axis xyz="1 0 0"/>
       <limit effort="0.0" lower="-3.14159" upper="3.14159" velocity="0.0"/>
    </joint>
    <joint name="Leg1_Leg7" type="revolute">
       <parent link="Leg1"/>
       <child  link="Leg7"/>
       <origin rpy="0 0 0" xyz="0.9386313863305108 2.4076794857258674 0" />
     <axis xyz="1 0 0"/>
       <limit effort="0.0" lower="-3.14159" upper="3.14159" velocity="0.0"/>
    </joint>
    <joint name="Leg6_Leg8" type="revolute">
       <parent link="Leg6"/>
       <child  link="Leg8"/>
       <origin rpy="0 0 0" xyz="1.2632294574033565 0.6210307570341125 0" />
     <axis xyz="1 0 0"/>
       <limit effort="0.0" lower="-3.14159" upper="3.14159" velocity="0.0"/>
    </joint>
    <joint name="Leg8_Leg9" type="revolute">
       <parent link="Leg8"/>
       <child  link="Leg9"/>
       <origin rpy="0 0 0" xyz="2.521437209850697 0 0" />
     <axis xyz="1 0 0"/>
       <limit effort="0.0" lower="-3.14159" upper="3.14159" velocity="0.0"/>
    </joint>
    <joint name="Leg8_Leg10" type="revolute">
       <parent link="Leg8"/>
       <child  link="Leg10"/>
       <origin rpy="0 0 0" xyz="2.521437209850697 1.0192419446766015 0" />
     <axis xyz="1 0 0"/>
       <limit effort="0.0" lower="-3.14159" upper="3.14159" velocity="0.0"/>
    </joint>
    <joint name="Leg8_Leg11" type="revolute">
       <parent link="Leg8"/>
       <child  link="Leg11"/>
       <origin rpy="0 0 0" xyz="2.521437209850697 1.0192419446766015 0.7392029762275804" />
     <axis xyz="1 0 0"/>
       <limit effort="0.0" lower="-3.14159" upper="3.14159" velocity="0.0"/>
    </joint>
    <joint name="Leg7_Leg12" type="revolute">
       <parent link="Leg7"/>
       <child  link="Leg12"/>
       <origin rpy="0 0 0" xyz="2.1129158951253393 0 0" />
     <axis xyz="1 0 0"/>
       <limit effort="0.0" lower="-3.14159" upper="3.14159" velocity="0.0"/>
    </joint>
    <joint name="Leg12_Leg13" type="revolute">
       <parent link="Leg12"/>
       <child  link="Leg13"/>
       <origin rpy="0 0 0" xyz="2.737904000400169 0 0" />
     <axis xyz="1 0 0"/>
       <limit effort="0.0" lower="-3.14159" upper="3.14159" velocity="0.0"/>
    </joint>
    <joint name="Leg3_Leg14" type="revolute">
       <parent link="Leg3"/>
       <child  link="Leg14"/>
       <origin rpy="0 0 0" xyz="0.7814334065792328 0 0.70237760615878" />
     <axis xyz="1 0 0"/>
       <limit effort="0.0" lower="-3.14159" upper="3.14159" velocity="0.0"/>
    </joint>
    <joint name="Leg14_Leg15" type="revolute">
       <parent link="Leg14"/>
       <child  link="Leg15"/>
       <origin rpy="0 0 0" xyz="0 1.546154612113818 0" />
     <axis xyz="1 0 0"/>
       <limit effort="0.0" lower="-3.14159" upper="3.14159" velocity="0.0"/>
    </joint>
    <joint name="Leg15_Leg16" type="revolute">
       <parent link="Leg15"/>
       <child  link="Leg16"/>
       <origin rpy="0 0 0" xyz="0 2.9312372320451767 0" />
     <axis xyz="1 0 0"/>
       <limit effort="0.0" lower="-3.14159" upper="3.14159" velocity="0.0"/>
    </joint>
    <joint name="Leg13_Leg17" type="revolute">
       <parent link="Leg13"/>
       <child  link="Leg17"/>
       <origin rpy="0 0 0" xyz="0 1.0823354624306996 0.7582765586049974" />
     <axis xyz="1 0 0"/>
       <limit effort="0.0" lower="-3.14159" upper="3.14159" velocity="0.0"/>
    </joint>
    <joint name="Leg16_Leg18" type="revolute">
       <parent link="Leg16"/>
       <child  link="Leg18"/>
       <origin rpy="0 0 0" xyz="0.5656832847952132 1.3686614245211484 0" />
     <axis xyz="1 0 0"/>
       <limit effort="0.0" lower="-3.14159" upper="3.14159" velocity="0.0"/>
    </joint>
    <joint name="Leg4_Leg19" type="revolute">
       <parent link="Leg4"/>
       <child  link="Leg19"/>
       <origin rpy="0 0 0" xyz="1.4622756504815269 0 0.5077804138895268" />
     <axis xyz="1 0 0"/>
       <limit effort="0.0" lower="-3.14159" upper="3.14159" velocity="0.0"/>
    </joint>
    <joint name="Leg4_Leg20" type="revolute">
       <parent link="Leg4"/>
       <child  link="Leg20"/>
       <origin rpy="0 0 0" xyz="1.4622756504815269 0 1.0155608277790535" />
     <axis xyz="1 0 0"/>
       <limit effort="0.0" lower="-3.14159" upper="3.14159" velocity="0.0"/>
    </joint>
    <joint name="Leg19_Leg21" type="revolute">
       <parent link="Leg19"/>
       <child  link="Leg21"/>
       <origin rpy="0 0 0" xyz="0 1.2449171140007727 0.5474645048600356" />
     <axis xyz="1 0 0"/>
       <limit effort="0.0" lower="-3.14159" upper="3.14159" velocity="0.0"/>
    </joint>
    <joint name="Leg5_Leg22" type="revolute">
       <parent link="Leg5"/>
       <child  link="Leg22"/>
       <origin rpy="0 0 0" xyz="0 1.4507807722725392 2.4132952554699614" />
     <axis xyz="1 0 0"/>
       <limit effort="0.0" lower="-3.14159" upper="3.14159" velocity="0.0"/>
    </joint>
    <joint name="Leg21_Leg23" type="revolute">
       <parent link="Leg21"/>
       <child  link="Leg23"/>
       <origin rpy="0 0 0" xyz="0.8637036184227866 1.412003434454746 0" />
     <axis xyz="1 0 0"/>
       <limit effort="0.0" lower="-3.14159" upper="3.14159" velocity="0.0"/>
    </joint>
    <joint name="Leg9_Leg24" type="revolute">
       <parent link="Leg9"/>
       <child  link="Leg24"/>
       <origin rpy="0 0 0" xyz="0 1.1814311846882224 0" />
     <axis xyz="1 0 0"/>
       <limit effort="0.0" lower="-3.14159" upper="3.14159" velocity="0.0"/>
    </joint>
    <joint name="Leg2_Leg25" type="revolute">
       <parent link="Leg2"/>
       <child  link="Leg25"/>
       <origin rpy="0 0 0" xyz="2.0618161005159696 0.7331576908085534 0.8064252865851812" />
     <axis xyz="1 0 0"/>
       <limit effort="0.0" lower="-3.14159" upper="3.14159" velocity="0.0"/>
    </joint>
</robot>