<robot name = "robot">
    <link name="Torso">
        <inertial>
            <origin xyz="0 0 1.1539925560636242" rpy="0 0 0"/>
            <mass value="1" />
            <inertia ixx="100" ixy="0" ixz="0" iyy="100" iyz="0" izz="100" />
        </inertial>
        <visual>
            <origin xyz="0 0 1.1539925560636242" rpy="0 0 0"/>
            <geometry>
                <box size="2.0429530239304907 2.882788495341237 2.3079851121272483" />
            </geometry>
            <material name="Green">
                <color rgba="0 180.0 0.0 1.0"/>
            </material>
        </visual>
        <collision>
            <origin xyz="0 0 1.1539925560636242" rpy="0 0 0"/>
            <geometry>
                <box size="2.0429530239304907 2.882788495341237 2.3079851121272483" />
            </geometry>
        </collision>
    </link>
    <link name="Leg1">
        <inertial>
            <origin xyz="1.1092670476229816 0 0" rpy="0 0 0"/>
            <mass value="1" />
            <inertia ixx="100" ixy="0" ixz="0" iyy="100" iyz="0" izz="100" />
        </inertial>
        <visual>
            <origin xyz="1.1092670476229816 0 0" rpy="0 0 0"/>
            <geometry>
                <box size="2.218534095245963 2.073026427782035 1.348715487493482" />
            </geometry>
            <material name="Green">
                <color rgba="0 180.0 0.0 1.0"/>
            </material>
        </visual>
        <collision>
            <origin xyz="1.1092670476229816 0 0" rpy="0 0 0"/>
            <geometry>
                <box size="2.218534095245963 2.073026427782035 1.348715487493482" />
            </geometry>
        </collision>
    </link>
    <link name="Leg2">
        <inertial>
            <origin xyz="0.7411684461145107 0 0" rpy="0 0 0"/>
            <mass value="1" />
            <inertia ixx="100" ixy="0" ixz="0" iyy="100" iyz="0" izz="100" />
        </inertial>
        <visual>
            <origin xyz="0.7411684461145107 0 0" rpy="0 0 0"/>
            <geometry>
                <box size="1.4823368922290214 1.604295634496424 2.538788653979543" />
            </geometry>
            <material name="Blue">
                <color rgba="0 1.0 1.0 1.0"/>
            </material>
        </visual>
        <collision>
            <origin xyz="0.7411684461145107 0 0" rpy="0 0 0"/>
            <geometry>
                <box size="1.4823368922290214 1.604295634496424 2.538788653979543" />
            </geometry>
        </collision>
    </link>
    <link name="Leg3">
        <inertial>
            <origin xyz="0 0 0.5219977085265903" rpy="0 0 0"/>
            <mass value="1" />
            <inertia ixx="100" ixy="0" ixz="0" iyy="100" iyz="0" izz="100" />
        </inertial>
        <visual>
            <origin xyz="0 0 0.5219977085265903" rpy="0 0 0"/>
            <geometry>
                <box size="1.5109450630493562 1.3724230284342391 1.0439954170531807" />
            </geometry>
            <material name="Blue">
                <color rgba="0 1.0 1.0 1.0"/>
            </material>
        </visual>
        <collision>
            <origin xyz="0 0 0.5219977085265903" rpy="0 0 0"/>
            <geometry>
                <box size="1.5109450630493562 1.3724230284342391 1.0439954170531807" />
            </geometry>
        </collision>
    </link>
    <link name="Leg4">
        <inertial>
            <origin xyz="0 0.8874358914652811 0" rpy="0 0 0"/>
            <mass value="1" />
            <inertia ixx="100" ixy="0" ixz="0" iyy="100" iyz="0" izz="100" />
        </inertial>
        <visual>
            <origin xyz="0 0.8874358914652811 0" rpy="0 0 0"/>
            <geometry>
                <box size="2.358489208294057 1.7748717829305622 1.014040564010643" />
            </geometry>
            <material name="Blue">
                <color rgba="0 1.0 1.0 1.0"/>
            </material>
        </visual>
        <collision>
            <origin xyz="0 0.8874358914652811 0" rpy="0 0 0"/>
            <geometry>
                <box size="2.358489208294057 1.7748717829305622 1.014040564010643" />
            </geometry>
        </collision>
    </link>
    <link name="Leg5">
        <inertial>
            <origin xyz="1.0744728911364176 0 0" rpy="0 0 0"/>
            <mass value="1" />
            <inertia ixx="100" ixy="0" ixz="0" iyy="100" iyz="0" izz="100" />
        </inertial>
        <visual>
            <origin xyz="1.0744728911364176 0 0" rpy="0 0 0"/>
            <geometry>
                <box size="2.1489457822728353 2.5931148251928224 2.2662788416193913" />
            </geometry>
            <material name="Blue">
                <color rgba="0 1.0 1.0 1.0"/>
            </material>
        </visual>
        <collision>
            <origin xyz="1.0744728911364176 0 0" rpy="0 0 0"/>
            <geometry>
                <box size="2.1489457822728353 2.5931148251928224 2.2662788416193913" />
            </geometry>
        </collision>
    </link>
    <link name="Leg6">
        <inertial>
            <origin xyz="0 0 1.102091820837396" rpy="0 0 0"/>
            <mass value="1" />
            <inertia ixx="100" ixy="0" ixz="0" iyy="100" iyz="0" izz="100" />
        </inertial>
        <visual>
            <origin xyz="0 0 1.102091820837396" rpy="0 0 0"/>
            <geometry>
                <box size="2.618044575527432 2.239477852447555 2.204183641674792" />
            </geometry>
            <material name="Blue">
                <color rgba="0 1.0 1.0 1.0"/>
            </material>
        </visual>
        <collision>
            <origin xyz="0 0 1.102091820837396" rpy="0 0 0"/>
            <geometry>
                <box size="2.618044575527432 2.239477852447555 2.204183641674792" />
            </geometry>
        </collision>
    </link>
    <link name="Leg7">
        <inertial>
            <origin xyz="0 1.1833967600503164 0" rpy="0 0 0"/>
            <mass value="1" />
            <inertia ixx="100" ixy="0" ixz="0" iyy="100" iyz="0" izz="100" />
        </inertial>
        <visual>
            <origin xyz="0 1.1833967600503164 0" rpy="0 0 0"/>
            <geometry>
                <box size="2.2977249373038298 2.3667935201006327 2.0599459829164837" />
            </geometry>
            <material name="Blue">
                <color rgba="0 1.0 1.0 1.0"/>
            </material>
        </visual>
        <collision>
            <origin xyz="0 1.1833967600503164 0" rpy="0 0 0"/>
            <geometry>
                <box size="2.2977249373038298 2.3667935201006327 2.0599459829164837" />
            </geometry>
        </collision>
    </link>
    <link name="Leg8">
        <inertial>
            <origin xyz="0 0 0.5104135457170317" rpy="0 0 0"/>
            <mass value="1" />
            <inertia ixx="100" ixy="0" ixz="0" iyy="100" iyz="0" izz="100" />
        </inertial>
        <visual>
            <origin xyz="0 0 0.5104135457170317" rpy="0 0 0"/>
            <geometry>
                <box size="1.0985410969607519 2.206616285633258 1.0208270914340634" />
            </geometry>
            <material name="Green">
                <color rgba="0 180.0 0.0 1.0"/>
            </material>
        </visual>
        <collision>
            <origin xyz="0 0 0.5104135457170317" rpy="0 0 0"/>
            <geometry>
                <box size="1.0985410969607519 2.206616285633258 1.0208270914340634" />
            </geometry>
        </collision>
    </link>
    <link name="Leg9">
        <inertial>
            <origin xyz="0.8074884957451113 0 0" rpy="0 0 0"/>
            <mass value="1" />
            <inertia ixx="100" ixy="0" ixz="0" iyy="100" iyz="0" izz="100" />
        </inertial>
        <visual>
            <origin xyz="0.8074884957451113 0 0" rpy="0 0 0"/>
            <geometry>
                <box size="1.6149769914902226 1.0022122560395608 2.788085648887871" />
            </geometry>
            <material name="Blue">
                <color rgba="0 1.0 1.0 1.0"/>
            </material>
        </visual>
        <collision>
            <origin xyz="0.8074884957451113 0 0" rpy="0 0 0"/>
            <geometry>
                <box size="1.6149769914902226 1.0022122560395608 2.788085648887871" />
            </geometry>
        </collision>
    </link>
    <link name="Leg10">
        <inertial>
            <origin xyz="0.9302046392208057 0 0" rpy="0 0 0"/>
            <mass value="1" />
            <inertia ixx="100" ixy="0" ixz="0" iyy="100" iyz="0" izz="100" />
        </inertial>
        <visual>
            <origin xyz="0.9302046392208057 0 0" rpy="0 0 0"/>
            <geometry>
                <box size="1.8604092784416113 1.0529141946675533 1.45436928177587" />
            </geometry>
            <material name="Blue">
                <color rgba="0 1.0 1.0 1.0"/>
            </material>
        </visual>
        <collision>
            <origin xyz="0.9302046392208057 0 0" rpy="0 0 0"/>
            <geometry>
                <box size="1.8604092784416113 1.0529141946675533 1.45436928177587" />
            </geometry>
        </collision>
    </link>
    <link name="Leg11">
        <inertial>
            <origin xyz="0.518891727805889 0 0" rpy="0 0 0"/>
            <mass value="1" />
            <inertia ixx="100" ixy="0" ixz="0" iyy="100" iyz="0" izz="100" />
        </inertial>
        <visual>
            <origin xyz="0.518891727805889 0 0" rpy="0 0 0"/>
            <geometry>
                <box size="1.037783455611778 2.9706700877643977 1.004232358135031" />
            </geometry>
            <material name="Blue">
                <color rgba="0 1.0 1.0 1.0"/>
            </material>
        </visual>
        <collision>
            <origin xyz="0.518891727805889 0 0" rpy="0 0 0"/>
            <geometry>
                <box size="1.037783455611778 2.9706700877643977 1.004232358135031" />
            </geometry>
        </collision>
    </link>
    <link name="Leg12">
        <inertial>
            <origin xyz="0 1.3485756885689242 0" rpy="0 0 0"/>
            <mass value="1" />
            <inertia ixx="100" ixy="0" ixz="0" iyy="100" iyz="0" izz="100" />
        </inertial>
        <visual>
            <origin xyz="0 1.3485756885689242 0" rpy="0 0 0"/>
            <geometry>
                <box size="1.5532327576823897 2.6971513771378484 1.8665697120913045" />
            </geometry>
            <material name="Blue">
                <color rgba="0 1.0 1.0 1.0"/>
            </material>
        </visual>
        <collision>
            <origin xyz="0 1.3485756885689242 0" rpy="0 0 0"/>
            <geometry>
                <box size="1.5532327576823897 2.6971513771378484 1.8665697120913045" />
            </geometry>
        </collision>
    </link>
    <link name="Leg13">
        <inertial>
            <origin xyz="1.1311783350475082 0 0" rpy="0 0 0"/>
            <mass value="1" />
            <inertia ixx="100" ixy="0" ixz="0" iyy="100" iyz="0" izz="100" />
        </inertial>
        <visual>
            <origin xyz="1.1311783350475082 0 0" rpy="0 0 0"/>
            <geometry>
                <box size="2.2623566700950164 1.4257680700230322 2.0275596563333598" />
            </geometry>
            <material name="Blue">
                <color rgba="0 1.0 1.0 1.0"/>
            </material>
        </visual>
        <collision>
            <origin xyz="1.1311783350475082 0 0" rpy="0 0 0"/>
            <geometry>
                <box size="2.2623566700950164 1.4257680700230322 2.0275596563333598" />
            </geometry>
        </collision>
    </link>
    <link name="Leg14">
        <inertial>
            <origin xyz="0 1.0439546103716388 0" rpy="0 0 0"/>
            <mass value="1" />
            <inertia ixx="100" ixy="0" ixz="0" iyy="100" iyz="0" izz="100" />
        </inertial>
        <visual>
            <origin xyz="0 1.0439546103716388 0" rpy="0 0 0"/>
            <geometry>
                <box size="1.650062769019974 2.0879092207432777 1.0473048641843077" />
            </geometry>
            <material name="Blue">
                <color rgba="0 1.0 1.0 1.0"/>
            </material>
        </visual>
        <collision>
            <origin xyz="0 1.0439546103716388 0" rpy="0 0 0"/>
            <geometry>
                <box size="1.650062769019974 2.0879092207432777 1.0473048641843077" />
            </geometry>
        </collision>
    </link>
    <link name="Leg15">
        <inertial>
            <origin xyz="0 0 0.77413109726416" rpy="0 0 0"/>
            <mass value="1" />
            <inertia ixx="100" ixy="0" ixz="0" iyy="100" iyz="0" izz="100" />
        </inertial>
        <visual>
            <origin xyz="0 0 0.77413109726416" rpy="0 0 0"/>
            <geometry>
                <box size="2.1412779189209097 1.6973111056521633 1.54826219452832" />
            </geometry>
            <material name="Green">
                <color rgba="0 180.0 0.0 1.0"/>
            </material>
        </visual>
        <collision>
            <origin xyz="0 0 0.77413109726416" rpy="0 0 0"/>
            <geometry>
                <box size="2.1412779189209097 1.6973111056521633 1.54826219452832" />
            </geometry>
        </collision>
    </link>
    <link name="Leg16">
        <inertial>
            <origin xyz="0 1.4164723288452363 0" rpy="0 0 0"/>
            <mass value="1" />
            <inertia ixx="100" ixy="0" ixz="0" iyy="100" iyz="0" izz="100" />
        </inertial>
        <visual>
            <origin xyz="0 1.4164723288452363 0" rpy="0 0 0"/>
            <geometry>
                <box size="1.2278496311588818 2.8329446576904727 2.2381471993553212" />
            </geometry>
            <material name="Blue">
                <color rgba="0 1.0 1.0 1.0"/>
            </material>
        </visual>
        <collision>
            <origin xyz="0 1.4164723288452363 0" rpy="0 0 0"/>
            <geometry>
                <box size="1.2278496311588818 2.8329446576904727 2.2381471993553212" />
            </geometry>
        </collision>
    </link>
    <link name="Leg17">
        <inertial>
            <origin xyz="0 0 1.249453101122132" rpy="0 0 0"/>
            <mass value="1" />
            <inertia ixx="100" ixy="0" ixz="0" iyy="100" iyz="0" izz="100" />
        </inertial>
        <visual>
            <origin xyz="0 0 1.249453101122132" rpy="0 0 0"/>
            <geometry>
                <box size="2.792926194834435 1.3290513997554536 2.498906202244264" />
            </geometry>
            <material name="Green">
                <color rgba="0 180.0 0.0 1.0"/>
            </material>
        </visual>
        <collision>
            <origin xyz="0 0 1.249453101122132" rpy="0 0 0"/>
            <geometry>
                <box size="2.792926194834435 1.3290513997554536 2.498906202244264" />
            </geometry>
        </collision>
    </link>
    <link name="Leg18">
        <inertial>
            <origin xyz="0 0 0.8217523846308026" rpy="0 0 0"/>
            <mass value="1" />
            <inertia ixx="100" ixy="0" ixz="0" iyy="100" iyz="0" izz="100" />
        </inertial>
        <visual>
            <origin xyz="0 0 0.8217523846308026" rpy="0 0 0"/>
            <geometry>
                <box size="1.541984624496625 2.426538196334455 1.6435047692616052" />
            </geometry>
            <material name="Green">
                <color rgba="0 180.0 0.0 1.0"/>
            </material>
        </visual>
        <collision>
            <origin xyz="0 0 0.8217523846308026" rpy="0 0 0"/>
            <geometry>
                <box size="1.541984624496625 2.426538196334455 1.6435047692616052" />
            </geometry>
        </collision>
    </link>
    <link name="Leg19">
        <inertial>
            <origin xyz="0 0.8372991122723463 0" rpy="0 0 0"/>
            <mass value="1" />
            <inertia ixx="100" ixy="0" ixz="0" iyy="100" iyz="0" izz="100" />
        </inertial>
        <visual>
            <origin xyz="0 0.8372991122723463 0" rpy="0 0 0"/>
            <geometry>
                <box size="2.683457983316891 1.6745982245446926 1.680600048398911" />
            </geometry>
            <material name="Green">
                <color rgba="0 180.0 0.0 1.0"/>
            </material>
        </visual>
        <collision>
            <origin xyz="0 0.8372991122723463 0" rpy="0 0 0"/>
            <geometry>
                <box size="2.683457983316891 1.6745982245446926 1.680600048398911" />
            </geometry>
        </collision>
    </link>
    <link name="Leg20">
        <inertial>
            <origin xyz="1.249384115674933 0 0" rpy="0 0 0"/>
            <mass value="1" />
            <inertia ixx="100" ixy="0" ixz="0" iyy="100" iyz="0" izz="100" />
        </inertial>
        <visual>
            <origin xyz="1.249384115674933 0 0" rpy="0 0 0"/>
            <geometry>
                <box size="2.498768231349866 2.528675623581565 2.9544753043629974" />
            </geometry>
            <material name="Blue">
                <color rgba="0 1.0 1.0 1.0"/>
            </material>
        </visual>
        <collision>
            <origin xyz="1.249384115674933 0 0" rpy="0 0 0"/>
            <geometry>
                <box size="2.498768231349866 2.528675623581565 2.9544753043629974" />
            </geometry>
        </collision>
    </link>
    <link name="Leg21">
        <inertial>
            <origin xyz="1.3431662858463342 0 0" rpy="0 0 0"/>
            <mass value="1" />
            <inertia ixx="100" ixy="0" ixz="0" iyy="100" iyz="0" izz="100" />
        </inertial>
        <visual>
            <origin xyz="1.3431662858463342 0 0" rpy="0 0 0"/>
            <geometry>
                <box size="2.6863325716926685 1.2035170271959836 2.9510648257370606" />
            </geometry>
            <material name="Blue">
                <color rgba="0 1.0 1.0 1.0"/>
            </material>
        </visual>
        <collision>
            <origin xyz="1.3431662858463342 0 0" rpy="0 0 0"/>
            <geometry>
                <box size="2.6863325716926685 1.2035170271959836 2.9510648257370606" />
            </geometry>
        </collision>
    </link>
    <link name="Leg22">
        <inertial>
            <origin xyz="0 0 1.039434523887168" rpy="0 0 0"/>
            <mass value="1" />
            <inertia ixx="100" ixy="0" ixz="0" iyy="100" iyz="0" izz="100" />
        </inertial>
        <visual>
            <origin xyz="0 0 1.039434523887168" rpy="0 0 0"/>
            <geometry>
                <box size="2.4929450159675905 2.223249982177461 2.078869047774336" />
            </geometry>
            <material name="Blue">
                <color rgba="0 1.0 1.0 1.0"/>
            </material>
        </visual>
        <collision>
            <origin xyz="0 0 1.039434523887168" rpy="0 0 0"/>
            <geometry>
                <box size="2.4929450159675905 2.223249982177461 2.078869047774336" />
            </geometry>
        </collision>
    </link>
    <link name="Leg23">
        <inertial>
            <origin xyz="0 0 0.775189107270542" rpy="0 0 0"/>
            <mass value="1" />
            <inertia ixx="100" ixy="0" ixz="0" iyy="100" iyz="0" izz="100" />
        </inertial>
        <visual>
            <origin xyz="0 0 0.775189107270542" rpy="0 0 0"/>
            <geometry>
                <box size="1.164538873603343 2.4242857199283923 1.550378214541084" />
            </geometry>
            <material name="Green">
                <color rgba="0 180.0 0.0 1.0"/>
            </material>
        </visual>
        <collision>
            <origin xyz="0 0 0.775189107270542" rpy="0 0 0"/>
            <geometry>
                <box size="1.164538873603343 2.4242857199283923 1.550378214541084" />
            </geometry>
        </collision>
    </link>
    <link name="Leg24">
        <inertial>
            <origin xyz="1.4101929618607973 0 0" rpy="0 0 0"/>
            <mass value="1" />
            <inertia ixx="100" ixy="0" ixz="0" iyy="100" iyz="0" izz="100" />
        </inertial>
        <visual>
            <origin xyz="1.4101929618607973 0 0" rpy="0 0 0"/>
            <geometry>
                <box size="2.8203859237215947 1.252940181928392 1.4246639186623473" />
            </geometry>
            <material name="Blue">
                <color rgba="0 1.0 1.0 1.0"/>
            </material>
        </visual>
        <collision>
            <origin xyz="1.4101929618607973 0 0" rpy="0 0 0"/>
            <geometry>
                <box size="2.8203859237215947 1.252940181928392 1.4246639186623473" />
            </geometry>
        </collision>
    </link>
    <link name="Leg25">
        <inertial>
            <origin xyz="0 0.7802527765279297 0" rpy="0 0 0"/>
            <mass value="1" />
            <inertia ixx="100" ixy="0" ixz="0" iyy="100" iyz="0" izz="100" />
        </inertial>
        <visual>
            <origin xyz="0 0.7802527765279297 0" rpy="0 0 0"/>
            <geometry>
                <box size="2.547839003295114 1.5605055530558594 1.7246831155051616" />
            </geometry>
            <material name="Blue">
                <color rgba="0 1.0 1.0 1.0"/>
            </material>
        </visual>
        <collision>
            <origin xyz="0 0.7802527765279297 0" rpy="0 0 0"/>
            <geometry>
                <box size="2.547839003295114 1.5605055530558594 1.7246831155051616" />
            </geometry>
        </collision>
    </link>
    <link name="Leg26">
        <inertial>
            <origin xyz="1.203654967909796 0 0" rpy="0 0 0"/>
            <mass value="1" />
            <inertia ixx="100" ixy="0" ixz="0" iyy="100" iyz="0" izz="100" />
        </inertial>
        <visual>
            <origin xyz="1.203654967909796 0 0" rpy="0 0 0"/>
            <geometry>
                <box size="2.407309935819592 1.4970050106703954 1.9230501729788019" />
            </geometry>
            <material name="Green">
                <color rgba="0 180.0 0.0 1.0"/>
            </material>
        </visual>
        <collision>
            <origin xyz="1.203654967909796 0 0" rpy="0 0 0"/>
            <geometry>
                <box size="2.407309935819592 1.4970050106703954 1.9230501729788019" />
            </geometry>
        </collision>
    </link>
    <link name="Leg27">
        <inertial>
            <origin xyz="0 0 0.7067047278523552" rpy="0 0 0"/>
            <mass value="1" />
            <inertia ixx="100" ixy="0" ixz="0" iyy="100" iyz="0" izz="100" />
        </inertial>
        <visual>
            <origin xyz="0 0 0.7067047278523552" rpy="0 0 0"/>
            <geometry>
                <box size="2.1994493382955147 1.1533541109684675 1.4134094557047103" />
            </geometry>
            <material name="Blue">
                <color rgba="0 1.0 1.0 1.0"/>
            </material>
        </visual>
        <collision>
            <origin xyz="0 0 0.7067047278523552" rpy="0 0 0"/>
            <geometry>
                <box size="2.1994493382955147 1.1533541109684675 1.4134094557047103" />
            </geometry>
        </collision>
    </link>
    <link name="Leg28">
        <inertial>
            <origin xyz="1.3396390984516302 0 0" rpy="0 0 0"/>
            <mass value="1" />
            <inertia ixx="100" ixy="0" ixz="0" iyy="100" iyz="0" izz="100" />
        </inertial>
        <visual>
            <origin xyz="1.3396390984516302 0 0" rpy="0 0 0"/>
            <geometry>
                <box size="2.6792781969032604 2.592857870587724 1.843645548326776" />
            </geometry>
            <material name="Green">
                <color rgba="0 180.0 0.0 1.0"/>
            </material>
        </visual>
        <collision>
            <origin xyz="1.3396390984516302 0 0" rpy="0 0 0"/>
            <geometry>
                <box size="2.6792781969032604 2.592857870587724 1.843645548326776" />
            </geometry>
        </collision>
    </link>
    <joint name="Torso_Leg1" type="revolute">
       <parent link="Torso"/>
       <child  link="Leg1"/>
       <origin rpy="0 0 0" xyz="1.0214765119652454 0 1.1539925560636242" />
     <axis xyz="1 0 0"/>
       <limit effort="0.0" lower="-3.14159" upper="3.14159" velocity="0.0"/>
    </joint>
    <joint name="Leg1_Leg2" type="revolute">
       <parent link="Leg1"/>
       <child  link="Leg2"/>
       <origin rpy="0 0 0" xyz="1.4823368922290214 0 0" />
     <axis xyz="1 0 0"/>
       <limit effort="0.0" lower="-3.14159" upper="3.14159" velocity="0.0"/>
    </joint>
    <joint name="Leg1_Leg3" type="revolute">
       <parent link="Leg1"/>
       <child  link="Leg3"/>
       <origin rpy="0 0 0" xyz="1.4823368922290214 0 1.2693943269897714" />
     <axis xyz="1 0 0"/>
       <limit effort="0.0" lower="-3.14159" upper="3.14159" velocity="0.0"/>
    </joint>
    <joint name="Leg1_Leg4" type="revolute">
       <parent link="Leg1"/>
       <child  link="Leg4"/>
       <origin rpy="0 0 0" xyz="1.4823368922290214 0.802147817248212 1.2693943269897714" />
     <axis xyz="1 0 0"/>
       <limit effort="0.0" lower="-3.14159" upper="3.14159" velocity="0.0"/>
    </joint>
    <joint name="Leg3_Leg5" type="revolute">
       <parent link="Leg3"/>
       <child  link="Leg5"/>
       <origin rpy="0 0 0" xyz="1.1792446041470286 0.8874358914652811 0" />
     <axis xyz="1 0 0"/>
       <limit effort="0.0" lower="-3.14159" upper="3.14159" velocity="0.0"/>
    </joint>
    <joint name="Torso_Leg6" type="revolute">
       <parent link="Torso"/>
       <child  link="Leg6"/>
       <origin rpy="0 0 0" xyz="1.1092670476229816 0 0.674357743746741" />
     <axis xyz="1 0 0"/>
       <limit effort="0.0" lower="-3.14159" upper="3.14159" velocity="0.0"/>
    </joint>
    <joint name="Leg3_Leg7" type="revolute">
       <parent link="Leg3"/>
       <child  link="Leg7"/>
       <origin rpy="0 0 0" xyz="1.1792446041470286 1.7748717829305622 0" />
     <axis xyz="1 0 0"/>
       <limit effort="0.0" lower="-3.14159" upper="3.14159" velocity="0.0"/>
    </joint>
    <joint name="Leg4_Leg8" type="revolute">
       <parent link="Leg4"/>
       <child  link="Leg8"/>
       <origin rpy="0 0 0" xyz="1.0744728911364176 0 1.1331394208096957" />
     <axis xyz="1 0 0"/>
       <limit effort="0.0" lower="-3.14159" upper="3.14159" velocity="0.0"/>
    </joint>
    <joint name="Leg6_Leg9" type="revolute">
       <parent link="Leg6"/>
       <child  link="Leg9"/>
       <origin rpy="0 0 0" xyz="1.1488624686519149 1.1833967600503164 0" />
     <axis xyz="1 0 0"/>
       <limit effort="0.0" lower="-3.14159" upper="3.14159" velocity="0.0"/>
    </joint>
    <joint name="Leg2_Leg10" type="revolute">
       <parent link="Leg2"/>
       <child  link="Leg10"/>
       <origin rpy="0 0 0" xyz="0.7554725315246781 0 0.5219977085265903" />
     <axis xyz="1 0 0"/>
       <limit effort="0.0" lower="-3.14159" upper="3.14159" velocity="0.0"/>
    </joint>
    <joint name="Leg5_Leg11" type="revolute">
       <parent link="Leg5"/>
       <child  link="Leg11"/>
       <origin rpy="0 0 0" xyz="1.309022287763716 0 1.102091820837396" />
     <axis xyz="1 0 0"/>
       <limit effort="0.0" lower="-3.14159" upper="3.14159" velocity="0.0"/>
    </joint>
    <joint name="Leg11_Leg12" type="revolute">
       <parent link="Leg11"/>
       <child  link="Leg12"/>
       <origin rpy="0 0 0" xyz="0 2.6971513771378484 0" />
     <axis xyz="1 0 0"/>
       <limit effort="0.0" lower="-3.14159" upper="3.14159" velocity="0.0"/>
    </joint>
    <joint name="Leg11_Leg13" type="revolute">
       <parent link="Leg11"/>
       <child  link="Leg13"/>
       <origin rpy="0 0 0" xyz="0.7766163788411948 2.6971513771378484 0" />
     <axis xyz="1 0 0"/>
       <limit effort="0.0" lower="-3.14159" upper="3.14159" velocity="0.0"/>
    </joint>
    <joint name="Leg9_Leg14" type="revolute">
       <parent link="Leg9"/>
       <child  link="Leg14"/>
       <origin rpy="0 0 0" xyz="0.9302046392208057 0.5264570973337767 0" />
     <axis xyz="1 0 0"/>
       <limit effort="0.0" lower="-3.14159" upper="3.14159" velocity="0.0"/>
    </joint>
    <joint name="Leg14_Leg15" type="revolute">
       <parent link="Leg14"/>
       <child  link="Leg15"/>
       <origin rpy="0 0 0" xyz="0 0 1.54826219452832" />
     <axis xyz="1 0 0"/>
       <limit effort="0.0" lower="-3.14159" upper="3.14159" velocity="0.0"/>
    </joint>
    <joint name="Leg8_Leg16" type="revolute">
       <parent link="Leg8"/>
       <child  link="Leg16"/>
       <origin rpy="0 0 0" xyz="0.8074884957451113 0.5011061280197804 0" />
     <axis xyz="1 0 0"/>
       <limit effort="0.0" lower="-3.14159" upper="3.14159" velocity="0.0"/>
    </joint>
    <joint name="Leg9_Leg17" type="revolute">
       <parent link="Leg9"/>
       <child  link="Leg17"/>
       <origin rpy="0 0 0" xyz="0.9302046392208057 0.5264570973337767 0.727184640887935" />
     <axis xyz="1 0 0"/>
       <limit effort="0.0" lower="-3.14159" upper="3.14159" velocity="0.0"/>
    </joint>
    <joint name="Leg17_Leg18" type="revolute">
       <parent link="Leg17"/>
       <child  link="Leg18"/>
       <origin rpy="0 0 0" xyz="0 0 1.6435047692616052" />
     <axis xyz="1 0 0"/>
       <limit effort="0.0" lower="-3.14159" upper="3.14159" velocity="0.0"/>
    </joint>
    <joint name="Leg6_Leg19" type="revolute">
       <parent link="Leg6"/>
       <child  link="Leg19"/>
       <origin rpy="0 0 0" xyz="1.1488624686519149 2.3667935201006327 0" />
     <axis xyz="1 0 0"/>
       <limit effort="0.0" lower="-3.14159" upper="3.14159" velocity="0.0"/>
    </joint>
    <joint name="Leg7_Leg20" type="revolute">
       <parent link="Leg7"/>
       <child  link="Leg20"/>
       <origin rpy="0 0 0" xyz="0.5492705484803759 0 0.5104135457170317" />
     <axis xyz="1 0 0"/>
       <limit effort="0.0" lower="-3.14159" upper="3.14159" velocity="0.0"/>
    </joint>
    <joint name="Leg13_Leg21" type="revolute">
       <parent link="Leg13"/>
       <child  link="Leg21"/>
       <origin rpy="0 0 0" xyz="0.825031384509987 1.0439546103716388 0" />
     <axis xyz="1 0 0"/>
       <limit effort="0.0" lower="-3.14159" upper="3.14159" velocity="0.0"/>
    </joint>
    <joint name="Leg12_Leg22" type="revolute">
       <parent link="Leg12"/>
       <child  link="Leg22"/>
       <origin rpy="0 0 0" xyz="1.1311783350475082 0 1.0137798281666799" />
     <axis xyz="1 0 0"/>
       <limit effort="0.0" lower="-3.14159" upper="3.14159" velocity="0.0"/>
    </joint>
    <joint name="Leg18_Leg23" type="revolute">
       <parent link="Leg18"/>
       <child  link="Leg23"/>
       <origin rpy="0 0 0" xyz="0 0.8372991122723463 0.8403000241994555" />
     <axis xyz="1 0 0"/>
       <limit effort="0.0" lower="-3.14159" upper="3.14159" velocity="0.0"/>
    </joint>
    <joint name="Leg15_Leg24" type="revolute">
       <parent link="Leg15"/>
       <child  link="Leg24"/>
       <origin rpy="0 0 0" xyz="0.6139248155794409 1.4164723288452363 0" />
     <axis xyz="1 0 0"/>
       <limit effort="0.0" lower="-3.14159" upper="3.14159" velocity="0.0"/>
    </joint>
    <joint name="Leg14_Leg25" type="revolute">
       <parent link="Leg14"/>
       <child  link="Leg25"/>
       <origin rpy="0 0 0" xyz="0 0.8486555528260816 1.54826219452832" />
     <axis xyz="1 0 0"/>
       <limit effort="0.0" lower="-3.14159" upper="3.14159" velocity="0.0"/>
    </joint>
    <joint name="Leg21_Leg26" type="revolute">
       <parent link="Leg21"/>
       <child  link="Leg26"/>
       <origin rpy="0 0 0" xyz="1.2464725079837953 0 1.039434523887168" />
     <axis xyz="1 0 0"/>
       <limit effort="0.0" lower="-3.14159" upper="3.14159" velocity="0.0"/>
    </joint>
    <joint name="Leg16_Leg27" type="revolute">
       <parent link="Leg16"/>
       <child  link="Leg27"/>
       <origin rpy="0 0 0" xyz="0 0 2.498906202244264" />
     <axis xyz="1 0 0"/>
       <limit effort="0.0" lower="-3.14159" upper="3.14159" velocity="0.0"/>
    </joint>
    <joint name="Leg12_Leg28" type="revolute">
       <parent link="Leg12"/>
       <child  link="Leg28"/>
       <origin rpy="0 0 0" xyz="2.2623566700950164 0 1.0137798281666799" />
     <axis xyz="1 0 0"/>
       <limit effort="0.0" lower="-3.14159" upper="3.14159" velocity="0.0"/>
    </joint>
</robot>