<robot name = "robot">
    <link name="Torso">
        <inertial>
            <origin xyz="0 0 1.3960786878002807" rpy="0 0 0"/>
            <mass value="1" />
            <inertia ixx="100" ixy="0" ixz="0" iyy="100" iyz="0" izz="100" />
        </inertial>
        <visual>
            <origin xyz="0 0 1.3960786878002807" rpy="0 0 0"/>
            <geometry>
                <box size="2.0566317070967486 1.2276463685132353 2.7921573756005613" />
            </geometry>
            <material name="Green">
                <color rgba="0 180.0 0.0 1.0"/>
            </material>
        </visual>
        <collision>
            <origin xyz="0 0 1.3960786878002807" rpy="0 0 0"/>
            <geometry>
                <box size="2.0566317070967486 1.2276463685132353 2.7921573756005613" />
            </geometry>
        </collision>
    </link>
    <link name="Leg1">
        <inertial>
            <origin xyz="0 1.0059186204335604 0" rpy="0 0 0"/>
            <mass value="1" />
            <inertia ixx="100" ixy="0" ixz="0" iyy="100" iyz="0" izz="100" />
        </inertial>
        <visual>
            <origin xyz="0 1.0059186204335604 0" rpy="0 0 0"/>
            <geometry>
                <box size="1.734903535749752 2.011837240867121 1.2690995524113067" />
            </geometry>
            <material name="Blue">
                <color rgba="0 1.0 1.0 1.0"/>
            </material>
        </visual>
        <collision>
            <origin xyz="0 1.0059186204335604 0" rpy="0 0 0"/>
            <geometry>
                <box size="1.734903535749752 2.011837240867121 1.2690995524113067" />
            </geometry>
        </collision>
    </link>
    <link name="Leg2">
        <inertial>
            <origin xyz="0.8063479024776665 0 0" rpy="0 0 0"/>
            <mass value="1" />
            <inertia ixx="100" ixy="0" ixz="0" iyy="100" iyz="0" izz="100" />
        </inertial>
        <visual>
            <origin xyz="0.8063479024776665 0 0" rpy="0 0 0"/>
            <geometry>
                <box size="1.612695804955333 2.1294449843491376 2.534387244419659" />
            </geometry>
            <material name="Green">
                <color rgba="0 180.0 0.0 1.0"/>
            </material>
        </visual>
        <collision>
            <origin xyz="0.8063479024776665 0 0" rpy="0 0 0"/>
            <geometry>
                <box size="1.612695804955333 2.1294449843491376 2.534387244419659" />
            </geometry>
        </collision>
    </link>
    <link name="Leg3">
        <inertial>
            <origin xyz="0 0 0.7968315386908599" rpy="0 0 0"/>
            <mass value="1" />
            <inertia ixx="100" ixy="0" ixz="0" iyy="100" iyz="0" izz="100" />
        </inertial>
        <visual>
            <origin xyz="0 0 0.7968315386908599" rpy="0 0 0"/>
            <geometry>
                <box size="2.848429174725158 1.8103055972344624 1.5936630773817198" />
            </geometry>
            <material name="Green">
                <color rgba="0 180.0 0.0 1.0"/>
            </material>
        </visual>
        <collision>
            <origin xyz="0 0 0.7968315386908599" rpy="0 0 0"/>
            <geometry>
                <box size="2.848429174725158 1.8103055972344624 1.5936630773817198" />
            </geometry>
        </collision>
    </link>
    <link name="Leg4">
        <inertial>
            <origin xyz="0 0 1.4763843062974893" rpy="0 0 0"/>
            <mass value="1" />
            <inertia ixx="100" ixy="0" ixz="0" iyy="100" iyz="0" izz="100" />
        </inertial>
        <visual>
            <origin xyz="0 0 1.4763843062974893" rpy="0 0 0"/>
            <geometry>
                <box size="1.4062250065167716 1.3900052882830602 2.9527686125949786" />
            </geometry>
            <material name="Blue">
                <color rgba="0 1.0 1.0 1.0"/>
            </material>
        </visual>
        <collision>
            <origin xyz="0 0 1.4763843062974893" rpy="0 0 0"/>
            <geometry>
                <box size="1.4062250065167716 1.3900052882830602 2.9527686125949786" />
            </geometry>
        </collision>
    </link>
    <link name="Leg5">
        <inertial>
            <origin xyz="0.7777527576271394 0 0" rpy="0 0 0"/>
            <mass value="1" />
            <inertia ixx="100" ixy="0" ixz="0" iyy="100" iyz="0" izz="100" />
        </inertial>
        <visual>
            <origin xyz="0.7777527576271394 0 0" rpy="0 0 0"/>
            <geometry>
                <box size="1.5555055152542787 2.4343937743376953 1.9061805932383091" />
            </geometry>
            <material name="Blue">
                <color rgba="0 1.0 1.0 1.0"/>
            </material>
        </visual>
        <collision>
            <origin xyz="0.7777527576271394 0 0" rpy="0 0 0"/>
            <geometry>
                <box size="1.5555055152542787 2.4343937743376953 1.9061805932383091" />
            </geometry>
        </collision>
    </link>
    <link name="Leg6">
        <inertial>
            <origin xyz="0 1.280413225669284 0" rpy="0 0 0"/>
            <mass value="1" />
            <inertia ixx="100" ixy="0" ixz="0" iyy="100" iyz="0" izz="100" />
        </inertial>
        <visual>
            <origin xyz="0 1.280413225669284 0" rpy="0 0 0"/>
            <geometry>
                <box size="1.4205016753047848 2.560826451338568 2.090720597468167" />
            </geometry>
            <material name="Blue">
                <color rgba="0 1.0 1.0 1.0"/>
            </material>
        </visual>
        <collision>
            <origin xyz="0 1.280413225669284 0" rpy="0 0 0"/>
            <geometry>
                <box size="1.4205016753047848 2.560826451338568 2.090720597468167" />
            </geometry>
        </collision>
    </link>
    <link name="Leg7">
        <inertial>
            <origin xyz="0 0 0.8951584976009758" rpy="0 0 0"/>
            <mass value="1" />
            <inertia ixx="100" ixy="0" ixz="0" iyy="100" iyz="0" izz="100" />
        </inertial>
        <visual>
            <origin xyz="0 0 0.8951584976009758" rpy="0 0 0"/>
            <geometry>
                <box size="1.2961319139482563 1.6347421682210228 1.7903169952019515" />
            </geometry>
            <material name="Blue">
                <color rgba="0 1.0 1.0 1.0"/>
            </material>
        </visual>
        <collision>
            <origin xyz="0 0 0.8951584976009758" rpy="0 0 0"/>
            <geometry>
                <box size="1.2961319139482563 1.6347421682210228 1.7903169952019515" />
            </geometry>
        </collision>
    </link>
    <link name="Leg8">
        <inertial>
            <origin xyz="0 1.065519564997364 0" rpy="0 0 0"/>
            <mass value="1" />
            <inertia ixx="100" ixy="0" ixz="0" iyy="100" iyz="0" izz="100" />
        </inertial>
        <visual>
            <origin xyz="0 1.065519564997364 0" rpy="0 0 0"/>
            <geometry>
                <box size="2.253498695708652 2.131039129994728 2.503740826940023" />
            </geometry>
            <material name="Green">
                <color rgba="0 180.0 0.0 1.0"/>
            </material>
        </visual>
        <collision>
            <origin xyz="0 1.065519564997364 0" rpy="0 0 0"/>
            <geometry>
                <box size="2.253498695708652 2.131039129994728 2.503740826940023" />
            </geometry>
        </collision>
    </link>
    <link name="Leg9">
        <inertial>
            <origin xyz="0 1.183139624302619 0" rpy="0 0 0"/>
            <mass value="1" />
            <inertia ixx="100" ixy="0" ixz="0" iyy="100" iyz="0" izz="100" />
        </inertial>
        <visual>
            <origin xyz="0 1.183139624302619 0" rpy="0 0 0"/>
            <geometry>
                <box size="1.7722571713081772 2.366279248605238 2.739059056720323" />
            </geometry>
            <material name="Blue">
                <color rgba="0 1.0 1.0 1.0"/>
            </material>
        </visual>
        <collision>
            <origin xyz="0 1.183139624302619 0" rpy="0 0 0"/>
            <geometry>
                <box size="1.7722571713081772 2.366279248605238 2.739059056720323" />
            </geometry>
        </collision>
    </link>
    <link name="Leg10">
        <inertial>
            <origin xyz="0 1.0231912430086316 0" rpy="0 0 0"/>
            <mass value="1" />
            <inertia ixx="100" ixy="0" ixz="0" iyy="100" iyz="0" izz="100" />
        </inertial>
        <visual>
            <origin xyz="0 1.0231912430086316 0" rpy="0 0 0"/>
            <geometry>
                <box size="1.8546989754608778 2.0463824860172632 1.0164958374297595" />
            </geometry>
            <material name="Green">
                <color rgba="0 180.0 0.0 1.0"/>
            </material>
        </visual>
        <collision>
            <origin xyz="0 1.0231912430086316 0" rpy="0 0 0"/>
            <geometry>
                <box size="1.8546989754608778 2.0463824860172632 1.0164958374297595" />
            </geometry>
        </collision>
    </link>
    <link name="Leg11">
        <inertial>
            <origin xyz="0.6275183810986017 0 0" rpy="0 0 0"/>
            <mass value="1" />
            <inertia ixx="100" ixy="0" ixz="0" iyy="100" iyz="0" izz="100" />
        </inertial>
        <visual>
            <origin xyz="0.6275183810986017 0 0" rpy="0 0 0"/>
            <geometry>
                <box size="1.2550367621972034 1.826497019993227 1.3916060186854646" />
            </geometry>
            <material name="Green">
                <color rgba="0 180.0 0.0 1.0"/>
            </material>
        </visual>
        <collision>
            <origin xyz="0.6275183810986017 0 0" rpy="0 0 0"/>
            <geometry>
                <box size="1.2550367621972034 1.826497019993227 1.3916060186854646" />
            </geometry>
        </collision>
    </link>
    <link name="Leg12">
        <inertial>
            <origin xyz="0.9011113503674807 0 0" rpy="0 0 0"/>
            <mass value="1" />
            <inertia ixx="100" ixy="0" ixz="0" iyy="100" iyz="0" izz="100" />
        </inertial>
        <visual>
            <origin xyz="0.9011113503674807 0 0" rpy="0 0 0"/>
            <geometry>
                <box size="1.8022227007349614 1.5846065327309478 1.629639638704709" />
            </geometry>
            <material name="Blue">
                <color rgba="0 1.0 1.0 1.0"/>
            </material>
        </visual>
        <collision>
            <origin xyz="0.9011113503674807 0 0" rpy="0 0 0"/>
            <geometry>
                <box size="1.8022227007349614 1.5846065327309478 1.629639638704709" />
            </geometry>
        </collision>
    </link>
    <link name="Leg13">
        <inertial>
            <origin xyz="0 1.2103270593775277 0" rpy="0 0 0"/>
            <mass value="1" />
            <inertia ixx="100" ixy="0" ixz="0" iyy="100" iyz="0" izz="100" />
        </inertial>
        <visual>
            <origin xyz="0 1.2103270593775277 0" rpy="0 0 0"/>
            <geometry>
                <box size="2.198021552145512 2.4206541187550554 1.9643920186996582" />
            </geometry>
            <material name="Blue">
                <color rgba="0 1.0 1.0 1.0"/>
            </material>
        </visual>
        <collision>
            <origin xyz="0 1.2103270593775277 0" rpy="0 0 0"/>
            <geometry>
                <box size="2.198021552145512 2.4206541187550554 1.9643920186996582" />
            </geometry>
        </collision>
    </link>
    <link name="Leg14">
        <inertial>
            <origin xyz="0 0 0.6204469693381449" rpy="0 0 0"/>
            <mass value="1" />
            <inertia ixx="100" ixy="0" ixz="0" iyy="100" iyz="0" izz="100" />
        </inertial>
        <visual>
            <origin xyz="0 0 0.6204469693381449" rpy="0 0 0"/>
            <geometry>
                <box size="2.899857670478868 1.4111694668555548 1.2408939386762898" />
            </geometry>
            <material name="Green">
                <color rgba="0 180.0 0.0 1.0"/>
            </material>
        </visual>
        <collision>
            <origin xyz="0 0 0.6204469693381449" rpy="0 0 0"/>
            <geometry>
                <box size="2.899857670478868 1.4111694668555548 1.2408939386762898" />
            </geometry>
        </collision>
    </link>
    <link name="Leg15">
        <inertial>
            <origin xyz="1.0256242627113477 0 0" rpy="0 0 0"/>
            <mass value="1" />
            <inertia ixx="100" ixy="0" ixz="0" iyy="100" iyz="0" izz="100" />
        </inertial>
        <visual>
            <origin xyz="1.0256242627113477 0 0" rpy="0 0 0"/>
            <geometry>
                <box size="2.0512485254226953 1.0509001996276266 2.7452025412103405" />
            </geometry>
            <material name="Green">
                <color rgba="0 180.0 0.0 1.0"/>
            </material>
        </visual>
        <collision>
            <origin xyz="1.0256242627113477 0 0" rpy="0 0 0"/>
            <geometry>
                <box size="2.0512485254226953 1.0509001996276266 2.7452025412103405" />
            </geometry>
        </collision>
    </link>
    <link name="Leg16">
        <inertial>
            <origin xyz="0 0.9313614163322173 0" rpy="0 0 0"/>
            <mass value="1" />
            <inertia ixx="100" ixy="0" ixz="0" iyy="100" iyz="0" izz="100" />
        </inertial>
        <visual>
            <origin xyz="0 0.9313614163322173 0" rpy="0 0 0"/>
            <geometry>
                <box size="2.84707174163651 1.8627228326644345 1.4520702210391918" />
            </geometry>
            <material name="Green">
                <color rgba="0 180.0 0.0 1.0"/>
            </material>
        </visual>
        <collision>
            <origin xyz="0 0.9313614163322173 0" rpy="0 0 0"/>
            <geometry>
                <box size="2.84707174163651 1.8627228326644345 1.4520702210391918" />
            </geometry>
        </collision>
    </link>
    <link name="Leg17">
        <inertial>
            <origin xyz="1.4745730538751076 0 0" rpy="0 0 0"/>
            <mass value="1" />
            <inertia ixx="100" ixy="0" ixz="0" iyy="100" iyz="0" izz="100" />
        </inertial>
        <visual>
            <origin xyz="1.4745730538751076 0 0" rpy="0 0 0"/>
            <geometry>
                <box size="2.9491461077502152 1.7012037674677112 1.2690466402606888" />
            </geometry>
            <material name="Blue">
                <color rgba="0 1.0 1.0 1.0"/>
            </material>
        </visual>
        <collision>
            <origin xyz="1.4745730538751076 0 0" rpy="0 0 0"/>
            <geometry>
                <box size="2.9491461077502152 1.7012037674677112 1.2690466402606888" />
            </geometry>
        </collision>
    </link>
    <link name="Leg18">
        <inertial>
            <origin xyz="0.8866736437952618 0 0" rpy="0 0 0"/>
            <mass value="1" />
            <inertia ixx="100" ixy="0" ixz="0" iyy="100" iyz="0" izz="100" />
        </inertial>
        <visual>
            <origin xyz="0.8866736437952618 0 0" rpy="0 0 0"/>
            <geometry>
                <box size="1.7733472875905236 1.8086927808428666 1.3690743148321547" />
            </geometry>
            <material name="Green">
                <color rgba="0 180.0 0.0 1.0"/>
            </material>
        </visual>
        <collision>
            <origin xyz="0.8866736437952618 0 0" rpy="0 0 0"/>
            <geometry>
                <box size="1.7733472875905236 1.8086927808428666 1.3690743148321547" />
            </geometry>
        </collision>
    </link>
    <link name="Leg19">
        <inertial>
            <origin xyz="1.0134060684918258 0 0" rpy="0 0 0"/>
            <mass value="1" />
            <inertia ixx="100" ixy="0" ixz="0" iyy="100" iyz="0" izz="100" />
        </inertial>
        <visual>
            <origin xyz="1.0134060684918258 0 0" rpy="0 0 0"/>
            <geometry>
                <box size="2.0268121369836516 2.389001898637212 2.013099594745233" />
            </geometry>
            <material name="Green">
                <color rgba="0 180.0 0.0 1.0"/>
            </material>
        </visual>
        <collision>
            <origin xyz="1.0134060684918258 0 0" rpy="0 0 0"/>
            <geometry>
                <box size="2.0268121369836516 2.389001898637212 2.013099594745233" />
            </geometry>
        </collision>
    </link>
    <link name="Leg20">
        <inertial>
            <origin xyz="0 1.0143612320556628 0" rpy="0 0 0"/>
            <mass value="1" />
            <inertia ixx="100" ixy="0" ixz="0" iyy="100" iyz="0" izz="100" />
        </inertial>
        <visual>
            <origin xyz="0 1.0143612320556628 0" rpy="0 0 0"/>
            <geometry>
                <box size="2.031941788310032 2.0287224641113255 2.830871780961872" />
            </geometry>
            <material name="Blue">
                <color rgba="0 1.0 1.0 1.0"/>
            </material>
        </visual>
        <collision>
            <origin xyz="0 1.0143612320556628 0" rpy="0 0 0"/>
            <geometry>
                <box size="2.031941788310032 2.0287224641113255 2.830871780961872" />
            </geometry>
        </collision>
    </link>
    <link name="Leg21">
        <inertial>
            <origin xyz="0 1.1469900696984985 0" rpy="0 0 0"/>
            <mass value="1" />
            <inertia ixx="100" ixy="0" ixz="0" iyy="100" iyz="0" izz="100" />
        </inertial>
        <visual>
            <origin xyz="0 1.1469900696984985 0" rpy="0 0 0"/>
            <geometry>
                <box size="2.6389510503773366 2.293980139396997 2.5926437556802013" />
            </geometry>
            <material name="Green">
                <color rgba="0 180.0 0.0 1.0"/>
            </material>
        </visual>
        <collision>
            <origin xyz="0 1.1469900696984985 0" rpy="0 0 0"/>
            <geometry>
                <box size="2.6389510503773366 2.293980139396997 2.5926437556802013" />
            </geometry>
        </collision>
    </link>
    <link name="Leg22">
        <inertial>
            <origin xyz="0 0 0.9055091892638849" rpy="0 0 0"/>
            <mass value="1" />
            <inertia ixx="100" ixy="0" ixz="0" iyy="100" iyz="0" izz="100" />
        </inertial>
        <visual>
            <origin xyz="0 0 0.9055091892638849" rpy="0 0 0"/>
            <geometry>
                <box size="1.6381004894476396 1.9979105137842634 1.8110183785277698" />
            </geometry>
            <material name="Blue">
                <color rgba="0 1.0 1.0 1.0"/>
            </material>
        </visual>
        <collision>
            <origin xyz="0 0 0.9055091892638849" rpy="0 0 0"/>
            <geometry>
                <box size="1.6381004894476396 1.9979105137842634 1.8110183785277698" />
            </geometry>
        </collision>
    </link>
    <link name="Leg23">
        <inertial>
            <origin xyz="0.9138335741850573 0 0" rpy="0 0 0"/>
            <mass value="1" />
            <inertia ixx="100" ixy="0" ixz="0" iyy="100" iyz="0" izz="100" />
        </inertial>
        <visual>
            <origin xyz="0.9138335741850573 0 0" rpy="0 0 0"/>
            <geometry>
                <box size="1.8276671483701146 1.0934866226277038 2.0076280815896075" />
            </geometry>
            <material name="Blue">
                <color rgba="0 1.0 1.0 1.0"/>
            </material>
        </visual>
        <collision>
            <origin xyz="0.9138335741850573 0 0" rpy="0 0 0"/>
            <geometry>
                <box size="1.8276671483701146 1.0934866226277038 2.0076280815896075" />
            </geometry>
        </collision>
    </link>
    <link name="Leg24">
        <inertial>
            <origin xyz="0 1.0030106346521885 0" rpy="0 0 0"/>
            <mass value="1" />
            <inertia ixx="100" ixy="0" ixz="0" iyy="100" iyz="0" izz="100" />
        </inertial>
        <visual>
            <origin xyz="0 1.0030106346521885 0" rpy="0 0 0"/>
            <geometry>
                <box size="2.2373040433553153 2.006021269304377 2.2017961054575608" />
            </geometry>
            <material name="Green">
                <color rgba="0 180.0 0.0 1.0"/>
            </material>
        </visual>
        <collision>
            <origin xyz="0 1.0030106346521885 0" rpy="0 0 0"/>
            <geometry>
                <box size="2.2373040433553153 2.006021269304377 2.2017961054575608" />
            </geometry>
        </collision>
    </link>
    <joint name="Torso_Leg1" type="revolute">
       <parent link="Torso"/>
       <child  link="Leg1"/>
       <origin rpy="0 0 0" xyz="0 0.6138231842566176 1.3960786878002807" />
     <axis xyz="1 0 0"/>
       <limit effort="0.0" lower="-3.14159" upper="3.14159" velocity="0.0"/>
    </joint>
    <joint name="Torso_Leg2" type="revolute">
       <parent link="Torso"/>
       <child  link="Leg2"/>
       <origin rpy="0 0 0" xyz="0.867451767874876 1.0059186204335604 0" />
     <axis xyz="1 0 0"/>
       <limit effort="0.0" lower="-3.14159" upper="3.14159" velocity="0.0"/>
    </joint>
    <joint name="Leg2_Leg3" type="revolute">
       <parent link="Leg2"/>
       <child  link="Leg3"/>
       <origin rpy="0 0 0" xyz="0 0 1.5936630773817198" />
     <axis xyz="1 0 0"/>
       <limit effort="0.0" lower="-3.14159" upper="3.14159" velocity="0.0"/>
    </joint>
    <joint name="Leg1_Leg4" type="revolute">
       <parent link="Leg1"/>
       <child  link="Leg4"/>
       <origin rpy="0 0 0" xyz="0.8063479024776665 0 1.2671936222098295" />
     <axis xyz="1 0 0"/>
       <limit effort="0.0" lower="-3.14159" upper="3.14159" velocity="0.0"/>
    </joint>
    <joint name="Leg2_Leg5" type="revolute">
       <parent link="Leg2"/>
       <child  link="Leg5"/>
       <origin rpy="0 0 0" xyz="1.424214587362579 0 1.5936630773817198" />
     <axis xyz="1 0 0"/>
       <limit effort="0.0" lower="-3.14159" upper="3.14159" velocity="0.0"/>
    </joint>
    <joint name="Leg4_Leg6" type="revolute">
       <parent link="Leg4"/>
       <child  link="Leg6"/>
       <origin rpy="0 0 0" xyz="0.7777527576271394 1.2171968871688477 0" />
     <axis xyz="1 0 0"/>
       <limit effort="0.0" lower="-3.14159" upper="3.14159" velocity="0.0"/>
    </joint>
    <joint name="Leg6_Leg7" type="revolute">
       <parent link="Leg6"/>
       <child  link="Leg7"/>
       <origin rpy="0 0 0" xyz="0 0 1.7903169952019515" />
     <axis xyz="1 0 0"/>
       <limit effort="0.0" lower="-3.14159" upper="3.14159" velocity="0.0"/>
    </joint>
    <joint name="Leg7_Leg8" type="revolute">
       <parent link="Leg7"/>
       <child  link="Leg8"/>
       <origin rpy="0 0 0" xyz="0 2.131039129994728 0" />
     <axis xyz="1 0 0"/>
       <limit effort="0.0" lower="-3.14159" upper="3.14159" velocity="0.0"/>
    </joint>
    <joint name="Leg8_Leg9" type="revolute">
       <parent link="Leg8"/>
       <child  link="Leg9"/>
       <origin rpy="0 0 0" xyz="0 2.366279248605238 0" />
     <axis xyz="1 0 0"/>
       <limit effort="0.0" lower="-3.14159" upper="3.14159" velocity="0.0"/>
    </joint>
    <joint name="Leg2_Leg10" type="revolute">
       <parent link="Leg2"/>
       <child  link="Leg10"/>
       <origin rpy="0 0 0" xyz="1.424214587362579 0.9051527986172312 1.5936630773817198" />
     <axis xyz="1 0 0"/>
       <limit effort="0.0" lower="-3.14159" upper="3.14159" velocity="0.0"/>
    </joint>
    <joint name="Leg4_Leg11" type="revolute">
       <parent link="Leg4"/>
       <child  link="Leg11"/>
       <origin rpy="0 0 0" xyz="1.5555055152542787 1.2171968871688477 0" />
     <axis xyz="1 0 0"/>
       <limit effort="0.0" lower="-3.14159" upper="3.14159" velocity="0.0"/>
    </joint>
    <joint name="Leg5_Leg12" type="revolute">
       <parent link="Leg5"/>
       <child  link="Leg12"/>
       <origin rpy="0 0 0" xyz="0.7102508376523924 1.280413225669284 0" />
     <axis xyz="1 0 0"/>
       <limit effort="0.0" lower="-3.14159" upper="3.14159" velocity="0.0"/>
    </joint>
    <joint name="Leg1_Leg13" type="revolute">
       <parent link="Leg1"/>
       <child  link="Leg13"/>
       <origin rpy="0 0 0" xyz="0.8063479024776665 1.0647224921745688 1.2671936222098295" />
     <axis xyz="1 0 0"/>
       <limit effort="0.0" lower="-3.14159" upper="3.14159" velocity="0.0"/>
    </joint>
    <joint name="Leg12_Leg14" type="revolute">
       <parent link="Leg12"/>
       <child  link="Leg14"/>
       <origin rpy="0 0 0" xyz="0 1.2103270593775277 0.9821960093498291" />
     <axis xyz="1 0 0"/>
       <limit effort="0.0" lower="-3.14159" upper="3.14159" velocity="0.0"/>
    </joint>
    <joint name="Leg9_Leg15" type="revolute">
       <parent link="Leg9"/>
       <child  link="Leg15"/>
       <origin rpy="0 0 0" xyz="0.9273494877304389 1.0231912430086316 0" />
     <axis xyz="1 0 0"/>
       <limit effort="0.0" lower="-3.14159" upper="3.14159" velocity="0.0"/>
    </joint>
    <joint name="Leg5_Leg16" type="revolute">
       <parent link="Leg5"/>
       <child  link="Leg16"/>
       <origin rpy="0 0 0" xyz="0.7102508376523924 2.560826451338568 0" />
     <axis xyz="1 0 0"/>
       <limit effort="0.0" lower="-3.14159" upper="3.14159" velocity="0.0"/>
    </joint>
    <joint name="Leg10_Leg17" type="revolute">
       <parent link="Leg10"/>
       <child  link="Leg17"/>
       <origin rpy="0 0 0" xyz="1.2550367621972034 0 0" />
     <axis xyz="1 0 0"/>
       <limit effort="0.0" lower="-3.14159" upper="3.14159" velocity="0.0"/>
    </joint>
    <joint name="Leg15_Leg18" type="revolute">
       <parent link="Leg15"/>
       <child  link="Leg18"/>
       <origin rpy="0 0 0" xyz="1.423535870818255 0.9313614163322173 0" />
     <axis xyz="1 0 0"/>
       <limit effort="0.0" lower="-3.14159" upper="3.14159" velocity="0.0"/>
    </joint>
    <joint name="Leg14_Leg19" type="revolute">
       <parent link="Leg14"/>
       <child  link="Leg19"/>
       <origin rpy="0 0 0" xyz="2.0512485254226953 0 0" />
     <axis xyz="1 0 0"/>
       <limit effort="0.0" lower="-3.14159" upper="3.14159" velocity="0.0"/>
    </joint>
    <joint name="Leg9_Leg20" type="revolute">
       <parent link="Leg9"/>
       <child  link="Leg20"/>
       <origin rpy="0 0 0" xyz="0.9273494877304389 2.0463824860172632 0" />
     <axis xyz="1 0 0"/>
       <limit effort="0.0" lower="-3.14159" upper="3.14159" velocity="0.0"/>
    </joint>
    <joint name="Leg14_Leg21" type="revolute">
       <parent link="Leg14"/>
       <child  link="Leg21"/>
       <origin rpy="0 0 0" xyz="2.0512485254226953 0.5254500998138133 0" />
     <axis xyz="1 0 0"/>
       <limit effort="0.0" lower="-3.14159" upper="3.14159" velocity="0.0"/>
    </joint>
    <joint name="Leg19_Leg22" type="revolute">
       <parent link="Leg19"/>
       <child  link="Leg22"/>
       <origin rpy="0 0 0" xyz="0 1.0143612320556628 1.415435890480936" />
     <axis xyz="1 0 0"/>
       <limit effort="0.0" lower="-3.14159" upper="3.14159" velocity="0.0"/>
    </joint>
    <joint name="Leg1_Leg23" type="revolute">
       <parent link="Leg1"/>
       <child  link="Leg23"/>
       <origin rpy="0 0 0" xyz="1.612695804955333 1.0647224921745688 1.2671936222098295" />
     <axis xyz="1 0 0"/>
       <limit effort="0.0" lower="-3.14159" upper="3.14159" velocity="0.0"/>
    </joint>
    <joint name="Leg12_Leg24" type="revolute">
       <parent link="Leg12"/>
       <child  link="Leg24"/>
       <origin rpy="0 0 0" xyz="0 2.4206541187550554 0.9821960093498291" />
     <axis xyz="1 0 0"/>
       <limit effort="0.0" lower="-3.14159" upper="3.14159" velocity="0.0"/>
    </joint>
</robot>